File: imagens/notebooks/dados experimentais/dsc/Karl_CTAB100 Ur 42%.txt
CLOSED
Version	1.0
Language	English
Run	1
RunSerial	147
Instrument	DSC Q100 V9.9 Build 303
Module	DSC Standard Cell FC
Operator	LL
File	\\Niger\ta\Data\DSC\2018\Geral\Karl_CTAB100 Ur 42%.001
ProcName	Karl
InstSerial	0100-1211
Sample	CTAB100 Ur 42%
Size	13.7400	mg
Method	Karl
Comment
Xcomment	Pan: Aluminum Hermetic
Xcomment	Gas1: Nitrogen 50.0 ml/min
Xcomment	Gas2: Nitrogen 0.0 ml/min
Text
Exotherm	UP
Kcell	1.09030
Calib	-11.7822
TempCal	1	pts	158.71	156.60
TzeroDt	-90.0515 -0.0093 2.2263
TzeroDtz	-90.0515 0.0466 2.4421
InstCalFile	Tzero: \\Niger\ta\Data\DSC\CALIBRATION\20122016\CALIBRATION\0_RCS_12_20_2016 17_23_31.TZR
InstCalFile	Baseline: \\Niger\ta\Data\DSC\CALIBRATION\20122016\L.Base 20122016
InstCalFile	Sapphire: \\Niger\ta\Data\DSC\CALIBRATION\20122016\Safira 20122017.001
InstCalDate	Tzero 2016-12-20 Time 19:23:31
TempRange	-90.04 to 395.23 °C at 19.96 °C/min Heat Only
AutoZero	Delta T Offset 0.000 uV
AutoZero	Delta T0 Offset 0.000 uV
Controls	Gas 1  Event Off  Sampling 0.2
Cell#	FC-02451
CoolingUnit	RCS
SelHeatFlow	Heat Flow T4 (mW)
AutoAnalysis	Off
MacroFile
Nsig	4
Sig1	Time (min)
Sig2	Temperature (°C)
Sig3	Heat Flow (mW)
Sig4	Sample Purge Flow (mL/min)
Date	2018-05-16
Time	10:49:20
OrgMethod	1: Equilibrate at 1.00 °C
OrgMethod	2: Ramp 2.00 °C/min to 60.00 °C
OrgMethod	3: Isothermal for 3.00 min
OrgMethod	4: Mark end of cycle 1
OrgMethod	5: Ramp 2.00 °C/min to 1.00 °C
OrgMethod	6: Isothermal for 3.00 min
OrgMethod	7: Mark end of cycle 2
OrgFile	C:\TA\Data\DSC\2018\Geral\Karl_CTAB100 Ur 42%.001
3.33324E-4 1.185374 1.300928 49.96384
0.05033332 1.169476 1.152536 49.97636
0.1003333 1.181012 0.9617511 50.04970
0.1503333 1.217398 0.7481218 50.00588
0.2003333 1.265444 0.5344156 49.91815
0.2503333 1.323444 0.3176465 50.22459
0.3003333 1.385411 0.1244396 49.99450
0.3503333 1.453864 -.05137061 50.09284
0.4003334 1.525153 -0.2187171 50.18246
0.4503334 1.601379 -0.3660254 49.86118
0.5003334 1.680423 -0.4907867 50.16730
0.5503332 1.762134 -0.6029579 49.95294
0.6003332 1.846340 -0.6996494 50.03015
0.6503332 1.931341 -0.7863536 49.86093
0.7003332 2.019672 -0.8566840 50.11008
0.7503332 2.108547 -0.9257785 50.27392
0.8003332 2.198602 -0.9826538 50.00541
0.8503332 2.289402 -1.027571 50.06124
0.9003332 2.382713 -1.071414 49.88769
0.9503334 2.474945 -1.108342 49.82352
1.000333 2.568828 -1.140222 49.84936
1.050334 2.664050 -1.166712 50.14304
1.100334 2.758362 -1.191052 49.92309
1.150334 2.854315 -1.212084 50.01225
1.200334 2.950172 -1.230568 50.03204
1.250334 3.046963 -1.245894 50.05298
1.300334 3.143338 -1.258849 49.94788
1.350333 3.240715 -1.271957 49.96881
1.400333 3.338328 -1.282487 50.09306
1.450334 3.435876 -1.291902 49.96660
1.500333 3.532439 -1.300794 50.09693
1.550334 3.631519 -1.309774 49.92646
1.600334 3.727972 -1.318768 50.05220
1.650333 3.826796 -1.327450 50.02018
1.700334 3.925250 -1.335746 50.07700
1.750334 4.023368 -1.343955 49.94287
1.800334 4.122248 -1.351563 50.04252
1.850334 4.220922 -1.358864 50.11736
1.900334 4.318486 -1.365740 50.06042
1.950334 4.417566 -1.372182 49.96640
2.000334 4.516372 -1.378361 49.86770
2.050333 4.615696 -1.384016 50.11306
2.100334 4.715154 -1.389465 50.09134
2.150334 4.813800 -1.394446 50.06934
2.200334 4.912902 -1.399095 50.02117
2.250334 5.011600 -1.403336 50.03975
2.300333 5.110153 -1.407351 49.94990
2.350334 5.210000 -1.411178 49.94167
2.400334 5.309380 -1.414792 49.85815
2.450334 5.408688 -1.418284 49.91638
2.500334 5.506988 -1.421482 49.51870
2.550333 5.606835 -1.424385 50.07663
2.600333 5.706407 -1.427197 49.89578
2.650333 5.805789 -1.429877 50.08817
2.700333 5.905137 -1.432517 49.91368
2.750333 6.004826 -1.434904 49.97807
2.800333 6.103024 -1.437343 49.87576
2.850333 6.202978 -1.439725 50.05238
2.900333 6.303332 -1.442016 50.03616
2.950333 6.403062 -1.444256 49.87658
3.000333 6.503089 -1.446606 49.94971
3.050333 6.602100 -1.448589 49.93672
3.100333 6.702134 -1.450697 50.10611
3.150333 6.802490 -1.452825 50.12180
3.200333 6.900489 -1.454772 49.94352
3.250333 7.001580 -1.456494 49.99840
3.300333 7.100986 -1.458002 49.70447
3.350333 7.200519 -1.459663 50.03524
3.400333 7.300660 -1.461024 49.93145
3.450333 7.399652 -1.462141 50.02797
3.500333 7.499360 -1.463218 50.25366
3.550333 7.598471 -1.464331 49.90045
3.600333 7.698406 -1.465220 50.02235
3.650333 7.797724 -1.466212 49.88616
3.700333 7.897022 -1.467082 50.08118
3.750333 7.997496 -1.467989 49.93004
3.800333 8.096031 -1.468842 49.99880
3.850333 8.196488 -1.469756 50.10340
3.900333 8.296372 -1.470959 49.91066
3.950333 8.395978 -1.472011 50.03689
4.000333 8.496639 -1.473205 49.93369
4.050333 8.595734 -1.474273 50.14258
4.100333 8.695184 -1.475469 49.76050
4.150333 8.795386 -1.476550 50.03261
4.200333 8.895059 -1.477381 50.01787
4.250333 8.994247 -1.478211 49.99880
4.300333 9.094609 -1.479083 50.02545
4.350333 9.194706 -1.479855 49.89133
4.400333 9.294214 -1.480620 50.30570
4.450333 9.393342 -1.481261 49.92656
4.500333 9.492992 -1.482031 49.93826
4.550333 9.592926 -1.482778 49.50805
4.600333 9.693321 -1.483626 49.87944
4.650333 9.792168 -1.484488 50.21421
4.700333 9.893047 -1.485253 50.02820
4.750333 9.992911 -1.485909 50.00161
4.800333 10.09216 -1.486737 49.86486
4.850333 10.19281 -1.487331 49.79817
4.900333 10.29247 -1.488252 50.03054
4.950333 10.39260 -1.489212 50.02994
5.000333 10.49372 -1.490107 50.05096
5.050333 10.59172 -1.491005 49.98238
5.100333 10.69252 -1.492001 50.11814
5.150333 10.79180 -1.492962 50.11194
5.200333 10.89182 -1.493875 49.92852
5.250332 10.99198 -1.494849 49.87710
5.300332 11.09227 -1.495788 50.15298
5.350332 11.19101 -1.496800 49.95410
5.400332 11.29148 -1.497599 49.84118
5.450332 11.39131 -1.498476 49.99368
5.500332 11.49206 -1.499075 50.13366
5.550332 11.59110 -1.499641 49.90668
5.600332 11.69057 -1.499935 49.99741
5.650332 11.79156 -1.500416 49.98590
5.700332 11.89134 -1.501009 49.89878
5.750332 11.99074 -1.501411 49.96756
5.800332 12.09018 -1.501772 49.99917
5.850332 12.19094 -1.502468 49.71628
5.900332 12.29054 -1.502897 49.98264
5.950332 12.39113 -1.503488 50.04558
6.000332 12.49073 -1.504118 49.35380
6.050332 12.59078 -1.504611 49.88438
6.100332 12.69020 -1.505144 49.92626
6.150332 12.78990 -1.505675 49.99522
6.200332 12.89016 -1.506121 50.03004
6.250332 12.98989 -1.506572 50.13632
6.300332 13.08996 -1.507289 50.09389
6.350332 13.18914 -1.507890 50.02672
6.400332 13.28911 -1.508539 50.24700
6.450332 13.38936 -1.509104 50.00715
6.500332 13.48922 -1.509850 50.00096
6.550332 13.58964 -1.510536 50.02164
6.600332 13.68899 -1.511259 50.02590
6.650332 13.78946 -1.511910 50.30696
6.700332 13.88824 -1.512580 49.95210
6.750332 13.98887 -1.513228 50.08013
6.800332 14.08829 -1.513789 50.07194
6.850332 14.18843 -1.514300 50.04626
6.900332 14.28856 -1.515040 50.13186
6.950332 14.38881 -1.515685 49.97356
7.000332 14.48752 -1.516364 50.06668
7.050332 14.58852 -1.517054 49.92254
7.100332 14.68865 -1.517602 50.11479
7.150332 14.78853 -1.518276 50.06861
7.200332 14.88855 -1.518982 49.97240
7.250332 14.98836 -1.519378 49.95765
7.300332 15.08784 -1.519857 50.10294
7.350332 15.18931 -1.520526 50.00928
7.400332 15.28805 -1.520881 50.12239
7.450332 15.38861 -1.521436 49.97840
7.500332 15.48740 -1.521963 49.76839
7.550332 15.58857 -1.522260 50.04956
7.600332 15.68870 -1.522795 49.94056
7.650332 15.78772 -1.523218 49.87589
7.700332 15.88704 -1.523728 49.79461
7.750332 15.98694 -1.524067 50.08487
7.800332 16.08801 -1.524409 49.84419
7.850332 16.18746 -1.524938 49.88672
7.900332 16.28723 -1.525462 49.84160
7.950332 16.38710 -1.526087 49.92940
8.000334 16.48768 -1.526872 50.07516
8.050332 16.58812 -1.527405 49.98513
8.100332 16.68815 -1.528294 49.99304
8.150332 16.78751 -1.528944 49.95703
8.200332 16.88803 -1.529466 49.82912
8.250334 16.98736 -1.530103 49.98938
8.300332 17.08805 -1.530724 50.05765
8.350332 17.18765 -1.531332 50.00134
8.400332 17.28865 -1.531789 49.89984
8.450332 17.38886 -1.532114 49.53679
8.500334 17.48686 -1.532640 50.29850
8.550332 17.58856 -1.533028 49.79234
8.600332 17.68761 -1.533497 50.13348
8.650332 17.78779 -1.533809 50.13884
8.700332 17.88846 -1.534322 49.99056
8.750334 17.98783 -1.534534 49.96954
8.800332 18.08746 -1.534913 50.07168
8.850332 18.18804 -1.535184 50.11046
8.900332 18.28756 -1.535367 50.03641
8.950332 18.38709 -1.535469 50.05022
9.000334 18.48781 -1.535520 50.11462
9.050332 18.58616 -1.535593 49.98066
9.100332 18.68586 -1.535472 50.24408
9.150332 18.78628 -1.535676 50.16878
9.200332 18.88590 -1.535882 49.87231
9.250334 18.98626 -1.536223 49.86191
9.300332 19.08578 -1.536730 50.06348
9.350332 19.18533 -1.537333 50.07056
9.400332 19.28606 -1.537808 49.94946
9.450332 19.38599 -1.538251 49.83266
9.500334 19.48501 -1.538858 50.13488
9.550332 19.58551 -1.539584 50.41128
9.600332 19.68599 -1.540122 50.02566
9.650332 19.78576 -1.540797 50.06303
9.700332 19.88551 -1.541309 50.03731
9.750334 19.98570 -1.541987 49.91797
9.800332 20.08535 -1.542814 50.29016
9.850332 20.18530 -1.543676 49.95906
9.900332 20.28526 -1.544451 49.86820
9.950332 20.38599 -1.545221 49.99549
10.00033 20.48509 -1.545865 49.93866
10.05033 20.58577 -1.546530 49.87181
10.10033 20.68511 -1.546989 49.90966
10.15033 20.78558 -1.547175 49.91632
10.20033 20.88523 -1.547244 50.07396
10.25033 20.98476 -1.547279 49.95989
10.30033 21.08440 -1.547426 50.00942
10.35033 21.18406 -1.547722 49.94494
10.40033 21.28395 -1.547971 49.95202
10.45033 21.38278 -1.548474 50.13854
10.50034 21.48337 -1.548815 49.91688
10.55033 21.58325 -1.549554 50.00032
10.60033 21.68310 -1.550224 49.98342
10.65033 21.78320 -1.551000 49.83935
10.70033 21.88304 -1.551651 49.98828
10.75034 21.98252 -1.552346 49.89190
10.80033 22.08242 -1.552959 50.01010
10.85033 22.18333 -1.553435 50.16040
10.90033 22.28287 -1.553961 49.71564
10.95033 22.38344 -1.554671 49.55404
11.00034 22.48345 -1.555269 50.15534
11.05033 22.58186 -1.555878 50.13176
11.10033 22.68293 -1.556548 50.15438
11.15033 22.78298 -1.557206 49.75004
11.20033 22.88278 -1.557801 49.87372
11.25034 22.98229 -1.558386 50.06215
11.30033 23.08226 -1.559053 49.85922
11.35033 23.18313 -1.559697 49.96722
11.40033 23.28256 -1.560241 49.94680
11.45033 23.38235 -1.560924 50.09486
11.50034 23.48271 -1.561578 49.86254
11.55033 23.58270 -1.562173 50.03044
11.60033 23.68248 -1.562979 50.12459
11.65033 23.78310 -1.563633 50.12660
11.70033 23.88239 -1.564308 49.94317
11.75034 23.98189 -1.564960 49.98132
11.80033 24.08230 -1.565706 49.96584
11.85033 24.18192 -1.566279 49.90453
11.90033 24.28087 -1.567006 49.98104
11.95033 24.38261 -1.567415 50.04394
12.00034 24.48255 -1.567922 50.06958
12.05033 24.58192 -1.568501 49.94338
12.10033 24.68194 -1.568906 50.07958
12.15033 24.78233 -1.569510 49.70148
12.20033 24.88246 -1.570155 50.00570
12.25034 24.98136 -1.570872 49.96276
12.30033 25.08176 -1.571669 49.85816
12.35033 25.18196 -1.572335 50.10790
12.40033 25.28138 -1.573073 49.99437
12.45033 25.38148 -1.573887 49.86266
12.50034 25.48152 -1.574681 50.04738
12.55033 25.58191 -1.575334 50.02029
12.60033 25.68129 -1.575936 49.97350
12.65033 25.78149 -1.576603 50.15097
12.70033 25.88210 -1.577019 49.81357
12.75034 25.98084 -1.577535 49.92540
12.80033 26.08153 -1.578047 49.94205
12.85033 26.18144 -1.578654 50.18112
12.90033 26.28058 -1.579122 49.96289
12.95034 26.38005 -1.579676 49.98503
13.00034 26.48015 -1.580337 49.97389
13.05033 26.58035 -1.581192 49.96802
13.10033 26.67988 -1.581968 49.79984
13.15033 26.78044 -1.582755 49.98648
13.20034 26.88059 -1.583638 50.12660
13.25034 26.98120 -1.584596 50.15280
13.30033 27.08028 -1.585472 49.94574
13.35033 27.17973 -1.586217 50.05606
13.40033 27.27866 -1.587092 50.05269
13.45034 27.37958 -1.587932 50.10546
13.50034 27.48025 -1.588772 49.94813
13.55033 27.58056 -1.589759 49.86974
13.60033 27.67970 -1.590730 49.93420
13.65033 27.78046 -1.591653 50.02794
13.70034 27.88008 -1.592948 49.90533
13.75034 27.98096 -1.594179 49.83047
13.80033 28.08028 -1.595354 49.82965
13.85033 28.18060 -1.596534 49.98996
13.90033 28.28024 -1.597609 50.03550
13.95034 28.37970 -1.598495 49.94384
14.00034 28.48034 -1.599272 50.06996
14.05033 28.57900 -1.600121 49.91122
14.10033 28.67947 -1.600784 50.04400
14.15033 28.77884 -1.601338 49.96293
14.20034 28.87860 -1.602076 49.90583
14.25034 28.97802 -1.602601 49.99478
14.30033 29.07905 -1.603116 49.91478
14.35033 29.17842 -1.604119 50.03170
14.40033 29.27820 -1.605148 49.94708
14.45034 29.37820 -1.606236 50.14011
14.50034 29.47920 -1.607481 49.99858
14.55033 29.57759 -1.608743 49.89922
14.60033 29.67817 -1.610194 50.05844
14.65033 29.77662 -1.611725 50.05332
14.70034 29.87688 -1.613452 49.88955
14.75034 29.97650 -1.615275 49.98234
14.80033 30.07668 -1.617483 49.89590
14.85033 30.17641 -1.619892 50.09770
14.90033 30.27663 -1.622654 50.11326
14.95034 30.37631 -1.625946 49.82711
15.00034 30.47553 -1.629936 50.06015
15.05033 30.57461 -1.634464 49.86339
15.10033 30.67490 -1.639447 49.89702
15.15033 30.77418 -1.645128 50.12394
15.20034 30.87358 -1.652208 49.85768
15.25034 30.97166 -1.661141 50.08426
15.30033 31.07135 -1.676368 49.98840
15.35033 31.16943 -1.700780 50.00740
15.40033 31.26693 -1.733105 50.19641
15.45034 31.36458 -1.773427 50.02274
15.50034 31.46154 -1.818918 49.89284
15.55033 31.55746 -1.872313 50.09421
15.60033 31.65371 -1.930397 50.14659
15.65033 31.74853 -1.995383 50.10746
15.70034 31.84439 -2.062289 50.13040
15.75034 31.93888 -2.133374 50.16884
15.80033 32.03257 -2.202673 50.01712
15.85033 32.12659 -2.273444 50.02972
15.90033 32.22176 -2.345334 49.47464
15.95034 32.31648 -2.413070 49.99508
16.00033 32.41080 -2.477102 50.07297
16.05033 32.50566 -2.537307 50.02904
16.10033 32.60040 -2.596618 49.88510
16.15033 32.69633 -2.642815 49.74030
16.20033 32.79281 -2.689668 49.87756
16.25033 32.88875 -2.734193 49.96876
16.30033 32.98488 -2.772603 50.08296
16.35033 33.08198 -2.804076 49.83060
16.40033 33.17960 -2.834864 50.02484
16.45033 33.27650 -2.862689 49.30180
16.50033 33.37518 -2.884978 49.96984
16.55033 33.47211 -2.904490 49.89712
16.60033 33.57084 -2.921492 49.70403
16.65033 33.66836 -2.938820 50.00674
16.70033 33.76681 -2.954375 49.99430
16.75033 33.86524 -2.968653 49.83820
16.80033 33.96442 -2.981941 49.84471
16.85033 34.06213 -2.995408 50.02556
16.90033 34.16137 -3.007398 49.82424
16.95033 34.25880 -3.020685 49.96194
17.00033 34.35934 -3.032922 50.11766
17.05033 34.45758 -3.043968 49.95912
17.10033 34.55775 -3.055789 51.00056
17.15033 34.65648 -3.066272 50.18562
17.20033 34.75588 -3.076546 50.13703
17.25033 34.85454 -3.085760 50.06376
17.30033 34.95434 -3.094267 49.85896
17.35033 35.05374 -3.101751 49.92182
17.40033 35.15340 -3.108337 50.17746
17.45033 35.25213 -3.114129 49.92582
17.50033 35.35212 -3.119007 49.94858
17.55033 35.45294 -3.122843 48.42003
17.60033 35.55246 -3.125751 49.17422
17.65033 35.65381 -3.127808 49.49768
17.70033 35.75362 -3.128633 49.92408
17.75033 35.85446 -3.128007 50.12183
17.80033 35.95374 -3.125617 50.02681
17.85033 36.05598 -3.121572 50.08044
17.90033 36.15625 -3.115240 49.89664
17.95033 36.25712 -3.105159 50.09960
18.00033 36.35845 -3.095750 50.05280
18.05033 36.46048 -3.087134 48.82384
18.10033 36.56085 -3.080887 49.82406
18.15033 36.66011 -3.078106 50.10433
18.20033 36.75872 -3.083822 50.01864
18.25033 36.85610 -3.112216 49.78010
18.30033 36.95416 -3.145350 50.05122
18.35033 37.05017 -3.208522 50.15111
18.40033 37.14719 -3.230020 51.12334
18.45033 37.24464 -3.243754 50.55000
18.50033 37.34286 -3.254290 50.04296
18.55033 37.44184 -3.259781 49.92378
18.60033 37.54277 -3.262350 50.02759
18.65033 37.64377 -3.244941 50.00042
18.70033 37.74748 -3.153237 50.05238
18.75033 37.85437 -3.018850 50.03950
18.80033 37.96438 -2.864564 50.04236
18.85033 38.07559 -2.702781 49.94464
18.90033 38.18887 -2.555480 50.07600
18.95033 38.30024 -2.431102 49.86534
19.00033 38.40922 -2.321742 49.97964
19.05033 38.51865 -2.229517 49.91754
19.10033 38.62605 -2.151610 49.93008
19.15033 38.73298 -2.085694 49.94574
19.20033 38.83813 -2.024834 50.16924
19.25033 38.94297 -1.972723 49.75496
19.30033 39.04730 -1.927851 50.01878
19.35033 39.15224 -1.890567 50.12046
19.40033 39.25542 -1.858652 50.04180
19.45033 39.35802 -1.836628 49.96589
19.50033 39.46022 -1.816250 50.09088
19.55033 39.56210 -1.801709 49.96890
19.60033 39.66358 -1.788641 50.22446
19.65033 39.76468 -1.779459 49.88037
19.70033 39.86596 -1.771604 49.86766
19.75033 39.96687 -1.762767 50.01370
19.80033 40.06758 -1.754940 49.98393
19.85033 40.16859 -1.747619 49.95526
19.90033 40.26976 -1.740838 50.07935
19.95033 40.36981 -1.734489 49.93863
20.00033 40.47024 -1.728648 50.05272
20.05033 40.56979 -1.723596 50.09247
20.10033 40.67035 -1.719022 50.01000
20.15033 40.77106 -1.714901 50.29140
20.20033 40.87042 -1.711149 50.13272
20.25033 40.97080 -1.707943 49.94708
20.30033 41.07082 -1.705344 49.77752
20.35033 41.17016 -1.703231 50.15844
20.40033 41.27071 -1.701424 49.96696
20.45033 41.37028 -1.700037 50.10836
20.50033 41.47120 -1.698920 49.93396
20.55033 41.56918 -1.697991 50.16541
20.60033 41.67024 -1.697284 50.04840
20.65033 41.76914 -1.696763 50.01816
20.70033 41.86914 -1.696363 50.05840
20.75033 41.96928 -1.696364 50.00829
20.80033 42.06885 -1.696592 50.19529
20.85033 42.16964 -1.696756 50.03366
20.90033 42.26933 -1.697303 50.07390
20.95033 42.36916 -1.698004 49.83652
21.00033 42.46920 -1.698911 49.94534
21.05033 42.56919 -1.699745 49.88060
21.10033 42.66893 -1.700797 50.02404
21.15033 42.76896 -1.701819 49.91645
21.20033 42.86861 -1.702632 50.00858
21.25033 42.96798 -1.703568 49.86211
21.30033 43.06832 -1.704762 50.05591
21.35033 43.16790 -1.705746 49.96713
21.40033 43.26821 -1.706833 49.86384
21.45033 43.36812 -1.708064 49.96576
21.50033 43.46772 -1.709124 50.03064
21.55033 43.56850 -1.710225 49.90894
21.60033 43.66773 -1.711335 49.83562
21.65033 43.76785 -1.712540 49.96199
21.70033 43.86812 -1.713473 49.83780
21.75033 43.96700 -1.714529 49.91466
21.80033 44.06676 -1.715562 50.06252
21.85033 44.16744 -1.716452 49.78140
21.90033 44.26706 -1.717476 49.95621
21.95033 44.36785 -1.718554 50.10190
22.00033 44.46672 -1.719522 49.96417
22.05033 44.56668 -1.720484 49.98104
22.10033 44.66630 -1.721465 50.00727
22.15033 44.76626 -1.722244 49.74325
22.20033 44.86680 -1.723354 50.23910
22.25033 44.96650 -1.724353 49.84984
22.30033 45.06606 -1.725388 50.03188
22.35033 45.16548 -1.726359 50.20103
22.40033 45.26570 -1.727454 50.01170
22.45033 45.36543 -1.728370 49.38594
22.50033 45.46511 -1.729476 50.07400
22.55033 45.56568 -1.730580 50.07617
22.60033 45.66507 -1.731734 49.87618
22.65033 45.76425 -1.732914 49.94915
22.70033 45.86418 -1.734053 49.75642
22.75033 45.96466 -1.735359 49.98170
22.80033 46.06448 -1.736961 49.95056
22.85033 46.16472 -1.738586 50.49521
22.90033 46.26418 -1.739966 49.91108
22.95033 46.36507 -1.741436 49.95670
23.00033 46.46494 -1.742617 50.06460
23.05033 46.56482 -1.743972 50.01730
23.10033 46.66504 -1.745211 50.06871
23.15033 46.76472 -1.746312 49.44531
23.20033 46.86460 -1.747574 50.15465
23.25033 46.96433 -1.748597 49.79343
23.30033 47.06456 -1.749528 49.85448
23.35033 47.16402 -1.750630 49.78384
23.40033 47.26414 -1.751563 50.12281
23.45033 47.36328 -1.752612 49.76317
23.50033 47.46290 -1.753647 49.18711
23.55033 47.56316 -1.754779 50.10214
23.60033 47.66286 -1.755765 49.93892
23.65033 47.76234 -1.756711 50.14216
23.70033 47.86170 -1.757385 50.13384
23.75033 47.96221 -1.758158 50.13000
23.80033 48.06182 -1.759262 49.94094
23.85033 48.16150 -1.760275 49.97412
23.90033 48.26131 -1.761512 50.01920
23.95033 48.36107 -1.762840 50.07314
24.00033 48.46140 -1.764413 50.26046
24.05033 48.56058 -1.765741 50.02700
24.10033 48.66157 -1.767299 50.04686
24.15033 48.76148 -1.768840 50.02978
24.20033 48.86062 -1.770211 49.87840
24.25033 48.96060 -1.771711 50.01220
24.30033 49.06125 -1.773209 50.04966
24.35033 49.16080 -1.774926 49.74376
24.40033 49.26050 -1.776394 50.17598
24.45033 49.36108 -1.777956 50.05648
24.50033 49.46080 -1.779409 50.18917
24.55033 49.56134 -1.781004 50.03138
24.60033 49.66100 -1.782392 50.02646
24.65033 49.76076 -1.783591 50.00297
24.70033 49.86047 -1.784820 49.97684
24.75033 49.96075 -1.786171 50.02055
24.80033 50.06036 -1.787716 50.01403
24.85033 50.16032 -1.788884 49.99125
24.90033 50.26032 -1.790276 49.92661
24.95033 50.35963 -1.791452 50.09478
25.00033 50.45933 -1.792779 49.88530
25.05033 50.55872 -1.794087 49.92470
25.10033 50.65804 -1.795488 50.13326
25.15033 50.75954 -1.796962 50.10942
25.20033 50.85864 -1.798482 50.00170
25.25033 50.95754 -1.800162 49.83769
25.30033 51.05668 -1.801472 50.10664
25.35033 51.15767 -1.802944 50.13518
25.40033 51.25688 -1.804445 50.02983
25.45033 51.35713 -1.805983 50.01535
25.50033 51.45681 -1.807535 50.14391
25.55033 51.55684 -1.809322 49.98742
25.60033 51.65714 -1.811333 50.11167
25.65033 51.75719 -1.813059 49.83060
25.70033 51.85665 -1.814850 49.97165
25.75033 51.95771 -1.816614 49.89176
25.80033 52.05701 -1.818346 50.16328
25.85033 52.15760 -1.820092 50.09180
25.90033 52.25688 -1.821541 50.13504
25.95033 52.35722 -1.822892 50.03421
26.00033 52.45659 -1.824376 49.42317
26.05033 52.55656 -1.825729 50.09090
26.10033 52.65662 -1.827298 49.83877
26.15033 52.75598 -1.828928 49.94742
26.20033 52.85580 -1.830441 49.96134
26.25033 52.95606 -1.831974 50.06624
26.30033 53.05580 -1.833621 50.01404
26.35033 53.15530 -1.835024 49.96034
26.40033 53.25503 -1.836512 50.11846
26.45033 53.35462 -1.838092 50.07731
26.50033 53.45500 -1.839513 50.01989
26.55033 53.55472 -1.840950 49.99141
26.60033 53.65386 -1.842632 50.10086
26.65033 53.75429 -1.844225 50.13627
26.70033 53.85450 -1.846039 50.11552
26.75033 53.95425 -1.847827 50.06484
26.80033 54.05310 -1.849675 50.15594
26.85033 54.15360 -1.851324 50.05534
26.90033 54.25347 -1.853172 49.84744
26.95033 54.35358 -1.854989 49.95620
27.00033 54.45366 -1.856578 49.71965
27.05033 54.55309 -1.858295 49.88482
27.10033 54.65187 -1.859878 49.96672
27.15033 54.75292 -1.861412 50.02302
27.20033 54.85188 -1.862849 49.99283
27.25033 54.95182 -1.864306 50.01211
27.30033 55.05154 -1.865854 50.04206
27.35033 55.15190 -1.867582 50.03617
27.40033 55.25169 -1.869338 49.94545
27.45033 55.35093 -1.871151 49.98378
27.50033 55.45102 -1.873114 50.15263
27.55033 55.55156 -1.875092 50.08962
27.60033 55.65140 -1.877098 49.91546
27.65033 55.75046 -1.879118 49.81574
27.70033 55.85040 -1.881041 49.38525
27.75033 55.95070 -1.883186 49.87114
27.80033 56.05157 -1.885023 49.92160
27.85033 56.15060 -1.887157 50.01303
27.90033 56.25084 -1.889026 50.05456
27.95033 56.34970 -1.890974 49.76766
28.00033 56.45043 -1.892609 50.01644
28.05033 56.54924 -1.894376 49.84586
28.10033 56.65014 -1.896250 49.90369
28.15033 56.74938 -1.897993 49.95960
28.20033 56.84950 -1.899995 50.08200
28.25033 56.94946 -1.902053 49.95144
28.30033 57.04876 -1.904009 49.97686
28.35033 57.14852 -1.905980 49.87730
28.40033 57.24825 -1.907935 49.99539
28.45033 57.34788 -1.909785 50.13098
28.50033 57.44765 -1.911237 50.09466
28.55033 57.54702 -1.912810 50.06896
28.60033 57.64628 -1.914503 50.07150
28.65033 57.74724 -1.916132 50.00620
28.70033 57.84662 -1.917877 50.11820
28.75033 57.94691 -1.919710 50.14517
28.80033 58.04651 -1.921599 50.02213
28.85033 58.14544 -1.923433 49.97053
28.90033 58.24536 -1.925454 49.96467
28.95033 58.34561 -1.927481 50.09938
29.00033 58.44431 -1.929652 50.13456
29.05033 58.54498 -1.931891 49.87489
29.10033 58.64504 -1.934184 49.94672
29.15033 58.74462 -1.936410 50.03724
29.20033 58.84540 -1.938741 49.83372
29.25033 58.94459 -1.941032 49.93832
29.30033 59.04442 -1.943484 49.98781
29.35033 59.14372 -1.945880 50.12276
29.40033 59.24360 -1.948064 50.05484
29.45033 59.34281 -1.950171 49.90085
29.50033 59.44184 -1.951931 49.87131
29.55033 59.53920 -1.954446 49.83097
29.60033 59.61140 -1.927158 49.96356
29.65033 59.66226 -1.791806 50.06525
29.70033 59.70046 -1.648936 50.09972
29.75033 59.73359 -1.502264 49.98453
29.80033 59.76165 -1.367319 49.98485
29.85033 59.78392 -1.231364 49.95526
29.90033 59.80406 -1.119230 50.14246
29.95033 59.82089 -1.015538 50.22066
30.00033 59.83560 -0.9182887 49.93475
30.05033 59.84704 -0.8404266 49.87750
30.10033 59.85747 -0.7689404 49.98744
30.15033 59.86718 -0.7084805 49.85789
30.20033 59.87385 -0.6578540 49.86685
30.25033 59.88071 -0.6150100 49.92294
30.30033 59.88706 -0.5746311 49.98740
30.35033 59.89188 -0.5454104 49.96138
30.40033 59.89560 -0.5187064 49.91600
30.45033 59.89957 -0.4980011 50.05029
30.50033 59.90302 -0.4807368 49.89739
30.55033 59.90600 -0.4645459 49.99837
30.60033 59.90778 -0.4533398 49.94429
30.65033 59.91012 -0.4430234 50.13781
30.70033 59.91132 -0.4336874 50.15269
30.75033 59.91334 -0.4249361 49.91554
30.80033 59.91518 -0.4169024 50.00869
30.85033 59.91607 -0.4088161 49.90956
30.90033 59.91670 -0.4010686 50.01645
30.95033 59.91822 -0.3933182 50.01928
31.00033 59.91922 -0.3861998 49.77228
31.05033 59.92002 -0.3794334 50.08165
31.10033 59.92132 -0.3733205 50.09101
31.15033 59.92230 -0.3678006 50.08926
31.20033 59.92245 -0.3628633 50.04671
31.25033 59.92312 -0.3584412 49.81034
31.30033 59.92400 -0.3543341 49.91750
31.35033 59.92496 -0.3506910 49.89632
31.40033 59.92410 -0.3474592 50.06114
31.45033 59.92527 -0.3444893 50.13508
31.50033 59.92610 -0.3418083 49.89758
31.55033 59.92645 -0.3392220 49.89972
31.60033 59.92639 -0.3370862 50.19312
31.65033 59.92835 -0.3352194 50.19899
31.70033 59.92778 -0.3335006 50.07194
31.75033 59.92768 -0.3318230 50.08638
31.80033 59.92720 -0.3301710 49.98441
31.85034 59.92808 -0.3284283 49.92197
31.90033 59.92780 -0.3267080 50.18854
31.95033 59.92879 -0.3252351 50.01282
32.00033 59.92802 -0.3240228 49.99654
32.05033 59.92860 -0.3230242 50.00504
32.10034 59.92864 -0.3224082 50.12734
32.15033 59.92844 -0.3219528 49.86000
32.20033 59.92875 -0.3217401 50.00403
32.25033 59.92912 -0.3213818 49.84622
32.30033 59.92925 -0.3211637 49.91110
32.35034 59.92960 -0.3210207 50.00120
32.40033 59.92950 -0.3206844 49.91514
32.45033 59.93061 -0.3204278 49.95500
-2.000000 1.000000 0.0000000 0.0000000
32.54700 59.92804 -0.3202791 50.11053
32.59700 59.90196 -0.2849672 49.92724
32.64700 59.85210 -0.1419241 49.87502
32.69700 59.79236 .002823732 49.92304
32.74700 59.72412 0.1545378 50.09441
32.79700 59.65191 0.2969452 50.07312
32.84700 59.57354 0.4321060 50.07986
32.89700 59.49374 0.5533207 50.06594
32.94700 59.40988 0.6611670 49.92863
32.99700 59.32363 0.7587171 49.96854
33.04700 59.23599 0.8404559 49.92428
33.09700 59.14724 0.9107201 49.67908
33.14700 59.05450 0.9746194 49.89933
33.19700 58.96330 1.029307 49.93463
33.24700 58.86968 1.075405 49.99717
33.29700 58.77539 1.113397 49.94500
33.34700 58.68060 1.148270 49.96363
33.39700 58.58445 1.174586 49.91588
33.44700 58.48882 1.198506 50.03970
33.49700 58.39189 1.218920 49.94806
33.54700 58.29511 1.235688 49.90859
33.59700 58.19747 1.249325 49.94366
33.64700 58.10032 1.263036 50.13674
33.69700 58.00278 1.273206 49.85498
33.74700 57.90381 1.282365 49.72604
33.79700 57.80590 1.291484 50.06946
33.84700 57.70780 1.301101 50.00090
33.89700 57.60934 1.309576 50.00748
33.94700 57.51087 1.318292 50.02530
33.99700 57.41101 1.326460 50.16860
34.04700 57.31354 1.334465 50.10796
34.09700 57.21363 1.341971 49.93493
34.14700 57.11455 1.349003 50.16172
34.19700 57.01441 1.355779 50.01168
34.24700 56.91614 1.362338 50.07840
34.29700 56.81748 1.368581 49.98516
34.34700 56.71762 1.374176 49.88356
34.39700 56.61796 1.379484 49.92415
34.44700 56.51826 1.384508 50.01097
34.49700 56.41907 1.389343 50.08469
34.54700 56.31900 1.394011 50.09539
34.59700 56.22074 1.398360 50.12679
34.64700 56.12022 1.402397 50.05012
34.69700 56.02124 1.406216 49.93320
34.74700 55.92112 1.409795 50.01335
34.79700 55.82338 1.413166 50.22983
34.84700 55.72268 1.416241 50.19152
34.89700 55.62310 1.419092 49.98993
34.94700 55.52384 1.421724 49.90480
34.99700 55.42589 1.424465 50.04698
35.04700 55.32526 1.427102 50.06208
35.09700 55.22584 1.429951 50.03662
35.14700 55.12630 1.432530 50.12198
35.19700 55.02666 1.435354 50.14320
35.24700 54.92682 1.437981 50.06206
35.29700 54.82754 1.440438 50.09347
35.34700 54.72755 1.442879 50.01084
35.39700 54.62782 1.445508 50.08246
35.44700 54.52851 1.448066 49.91780
35.49700 54.42887 1.450482 50.01884
35.54700 54.32911 1.452921 50.07248
35.59700 54.23000 1.455246 50.03828
35.64700 54.12988 1.457463 50.11020
35.69700 54.02974 1.459622 49.85976
35.74700 53.93056 1.461746 50.03228
35.79700 53.83090 1.463858 49.83200
35.84700 53.72988 1.466016 49.93710
35.89700 53.63115 1.468237 50.04230
35.94700 53.53039 1.470376 49.86320
35.99700 53.43086 1.472523 49.86233
36.04700 53.33106 1.474454 49.92572
36.09700 53.23132 1.476276 49.95761
36.14700 53.13110 1.478204 50.01143
36.19700 53.03165 1.480013 49.87570
36.24700 52.93268 1.481714 50.02754
36.29700 52.83199 1.483455 49.81977
36.34700 52.73245 1.485116 49.98129
36.39700 52.63300 1.486766 50.09387
36.44700 52.53356 1.488482 50.15054
36.49700 52.43392 1.490303 49.83622
36.54700 52.33410 1.492164 49.94119
36.59700 52.23457 1.493976 49.96498
36.64700 52.13438 1.495944 49.99551
36.69700 52.03528 1.497856 50.05908
36.74700 51.93506 1.499661 49.93972
36.79700 51.83574 1.501402 50.16300
36.84700 51.73524 1.503061 50.00122
36.89700 51.63618 1.504714 49.92618
36.94700 51.53560 1.506417 50.05370
36.99700 51.43634 1.508030 49.90558
37.04700 51.33715 1.509779 50.06616
37.09700 51.23740 1.511395 49.91016
37.14700 51.13741 1.513146 49.97592
37.19700 51.03688 1.514907 49.94016
37.24700 50.93582 1.516505 50.12682
37.29700 50.83742 1.518308 50.13372
37.34700 50.73656 1.520161 49.75464
37.39700 50.63648 1.521927 50.00106
37.44700 50.53754 1.523641 49.89541
37.49700 50.43768 1.525194 49.97000
37.54700 50.33766 1.526677 49.96390
37.59700 50.23861 1.528145 50.05628
37.64700 50.13830 1.529252 49.79468
37.69700 50.03802 1.530287 49.86738
37.74700 49.93832 1.531234 50.05826
37.79700 49.83878 1.532230 49.94676
37.84700 49.74028 1.533310 50.04931
37.89700 49.63984 1.534396 49.87246
37.94700 49.54066 1.535472 49.89691
37.99700 49.44106 1.536676 49.88736
38.04700 49.34060 1.537849 50.04508
38.09700 49.24040 1.539202 50.21205
38.14700 49.14144 1.540524 50.18357
38.19700 49.04141 1.541959 49.94918
38.24700 48.94304 1.543374 50.10838
38.29700 48.84144 1.544898 50.01233
38.34700 48.74219 1.546302 50.12293
38.39700 48.64260 1.547775 49.97592
38.44700 48.54210 1.549367 50.00831
38.49700 48.44258 1.550936 50.09484
38.54700 48.34381 1.552342 49.98125
38.59700 48.24273 1.553903 50.08553
38.64700 48.14312 1.555501 49.97182
38.69700 48.04326 1.557119 50.59985
38.74700 47.94394 1.558709 49.96600
38.79700 47.84356 1.560100 50.06055
38.84700 47.74322 1.561700 49.79824
38.89700 47.64384 1.563441 50.11646
38.94700 47.54238 1.565129 49.95114
38.99700 47.44364 1.566805 49.97338
39.04700 47.34338 1.568428 50.02466
39.09700 47.24361 1.569729 50.05974
39.14700 47.14383 1.571174 50.01837
39.19700 47.04403 1.572338 50.10067
39.24700 46.94339 1.573490 49.90637
39.29700 46.84352 1.574532 49.98609
39.34700 46.74388 1.575495 49.87164
39.39700 46.64480 1.576490 49.97408
39.44700 46.54488 1.577288 50.01992
39.49700 46.44555 1.578371 49.96108
39.54700 46.34528 1.579232 49.87956
39.59700 46.24578 1.580192 50.05752
39.64700 46.14507 1.581206 49.88789
39.69700 46.04622 1.582377 50.10231
39.74700 45.94621 1.583472 50.04520
39.79700 45.84744 1.584604 49.87187
39.84700 45.74736 1.585821 49.97698
39.89700 45.64734 1.587088 50.00000
39.94700 45.54846 1.588419 50.04000
39.99700 45.44796 1.589748 49.38425
40.04700 45.34770 1.591224 49.81935
40.09700 45.24731 1.592689 50.06989
40.14700 45.14750 1.593976 49.96088
40.19700 45.04790 1.595264 49.82105
40.24700 44.94804 1.596524 49.81039
40.29700 44.84844 1.597556 49.90523
40.34700 44.74854 1.598683 49.75056
40.39700 44.64893 1.599684 49.92680
40.44700 44.54890 1.600659 50.16040
40.49700 44.44940 1.601689 49.90828
40.54700 44.34946 1.602532 50.03951
40.59700 44.24948 1.603658 49.77736
40.64700 44.15064 1.604873 49.88050
40.69700 44.04996 1.606270 49.83703
40.74700 43.94891 1.607669 49.87860
40.79700 43.84956 1.609039 50.16794
40.84700 43.74990 1.610349 50.02212
40.89700 43.64988 1.611766 49.89100
40.94700 43.55004 1.612729 50.02036
40.99700 43.44950 1.613848 49.89721
41.04700 43.35061 1.614828 49.87066
41.09700 43.25153 1.615791 49.98684
41.14700 43.15136 1.616518 49.98409
41.19700 43.05172 1.617315 49.97139
41.24700 42.95162 1.618052 50.01799
41.29700 42.85111 1.618920 49.99708
41.34700 42.75184 1.619610 49.91534
41.39700 42.65195 1.620415 50.04684
41.44700 42.55289 1.621410 49.89072
41.49700 42.45316 1.622077 50.09459
41.54700 42.35209 1.623129 49.93850
41.59700 42.25250 1.623986 49.81678
41.64700 42.15289 1.625103 49.91441
41.69700 42.05334 1.626038 50.05196
41.74700 41.95219 1.627010 50.10175
41.79700 41.85226 1.628100 49.94106
41.84700 41.75286 1.629152 49.96578
41.89700 41.65285 1.630128 49.87434
41.94700 41.55424 1.631116 50.01518
41.99700 41.45326 1.631906 49.95343
42.04700 41.35416 1.632773 50.03409
42.09700 41.25407 1.633701 50.07070
42.14700 41.15300 1.635002 50.09706
42.19700 41.05390 1.636090 50.03630
42.24700 40.95426 1.637234 50.37150
42.29700 40.85348 1.638312 49.84194
42.34700 40.75315 1.639377 49.97698
42.39700 40.65450 1.640234 49.99220
42.44700 40.55476 1.641101 49.95386
42.49700 40.45480 1.641756 50.04926
42.54700 40.35559 1.642393 49.94144
42.59700 40.25546 1.643116 50.02352
42.64700 40.15505 1.643676 49.97913
42.69700 40.05530 1.644369 49.89710
42.74700 39.95574 1.644914 50.03160
42.79700 39.85590 1.645543 49.96400
42.84700 39.75632 1.646171 49.99500
42.89700 39.65656 1.646819 49.97190
42.94700 39.55569 1.647611 49.89627
42.99700 39.45567 1.648353 49.78838
43.04700 39.35666 1.649233 50.06504
43.09700 39.25672 1.649992 50.01242
43.14700 39.15668 1.651010 49.90002
43.19700 39.05634 1.651852 50.07214
43.24700 38.95626 1.652864 50.24912
43.29700 38.85578 1.654006 50.02660
43.34700 38.75759 1.654996 50.06750
43.39700 38.65587 1.656165 50.01010
43.44700 38.55544 1.657246 49.97758
43.49700 38.45622 1.658236 50.01846
43.54700 38.35660 1.659191 50.03768
43.59700 38.25656 1.659896 49.83850
43.64700 38.15735 1.660781 50.05676
43.69700 38.05733 1.661334 50.00866
43.74700 37.95747 1.661925 49.65633
43.79700 37.85744 1.662219 50.80376
43.84700 37.75826 1.662739 49.95313
43.89700 37.65784 1.663189 50.18305
43.94700 37.55792 1.663589 49.82398
43.99700 37.45822 1.663998 49.81816
44.04700 37.35837 1.664257 49.86000
44.09700 37.25837 1.664932 50.06064
44.14700 37.15880 1.665425 50.00720
44.19700 37.05898 1.666044 50.08563
44.24700 36.95839 1.666600 49.96954
44.29700 36.85871 1.667356 50.00816
44.34700 36.75880 1.667879 49.89276
44.39700 36.65975 1.668554 49.78974
44.44700 36.55997 1.669352 50.61061
44.49700 36.45976 1.669922 49.91470
44.54700 36.36017 1.670679 49.95224
44.59700 36.26013 1.671402 50.91200
44.64700 36.15994 1.671912 49.92707
44.69700 36.06050 1.672697 50.08614
44.74700 35.95940 1.673270 49.79590
44.79700 35.86144 1.673706 49.83350
44.84700 35.76062 1.674299 49.91416
44.89700 35.65982 1.675007 50.03760
44.94700 35.56013 1.675855 49.98784
44.99700 35.46006 1.676688 50.10938
45.04700 35.36098 1.677524 50.02824
45.09700 35.26059 1.678461 50.14336
45.14700 35.16031 1.679247 49.97598
45.19700 35.05975 1.679985 49.87079
45.24700 34.96019 1.680564 50.02780
45.29700 34.86078 1.681093 49.75188
45.34700 34.76158 1.681476 50.07705
45.39700 34.66109 1.682017 50.23343
45.44700 34.56058 1.682236 50.04226
45.49700 34.46174 1.682614 49.92300
45.54700 34.36130 1.682911 49.88022
45.59700 34.26187 1.683146 50.02542
45.64700 34.16166 1.683520 49.94853
45.69700 34.06247 1.683840 50.25508
45.74700 33.96238 1.684243 49.98438
45.79700 33.86209 1.684672 50.05334
45.84700 33.76306 1.685099 49.99586
45.89700 33.66275 1.685568 50.14676
45.94700 33.56238 1.686089 49.35562
45.99700 33.46366 1.686748 49.93110
46.04700 33.36258 1.687390 49.90502
46.09700 33.26406 1.688141 49.86478
46.14700 33.16350 1.688918 50.28352
46.19700 33.06460 1.689658 50.12930
46.24700 32.96375 1.690342 50.03858
46.29700 32.86409 1.690824 49.52114
46.34700 32.76343 1.691461 49.74876
46.39700 32.66441 1.692216 49.88914
46.44700 32.56457 1.692813 50.07374
46.49700 32.46426 1.693563 50.07882
46.54700 32.36490 1.694261 49.98356
46.59700 32.26440 1.694953 49.90324
46.64700 32.16480 1.695478 50.06720
46.69700 32.06475 1.696109 49.82884
46.74700 31.96494 1.696715 49.97299
46.79700 31.86480 1.697444 50.18263
46.84700 31.76534 1.698250 50.11434
46.89700 31.66543 1.699096 51.01613
46.94700 31.56441 1.699954 49.78610
46.99700 31.46618 1.701158 49.95216
47.04700 31.36520 1.702666 49.94097
47.09700 31.26659 1.704702 49.91872
47.14700 31.16619 1.707924 49.96958
47.19700 31.06694 1.714446 50.05248
47.24700 30.96758 1.731349 49.86336
47.29700 30.87076 1.781412 50.16166
47.34700 30.77414 1.863718 49.96110
47.39700 30.68076 1.967279 50.01825
47.44700 30.58862 2.112938 49.46900
47.49700 30.50088 2.305472 49.89238
47.54700 30.41744 2.560244 50.14228
47.59700 30.33799 2.868810 49.99764
47.64700 30.26396 3.235302 50.01556
47.69700 30.19387 3.648470 50.05460
47.74700 30.12674 4.086489 50.03066
47.79700 30.06332 4.525063 49.99088
47.84700 29.99808 4.946894 49.73982
47.89700 29.93284 5.311313 50.16404
47.94700 29.86107 5.597405 49.99200
47.99700 29.78442 5.804232 50.01674
48.04700 29.70109 5.918599 50.16256
48.09700 29.61045 5.963829 49.93816
48.14700 29.51402 5.955852 50.06961
48.19700 29.41245 5.896274 49.90104
48.24700 29.30776 5.777686 49.90922
48.29700 29.19771 5.628844 49.93912
48.34700 29.08635 5.458862 49.93094
48.39700 28.97357 5.270099 50.05966
48.44700 28.85823 5.060744 49.95563
48.49700 28.74178 4.844780 49.95032
48.54700 28.62330 4.613154 49.94085
48.59700 28.50600 4.376148 50.03160
48.64700 28.38691 4.145878 50.12134
48.69700 28.26645 3.920315 49.85589
48.74700 28.14826 3.713504 50.00297
48.79700 28.03195 3.506400 50.01594
48.84700 27.91473 3.306195 49.83580
48.89700 27.79823 3.109900 49.87398
48.94700 27.68176 2.920334 50.06626
48.99700 27.56732 2.750586 50.05035
49.04700 27.45276 2.602364 49.99718
49.09700 27.33975 2.473800 49.97369
49.14700 27.23010 2.362379 49.81016
49.19700 27.12032 2.266006 49.98574
49.24700 27.01282 2.186413 49.92812
49.29700 26.90685 2.121075 50.02576
49.34700 26.80102 2.061580 49.98490
49.39700 26.69616 2.013854 50.09033
49.44700 26.59260 1.972678 50.09000
49.49700 26.48969 1.939896 50.00112
49.54700 26.38633 1.911710 50.00650
49.59700 26.28435 1.890322 50.01756
49.64700 26.18238 1.870344 49.91946
49.69700 26.08033 1.854536 49.89394
49.74700 25.97838 1.842943 50.03377
49.79700 25.87760 1.831780 49.98798
49.84700 25.77675 1.823240 50.08924
49.89700 25.67531 1.814198 49.88108
49.94700 25.57525 1.806126 50.16350
49.99700 25.47432 1.798052 50.17766
50.04700 25.37417 1.790419 49.96520
50.09700 25.27370 1.783200 49.80969
50.14700 25.17354 1.776519 50.03931
50.19700 25.07316 1.770523 50.04164
50.24700 24.97256 1.764945 49.83004
50.29700 24.87219 1.760072 49.79310
50.34700 24.77206 1.755632 50.14996
50.39700 24.67132 1.751712 50.00604
50.44700 24.57199 1.748249 49.92235
50.49700 24.47140 1.745146 50.01441
50.54700 24.37123 1.742326 50.03283
50.59700 24.27237 1.739949 49.79812
50.64700 24.17083 1.737852 49.88461
50.69700 24.07197 1.735994 50.00306
50.74700 23.97198 1.734204 49.97488
50.79700 23.87176 1.732789 50.11723
50.84700 23.77144 1.731277 49.82589
50.89700 23.67082 1.730073 50.13654
50.94700 23.57087 1.728996 50.01066
50.99700 23.47090 1.728152 49.78330
51.04700 23.37036 1.727600 50.19441
51.09700 23.27037 1.727120 50.08522
51.14700 23.17065 1.726843 49.87697
51.19700 23.07009 1.726412 49.95491
51.24700 22.97062 1.726018 50.11738
51.29700 22.87010 1.725722 50.04708
51.34700 22.77066 1.725199 50.00163
51.39700 22.67130 1.724731 50.12884
51.44700 22.57054 1.724311 50.07559
51.49700 22.47054 1.723956 50.12272
51.54700 22.37170 1.723640 49.07720
51.59700 22.27050 1.723432 50.03370
51.64700 22.17080 1.723256 49.96313
51.69700 22.07121 1.723230 49.97481
51.74700 21.97114 1.722928 50.00130
51.79700 21.87125 1.722616 50.01205
51.84700 21.77211 1.722469 49.96907
51.89700 21.67158 1.722583 50.08900
51.94700 21.57128 1.722568 49.98670
51.99700 21.47192 1.722572 49.95119
52.04700 21.37203 1.722545 50.03662
52.09700 21.27210 1.722461 50.04176
52.14700 21.17160 1.722396 49.95340
52.19700 21.07247 1.722365 49.88458
52.24700 20.97266 1.722410 49.84167
52.29700 20.87222 1.722162 49.82500
52.34700 20.77289 1.722003 49.92240
52.39700 20.67286 1.722112 49.76797
52.44700 20.57264 1.722084 49.94631
52.49700 20.47278 1.722234 49.99199
52.54700 20.37211 1.722634 50.05019
52.59700 20.27165 1.723094 49.87908
52.64700 20.17299 1.723476 49.91733
52.69700 20.07121 1.724061 49.98180
52.74700 19.97130 1.724456 49.94226
52.79700 19.87155 1.724725 50.09309
52.84700 19.77147 1.724959 50.07876
52.89700 19.67166 1.724965 49.90109
52.94700 19.57179 1.724916 50.02998
52.99700 19.47128 1.724869 50.00762
53.04700 19.37192 1.724669 49.99744
53.09700 19.27138 1.724457 50.04634
53.14700 19.17276 1.724244 49.87066
53.19700 19.07171 1.724046 49.99572
53.24700 18.97219 1.723820 50.11289
53.29700 18.87178 1.723530 50.02734
53.34700 18.77201 1.723547 50.63498
53.39700 18.67265 1.723322 49.85000
53.44700 18.57245 1.723201 49.75623
53.49700 18.47232 1.722965 50.04216
53.54700 18.37282 1.722903 49.96250
53.59700 18.27315 1.722702 50.20244
53.64700 18.17255 1.722652 50.01552
53.69700 18.07326 1.722822 49.84417
53.74700 17.97221 1.722807 50.14156
53.79700 17.87380 1.722820 49.99504
53.84700 17.77343 1.722850 50.08260
53.89700 17.67368 1.722808 49.89448
53.94700 17.57415 1.722764 49.83956
53.99700 17.47418 1.722967 49.84088
54.04700 17.37408 1.722958 49.94684
54.09700 17.27410 1.723090 49.95551
54.14700 17.17384 1.723291 50.06919
54.19700 17.07419 1.723275 49.75246
54.24700 16.97423 1.723213 49.93269
54.29700 16.87459 1.723390 50.06319
54.34700 16.77423 1.723494 50.03023
54.39700 16.67428 1.723662 50.07460
54.44700 16.57513 1.723926 49.91644
54.49700 16.47372 1.724074 50.05661
54.54700 16.37486 1.724294 49.95082
54.59700 16.27428 1.724368 50.02084
54.64700 16.17431 1.724572 50.18083
54.69700 16.07522 1.724451 49.98384
54.74700 15.97594 1.724263 49.89834
54.79700 15.87602 1.724073 50.16334
54.84700 15.77666 1.724084 50.01994
54.89700 15.67692 1.724332 50.15816
54.94700 15.57696 1.724633 49.88267
54.99700 15.47775 1.724920 50.23820
55.04700 15.37779 1.725350 50.10359
55.09700 15.27780 1.725896 50.04004
55.14700 15.17750 1.726265 49.91406
55.19700 15.07772 1.726941 49.84719
55.24700 14.97804 1.727215 49.90953
55.29700 14.87806 1.727604 49.38303
55.34700 14.77920 1.727939 49.98248
55.39700 14.67817 1.728230 50.02554
55.44700 14.57866 1.728524 49.96124
55.49700 14.47842 1.728918 49.96257
55.54700 14.37818 1.729000 49.88149
55.59700 14.27869 1.729196 50.20850
55.64700 14.17868 1.729338 49.91635
55.69700 14.07907 1.729666 49.92011
55.74700 13.97912 1.730070 49.58970
55.79700 13.87897 1.730266 50.03754
55.84700 13.77908 1.730691 49.92943
55.89700 13.67849 1.730927 49.81942
55.94700 13.57816 1.731206 50.08554
55.99700 13.47831 1.731385 49.79291
56.04700 13.37818 1.731427 49.88053
56.09700 13.27759 1.731694 49.79458
56.14700 13.17721 1.731898 50.05957
56.19700 13.07805 1.731825 50.17939
56.24700 12.97766 1.731741 50.03502
56.29700 12.87740 1.731424 50.14622
56.34700 12.77666 1.730948 50.16205
56.39700 12.67702 1.730492 49.93562
56.44700 12.57775 1.730128 49.68593
56.49700 12.47716 1.729736 50.14297
56.54700 12.37682 1.729256 49.88216
56.59700 12.27689 1.728832 49.83757
56.64700 12.17671 1.728308 50.18219
56.69700 12.07786 1.727888 50.00554
56.74700 11.97813 1.727245 49.79080
56.79700 11.87692 1.726960 50.04264
56.84700 11.77782 1.726624 50.04502
56.89700 11.67676 1.726262 50.07648
56.94700 11.57761 1.726168 49.98984
56.99700 11.47742 1.725988 49.98403
57.04700 11.37737 1.725897 50.05028
57.09700 11.27744 1.725850 50.04496
57.14700 11.17686 1.725940 49.86601
57.19700 11.07682 1.726106 50.06913
57.24700 10.97780 1.726254 49.94196
57.29700 10.87665 1.726210 50.08884
57.34700 10.77723 1.726342 50.15721
57.39700 10.67712 1.726296 50.09294
57.44700 10.57731 1.726212 50.19574
57.49700 10.47626 1.725998 49.94597
57.54700 10.37630 1.725752 50.04023
57.59700 10.27671 1.725557 49.83313
57.64700 10.17730 1.725344 50.18090
57.69700 10.07685 1.724910 49.80340
57.74700 9.977570 1.724579 49.99184
57.79700 9.877743 1.724191 49.90483
57.84700 9.777444 1.723934 49.84965
57.89700 9.677179 1.723676 49.31448
57.94700 9.576886 1.723683 50.12739
57.99700 9.476972 1.723532 49.89404
58.04700 9.377701 1.723684 49.94922
58.09700 9.277472 1.723588 49.86232
58.14700 9.177647 1.723699 49.95990
58.19700 9.077434 1.723665 49.97934
58.24700 8.977453 1.723700 50.25043
58.29700 8.877613 1.723538 49.87043
58.34700 8.777782 1.723518 49.84326
58.39700 8.678138 1.723405 49.97510
58.44700 8.578199 1.723221 50.10126
58.49700 8.477603 1.723284 49.79407
58.54700 8.377553 1.723325 49.93311
58.59700 8.278961 1.723375 50.05969
58.64700 8.178634 1.723407 50.14390
58.69700 8.078100 1.723363 49.85680
58.74700 7.979160 1.723370 49.87780
58.79700 7.878550 1.723404 50.25413
58.84700 7.779511 1.723379 50.04383
58.89700 7.679478 1.723224 49.98102
58.94700 7.579316 1.723070 49.92472
58.99700 7.479003 1.722934 50.03784
59.04700 7.378656 1.722595 49.93766
59.09700 7.278961 1.722471 50.06109
59.14700 7.179266 1.722265 49.50276
59.19700 7.079525 1.722029 49.98838
59.24700 6.979429 1.721916 49.96744
59.29700 6.878753 1.721813 49.92306
59.34700 6.778878 1.721635 50.06225
59.39700 6.679593 1.721612 49.96830
59.44700 6.579562 1.721609 50.09336
59.49700 6.479000 1.721673 49.90622
59.54700 6.378718 1.721781 49.90125
59.59700 6.279194 1.721842 49.48217
59.64700 6.179072 1.721800 50.04074
59.69700 6.078590 1.721910 50.02348
59.74700 5.979024 1.721885 50.08617
59.79700 5.878941 1.721849 49.91340
59.84700 5.778711 1.722011 49.90393
59.89700 5.679474 1.721864 49.73830
59.94700 5.579308 1.721844 50.03027
59.99700 5.478814 1.721790 50.07657
60.04700 5.379304 1.721631 49.90791
60.09700 5.279211 1.721534 50.18856
60.14700 5.179148 1.721666 49.91348
60.19700 5.079531 1.721626 49.85737
60.24700 4.978928 1.721638 50.08856
60.29700 4.879396 1.721514 49.85561
60.34700 4.779559 1.721474 50.12578
60.39700 4.679696 1.721200 50.23056
60.44700 4.580006 1.721155 50.07384
60.49700 4.480482 1.721082 50.23869
60.54700 4.379126 1.720835 49.87156
60.59700 4.280392 1.720675 49.98764
60.64700 4.180178 1.720591 49.96552
60.69700 4.079321 1.720432 50.08061
60.74700 3.979668 1.720314 49.97240
60.79700 3.879645 1.720382 49.97715
60.84700 3.779610 1.720333 50.08284
60.89700 3.681311 1.720362 49.94283
60.94700 3.580066 1.720259 49.72524
60.99700 3.482210 1.720171 50.02030
61.04700 3.381609 1.720086 50.11165
61.09700 3.282052 1.720083 50.14241
61.14700 3.181919 1.720228 49.88310
61.19700 3.081769 1.720527 50.02600
61.24700 2.983269 1.720869 49.61700
61.29700 2.881600 1.721339 50.03964
61.34700 2.782840 1.721808 49.88233
61.39700 2.682174 1.722318 50.12366
61.44700 2.581629 1.722582 50.13672
61.49700 2.482048 1.722868 49.91112
61.54700 2.382223 1.722883 50.04574
61.59700 2.283162 1.722621 50.02844
61.64700 2.182720 1.722467 50.02079
61.69700 2.082295 1.722279 50.16581
61.74700 1.982323 1.722185 49.84794
61.79700 1.883779 1.722080 49.43884
61.84700 1.783031 1.722148 49.83693
61.89700 1.683594 1.722111 50.01748
61.94700 1.583582 1.722070 49.97933
61.99700 1.483715 1.722150 50.16536
62.04700 1.386723 1.722599 50.01090
62.09700 1.312461 1.689650 50.13860
62.14700 1.262634 1.561840 49.95846
62.19700 1.224502 1.431849 49.97224
62.24700 1.192266 1.298694 50.00858
62.29700 1.165572 1.172702 50.00350
62.34700 1.142386 1.048952 50.02617
62.39700 1.123486 0.9407176 49.91144
62.44700 1.106695 0.8420961 49.78256
62.49700 1.092145 0.7527368 49.85647
62.54700 1.080284 0.6754106 50.09941
62.59700 1.069464 0.6085806 50.04221
62.64700 1.060076 0.5471260 49.83930
62.69700 1.052160 0.4968258 49.95426
62.74700 1.046377 0.4548112 50.08625
62.79700 1.039601 0.4183067 50.04033
62.84700 1.034763 0.3870365 50.03426
62.89700 1.031236 0.3587468 50.06910
62.94700 1.026867 0.3369248 50.01007
62.99700 1.023433 0.3189862 50.13662
63.04700 1.021004 0.3013250 50.12630
63.09700 1.019114 0.2887102 50.05855
63.14700 1.015831 0.2785494 49.89366
63.19700 1.013242 0.2692704 49.99550
63.24700 1.011267 0.2600064 50.03352
63.29700 1.011252 0.2515045 49.98466
63.34700 1.009476 0.2431862 49.99283
63.39700 1.008462 0.2349173 49.92172
63.44700 1.007899 0.2272058 49.80691
63.49700 1.006055 0.2199671 49.94328
63.54700 1.005390 0.2130754 49.96400
63.59700 1.005510 0.2071485 49.81962
63.64700 1.003436 0.2016018 49.81793
63.69700 1.003735 0.1963732 49.88194
63.74700 1.002439 0.1917978 49.96130
63.79700 1.001984 0.1876423 50.01486
63.84700 1.001108 0.1836909 49.96704
63.89700 1.000733 0.1803745 49.93026
63.94700 0.9992462 0.1770590 49.96538
63.99700 1.000243 0.1740511 49.96826
64.04700 0.9992426 0.1714617 49.99086
64.09700 0.9989632 0.1690281 49.91645
64.14700 0.9987579 0.1668770 49.91611
64.19701 0.9981934 0.1647633 49.95060
64.24700 0.9978759 0.1628899 50.12446
64.29700 0.9975069 0.1614505 50.06892
64.34700 0.9975501 0.1599160 50.10684
64.39700 0.9980181 0.1586243 50.12485
64.44701 0.9977746 0.1573348 50.19574
64.49700 0.9971832 0.1563435 49.97220
64.54700 0.9964852 0.1554694 50.26724
64.59700 0.9954842 0.1545804 49.92406
64.64700 0.9958251 0.1536956 50.02983
64.69701 0.9962116 0.1528885 50.03854
64.74700 0.9958312 0.1519655 50.00263
64.79700 0.9953968 0.1513454 50.13594
-2.000000 2.000000 0.0000000 0.0000000