File: imagens/notebooks/dados experimentais/dsc/Karl_TTAB100 Ur 45%.txt
CLOSED
Version	1.0
Language	English
Run	1
RunSerial	156
Instrument	DSC Q100 V9.9 Build 303
Module	DSC Standard Cell FC
Operator	LL
File	\\Niger\ta\Data\DSC\2018\Geral\Karl_TTAB100 Ur 45%.001
ProcName	Karl
InstSerial	0100-1211
Sample	TTAB100 Ur 45%
Size	13.8900	mg
Method	Karl
Comment
Xcomment	Pan: Aluminum Hermetic
Xcomment	Gas1: Nitrogen 50.0 ml/min
Xcomment	Gas2: Nitrogen 0.0 ml/min
Text
Exotherm	UP
Kcell	1.09030
Calib	-11.7822
TempCal	1	pts	158.71	156.60
TzeroDt	-90.0515 -0.0093 2.2263
TzeroDtz	-90.0515 0.0466 2.4421
InstCalFile	Tzero: \\Niger\ta\Data\DSC\CALIBRATION\20122016\CALIBRATION\0_RCS_12_20_2016 17_23_31.TZR
InstCalFile	Baseline: \\Niger\ta\Data\DSC\CALIBRATION\20122016\L.Base 20122016
InstCalFile	Sapphire: \\Niger\ta\Data\DSC\CALIBRATION\20122016\Safira 20122017.001
InstCalDate	Tzero 2016-12-20 Time 19:23:31
TempRange	-90.04 to 395.23 °C at 19.96 °C/min Heat Only
AutoZero	Delta T Offset 0.000 uV
AutoZero	Delta T0 Offset 0.000 uV
Controls	Gas 1  Event Off  Sampling 0.2
Cell#	FC-02451
CoolingUnit	RCS
SelHeatFlow	Heat Flow T4 (mW)
AutoAnalysis	Off
MacroFile
Nsig	4
Sig1	Time (min)
Sig2	Temperature (°C)
Sig3	Heat Flow (mW)
Sig4	Sample Purge Flow (mL/min)
Date	2018-05-17
Time	15:51:23
OrgMethod	1: Equilibrate at 1.00 °C
OrgMethod	2: Ramp 2.00 °C/min to 60.00 °C
OrgMethod	3: Isothermal for 3.00 min
OrgMethod	4: Mark end of cycle 1
OrgMethod	5: Ramp 2.00 °C/min to 1.00 °C
OrgMethod	6: Isothermal for 3.00 min
OrgMethod	7: Mark end of cycle 2
OrgFile	C:\TA\Data\DSC\2018\Geral\Karl_TTAB100 Ur 45%.001
3.33324E-4 1.177792 1.248100 50.01010
0.05033332 1.163227 1.100583 49.85800
0.1003333 1.175218 0.9082674 50.15738
0.1503333 1.212012 0.6919174 50.10171
0.2003333 1.260581 0.4706097 49.93892
0.2503333 1.316594 0.2583430 50.01244
0.3003333 1.380312 0.06441407 50.07529
0.3503333 1.448097 -0.1157928 49.91527
0.4003334 1.520074 -0.2835229 49.92056
0.4503334 1.595490 -0.4267132 49.90334
0.5003334 1.675429 -0.5520521 50.01684
0.5503332 1.756762 -0.6616578 50.01261
0.6003332 1.840435 -0.7622714 50.04988
0.6503332 1.925736 -0.8478204 50.00588
0.7003332 2.014118 -0.9219718 50.02963
0.7503332 2.103449 -0.9867569 50.21904
0.8003332 2.193862 -1.040301 50.12480
0.8503332 2.286204 -1.092876 49.95870
0.9003332 2.378094 -1.130275 49.90760
0.9503334 2.471370 -1.169558 49.86272
1.000333 2.565382 -1.199483 50.00196
1.050334 2.659192 -1.227726 50.10918
1.100334 2.754698 -1.251211 49.80500
1.150334 2.850914 -1.269589 50.11034
1.200334 2.946992 -1.288905 50.03538
1.250334 3.042755 -1.302752 49.97607
1.300334 3.139750 -1.316450 50.05376
1.350333 3.236906 -1.328104 50.09070
1.400333 3.334128 -1.338477 50.14590
1.450334 3.430975 -1.349560 50.06926
1.500333 3.529706 -1.358116 50.04556
1.550334 3.627200 -1.367093 49.90510
1.600334 3.725460 -1.375742 50.03775
1.650333 3.822917 -1.384224 49.88584
1.700334 3.921688 -1.392322 49.98828
1.750334 4.019597 -1.400273 49.94804
1.800334 4.118404 -1.407820 49.98794
1.850334 4.217242 -1.414955 50.05443
1.900334 4.315044 -1.421577 49.89274
1.950334 4.415246 -1.428010 49.92744
2.000334 4.513687 -1.433724 50.03372
2.050333 4.612002 -1.439379 50.02461
2.100334 4.711660 -1.444657 49.91461
2.150334 4.810939 -1.449672 49.97930
2.200334 4.909479 -1.454272 49.90201
2.250334 5.009321 -1.458440 49.91506
2.300333 5.108148 -1.462488 50.07116
2.350334 5.207214 -1.466015 49.87484
2.400334 5.306003 -1.469514 50.05071
2.450334 5.406044 -1.472943 50.09989
2.500334 5.504875 -1.476124 50.01274
2.550333 5.604664 -1.479215 49.90369
2.600333 5.704190 -1.481965 49.94470
2.650333 5.803570 -1.484712 49.99719
2.700333 5.902434 -1.487232 49.98574
2.750333 6.002192 -1.489633 49.89054
2.800333 6.100944 -1.491970 50.12602
2.850333 6.201230 -1.494185 49.98217
2.900333 6.300098 -1.496422 49.98488
2.950333 6.400410 -1.498495 50.03850
3.000333 6.499493 -1.500668 49.98217
3.050333 6.599228 -1.502483 50.12590
3.100333 6.699668 -1.504103 49.96263
3.150333 6.798992 -1.505735 50.04680
3.200333 6.898589 -1.507334 50.17406
3.250333 6.998443 -1.508812 50.28400
3.300333 7.098110 -1.510369 50.11258
3.350333 7.197753 -1.511670 49.87896
3.400333 7.297109 -1.512874 50.01855
3.450333 7.396156 -1.514284 50.11586
3.500333 7.496318 -1.515634 50.10968
3.550333 7.596344 -1.516775 49.88100
3.600333 7.696661 -1.518167 50.02603
3.650333 7.795556 -1.519478 49.90172
3.700333 7.894734 -1.520843 49.97571
3.750333 7.994952 -1.521950 50.06210
3.800333 8.094901 -1.523387 50.01332
3.850333 8.194749 -1.524634 49.96813
3.900333 8.294420 -1.525725 50.07085
3.950333 8.394062 -1.527040 49.83163
4.000333 8.494828 -1.528191 49.93703
4.050333 8.593826 -1.529313 49.95540
4.100333 8.694050 -1.530359 50.08117
4.150333 8.793445 -1.531484 50.17274
4.200333 8.893806 -1.532701 49.99950
4.250333 8.993280 -1.533815 49.94200
4.300333 9.092259 -1.534794 49.97406
4.350333 9.192794 -1.535564 49.96003
4.400333 9.292969 -1.536339 49.96810
4.450333 9.393030 -1.537079 50.10128
4.500333 9.491425 -1.537499 49.97128
4.550333 9.591114 -1.538108 50.05824
4.600333 9.690906 -1.538667 50.03086
4.650333 9.790250 -1.539121 50.06935
4.700333 9.890036 -1.539871 49.93053
4.750333 9.990522 -1.540488 49.91666
4.800333 10.08972 -1.541173 50.08940
4.850333 10.18915 -1.542149 49.92708
4.900333 10.29014 -1.543079 50.05084
4.950333 10.38954 -1.544144 49.96844
5.000333 10.48873 -1.545106 49.95182
5.050333 10.58822 -1.546062 50.11518
5.100333 10.68917 -1.546891 50.07652
5.150333 10.78891 -1.547912 50.01962
5.200333 10.88841 -1.548900 49.94824
5.250332 10.98848 -1.549695 50.09055
5.300332 11.08885 -1.550538 50.11348
5.350332 11.18850 -1.551477 50.00832
5.400332 11.28780 -1.552292 49.76614
5.450332 11.38796 -1.553123 50.11322
5.500332 11.48785 -1.553914 49.79934
5.550332 11.58738 -1.554811 50.15634
5.600332 11.68713 -1.555537 50.15606
5.650332 11.78756 -1.556334 49.91829
5.700332 11.88787 -1.557004 50.13944
5.750332 11.98795 -1.557591 49.95104
5.800332 12.08677 -1.558210 50.02946
5.850332 12.18749 -1.558940 49.94985
5.900332 12.28779 -1.559483 50.07546
5.950332 12.38719 -1.560278 50.06676
6.000332 12.48700 -1.560751 50.14145
6.050332 12.58714 -1.561370 50.08768
6.100332 12.68719 -1.562001 50.01867
6.150332 12.78592 -1.562724 50.20688
6.200332 12.88700 -1.563387 50.00024
6.250332 12.98702 -1.563906 49.79526
6.300332 13.08597 -1.564517 50.15120
6.350332 13.18626 -1.565132 50.02290
6.400332 13.28669 -1.565936 49.95080
6.450332 13.38619 -1.566602 50.04451
6.500332 13.48632 -1.567181 50.06426
6.550332 13.58559 -1.567905 50.04906
6.600332 13.68494 -1.568479 49.91668
6.650332 13.78529 -1.569139 49.94828
6.700332 13.88521 -1.569704 50.18968
6.750332 13.98622 -1.570268 50.22575
6.800332 14.08414 -1.571098 49.81979
6.850332 14.18459 -1.571629 50.11340
6.900332 14.28460 -1.572140 50.08728
6.950332 14.38415 -1.572739 50.03248
7.000332 14.48428 -1.573450 50.00241
7.050332 14.58513 -1.574201 50.04679
7.100332 14.68460 -1.574864 49.88498
7.150332 14.78416 -1.575549 49.87369
7.200332 14.88438 -1.576133 49.82160
7.250332 14.98344 -1.576692 49.89806
7.300332 15.08403 -1.577469 49.92935
7.350332 15.18459 -1.578063 49.84203
7.400332 15.28400 -1.578858 50.05986
7.450332 15.38408 -1.579520 49.80886
7.500332 15.48364 -1.580154 50.02478
7.550332 15.58350 -1.581034 49.98680
7.600332 15.68333 -1.581756 50.05533
7.650332 15.78267 -1.582476 50.01242
7.700332 15.88297 -1.583211 50.23830
7.750332 15.98291 -1.583826 49.96764
7.800332 16.08296 -1.584575 50.05789
7.850332 16.18333 -1.585314 49.90982
7.900332 16.28329 -1.586250 50.03453
7.950332 16.38266 -1.586770 50.04634
8.000334 16.48329 -1.587501 50.03085
8.050332 16.58302 -1.588157 50.08696
8.100332 16.68358 -1.588766 49.96500
8.150332 16.78266 -1.589395 49.96027
8.200332 16.88278 -1.590002 50.00326
8.250334 16.98288 -1.590735 50.09291
8.300332 17.08190 -1.591282 49.96852
8.350332 17.18281 -1.591841 49.96826
8.400332 17.28274 -1.592556 50.10470
8.450332 17.38278 -1.593276 50.19660
8.500334 17.48256 -1.594042 50.01490
8.550332 17.58309 -1.594537 50.22473
8.600332 17.68265 -1.594977 50.00924
8.650332 17.78222 -1.595678 50.05830
8.700332 17.88249 -1.596312 50.02574
8.750334 17.98183 -1.596774 50.04614
8.800332 18.08137 -1.597252 49.98728
8.850332 18.18137 -1.597701 49.99732
8.900332 18.28170 -1.598350 49.95699
8.950332 18.38091 -1.598986 49.95080
9.000334 18.48148 -1.599658 49.99083
9.050332 18.58085 -1.600472 50.13486
9.100332 18.68134 -1.601180 49.92750
9.150332 18.78146 -1.601839 49.97186
9.200332 18.88070 -1.602421 50.01574
9.250334 18.98090 -1.603317 49.84266
9.300332 19.08029 -1.603934 49.92720
9.350332 19.18083 -1.604584 49.98892
9.400332 19.28065 -1.605441 49.92990
9.450332 19.38012 -1.606091 50.11308
9.500334 19.47958 -1.606958 49.86976
9.550332 19.58016 -1.607910 50.05313
9.600332 19.68034 -1.608693 49.94658
9.650332 19.77994 -1.609505 49.94594
9.700332 19.87924 -1.610369 49.90976
9.750334 19.97968 -1.611308 50.11141
9.800332 20.08014 -1.612094 50.10110
9.850332 20.17887 -1.613009 50.03326
9.900332 20.27962 -1.613762 50.01134
9.950332 20.37963 -1.614731 50.05919
10.00033 20.48044 -1.615386 50.04226
10.05033 20.57892 -1.616129 50.13684
10.10033 20.67924 -1.617209 50.00418
10.15033 20.77965 -1.617902 50.01360
10.20033 20.87897 -1.618824 49.95264
10.25033 20.97919 -1.619592 50.08402
10.30033 21.07857 -1.620497 50.05334
10.35033 21.17898 -1.621352 49.94976
10.40033 21.27871 -1.622119 50.17203
10.45033 21.37883 -1.622767 50.15472
10.50034 21.47887 -1.623574 49.86592
10.55033 21.57888 -1.624271 50.11491
10.60033 21.67877 -1.624921 50.09402
10.65033 21.77888 -1.625674 50.01836
10.70033 21.87792 -1.626520 49.96984
10.75034 21.97782 -1.627148 50.00843
10.80033 22.07843 -1.627875 50.15436
10.85033 22.17784 -1.628540 50.08480
10.90033 22.27756 -1.629458 49.98567
10.95033 22.37803 -1.630247 49.73492
11.00034 22.47723 -1.631210 50.02234
11.05033 22.57717 -1.632036 49.83926
11.10033 22.67786 -1.633208 50.10772
11.15033 22.77777 -1.634388 50.07708
11.20033 22.87704 -1.635512 50.11587
11.25034 22.97786 -1.636711 49.89970
11.30033 23.07708 -1.637828 49.93047
11.35033 23.17714 -1.639071 50.00653
11.40033 23.27734 -1.640175 49.95402
11.45033 23.37797 -1.641198 50.14265
11.50034 23.47783 -1.642289 50.02304
11.55033 23.57747 -1.643416 50.06485
11.60033 23.67704 -1.644487 50.02832
11.65033 23.77668 -1.645455 50.00660
11.70033 23.87722 -1.646307 50.06033
11.75034 23.97617 -1.647415 50.21859
11.80033 24.07620 -1.648314 50.02269
11.85033 24.17666 -1.649223 50.23348
11.90033 24.27618 -1.649891 49.91588
11.95033 24.37515 -1.650877 49.89016
12.00034 24.47528 -1.651779 50.06873
12.05033 24.57538 -1.652778 49.91598
12.10033 24.67493 -1.653768 50.09955
12.15033 24.77420 -1.654851 49.94542
12.20033 24.87506 -1.655835 50.01464
12.25034 24.97430 -1.656975 49.84306
12.30033 25.07425 -1.657974 50.09500
12.35033 25.17389 -1.659137 50.12014
12.40033 25.27330 -1.660502 49.88503
12.45033 25.37414 -1.661701 50.18900
12.50034 25.47363 -1.662910 49.98614
12.55033 25.57368 -1.664365 50.11146
12.60033 25.67261 -1.665697 50.03858
12.65033 25.77290 -1.667087 50.06686
12.70033 25.87274 -1.668496 49.93018
12.75034 25.97210 -1.669847 50.03060
12.80033 26.07197 -1.671322 49.99394
12.85033 26.17175 -1.672731 49.93874
12.90033 26.27198 -1.674233 50.08536
12.95034 26.37144 -1.675690 50.08684
13.00034 26.47182 -1.677079 50.08399
13.05033 26.57210 -1.678689 50.10778
13.10033 26.67112 -1.680180 50.05942
13.15033 26.77185 -1.681702 49.97339
13.20034 26.87024 -1.683332 50.17136
13.25034 26.97080 -1.684877 49.99368
13.30033 27.07095 -1.686626 50.18110
13.35033 27.17013 -1.688242 49.99274
13.40033 27.27034 -1.689869 50.00118
13.45034 27.37091 -1.691446 50.10417
13.50034 27.47106 -1.693024 50.03930
13.55033 27.57013 -1.694644 50.15497
13.60033 27.67072 -1.696381 49.78154
13.65033 27.76955 -1.697925 50.07288
13.70034 27.87065 -1.699549 49.85737
13.75034 27.97032 -1.701110 50.05552
13.80033 28.07006 -1.702803 50.00941
13.85033 28.17006 -1.704444 49.90060
13.90033 28.27012 -1.706156 49.93593
13.95034 28.36862 -1.707759 50.03710
14.00034 28.46883 -1.709484 49.83931
14.05033 28.56846 -1.711227 50.01944
14.10033 28.66885 -1.713099 50.02813
14.15033 28.76815 -1.715090 50.03803
14.20034 28.86848 -1.716827 49.95367
14.25034 28.96765 -1.718561 49.90813
14.30033 29.06720 -1.720394 49.93154
14.35033 29.16608 -1.722518 50.02452
14.40033 29.26680 -1.724523 50.01750
14.45034 29.36759 -1.726557 50.01930
14.50034 29.46670 -1.728450 49.83942
14.55033 29.56578 -1.730514 49.78972
14.60033 29.66618 -1.732502 49.98552
14.65033 29.76607 -1.734586 50.25136
14.70034 29.86660 -1.736893 50.00464
14.75034 29.96555 -1.739032 50.13500
14.80033 30.06497 -1.741181 49.92688
14.85033 30.16521 -1.743547 49.99124
14.90033 30.26460 -1.745756 49.90972
14.95034 30.36560 -1.748148 50.01894
15.00034 30.46535 -1.750457 50.08717
15.05033 30.56367 -1.752652 49.96644
15.10033 30.66470 -1.755041 50.17988
15.15033 30.76366 -1.757467 50.09820
15.20034 30.86306 -1.759934 49.86010
15.25034 30.96360 -1.762640 50.05024
15.30033 31.06238 -1.765156 49.97812
15.35033 31.16280 -1.767992 49.93045
15.40033 31.26196 -1.770569 50.13174
15.45034 31.36262 -1.773318 50.00164
15.50034 31.46185 -1.776115 49.89438
15.55033 31.56201 -1.778980 50.07012
15.60033 31.66175 -1.781977 49.81594
15.65033 31.76060 -1.785228 50.03430
15.70034 31.86081 -1.788461 50.09021
15.75034 31.95982 -1.791826 49.97298
15.80033 32.05994 -1.795790 49.86841
15.85033 32.15899 -1.800254 49.99373
15.90033 32.25884 -1.805680 49.89924
15.95034 32.35844 -1.812384 49.90836
16.00033 32.45600 -1.822677 50.08526
16.05033 32.55604 -1.837177 49.99111
16.10033 32.65518 -1.859754 49.96564
16.15033 32.75246 -1.884356 49.90317
16.20033 32.85000 -1.914158 50.10410
16.25033 32.94912 -1.947430 49.95990
16.30033 33.04703 -1.987742 50.10902
16.35033 33.14344 -2.029862 49.98561
16.40033 33.24036 -2.082348 50.07747
16.45033 33.33546 -2.138570 49.92312
16.50033 33.43131 -2.198298 49.87992
16.55033 33.52675 -2.259190 50.12828
16.60033 33.62214 -2.320742 50.07250
16.65033 33.71603 -2.387361 49.94267
16.70033 33.81204 -2.447650 49.83772
16.75033 33.90647 -2.506918 50.01039
16.80033 34.00151 -2.565840 49.95606
16.85033 34.09587 -2.617813 50.10252
16.90033 34.19188 -2.661457 50.10670
16.95033 34.28899 -2.702361 49.99301
17.00033 34.38578 -2.730129 49.93652
17.05033 34.48230 -2.749461 50.05105
17.10033 34.58203 -2.757622 49.90567
17.15033 34.68098 -2.762918 49.99926
17.20033 34.77994 -2.766558 50.03276
17.25033 34.87980 -2.768872 49.88900
17.30033 34.98082 -2.770344 49.95884
17.35033 35.08018 -2.772381 49.94527
17.40033 35.17920 -2.775893 50.03149
17.45033 35.27752 -2.790344 49.94821
17.50033 35.37577 -2.814156 49.92612
17.55033 35.47328 -2.855214 49.96324
17.60033 35.57063 -2.898646 49.99370
17.65033 35.66800 -2.941581 49.97204
17.70033 35.76540 -2.980638 50.07886
17.75033 35.86143 -3.023290 50.09660
17.80033 35.95843 -3.061852 49.92283
17.85033 36.05528 -3.102224 49.92056
17.90033 36.15154 -3.137186 50.02900
17.95033 36.24850 -3.171538 49.91968
18.00033 36.34622 -3.204264 50.06074
18.05033 36.44314 -3.236108 49.89449
18.10033 36.54128 -3.266338 50.00926
18.15033 36.63795 -3.292256 49.95980
18.20033 36.73596 -3.320334 50.14382
18.25033 36.83357 -3.346615 50.08320
18.30033 36.93076 -3.373245 49.96598
18.35033 37.02881 -3.397410 49.87588
18.40033 37.12650 -3.421322 49.96612
18.45033 37.22494 -3.445248 49.94266
18.50033 37.32283 -3.467828 49.97214
18.55033 37.42039 -3.489190 49.90533
18.60033 37.51883 -3.501366 49.98196
18.65033 37.61812 -3.511245 49.91480
18.70033 37.71743 -3.517959 50.03676
18.75033 37.81819 -3.521553 50.00796
18.80033 37.91981 -3.499182 50.05652
18.85033 38.02380 -3.418286 50.01663
18.90033 38.13044 -3.317748 50.11602
18.95033 38.23704 -3.214258 50.23590
19.00033 38.34626 -3.082464 49.98867
19.05033 38.45513 -2.951133 50.13680
19.10033 38.56660 -2.813949 50.02378
19.15033 38.67618 -2.688553 49.95344
19.20033 38.78716 -2.570314 49.98512
19.25033 38.89680 -2.467271 50.02044
19.30033 39.00468 -2.376556 50.16578
19.35033 39.11280 -2.298755 50.01158
19.40033 39.21888 -2.234512 50.11160
19.45033 39.32380 -2.176026 50.01119
19.50033 39.42859 -2.130562 50.07374
19.55033 39.53276 -2.091686 49.90032
19.60033 39.63614 -2.060992 50.01098
19.65033 39.73925 -2.031746 49.99828
19.70033 39.84048 -2.009144 49.87688
19.75033 39.94322 -1.989360 49.96862
19.80033 40.04450 -1.974001 50.16950
19.85033 40.14670 -1.960941 49.99614
19.90033 40.24854 -1.950195 49.98676
19.95033 40.34922 -1.940591 50.01124
20.00033 40.44959 -1.932058 50.01431
20.05033 40.55020 -1.923680 50.00440
20.10033 40.65005 -1.914939 49.95688
20.15033 40.75158 -1.906830 49.92383
20.20033 40.85306 -1.899295 49.93368
20.25033 40.95227 -1.892223 49.99117
20.30033 41.05372 -1.885467 50.08744
20.35033 41.15298 -1.879198 50.09820
20.40033 41.25370 -1.873383 49.87428
20.45033 41.35421 -1.868281 49.90726
20.50033 41.45448 -1.863792 49.85024
20.55033 41.55378 -1.859882 49.86397
20.60033 41.65520 -1.856525 50.12471
20.65033 41.75406 -1.853628 50.22286
20.70033 41.85330 -1.851286 49.84634
20.75033 41.95428 -1.849661 49.84937
20.80033 42.05443 -1.848337 50.01846
20.85033 42.15468 -1.847403 50.03947
20.90033 42.25464 -1.846806 50.08914
20.95033 42.35434 -1.846720 50.07316
21.00033 42.45426 -1.846696 49.97740
21.05033 42.55469 -1.847092 49.82062
21.10033 42.65378 -1.847524 50.04824
21.15033 42.75430 -1.848255 50.02886
21.20033 42.85464 -1.849124 50.08250
21.25033 42.95467 -1.849992 50.00239
21.30033 43.05434 -1.851133 49.96534
21.35033 43.15411 -1.852185 50.02584
21.40033 43.25404 -1.853546 50.13887
21.45033 43.35391 -1.855026 50.02414
21.50033 43.45389 -1.856619 50.08464
21.55033 43.55400 -1.858254 49.96366
21.60033 43.65341 -1.859767 50.08244
21.65033 43.75357 -1.861191 50.06531
21.70033 43.85355 -1.862528 50.02081
21.75033 43.95238 -1.863785 50.07402
21.80033 44.05290 -1.865209 50.02404
21.85033 44.15234 -1.866402 49.82622
21.90033 44.25193 -1.867692 50.14538
21.95033 44.35250 -1.868805 50.10214
22.00033 44.45106 -1.870099 50.05826
22.05033 44.55070 -1.871449 49.93170
22.10033 44.65082 -1.872835 49.90357
22.15033 44.75070 -1.874133 49.92933
22.20033 44.85166 -1.875554 50.01510
22.25033 44.95058 -1.876900 49.98350
22.30033 45.04910 -1.878269 49.83598
22.35033 45.14953 -1.879674 50.13241
22.40033 45.24922 -1.881190 49.82418
22.45033 45.34831 -1.882869 49.94965
22.50033 45.44840 -1.884592 49.87959
22.55033 45.54854 -1.886497 50.03441
22.60033 45.64872 -1.888321 49.99418
22.65033 45.74874 -1.890278 49.99832
22.70033 45.84775 -1.892089 49.92046
22.75033 45.94778 -1.893821 50.02996
22.80033 46.04810 -1.895829 49.91218
22.85033 46.14753 -1.897538 49.88680
22.90033 46.24698 -1.899463 50.06261
22.95033 46.34578 -1.901457 50.03962
23.00033 46.44672 -1.903356 50.00971
23.05033 46.54682 -1.905261 49.95688
23.10033 46.64590 -1.907272 50.16125
23.15033 46.74576 -1.909354 49.96320
23.20033 46.84578 -1.911462 49.83868
23.25033 46.94555 -1.913438 49.94787
23.30033 47.04602 -1.915385 50.07452
23.35033 47.14606 -1.917148 49.95748
23.40033 47.24558 -1.918941 50.13400
23.45033 47.34544 -1.920922 49.98146
23.50033 47.44549 -1.922942 49.98554
23.55033 47.54532 -1.924990 50.12818
23.60033 47.64410 -1.927004 50.02460
23.65033 47.74446 -1.929068 49.92809
23.70033 47.84492 -1.931244 49.99110
23.75033 47.94389 -1.933289 50.03647
23.80033 48.04351 -1.935406 49.86070
23.85033 48.14372 -1.937371 50.15481
23.90033 48.24320 -1.939226 49.95172
23.95033 48.34396 -1.941210 49.87550
24.00033 48.44346 -1.943252 50.06592
24.05033 48.54259 -1.945178 49.85700
24.10033 48.64189 -1.947296 49.86065
24.15033 48.74219 -1.949648 50.03110
24.20033 48.84235 -1.951734 49.91976
24.25033 48.94174 -1.953949 50.13920
24.30033 49.04148 -1.956093 49.89850
24.35033 49.14272 -1.958290 50.11680
24.40033 49.24102 -1.960275 49.96334
24.45033 49.34208 -1.962418 50.05055
24.50033 49.44134 -1.964584 50.24183
24.55033 49.54135 -1.966603 50.11987
24.60033 49.64116 -1.968587 50.18438
24.65033 49.73993 -1.970695 49.94824
24.70033 49.84107 -1.972756 49.81242
24.75033 49.93941 -1.974961 49.84459
24.80033 50.04097 -1.977332 50.14258
24.85033 50.13972 -1.979575 50.00191
24.90033 50.24011 -1.981783 49.89360
24.95033 50.33924 -1.984241 49.99448
25.00033 50.43936 -1.986569 50.03326
25.05033 50.53943 -1.988934 50.07184
25.10033 50.63900 -1.991331 49.99104
25.15033 50.73902 -1.993606 50.03183
25.20033 50.83828 -1.995884 49.99537
25.25033 50.93826 -1.998298 49.97676
25.30033 51.03783 -2.000709 50.10758
25.35033 51.13822 -2.003233 49.87641
25.40033 51.23742 -2.005773 49.94536
25.45033 51.33816 -2.008019 50.07066
25.50033 51.43713 -2.010132 49.97164
25.55033 51.53666 -2.012336 49.92920
25.60033 51.63682 -2.014592 49.88222
25.65033 51.73667 -2.016978 50.07684
25.70033 51.83552 -2.019356 49.86546
25.75033 51.93570 -2.021764 49.99190
25.80033 52.03582 -2.023953 50.02798
25.85033 52.13467 -2.026544 50.03979
25.90033 52.23458 -2.029230 49.93189
25.95033 52.33493 -2.032013 50.00887
26.00033 52.43488 -2.034758 50.05784
26.05033 52.53482 -2.037537 49.99672
26.10033 52.63422 -2.040506 50.10031
26.15033 52.73382 -2.043268 49.90197
26.20033 52.83437 -2.045938 49.88009
26.25033 52.93380 -2.048784 50.02903
26.30033 53.03374 -2.051317 50.04068
26.35033 53.13321 -2.054031 49.99104
26.40033 53.23284 -2.056772 50.15420
26.45033 53.33330 -2.059380 49.95675
26.50033 53.43289 -2.061972 50.03348
26.55033 53.53266 -2.064549 50.02954
26.60033 53.63335 -2.067168 50.02842
26.65033 53.73182 -2.069776 49.95913
26.70033 53.83244 -2.072434 50.10192
26.75033 53.93112 -2.075180 50.11291
26.80033 54.03100 -2.078085 50.25792
26.85033 54.13130 -2.081005 49.83799
26.90033 54.23130 -2.083874 49.85330
26.95033 54.33110 -2.086901 50.14044
27.00033 54.43090 -2.089930 49.86070
27.05033 54.53092 -2.092906 50.04954
27.10033 54.63028 -2.095933 49.86008
27.15033 54.73064 -2.099046 49.90940
27.20033 54.83038 -2.102068 50.04454
27.25033 54.93018 -2.104968 50.01389
27.30033 55.03041 -2.107685 50.06348
27.35033 55.12989 -2.110496 49.99380
27.40033 55.22925 -2.113247 49.87214
27.45033 55.33000 -2.115924 49.97340
27.50033 55.42891 -2.118352 50.03829
27.55033 55.52826 -2.120925 49.89376
27.60033 55.62824 -2.123505 50.12720
27.65033 55.72681 -2.125890 49.42540
27.70033 55.82691 -2.128456 50.00632
27.75033 55.92563 -2.131034 49.98352
27.80033 56.02724 -2.133672 49.93348
27.85033 56.12626 -2.136324 49.99508
27.90033 56.22620 -2.139103 50.08654
27.95033 56.32518 -2.142075 50.09430
28.00033 56.42430 -2.144936 50.05790
28.05033 56.52514 -2.147826 49.94530
28.10033 56.62410 -2.150747 50.09314
28.15033 56.72291 -2.153627 50.02036
28.20033 56.82278 -2.156584 50.05611
28.25033 56.92392 -2.159530 50.00636
28.30033 57.02244 -2.162332 50.12161
28.35033 57.12176 -2.165245 49.94440
28.40033 57.22156 -2.168163 49.85117
28.45033 57.32176 -2.171437 49.98528
28.50033 57.42037 -2.174791 49.96262
28.55033 57.52062 -2.178241 50.00387
28.60033 57.62037 -2.181885 49.95132
28.65033 57.72026 -2.185473 49.83806
28.70033 57.81972 -2.188940 50.01042
28.75033 57.92000 -2.192497 50.00668
28.80033 58.01991 -2.196006 49.95967
28.85033 58.11882 -2.199298 50.05928
28.90033 58.21844 -2.202556 50.04025
28.95033 58.31832 -2.205668 49.87528
29.00033 58.41836 -2.208832 49.98266
29.05033 58.51812 -2.212041 49.97186
29.10033 58.61743 -2.215198 50.01524
29.15033 58.71762 -2.218318 50.04947
29.20033 58.81676 -2.221615 49.89412
29.25033 58.91609 -2.224975 50.05985
29.30033 59.01537 -2.228516 50.06944
29.35033 59.11640 -2.231977 49.99941
29.40033 59.21620 -2.235704 50.12997
29.45033 59.31492 -2.239210 49.88676
29.50033 59.41457 -2.242487 50.15246
29.55033 59.51046 -2.246532 49.84406
29.60033 59.58276 -2.218904 49.97306
29.65033 59.63160 -2.086127 50.05756
29.70033 59.67190 -1.939635 49.93453
29.75033 59.70472 -1.798530 50.01969
29.80033 59.73262 -1.659090 50.16459
29.85033 59.75623 -1.531141 49.80560
29.90033 59.77593 -1.413454 49.89734
29.95033 59.79190 -1.307991 49.98279
30.00033 59.80718 -1.219742 49.88616
30.05033 59.81941 -1.135511 50.07462
30.10033 59.83079 -1.070400 50.05062
30.15033 59.83946 -1.006865 50.01376
30.20033 59.84736 -0.9572926 49.85782
30.25033 59.85371 -0.9155390 50.09714
30.30033 59.85882 -0.8793199 50.02262
30.35033 59.86511 -0.8465092 50.11029
30.40033 59.87018 -0.8209960 50.04790
30.45033 59.87405 -0.7994980 49.97408
30.50033 59.87631 -0.7815069 49.88802
30.55033 59.87916 -0.7663251 49.98010
30.60033 59.88212 -0.7532235 49.93946
30.65033 59.88407 -0.7419126 49.78862
30.70033 59.88663 -0.7324474 50.15152
30.75033 59.88787 -0.7237942 49.96646
30.80033 59.88980 -0.7156401 50.05856
30.85033 59.89135 -0.7073636 49.89520
30.90033 59.89222 -0.6992169 49.80596
30.95033 59.89264 -0.6915150 50.00781
31.00033 59.89400 -0.6842804 50.09372
31.05033 59.89463 -0.6774806 50.25101
31.10033 59.89553 -0.6713670 50.08150
31.15033 59.89590 -0.6657208 49.92080
31.20033 59.89714 -0.6604229 50.03660
31.25033 59.89631 -0.6557160 49.91670
31.30033 59.89676 -0.6515813 49.96286
31.35033 59.89805 -0.6477711 49.97608
31.40033 59.89916 -0.6444091 50.05052
31.45033 59.89918 -0.6413804 50.02524
31.50033 59.90049 -0.6387982 50.04051
31.55033 59.89949 -0.6362379 50.10412
31.60033 59.90005 -0.6342074 49.88537
31.65033 59.90040 -0.6323662 50.04328
31.70033 59.90066 -0.6306601 50.00132
31.75033 59.90085 -0.6291834 49.96450
31.80033 59.90179 -0.6277115 50.00370
31.85034 59.90125 -0.6263238 49.99805
31.90033 59.90172 -0.6248668 49.99234
31.95033 59.90269 -0.6237436 49.99528
32.00033 59.90218 -0.6224197 49.96205
32.05033 59.90252 -0.6213620 50.11406
32.10034 59.90298 -0.6203928 50.12182
32.15033 59.90229 -0.6195940 50.06188
32.20033 59.90225 -0.6187809 50.08894
32.25033 59.90158 -0.6178738 50.01567
32.30033 59.90247 -0.6171493 50.08510
32.35034 59.90351 -0.6164841 50.06583
32.40033 59.90312 -0.6160802 50.00665
32.45033 59.90313 -0.6156277 50.00492
-2.000000 1.000000 0.0000000 0.0000000
32.54700 59.90000 -0.6153588 49.83564
32.59700 59.87426 -0.5810434 49.95874
32.64700 59.82340 -0.4335636 49.88844
32.69700 59.76372 -0.2846334 50.11054
32.74700 59.69570 -0.1326371 50.07140
32.79700 59.62348 0.01403913 50.06832
32.84700 59.54606 0.1440497 49.84828
32.89700 59.46558 0.2654253 49.99043
32.94700 59.38280 0.3741131 50.15756
32.99700 59.29611 0.4718227 49.89406
33.04700 59.20875 0.5552780 49.88975
33.09700 59.11925 0.6265479 50.06030
33.14700 59.02780 0.6912370 49.95190
33.19700 58.93587 0.7429602 49.86767
33.24700 58.84289 0.7900920 50.13183
33.29700 58.74854 0.8307637 50.03104
33.34700 58.65360 0.8656631 50.12045
33.39700 58.55774 0.8952682 49.86040
33.44700 58.46153 0.9199718 49.94392
33.49700 58.36600 0.9412128 49.81650
33.54700 58.26840 0.9610669 49.91551
33.59700 58.17113 0.9763508 49.89766
33.64700 58.07411 0.9895416 50.10324
33.69700 57.97556 1.002602 49.89459
33.74700 57.87822 1.013480 50.02908
33.79700 57.77948 1.023097 49.95982
33.84700 57.68069 1.031766 49.98650
33.89700 57.58228 1.040729 50.09661
33.94700 57.48446 1.050006 49.81273
33.99700 57.38540 1.058760 49.94904
34.04700 57.28586 1.067655 49.86734
34.09700 57.18762 1.075972 49.97290
34.14700 57.08835 1.083869 50.17640
34.19700 56.98878 1.091612 50.02340
34.24700 56.89028 1.098930 49.98477
34.29700 56.79063 1.105954 49.82456
34.34700 56.69169 1.112626 49.79250
34.39700 56.59271 1.118743 49.88447
34.44700 56.49291 1.124671 50.06498
34.49700 56.39368 1.130296 50.05523
34.54700 56.29480 1.135810 50.15212
34.59700 56.19527 1.140967 49.93912
34.64700 56.09634 1.145972 49.89358
34.69700 55.99620 1.150669 50.10544
34.74700 55.89660 1.155297 50.03766
34.79700 55.79810 1.159678 50.00006
34.84700 55.69878 1.164128 49.92804
34.89700 55.59950 1.168555 49.95326
34.94700 55.49996 1.172542 50.00411
34.99700 55.40058 1.176612 49.99506
35.04700 55.30087 1.180430 50.02644
35.09700 55.20190 1.184092 49.96854
35.14700 55.10188 1.187972 50.07541
35.19700 55.00220 1.191843 49.93486
35.24700 54.90258 1.195565 50.05472
35.29700 54.80316 1.199161 50.00522
35.34700 54.70466 1.203192 50.12278
35.39700 54.60321 1.206878 49.90304
35.44700 54.50506 1.210483 50.08194
35.49700 54.40566 1.214298 49.97124
35.54700 54.30528 1.217814 49.95882
35.59700 54.20613 1.221390 49.96530
35.64700 54.10660 1.224589 50.03262
35.69700 54.00635 1.228037 50.18344
35.74700 53.90674 1.231409 49.89550
35.79700 53.80753 1.234621 49.99376
35.84700 53.70761 1.237813 50.04710
35.89700 53.60920 1.241053 50.00030
35.94700 53.50854 1.244188 50.14932
35.99700 53.40868 1.247247 50.03119
36.04700 53.30880 1.250375 49.88856
36.09700 53.21003 1.253458 50.13461
36.14700 53.10910 1.256621 50.12090
36.19700 53.01035 1.259343 49.96146
36.24700 52.90986 1.262398 50.02870
36.29700 52.81076 1.265166 50.19553
36.34700 52.71140 1.268073 50.08976
36.39700 52.61116 1.270876 50.09986
36.44700 52.51270 1.273700 50.04268
36.49700 52.41311 1.276287 49.91335
36.54700 52.31262 1.279171 50.08080
36.59700 52.21303 1.282005 50.04138
36.64700 52.11376 1.284812 49.99942
36.69700 52.01422 1.287608 50.12436
36.74700 51.91472 1.290324 49.91060
36.79700 51.81467 1.293186 50.05195
36.84700 51.71458 1.295965 50.03474
36.89700 51.61500 1.298754 49.94032
36.94700 51.51594 1.301604 49.95496
36.99700 51.41572 1.304284 49.93977
37.04700 51.31658 1.306943 49.98025
37.09700 51.21678 1.309598 49.85492
37.14700 51.11688 1.312310 49.87926
37.19700 51.01700 1.314853 49.93270
37.24700 50.91744 1.317388 49.95462
37.29700 50.81816 1.319872 49.95389
37.34700 50.71854 1.322562 49.91074
37.39700 50.61846 1.324963 50.25750
37.44700 50.51873 1.327540 49.98465
37.49700 50.41947 1.329981 49.93870
37.54700 50.31933 1.332524 49.92664
37.59700 50.21992 1.334981 49.99157
37.64700 50.11937 1.337492 50.08030
37.69700 50.01960 1.339920 50.02718
37.74700 49.91952 1.342385 50.06876
37.79700 49.82093 1.344781 50.13606
37.84700 49.72050 1.347452 49.93142
37.89700 49.62068 1.349802 50.09695
37.94700 49.52132 1.352148 49.93045
37.99700 49.42097 1.354636 50.03041
38.04700 49.32117 1.356866 49.93607
38.09700 49.22200 1.359145 49.91957
38.14700 49.12178 1.361379 50.06210
38.19700 49.02232 1.363772 49.96852
38.24700 48.92316 1.365948 50.01869
38.29700 48.82400 1.368124 49.98364
38.34700 48.72390 1.370476 49.99474
38.39700 48.62378 1.372618 49.99536
38.44700 48.52500 1.374886 49.92228
38.49700 48.42410 1.376923 49.91534
38.54700 48.32498 1.379283 50.00473
38.59700 48.22480 1.381373 50.00297
38.64700 48.12512 1.383615 49.98228
38.69700 48.02484 1.385700 49.98372
38.74700 47.92576 1.387913 49.89190
38.79700 47.82598 1.390122 50.00527
38.84700 47.72666 1.392456 49.92520
38.89700 47.62642 1.394526 49.88293
38.94700 47.52662 1.396749 50.06006
38.99700 47.42737 1.398942 49.94826
39.04700 47.32828 1.401029 50.04204
39.09700 47.22762 1.403338 49.82525
39.14700 47.12815 1.405706 50.17484
39.19700 47.02797 1.407925 50.04481
39.24700 46.92869 1.410177 49.94756
39.29700 46.82920 1.412506 50.03086
39.34700 46.72859 1.414704 50.04508
39.39700 46.62910 1.416986 50.16861
39.44700 46.52931 1.419166 49.83526
39.49700 46.42944 1.421202 50.03037
39.54700 46.33020 1.423340 50.02508
39.59700 46.23020 1.425580 49.89816
39.64700 46.13026 1.427530 50.10712
39.69700 46.03044 1.429520 50.04038
39.74700 45.92994 1.431581 49.94808
39.79700 45.82978 1.433541 50.06846
39.84700 45.73074 1.435525 50.18063
39.89700 45.63144 1.437494 49.98413
39.94700 45.53098 1.439328 50.16390
39.99700 45.43057 1.441231 50.02238
40.04700 45.33124 1.443101 50.00859
40.09700 45.23272 1.444882 50.12642
40.14700 45.13205 1.446694 49.93941
40.19700 45.03183 1.448465 50.13140
40.24700 44.93172 1.450097 50.09336
40.29700 44.83223 1.451926 49.95910
40.34700 44.73338 1.453633 49.88674
40.39700 44.63230 1.455446 50.10767
40.44700 44.53412 1.457099 50.01591
40.49700 44.43410 1.458649 49.91040
40.54700 44.33383 1.460417 50.00567
40.59700 44.23520 1.461921 49.82967
40.64700 44.13446 1.463549 49.90356
40.69700 44.03538 1.465204 50.02526
40.74700 43.93458 1.466728 49.92685
40.79700 43.83476 1.468376 50.04351
40.84700 43.73550 1.470076 49.93536
40.89700 43.63637 1.471738 50.20674
40.94700 43.53679 1.473524 49.95123
40.99700 43.43676 1.475182 49.94158
41.04700 43.33702 1.476823 49.90271
41.09700 43.23632 1.478481 49.97470
41.14700 43.13695 1.480239 50.07592
41.19700 43.03726 1.482255 49.96158
41.24700 42.93713 1.484058 50.22270
41.29700 42.83718 1.485830 49.98652
41.34700 42.73808 1.487573 50.01898
41.39700 42.63772 1.489191 49.89410
41.44700 42.53866 1.490869 50.01287
41.49700 42.43848 1.492444 49.89252
41.54700 42.33810 1.494094 49.91386
41.59700 42.23894 1.495658 49.87954
41.64700 42.13900 1.497334 49.99060
41.69700 42.03852 1.498881 49.88817
41.74700 41.93922 1.500423 50.04548
41.79700 41.83888 1.501993 49.74682
41.84700 41.73912 1.503414 50.04550
41.89700 41.64013 1.504909 49.79426
41.94700 41.54049 1.506377 50.07436
41.99700 41.44049 1.507853 50.02406
42.04700 41.34107 1.509494 49.84808
42.09700 41.24130 1.511001 49.92297
42.14700 41.14072 1.512447 49.99239
42.19700 41.04171 1.513989 49.94724
42.24700 40.94185 1.515338 50.00163
42.29700 40.84181 1.516779 49.94586
42.34700 40.74188 1.518163 50.01131
42.39700 40.64228 1.519621 50.15964
42.44700 40.54219 1.521221 50.15847
42.49700 40.44176 1.522811 50.10372
42.54700 40.34233 1.524138 50.07006
42.59700 40.24283 1.525626 49.91156
42.64700 40.14202 1.526981 49.96466
42.69700 40.04266 1.528436 49.93172
42.74700 39.94178 1.529818 49.95684
42.79700 39.84325 1.531237 50.02619
42.84700 39.74329 1.532731 50.14348
42.89700 39.64468 1.534185 50.06646
42.94700 39.54460 1.535734 49.93487
42.99700 39.44400 1.537306 50.02334
43.04700 39.34452 1.538733 50.06018
43.09700 39.24484 1.540226 49.96065
43.14700 39.14456 1.541704 49.97504
43.19700 39.04482 1.543197 50.12540
43.24700 38.94498 1.544280 49.83700
43.29700 38.84465 1.545582 49.95478
43.34700 38.74433 1.546644 49.91716
43.39700 38.64558 1.547859 50.01726
43.44700 38.54516 1.549000 49.91656
43.49700 38.44532 1.549997 49.97691
43.54700 38.34610 1.551007 49.98489
43.59700 38.24668 1.552242 50.00225
43.64700 38.14552 1.553443 49.95116
43.69700 38.04630 1.554666 50.01830
43.74700 37.94627 1.555960 50.04537
43.79700 37.84675 1.557176 49.97777
43.84700 37.74664 1.558599 49.93598
43.89700 37.64702 1.559841 49.95324
43.94700 37.54645 1.560882 50.06522
43.99700 37.44708 1.562122 49.99560
44.04700 37.34759 1.563171 49.96356
44.09700 37.24731 1.564032 50.01370
44.14700 37.14819 1.565219 49.97148
44.19700 37.04789 1.566088 50.09648
44.24700 36.94789 1.567203 49.92624
44.29700 36.84877 1.568316 50.01960
44.34700 36.74834 1.569511 49.90512
44.39700 36.64926 1.570825 50.14974
44.44700 36.54896 1.572009 49.99746
44.49700 36.44951 1.573442 50.03834
44.54700 36.35000 1.575116 49.92698
44.59700 36.24995 1.577107 49.94575
44.64700 36.15042 1.579879 49.95181
44.69700 36.05063 1.583970 49.97342
44.74700 35.95264 1.591232 49.99307
44.79700 35.85281 1.608730 49.99942
44.84700 35.75590 1.651504 49.94650
44.89700 35.65804 1.720656 50.13772
44.94700 35.56396 1.811194 49.92238
44.99700 35.47110 1.947302 49.98789
45.04700 35.38213 2.139903 50.01341
45.09700 35.29910 2.399972 49.95357
45.14700 35.22104 2.740128 49.95741
45.19700 35.14874 3.143582 50.08750
45.24700 35.08168 3.601568 49.98480
45.29700 35.01865 4.108398 50.02088
45.34700 34.95940 4.609128 49.96559
45.39700 34.89822 5.052531 50.05980
45.44700 34.83229 5.372394 49.96808
45.49700 34.75574 5.551885 49.91646
45.54700 34.67051 5.608516 50.07004
45.59700 34.57548 5.582358 49.86764
45.64700 34.47309 5.479900 50.02908
45.69700 34.36455 5.334102 50.02414
45.74700 34.25408 5.156460 49.84330
45.79700 34.13979 4.961647 49.89838
45.84700 34.02467 4.748639 49.84988
45.89700 33.90836 4.529868 49.90200
45.94700 33.79130 4.299753 50.09090
45.99700 33.67148 4.067854 50.14383
46.04700 33.55262 3.833203 49.89684
46.09700 33.43439 3.603348 50.08854
46.14700 33.31564 3.382617 50.08241
46.19700 33.19851 3.182657 50.07211
46.24700 33.08222 3.003822 50.07018
46.29700 32.96887 2.853315 50.18496
46.34700 32.85642 2.724203 50.00725
46.39700 32.74532 2.612168 50.01037
46.44700 32.63566 2.493658 50.05518
46.49700 32.52640 2.376892 50.07008
46.54700 32.41672 2.276896 49.98038
46.59700 32.30872 2.195744 49.95017
46.64700 32.20233 2.125438 49.97440
46.69700 32.09642 2.065130 49.89446
46.74700 31.99150 2.016642 49.96604
46.79700 31.88765 1.973775 49.84552
46.84700 31.78440 1.938164 50.05328
46.89700 31.68130 1.907754 50.09984
46.94700 31.57808 1.884304 49.96396
46.99700 31.47576 1.864584 50.03623
47.04700 31.37440 1.848600 49.82066
47.09700 31.27348 1.835376 49.85256
47.14700 31.17144 1.823890 49.88789
47.19700 31.07062 1.814977 50.01391
47.24700 30.96981 1.806559 50.02706
47.29700 30.86956 1.797489 49.96947
47.34700 30.76769 1.789266 50.16806
47.39700 30.66772 1.781262 50.16896
47.44700 30.56768 1.773630 49.88378
47.49700 30.46670 1.766321 49.94372
47.54700 30.36721 1.759506 49.88211
47.59700 30.26605 1.753184 49.93100
47.64700 30.16678 1.747429 50.02533
47.69700 30.06509 1.742113 50.15286
47.74700 29.96515 1.737176 49.93045
47.79700 29.86545 1.732716 49.97480
47.84700 29.76616 1.728842 49.99416
47.89700 29.66562 1.725406 50.07079
47.94700 29.56552 1.722332 49.97424
47.99700 29.46475 1.719511 49.95985
48.04700 29.36458 1.716835 50.20162
48.09700 29.26474 1.714562 50.20547
48.14700 29.16464 1.712378 49.98726
48.19700 29.06569 1.710397 50.00716
48.24700 28.96428 1.708637 50.04890
48.29700 28.86440 1.706870 50.05818
48.34700 28.76427 1.705296 49.88896
48.39700 28.66418 1.703796 49.99894
48.44700 28.56449 1.702494 49.86264
48.49700 28.46482 1.701284 50.08964
48.54700 28.36443 1.700116 49.97809
48.59700 28.26463 1.698986 49.99162
48.64700 28.16496 1.697946 50.05085
48.69700 28.06568 1.696810 49.88396
48.74700 27.96419 1.695645 50.06230
48.79700 27.86462 1.694631 50.11000
48.84700 27.76496 1.693778 50.19646
48.89700 27.66446 1.692840 50.19508
48.94700 27.56370 1.691868 50.08416
48.99700 27.46450 1.691000 50.01554
49.04700 27.36380 1.690260 49.90802
49.09700 27.26370 1.689424 49.96560
49.14700 27.16404 1.688605 50.01041
49.19700 27.06440 1.687564 50.05220
49.24700 26.96405 1.686952 50.08481
49.29700 26.86380 1.685917 49.96906
49.34700 26.76431 1.685074 50.02063
49.39700 26.66412 1.684089 50.06040
49.44700 26.56255 1.683302 50.01211
49.49700 26.46390 1.682384 50.06939
49.54700 26.36416 1.681595 49.91406
49.59700 26.26398 1.680781 49.95069
49.64700 26.16380 1.679943 49.91980
49.69700 26.06298 1.679296 49.96746
49.74700 25.96381 1.678743 49.95449
49.79700 25.86482 1.678098 49.94336
49.84700 25.76422 1.677573 49.87558
49.89700 25.66408 1.677059 49.92857
49.94700 25.56447 1.676716 49.86388
49.99700 25.46344 1.676230 49.88472
50.04700 25.36494 1.676000 50.17467
50.09700 25.26493 1.675519 50.17306
50.14700 25.16408 1.675053 49.94242
50.19700 25.06491 1.674692 49.93614
50.24700 24.96431 1.674305 50.01921
50.29700 24.86512 1.674139 49.94384
50.34700 24.76418 1.673896 49.98188
50.39700 24.66438 1.673891 50.02628
50.44700 24.56469 1.673913 49.84888
50.49700 24.46494 1.673708 50.12826
50.54700 24.36485 1.673779 49.86533
50.59700 24.26476 1.673732 50.12183
50.64700 24.16569 1.673935 49.94050
50.69700 24.06459 1.673998 49.97417
50.74700 23.96484 1.674046 49.96808
50.79700 23.86484 1.674025 50.13756
50.84700 23.76510 1.674054 50.12634
50.89700 23.66470 1.674057 49.90588
50.94700 23.56522 1.674148 50.08986
50.99700 23.46560 1.674142 49.91674
51.04700 23.36595 1.674296 50.05257
51.09700 23.26569 1.674200 49.95466
51.14700 23.16553 1.674202 49.88230
51.19700 23.06556 1.674231 50.04967
51.24700 22.96562 1.674062 49.91524
51.29700 22.86570 1.674099 49.98658
51.34700 22.76530 1.674235 49.77390
51.39700 22.66590 1.674113 49.91649
51.44700 22.56596 1.674110 50.01590
51.49700 22.46563 1.674122 49.99050
51.54700 22.36654 1.674174 49.85399
51.59700 22.26630 1.674088 50.04600
51.64700 22.16682 1.674248 49.93559
51.69700 22.06676 1.674410 50.12089
51.74700 21.96638 1.674569 50.04100
51.79700 21.86727 1.674606 50.17776
51.84700 21.76624 1.674733 49.98133
51.89700 21.66612 1.674804 49.97690
51.94700 21.56750 1.674882 50.05542
51.99700 21.46665 1.675074 49.98848
52.04700 21.36711 1.674956 49.99153
52.09700 21.26724 1.675107 49.85766
52.14700 21.16603 1.675092 50.03591
52.19700 21.06736 1.675192 50.10140
52.24700 20.96653 1.675407 49.84466
52.29700 20.86698 1.675460 49.97256
52.34700 20.76653 1.675547 50.00364
52.39700 20.66816 1.675608 50.07163
52.44700 20.56842 1.675714 50.08039
52.49700 20.46738 1.675798 49.96739
52.54700 20.36858 1.675988 49.97333
52.59700 20.26819 1.676202 50.00604
52.64700 20.16830 1.676369 49.85818
52.69700 20.06762 1.676396 50.01566
52.74700 19.96847 1.676476 50.02004
52.79700 19.86963 1.676656 49.97873
52.84700 19.76841 1.676811 50.08681
52.89700 19.66855 1.676978 50.02019
52.94700 19.56884 1.677066 49.88154
52.99700 19.46837 1.677126 49.90647
53.04700 19.36877 1.677247 49.94613
53.09700 19.26806 1.677400 49.90769
53.14700 19.16877 1.677514 49.97965
53.19700 19.06888 1.677676 50.00959
53.24700 18.96812 1.677782 49.87906
53.29700 18.86933 1.677944 49.95461
53.34700 18.76871 1.678158 49.98466
53.39700 18.67014 1.678370 49.99670
53.44700 18.56808 1.678530 49.92292
53.49700 18.47013 1.678753 50.12389
53.54700 18.36919 1.678910 49.94031
53.59700 18.26937 1.679052 50.02328
53.64700 18.16934 1.679272 50.05408
53.69700 18.06968 1.679346 49.98904
53.74700 17.96942 1.679437 49.86068
53.79700 17.87010 1.679478 49.94715
53.84700 17.77020 1.679399 49.92396
53.89700 17.67006 1.679456 49.99145
53.94700 17.57051 1.679310 50.08395
53.99700 17.47016 1.679217 49.94419
54.04700 17.37128 1.679141 50.09010
54.09700 17.27063 1.679127 49.96851
54.14700 17.17150 1.679287 49.99877
54.19700 17.07096 1.679516 50.02861
54.24700 16.97180 1.679689 50.08415
54.29700 16.87160 1.680039 50.19120
54.34700 16.77082 1.680474 50.10548
54.39700 16.67123 1.681004 49.88512
54.44700 16.57061 1.681530 50.07652
54.49700 16.47109 1.682076 50.15473
54.54700 16.37086 1.682541 50.00686
54.59700 16.27118 1.683048 49.89054
54.64700 16.17108 1.683296 50.17150
54.69700 16.07099 1.683575 49.89210
54.74700 15.97086 1.683773 49.99409
54.79700 15.87052 1.683995 49.92312
54.84700 15.77118 1.684204 49.82441
54.89700 15.67118 1.684269 50.02756
54.94700 15.57062 1.684380 50.05731
54.99700 15.47144 1.684566 49.99842
55.04700 15.37180 1.684538 49.96171
55.09700 15.27123 1.684517 50.02761
55.14700 15.17108 1.684702 50.05450
55.19700 15.07017 1.684787 49.88096
55.24700 14.97048 1.684898 50.08084
55.29700 14.87162 1.685048 50.04106
55.34700 14.77184 1.685060 49.91908
55.39700 14.67169 1.685187 50.10150
55.44700 14.57184 1.685262 49.95130
55.49700 14.47108 1.685417 49.95471
55.54700 14.37096 1.685256 50.07067
55.59700 14.27143 1.685423 50.06816
55.64700 14.17278 1.685396 49.95504
55.69700 14.07172 1.685535 49.84778
55.74700 13.97196 1.685541 50.07857
55.79700 13.87234 1.685606 50.10921
55.84700 13.77184 1.685442 50.07770
55.89700 13.67180 1.685520 49.94968
55.94700 13.57201 1.685473 50.02652
55.99700 13.47253 1.685656 49.92552
56.04700 13.37279 1.685530 49.99172
56.09700 13.27286 1.685654 50.04962
56.14700 13.17289 1.685922 50.05656
56.19700 13.07319 1.686041 49.96987
56.24700 12.97340 1.686301 49.97058
56.29700 12.87265 1.686423 50.01579
56.34700 12.77279 1.686336 50.01294
56.39700 12.67265 1.686363 49.98056
56.44700 12.57413 1.686243 50.10965
56.49700 12.47412 1.686292 50.08003
56.54700 12.37337 1.686312 50.12715
56.59700 12.27401 1.686406 49.89127
56.64700 12.17323 1.686716 50.12690
56.69700 12.07392 1.686830 50.15188
56.74700 11.97328 1.686947 49.95736
56.79700 11.87410 1.687047 50.01162
56.84700 11.77344 1.687229 50.06326
56.89700 11.67403 1.687276 49.98199
56.94700 11.57391 1.687425 50.11520
56.99700 11.47421 1.687420 50.05118
57.04700 11.37323 1.687373 49.99824
57.09700 11.27458 1.687356 49.95059
57.14700 11.17500 1.687414 49.91059
57.19700 11.07378 1.687512 50.02821
57.24700 10.97438 1.687636 50.07250
57.29700 10.87451 1.687652 49.96900
57.34700 10.77373 1.687713 50.01688
57.39700 10.67336 1.687630 49.99928
57.44700 10.57461 1.687746 50.02578
57.49700 10.47439 1.687569 49.92996
57.54700 10.37497 1.687675 49.89406
57.59700 10.27459 1.687567 49.97002
57.64700 10.17520 1.687419 50.05098
57.69700 10.07480 1.687362 49.86516
57.74700 9.975196 1.687369 49.97970
57.79700 9.874243 1.687415 49.83822
57.84700 9.775178 1.687477 49.95346
57.89700 9.675228 1.687525 49.95762
57.94700 9.575772 1.687630 49.90516
57.99700 9.475012 1.687751 49.86900
58.04700 9.375566 1.687861 50.08568
58.09700 9.275089 1.687951 49.93374
58.14700 9.174898 1.688023 50.04634
58.19700 9.075782 1.688285 49.94757
58.24700 8.975129 1.688319 49.85276
58.29700 8.874828 1.688147 50.08252
58.34700 8.775939 1.688184 49.83160
58.39700 8.675253 1.688208 50.03572
58.44700 8.574957 1.688216 50.02335
58.49700 8.475129 1.688118 50.02856
58.54700 8.376239 1.688286 50.02516
58.59700 8.276018 1.688299 50.02632
58.64700 8.176255 1.688324 50.03306
58.69700 8.075380 1.688429 49.98900
58.74700 7.975738 1.688301 49.92402
58.79700 7.875688 1.688281 49.92382
58.84700 7.776026 1.688052 50.12554
58.89700 7.675996 1.688011 49.87764
58.94700 7.575434 1.687888 50.08287
58.99700 7.475839 1.687746 50.07044
59.04700 7.376665 1.687757 50.11373
59.09700 7.275512 1.687797 49.94402
59.14700 7.175934 1.687772 50.03308
59.19700 7.076957 1.687808 50.03878
59.24700 6.975622 1.688090 49.93428
59.29700 6.875695 1.688066 49.92330
59.34700 6.776078 1.688171 50.03691
59.39700 6.676745 1.688320 49.96224
59.44700 6.575939 1.688346 49.98315
59.49700 6.476840 1.688387 50.07950
59.54700 6.376730 1.688536 49.88489
59.59700 6.275996 1.688643 50.11688
59.64700 6.176368 1.688640 49.83838
59.69700 6.075866 1.688817 49.85038
59.74700 5.975902 1.688692 49.84916
59.79700 5.875807 1.688580 50.00037
59.84700 5.777008 1.688583 50.07154
59.89700 5.677132 1.688595 50.03418
59.94700 5.576825 1.688500 50.05619
59.99700 5.476985 1.688561 49.94090
60.04700 5.376655 1.688340 49.92276
60.09700 5.276215 1.688480 50.14742
60.14700 5.176770 1.688424 50.09067
60.19700 5.076452 1.688333 49.89621
60.24700 4.975766 1.688095 50.03575
60.29700 4.876694 1.688076 50.01365
60.34700 4.777892 1.687890 50.12807
60.39700 4.677436 1.687800 49.92688
60.44700 4.579040 1.687709 50.11846
60.49700 4.477883 1.687543 49.95306
60.54700 4.377480 1.687477 50.02328
60.59700 4.277708 1.687434 50.05200
60.64700 4.176798 1.687448 49.97850
60.69700 4.077370 1.687313 50.14480
60.74700 3.978314 1.687471 50.09184
60.79700 3.876563 1.687532 50.17280
60.84700 3.777778 1.687494 49.92450
60.89700 3.677044 1.687510 50.27280
60.94700 3.578008 1.687617 49.97075
60.99700 3.478428 1.687534 49.96762
61.04700 3.378140 1.687583 49.91431
61.09700 3.278558 1.687434 50.20938
61.14700 3.178272 1.687315 49.94404
61.19700 3.078457 1.687262 49.90194
61.24700 2.977534 1.687174 49.98524
61.29700 2.878492 1.687145 50.18164
61.34700 2.779003 1.687155 49.99553
61.39700 2.678191 1.687151 49.90422
61.44700 2.577713 1.687160 50.05320
61.49700 2.478328 1.687221 50.05934
61.54700 2.379394 1.687072 50.08476
61.59700 2.278338 1.687101 50.02429
61.64700 2.178704 1.687111 50.10786
61.69700 2.079688 1.687131 49.98921
61.74700 1.979277 1.687051 49.98344
61.79700 1.879964 1.687075 49.88440
61.84700 1.779052 1.687106 49.88830
61.89700 1.679902 1.687122 50.06586
61.94700 1.579275 1.687198 50.05624
61.99700 1.479372 1.687052 50.05206
62.04700 1.382284 1.687435 50.01126
62.09700 1.309850 1.645094 50.14047
62.14700 1.260917 1.516028 50.16610
62.19700 1.222441 1.385572 49.89894
62.24700 1.189495 1.252411 49.82376
62.29700 1.163382 1.126608 49.91785
62.34700 1.140517 1.007319 49.98503
62.39700 1.119743 0.8948906 49.91269
62.44700 1.103002 0.7955293 50.16470
62.49700 1.090286 0.7095031 50.00847
62.54700 1.077963 0.6354664 50.11746
62.59700 1.067384 0.5642572 49.90316
62.64700 1.059164 0.5073779 50.06167
62.69700 1.051016 0.4582430 49.93308
62.74700 1.044662 0.4158762 49.90084
62.79700 1.038643 0.3780022 49.99551
62.84700 1.033396 0.3492285 49.97549
62.89700 1.029989 0.3219056 49.98165
62.94700 1.026438 0.3011094 49.93879
62.99700 1.023438 0.2837710 49.98213
63.04700 1.020081 0.2668621 49.97912
63.09700 1.017531 0.2550748 49.99002
63.14700 1.015564 0.2453743 49.85410
63.19700 1.013246 0.2360911 50.08146
63.24700 1.011465 0.2271571 49.88444
63.29700 1.010148 0.2184834 50.16378
63.34700 1.008502 0.2102811 50.13082
63.39700 1.008344 0.2022003 49.95665
63.44700 1.007522 0.1946082 49.85088
63.49700 1.005258 0.1874932 49.96811
63.54700 1.005524 0.1807633 50.03735
63.59700 1.003749 0.1746953 50.05200
63.64700 1.004568 0.1691477 50.16338
63.69700 1.002931 0.1641949 50.04179
63.74700 1.002301 0.1594657 50.05676
63.79700 1.002377 0.1552678 49.98324
63.84700 1.001444 0.1514909 50.04244
63.89700 1.000758 0.1480934 49.91687
63.94700 1.000781 0.1450768 49.91294
63.99700 1.000161 0.1423387 50.13930
64.04700 0.9999601 0.1398328 49.88317
64.09700 0.9994220 0.1376870 50.00041
64.14700 0.9986580 0.1356336 49.94574
64.19701 0.9982822 0.1337869 49.98312
64.24700 0.9996231 0.1320903 50.05592
64.29700 0.9984765 0.1304686 49.91967
64.34700 0.9982722 0.1291710 49.96707
64.39700 0.9980981 0.1278043 49.98290
64.44701 0.9989343 0.1265204 50.07913
64.49700 0.9984912 0.1253628 50.03293
64.54700 0.9970332 0.1240774 49.87549
64.59700 0.9976522 0.1230695 50.07208
64.64700 0.9977137 0.1222139 50.16190
64.69701 0.9974438 0.1215743 50.03925
64.74700 0.9968658 0.1209651 49.88539
64.79700 0.9971439 0.1205257 50.00368
-2.000000 2.000000 0.0000000 0.0000000