File: imagens/notebooks/dados experimentais/dsc/Karl_DTAB200 Ur 45%.txt
CLOSED
Version	1.0
Language	English
Run	1
RunSerial	154
Instrument	DSC Q100 V9.9 Build 303
Module	DSC Standard Cell FC
Operator	LL
File	\\Niger\ta\Data\DSC\2018\Geral\Karl_DTAB200 Ur 45%.001
ProcName	Karl
InstSerial	0100-1211
Sample	DTAB200 Ur 45%
Size	14.5300	mg
Method	Karl
Comment
Xcomment	Pan: Aluminum Hermetic
Xcomment	Gas1: Nitrogen 50.0 ml/min
Xcomment	Gas2: Nitrogen 0.0 ml/min
Text
Exotherm	UP
Kcell	1.09030
Calib	-11.7822
TempCal	1	pts	158.71	156.60
TzeroDt	-90.0515 -0.0093 2.2263
TzeroDtz	-90.0515 0.0466 2.4421
InstCalFile	Tzero: \\Niger\ta\Data\DSC\CALIBRATION\20122016\CALIBRATION\0_RCS_12_20_2016 17_23_31.TZR
InstCalFile	Baseline: \\Niger\ta\Data\DSC\CALIBRATION\20122016\L.Base 20122016
InstCalFile	Sapphire: \\Niger\ta\Data\DSC\CALIBRATION\20122016\Safira 20122017.001
InstCalDate	Tzero 2016-12-20 Time 19:23:31
TempRange	-90.04 to 395.23 °C at 19.96 °C/min Heat Only
AutoZero	Delta T Offset 0.000 uV
AutoZero	Delta T0 Offset 0.000 uV
Controls	Gas 1  Event Off  Sampling 0.2
Cell#	FC-02451
CoolingUnit	RCS
SelHeatFlow	Heat Flow T4 (mW)
AutoAnalysis	Off
MacroFile
Nsig	4
Sig1	Time (min)
Sig2	Temperature (°C)
Sig3	Heat Flow (mW)
Sig4	Sample Purge Flow (mL/min)
Date	2018-05-17
Time	13:08:27
OrgMethod	1: Equilibrate at 1.00 °C
OrgMethod	2: Ramp 2.00 °C/min to 60.00 °C
OrgMethod	3: Isothermal for 3.00 min
OrgMethod	4: Mark end of cycle 1
OrgMethod	5: Ramp 2.00 °C/min to 1.00 °C
OrgMethod	6: Isothermal for 3.00 min
OrgMethod	7: Mark end of cycle 2
OrgFile	C:\TA\Data\DSC\2018\Geral\Karl_DTAB200 Ur 45%.001
3.33324E-4 1.179808 1.211141 50.00724
0.05033332 1.163841 1.063684 50.11793
0.1003333 1.175341 0.8655988 49.81604
0.1503333 1.212475 0.6350308 50.03396
0.2003333 1.259823 0.4100620 49.88342
0.2503333 1.316133 0.1917780 49.78428
0.3003333 1.378833 -3.0287E-3 50.14496
0.3503333 1.445469 -0.1886789 49.92454
0.4003334 1.518435 -0.3511124 50.07681
0.4503334 1.594279 -0.4924138 49.85746
0.5003334 1.673977 -0.6173900 49.97696
0.5503332 1.755384 -0.7296076 50.03896
0.6003332 1.839844 -0.8265124 49.89780
0.6503332 1.925239 -0.9094290 49.92114
0.7003332 2.013428 -0.9833200 49.95887
0.7503332 2.101860 -1.047361 50.02906
0.8003332 2.193560 -1.101112 50.02571
0.8503332 2.284749 -1.150820 50.06960
0.9003332 2.377263 -1.189469 49.82306
0.9503334 2.470828 -1.223268 50.09730
1.000333 2.564388 -1.255477 49.94524
1.050334 2.659634 -1.280174 50.03837
1.100334 2.755043 -1.302936 49.97964
1.150334 2.849170 -1.321072 50.08259
1.200334 2.946048 -1.337067 50.18706
1.250334 3.041669 -1.351562 50.06956
1.300334 3.138389 -1.363781 50.00880
1.350333 3.236468 -1.375760 49.88900
1.400333 3.333858 -1.386014 49.88450
1.450334 3.430838 -1.394606 50.14238
1.500333 3.528989 -1.404067 50.09884
1.550334 3.626507 -1.412769 49.86270
1.600334 3.725024 -1.421451 49.79863
1.650333 3.823370 -1.429821 49.85720
1.700334 3.920374 -1.437912 50.07297
1.750334 4.019626 -1.445556 50.13318
1.800334 4.116656 -1.452754 49.89770
1.850334 4.216050 -1.459608 49.87576
1.900334 4.315052 -1.466123 49.98029
1.950334 4.414649 -1.472148 50.07032
2.000334 4.512470 -1.477980 50.11590
2.050333 4.612084 -1.483199 50.01775
2.100334 4.710570 -1.488215 49.94715
2.150334 4.810211 -1.492991 49.87442
2.200334 4.908456 -1.497478 50.08346
2.250334 5.007464 -1.501587 49.95843
2.300333 5.106666 -1.505438 49.99400
2.350334 5.207107 -1.509015 49.84100
2.400334 5.305038 -1.512422 50.07212
2.450334 5.404789 -1.515582 49.99198
2.500334 5.504521 -1.518625 49.84107
2.550333 5.603924 -1.521575 50.05812
2.600333 5.703555 -1.524368 49.93292
2.650333 5.802546 -1.526994 50.10803
2.700333 5.901690 -1.529533 50.17210
2.750333 6.001162 -1.532188 49.96474
2.800333 6.101407 -1.534594 49.90590
2.850333 6.200671 -1.536825 50.00650
2.900333 6.299617 -1.538854 50.05893
2.950333 6.399101 -1.540975 50.05008
3.000333 6.498862 -1.542950 49.95989
3.050333 6.598462 -1.544908 49.92344
3.100333 6.697208 -1.546828 49.93906
3.150333 6.797425 -1.548669 50.06607
3.200333 6.897515 -1.550496 50.08688
3.250333 6.996312 -1.552311 50.08424
3.300333 7.095839 -1.554042 50.06010
3.350333 7.196038 -1.555702 50.06072
3.400333 7.295905 -1.557244 50.03602
3.450333 7.395359 -1.558943 50.03840
3.500333 7.495390 -1.560788 50.08228
3.550333 7.594775 -1.562433 49.85468
3.600333 7.693932 -1.564029 50.02280
3.650333 7.793744 -1.565476 50.16691
3.700333 7.893424 -1.566977 50.06318
3.750333 7.993256 -1.568411 49.79334
3.800333 8.093456 -1.569889 49.88212
3.850333 8.192726 -1.571283 49.84958
3.900333 8.293400 -1.572816 49.93139
3.950333 8.393334 -1.574372 49.94205
4.000333 8.492484 -1.575980 49.81596
4.050333 8.593308 -1.577531 49.88398
4.100333 8.692442 -1.579061 49.97777
4.150333 8.791902 -1.580370 49.93829
4.200333 8.892894 -1.581794 49.99353
4.250333 8.991472 -1.583114 49.93880
4.300333 9.091805 -1.584530 50.04663
4.350333 9.191666 -1.585777 50.12421
4.400333 9.292001 -1.586928 49.92782
4.450333 9.390631 -1.588052 50.22848
4.500333 9.490589 -1.589187 49.87406
4.550333 9.591079 -1.590227 49.97002
4.600333 9.690514 -1.591159 49.83757
4.650333 9.789550 -1.592421 49.97859
4.700333 9.889129 -1.593402 50.01660
4.750333 9.989239 -1.594525 49.94714
4.800333 10.08905 -1.595624 50.04540
4.850333 10.18870 -1.596584 50.14138
4.900333 10.28798 -1.597526 50.09176
4.950333 10.38852 -1.598600 49.95454
5.000333 10.48796 -1.599702 49.98892
5.050333 10.58718 -1.600968 50.03043
5.100333 10.68702 -1.602352 50.01380
5.150333 10.78627 -1.603918 50.11004
5.200333 10.88629 -1.605213 49.98868
5.250332 10.98668 -1.606603 50.03121
5.300332 11.08602 -1.607748 49.89516
5.350332 11.18662 -1.608989 49.94360
5.400332 11.28606 -1.610134 50.09016
5.450332 11.38559 -1.611356 50.08145
5.500332 11.48569 -1.612561 50.15041
5.550332 11.58500 -1.613628 50.07328
5.600332 11.68547 -1.614885 50.08166
5.650332 11.78487 -1.616279 50.08149
5.700332 11.88512 -1.617466 50.01504
5.750332 11.98443 -1.618664 49.92852
5.800332 12.08514 -1.620019 50.12146
5.850332 12.18398 -1.621275 49.80876
5.900332 12.28493 -1.622523 50.12642
5.950332 12.38435 -1.623856 50.05912
6.000332 12.48529 -1.625316 50.03836
6.050332 12.58408 -1.626825 50.04829
6.100332 12.68386 -1.628224 49.81330
6.150332 12.78378 -1.629672 49.96826
6.200332 12.88365 -1.631383 49.82113
6.250332 12.98347 -1.632736 50.02271
6.300332 13.08243 -1.634264 50.11334
6.350332 13.18306 -1.635803 50.02564
6.400332 13.28262 -1.637002 49.98050
6.450332 13.38273 -1.638428 50.09432
6.500332 13.48268 -1.639891 49.96876
6.550332 13.58276 -1.641186 50.06036
6.600332 13.68294 -1.642722 50.06381
6.650332 13.78250 -1.644006 50.02716
6.700332 13.88209 -1.645408 50.10046
6.750332 13.98243 -1.646778 50.07083
6.800332 14.08213 -1.648019 50.09407
6.850332 14.18269 -1.649547 50.16468
6.900332 14.28234 -1.650826 49.86320
6.950332 14.38256 -1.652110 50.09954
7.000332 14.48124 -1.653446 49.93647
7.050332 14.58316 -1.654597 50.14954
7.100332 14.68214 -1.655714 49.97824
7.150332 14.78142 -1.656907 49.98296
7.200332 14.88189 -1.658018 50.16564
7.250332 14.98102 -1.659218 49.91272
7.300332 15.08084 -1.660267 49.90910
7.350332 15.18039 -1.661524 49.93682
7.400332 15.27981 -1.662670 49.92230
7.450332 15.37974 -1.663773 49.93238
7.500332 15.47947 -1.665020 50.12276
7.550332 15.57948 -1.666246 49.97304
7.600332 15.67951 -1.667819 50.07022
7.650332 15.77926 -1.669365 49.96652
7.700332 15.87865 -1.670823 50.00766
7.750332 15.97898 -1.672450 49.97896
7.800332 16.07920 -1.674220 49.90862
7.850332 16.17854 -1.675792 49.93484
7.900332 16.27872 -1.677174 50.17110
7.950332 16.37836 -1.678613 49.86800
8.000334 16.47797 -1.679928 49.81303
8.050332 16.57799 -1.681204 50.00018
8.100332 16.67805 -1.682382 50.06794
8.150332 16.77799 -1.683649 49.91214
8.200332 16.87747 -1.684964 49.87954
8.250334 16.97718 -1.686209 50.09353
8.300332 17.07706 -1.687602 49.91601
8.350332 17.17681 -1.689133 50.08083
8.400332 17.27658 -1.690577 49.89267
8.450332 17.37556 -1.692074 50.06983
8.500334 17.47611 -1.693656 50.02488
8.550332 17.57569 -1.695264 50.03029
8.600332 17.67676 -1.696999 50.11718
8.650332 17.77562 -1.698700 50.03628
8.700332 17.87547 -1.700494 49.95538
8.750334 17.97540 -1.702413 49.96511
8.800332 18.07556 -1.704271 50.00217
8.850332 18.17502 -1.706280 50.05282
8.900332 18.27550 -1.708219 49.98544
8.950332 18.37519 -1.710378 49.88966
9.000334 18.47460 -1.712383 49.88054
9.050332 18.57521 -1.714320 49.93878
9.100332 18.67429 -1.716396 50.05348
9.150332 18.77305 -1.718392 50.12036
9.200332 18.87395 -1.720422 50.02564
9.250334 18.97412 -1.722455 49.88997
9.300332 19.07329 -1.724596 49.96729
9.350332 19.17264 -1.726788 50.00722
9.400332 19.27393 -1.728912 49.95094
9.450332 19.37263 -1.731221 49.96228
9.500334 19.47172 -1.733566 50.01071
9.550332 19.57178 -1.735976 50.01560
9.600332 19.67334 -1.738319 50.14967
9.650332 19.77240 -1.740830 50.10071
9.700332 19.87179 -1.743104 49.96926
9.750334 19.97267 -1.745645 49.88648
9.800332 20.07280 -1.747970 49.98370
9.850332 20.17170 -1.750192 50.05067
9.900332 20.27207 -1.752414 49.85696
9.950332 20.37174 -1.754616 49.93224
10.00033 20.47066 -1.756754 50.05056
10.05033 20.57108 -1.759146 50.00687
10.10033 20.67126 -1.761519 50.07842
10.15033 20.77068 -1.763821 49.83060
10.20033 20.87078 -1.766162 50.00960
10.25033 20.97039 -1.768585 50.03873
10.30033 21.06963 -1.771038 49.98238
10.35033 21.16920 -1.773477 49.87788
10.40033 21.26848 -1.776069 50.07431
10.45033 21.36892 -1.778590 49.93084
10.50034 21.46792 -1.781141 49.91410
10.55033 21.56786 -1.783829 50.14576
10.60033 21.66815 -1.786239 50.03050
10.65033 21.76834 -1.788875 50.04318
10.70033 21.86703 -1.791565 49.92384
10.75034 21.96723 -1.794345 49.87883
10.80033 22.06645 -1.796955 49.96399
10.85033 22.16722 -1.799869 50.11947
10.90033 22.26712 -1.802676 50.03350
10.95033 22.36611 -1.805452 49.98580
11.00034 22.46577 -1.808201 49.96228
11.05033 22.56580 -1.810979 50.11916
11.10033 22.66537 -1.813660 50.00106
11.15033 22.76430 -1.816532 50.00374
11.20033 22.86516 -1.819160 50.11924
11.25034 22.96324 -1.821817 50.04538
11.30033 23.06339 -1.824389 50.12430
11.35033 23.16268 -1.826778 50.13057
11.40033 23.26270 -1.829434 50.05190
11.45033 23.36290 -1.832084 50.01746
11.50034 23.46189 -1.834685 50.08734
11.55033 23.56221 -1.837226 50.07301
11.60033 23.66094 -1.840106 49.96267
11.65033 23.76177 -1.842840 49.94748
11.70033 23.86035 -1.845703 49.92576
11.75034 23.96062 -1.848699 50.13326
11.80033 24.06051 -1.851691 50.03652
11.85033 24.16014 -1.854694 49.89452
11.90033 24.25970 -1.857861 49.92340
11.95033 24.35992 -1.860945 50.10325
12.00034 24.46050 -1.864013 50.00106
12.05033 24.55892 -1.866966 49.92610
12.10033 24.65846 -1.870114 49.99470
12.15033 24.75898 -1.873331 50.05754
12.20033 24.85842 -1.876448 50.04730
12.25034 24.95744 -1.879972 50.10694
12.30033 25.05783 -1.883667 50.04078
12.35033 25.15777 -1.887359 49.94234
12.40033 25.25763 -1.891188 49.86875
12.45033 25.35750 -1.895183 50.02662
12.50034 25.45563 -1.899441 49.88363
12.55033 25.55625 -1.903725 49.87836
12.60033 25.65444 -1.908162 49.91120
12.65033 25.75460 -1.912871 49.98639
12.70033 25.85405 -1.917840 50.03976
12.75034 25.95443 -1.923153 49.97170
12.80033 26.05375 -1.928589 50.08398
12.85033 26.15283 -1.934779 50.03860
12.90033 26.25240 -1.941178 50.19213
12.95034 26.35100 -1.948167 50.08312
13.00034 26.45100 -1.956696 49.99133
13.05033 26.54898 -1.966532 50.10403
13.10033 26.64800 -1.983581 50.02340
13.15033 26.74652 -2.010793 50.06630
13.20034 26.84400 -2.047535 49.79180
13.25034 26.94248 -2.092894 49.95100
13.30033 27.03842 -2.142235 50.01619
13.35033 27.13550 -2.200078 50.04196
13.40033 27.23100 -2.255306 50.04288
13.45034 27.32648 -2.316064 49.93688
13.50034 27.42172 -2.376877 49.94743
13.55033 27.51706 -2.437926 50.01996
13.60033 27.61128 -2.498423 50.15910
13.65033 27.70596 -2.559131 49.92653
13.70034 27.80144 -2.617997 50.08354
13.75034 27.89724 -2.676008 49.92810
13.80033 27.99228 -2.727754 50.00554
13.85033 28.08829 -2.780459 49.94226
13.90033 28.18287 -2.826966 49.91965
13.95034 28.27969 -2.872971 50.07528
14.00034 28.37576 -2.918246 49.86106
14.05033 28.47185 -2.956690 50.05990
14.10033 28.56846 -2.994959 49.96344
14.15033 28.66546 -3.030706 49.95737
14.20034 28.76130 -3.062918 50.07918
14.25034 28.85952 -3.097452 49.93478
14.30033 28.95728 -3.125700 49.98830
14.35033 29.05350 -3.152810 50.10953
14.40033 29.15166 -3.179245 49.85266
14.45034 29.24817 -3.203100 49.91601
14.50034 29.34736 -3.226684 50.03050
14.55033 29.44530 -3.247958 50.10824
14.60033 29.54348 -3.266898 49.89231
14.65033 29.64111 -3.286471 50.04553
14.70034 29.74006 -3.303785 50.09198
14.75034 29.83834 -3.320975 49.96418
14.80033 29.93740 -3.337180 49.97994
14.85033 30.03643 -3.352731 50.01618
14.90033 30.13384 -3.364982 49.87314
14.95034 30.23368 -3.378706 49.88124
15.00034 30.33230 -3.390275 50.05118
15.05033 30.43113 -3.403910 49.90367
15.10033 30.52980 -3.414622 50.12618
15.15033 30.62894 -3.426136 49.98226
15.20034 30.72710 -3.437598 50.07703
15.25034 30.82682 -3.448289 49.84006
15.30033 30.92558 -3.460772 50.10623
15.35033 31.02466 -3.471286 50.05124
15.40033 31.12318 -3.481894 50.16990
15.45034 31.22334 -3.492361 50.01199
15.50034 31.32190 -3.503190 49.94191
15.55033 31.42246 -3.514094 50.00951
15.60033 31.52116 -3.525161 49.94982
15.65033 31.62000 -3.535595 49.96567
15.70034 31.71962 -3.545184 49.99698
15.75034 31.81894 -3.554797 50.02146
15.80033 31.91887 -3.563746 49.90776
15.85033 32.01710 -3.572594 50.03758
15.90033 32.11710 -3.581390 50.06194
15.95034 32.21665 -3.589759 50.13048
16.00033 32.31579 -3.597899 50.05569
16.05033 32.41576 -3.605728 50.18272
16.10033 32.51455 -3.613444 49.91372
16.15033 32.61441 -3.620850 50.01350
16.20033 32.71342 -3.627922 50.14060
16.25033 32.81336 -3.634812 49.95108
16.30033 32.91218 -3.641328 50.13550
16.35033 33.01147 -3.647525 49.99761
16.40033 33.11120 -3.653225 50.00606
16.45033 33.21090 -3.658344 50.06100
16.50033 33.31106 -3.662532 50.09378
16.55033 33.41101 -3.663855 49.99443
16.60033 33.51200 -3.658071 49.86350
16.65033 33.61350 -3.623726 50.10582
16.70033 33.71847 -3.538031 50.13270
16.75033 33.82598 -3.394395 50.06220
16.80033 33.93588 -3.190167 50.01987
16.85033 34.05199 -2.981374 50.14246
16.90033 34.16854 -2.778380 49.99476
16.95033 34.28348 -2.608211 49.92744
17.00033 34.39740 -2.465690 50.12472
17.05033 34.50894 -2.346096 50.01500
17.10033 34.61842 -2.240562 50.06378
17.15033 34.72654 -2.155890 49.93846
17.20033 34.83386 -2.083729 50.01310
17.25033 34.93930 -2.020706 50.07579
17.30033 35.04540 -1.974607 49.93369
17.35033 35.14870 -1.935834 50.08885
17.40033 35.25192 -1.902094 50.05926
17.45033 35.35632 -1.874096 50.05455
17.50033 35.45730 -1.852101 50.13320
17.55033 35.55984 -1.833060 49.97483
17.60033 35.66125 -1.819624 49.96257
17.65033 35.76230 -1.808668 49.91140
17.70033 35.86321 -1.798782 49.93544
17.75033 35.96456 -1.788757 49.91094
17.80033 36.06620 -1.780548 50.13941
17.85033 36.16671 -1.772106 50.11080
17.90033 36.26792 -1.763842 49.93452
17.95033 36.36768 -1.755954 49.95028
18.00033 36.46906 -1.748623 49.89966
18.05033 36.56875 -1.741708 50.04342
18.10033 36.66922 -1.735558 50.03280
18.15033 36.76970 -1.730006 50.16172
18.20033 36.87020 -1.724883 49.98736
18.25033 36.97038 -1.720382 50.07458
18.30033 37.07046 -1.716338 49.93494
18.35033 37.17098 -1.712860 49.98490
18.40033 37.27107 -1.709750 50.16946
18.45033 37.37030 -1.706859 49.98814
18.50033 37.47067 -1.704437 49.96672
18.55033 37.57085 -1.702284 50.01863
18.60033 37.67033 -1.700236 50.10347
18.65033 37.76983 -1.698521 50.08243
18.70033 37.87100 -1.696954 50.09780
18.75033 37.97063 -1.695764 50.02695
18.80033 38.07090 -1.694559 50.05105
18.85033 38.17191 -1.693656 50.18890
18.90033 38.27024 -1.693019 50.06968
18.95033 38.37125 -1.692582 49.85587
19.00033 38.47100 -1.692235 49.92060
19.05033 38.57101 -1.691766 49.81824
19.10033 38.67115 -1.691345 50.10430
19.15033 38.77095 -1.690698 50.02089
19.20033 38.87122 -1.690233 50.06696
19.25033 38.97156 -1.689816 50.09384
19.30033 39.07105 -1.689497 50.04708
19.35033 39.17184 -1.689297 50.11186
19.40033 39.27068 -1.689085 49.88572
19.45033 39.37112 -1.688930 50.09270
19.50033 39.47094 -1.688881 50.14593
19.55033 39.57055 -1.688697 50.00090
19.60033 39.67022 -1.688852 50.02740
19.65033 39.77075 -1.688958 50.03446
19.70033 39.87128 -1.689144 49.88180
19.75033 39.97110 -1.689424 50.01868
19.80033 40.07050 -1.689666 49.99190
19.85033 40.17086 -1.689964 49.84796
19.90033 40.27010 -1.690035 49.92446
19.95033 40.37076 -1.689966 50.12829
20.00033 40.46952 -1.689890 50.01002
20.05033 40.57087 -1.689828 49.97978
20.10033 40.67008 -1.689839 50.02212
20.15033 40.77088 -1.689780 49.92547
20.20033 40.87072 -1.689776 50.14466
20.25033 40.97003 -1.689929 49.88340
20.30033 41.06974 -1.690036 49.98134
20.35033 41.17030 -1.690182 50.08525
20.40033 41.27083 -1.690252 50.09050
20.45033 41.36984 -1.690398 49.98626
20.50033 41.46907 -1.690509 50.00076
20.55033 41.57000 -1.690789 49.84470
20.60033 41.66998 -1.690851 49.94787
20.65033 41.76970 -1.691032 49.96678
20.70033 41.86950 -1.690977 49.97367
20.75033 41.96942 -1.691250 49.96332
20.80033 42.06955 -1.691549 50.02812
20.85033 42.16876 -1.691868 50.11140
20.90033 42.26978 -1.692137 50.01450
20.95033 42.36958 -1.692208 50.07914
21.00033 42.46910 -1.692362 50.12783
21.05033 42.56938 -1.692409 50.01596
21.10033 42.66922 -1.692479 50.02450
21.15033 42.76904 -1.692641 50.03037
21.20033 42.86873 -1.692778 50.00086
21.25033 42.96893 -1.692993 50.00664
21.30033 43.06928 -1.693235 49.89622
21.35033 43.16851 -1.693533 50.04890
21.40033 43.26820 -1.693729 50.14546
21.45033 43.36810 -1.694138 50.10300
21.50033 43.46998 -1.694414 49.93276
21.55033 43.56944 -1.694626 50.14548
21.60033 43.66943 -1.694975 50.09259
21.65033 43.76896 -1.695254 49.91526
21.70033 43.86886 -1.695509 50.03150
21.75033 43.96922 -1.695676 49.81802
21.80033 44.06896 -1.695875 49.97715
21.85033 44.16846 -1.696034 49.94146
21.90033 44.26950 -1.696205 49.93646
21.95033 44.36950 -1.696344 50.02486
22.00033 44.46859 -1.696448 49.94906
22.05033 44.56890 -1.696509 50.01900
22.10033 44.66822 -1.696709 49.87826
22.15033 44.76834 -1.696760 49.90030
22.20033 44.86856 -1.696812 49.95822
22.25033 44.96874 -1.696903 50.02724
22.30033 45.06856 -1.696804 50.00884
22.35033 45.16770 -1.696726 49.99898
22.40033 45.26776 -1.696671 50.20380
22.45033 45.36750 -1.696826 50.07264
22.50033 45.46776 -1.697032 49.88731
22.55033 45.56739 -1.697258 49.92436
22.60033 45.66796 -1.697356 50.13350
22.65033 45.76791 -1.697526 49.96084
22.70033 45.86791 -1.697643 49.94641
22.75033 45.96803 -1.697971 49.95302
22.80033 46.06825 -1.698217 49.91000
22.85033 46.16734 -1.698316 50.10584
22.90033 46.26783 -1.698346 50.17344
22.95033 46.36698 -1.698338 49.90785
23.00033 46.46772 -1.698304 50.04300
23.05033 46.56718 -1.698335 50.00786
23.10033 46.66783 -1.698239 50.00934
23.15033 46.76750 -1.698289 50.05258
23.20033 46.86750 -1.698286 50.02790
23.25033 46.96738 -1.698315 50.16656
23.30033 47.06792 -1.698229 49.80790
23.35033 47.16752 -1.698048 50.05464
23.40033 47.26769 -1.698195 49.99467
23.45033 47.36700 -1.698280 49.91528
23.50033 47.46741 -1.698354 49.98516
23.55033 47.56784 -1.698442 49.87981
23.60033 47.66762 -1.698488 50.07978
23.65033 47.76778 -1.698520 49.98633
23.70033 47.86736 -1.698455 50.12626
23.75033 47.96774 -1.698407 49.94593
23.80033 48.06689 -1.698573 49.94650
23.85033 48.16756 -1.698685 49.80054
23.90033 48.26652 -1.698801 50.08716
23.95033 48.36680 -1.698994 49.99169
24.00033 48.46678 -1.699069 49.99547
24.05033 48.56726 -1.699142 50.07062
24.10033 48.66703 -1.699107 50.15020
24.15033 48.76710 -1.699106 49.92444
24.20033 48.86650 -1.698852 50.02961
24.25033 48.96618 -1.698720 49.91438
24.30033 49.06648 -1.698641 50.07988
24.35033 49.16618 -1.698527 49.89060
24.40033 49.26540 -1.698413 49.91303
24.45033 49.36693 -1.698165 50.03461
24.50033 49.46684 -1.698227 50.02115
24.55033 49.56670 -1.698198 50.12246
24.60033 49.66648 -1.698270 49.96236
24.65033 49.76653 -1.698284 49.94018
24.70033 49.86652 -1.698278 50.09798
24.75033 49.96668 -1.698408 50.11642
24.80033 50.06486 -1.698508 49.94502
24.85033 50.16601 -1.698863 50.01207
24.90033 50.26554 -1.699166 50.18392
24.95033 50.36528 -1.699663 50.11939
25.00033 50.46548 -1.700113 50.07159
25.05033 50.56563 -1.700557 49.90016
25.10033 50.66598 -1.700878 49.93944
25.15033 50.76528 -1.701096 50.02452
25.20033 50.86585 -1.701456 49.96396
25.25033 50.96541 -1.701876 49.94907
25.30033 51.06545 -1.702196 50.01906
25.35033 51.16553 -1.702405 49.77938
25.40033 51.26550 -1.702674 49.96783
25.45033 51.36570 -1.702836 49.95138
25.50033 51.46546 -1.702836 49.99093
25.55033 51.56530 -1.702744 50.05718
25.60033 51.66604 -1.702544 49.94498
25.65033 51.76606 -1.702478 49.92231
25.70033 51.86540 -1.702370 50.00440
25.75033 51.96578 -1.702402 49.94320
25.80033 52.06594 -1.702391 50.00653
25.85033 52.16568 -1.702378 49.97965
25.90033 52.26508 -1.702504 50.03377
25.95033 52.36519 -1.702658 49.96012
26.00033 52.46634 -1.702631 49.97444
26.05033 52.56470 -1.702840 49.95122
26.10033 52.66511 -1.703262 50.06160
26.15033 52.76510 -1.703541 50.01341
26.20033 52.86433 -1.703908 49.96018
26.25033 52.96460 -1.704056 50.09058
26.30033 53.06501 -1.704281 50.02510
26.35033 53.16412 -1.704606 49.83435
26.40033 53.26412 -1.704856 49.96776
26.45033 53.36452 -1.705258 50.13456
26.50033 53.46490 -1.705598 49.80212
26.55033 53.56380 -1.705938 49.79511
26.60033 53.66340 -1.706208 49.96474
26.65033 53.76360 -1.706432 50.15574
26.70033 53.86421 -1.706749 49.80172
26.75033 53.96470 -1.707102 49.98619
26.80033 54.06420 -1.707376 49.75024
26.85033 54.16384 -1.707644 50.05455
26.90033 54.26391 -1.707867 49.92636
26.95033 54.36343 -1.708077 50.00704
27.00033 54.46507 -1.708441 50.12532
27.05033 54.56479 -1.708638 49.83922
27.10033 54.66394 -1.708840 49.92920
27.15033 54.76376 -1.708965 49.93922
27.20033 54.86371 -1.708908 49.87797
27.25033 54.96400 -1.709034 50.06876
27.30033 55.06485 -1.709163 49.90512
27.35033 55.16438 -1.709508 50.08014
27.40033 55.26300 -1.709795 49.93282
27.45033 55.36310 -1.710229 50.00064
27.50033 55.46408 -1.710655 49.97028
27.55033 55.56370 -1.711143 50.04072
27.60033 55.66409 -1.711572 49.97394
27.65033 55.76376 -1.711897 50.02190
27.70033 55.86316 -1.712467 49.86160
27.75033 55.96344 -1.712808 50.06234
27.80033 56.06367 -1.713118 49.93252
27.85033 56.16313 -1.713495 49.95554
27.90033 56.26350 -1.713840 50.04450
27.95033 56.36322 -1.714325 49.98398
28.00033 56.46421 -1.714700 49.96533
28.05033 56.56301 -1.715176 50.15498
28.10033 56.66278 -1.715509 50.19129
28.15033 56.76324 -1.715636 49.90030
28.20033 56.86262 -1.716118 50.08890
28.25033 56.96320 -1.716512 50.02946
28.30033 57.06240 -1.716765 50.07722
28.35033 57.16250 -1.717008 49.91889
28.40033 57.26236 -1.717367 49.91678
28.45033 57.36279 -1.717575 50.09664
28.50033 57.46262 -1.717875 49.97242
28.55033 57.56268 -1.718280 50.23750
28.60033 57.66274 -1.718712 50.08962
28.65033 57.76295 -1.719195 49.98378
28.70033 57.86218 -1.719523 50.18547
28.75033 57.96174 -1.719737 50.06079
28.80033 58.06220 -1.719662 50.04636
28.85033 58.16132 -1.719832 49.93674
28.90033 58.26148 -1.720126 50.04000
28.95033 58.36240 -1.720494 50.01273
29.00033 58.46118 -1.720980 49.95007
29.05033 58.56039 -1.721278 50.08893
29.10033 58.66193 -1.721820 50.00271
29.15033 58.76113 -1.722336 49.96536
29.20033 58.86125 -1.722680 50.08661
29.25033 58.96208 -1.723010 49.93582
29.30033 59.06157 -1.723303 50.01103
29.35033 59.16116 -1.723666 49.88474
29.40033 59.26121 -1.723805 50.00726
29.45033 59.36051 -1.724142 50.02184
29.50033 59.46133 -1.724474 49.98950
29.55033 59.55671 -1.725687 49.90320
29.60033 59.62812 -1.675913 50.04184
29.65033 59.67895 -1.525872 50.03234
29.70033 59.71929 -1.380850 50.02412
29.75033 59.75256 -1.224596 50.01798
29.80033 59.78011 -1.080436 49.89678
29.85033 59.80386 -0.9445328 50.07953
29.90033 59.82394 -0.8212476 49.95700
29.95033 59.84043 -0.7131210 50.05616
30.00033 59.85559 -0.6139540 50.02094
30.05033 59.86791 -0.5311785 49.91038
30.10033 59.87795 -0.4557628 50.09000
30.15033 59.88793 -0.3974039 50.01215
30.20033 59.89575 -0.3461004 50.02090
30.25033 59.90205 -0.3001048 49.91934
30.30033 59.90818 -0.2615642 50.02231
30.35033 59.91348 -0.2274930 50.03966
30.40033 59.91778 -0.2003154 50.07024
30.45033 59.92224 -0.1737768 49.88675
30.50033 59.92522 -0.1557989 50.11620
30.55033 59.92725 -0.1393695 49.95812
30.60033 59.93111 -0.1262106 50.08435
30.65033 59.93309 -0.1140462 49.95250
30.70033 59.93416 -0.1043555 49.94158
30.75033 59.93660 -.09597438 49.92594
30.80033 59.93832 -.08720234 49.95482
30.85033 59.94028 -.07888182 49.99946
30.90033 59.94138 -.07085681 50.01824
30.95033 59.94277 -.06303695 50.12266
31.00033 59.94351 -.05564558 50.04127
31.05033 59.94408 -.04875256 49.97194
31.10033 59.94552 -.04238738 50.14469
31.15033 59.94552 -.03642692 49.90760
31.20033 59.94700 -.03100310 50.00513
31.25033 59.94700 -.02609310 50.04690
31.30033 59.94706 -.02146090 49.92517
31.35033 59.94832 -.01744940 50.01758
31.40033 59.94872 -.01369383 50.12631
31.45033 59.94901 -.01036256 50.01628
31.50033 59.94926 -7.4288E-3 49.90761
31.55033 59.95000 -4.9806E-3 50.14768
31.60033 59.95036 -2.7056E-3 50.02719
31.65033 59.95060 -4.0105E-4 49.97140
31.70033 59.95068 .001679793 50.04356
31.75033 59.95182 .003650434 49.88548
31.80033 59.95082 .005453881 50.01437
31.85034 59.95075 .007256324 49.87125
31.90033 59.95168 .008960959 49.97988
31.95033 59.95201 0.01033834 49.91016
32.00033 59.95175 0.01178462 49.97078
32.05033 59.95286 0.01308738 49.91632
32.10034 59.95328 0.01393706 49.87222
32.15033 59.95324 0.01469184 49.97834
32.20033 59.95342 0.01547802 49.95391
32.25033 59.95351 0.01623310 49.82210
32.30033 59.95332 0.01687082 50.01314
32.35034 59.95392 0.01769706 50.14569
32.40033 59.95371 0.01809577 50.02522
32.45033 59.95352 0.01877188 50.11063
-2.000000 1.000000 0.0000000 0.0000000
32.54700 59.95104 0.01954854 50.04925
32.59700 59.92566 0.06755728 49.89986
32.64700 59.87498 0.2171824 49.97735
32.69700 59.81560 0.3711788 50.14854
32.74700 59.74790 0.5246822 50.02947
32.79700 59.67548 0.6759061 50.10802
32.84700 59.59918 0.8146884 50.10273
32.89700 59.51938 0.9365068 50.01312
32.94700 59.43576 1.045445 49.99567
32.99700 59.35131 1.145597 50.01154
33.04700 59.26238 1.226994 49.93967
33.09700 59.17319 1.302501 50.17422
33.14700 59.08181 1.366511 50.06105
33.19700 58.98940 1.419184 50.10428
33.24700 58.89634 1.465274 49.98066
33.29700 58.80322 1.506726 49.87891
33.34700 58.70684 1.537968 50.01380
33.39700 58.61243 1.566305 50.05426
33.44700 58.51550 1.589740 49.94897
33.49700 58.41902 1.609119 50.00064
33.54700 58.32201 1.626199 50.00100
33.59700 58.22436 1.638441 50.13316
33.64700 58.12626 1.649404 49.89757
33.69700 58.02820 1.659120 50.07954
33.74700 57.92971 1.668348 50.00196
33.79700 57.83180 1.676875 50.07226
33.84700 57.73340 1.685222 50.06765
33.89700 57.63376 1.693795 50.18081
33.94700 57.53598 1.701693 49.99520
33.99700 57.43690 1.709494 49.94824
34.04700 57.33810 1.716566 50.10992
34.09700 57.23871 1.723202 50.19650
34.14700 57.13941 1.729292 49.86456
34.19700 57.04038 1.735004 50.04683
34.24700 56.94143 1.740032 49.99586
34.29700 56.84082 1.744566 50.05846
34.34700 56.74309 1.748701 49.88123
34.39700 56.64285 1.752489 50.02352
34.44700 56.54432 1.755949 49.96238
34.49700 56.44482 1.759249 49.94960
34.54700 56.34454 1.762324 50.05006
34.59700 56.24520 1.765021 50.12934
34.64700 56.14630 1.767451 50.08116
34.69700 56.04670 1.769561 49.88982
34.74700 55.94590 1.771795 49.96266
34.79700 55.84706 1.773785 49.82739
34.84700 55.74744 1.775589 50.00964
34.89700 55.64795 1.777396 50.20270
34.94700 55.54826 1.779127 49.95543
34.99700 55.44776 1.780668 50.05641
35.04700 55.34928 1.782134 49.92574
35.09700 55.24892 1.783673 49.99837
35.14700 55.14980 1.785047 49.90696
35.19700 55.04939 1.786476 49.85422
35.24700 54.94998 1.787870 49.99696
35.29700 54.85098 1.789102 49.95130
35.34700 54.75082 1.790180 50.07264
35.39700 54.65030 1.791484 49.93418
35.44700 54.55132 1.792621 50.03720
35.49700 54.45124 1.793608 50.07488
35.54700 54.35110 1.794835 49.99104
35.59700 54.25142 1.795646 50.06260
35.64700 54.15092 1.796383 49.94128
35.69700 54.05142 1.797087 50.12300
35.74700 53.95157 1.797908 50.10238
35.79700 53.85215 1.798424 50.04366
35.84700 53.75225 1.799120 49.99150
35.89700 53.65202 1.799701 49.91334
35.94700 53.55255 1.800172 50.11863
35.99700 53.45280 1.800570 49.91270
36.04700 53.35210 1.801111 49.90056
36.09700 53.25344 1.801754 50.10837
36.14700 53.15315 1.802176 49.87419
36.19700 53.05328 1.802804 49.87622
36.24700 52.95332 1.803450 49.88709
36.29700 52.85322 1.804057 50.00813
36.34700 52.75390 1.804581 49.92858
36.39700 52.65424 1.805166 49.93340
36.44700 52.55406 1.805679 50.03270
36.49700 52.45498 1.806066 50.04627
36.54700 52.35556 1.806622 50.08710
36.59700 52.25500 1.807031 49.94270
36.64700 52.15532 1.807616 49.98294
36.69700 52.05546 1.808239 50.09626
36.74700 51.95542 1.808640 50.02334
36.79700 51.85600 1.809096 50.09552
36.84700 51.75617 1.809536 50.14150
36.89700 51.65652 1.809846 49.98970
36.94700 51.55572 1.810230 49.87422
36.99700 51.45644 1.810516 49.94456
37.04700 51.35678 1.810903 49.99224
37.09700 51.25726 1.811428 50.00918
37.14700 51.15650 1.811948 49.93217
37.19700 51.05750 1.812453 49.97113
37.24700 50.95733 1.812989 49.78052
37.29700 50.85732 1.813462 50.06003
37.34700 50.75778 1.814348 49.85919
37.39700 50.65680 1.815031 49.98545
37.44700 50.55726 1.815614 49.98557
37.49700 50.45700 1.816276 49.97855
37.54700 50.35788 1.816852 50.06916
37.59700 50.25820 1.817233 50.05276
37.64700 50.15759 1.817718 49.97590
37.69700 50.05732 1.818112 50.17079
37.74700 49.95780 1.818399 50.17992
37.79700 49.85757 1.818884 50.13604
37.84700 49.75808 1.819216 49.91391
37.89700 49.65811 1.819663 49.98016
37.94700 49.55809 1.820041 49.98918
37.99700 49.45912 1.820332 50.05044
38.04700 49.35863 1.820644 49.93887
38.09700 49.25810 1.820716 50.00606
38.14700 49.15816 1.820956 50.04933
38.19700 49.05840 1.821231 50.14801
38.24700 48.95892 1.821377 49.90463
38.29700 48.85963 1.821462 50.08982
38.34700 48.75936 1.821632 49.99421
38.39700 48.65970 1.821989 49.87604
38.44700 48.55994 1.822228 49.91006
38.49700 48.45971 1.822357 49.98213
38.54700 48.36053 1.822550 49.96025
38.59700 48.26110 1.822890 49.97470
38.64700 48.16069 1.823028 49.90500
38.69700 48.06067 1.823213 50.07818
38.74700 47.96070 1.823436 50.09886
38.79700 47.86113 1.823853 50.00623
38.84700 47.76070 1.824147 49.97338
38.89700 47.66108 1.824530 49.97806
38.94700 47.56090 1.824997 50.01065
38.99700 47.46146 1.825346 50.14166
39.04700 47.36131 1.825718 50.14038
39.09700 47.26186 1.826102 49.91940
39.14700 47.16121 1.826635 49.91270
39.19700 47.06139 1.826881 50.04132
39.24700 46.96136 1.827292 50.10759
39.29700 46.86252 1.827607 49.98606
39.34700 46.76266 1.828041 50.10568
39.39700 46.66275 1.828359 49.85928
39.44700 46.56288 1.828678 49.97706
39.49700 46.46246 1.829040 49.82844
39.54700 46.36230 1.829537 50.10137
39.59700 46.26246 1.829986 49.98324
39.64700 46.16260 1.830421 50.12770
39.69700 46.06363 1.830972 50.02471
39.74700 45.96344 1.831286 49.96426
39.79700 45.86297 1.831669 49.86047
39.84700 45.76228 1.831920 49.98313
39.89700 45.66336 1.832194 49.93442
39.94700 45.56348 1.832513 49.97508
39.99700 45.46326 1.832718 50.05912
40.04700 45.36416 1.832893 49.96610
40.09700 45.26398 1.833202 50.08063
40.14700 45.16422 1.833483 50.00156
40.19700 45.06484 1.833752 50.01553
40.24700 44.96488 1.834167 49.95770
40.29700 44.86532 1.834460 50.00289
40.34700 44.76447 1.834852 49.93570
40.39700 44.66570 1.835247 49.90867
40.44700 44.56392 1.835491 50.04739
40.49700 44.46366 1.835876 49.94206
40.54700 44.36446 1.836214 50.10159
40.59700 44.26416 1.836492 50.08627
40.64700 44.16440 1.836745 50.00102
40.69700 44.06492 1.836999 49.94759
40.74700 43.96500 1.837379 49.84266
40.79700 43.86537 1.837585 49.97961
40.84700 43.76508 1.837734 49.91922
40.89700 43.66494 1.837892 50.00440
40.94700 43.56494 1.838134 50.09250
40.99700 43.46524 1.838417 49.88350
41.04700 43.36620 1.838613 49.97752
41.09700 43.26575 1.838881 50.12003
41.14700 43.16617 1.839132 49.97242
41.19700 43.06707 1.839321 49.97309
41.24700 42.96616 1.839525 49.89504
41.29700 42.86607 1.839744 49.87910
41.34700 42.76682 1.839913 50.02112
41.39700 42.66618 1.840094 50.07470
41.44700 42.56738 1.840210 49.80600
41.49700 42.46641 1.840353 49.97466
41.54700 42.36719 1.840723 49.80074
41.59700 42.26830 1.840900 50.04445
41.64700 42.16759 1.841192 50.19270
41.69700 42.06679 1.841493 50.04739
41.74700 41.96752 1.841733 49.98434
41.79700 41.86707 1.841776 49.99936
41.84700 41.76724 1.841992 49.97324
41.89700 41.66741 1.842378 49.85598
41.94700 41.56754 1.842500 49.90137
41.99700 41.46676 1.842785 49.92728
42.04700 41.36812 1.842905 49.93060
42.09700 41.26797 1.843004 50.02286
42.14700 41.16782 1.843156 50.04480
42.19700 41.06739 1.843238 49.99704
42.24700 40.96766 1.843453 49.86250
42.29700 40.86768 1.843579 50.06006
42.34700 40.76736 1.843734 50.02876
42.39700 40.66821 1.843836 50.01880
42.44700 40.56838 1.843945 49.96400
42.49700 40.46812 1.843948 50.03286
42.54700 40.36792 1.843910 50.02094
42.59700 40.26784 1.843804 50.10370
42.64700 40.16747 1.843729 50.01478
42.69700 40.06848 1.843616 50.01000
42.74700 39.96844 1.843511 49.92145
42.79700 39.86902 1.843476 50.10496
42.84700 39.76860 1.843500 49.94066
42.89700 39.66910 1.843446 50.03102
42.94700 39.56919 1.843176 50.04364
42.99700 39.46837 1.843118 49.82574
43.04700 39.36964 1.843091 49.94488
43.09700 39.26950 1.842976 49.94168
43.14700 39.16997 1.842983 50.10266
43.19700 39.07007 1.843120 50.01924
43.24700 38.97024 1.843228 50.11730
43.29700 38.86969 1.843311 50.00821
43.34700 38.76992 1.843464 50.05219
43.39700 38.67028 1.843706 49.99662
43.44700 38.57031 1.843987 50.04126
43.49700 38.46979 1.844306 49.96847
43.54700 38.37030 1.844479 50.14612
43.59700 38.27060 1.844530 49.95706
43.64700 38.17000 1.844702 50.17628
43.69700 38.07068 1.844783 50.08920
43.74700 37.97108 1.844880 50.01818
43.79700 37.87094 1.845030 49.94626
43.84700 37.77101 1.845160 50.05086
43.89700 37.67048 1.845189 49.99373
43.94700 37.57070 1.845220 50.03399
43.99700 37.47036 1.845384 49.93261
44.04700 37.37142 1.845576 49.86520
44.09700 37.27120 1.845676 50.08912
44.14700 37.17072 1.845648 49.99103
44.19700 37.07030 1.845908 49.95053
44.24700 36.97091 1.845992 49.91166
44.29700 36.87065 1.846181 50.11989
44.34700 36.77133 1.846446 49.92092
44.39700 36.67156 1.846283 49.93766
44.44700 36.57124 1.846375 49.96631
44.49700 36.47075 1.846569 49.85562
44.54700 36.37111 1.846743 49.91441
44.59700 36.27119 1.846758 50.06544
44.64700 36.17115 1.846737 50.21498
44.69700 36.07122 1.846820 49.98367
44.74700 35.97078 1.846825 50.13261
44.79700 35.87148 1.846800 50.04938
44.84700 35.77204 1.846722 49.89613
44.89700 35.67207 1.846449 50.13713
44.94700 35.57234 1.846504 50.11895
44.99700 35.47197 1.846329 49.92154
45.04700 35.37270 1.846463 50.00723
45.09700 35.27226 1.846465 50.05414
45.14700 35.17334 1.846504 50.08482
45.19700 35.07182 1.846514 49.97892
45.24700 34.97233 1.846596 49.98336
45.29700 34.87316 1.846961 50.02306
45.34700 34.77344 1.847188 49.89238
45.39700 34.67291 1.847420 50.11852
45.44700 34.57341 1.847684 49.91562
45.49700 34.47354 1.848119 49.90146
45.54700 34.37336 1.848192 50.06910
45.59700 34.27345 1.848463 49.99520
45.64700 34.17311 1.848650 50.05417
45.69700 34.07385 1.849039 49.88285
45.74700 33.97383 1.849195 49.96340
45.79700 33.87478 1.849269 49.98410
45.84700 33.77397 1.849385 50.00153
45.89700 33.67420 1.849403 49.96490
45.94700 33.57416 1.849523 49.94500
45.99700 33.47412 1.849361 49.94547
46.04700 33.37436 1.849419 50.03179
46.09700 33.27459 1.849160 50.17557
46.14700 33.17493 1.849071 49.85808
46.19700 33.07478 1.848955 50.20524
46.24700 32.97460 1.848663 49.99036
46.29700 32.87476 1.848614 49.96729
46.34700 32.77447 1.848483 50.19170
46.39700 32.67459 1.848444 50.10717
46.44700 32.57484 1.848281 50.04457
46.49700 32.47430 1.848210 50.05112
46.54700 32.37460 1.848097 49.96591
46.59700 32.27426 1.847977 49.93210
46.64700 32.17432 1.847837 50.07124
46.69700 32.07444 1.847654 50.10246
46.74700 31.97573 1.847609 49.78580
46.79700 31.87454 1.847617 49.97280
46.84700 31.77422 1.847584 50.23797
46.89700 31.67416 1.847614 50.07746
46.94700 31.57507 1.847481 49.90548
46.99700 31.47460 1.847418 49.92824
47.04700 31.37554 1.847461 49.97559
47.09700 31.27472 1.847271 50.01287
47.14700 31.17507 1.847098 50.03457
47.19700 31.07520 1.847066 50.01522
47.24700 30.97599 1.847021 50.03834
47.29700 30.87530 1.847007 49.86916
47.34700 30.77544 1.847320 50.00988
47.39700 30.67660 1.848326 50.05989
47.44700 30.57620 1.852528 49.97257
47.49700 30.48000 1.955166 50.01070
47.54700 30.39210 2.268562 49.91944
47.59700 30.32390 2.963435 50.10494
47.64700 30.28502 4.018261 50.01918
47.69700 30.26306 5.001498 50.09828
47.74700 30.23085 5.603066 49.99946
47.79700 30.17589 5.893010 49.95540
47.84700 30.10148 6.010530 50.00402
47.89700 30.01398 6.035657 50.05810
47.94700 29.91578 5.976948 50.10139
47.99700 29.81191 5.854649 49.97851
48.04700 29.70297 5.711514 49.89118
48.09700 29.59296 5.576628 50.14120
48.14700 29.48159 5.447626 49.85652
48.19700 29.37192 5.321964 49.90450
48.24700 29.26143 5.202228 50.06862
48.29700 29.15217 5.091261 50.05268
48.34700 29.04326 4.986460 50.04996
48.39700 28.93454 4.886064 49.92450
48.44700 28.82606 4.788292 49.80800
48.49700 28.71789 4.693242 49.92137
48.54700 28.61052 4.609640 50.03662
48.59700 28.50385 4.531360 49.87946
48.64700 28.39707 4.449447 50.00379
48.69700 28.29096 4.379272 49.83789
48.74700 28.18502 4.309500 50.00718
48.79700 28.07954 4.245062 50.08967
48.84700 27.97425 4.184180 49.97106
48.89700 27.86812 4.127478 50.07256
48.94700 27.76446 4.068442 49.91850
48.99700 27.65944 4.016620 49.94641
49.04700 27.55492 3.962689 49.87815
49.09700 27.45142 3.911807 50.07688
49.14700 27.34676 3.862420 50.07922
49.19700 27.24202 3.812139 49.84640
49.24700 27.13909 3.758424 49.88820
49.29700 27.03426 3.705182 49.96328
49.34700 26.93054 3.646762 49.91904
49.39700 26.82476 3.581409 50.04111
49.44700 26.72030 3.514580 50.01481
49.49700 26.61528 3.437986 49.88814
49.54700 26.50904 3.358606 49.97678
49.59700 26.40216 3.266155 49.91840
49.64700 26.29439 3.168590 49.86756
49.69700 26.18648 3.068720 49.94050
49.74700 26.07926 2.970058 49.86094
49.79700 25.97175 2.874390 49.88498
49.84700 25.86324 2.782700 49.99893
49.89700 25.75642 2.702478 49.95542
49.94700 25.64943 2.632441 50.00008
49.99700 25.54408 2.567195 50.14954
50.04700 25.43790 2.509894 49.89571
50.09700 25.33350 2.461677 50.07789
50.14700 25.22832 2.418970 49.99414
50.19700 25.12514 2.381901 49.92148
50.24700 25.02293 2.348870 49.89590
50.29700 24.91925 2.321641 50.11434
50.34700 24.81710 2.296957 49.90490
50.39700 24.71514 2.275633 49.95096
50.44700 24.61308 2.258276 50.03268
50.49700 24.51184 2.242611 49.96253
50.54700 24.41073 2.229092 50.08754
50.59700 24.30874 2.216631 49.93045
50.64700 24.20756 2.205984 50.00046
50.69700 24.10727 2.196289 49.93888
50.74700 24.00609 2.187082 49.95242
50.79700 23.90508 2.177611 49.98600
50.84700 23.80493 2.168291 49.91674
50.89700 23.70403 2.159070 49.99881
50.94700 23.60301 2.150205 50.15444
50.99700 23.50258 2.141590 50.02617
51.04700 23.40297 2.133497 50.03666
51.09700 23.30108 2.125579 49.95706
51.14700 23.20186 2.118098 50.03816
51.19700 23.10073 2.110997 49.86452
51.24700 22.99946 2.104146 49.97596
51.29700 22.89996 2.097690 50.02575
51.34700 22.79995 2.091449 49.99959
51.39700 22.70044 2.085598 50.09708
51.44700 22.59903 2.079898 50.03764
51.49700 22.49956 2.074460 49.95820
51.54700 22.39890 2.069073 49.98832
51.59700 22.29830 2.064049 49.90404
51.64700 22.19760 2.059181 49.91438
51.69700 22.09873 2.054338 50.14452
51.74700 21.99812 2.049812 50.06174
51.79700 21.89819 2.045576 49.98200
51.84700 21.79804 2.041306 49.96108
51.89700 21.69754 2.037209 49.99213
51.94700 21.59713 2.033282 49.94420
51.99700 21.49692 2.029616 50.04418
52.04700 21.39661 2.026040 50.00182
52.09700 21.29663 2.022618 49.91440
52.14700 21.19534 2.019191 49.93300
52.19700 21.09490 2.015964 50.10674
52.24700 20.99502 2.012909 50.02199
52.29700 20.89561 2.009723 50.05426
52.34700 20.79534 2.006479 50.16920
52.39700 20.69475 2.003392 50.00496
52.44700 20.59388 2.000205 50.01817
52.49700 20.49366 1.997092 50.00488
52.54700 20.39431 1.993830 50.06563
52.59700 20.29336 1.990616 50.08392
52.64700 20.19299 1.987511 50.06346
52.69700 20.09348 1.984375 50.06578
52.74700 19.99285 1.981162 50.17686
52.79700 19.89330 1.978140 50.04012
52.84700 19.79306 1.975112 49.86078
52.89700 19.69237 1.972121 49.88272
52.94700 19.59233 1.969238 49.90531
52.99700 19.49212 1.966317 50.04660
53.04700 19.39241 1.963393 49.93549
53.09700 19.29157 1.960670 49.98746
53.14700 19.19194 1.957925 49.86911
53.19700 19.09181 1.955307 50.01298
53.24700 18.99185 1.952476 50.03147
53.29700 18.89164 1.950005 49.86460
53.34700 18.79136 1.947513 50.12211
53.39700 18.69144 1.945054 49.84000
53.44700 18.59018 1.942602 50.04113
53.49700 18.49091 1.940301 49.93129
53.54700 18.39075 1.937716 50.05978
53.59700 18.28939 1.935260 50.03102
53.64700 18.19088 1.932938 49.86422
53.69700 18.09016 1.930362 49.91934
53.74700 17.99060 1.928003 49.91348
53.79700 17.89048 1.925484 50.05288
53.84700 17.79003 1.923213 50.11739
53.89700 17.68995 1.921105 50.04908
53.94700 17.58977 1.918916 49.98219
53.99700 17.48948 1.916831 49.90388
54.04700 17.38888 1.914748 49.82283
54.09700 17.28860 1.912548 50.00815
54.14700 17.18848 1.910611 50.03563
54.19700 17.08850 1.908522 49.95342
54.24700 16.98909 1.906692 49.84676
54.29700 16.88895 1.904716 50.05092
54.34700 16.78959 1.902683 49.91726
54.39700 16.68930 1.900720 49.91983
54.44700 16.58890 1.898691 50.01112
54.49700 16.48912 1.896718 50.03011
54.54700 16.38856 1.894696 50.12000
54.59700 16.28936 1.892929 49.97016
54.64700 16.18864 1.891129 50.04296
54.69700 16.08832 1.889522 49.96850
54.74700 15.98796 1.887822 49.95944
54.79700 15.88776 1.886315 49.95996
54.84700 15.78820 1.884838 50.07848
54.89700 15.68860 1.883312 49.93798
54.94700 15.58860 1.881600 49.83231
54.99700 15.48832 1.879823 50.16559
55.04700 15.38748 1.878311 50.02276
55.09700 15.28730 1.876819 50.02072
55.14700 15.18800 1.875383 49.88696
55.19700 15.08697 1.873977 49.97490
55.24700 14.98774 1.872681 49.86830
55.29700 14.88696 1.871237 50.01967
55.34700 14.78632 1.870079 49.99016
55.39700 14.68691 1.868721 49.89788
55.44700 14.58733 1.867382 50.13117
55.49700 14.48602 1.866094 49.92761
55.54700 14.38707 1.864699 50.12946
55.59700 14.28702 1.863267 49.97438
55.64700 14.18705 1.861965 50.05981
55.69700 14.08631 1.860468 50.10640
55.74700 13.98722 1.859026 49.86508
55.79700 13.88663 1.857583 50.03874
55.84700 13.78699 1.856173 50.04528
55.89700 13.68740 1.854860 49.86440
55.94700 13.58686 1.853486 49.90051
55.99700 13.48617 1.852067 50.03789
56.04700 13.38695 1.850785 50.23425
56.09700 13.28612 1.849399 49.93217
56.14700 13.18638 1.848168 49.93709
56.19700 13.08610 1.846818 50.15271
56.24700 12.98608 1.845547 50.05990
56.29700 12.88650 1.844226 49.97596
56.34700 12.78659 1.843162 50.03639
56.39700 12.68655 1.842040 50.02321
56.44700 12.58624 1.841026 49.90262
56.49700 12.48581 1.840091 50.03584
56.54700 12.38640 1.839194 49.92008
56.59700 12.28667 1.838159 50.02644
56.64700 12.18690 1.837161 50.01650
56.69700 12.08595 1.836202 50.02540
56.74700 11.98662 1.835246 49.96356
56.79700 11.88536 1.834227 50.02268
56.84700 11.78691 1.833268 50.15473
56.89700 11.68617 1.832218 50.05064
56.94700 11.58592 1.831252 50.11560
56.99700 11.48634 1.830124 50.13690
57.04700 11.38586 1.829115 50.02662
57.09700 11.28635 1.828120 50.13406
57.14700 11.18734 1.827169 50.00299
57.19700 11.08584 1.826376 50.12876
57.24700 10.98569 1.825505 49.88062
57.29700 10.88554 1.824572 49.93176
57.34700 10.78605 1.823691 50.06586
57.39700 10.68523 1.822929 50.09399
57.44700 10.58660 1.822041 50.06042
57.49700 10.48500 1.821326 50.05656
57.54700 10.38579 1.820464 49.91850
57.59700 10.28597 1.819501 50.12206
57.64700 10.18545 1.818664 49.90200
57.69700 10.08563 1.817703 50.00090
57.74700 9.985626 1.816755 49.99632
57.79700 9.886070 1.815961 50.04464
57.84700 9.785772 1.815209 49.91031
57.89700 9.686350 1.814459 50.06532
57.94700 9.585995 1.813689 50.00034
57.99700 9.485541 1.812922 49.89248
58.04700 9.386182 1.812250 49.91932
58.09700 9.285208 1.811460 49.82971
58.14700 9.186282 1.810518 49.90162
58.19700 9.085824 1.809624 50.03105
58.24700 8.985809 1.808652 50.08362
58.29700 8.886649 1.807758 49.91772
58.34700 8.784928 1.806872 49.93916
58.39700 8.686519 1.805888 49.98839
58.44700 8.586018 1.805087 50.04754
58.49700 8.486766 1.804418 50.12643
58.54700 8.386422 1.803713 49.96338
58.59700 8.286512 1.803213 50.11422
58.64700 8.186853 1.802648 49.89952
58.69700 8.086749 1.802166 49.96109
58.74700 7.986858 1.801861 49.95628
58.79700 7.886978 1.801564 50.14028
58.84700 7.785816 1.801149 50.02921
58.89700 7.686030 1.800686 49.94304
58.94700 7.586762 1.800206 49.95856
58.99700 7.486288 1.799740 50.12213
59.04700 7.386894 1.799395 50.08710
59.09700 7.286510 1.798952 49.99438
59.14700 7.186835 1.798399 49.94011
59.19700 7.086121 1.797934 50.05829
59.24700 6.986414 1.797225 49.93316
59.29700 6.885344 1.796744 50.07162
59.34700 6.786718 1.795997 50.11074
59.39700 6.686160 1.795388 50.18384
59.44700 6.586324 1.794893 50.04181
59.49700 6.485610 1.794262 50.06746
59.54700 6.387340 1.793721 49.87949
59.59700 6.286006 1.793368 49.79403
59.64700 6.186290 1.793006 49.97766
59.69700 6.086585 1.792518 49.97096
59.74700 5.986162 1.791969 50.05338
59.79700 5.886780 1.791571 50.03504
59.84700 5.786886 1.791267 49.88288
59.89700 5.686658 1.790741 50.08962
59.94700 5.587107 1.790149 50.15336
59.99700 5.486990 1.789738 50.04941
60.04700 5.387359 1.789216 50.01914
60.09700 5.287414 1.788796 49.91720
60.14700 5.187678 1.788296 50.13330
60.19700 5.087013 1.787933 49.96216
60.24700 4.986687 1.787349 49.92652
60.29700 4.887540 1.786901 49.95367
60.34700 4.788916 1.786322 50.01089
60.39700 4.687357 1.785859 49.98641
60.44700 4.588734 1.785616 50.19706
60.49700 4.488156 1.785636 50.00217
60.54700 4.387500 1.785458 49.87161
60.59700 4.288326 1.785222 49.84471
60.64700 4.187870 1.784877 50.00388
60.69700 4.087865 1.784716 49.93456
60.74700 3.987032 1.784651 50.13450
60.79700 3.887928 1.784607 49.88328
60.84700 3.787204 1.784501 49.93504
60.89700 3.688225 1.784411 49.95966
60.94700 3.587604 1.784218 49.90121
60.99700 3.487549 1.784166 49.95518
61.04700 3.387699 1.783938 49.98674
61.09700 3.287448 1.783552 50.03388
61.14700 3.187472 1.783222 50.01763
61.19700 3.086892 1.783000 49.94312
61.24700 2.987500 1.782610 49.95078
61.29700 2.886635 1.782377 49.78984
61.34700 2.787700 1.781944 50.05881
61.39700 2.688056 1.781632 49.96653
61.44700 2.586722 1.781354 50.16343
61.49700 2.486804 1.781050 50.15379
61.54700 2.387543 1.780838 50.06480
61.59700 2.287912 1.780589 49.95873
61.64700 2.187326 1.780250 50.05910
61.69700 2.087553 1.780110 49.99384
61.74700 1.987232 1.779642 50.13164
61.79700 1.886596 1.779282 49.93360
61.84700 1.787799 1.778994 49.99893
61.89700 1.686808 1.778581 50.12879
61.94700 1.586851 1.778264 50.04779
61.99700 1.487034 1.777870 50.03210
62.04700 1.390766 1.777792 49.96160
62.09700 1.318028 1.725586 50.11344
62.14700 1.267516 1.590088 49.96856
62.19700 1.228503 1.455051 49.95085
62.24700 1.196101 1.315966 49.88485
62.29700 1.168914 1.183477 50.02528
62.34700 1.145526 1.058369 50.08428
62.39700 1.125352 0.9434469 49.85730
62.44700 1.108514 0.8447841 49.88260
62.49700 1.094450 0.7505278 50.02921
62.54700 1.081828 0.6701894 50.02782
62.59700 1.072446 0.6047016 49.85747
62.64700 1.062184 0.5439966 50.03080
62.69700 1.054477 0.4917806 50.02885
62.74700 1.047552 0.4477940 50.01288
62.79700 1.042260 0.4085647 49.98215
62.84700 1.037724 0.3766919 49.95970
62.89700 1.032356 0.3508460 49.87274
62.94700 1.029393 0.3276532 50.10238
62.99700 1.025347 0.3096459 49.95670
63.04700 1.023474 0.2914711 49.92108
63.09700 1.020469 0.2794816 49.98447
63.14700 1.018508 0.2693936 50.06530
63.19700 1.016253 0.2605086 49.92148
63.24700 1.014902 0.2520402 49.94482
63.29700 1.013672 0.2429966 50.04810
63.34700 1.011739 0.2346994 49.90943
63.39700 1.010098 0.2264552 49.99264
63.44700 1.010046 0.2187578 50.03912
63.49700 1.008173 0.2115579 50.00468
63.54700 1.007534 0.2049253 50.14981
63.59700 1.006953 0.1987189 50.14629
63.64700 1.006349 0.1929927 49.95717
63.69700 1.005819 0.1876688 50.05335
63.74700 1.004152 0.1828685 49.82938
63.79700 1.004397 0.1786421 49.99202
63.84700 1.003537 0.1745817 50.17384
63.89700 1.002611 0.1711542 49.83348
63.94700 1.003561 0.1678658 49.93705
63.99700 1.001859 0.1649184 49.97116
64.04700 1.001178 0.1622109 49.98864
64.09700 1.001354 0.1599740 50.01933
64.14700 1.001177 0.1578270 50.00031
64.19701 1.001654 0.1558783 50.00526
64.24700 1.000198 0.1540029 49.89795
64.29700 0.9996719 0.1522551 49.96786
64.34700 0.9994314 0.1507490 50.16504
64.39700 0.9999191 0.1494197 50.02259
64.44701 1.000498 0.1480263 50.03941
64.49700 1.000043 0.1469854 49.94638
64.54700 0.9994246 0.1459347 49.97367
64.59700 0.9989266 0.1449712 50.00266
64.64700 0.9991424 0.1443194 50.01968
64.69701 0.9979141 0.1435283 50.10956
64.74700 0.9990362 0.1429810 50.02457
64.79700 0.9976830 0.1424896 50.08915
-2.000000 2.000000 0.0000000 0.0000000