File: imagens/notebooks/dados experimentais/dsc/Karl_TTAB200 Ur 45%.txt
CLOSED
Version	1.0
Language	English
Run	1
RunSerial	157
Instrument	DSC Q100 V9.9 Build 303
Module	DSC Standard Cell FC
Operator	LL
File	\\Niger\ta\Data\DSC\2018\Geral\Karl_TTAB200 Ur 45%.001
ProcName	Karl
InstSerial	0100-1211
Sample	TTAB200 Ur 45%
Size	11.6800	mg
Method	Karl
Comment
Xcomment	Pan: Aluminum Hermetic
Xcomment	Gas1: Nitrogen 50.0 ml/min
Xcomment	Gas2: Nitrogen 0.0 ml/min
Text
Exotherm	UP
Kcell	1.09030
Calib	-11.7822
TempCal	1	pts	158.71	156.60
TzeroDt	-90.0515 -0.0093 2.2263
TzeroDtz	-90.0515 0.0466 2.4421
InstCalFile	Tzero: \\Niger\ta\Data\DSC\CALIBRATION\20122016\CALIBRATION\0_RCS_12_20_2016 17_23_31.TZR
InstCalFile	Baseline: \\Niger\ta\Data\DSC\CALIBRATION\20122016\L.Base 20122016
InstCalFile	Sapphire: \\Niger\ta\Data\DSC\CALIBRATION\20122016\Safira 20122017.001
InstCalDate	Tzero 2016-12-20 Time 19:23:31
TempRange	-90.04 to 395.23 °C at 19.96 °C/min Heat Only
AutoZero	Delta T Offset 0.000 uV
AutoZero	Delta T0 Offset 0.000 uV
Controls	Gas 1  Event Off  Sampling 0.2
Cell#	FC-02451
CoolingUnit	RCS
SelHeatFlow	Heat Flow T4 (mW)
AutoAnalysis	Off
MacroFile
Nsig	4
Sig1	Time (min)
Sig2	Temperature (°C)
Sig3	Heat Flow (mW)
Sig4	Sample Purge Flow (mL/min)
Date	2018-05-17
Time	17:00:37
OrgMethod	1: Equilibrate at 1.00 °C
OrgMethod	2: Ramp 2.00 °C/min to 60.00 °C
OrgMethod	3: Isothermal for 3.00 min
OrgMethod	4: Mark end of cycle 1
OrgMethod	5: Ramp 2.00 °C/min to 1.00 °C
OrgMethod	6: Isothermal for 3.00 min
OrgMethod	7: Mark end of cycle 2
OrgFile	C:\TA\Data\DSC\2018\Geral\Karl_TTAB200 Ur 45%.001
3.33324E-4 1.161500 1.027480 49.89020
0.05033332 1.148570 0.9122447 50.05550
0.1003333 1.163360 0.7629676 49.87676
0.1503333 1.204057 0.5893301 50.04817
0.2003333 1.255239 0.4051991 49.85117
0.2503333 1.315357 0.2278767 49.96125
0.3003333 1.381892 0.06680450 49.95675
0.3503333 1.451930 -.08911681 50.04784
0.4003334 1.526736 -0.2238484 49.96090
0.4503334 1.604386 -0.3444903 50.12560
0.5003334 1.686222 -0.4521420 49.81121
0.5503332 1.769877 -0.5433590 49.97166
0.6003332 1.854615 -0.6240215 50.03674
0.6503332 1.943177 -0.6932563 49.99870
0.7003332 2.032397 -0.7515850 49.94834
0.7503332 2.122162 -0.8066757 50.09512
0.8003332 2.214480 -0.8496858 49.96097
0.8503332 2.306374 -0.8892909 49.92447
0.9003332 2.399541 -0.9227738 50.04986
0.9503334 2.492820 -0.9510192 49.99704
1.000333 2.588049 -0.9763519 50.09761
1.050334 2.684130 -0.9974755 50.01235
1.100334 2.778877 -1.015196 50.08824
1.150334 2.874300 -1.030532 49.99179
1.200334 2.970838 -1.043948 49.88656
1.250334 3.067433 -1.054418 50.05008
1.300334 3.164732 -1.064638 50.03093
1.350333 3.261398 -1.074506 49.88702
1.400333 3.359937 -1.084113 49.97710
1.450334 3.456626 -1.092539 50.12571
1.500333 3.554241 -1.101143 50.00472
1.550334 3.652496 -1.109276 49.89038
1.600334 3.749688 -1.117325 50.00684
1.650333 3.849294 -1.125023 50.07991
1.700334 3.947262 -1.132388 49.97975
1.750334 4.045615 -1.139381 50.09072
1.800334 4.144732 -1.146124 50.05386
1.850334 4.243594 -1.152392 50.16419
1.900334 4.342630 -1.158255 49.92887
1.950334 4.440976 -1.163776 49.95684
2.000334 4.539662 -1.168904 50.05744
2.050333 4.638784 -1.173666 50.12417
2.100334 4.738184 -1.178133 50.06216
2.150334 4.836044 -1.182250 50.05838
2.200334 4.934982 -1.185986 50.03940
2.250334 5.035172 -1.189540 50.08203
2.300333 5.134408 -1.192909 49.81597
2.350334 5.232900 -1.196137 50.00308
2.400334 5.332026 -1.198949 50.00812
2.450334 5.431172 -1.201622 49.83163
2.500334 5.531580 -1.204222 50.09392
2.550333 5.630991 -1.206687 49.94876
2.600333 5.730693 -1.209081 50.14508
2.650333 5.829018 -1.211467 50.05894
2.700333 5.929110 -1.213562 49.92325
2.750333 6.028691 -1.215594 50.01018
2.800333 6.127978 -1.217636 50.21733
2.850333 6.228596 -1.219571 50.10926
2.900333 6.327918 -1.221471 49.95168
2.950333 6.427532 -1.223257 50.03720
3.000333 6.526387 -1.224885 49.97700
3.050333 6.626563 -1.226457 49.95172
3.100333 6.725937 -1.228014 50.00808
3.150333 6.825326 -1.229276 50.18750
3.200333 6.925100 -1.230724 50.09274
3.250333 7.025207 -1.232033 50.07266
3.300333 7.124521 -1.233380 49.92537
3.350333 7.224394 -1.234624 50.04070
3.400333 7.324650 -1.235846 50.08475
3.450333 7.423978 -1.236931 50.05272
3.500333 7.523085 -1.238073 50.06367
3.550333 7.623674 -1.239108 50.08457
3.600333 7.722610 -1.240036 50.08092
3.650333 7.822480 -1.240942 49.85594
3.700333 7.922116 -1.241747 50.15516
3.750333 8.023066 -1.242705 50.04556
3.800333 8.122440 -1.243640 50.08358
3.850333 8.220812 -1.244390 49.97037
3.900333 8.322648 -1.245381 50.06374
3.950333 8.420742 -1.246141 50.13056
4.000333 8.520672 -1.246858 50.01360
4.050333 8.620841 -1.247636 49.98687
4.100333 8.720289 -1.248457 50.07762
4.150333 8.821166 -1.249078 50.07369
4.200333 8.920226 -1.249958 50.08372
4.250333 9.020084 -1.250511 49.89504
4.300333 9.120206 -1.251200 49.92500
4.350333 9.219910 -1.252004 49.90400
4.400333 9.318859 -1.252520 49.84550
4.450333 9.418348 -1.253279 50.04933
4.500333 9.518719 -1.253885 49.95168
4.550333 9.618266 -1.254662 50.12795
4.600333 9.718616 -1.255376 50.20230
4.650333 9.818985 -1.255977 49.91108
4.700333 9.917442 -1.256486 50.01560
4.750333 10.01787 -1.257222 49.91944
4.800333 10.11866 -1.257888 49.96422
4.850333 10.21804 -1.258514 49.93966
4.900333 10.31802 -1.259274 50.13854
4.950333 10.41722 -1.260106 50.00126
5.000333 10.51732 -1.260843 49.89000
5.050333 10.61809 -1.261504 50.07174
5.100333 10.71796 -1.262278 49.86992
5.150333 10.81799 -1.262966 50.04211
5.200333 10.91707 -1.263492 49.92810
5.250332 11.01785 -1.263911 49.91921
5.300332 11.11646 -1.264418 50.10188
5.350332 11.21707 -1.264943 49.96542
5.400332 11.31633 -1.265220 49.84991
5.450332 11.41694 -1.265686 49.93187
5.500332 11.51624 -1.266099 49.94187
5.550332 11.61687 -1.266426 50.09125
5.600332 11.71617 -1.266731 49.93830
5.650332 11.81642 -1.267115 49.95728
5.700332 11.91652 -1.267545 50.15433
5.750332 12.01550 -1.267845 50.03766
5.800332 12.11621 -1.268280 49.96350
5.850332 12.21596 -1.268660 50.13663
5.900332 12.31516 -1.269138 49.93574
5.950332 12.41575 -1.269442 49.88070
6.000332 12.51406 -1.269786 50.05963
6.050332 12.61567 -1.270276 50.08248
6.100332 12.71463 -1.270764 49.88600
6.150332 12.81458 -1.271179 50.13330
6.200332 12.91538 -1.271794 49.90078
6.250332 13.01544 -1.272456 50.19748
6.300332 13.11397 -1.272858 49.87590
6.350332 13.21491 -1.273414 50.00980
6.400332 13.31398 -1.273976 49.96386
6.450332 13.41422 -1.274557 49.98706
6.500332 13.51431 -1.275113 49.99837
6.550332 13.61319 -1.275601 50.08936
6.600332 13.71381 -1.276223 49.91367
6.650332 13.81444 -1.276736 50.12020
6.700332 13.91363 -1.277338 50.06612
6.750332 14.01383 -1.277741 50.09404
6.800332 14.11499 -1.278148 49.98412
6.850332 14.21326 -1.278526 50.02575
6.900332 14.31367 -1.278787 50.00639
6.950332 14.41382 -1.279186 49.87324
7.000332 14.51256 -1.279470 49.92686
7.050332 14.61427 -1.279842 49.97778
7.100332 14.71317 -1.280132 49.96390
7.150332 14.81373 -1.280563 49.89900
7.200332 14.91351 -1.280870 50.11010
7.250332 15.01357 -1.281222 50.00272
7.300332 15.11352 -1.281649 50.19470
7.350332 15.21330 -1.282033 50.03324
7.400332 15.31356 -1.282392 49.92083
7.450332 15.41372 -1.282950 49.79056
7.500332 15.51274 -1.283366 49.95460
7.550332 15.61265 -1.283886 50.06288
7.600332 15.71248 -1.284188 50.09341
7.650332 15.81252 -1.284597 49.91791
7.700332 15.91302 -1.285026 49.95362
7.750332 16.01231 -1.285401 49.93106
7.800332 16.11250 -1.285778 50.20672
7.850332 16.21140 -1.286117 49.98130
7.900332 16.31239 -1.286525 50.01590
7.950332 16.41236 -1.286934 49.95354
8.000334 16.51246 -1.287197 50.04746
8.050332 16.61151 -1.287579 49.93180
8.100332 16.71074 -1.287980 49.94303
8.150332 16.81066 -1.288178 49.93756
8.200332 16.91122 -1.288488 49.91858
8.250334 17.01117 -1.288838 49.95992
8.300332 17.11100 -1.289154 49.92474
8.350332 17.21122 -1.289668 50.04024
8.400332 17.31197 -1.290284 50.03235
8.450332 17.41057 -1.290741 50.04788
8.500334 17.51013 -1.291385 50.24897
8.550332 17.61128 -1.291874 49.98404
8.600332 17.71084 -1.292466 50.12052
8.650332 17.81130 -1.293011 50.01680
8.700332 17.91073 -1.293569 50.04640
8.750334 18.01044 -1.294106 49.89914
8.800332 18.10932 -1.294588 50.09459
8.850332 18.21020 -1.295093 49.89114
8.900332 18.31064 -1.295673 50.09458
8.950332 18.41000 -1.296210 50.10669
9.000334 18.51006 -1.296552 49.98587
9.050332 18.60967 -1.296863 50.05343
9.100332 18.71033 -1.297241 50.08203
9.150332 18.80982 -1.297836 50.14628
9.200332 18.90955 -1.298260 49.96010
9.250334 19.00984 -1.298997 49.88741
9.300332 19.10952 -1.299592 49.99878
9.350332 19.20955 -1.300228 50.01610
9.400332 19.31070 -1.300902 50.06662
9.450332 19.41030 -1.301358 50.06803
9.500334 19.50900 -1.301988 50.17781
9.550332 19.60935 -1.302710 49.85016
9.600332 19.70903 -1.303331 50.14476
9.650332 19.80910 -1.303850 50.01869
9.700332 19.90940 -1.304398 49.76440
9.750334 20.00816 -1.304876 50.02799
9.800332 20.10924 -1.305318 50.09131
9.850332 20.20911 -1.305904 49.98788
9.900332 20.30765 -1.306577 49.84464
9.950332 20.40830 -1.307320 50.11689
10.00033 20.50824 -1.307909 49.93630
10.05033 20.60844 -1.308703 50.10019
10.10033 20.70790 -1.309535 49.95210
10.15033 20.80801 -1.310301 49.92719
10.20033 20.90852 -1.310998 50.02478
10.25033 21.00807 -1.311927 49.88956
10.30033 21.10846 -1.312785 50.10761
10.35033 21.20818 -1.313644 49.94022
10.40033 21.30754 -1.314587 50.12292
10.45033 21.40852 -1.315308 49.99033
10.50034 21.50816 -1.316218 50.03416
10.55033 21.60775 -1.316988 49.95765
10.60033 21.70783 -1.317876 49.83654
10.65033 21.80834 -1.318582 49.81596
10.70033 21.90875 -1.319289 49.87537
10.75034 22.00790 -1.319992 49.91274
10.80033 22.10760 -1.320564 49.95797
10.85033 22.20752 -1.321108 49.84700
10.90033 22.30670 -1.321515 49.86191
10.95033 22.40761 -1.322044 49.99412
11.00034 22.50670 -1.322578 49.97046
11.05033 22.60649 -1.323128 50.12604
11.10033 22.70629 -1.323942 49.98606
11.15033 22.80607 -1.324553 49.97185
11.20033 22.90619 -1.325378 50.02432
11.25034 23.00590 -1.326227 49.99448
11.30033 23.10594 -1.327101 50.07160
11.35033 23.20656 -1.328413 49.88198
11.40033 23.30723 -1.329511 50.09728
11.45033 23.40646 -1.330530 50.06860
11.50034 23.50789 -1.331738 50.05063
11.55033 23.60720 -1.332775 50.04254
11.60033 23.70628 -1.334054 49.94184
11.65033 23.80666 -1.334992 50.11526
11.70033 23.90681 -1.335926 49.94942
11.75034 24.00668 -1.336753 50.15156
11.80033 24.10598 -1.337698 50.06961
11.85033 24.20639 -1.338624 49.88668
11.90033 24.30667 -1.339664 49.98874
11.95033 24.40703 -1.340531 50.05129
12.00034 24.50592 -1.341363 49.92828
12.05033 24.60515 -1.342330 50.01700
12.10033 24.70488 -1.342983 49.93863
12.15033 24.80455 -1.343851 50.08752
12.20033 24.90451 -1.344632 50.15508
12.25034 25.00388 -1.345499 49.94098
12.30033 25.10388 -1.346304 50.05406
12.35033 25.20330 -1.347068 50.01234
12.40033 25.30334 -1.347935 49.96074
12.45033 25.40334 -1.348928 50.10475
12.50034 25.50299 -1.349990 49.95304
12.55033 25.60214 -1.351077 49.91045
12.60033 25.70226 -1.352282 50.01774
12.65033 25.80187 -1.353572 50.13701
12.70033 25.90092 -1.354882 49.83969
12.75034 26.00114 -1.356146 49.97783
12.80033 26.10111 -1.357654 50.00176
12.85033 26.20098 -1.358960 50.04716
12.90033 26.30155 -1.360516 50.05759
12.95034 26.40142 -1.361929 50.07722
13.00034 26.50060 -1.363543 49.96000
13.05033 26.60009 -1.365163 50.07373
13.10033 26.69960 -1.366747 49.97620
13.15033 26.80000 -1.368436 49.92389
13.20034 26.90077 -1.370212 50.08257
13.25034 27.00074 -1.372046 50.02729
13.30033 27.10020 -1.373692 49.86170
13.35033 27.19990 -1.375511 50.04746
13.40033 27.29923 -1.377470 49.90288
13.45034 27.39883 -1.379376 50.03639
13.50034 27.49902 -1.381275 50.02868
13.55033 27.59920 -1.383315 49.86611
13.60033 27.69867 -1.385562 50.15222
13.65033 27.79858 -1.387679 49.76119
13.70034 27.89783 -1.390121 50.04022
13.75034 27.99840 -1.392770 50.16754
13.80033 28.09732 -1.396127 49.98548
13.85033 28.19690 -1.400615 50.21727
13.90033 28.29616 -1.407096 49.91946
13.95034 28.39450 -1.419089 49.89484
14.00034 28.49333 -1.447632 50.18804
14.05033 28.59076 -1.486834 49.99447
14.10033 28.68760 -1.530736 50.06214
14.15033 28.78439 -1.581645 49.84962
14.20034 28.88152 -1.626677 49.93383
14.25034 28.97702 -1.673977 49.93587
14.30033 29.07367 -1.721857 49.96466
14.35033 29.17000 -1.767420 50.15568
14.40033 29.26604 -1.812703 49.98211
14.45034 29.36287 -1.858648 49.97700
14.50034 29.45877 -1.903989 49.93380
14.55033 29.55426 -1.951248 49.94307
14.60033 29.65062 -1.995696 50.01531
14.65033 29.74692 -2.038080 49.81795
14.70034 29.84364 -2.079137 50.06000
14.75034 29.94096 -2.116210 49.91451
14.80033 30.03740 -2.152828 49.99906
14.85033 30.13418 -2.187418 50.11582
14.90033 30.23168 -2.215932 49.90082
14.95034 30.32974 -2.242234 49.93194
15.00034 30.42715 -2.264006 49.99082
15.05033 30.52520 -2.283968 50.03104
15.10033 30.62283 -2.299723 50.09363
15.15033 30.72078 -2.312680 49.97728
15.20034 30.82085 -2.321299 49.97548
15.25034 30.91977 -2.328472 49.89097
15.30033 31.01822 -2.335422 49.86176
15.35033 31.11856 -2.341845 50.02303
15.40033 31.21812 -2.347623 49.96696
15.45034 31.31730 -2.352765 50.00937
15.50034 31.41708 -2.357708 49.96790
15.55033 31.51624 -2.362474 50.16212
15.60033 31.61661 -2.367224 49.89810
15.65033 31.71530 -2.372260 49.99621
15.70034 31.81544 -2.377678 50.08076
15.75034 31.91465 -2.383805 50.02448
15.80033 32.01271 -2.390408 50.05246
15.85033 32.11350 -2.397552 50.05049
15.90033 32.21134 -2.405674 49.92208
15.95034 32.31147 -2.414654 49.99621
16.00033 32.41008 -2.424868 50.16818
16.05033 32.50952 -2.435774 49.99254
16.10033 32.60827 -2.448219 50.02016
16.15033 32.70793 -2.462340 50.16234
16.20033 32.80652 -2.476711 49.93452
16.25033 32.90530 -2.490424 50.04006
16.30033 33.00528 -2.504616 49.95276
16.35033 33.10352 -2.520459 50.04128
16.40033 33.20230 -2.535489 50.00310
16.45033 33.30064 -2.550239 49.85352
16.50033 33.40068 -2.563823 49.74497
16.55033 33.49977 -2.579398 49.96619
16.60033 33.59866 -2.593676 49.89600
16.65033 33.69805 -2.609550 49.92021
16.70033 33.79761 -2.621640 49.96287
16.75033 33.89590 -2.634024 50.01856
16.80033 33.99450 -2.646915 49.84166
16.85033 34.09383 -2.658200 49.92750
16.90033 34.19211 -2.669578 50.08502
16.95033 34.29193 -2.680992 50.03521
17.00033 34.39084 -2.691764 49.98654
17.05033 34.48898 -2.704260 50.04794
17.10033 34.58811 -2.715402 49.82511
17.15033 34.68736 -2.726137 50.04936
17.20033 34.78579 -2.738787 49.97302
17.25033 34.88462 -2.750474 49.96068
17.30033 34.98310 -2.762320 49.88422
17.35033 35.08180 -2.773935 49.97254
17.40033 35.18065 -2.786334 49.97012
17.45033 35.27920 -2.798685 50.06448
17.50033 35.37906 -2.809170 49.97676
17.55033 35.47783 -2.820279 50.00533
17.60033 35.57668 -2.832191 50.06959
17.65033 35.67504 -2.843471 49.82944
17.70033 35.77363 -2.854764 50.07964
17.75033 35.87353 -2.864638 50.09154
17.80033 35.97245 -2.874546 50.02346
17.85033 36.07154 -2.884106 49.97224
17.90033 36.17097 -2.893660 49.96226
17.95033 36.27102 -2.902527 49.90054
18.00033 36.37028 -2.911078 49.96784
18.05033 36.46997 -2.919196 49.86733
18.10033 36.56935 -2.926987 50.09469
18.15033 36.66888 -2.934076 50.07711
18.20033 36.76804 -2.940958 50.04610
18.25033 36.86782 -2.947116 50.11730
18.30033 36.96682 -2.952609 50.02131
18.35033 37.06737 -2.957410 49.91070
18.40033 37.16691 -2.961458 49.99486
18.45033 37.26775 -2.964662 49.90418
18.50033 37.36658 -2.966847 50.07676
18.55033 37.46716 -2.968002 50.04698
18.60033 37.56872 -2.967969 49.86871
18.65033 37.66939 -2.966174 50.12433
18.70033 37.76883 -2.961816 50.05167
18.75033 37.87028 -2.951954 50.07891
18.80033 37.97130 -2.931830 49.98526
18.85033 38.07363 -2.889881 49.87280
18.90033 38.17678 -2.838846 50.05580
18.95033 38.27937 -2.778856 50.09392
19.00033 38.38410 -2.705582 50.03172
19.05033 38.49031 -2.621138 50.06456
19.10033 38.59761 -2.523016 49.86781
19.15033 38.70535 -2.416767 49.94550
19.20033 38.81320 -2.312773 49.93788
19.25033 38.92221 -2.206255 49.83844
19.30033 39.03049 -2.110318 49.96949
19.35033 39.13796 -2.016732 50.03996
19.40033 39.24526 -1.931749 50.03714
19.45033 39.35214 -1.860014 49.90170
19.50033 39.45755 -1.799066 50.07382
19.55033 39.56390 -1.745415 50.02500
19.60033 39.66811 -1.697356 49.86809
19.65033 39.77172 -1.659066 49.96438
19.70033 39.87411 -1.626080 50.05691
19.75033 39.97773 -1.599480 50.05940
19.80033 40.07938 -1.579758 49.95113
19.85033 40.18201 -1.562330 49.86292
19.90033 40.28374 -1.548069 50.10054
19.95033 40.38502 -1.537652 49.99789
20.00033 40.48638 -1.529719 49.82136
20.05033 40.58694 -1.520424 50.19038
20.10033 40.68760 -1.512344 49.89160
20.15033 40.78789 -1.504366 50.03293
20.20033 40.88846 -1.496654 50.01687
20.25033 40.98914 -1.489584 49.99528
20.30033 41.08960 -1.483176 49.87682
20.35033 41.18979 -1.477246 49.98086
20.40033 41.29082 -1.471940 49.91367
20.45033 41.38970 -1.467149 49.78076
20.50033 41.49119 -1.462808 50.10612
20.55033 41.59046 -1.458808 49.89694
20.60033 41.69088 -1.455515 49.93832
20.65033 41.78991 -1.452669 49.99878
20.70033 41.89008 -1.450378 49.99274
20.75033 41.99026 -1.448431 50.02256
20.80033 42.09067 -1.446861 49.95922
20.85033 42.18984 -1.445538 49.97314
20.90033 42.29004 -1.444627 49.94864
20.95033 42.38914 -1.443856 50.10672
21.00033 42.49036 -1.443609 49.82795
21.05033 42.58912 -1.443536 50.07227
21.10033 42.68996 -1.443486 49.94402
21.15033 42.78924 -1.443643 50.02274
21.20033 42.88922 -1.443744 50.00522
21.25033 42.98957 -1.443906 50.03220
21.30033 43.08868 -1.444366 49.97197
21.35033 43.18903 -1.444974 49.92068
21.40033 43.28926 -1.445449 50.03622
21.45033 43.38874 -1.445962 50.03200
21.50033 43.48798 -1.446808 49.96931
21.55033 43.58784 -1.447652 50.01239
21.60033 43.68836 -1.448144 50.09140
21.65033 43.78844 -1.448879 50.08590
21.70033 43.88837 -1.449681 49.95523
21.75033 43.98777 -1.450542 50.00860
21.80033 44.08828 -1.451401 50.16369
21.85033 44.18881 -1.452317 49.95601
21.90033 44.28791 -1.453301 50.10024
21.95033 44.38740 -1.454230 49.91382
22.00033 44.48824 -1.455430 49.97742
22.05033 44.58781 -1.456354 49.86050
22.10033 44.68790 -1.457358 50.07376
22.15033 44.78848 -1.458575 49.92940
22.20033 44.88843 -1.459583 49.89406
22.25033 44.98831 -1.460548 50.03165
22.30033 45.08804 -1.461402 50.04898
22.35033 45.18780 -1.462222 49.97261
22.40033 45.28820 -1.463043 49.80922
22.45033 45.38822 -1.464063 49.99850
22.50033 45.48886 -1.464960 50.22074
22.55033 45.58826 -1.466030 50.07010
22.60033 45.68860 -1.467026 50.01281
22.65033 45.78832 -1.467995 49.94180
22.70033 45.88809 -1.468832 49.95007
22.75033 45.98856 -1.469937 50.01018
22.80033 46.08840 -1.470971 50.03294
22.85033 46.18875 -1.472118 50.03406
22.90033 46.28842 -1.473402 49.82449
22.95033 46.38854 -1.474882 50.06032
23.00033 46.48928 -1.476112 50.00766
23.05033 46.58862 -1.477202 49.93444
23.10033 46.68703 -1.478104 50.05269
23.15033 46.78731 -1.478852 50.14231
23.20033 46.88657 -1.479749 49.93894
23.25033 46.98746 -1.480346 49.89644
23.30033 47.08694 -1.481094 50.12545
23.35033 47.18662 -1.481815 50.10855
23.40033 47.28685 -1.482567 50.06388
23.45033 47.38586 -1.483394 50.11219
23.50033 47.48720 -1.484113 50.08801
23.55033 47.58578 -1.485110 50.20280
23.60033 47.68566 -1.485802 49.78087
23.65033 47.78586 -1.486759 50.05476
23.70033 47.88494 -1.487604 49.80354
23.75033 47.98538 -1.488613 50.16820
23.80033 48.08521 -1.489673 50.02482
23.85033 48.18547 -1.490638 50.04241
23.90033 48.28530 -1.491716 50.10739
23.95033 48.38504 -1.492656 49.85718
24.00033 48.48470 -1.493640 49.96335
24.05033 48.58524 -1.494675 49.96574
24.10033 48.68472 -1.495711 49.91674
24.15033 48.78442 -1.496927 50.01335
24.20033 48.88416 -1.498019 50.03289
24.25033 48.98446 -1.499191 49.94672
24.30033 49.08309 -1.500417 49.98554
24.35033 49.18388 -1.501667 50.11724
24.40033 49.28392 -1.503087 50.02710
24.45033 49.38353 -1.504458 50.12889
24.50033 49.48446 -1.506011 50.10528
24.55033 49.58456 -1.507571 49.99112
24.60033 49.68463 -1.509172 50.04198
24.65033 49.78486 -1.510782 50.08339
24.70033 49.88555 -1.512746 50.09004
24.75033 49.98598 -1.514985 49.96640
24.80033 50.08362 -1.516658 50.01590
24.85033 50.18109 -1.517291 49.97912
24.90033 50.27818 -1.516568 50.01076
24.95033 50.37493 -1.514582 49.90354
25.00033 50.47250 -1.511918 49.96578
25.05033 50.57019 -1.509021 50.00071
25.10033 50.66780 -1.506276 50.07669
25.15033 50.76664 -1.504038 50.00157
25.20033 50.86397 -1.502755 49.85556
25.25033 50.96344 -1.502285 50.09610
25.30033 51.06338 -1.502676 49.99120
25.35033 51.16304 -1.503994 50.05652
25.40033 51.26276 -1.505925 50.13493
25.45033 51.36228 -1.508688 49.97061
25.50033 51.46355 -1.511706 50.12762
25.55033 51.56382 -1.515062 50.21142
25.60033 51.66390 -1.518690 49.99504
25.65033 51.76464 -1.522334 49.81926
25.70033 51.86554 -1.525900 49.94697
25.75033 51.96518 -1.529454 50.04854
25.80033 52.06533 -1.532719 50.08794
25.85033 52.16616 -1.535755 50.04124
25.90033 52.26757 -1.538916 49.95230
25.95033 52.36738 -1.541910 50.05128
26.00033 52.46757 -1.544807 50.00366
26.05033 52.56870 -1.547739 49.96085
26.10033 52.66879 -1.550297 50.00650
26.15033 52.76880 -1.552753 49.86306
26.20033 52.86890 -1.555006 50.02441
26.25033 52.96936 -1.556919 50.08786
26.30033 53.06945 -1.558707 49.93259
26.35033 53.17059 -1.560272 50.12584
26.40033 53.27049 -1.561719 50.04633
26.45033 53.37090 -1.563133 50.07230
26.50033 53.47094 -1.564185 49.88686
26.55033 53.57098 -1.565332 49.88522
26.60033 53.67089 -1.566511 50.15898
26.65033 53.77062 -1.567768 49.84691
26.70033 53.87031 -1.569104 49.97883
26.75033 53.97193 -1.570449 49.85519
26.80033 54.07154 -1.571742 50.03684
26.85033 54.17066 -1.573176 49.90084
26.90033 54.27130 -1.574576 50.03956
26.95033 54.37161 -1.575923 50.08399
27.00033 54.47128 -1.577438 50.04184
27.05033 54.57205 -1.578989 50.03970
27.10033 54.67136 -1.580622 50.10614
27.15033 54.77238 -1.581949 49.90856
27.20033 54.87187 -1.583120 49.98866
27.25033 54.97114 -1.584444 49.80250
27.30033 55.07212 -1.585558 50.09858
27.35033 55.17198 -1.586720 49.90542
27.40033 55.27100 -1.587994 49.86430
27.45033 55.37046 -1.589202 49.88519
27.50033 55.47026 -1.590481 49.98458
27.55033 55.57006 -1.591651 49.96678
27.60033 55.67079 -1.593015 49.88020
27.65033 55.77004 -1.594500 50.00756
27.70033 55.87031 -1.596108 50.11020
27.75033 55.96988 -1.597626 49.90050
27.80033 56.07044 -1.599246 50.10041
27.85033 56.16941 -1.600958 49.97522
27.90033 56.27000 -1.602639 49.83868
27.95033 56.36930 -1.604192 50.14908
28.00033 56.47003 -1.605917 50.01125
28.05033 56.57000 -1.607880 49.91780
28.10033 56.66918 -1.609658 50.02340
28.15033 56.76941 -1.611598 49.92592
28.20033 56.86902 -1.613501 50.13876
28.25033 56.96918 -1.615432 49.95366
28.30033 57.06934 -1.617359 50.09951
28.35033 57.16846 -1.618992 50.05456
28.40033 57.26882 -1.620807 49.85916
28.45033 57.36870 -1.622602 50.15226
28.50033 57.46932 -1.624277 49.94924
28.55033 57.56839 -1.625703 50.04266
28.60033 57.66899 -1.627334 49.84969
28.65033 57.76782 -1.628800 49.95986
28.70033 57.86700 -1.630402 49.97041
28.75033 57.96775 -1.631771 50.14307
28.80033 58.06704 -1.633369 49.99915
28.85033 58.16750 -1.635005 50.08180
28.90033 58.26726 -1.636668 50.03140
28.95033 58.36634 -1.638270 49.97312
29.00033 58.46609 -1.639826 49.96860
29.05033 58.56594 -1.641256 50.22741
29.10033 58.66615 -1.642709 49.89167
29.15033 58.76528 -1.644516 49.98389
29.20033 58.86496 -1.646088 50.14088
29.25033 58.96474 -1.647928 50.23660
29.30033 59.06464 -1.649853 49.86769
29.35033 59.16551 -1.651849 50.04450
29.40033 59.26421 -1.653851 50.17660
29.45033 59.36456 -1.655748 49.86414
29.50033 59.46448 -1.657800 50.09283
29.55033 59.56060 -1.660564 49.98856
29.60033 59.63200 -1.649139 50.21619
29.65033 59.67893 -1.532290 50.19721
29.70033 59.71729 -1.411012 49.95118
29.75033 59.74885 -1.286499 50.04346
29.80033 59.77482 -1.163951 50.08540
29.85033 59.79576 -1.051301 49.82670
29.90033 59.81430 -0.9470482 49.97156
29.95033 59.83039 -0.8566186 50.04817
30.00033 59.84399 -0.7744376 50.07734
30.05033 59.85407 -0.7078608 50.06880
30.10033 59.86389 -0.6467216 49.89617
30.15033 59.87226 -0.5969172 49.84470
30.20033 59.88044 -0.5531246 49.92441
30.25033 59.88542 -0.5173967 50.07668
30.30033 59.89088 -0.4876946 50.07517
30.35033 59.89584 -0.4617224 49.99476
30.40033 59.89895 -0.4398674 50.07874
30.45033 59.90289 -0.4226557 50.01094
30.50033 59.90540 -0.4084066 49.90670
30.55033 59.90832 -0.3969704 49.92081
30.60033 59.91085 -0.3877964 50.08402
30.65033 59.91244 -0.3778547 50.07494
30.70033 59.91480 -0.3696270 50.12805
30.75033 59.91607 -0.3615713 49.90746
30.80033 59.91700 -0.3535402 50.05542
30.85033 59.91866 -0.3459148 49.94036
30.90033 59.91918 -0.3385980 50.04056
30.95033 59.91988 -0.3318802 49.92674
31.00033 59.92020 -0.3256145 49.50525
31.05033 59.92184 -0.3199358 50.21630
31.10033 59.92252 -0.3148315 49.92609
31.15033 59.92270 -0.3101609 50.15159
31.20033 59.92402 -0.3059216 49.86798
31.25033 59.92482 -0.3021144 49.88009
31.30033 59.92484 -0.2984880 49.95868
31.35033 59.92511 -0.2952259 49.98000
31.40033 59.92536 -0.2922818 49.94722
31.45033 59.92542 -0.2898054 49.95472
31.50033 59.92598 -0.2874745 50.00296
31.55033 59.92644 -0.2854088 49.85766
31.60033 59.92676 -0.2835478 49.95535
31.65033 59.92770 -0.2821298 49.96741
31.70033 59.92691 -0.2807740 49.98522
31.75033 59.92755 -0.2793829 49.89820
31.80033 59.92797 -0.2779692 50.09521
31.85034 59.92783 -0.2767837 49.99634
31.90033 59.92761 -0.2755653 50.08034
31.95033 59.92766 -0.2746904 50.15802
32.00033 59.92842 -0.2738185 50.07792
32.05033 59.92886 -0.2731047 49.88730
32.10034 59.92860 -0.2724907 50.11072
32.15033 59.92960 -0.2718885 49.79211
32.20033 59.92846 -0.2712415 49.99037
32.25033 59.92871 -0.2705250 50.01420
32.30033 59.92922 -0.2701251 50.13150
32.35034 59.92932 -0.2696400 49.91723
32.40033 59.92984 -0.2693374 50.13192
32.45033 59.92904 -0.2691050 50.00320
-2.000000 1.000000 0.0000000 0.0000000
32.54700 59.92708 -0.2689524 50.17503
32.59700 59.90024 -0.2523236 49.87375
32.64700 59.84861 -0.1307591 50.03654
32.69700 59.78612 .002084418 50.05196
32.74700 59.71670 0.1291262 49.99093
32.79700 59.64270 0.2479509 50.07359
32.84700 59.56378 0.3713944 50.06051
32.89700 59.48264 0.4730631 50.13840
32.94700 59.39818 0.5681746 50.04514
32.99700 59.31184 0.6487778 49.95437
33.04700 59.22304 0.7193824 49.95554
33.09700 59.13295 0.7809844 49.99389
33.14700 59.04008 0.8331652 50.06432
33.19700 58.94820 0.8769941 50.07426
33.24700 58.85416 0.9176556 50.03113
33.29700 58.75906 0.9491282 50.15958
33.34700 58.66391 0.9753922 49.98316
33.39700 58.56832 0.9994330 49.80347
33.44700 58.47110 1.018374 49.84122
33.49700 58.37463 1.033479 49.91736
33.54700 58.27678 1.049263 49.98728
33.59700 58.17877 1.061468 50.03240
33.64700 58.08048 1.071875 50.06754
33.69700 57.98244 1.082175 50.12418
33.74700 57.88395 1.090873 49.82235
33.79700 57.78593 1.099319 49.98616
33.84700 57.68666 1.107622 49.96161
33.89700 57.58796 1.115653 50.03542
33.94700 57.48932 1.123439 49.96028
33.99700 57.39009 1.130806 50.11926
34.04700 57.29106 1.137656 49.95102
34.09700 57.19133 1.144074 49.93026
34.14700 57.09310 1.149949 50.13552
34.19700 56.99382 1.155652 50.06672
34.24700 56.89411 1.160982 50.11138
34.29700 56.79584 1.165947 50.12896
34.34700 56.69632 1.170660 50.09269
34.39700 56.59739 1.174972 49.87216
34.44700 56.49786 1.179116 49.94162
34.49700 56.39941 1.182754 50.03154
34.54700 56.29861 1.186235 50.01306
34.59700 56.19947 1.189784 49.97895
34.64700 56.10108 1.192924 49.81990
34.69700 56.00068 1.196014 50.09633
34.74700 55.90120 1.198995 50.01148
34.79700 55.80145 1.201902 49.99384
34.84700 55.70225 1.204641 49.99238
34.89700 55.60301 1.207617 49.93224
34.94700 55.50272 1.210359 49.95216
34.99700 55.40318 1.213229 49.97124
35.04700 55.30375 1.215766 50.05038
35.09700 55.20322 1.218454 49.95039
35.14700 55.10410 1.221072 49.98786
35.19700 55.00364 1.223626 49.92660
35.24700 54.90385 1.226240 50.15772
35.29700 54.80429 1.228690 50.14303
35.34700 54.70424 1.231033 49.96957
35.39700 54.60447 1.233186 50.12637
35.44700 54.50491 1.235048 50.09928
35.49700 54.40418 1.236896 49.94678
35.54700 54.30598 1.238747 49.99561
35.59700 54.20610 1.240378 50.06088
35.64700 54.10672 1.242079 49.86519
35.69700 54.00716 1.243703 50.03520
35.74700 53.90732 1.245138 50.14253
35.79700 53.80794 1.246698 49.91203
35.84700 53.70758 1.248348 49.94649
35.89700 53.60840 1.249894 50.22680
35.94700 53.50920 1.251530 50.17161
35.99700 53.40908 1.253216 50.07275
36.04700 53.30952 1.254900 50.12762
36.09700 53.20920 1.256491 49.92524
36.14700 53.10984 1.258183 50.00538
36.19700 53.01026 1.259758 49.87016
36.24700 52.90976 1.261458 49.98338
36.29700 52.81171 1.263086 50.05172
36.34700 52.71160 1.264637 49.99426
36.39700 52.61146 1.266218 50.02480
36.44700 52.51093 1.267884 49.77581
36.49700 52.41153 1.269499 49.92716
36.54700 52.31242 1.271056 50.06141
36.59700 52.21275 1.272804 49.87986
36.64700 52.11270 1.274444 49.92852
36.69700 52.01272 1.276145 49.85710
36.74700 51.91358 1.277816 50.11376
36.79700 51.81311 1.279442 50.03274
36.84700 51.71336 1.280934 50.16711
36.89700 51.61458 1.282422 50.04334
36.94700 51.51326 1.284109 50.04085
36.99700 51.41409 1.285651 50.01260
37.04700 51.31367 1.287471 49.92355
37.09700 51.21320 1.289250 49.84672
37.14700 51.11492 1.291067 50.15421
37.19700 51.01410 1.292761 50.03977
37.24700 50.91453 1.294407 49.83964
37.29700 50.81516 1.295896 50.06395
37.34700 50.71440 1.297317 49.99518
37.39700 50.61480 1.298590 50.03059
37.44700 50.51486 1.299708 50.11836
37.49700 50.41496 1.300801 49.92630
37.54700 50.31576 1.301957 49.96124
37.59700 50.21627 1.303228 49.97032
37.64700 50.11617 1.304315 49.99970
37.69700 50.01670 1.305523 50.15718
37.74700 49.91678 1.306562 49.95514
37.79700 49.81766 1.307816 49.95805
37.84700 49.71762 1.308777 50.02959
37.89700 49.61744 1.309821 49.89334
37.94700 49.51750 1.311044 49.96464
37.99700 49.41806 1.312114 50.18988
38.04700 49.31786 1.313334 49.95574
38.09700 49.21885 1.314513 49.94711
38.14700 49.11911 1.315696 50.03434
38.19700 49.01848 1.317046 50.14487
38.24700 48.91989 1.318363 50.01070
38.29700 48.82024 1.319687 49.90214
38.34700 48.71950 1.321212 49.97588
38.39700 48.61970 1.322498 49.92261
38.44700 48.52056 1.323736 50.17106
38.49700 48.42070 1.325091 50.04914
38.54700 48.32039 1.326366 50.03760
38.59700 48.22082 1.327605 49.88846
38.64700 48.12094 1.328818 49.90542
38.69700 48.02098 1.330209 50.00976
38.74700 47.92174 1.331546 50.00488
38.79700 47.82116 1.332747 50.12767
38.84700 47.72156 1.334117 50.00567
38.89700 47.62094 1.335478 50.06147
38.94700 47.52157 1.336926 50.07761
38.99700 47.42234 1.338114 50.16808
39.04700 47.32140 1.339404 49.90313
39.09700 47.22312 1.340505 50.14484
39.14700 47.12246 1.341678 50.04195
39.19700 47.02264 1.342711 50.09812
39.24700 46.92336 1.343792 50.11054
39.29700 46.82350 1.344716 50.07778
39.34700 46.72352 1.345906 49.93158
39.39700 46.62329 1.346899 49.85996
39.44700 46.52350 1.347769 49.75320
39.49700 46.42389 1.348789 50.09750
39.54700 46.32390 1.349877 49.88087
39.59700 46.22402 1.350924 49.90836
39.64700 46.12347 1.352198 49.96826
39.69700 46.02424 1.353244 50.01556
39.74700 45.92441 1.354570 49.91458
39.79700 45.82434 1.355793 50.03492
39.84700 45.72418 1.357172 49.86996
39.89700 45.62422 1.358490 49.89444
39.94700 45.52418 1.359710 50.08842
39.99700 45.42456 1.360830 50.11948
40.04700 45.32420 1.361786 50.06028
40.09700 45.22434 1.362694 49.97893
40.14700 45.12463 1.363613 49.91474
40.19700 45.02476 1.364307 49.92162
40.24700 44.92524 1.365092 49.97440
40.29700 44.82600 1.366002 49.95867
40.34700 44.72605 1.366719 49.96334
40.39700 44.62626 1.367382 49.99778
40.44700 44.52688 1.368232 50.02281
40.49700 44.42726 1.369096 49.91806
40.54700 44.32656 1.369851 50.06731
40.59700 44.22634 1.370626 49.90684
40.64700 44.12725 1.371392 50.09211
40.69700 44.02711 1.372267 50.05530
40.74700 43.92722 1.373005 49.90642
40.79700 43.82764 1.373793 49.93704
40.84700 43.72885 1.374689 50.07068
40.89700 43.62799 1.375577 50.01831
40.94700 43.52783 1.376633 50.02352
40.99700 43.42863 1.377456 49.88100
41.04700 43.32900 1.378491 50.06231
41.09700 43.22926 1.379610 50.00556
41.14700 43.12932 1.380464 50.10697
41.19700 43.02981 1.381490 50.01092
41.24700 42.92932 1.382470 49.92806
41.29700 42.83000 1.383468 50.06998
41.34700 42.72981 1.384380 49.93719
41.39700 42.63060 1.385296 49.92933
41.44700 42.52991 1.386122 49.99278
41.49700 42.43006 1.387086 50.15256
41.54700 42.32996 1.387842 49.99176
41.59700 42.22982 1.388780 50.14998
41.64700 42.12942 1.389627 49.98549
41.69700 42.03056 1.390618 50.00637
41.74700 41.93024 1.391386 49.83063
41.79700 41.83041 1.392262 49.97122
41.84700 41.72996 1.392984 50.04608
41.89700 41.62973 1.393873 49.96539
41.94700 41.53060 1.394649 50.02691
41.99700 41.43066 1.395279 50.05090
42.04700 41.33141 1.395814 50.09213
42.09700 41.23174 1.396428 50.08524
42.14700 41.13215 1.397168 50.12394
42.19700 41.03169 1.397815 49.82584
42.24700 40.93168 1.398338 49.95682
42.29700 40.83134 1.399058 49.96794
42.34700 40.73245 1.399666 49.88618
42.39700 40.63258 1.400269 50.02706
42.44700 40.53228 1.400939 49.99222
42.49700 40.43230 1.401702 49.93830
42.54700 40.33274 1.402451 50.00380
42.59700 40.23326 1.403195 49.90377
42.64700 40.13284 1.403953 49.98729
42.69700 40.03282 1.404648 49.81710
42.74700 39.93369 1.405271 49.94781
42.79700 39.83344 1.405889 50.13512
42.84700 39.73396 1.406567 49.98700
42.89700 39.63400 1.407361 50.07440
42.94700 39.53391 1.407950 50.24981
42.99700 39.43409 1.408561 49.99194
43.04700 39.33382 1.409232 49.96549
43.09700 39.23422 1.409939 49.96494
43.14700 39.13383 1.410652 50.06660
43.19700 39.03467 1.411401 49.95694
43.24700 38.93472 1.412438 50.13315
43.29700 38.83422 1.413308 50.04592
43.34700 38.73359 1.414303 50.00687
43.39700 38.63374 1.415210 49.94741
43.44700 38.53484 1.415982 49.96955
43.49700 38.43443 1.416693 49.96316
43.54700 38.33462 1.417327 50.03154
43.59700 38.23394 1.417809 50.15116
43.64700 38.13471 1.418499 50.06270
43.69700 38.03481 1.418934 50.13246
43.74700 37.93420 1.419361 50.37024
43.79700 37.83542 1.419789 50.14071
43.84700 37.73540 1.420030 50.06418
43.89700 37.63514 1.420529 49.97266
43.94700 37.53518 1.420801 49.95806
43.99700 37.43617 1.420996 50.01593
44.04700 37.33653 1.421352 50.08730
44.09700 37.23663 1.421751 50.01826
44.14700 37.13560 1.422128 50.01717
44.19700 37.03684 1.422599 50.12328
44.24700 36.93690 1.423118 50.07246
44.29700 36.83721 1.423706 50.04488
44.34700 36.73710 1.424264 49.98041
44.39700 36.63679 1.424843 49.86896
44.44700 36.53772 1.425493 49.83002
44.49700 36.43802 1.426187 49.99924
44.54700 36.33834 1.426887 49.85196
44.59700 36.23747 1.427616 49.90044
44.64700 36.13834 1.428094 49.85022
44.69700 36.03824 1.428776 49.99292
44.74700 35.93769 1.429371 49.93100
44.79700 35.83810 1.430142 50.01761
44.84700 35.73806 1.430864 49.90146
44.89700 35.63761 1.431687 50.34720
44.94700 35.53778 1.432412 49.94361
44.99700 35.43752 1.433344 50.10128
45.04700 35.33846 1.434283 49.89874
45.09700 35.23860 1.435490 50.00126
45.14700 35.13946 1.437221 50.05570
45.19700 35.03995 1.440604 50.01900
45.24700 34.94138 1.454980 49.90152
45.29700 34.84396 1.518549 50.09498
45.34700 34.74970 1.637313 50.00064
45.39700 34.65918 1.816250 50.00122
45.44700 34.57370 2.071840 50.13742
45.49700 34.49610 2.422892 49.94683
45.54700 34.42449 2.841895 50.08500
45.59700 34.35902 3.298953 49.88926
45.64700 34.29436 3.761879 49.91533
45.69700 34.23190 4.205734 49.98568
45.74700 34.16695 4.588674 49.89109
45.79700 34.09659 4.887752 49.86781
45.84700 34.02026 5.095729 50.16147
45.89700 33.93660 5.216775 49.94649
45.94700 33.84671 5.263644 49.86441
45.99700 33.74994 5.260914 49.84320
46.04700 33.65023 5.219817 49.88852
46.09700 33.54556 5.110646 49.89791
46.14700 33.43777 4.991876 49.76042
46.19700 33.32937 4.863541 49.90720
46.24700 33.21825 4.724662 50.01940
46.29700 33.10847 4.588600 50.21056
46.34700 32.99725 4.450647 49.92396
46.39700 32.88639 4.319988 50.08258
46.44700 32.77573 4.193328 50.05821
46.49700 32.66523 4.075533 49.92252
46.54700 32.55630 3.964072 49.78409
46.59700 32.44724 3.864500 49.96210
46.64700 32.33875 3.767748 50.18067
46.69700 32.23116 3.679378 50.13486
46.74700 32.12310 3.596302 49.88900
46.79700 32.01760 3.523381 49.97461
46.84700 31.91162 3.453312 50.09062
46.89700 31.80578 3.389780 49.85408
46.94700 31.69990 3.328187 50.15672
46.99700 31.59570 3.276154 49.92944
47.04700 31.49150 3.226563 50.02012
47.09700 31.38739 3.178375 49.96411
47.14700 31.28325 3.133407 49.99796
47.19700 31.17900 3.094040 49.98806
47.24700 31.07572 3.054614 49.89350
47.29700 30.97350 3.016809 50.15921
47.34700 30.87008 2.983043 49.93004
47.39700 30.76771 2.947288 49.89963
47.44700 30.66328 2.914311 49.98129
47.49700 30.56218 2.879991 49.94860
47.54700 30.45889 2.847564 49.98940
47.59700 30.35620 2.816288 50.03330
47.64700 30.25354 2.782355 50.01976
47.69700 30.15070 2.749093 50.04049
47.74700 30.04775 2.709738 49.92363
47.79700 29.94596 2.675232 49.85488
47.84700 29.84260 2.633848 50.18259
47.89700 29.73898 2.590870 49.86024
47.94700 29.63610 2.545822 50.02604
47.99700 29.53315 2.500224 50.22710
48.04700 29.42922 2.449235 50.16344
48.09700 29.32486 2.401816 49.92534
48.14700 29.22127 2.348225 50.07240
48.19700 29.11662 2.300774 49.98224
48.24700 29.01162 2.251136 50.05029
48.29700 28.90735 2.202713 49.90366
48.34700 28.80476 2.178724 49.89131
48.39700 28.70465 2.176306 50.08004
48.44700 28.60450 2.177040 49.81537
48.49700 28.50190 2.134295 50.16504
48.54700 28.39813 2.036989 50.00630
48.59700 28.29150 1.960492 49.99288
48.64700 28.18655 1.898434 49.94068
48.69700 28.08085 1.843372 49.93634
48.74700 27.97700 1.794391 49.95639
48.79700 27.87205 1.755300 49.94459
48.84700 27.76914 1.719698 50.03444
48.89700 27.66680 1.692553 50.17434
48.94700 27.56408 1.669207 49.87610
48.99700 27.46174 1.650896 50.02862
49.04700 27.36024 1.635984 49.99558
49.09700 27.25850 1.623345 49.97578
49.14700 27.15637 1.611906 49.93196
49.19700 27.05564 1.602223 49.98644
49.24700 26.95464 1.594340 49.97746
49.29700 26.85365 1.586152 50.17109
49.34700 26.75390 1.577792 50.17157
49.39700 26.65182 1.570118 49.81896
49.44700 26.55246 1.562784 49.93578
49.49700 26.45225 1.555802 50.12900
49.54700 26.35250 1.549089 49.97961
49.59700 26.25177 1.543083 50.02284
49.64700 26.15125 1.537488 50.06176
49.69700 26.05164 1.532406 49.98594
49.74700 25.95061 1.527558 50.00977
49.79700 25.85104 1.523395 50.19872
49.84700 25.75046 1.519399 50.09687
49.89700 25.65082 1.515969 49.99816
49.94700 25.55104 1.512743 50.00826
49.99700 25.45138 1.509898 49.85478
50.04700 25.35114 1.507323 49.93412
50.09700 25.25085 1.505012 50.01222
50.14700 25.15056 1.502794 49.88438
50.19700 25.04982 1.500971 50.01321
50.24700 24.95030 1.499236 50.15174
50.29700 24.85006 1.497677 49.77486
50.34700 24.74952 1.496262 50.04986
50.39700 24.65019 1.494880 49.91988
50.44700 24.55052 1.493633 50.09830
50.49700 24.45007 1.492454 50.05034
50.54700 24.35014 1.491424 50.10942
50.59700 24.25016 1.490480 49.94866
50.64700 24.14955 1.489550 50.01919
50.69700 24.04973 1.488737 50.04122
50.74700 23.94921 1.487912 50.01176
50.79700 23.84980 1.487217 49.94786
50.84700 23.74956 1.486493 49.82590
50.89700 23.64912 1.485681 50.13681
50.94700 23.54916 1.484841 50.11490
50.99700 23.44882 1.484087 49.96377
51.04700 23.34956 1.483300 50.12774
51.09700 23.25024 1.482433 50.18310
51.14700 23.14994 1.481538 49.95188
51.19700 23.05003 1.480743 50.01940
51.24700 22.95081 1.480108 50.05668
51.29700 22.84958 1.479368 49.98940
51.34700 22.75002 1.478815 50.01205
51.39700 22.65094 1.478169 50.05437
51.44700 22.54958 1.477597 49.97256
51.49700 22.44984 1.477045 50.21168
51.54700 22.35022 1.476649 50.16980
51.59700 22.24972 1.476194 50.21122
51.64700 22.14992 1.475750 50.08426
51.69700 22.05009 1.475524 49.90353
51.74700 21.94992 1.475203 50.05289
51.79700 21.85002 1.474776 50.01412
51.84700 21.74947 1.474506 50.02437
51.89700 21.65146 1.474097 49.87676
51.94700 21.55012 1.473675 50.02996
51.99700 21.45083 1.473362 49.87483
52.04700 21.35045 1.472921 50.12682
52.09700 21.25018 1.472763 49.93135
52.14700 21.14955 1.472325 50.28534
52.19700 21.05054 1.471950 49.75226
52.24700 20.95045 1.471798 49.76750
52.29700 20.85048 1.471413 50.01079
52.34700 20.75094 1.471014 49.97094
52.39700 20.65090 1.470754 50.05610
52.44700 20.55019 1.470575 49.80172
52.49700 20.45111 1.470220 50.00761
52.54700 20.35032 1.469953 50.07830
52.59700 20.25032 1.469514 49.94412
52.64700 20.15054 1.469064 50.15004
52.69700 20.05012 1.468627 50.02680
52.74700 19.95096 1.468317 50.11034
52.79700 19.85058 1.467866 50.00602
52.84700 19.75129 1.467293 49.97230
52.89700 19.65124 1.467030 50.02954
52.94700 19.55186 1.466658 50.05252
52.99700 19.45120 1.466301 49.94536
53.04700 19.35125 1.465896 50.01867
53.09700 19.25191 1.465475 50.08579
53.14700 19.15138 1.465070 49.98716
53.19700 19.05173 1.464653 49.78259
53.24700 18.95108 1.464306 50.10415
53.29700 18.85161 1.464005 49.98470
53.34700 18.75186 1.463618 50.12114
53.39700 18.65262 1.463448 50.13443
53.44700 18.55212 1.463185 50.05648
53.49700 18.45168 1.462986 50.03817
53.54700 18.35244 1.462831 50.10092
53.59700 18.25186 1.462679 50.11691
53.64700 18.15266 1.462617 49.87817
53.69700 18.05206 1.462346 49.98410
53.74700 17.95228 1.462112 50.07352
53.79700 17.85152 1.461932 49.92520
53.84700 17.75210 1.461529 49.89258
53.89700 17.65206 1.461042 49.88098
53.94700 17.55258 1.460755 49.89377
53.99700 17.45343 1.460540 49.93856
54.04700 17.35324 1.460178 49.87894
54.09700 17.25342 1.459799 50.13270
54.14700 17.15348 1.459458 49.84946
54.19700 17.05378 1.459179 50.00859
54.24700 16.95376 1.459006 49.93123
54.29700 16.85378 1.458684 50.14826
54.34700 16.75391 1.458462 49.89453
54.39700 16.65378 1.458635 49.85506
54.44700 16.55267 1.458770 49.99662
54.49700 16.45325 1.458954 50.18519
54.54700 16.35318 1.459202 50.07116
54.59700 16.25323 1.459511 50.00342
54.64700 16.15274 1.459542 49.90678
54.69700 16.05322 1.459609 49.95864
54.74700 15.95250 1.459502 49.86244
54.79700 15.85326 1.459422 50.15386
54.84700 15.75300 1.459322 49.90666
54.89700 15.65320 1.459098 49.91132
54.94700 15.55363 1.458860 49.93106
54.99700 15.45296 1.458740 50.06954
55.04700 15.35332 1.458438 49.98239
55.09700 15.25242 1.458210 49.99134
55.14700 15.15318 1.457980 49.81653
55.19700 15.05279 1.457825 49.95836
55.24700 14.95322 1.457744 50.06220
55.29700 14.85244 1.457389 49.90652
55.34700 14.75275 1.457226 49.90727
55.39700 14.65286 1.456934 49.97851
55.44700 14.55384 1.456718 50.10587
55.49700 14.45264 1.456587 50.05636
55.54700 14.35332 1.456568 50.00317
55.59700 14.25424 1.456463 49.94474
55.64700 14.15400 1.456428 50.08498
55.69700 14.05365 1.456369 49.93396
55.74700 13.95439 1.456248 50.12092
55.79700 13.85483 1.456134 49.98603
55.84700 13.75401 1.455790 50.10234
55.89700 13.65396 1.455785 50.05441
55.94700 13.55378 1.455616 49.87914
55.99700 13.45385 1.455624 50.05728
56.04700 13.35298 1.455628 50.00988
56.09700 13.25325 1.455685 49.96782
56.14700 13.15316 1.455790 50.01246
56.19700 13.05339 1.455868 49.88619
56.24700 12.95316 1.455766 49.98990
56.29700 12.85297 1.455747 50.15370
56.34700 12.75298 1.455884 49.97508
56.39700 12.65309 1.455767 50.05537
56.44700 12.55344 1.455700 50.03398
56.49700 12.45353 1.455636 49.94976
56.54700 12.35293 1.455394 50.04107
56.59700 12.25325 1.455204 50.04074
56.64700 12.15278 1.454880 50.06717
56.69700 12.05312 1.454674 50.19387
56.74700 11.95410 1.454514 50.11757
56.79700 11.85328 1.454311 50.16606
56.84700 11.75351 1.454027 50.03054
56.89700 11.65314 1.453786 50.08831
56.94700 11.55400 1.453433 49.95874
56.99700 11.45394 1.453193 50.22239
57.04700 11.35402 1.452780 49.95243
57.09700 11.25489 1.452405 49.91924
57.14700 11.15480 1.452111 50.00032
57.19700 11.05544 1.451654 49.90946
57.24700 10.95510 1.451340 50.11139
57.29700 10.85523 1.451071 50.13150
57.34700 10.75523 1.450772 50.14239
57.39700 10.65484 1.450473 49.81832
57.44700 10.55456 1.450175 49.90619
57.49700 10.45506 1.449997 49.92089
57.54700 10.35464 1.449842 50.10382
57.59700 10.25542 1.449795 50.04818
57.64700 10.15594 1.449653 50.04053
57.69700 10.05510 1.449598 50.04582
57.74700 9.955391 1.449405 50.20252
57.79700 9.856322 1.449265 49.91696
57.84700 9.755845 1.448953 50.16348
57.89700 9.656128 1.448917 49.84908
57.94700 9.556408 1.448741 49.86724
57.99700 9.455762 1.448559 49.86683
58.04700 9.356085 1.448504 49.96225
58.09700 9.256026 1.448353 49.97143
58.14700 9.155988 1.448368 49.85490
58.19700 9.055772 1.448262 49.99915
58.24700 8.956172 1.448431 50.03991
58.29700 8.855532 1.448392 50.04859
58.34700 8.755280 1.448531 50.12912
58.39700 8.655032 1.448569 50.06063
58.44700 8.554778 1.448511 49.93313
58.49700 8.455322 1.448632 49.96068
58.54700 8.356281 1.448458 50.04591
58.59700 8.255699 1.448432 49.82718
58.64700 8.156010 1.448158 49.95639
58.69700 8.056020 1.447891 49.89488
58.74700 7.956362 1.447864 50.04536
58.79700 7.856816 1.447462 50.15152
58.84700 7.755728 1.447180 50.10350
58.89700 7.656110 1.446847 50.00500
58.94700 7.556770 1.446621 50.02693
58.99700 7.457146 1.446421 49.90051
59.04700 7.356219 1.446159 50.08467
59.09700 7.255591 1.445971 50.03433
59.14700 7.156938 1.445867 49.97580
59.19700 7.056046 1.445671 49.98821
59.24700 6.957016 1.445504 50.12187
59.29700 6.857765 1.445499 49.81614
59.34700 6.755946 1.445329 49.95686
59.39700 6.656220 1.445287 50.07940
59.44700 6.557458 1.445217 49.93440
59.49700 6.457039 1.445148 50.01016
59.54700 6.356457 1.445171 50.16094
59.59700 6.256293 1.445134 49.93734
59.64700 6.157086 1.445130 49.77295
59.69700 6.057849 1.445127 50.05550
59.74700 5.956856 1.445047 49.90538
59.79700 5.857105 1.444827 49.86126
59.84700 5.757144 1.444785 49.93194
59.89700 5.656918 1.444610 49.96879
59.94700 5.556836 1.444464 49.93600
59.99700 5.456754 1.444336 49.97797
60.04700 5.357115 1.444201 49.95629
60.09700 5.256934 1.443888 49.96121
60.14700 5.157169 1.443749 50.16536
60.19700 5.057836 1.443595 50.06748
60.24700 4.957048 1.443449 49.85832
60.29700 4.857324 1.443194 50.10268
60.34700 4.757644 1.443154 50.06266
60.39700 4.657002 1.443019 49.92578
60.44700 4.557583 1.442947 50.23009
60.49700 4.457620 1.442826 49.92190
60.54700 4.358330 1.442685 50.06794
60.59700 4.258138 1.442445 49.94347
60.64700 4.157662 1.442147 49.98633
60.69700 4.058615 1.441912 49.91408
60.74700 3.957936 1.441584 50.19262
60.79700 3.858462 1.441285 50.07933
60.84700 3.758456 1.441154 49.98134
60.89700 3.658306 1.441039 50.23164
60.94700 3.558899 1.441153 49.99074
60.99700 3.458469 1.441266 50.12197
61.04700 3.358330 1.441467 50.13391
61.09700 3.258511 1.441841 50.07362
61.14700 3.157918 1.441920 49.99053
61.19700 3.057827 1.441944 49.95538
61.24700 2.957544 1.442043 50.14254
61.29700 2.857441 1.442044 50.12610
61.34700 2.757551 1.441725 50.06760
61.39700 2.657290 1.441414 49.92252
61.44700 2.557666 1.441228 49.83762
61.49700 2.457321 1.440865 50.00610
61.54700 2.357672 1.440633 49.87900
61.59700 2.258938 1.440271 50.09716
61.64700 2.158175 1.439919 50.00088
61.69700 2.059196 1.439514 49.87679
61.74700 1.958611 1.439208 49.96860
61.79700 1.859550 1.438808 50.11090
61.84700 1.759165 1.438591 50.14070
61.89700 1.658056 1.438356 50.05758
61.94700 1.559907 1.438329 49.97733
61.99700 1.459519 1.438267 50.07607
62.04700 1.361671 1.438827 50.01469
62.09700 1.290038 1.416050 50.10630
62.14700 1.240926 1.312750 49.95496
62.19700 1.203350 1.202774 50.12566
62.24700 1.174405 1.089463 50.02344
62.29700 1.147118 0.9762231 50.12116
62.34700 1.127003 0.8667969 49.84863
62.39700 1.109004 0.7770137 49.93597
62.44700 1.093662 0.6883259 49.96716
62.49700 1.080219 0.6162390 49.98697
62.54700 1.069840 0.5511646 50.03492
62.59700 1.060412 0.4934674 49.87863
62.64700 1.053056 0.4427866 50.11964
62.69700 1.045599 0.4015876 50.03076
62.74700 1.040206 0.3657478 49.92011
62.79700 1.035210 0.3359902 49.95828
62.84700 1.029977 0.3105493 49.90848
62.89700 1.026849 0.2907147 49.96243
62.94700 1.024703 0.2725400 49.90392
62.99700 1.020945 0.2589669 50.00333
63.04700 1.018604 0.2471448 49.94270
63.09700 1.016433 0.2369509 50.09903
63.14700 1.015109 0.2273620 50.14526
63.19700 1.012699 0.2184493 49.94701
63.24700 1.010630 0.2103049 49.86958
63.29700 1.010039 0.2024651 50.24024
63.34700 1.008873 0.1950644 49.89682
63.39700 1.008239 0.1878606 49.96988
63.44700 1.006669 0.1811999 50.07724
63.49700 1.006477 0.1751051 50.02124
63.54700 1.004201 0.1694847 49.97568
63.59700 1.003871 0.1643469 50.02969
63.64700 1.003208 0.1598678 49.96146
63.69700 1.002350 0.1557324 49.92574
63.74700 1.002361 0.1520607 50.08090
63.79700 1.001713 0.1486960 49.97760
63.84700 1.000599 0.1456194 50.07531
63.89700 1.000019 0.1429919 49.95863
63.94700 0.9999629 0.1405013 50.10966
63.99700 0.9994903 0.1380603 49.85053
64.04700 0.9997426 0.1360530 50.20598
64.09700 0.9989206 0.1342098 49.98086
64.14700 0.9987362 0.1324628 50.08422
64.19701 0.9984981 0.1308557 49.97563
64.24700 0.9986001 0.1292478 50.00691
64.29700 0.9981197 0.1278020 49.95737
64.34700 0.9978954 0.1265204 50.16973
64.39700 0.9985782 0.1254613 49.91156
64.44701 0.9971797 0.1245026 49.97574
64.49700 0.9976856 0.1234962 50.12566
64.54700 0.9960891 0.1226826 49.79372
64.59700 0.9972449 0.1218308 50.02789
64.64700 0.9965253 0.1211336 50.16788
64.69701 0.9971451 0.1205313 49.92022
64.74700 0.9967485 0.1199973 49.91897
64.79700 0.9961952 0.1195308 50.03772
-2.000000 2.000000 0.0000000 0.0000000