File: imagens/notebooks/dados experimentais/dsc/Karl_CTAB100 Ur 40%.txt
CLOSED
Version	1.0
Language	English
Run	1
RunSerial	36
Instrument	DSC Q100 V9.9 Build 303
Module	DSC Standard Cell FC
Operator	LL
File	\\Niger\ta\Data\DSC\2018\Geral\Karl_CTAB100.001
ProcName	Karl
InstSerial	0100-1211
Sample	CTAB100
Size	22.6700	mg
Method	Karl
Comment
Xcomment	Pan: Aluminum Hermetic
Xcomment	Gas1: Nitrogen 50.0 ml/min
Xcomment	Gas2: Nitrogen 0.0 ml/min
Text
Exotherm	UP
Kcell	1.09030
Calib	-11.7822
TempCal	1	pts	158.71	156.60
TzeroDt	-90.0515 -0.0093 2.2263
TzeroDtz	-90.0515 0.0466 2.4421
InstCalFile	Tzero: \\Niger\ta\Data\DSC\CALIBRATION\20122016\CALIBRATION\0_RCS_12_20_2016 17_23_31.TZR
InstCalFile	Baseline: \\Niger\ta\Data\DSC\CALIBRATION\20122016\L.Base 20122016
InstCalFile	Sapphire: \\Niger\ta\Data\DSC\CALIBRATION\20122016\Safira 20122017.001
InstCalDate	Tzero 2016-12-20 Time 19:23:31
TempRange	-90.04 to 395.23 °C at 19.96 °C/min Heat Only
AutoZero	Delta T Offset 0.000 uV
AutoZero	Delta T0 Offset 0.000 uV
Controls	Gas 1  Event Off  Sampling 0.2
Cell#	FC-02451
CoolingUnit	RCS
SelHeatFlow	Heat Flow T4 (mW)
AutoAnalysis	Off
MacroFile
Nsig	4
Sig1	Time (min)
Sig2	Temperature (°C)
Sig3	Heat Flow (mW)
Sig4	Sample Purge Flow (mL/min)
Date	2018-01-17
Time	10:28:52
OrgMethod	1: Equilibrate at 1.00 °C
OrgMethod	2: Ramp 2.00 °C/min to 50.00 °C
OrgMethod	3: Isothermal for 3.00 min
OrgMethod	4: Mark end of cycle 1
OrgMethod	5: Ramp 2.00 °C/min to 1.00 °C
OrgMethod	6: Isothermal for 3.00 min
OrgMethod	7: Mark end of cycle 2
OrgFile	C:\TA\Data\DSC\2018\Geral\Karl_CTAB100.001
3.33324E-4 1.451600 3.799963 49.88370
0.04366666 1.417049 3.461142 50.01587
0.08700000 1.402327 3.134103 49.93478
0.1303333 1.412959 2.790808 50.07910
0.1736667 1.435918 2.438608 50.01330
0.2170000 1.466502 2.087772 50.20162
0.2603333 1.502104 1.748865 49.95862
0.3036666 1.542059 1.421699 50.10956
0.3470000 1.587248 1.114547 49.79844
0.3903334 1.634680 0.8280774 49.79356
0.4336666 1.686183 0.5618537 49.98697
0.4770000 1.741015 0.3121520 50.11732
0.5203333 1.799310 0.08869519 49.73968
0.5636668 1.858452 -0.1205478 50.21118
0.6070000 1.921515 -0.3208732 49.87422
0.6503332 1.985844 -0.4971940 49.98007
0.6936668 2.051988 -0.6583308 49.90216
0.7370000 2.119352 -0.8048929 50.05048
0.7803332 2.188382 -0.9390744 49.97027
0.8236668 2.260042 -1.064706 49.86142
0.8670000 2.331720 -1.178791 50.04772
0.9103334 2.406550 -1.281339 50.08548
0.9536668 2.480684 -1.370311 50.05204
0.9970000 2.556440 -1.456466 50.04844
1.040333 2.631928 -1.534897 50.08329
1.083667 2.709354 -1.605739 50.02156
1.127000 2.787474 -1.666914 49.80904
1.170334 2.864606 -1.728964 49.94484
1.213667 2.943906 -1.780966 49.94232
1.257000 3.023830 -1.831707 50.04008
1.300334 3.104565 -1.876589 50.03060
1.343667 3.185045 -1.916628 49.98346
1.387000 3.265655 -1.954297 50.04742
1.430333 3.347882 -1.989246 49.98080
1.473667 3.430398 -2.020680 50.04306
1.517000 3.512036 -2.047784 49.89231
1.560334 3.596320 -2.075082 50.12244
1.603667 3.678335 -2.099819 50.18313
1.647000 3.761095 -2.121661 49.99062
1.690334 3.845280 -2.141493 50.01916
1.733667 3.928174 -2.159777 50.03488
1.777000 4.012295 -2.176470 50.07317
1.820333 4.096625 -2.192166 50.22117
1.863667 4.179394 -2.205584 49.84104
1.907000 4.265322 -2.218700 49.91333
1.950334 4.349580 -2.229768 49.96874
1.993667 4.433922 -2.240707 50.02211
2.037000 4.519012 -2.249826 49.97650
2.080333 4.603210 -2.259255 49.94112
2.123667 4.687634 -2.268645 50.12747
2.167000 4.773381 -2.278882 50.21152
2.210333 4.858461 -2.287033 49.94467
2.253667 4.943148 -2.295008 49.89580
2.297000 5.028168 -2.303047 49.90124
2.340333 5.113412 -2.310883 49.91674
2.383667 5.198726 -2.318588 50.12330
2.427000 5.283965 -2.325793 49.98711
2.470333 5.368560 -2.332918 49.97957
2.513666 5.455390 -2.339751 49.81734
2.557000 5.540480 -2.346380 49.93867
2.600333 5.625956 -2.352862 50.19627
2.643667 5.711346 -2.359223 50.01826
2.687000 5.798349 -2.365305 49.97484
2.730333 5.883579 -2.371325 50.03293
2.773667 5.969135 -2.377019 50.00247
2.817000 6.056180 -2.382562 49.98476
2.860334 6.141256 -2.387950 50.03622
2.903667 6.227282 -2.392854 49.86804
2.947000 6.314408 -2.397722 50.16484
2.990333 6.400028 -2.402403 50.03061
3.033667 6.485200 -2.406664 49.90436
3.077000 6.572162 -2.410854 49.97824
3.120334 6.658472 -2.414896 49.95140
3.163667 6.744946 -2.418608 50.11370
3.207000 6.830964 -2.422212 50.00733
3.250333 6.916314 -2.425555 50.22193
3.293666 7.002244 -2.428704 50.04190
3.337000 7.088978 -2.431658 50.05933
3.380333 7.175359 -2.434434 50.07483
3.423667 7.260587 -2.437048 49.89533
3.467000 7.348556 -2.439703 49.96986
3.510333 7.433692 -2.442160 50.12584
3.553667 7.519835 -2.444454 49.94671
3.597000 7.606052 -2.446723 49.96630
3.640334 7.692170 -2.448821 50.04602
3.683667 7.778796 -2.450860 49.96816
3.727000 7.865462 -2.452760 49.94568
3.770333 7.950866 -2.454549 50.05850
3.813666 8.037540 -2.456290 49.99170
3.857000 8.122844 -2.457927 49.84387
3.900333 8.208960 -2.459347 49.92234
3.943666 8.296682 -2.460685 50.06783
3.987000 8.381900 -2.462058 49.99750
4.030334 8.468891 -2.463494 49.86695
4.073666 8.553959 -2.464728 49.96889
4.117000 8.641606 -2.466255 49.95320
4.160333 8.727851 -2.467739 49.99447
4.203666 8.814056 -2.469311 50.02694
4.247000 8.900732 -2.470873 49.98242
4.290333 8.987379 -2.472568 50.00804
4.333667 9.073991 -2.474103 49.98782
4.377000 9.160132 -2.475722 49.97834
4.420334 9.246449 -2.477224 50.03080
4.463666 9.332813 -2.478779 50.13170
4.507000 9.419845 -2.480352 50.07270
4.550333 9.507035 -2.481934 49.92090
4.593666 9.592109 -2.483610 50.09394
4.637000 9.679595 -2.485164 50.08203
4.680333 9.765606 -2.486856 50.07528
4.723666 9.853908 -2.488393 50.07198
4.767000 9.939191 -2.489758 49.96750
4.810333 10.02540 -2.491140 50.04690
4.853666 10.11260 -2.492288 49.96988
4.897000 10.19939 -2.493636 50.10562
4.940334 10.28518 -2.494682 50.03641
4.983667 10.37115 -2.495746 50.00094
5.027000 10.45824 -2.496786 49.95824
5.070334 10.54406 -2.497668 50.03808
5.113666 10.63090 -2.498677 49.94096
5.157000 10.71632 -2.499481 50.14858
5.200333 10.80313 -2.500366 50.03074
5.243668 10.89004 -2.501137 50.11612
5.287000 10.97619 -2.501944 50.09420
5.330332 11.06161 -2.502754 50.03734
5.373668 11.14944 -2.503720 49.78352
5.417000 11.23573 -2.504647 50.26840
5.460332 11.32285 -2.505522 49.89516
5.503668 11.40947 -2.506522 50.01850
5.547000 11.49538 -2.507513 49.91314
5.590332 11.58172 -2.508462 50.13516
5.633666 11.66919 -2.509542 49.96836
5.677000 11.75504 -2.510438 50.00131
5.720332 11.84184 -2.511487 49.98960
5.763666 11.92919 -2.512540 49.93028
5.807000 12.01545 -2.513570 49.93856
5.850332 12.10152 -2.514439 50.05457
5.893668 12.18771 -2.515470 50.07521
5.937000 12.27532 -2.516376 50.01965
5.980332 12.36228 -2.517348 50.12128
6.023668 12.44828 -2.518127 50.02695
6.067000 12.53508 -2.519027 49.89394
6.110332 12.62176 -2.519880 50.14209
6.153668 12.70740 -2.520845 50.20000
6.197000 12.79403 -2.521687 49.90350
6.240332 12.88096 -2.522630 50.02906
6.283666 12.96797 -2.523541 49.93938
6.327000 13.05435 -2.524736 50.06639
6.370332 13.14165 -2.525791 50.11828
6.413666 13.22716 -2.526811 50.00454
6.457000 13.31432 -2.527872 50.10676
6.500332 13.40104 -2.528808 49.82873
6.543668 13.48746 -2.528854 50.00456
6.587000 13.57521 -2.528412 49.94787
6.630334 13.66160 -2.527914 50.03464
6.673666 13.74648 -2.527176 50.16413
6.717000 13.83348 -2.526485 49.97620
6.760332 13.92016 -2.525991 50.04578
6.803668 14.00736 -2.525475 49.87618
6.847000 14.09313 -2.525230 50.16904
6.890332 14.17966 -2.525079 49.84624
6.933668 14.26686 -2.525156 49.77203
6.977000 14.35314 -2.525181 50.01909
7.020332 14.44044 -2.525371 50.09812
7.063666 14.52653 -2.525488 49.84224
7.107000 14.61363 -2.525592 50.20641
7.150332 14.69967 -2.525943 49.90896
7.193666 14.78614 -2.526080 49.94278
7.237000 14.87317 -2.526247 50.11318
7.280334 14.95916 -2.526760 49.89902
7.323666 15.04646 -2.527156 49.93676
7.367000 15.13245 -2.527486 50.12390
7.410332 15.21975 -2.527939 50.05904
7.453668 15.30653 -2.526529 50.10422
7.497000 15.39492 -2.518020 49.97380
7.540332 15.48189 -2.517457 50.24880
7.583668 15.56762 -2.518095 50.02824
7.627000 15.65489 -2.519118 49.99690
7.670332 15.74113 -2.520594 49.99517
7.713666 15.82717 -2.522221 50.02400
7.757000 15.91304 -2.523928 49.95676
7.800332 15.99991 -2.525797 49.77059
7.843668 16.08661 -2.527598 50.05888
7.887000 16.17310 -2.529075 49.83110
7.930332 16.25822 -2.530505 49.96373
7.973668 16.34486 -2.531936 49.89440
8.017000 16.43092 -2.533139 50.04511
8.060332 16.51882 -2.534363 49.80834
8.103668 16.60419 -2.535413 50.32688
8.147000 16.69040 -2.536336 50.01797
8.190332 16.77742 -2.537259 50.01309
8.233666 16.86368 -2.538173 49.91322
8.277000 16.95047 -2.539044 49.77014
8.320334 17.03748 -2.540012 49.86139
8.363666 17.12412 -2.540848 49.86342
8.407000 17.21169 -2.541614 49.88860
8.450332 17.29654 -2.542470 50.01850
8.493668 17.38402 -2.543182 50.07813
8.537000 17.47063 -2.544085 50.07188
8.580334 17.55783 -2.544857 50.15556
8.623666 17.64407 -2.545615 49.92022
8.667000 17.73140 -2.546498 49.97850
8.710332 17.81764 -2.547184 50.06389
8.753668 17.90450 -2.547892 49.99590
8.797000 17.99059 -2.548627 50.07438
8.840332 18.07793 -2.549358 49.98787
8.883668 18.16472 -2.549850 50.03754
8.927001 18.25092 -2.550740 50.04130
8.970332 18.33742 -2.551412 49.99196
9.013668 18.42457 -2.552266 49.94031
9.057000 18.51126 -2.553122 50.10034
9.100332 18.59907 -2.554002 49.91076
9.143666 18.68388 -2.555186 49.98694
9.187000 18.77032 -2.555980 49.81416
9.230332 18.85756 -2.556595 50.08378
9.273666 18.94366 -2.557138 49.92869
9.317001 19.02942 -2.557548 49.90662
9.360332 19.11727 -2.557932 49.84127
9.403668 19.20289 -2.558402 49.93076
9.447000 19.29021 -2.558834 50.04656
9.490332 19.37576 -2.559242 50.11473
9.533668 19.46236 -2.559861 49.82068
9.577000 19.55044 -2.560523 50.01284
9.620334 19.63644 -2.561287 50.03496
9.663666 19.72302 -2.561985 50.01217
9.707000 19.81069 -2.562824 50.08742
9.750334 19.89690 -2.563689 50.00074
9.793668 19.98295 -2.564538 50.13730
9.837000 20.06946 -2.565280 50.00449
9.880332 20.15639 -2.566272 50.08578
9.923668 20.24248 -2.567426 50.08036
9.967000 20.32894 -2.568581 49.96420
10.01033 20.41524 -2.569588 49.99731
10.05367 20.50148 -2.570705 49.94524
10.09700 20.58838 -2.571625 50.00688
10.14033 20.67607 -2.572557 50.00601
10.18367 20.76226 -2.573481 50.08041
10.22700 20.84845 -2.574553 50.09706
10.27033 20.93523 -2.575625 49.96900
10.31367 21.02194 -2.576726 50.17178
10.35700 21.10858 -2.577784 49.93196
10.40033 21.19520 -2.578577 49.90906
10.44367 21.28027 -2.579289 49.85840
10.48700 21.36849 -2.580268 49.99980
10.53033 21.45516 -2.581300 50.00818
10.57367 21.54087 -2.582330 50.03797
10.61700 21.62797 -2.583374 49.94034
10.66033 21.71385 -2.584518 50.02288
10.70367 21.80138 -2.585532 50.01217
10.74700 21.88706 -2.586492 50.02348
10.79033 21.97339 -2.587295 49.89120
10.83367 22.06020 -2.588205 49.89154
10.87700 22.14629 -2.588994 50.09254
10.92033 22.23332 -2.589552 49.91774
10.96367 22.31960 -2.590188 49.83326
11.00700 22.40625 -2.590868 50.07152
11.05033 22.49192 -2.591715 49.93770
11.09367 22.57860 -2.592578 50.04035
11.13700 22.66520 -2.593614 49.98824
11.18033 22.75299 -2.594790 50.21306
11.22367 22.83762 -2.596057 50.17316
11.26700 22.92585 -2.597486 49.81122
11.31033 23.01090 -2.598787 49.96328
11.35367 23.09848 -2.599972 49.97678
11.39700 23.18540 -2.601236 49.91366
11.44033 23.27178 -2.602471 49.94584
11.48366 23.35864 -2.603608 50.03034
11.52700 23.44482 -2.604639 50.15219
11.57034 23.53136 -2.605791 49.99797
11.61367 23.61776 -2.606912 50.16180
11.65700 23.70433 -2.607820 50.07330
11.70033 23.79070 -2.608884 49.85396
11.74367 23.87788 -2.609909 50.05566
11.78700 23.96375 -2.611146 49.94372
11.83033 24.05058 -2.612345 49.96220
11.87367 24.13747 -2.613661 49.92806
11.91700 24.22448 -2.615313 50.06282
11.96033 24.31060 -2.616938 49.83455
12.00367 24.39796 -2.618689 50.08104
12.04700 24.48435 -2.620482 49.95248
12.09033 24.57144 -2.622072 50.01275
12.13367 24.65706 -2.623715 50.11196
12.17700 24.74404 -2.625166 49.77266
12.22033 24.82978 -2.626630 50.06435
12.26367 24.91685 -2.628214 49.89722
12.30700 25.00346 -2.629676 50.03716
12.35033 25.09063 -2.631112 50.02379
12.39366 25.17715 -2.632442 50.03442
12.43700 25.26374 -2.633920 50.15051
12.48033 25.35071 -2.635220 50.14772
12.52367 25.43691 -2.636411 49.96558
12.56700 25.52192 -2.637592 49.89571
12.61033 25.60902 -2.638560 49.99750
12.65367 25.69502 -2.639537 49.85056
12.69700 25.78100 -2.640338 49.99215
12.74033 25.86778 -2.640888 49.87063
12.78367 25.95440 -2.641726 50.13572
12.82700 26.04100 -2.642676 49.90892
12.87034 26.12666 -2.643526 49.96488
12.91367 26.21238 -2.644700 50.00508
12.95700 26.29991 -2.646017 49.93750
13.00034 26.38623 -2.647553 49.97726
13.04367 26.47360 -2.649236 49.92889
13.08700 26.55942 -2.651182 49.95893
13.13033 26.64633 -2.653162 50.06224
13.17367 26.73245 -2.655444 49.91574
13.21700 26.81850 -2.658296 50.07379
13.26033 26.90578 -2.661726 50.03770
13.30367 26.99156 -2.665582 50.19150
13.34700 27.07858 -2.669940 49.96697
13.39033 27.16465 -2.674930 50.03500
13.43367 27.25060 -2.680646 50.07592
13.47700 27.33643 -2.687078 49.87321
13.52034 27.42263 -2.695048 49.89094
13.56366 27.50772 -2.704176 50.06785
13.60700 27.59406 -2.715533 49.96928
13.65033 27.67866 -2.731566 49.90219
13.69366 27.76418 -2.752496 50.14490
13.73700 27.84970 -2.777195 49.89906
13.78033 27.93515 -2.807692 50.01441
13.82367 28.01930 -2.840568 49.77982
13.86700 28.10400 -2.879078 49.90844
13.91033 28.18685 -2.922139 50.03340
13.95367 28.27146 -2.968602 49.99444
13.99700 28.35440 -3.021824 49.88182
14.04033 28.43593 -3.082444 49.96456
14.08367 28.51877 -3.144412 49.93879
14.12700 28.60083 -3.212766 50.01758
14.17033 28.68146 -3.286452 49.85234
14.21367 28.76135 -3.363822 50.00839
14.25700 28.84263 -3.448226 49.95868
14.30033 28.92310 -3.526865 49.93906
14.34367 29.00201 -3.608952 50.01233
14.38700 29.08282 -3.686885 49.96094
14.43033 29.16275 -3.765019 49.94473
14.47367 29.24325 -3.837984 49.96316
14.51700 29.32334 -3.911519 49.83568
14.56033 29.40346 -3.983661 50.15340
14.60367 29.48432 -4.047106 49.98050
14.64700 29.56620 -4.115478 49.99834
14.69033 29.64659 -4.179300 50.05048
14.73367 29.72974 -4.234083 50.10630
14.77700 29.81121 -4.291297 49.95120
14.82034 29.89206 -4.344180 50.07032
14.86366 29.97370 -4.398029 50.01865
14.90700 30.05720 -4.449076 50.09146
14.95034 30.14003 -4.494370 50.04590
14.99366 30.22274 -4.541179 50.01598
15.03700 30.30604 -4.584047 49.87489
15.08034 30.38879 -4.624211 49.94192
15.12367 30.47142 -4.665684 49.92907
15.16700 30.55635 -4.699576 50.12950
15.21033 30.63935 -4.733620 50.17124
15.25367 30.72235 -4.767033 49.93331
15.29700 30.80700 -4.796756 49.83583
15.34033 30.89038 -4.826004 49.98370
15.38367 30.97534 -4.854390 49.87270
15.42700 31.05959 -4.879334 49.80711
15.47034 31.14406 -4.906426 49.95460
15.51367 31.22867 -4.949966 50.04778
15.55700 31.31251 -4.978232 50.08392
15.60033 31.39725 -4.995731 49.99825
15.64366 31.48242 -5.008544 50.00982
15.68700 31.56712 -5.019998 49.88744
15.73033 31.65232 -5.033090 50.14570
15.77367 31.73728 -5.045502 49.99611
15.81700 31.82253 -5.059201 49.88848
15.86033 31.90779 -5.071209 49.98947
15.90367 31.99275 -5.083734 50.03772
15.94700 32.07859 -5.095484 49.96810
15.99033 32.16368 -5.108053 50.01300
16.03367 32.24884 -5.118156 50.07639
16.07700 32.33487 -5.127481 49.89008
16.12033 32.42090 -5.138533 49.79480
16.16366 32.50747 -5.148100 50.11487
16.20700 32.59302 -5.156240 49.98480
16.25033 32.67854 -5.164111 49.97574
16.29366 32.76505 -5.171412 50.02100
16.33700 32.85170 -5.178370 50.01682
16.38033 32.93770 -5.184766 50.16016
16.42367 33.02372 -5.190234 50.11208
16.46700 33.11088 -5.194851 49.80222
16.51033 33.19839 -5.198526 50.03968
16.55366 33.28410 -5.200814 50.17524
16.59700 33.37200 -5.201836 49.86957
16.64034 33.45950 -5.201311 49.94075
16.68367 33.54645 -5.198862 50.00524
16.72700 33.63422 -5.192832 49.93829
16.77033 33.72255 -5.182968 50.07123
16.81366 33.81002 -5.163932 50.05374
16.85700 33.89835 -5.139820 50.11060
16.90033 33.98690 -5.110532 50.05490
16.94366 34.07590 -5.077454 49.96681
16.98700 34.16494 -5.040196 50.00394
17.03034 34.25439 -5.000794 50.06254
17.07367 34.34496 -4.951358 50.08476
17.11700 34.43464 -4.899559 50.02700
17.16033 34.52466 -4.829590 50.05146
17.20366 34.61736 -4.744132 50.21170
17.24700 34.71135 -4.647144 50.00165
17.29033 34.80456 -4.543296 49.92861
17.33366 34.89937 -4.446814 50.03261
17.37700 34.99450 -4.351967 50.16368
17.42033 35.08840 -4.265870 50.01187
17.46366 35.18203 -4.170460 50.05083
17.50700 35.27610 -4.073510 49.82347
17.55033 35.37113 -3.972037 49.99094
17.59366 35.46580 -3.873794 50.17421
17.63700 35.56117 -3.783308 49.99844
17.68033 35.65538 -3.687614 49.98444
17.72366 35.74975 -3.603235 50.09399
17.76700 35.84264 -3.523728 49.92086
17.81034 35.93462 -3.446684 49.94952
17.85367 36.02850 -3.378394 49.95144
17.89700 36.12040 -3.309456 50.07596
17.94033 36.21344 -3.251187 50.15454
17.98366 36.30474 -3.191942 50.02435
18.02700 36.39548 -3.143334 49.99813
18.07033 36.48672 -3.096837 49.89612
18.11366 36.57712 -3.055918 50.06522
18.15700 36.66700 -3.021538 49.89838
18.20033 36.75730 -2.988142 49.86293
18.24366 36.84714 -2.960617 49.93315
18.28700 36.93542 -2.933908 49.88979
18.33033 37.02534 -2.911080 49.96277
18.37366 37.11409 -2.891122 50.07361
18.41700 37.20203 -2.871799 49.93454
18.46034 37.29112 -2.854955 50.04231
18.50366 37.37906 -2.841942 49.94303
18.54700 37.46796 -2.828492 50.06970
18.59033 37.55478 -2.817179 49.99686
18.63366 37.64292 -2.807132 49.95996
18.67700 37.73098 -2.798773 50.06429
18.72034 37.81794 -2.790644 50.03634
18.76366 37.90515 -2.781929 49.93730
18.80700 37.99310 -2.774163 50.04204
18.85033 38.07909 -2.766123 49.75945
18.89366 38.16582 -2.758461 49.91332
18.93700 38.25366 -2.751062 50.13355
18.98034 38.34062 -2.743744 50.08266
19.02367 38.42770 -2.736872 50.06646
19.06700 38.51522 -2.730412 49.96384
19.11034 38.60233 -2.724570 50.15518
19.15366 38.68933 -2.719065 49.88049
19.19700 38.77521 -2.713864 50.03097
19.24033 38.86139 -2.709280 50.02146
19.28367 38.94872 -2.704903 50.04109
19.32700 39.03663 -2.700735 49.89946
19.37033 39.12289 -2.697194 49.82720
19.41366 39.20935 -2.693715 50.01418
19.45700 39.29674 -2.690668 49.91989
19.50033 39.38348 -2.688034 49.95716
19.54366 39.47049 -2.685820 49.96078
19.58700 39.55695 -2.683781 49.90220
19.63034 39.64344 -2.681922 49.98131
19.67367 39.73091 -2.680503 49.92511
19.71700 39.81819 -2.679306 49.99433
19.76033 39.90466 -2.678675 50.00784
19.80366 39.99150 -2.678267 49.98630
19.84700 40.07691 -2.678114 50.14068
19.89034 40.16506 -2.678227 50.19670
19.93367 40.25102 -2.678902 49.88096
19.97700 40.33720 -2.680176 49.91617
20.02033 40.42243 -2.717869 49.98728
20.06366 40.50910 -2.716922 49.96310
20.10700 40.59488 -2.716759 49.99250
20.15033 40.68179 -2.717278 49.82678
20.19366 40.76856 -2.718100 49.88472
20.23700 40.85527 -2.719602 49.88328
20.28034 40.94048 -2.721528 50.09475
20.32367 41.02678 -2.723718 49.92878
20.36700 41.11291 -2.726099 50.05730
20.41033 41.19902 -2.729232 50.01513
20.45366 41.28432 -2.733340 49.98160
20.49700 41.37026 -2.740232 50.11648
20.54033 41.45559 -2.748955 49.88637
20.58366 41.54162 -2.762148 49.99316
20.62700 41.62688 -2.770404 49.86154
20.67033 41.71311 -2.780125 50.01701
20.71367 41.79902 -2.793522 49.97613
20.75700 41.88396 -2.807730 50.06637
20.80033 41.97162 -2.810375 49.87442
20.84367 42.05736 -2.820083 49.98416
20.88700 42.14250 -2.838404 50.11332
20.93033 42.22964 -2.846111 50.10568
20.97366 42.31504 -2.858422 50.00754
21.01700 42.40016 -2.865619 50.10172
21.06033 42.48666 -2.872908 49.99616
21.10367 42.57296 -2.879798 49.88794
21.14700 42.65863 -2.887523 50.08050
21.19033 42.74434 -2.893754 50.04394
21.23366 42.82984 -2.899209 50.02180
21.27700 42.91658 -2.904351 50.02807
21.32033 43.00408 -2.909876 49.95566
21.36367 43.08926 -2.915300 49.72970
21.40700 43.17590 -2.920332 50.14946
21.45033 43.26244 -2.925591 50.01056
21.49367 43.34900 -2.931740 49.92774
21.53700 43.43362 -2.946245 49.86033
21.58033 43.51925 -2.952210 49.88436
21.62366 43.60554 -2.958258 49.91075
21.66700 43.69186 -2.964303 50.01404
21.71033 43.77771 -2.975786 49.95739
21.75366 43.86366 -2.982649 50.02988
21.79700 43.95026 -2.989224 50.02538
21.84033 44.03622 -2.994341 50.07794
21.88366 44.12264 -2.998661 49.92322
21.92700 44.20932 -3.002677 49.98789
21.97034 44.29700 -3.005276 50.08608
22.01367 44.38246 -3.007398 50.06301
22.05700 44.46942 -3.008872 50.05768
22.10033 44.55681 -3.007931 50.05020
22.14366 44.64330 -3.005342 49.87133
22.18700 44.73243 -3.000845 50.01383
22.23033 44.81918 -2.996255 49.92730
22.27367 44.90620 -2.990273 50.02912
22.31700 44.99410 -2.984565 49.98729
22.36033 45.08033 -2.978653 49.85138
22.40366 45.16794 -2.972504 50.08359
22.44700 45.25625 -2.966162 50.11406
22.49033 45.34262 -2.960184 50.01550
22.53367 45.42918 -2.954380 50.08080
22.57700 45.51650 -2.949239 50.09133
22.62033 45.60399 -2.944496 49.92710
22.66367 45.69085 -2.940436 50.06784
22.70700 45.77762 -2.936826 49.41876
22.75033 45.86411 -2.933748 49.99082
22.79366 45.95131 -2.931187 50.21129
22.83700 46.03782 -2.928842 50.17414
22.88033 46.12454 -2.927050 50.12256
22.92367 46.20990 -2.925432 49.83686
22.96700 46.29606 -2.924054 49.95607
23.01033 46.38306 -2.922914 49.82269
23.05366 46.46946 -2.922037 49.95972
23.09700 46.55634 -2.921168 50.17067
23.14034 46.64274 -2.920679 50.01452
23.18367 46.72914 -2.920407 49.85175
23.22700 46.81588 -2.920183 50.10572
23.27033 46.90237 -2.920200 50.06822
23.31367 46.98975 -2.920135 50.17231
23.35700 47.07574 -2.920295 50.02004
23.40033 47.16253 -2.920383 50.05203
23.44367 47.24930 -2.920464 49.95570
23.48700 47.33608 -2.920736 50.20056
23.53033 47.42266 -2.920793 49.91962
23.57367 47.50955 -2.920725 50.00600
23.61700 47.59688 -2.921089 50.01144
23.66033 47.68283 -2.921405 50.02908
23.70366 47.77012 -2.921791 49.94360
23.74700 47.85639 -2.922147 49.95202
23.79033 47.94324 -2.922359 49.99756
23.83366 48.03016 -2.922244 49.74152
23.87700 48.11812 -2.922267 49.97930
23.92033 48.20352 -2.922092 50.03225
23.96367 48.29088 -2.921615 49.91838
24.00700 48.37736 -2.921213 49.79613
24.05033 48.46445 -2.920603 49.96909
24.09367 48.55027 -2.920016 49.96332
24.13700 48.63783 -2.919434 49.96356
24.18033 48.72400 -2.919022 49.93179
24.22366 48.81180 -2.918391 50.15644
24.26700 48.89756 -2.917746 49.97470
24.31033 48.98386 -2.917176 50.02621
24.35367 49.07217 -2.916646 50.08218
24.39700 49.15800 -2.916276 50.08042
24.44033 49.24502 -2.915923 50.01002
24.48366 49.33165 -2.915606 49.96936
24.52700 49.41838 -2.915537 49.88782
24.57033 49.49500 -2.915530 49.88716
24.61367 49.54756 -2.871436 50.03717
24.65700 49.58766 -2.748604 50.15542
24.70033 49.62239 -2.610662 50.14867
24.74367 49.65212 -2.462464 49.97969
24.78700 49.67965 -2.311701 50.09885
24.83033 49.70343 -2.154594 49.94839
24.87366 49.72430 -2.008234 49.77660
24.91700 49.74485 -1.862356 50.10000
24.96033 49.76224 -1.728049 50.01233
25.00366 49.77900 -1.599272 49.96012
25.04700 49.79342 -1.481114 49.98868
25.09033 49.80736 -1.373117 50.02664
25.13366 49.81994 -1.270332 50.20109
25.17700 49.83058 -1.184364 49.99288
25.22034 49.84054 -1.097972 49.84247
25.26367 49.84967 -1.019812 50.20663
25.30700 49.85739 -0.9527993 49.86154
25.35033 49.86593 -0.8901568 49.86690
25.39366 49.87290 -0.8316268 49.86738
25.43700 49.87846 -0.7785569 50.09828
25.48033 49.88476 -0.7296072 50.09793
25.52367 49.88988 -0.6849609 49.98374
25.56700 49.89354 -0.6477031 49.93557
25.61033 49.89926 -0.6140722 50.13543
25.65366 49.90176 -0.5810430 49.81250
25.69700 49.90555 -0.5538770 50.16322
25.74033 49.90928 -0.5260478 50.13383
25.78367 49.91254 -0.5037537 50.18748
25.82700 49.91442 -0.4826642 50.01463
25.87034 49.91727 -0.4643234 49.76720
25.91367 49.91920 -0.4458424 49.94329
25.95700 49.92128 -0.4331660 50.11363
26.00033 49.92320 -0.4186222 49.96009
26.04366 49.92398 -0.4069603 49.97404
26.08700 49.92606 -0.3958234 49.79990
26.13034 49.92748 -0.3868580 49.89812
26.17367 49.92947 -0.3782089 49.98384
26.21700 49.93109 -0.3699610 50.00918
26.26033 49.93156 -0.3618680 50.01813
26.30366 49.93231 -0.3534082 49.89176
26.34700 49.93398 -0.3446888 50.03164
26.39033 49.93536 -0.3367893 49.90881
26.43367 49.93544 -0.3293373 49.97410
26.47700 49.93757 -0.3221481 49.95686
26.52033 49.93822 -0.3151386 49.84615
26.56367 49.93802 -0.3083406 49.90447
26.60700 49.93844 -0.3018280 49.99669
26.65033 49.93903 -0.2956457 50.01701
26.69367 49.94056 -0.2896483 50.05412
26.73700 49.94113 -0.2839193 49.95215
26.78033 49.94281 -0.2784212 50.05403
26.82367 49.94254 -0.2729272 50.01844
26.86700 49.94237 -0.2677939 49.86796
26.91033 49.94308 -0.2631296 49.80791
26.95366 49.94370 -0.2586782 49.99898
26.99700 49.94395 -0.2544341 49.94732
27.04033 49.94434 -0.2503707 50.10283
27.08367 49.94506 -0.2463751 49.86976
27.12700 49.94520 -0.2427611 50.07597
27.17033 49.94549 -0.2394209 50.08376
27.21367 49.94563 -0.2362126 49.94516
27.25700 49.94624 -0.2333556 50.11168
27.30033 49.94619 -0.2304930 49.92463
27.34366 49.94654 -0.2277875 50.13098
27.38700 49.94597 -0.2249029 49.99930
27.43033 49.94713 -0.2220406 50.13930
27.47367 49.94634 -0.2193420 50.04066
27.51367 49.94765 -0.2171260 49.85656
27.55700 49.94164 -0.2154785 50.10972
27.60033 49.91552 -0.1910428 49.90536
27.64366 49.87113 -.07230335 49.93340
27.68700 49.81890 0.06567776 50.06262
27.73034 49.76205 0.2128662 50.02760
27.77367 49.70342 0.3669719 49.88455
27.81700 49.63989 0.5274614 50.08160
27.86033 49.57674 0.6806285 50.11272
27.90366 49.50947 0.8294126 49.95734
27.94700 49.43967 0.9717462 49.88750
27.99033 49.36981 1.104245 50.02880
28.03367 49.29890 1.226748 50.01288
28.07700 49.22503 1.338764 50.13386
28.12034 49.15007 1.441427 49.96544
28.16367 49.07512 1.531862 50.11796
28.20700 48.99748 1.622858 49.35097
28.25033 48.92044 1.700910 49.75500
28.29366 48.84153 1.771619 50.00433
28.33700 48.76308 1.833758 50.01924
28.38034 48.68303 1.894536 50.16773
28.42367 48.60212 1.946310 50.11384
28.46700 48.52203 1.994515 49.97884
28.51033 48.44022 2.035910 49.74122
28.55366 48.35840 2.073448 49.90100
28.59700 48.27528 2.111598 49.96372
28.64033 48.19340 2.143746 49.89759
28.68367 48.10937 2.172728 49.88416
28.72700 48.02667 2.198574 49.86078
28.77033 47.94328 2.223162 49.88806
28.81367 47.85847 2.243692 50.12344
28.85700 47.77514 2.263724 50.22066
28.90033 47.69052 2.279370 50.04606
28.94367 47.60608 2.294644 49.96620
28.98700 47.52152 2.310528 49.86560
29.03033 47.43675 2.323186 50.09092
29.07367 47.35204 2.334801 50.03190
29.11700 47.26582 2.345893 50.08627
29.16033 47.18121 2.356137 49.82576
29.20366 47.09565 2.364570 49.78542
29.24700 47.01076 2.374257 50.09960
29.29033 46.92537 2.382257 49.99578
29.33367 46.83980 2.390460 50.06394
29.37700 46.75421 2.398133 49.79782
29.42033 46.66741 2.405798 50.19444
29.46367 46.58123 2.413661 50.01844
29.50700 46.49696 2.421216 50.11731
29.55033 46.41013 2.428691 49.94368
29.59366 46.32486 2.436014 50.04821
29.63700 46.23856 2.442722 49.98620
29.68033 46.15270 2.449081 49.90730
29.72367 46.06699 2.455044 50.13950
29.76700 45.98007 2.460792 50.01874
29.81033 45.89472 2.466424 49.92447
29.85366 45.80771 2.471674 49.72854
29.89700 45.72218 2.476805 50.12211
29.94033 45.63602 2.481552 50.06522
29.98367 45.54980 2.486286 49.82676
30.02700 45.46434 2.490363 49.99057
30.07033 45.37840 2.494400 49.94269
30.11367 45.29074 2.498352 50.01456
30.15700 45.20456 2.502186 50.12713
30.20033 45.11763 2.505820 49.90270
30.24366 45.03272 2.509234 49.89090
30.28700 44.94610 2.512450 50.05862
30.33033 44.85976 2.515587 50.14730
30.37366 44.77328 2.518662 50.00781
30.41700 44.68722 2.521420 49.97886
30.46033 44.60016 2.524184 49.89068
30.50366 44.51594 2.526707 49.98835
30.54700 44.42882 2.529094 50.08560
30.59033 44.34160 2.531591 49.88318
30.63366 44.25570 2.533936 49.84457
30.67700 44.17039 2.536285 49.85859
30.72034 44.08270 2.538430 50.08270
30.76367 43.99744 2.540652 50.10604
30.80700 43.91047 2.542708 49.95671
30.85033 43.82378 2.544926 49.78724
30.89366 43.73697 2.547123 49.90676
30.93700 43.65171 2.549504 49.99500
30.98034 43.56550 2.551776 49.83426
31.02367 43.47895 2.553930 50.09253
31.06700 43.39224 2.556152 49.91205
31.11033 43.30476 2.558379 49.89654
31.15366 43.21922 2.560356 49.93337
31.19700 43.13300 2.562365 50.00876
31.24033 43.04637 2.564345 49.91690
31.28367 42.95970 2.566206 49.99830
31.32700 42.87356 2.568133 50.12392
31.37034 42.78719 2.569908 49.95067
31.41367 42.70121 2.571925 50.04932
31.45700 42.61431 2.573875 50.05934
31.50033 42.52858 2.575744 50.00844
31.54366 42.44178 2.577925 50.06928
31.58700 42.35602 2.580044 50.00361
31.63034 42.26907 2.582244 49.88209
31.67367 42.18300 2.584642 50.07312
31.71700 42.09680 2.587024 50.02465
31.76033 42.01060 2.589398 49.92238
31.80366 41.92382 2.591760 50.06555
31.84700 41.83740 2.594159 50.02729
31.89033 41.75148 2.596502 49.81387
31.93367 41.66432 2.598755 49.91049
31.97700 41.57791 2.600982 49.98896
32.02033 41.49170 2.602968 50.05645
32.06367 41.40524 2.604695 49.83637
32.10700 41.31880 2.606318 49.93098
32.15033 41.23261 2.607898 50.05094
32.19366 41.14717 2.609247 50.09297
32.23700 41.05870 2.610582 49.84906
32.28033 40.97248 2.611947 50.00570
32.32367 40.88600 2.613246 49.87269
32.36700 40.79816 2.614432 49.88596
32.41033 40.71227 2.615711 49.99274
32.45367 40.62523 2.616814 50.03424
32.49700 40.53910 2.618106 50.05976
32.54033 40.45383 2.619136 49.82632
32.58366 40.36597 2.619779 49.90043
32.62700 40.27987 2.620550 50.17261
32.67034 40.19381 2.621075 49.86776
32.71367 40.10745 2.621538 49.99434
32.75700 40.02090 2.621820 49.91081
32.80033 39.93384 2.621814 49.84381
32.84366 39.84760 2.621960 50.02533
32.88700 39.76087 2.622070 49.93886
32.93033 39.67420 2.622375 50.19378
32.97367 39.58770 2.622260 49.93617
33.01700 39.50082 2.622480 49.91370
33.06033 39.41525 2.622602 49.98352
33.10366 39.32850 2.622770 50.03526
33.14700 39.24158 2.623069 49.96072
33.19033 39.15472 2.623347 49.98393
33.23367 39.06832 2.623627 50.08942
33.27700 38.98168 2.623766 50.03984
33.32033 38.89544 2.624066 49.83449
33.36367 38.80884 2.624154 50.07878
33.40700 38.72233 2.624390 49.88724
33.45033 38.63562 2.624570 50.04640
33.49367 38.54939 2.624757 49.90961
33.53700 38.46191 2.624906 50.12824
33.58034 38.37609 2.625178 49.90134
33.62366 38.29004 2.625460 49.98346
33.66700 38.20313 2.625571 49.90377
33.71033 38.11637 2.625860 49.93194
33.75366 38.02987 2.626114 50.08324
33.79700 37.94461 2.626600 50.13796
33.84033 37.85706 2.627012 49.99654
33.88367 37.76979 2.627568 50.10059
33.92700 37.68385 2.628359 50.12799
33.97034 37.59586 2.629158 50.03429
34.01367 37.50919 2.630222 49.95696
34.05700 37.42268 2.631375 49.98312
34.10034 37.33618 2.632414 50.04513
34.14366 37.24922 2.633661 49.88960
34.18700 37.16421 2.634799 50.01972
34.23033 37.07690 2.636145 50.10530
34.27367 36.99053 2.637382 49.79898
34.31700 36.90451 2.638609 50.17191
34.36033 36.81844 2.640014 50.05268
34.40367 36.73167 2.641380 49.93941
34.44700 36.64524 2.642898 49.89502
34.49033 36.55806 2.644552 49.83962
34.53366 36.47225 2.646278 49.84428
34.57700 36.38602 2.648035 50.15497
34.62033 36.29992 2.649904 49.94082
34.66367 36.21350 2.651809 49.82907
34.70700 36.12739 2.653703 50.05590
34.75033 36.03961 2.655664 50.04746
34.79367 35.95462 2.657572 49.93960
34.83700 35.86748 2.659172 50.12148
34.88034 35.78202 2.660548 49.99684
34.92366 35.69430 2.661877 49.91472
34.96700 35.60857 2.662870 50.01379
35.01033 35.52230 2.663754 50.02666
35.05366 35.43540 2.664370 50.01504
35.09700 35.34886 2.664839 50.05004
35.14033 35.26215 2.665044 49.90747
35.18367 35.17515 2.665154 50.11211
35.22700 35.08954 2.665148 49.86182
35.27033 35.00193 2.665017 50.06352
35.31367 34.91506 2.664974 49.86256
35.35700 34.82825 2.664727 50.06548
35.40033 34.74185 2.664388 50.13516
35.44366 34.65538 2.664008 50.25247
35.48700 34.56875 2.663580 49.91000
35.53033 34.48120 2.663082 50.04947
35.57367 34.39514 2.662655 49.98691
35.61700 34.30748 2.662283 49.88470
35.66033 34.22160 2.662108 49.94532
35.70367 34.13452 2.661864 50.06254
35.74700 34.04758 2.661747 50.02795
35.79033 33.96135 2.661504 49.91817
35.83366 33.87460 2.661251 50.10289
35.87700 33.78808 2.660737 49.98541
35.92034 33.69978 2.660260 50.00435
35.96367 33.61464 2.659465 49.99238
36.00700 33.52739 2.658785 50.09926
36.05033 33.44185 2.658106 49.97440
36.09366 33.35468 2.657419 50.09671
36.13700 33.26836 2.656693 50.19170
36.18033 33.18164 2.655900 49.83915
36.22367 33.09517 2.655293 50.14858
36.26700 33.00854 2.654597 50.08474
36.31033 32.92220 2.654031 49.90295
36.35366 32.83560 2.653561 49.93602
36.39700 32.74896 2.653284 50.02230
36.44033 32.66284 2.653247 49.98913
36.48367 32.57556 2.653136 49.80492
36.52700 32.48975 2.653174 49.82695
36.57033 32.40278 2.653404 49.95209
36.61367 32.31564 2.653624 50.07419
36.65700 32.22976 2.654020 49.98690
36.70033 32.14424 2.654437 49.87012
36.74367 32.05647 2.654931 49.92228
36.78700 31.97073 2.655469 49.88082
36.83034 31.88509 2.656052 49.98650
36.87366 31.79727 2.656588 50.07787
36.91700 31.71145 2.657018 49.91520
36.96033 31.62434 2.657392 49.95978
37.00366 31.53734 2.657675 49.87570
37.04700 31.45098 2.657860 49.99425
37.09033 31.36360 2.658262 49.92518
37.13367 31.27662 2.658305 50.18536
37.17700 31.19034 2.658425 49.97087
37.22034 31.10339 2.658429 49.89417
37.26367 31.01692 2.658305 49.11107
37.30700 30.93004 2.658039 50.06156
37.35034 30.84343 2.657642 50.08804
37.39366 30.75670 2.656929 49.85160
37.43700 30.67079 2.656122 49.84088
37.48033 30.58381 2.655409 49.90286
37.52367 30.49672 2.654779 50.07800
37.56700 30.41100 2.653961 49.95662
37.61033 30.32296 2.653160 49.84524
37.65367 30.23752 2.652324 49.96076
37.69700 30.15063 2.651631 49.96124
37.74033 30.06341 2.650960 50.17090
37.78366 29.97764 2.650297 49.95820
37.82700 29.89059 2.649706 49.97494
37.87033 29.80411 2.648982 50.05777
37.91367 29.71790 2.648611 50.09705
37.95700 29.63098 2.648190 50.05009
38.00033 29.54390 2.647856 49.88956
38.04367 29.45735 2.647608 50.06816
38.08700 29.37138 2.647341 50.08090
38.13034 29.28433 2.647212 50.18586
38.17366 29.19845 2.647072 49.92448
38.21700 29.11208 2.646770 49.90810
38.26033 29.02462 2.646552 50.03848
38.30366 28.93914 2.646433 49.92550
38.34700 28.85239 2.646654 50.18250
38.39033 28.76458 2.646840 49.91547
38.43367 28.67773 2.647227 50.05342
38.47700 28.59100 2.647676 50.07676
38.52033 28.50456 2.648272 50.14773
38.56367 28.41746 2.648870 49.83296
38.60700 28.33106 2.649540 49.95260
38.65033 28.24420 2.650086 50.16088
38.69366 28.15825 2.650667 50.12284
38.73700 28.07046 2.651316 50.07231
38.78033 27.98381 2.651884 50.21825
38.82367 27.89764 2.652440 50.00872
38.86700 27.81152 2.652938 49.91276
38.91033 27.72442 2.653382 50.11722
38.95367 27.63776 2.654012 49.89357
38.99700 27.55097 2.654513 50.02390
39.04033 27.46500 2.655106 49.97930
39.08366 27.37804 2.655792 49.99184
39.12700 27.29185 2.656578 50.03728
39.17034 27.20566 2.657630 50.03830
39.21367 27.11881 2.658701 50.04526
39.25700 27.03217 2.660099 50.02502
39.30033 26.94668 2.661869 49.90809
39.34366 26.86061 2.664166 49.84414
39.38700 26.77469 2.667613 50.11594
39.43033 26.68875 2.672660 49.99714
39.47367 26.60346 2.684940 49.84292
39.51700 26.51905 2.717728 49.92914
39.56033 26.43495 2.772958 49.98922
39.60366 26.35172 2.849170 49.90592
39.64700 26.27256 2.949375 50.00446
39.69033 26.19341 3.090298 49.95566
39.73367 26.11870 3.267438 50.01808
39.77700 26.04590 3.499464 49.91299
39.82033 25.97986 3.785794 49.89166
39.86367 25.91646 4.127194 50.00558
39.90700 25.85699 4.519628 49.86660
39.95033 25.80212 4.948844 49.97341
39.99367 25.74952 5.400668 49.97704
40.03700 25.69947 5.854466 50.10520
40.08034 25.64964 6.293079 50.04244
40.12366 25.59794 6.699929 49.91496
40.16700 25.54428 7.053272 49.93487
40.21033 25.48577 7.347538 50.11861
40.25366 25.42427 7.585393 49.95929
40.29700 25.35776 7.763694 49.90914
40.34033 25.28506 7.889018 49.90159
40.38367 25.20916 7.963638 50.06631
40.42700 25.13070 7.997387 49.97210
40.47034 25.04816 8.004846 50.10168
40.51367 24.96146 7.992831 50.13524
40.55700 24.87248 7.940512 49.83526
40.60034 24.78249 7.857818 49.88606
40.64366 24.68998 7.758804 50.15264
40.68700 24.59600 7.645752 49.96626
40.73033 24.49994 7.522340 50.01134
40.77367 24.40366 7.381661 50.06662
40.81700 24.30616 7.235576 50.01184
40.86033 24.20812 7.076906 50.02064
40.90367 24.10870 6.904068 49.85806
40.94700 24.00742 6.727280 49.98689
40.99033 23.90618 6.530824 49.91567
41.03366 23.80449 6.330871 49.98510
41.07700 23.70158 6.124869 50.00286
41.12033 23.59814 5.915502 49.96500
41.16367 23.49418 5.706472 50.10172
41.20700 23.39072 5.503650 50.11918
41.25033 23.28674 5.302654 50.10551
41.29367 23.18470 5.112762 49.84126
41.33700 23.08113 4.928266 50.00146
41.38033 22.98042 4.755875 50.12098
41.42366 22.87908 4.591291 50.04483
41.46700 22.77824 4.435426 49.96646
41.51033 22.67869 4.288059 49.94876
41.55367 22.57935 4.149113 50.00717
41.59700 22.48203 4.020030 49.80619
41.64033 22.38435 3.899978 49.93583
41.68367 22.28684 3.786714 50.25910
41.72700 22.19054 3.688232 49.97956
41.77033 22.09570 3.591328 49.92556
41.81367 22.00204 3.507144 49.80878
41.85700 21.90753 3.426322 49.99940
41.90033 21.81395 3.356520 49.85737
41.94366 21.72213 3.291896 50.12491
41.98700 21.63000 3.232887 50.14096
42.03033 21.53806 3.180843 49.86134
42.07367 21.44598 3.133683 49.99791
42.11700 21.35548 3.088400 49.95533
42.16033 21.26599 3.049091 49.94360
42.20367 21.17622 3.015610 50.16484
42.24700 21.08606 2.981764 49.84104
42.29033 20.99654 2.954888 49.80367
42.33366 20.90735 2.925513 49.94135
42.37700 20.81978 2.903650 50.11190
42.42033 20.73055 2.882007 50.22433
42.46367 20.64222 2.861299 49.97176
42.50700 20.55408 2.846067 50.00837
42.55033 20.46488 2.830008 50.04231
42.59366 20.37743 2.817124 50.00672
42.63700 20.28866 2.806800 50.03379
42.68033 20.20101 2.798134 50.03907
42.72367 20.11361 2.789086 49.95906
42.76700 20.02522 2.780626 50.08031
42.81033 19.93788 2.771356 49.88040
42.85367 19.85131 2.763648 49.98212
42.89700 19.76393 2.755402 50.01446
42.94033 19.67646 2.747522 49.96176
42.98367 19.58816 2.740053 49.90600
43.02700 19.50184 2.732977 49.94220
43.07033 19.41456 2.726328 49.98666
43.11367 19.32698 2.720153 49.88680
43.15700 19.23998 2.714392 49.84765
43.20033 19.15259 2.708947 50.15384
43.24367 19.06587 2.703762 50.15396
43.28700 18.97986 2.698860 50.02867
43.33033 18.89171 2.694138 50.07863
43.37366 18.80521 2.689776 49.90719
43.41700 18.71864 2.685669 50.09136
43.46033 18.63153 2.681679 49.99016
43.50367 18.54601 2.678054 49.88308
43.54700 18.45872 2.674547 49.97334
43.59033 18.37165 2.671398 50.10092
43.63367 18.28516 2.668642 50.01860
43.67700 18.19842 2.666059 49.95759
43.72033 18.11168 2.663512 49.76004
43.76367 18.02522 2.661285 50.12703
43.80700 17.93861 2.659203 50.10122
43.85034 17.85152 2.657244 49.87992
43.89366 17.76456 2.655516 49.90410
43.93700 17.67885 2.653656 49.90084
43.98033 17.59139 2.652102 50.22172
44.02367 17.50618 2.650650 49.98105
44.06700 17.41910 2.649362 49.91034
44.11033 17.33162 2.648108 50.07352
44.15367 17.24594 2.647129 50.03282
44.19700 17.15872 2.645963 49.94572
44.24033 17.07292 2.644752 49.82617
44.28366 16.98571 2.643751 50.04746
44.32700 16.89917 2.642878 49.90333
44.37033 16.81204 2.642134 49.97784
44.41367 16.72604 2.641565 49.97397
44.45700 16.63893 2.641049 50.10906
44.50033 16.55185 2.640647 50.06500
44.54367 16.46511 2.640513 49.88472
44.58700 16.37847 2.640503 49.99504
44.63033 16.29060 2.640424 49.99128
44.67366 16.20404 2.640554 49.97080
44.71700 16.11696 2.640763 49.87224
44.76033 16.03082 2.640945 50.06696
44.80367 15.94429 2.640986 50.03540
44.84700 15.85673 2.640826 50.18608
44.89033 15.77102 2.640773 49.88456
44.93367 15.68380 2.640524 50.06262
44.97700 15.59757 2.640205 49.96336
45.02033 15.51164 2.639872 50.07563
45.06367 15.42406 2.639456 49.85869
45.10700 15.33833 2.639158 50.12656
45.15033 15.25144 2.638798 50.02936
45.19366 15.16485 2.638327 50.03072
45.23700 15.07752 2.637793 50.13524
45.28033 14.99187 2.637480 49.96712
45.32367 14.90524 2.636853 49.87366
45.36700 14.81941 2.636099 50.28830
45.41033 14.73231 2.635464 49.93640
45.45367 14.64503 2.634873 50.07898
45.49700 14.55981 2.634084 50.02463
45.54033 14.47377 2.633586 49.98978
45.58366 14.38602 2.633110 49.83400
45.62700 14.30030 2.632697 49.96336
45.67033 14.21392 2.632367 50.11100
45.71367 14.12639 2.632084 50.19428
45.75700 14.04032 2.631878 50.06469
45.80033 13.95346 2.631760 50.02797
45.84366 13.86656 2.631474 50.01153
45.88700 13.78003 2.631260 49.90984
45.93033 13.69411 2.631368 50.01717
45.97367 13.60678 2.631372 49.90024
46.01700 13.52030 2.631390 50.05304
46.06033 13.43353 2.631425 49.92722
46.10367 13.34725 2.631550 50.08870
46.14700 13.26057 2.631518 50.02336
46.19033 13.17366 2.631570 50.07104
46.23367 13.08685 2.631381 50.04301
46.27700 13.00104 2.631258 50.08390
46.32033 12.91395 2.630972 50.01826
46.36367 12.82808 2.630657 49.91098
46.40700 12.74089 2.630470 50.20854
46.45033 12.65377 2.630135 50.02906
46.49367 12.56692 2.629994 49.97934
46.53700 12.48048 2.629893 50.20373
46.58033 12.39466 2.629670 49.91932
46.62366 12.30806 2.629494 50.00634
46.66700 12.22039 2.629385 49.92442
46.71033 12.13428 2.629309 49.98474
46.75367 12.04694 2.629328 49.96998
46.79700 11.95950 2.629217 50.05691
46.84033 11.87402 2.629426 49.81742
46.88367 11.78688 2.629231 49.95888
46.92700 11.69991 2.629166 49.94380
46.97033 11.61416 2.628827 49.87664
47.01367 11.52695 2.628565 49.84996
47.05700 11.44003 2.628381 50.14590
47.10034 11.35362 2.628102 50.21304
47.14366 11.26578 2.627754 49.96412
47.18700 11.18029 2.627290 49.88102
47.23033 11.09501 2.626932 49.74765
47.27367 11.00787 2.626582 49.99398
47.31700 10.92018 2.626468 49.90545
47.36033 10.83344 2.626188 49.79793
47.40367 10.74593 2.626056 49.84521
47.44700 10.66018 2.625976 50.00956
47.49033 10.57352 2.625854 50.02269
47.53366 10.48673 2.625696 49.98447
47.57700 10.39999 2.625458 49.82211
47.62033 10.31347 2.625228 50.03521
47.66367 10.22664 2.625010 49.91712
47.70700 10.14045 2.624826 49.87800
47.75033 10.05435 2.624787 49.87508
47.79367 9.967626 2.624426 50.01967
47.83700 9.880039 2.624144 50.13344
47.88033 9.794168 2.624018 49.93702
47.92366 9.707452 2.623758 49.93734
47.96700 9.620644 2.623521 49.95998
48.01033 9.533351 2.623142 50.01430
48.05367 9.447982 2.622858 50.08048
48.09700 9.361915 2.622470 50.23463
48.14033 9.274322 2.621975 50.08691
48.18367 9.187653 2.621732 50.08432
48.22700 9.101988 2.621464 49.85665
48.27033 9.014716 2.621097 50.11813
48.31367 8.928566 2.620774 50.05395
48.35700 8.841938 2.620376 49.97350
48.40033 8.754939 2.620056 49.89890
48.44366 8.668661 2.619816 49.96932
48.48700 8.581964 2.619621 50.07684
48.53033 8.495982 2.619085 49.95574
48.57367 8.410012 2.618723 49.94050
48.61700 8.322348 2.618439 50.25902
48.66033 8.235330 2.618358 49.94303
48.70367 8.149019 2.618350 49.87952
48.74700 8.061322 2.618606 49.98588
48.79033 7.975122 2.618950 50.10510
48.83366 7.888122 2.619289 49.91386
48.87700 7.801070 2.619653 50.01702
48.92033 7.714312 2.620158 49.80133
48.96367 7.628132 2.620634 50.21184
49.00700 7.541232 2.621199 49.82938
49.05033 7.454276 2.621617 50.10226
49.09366 7.367768 2.622112 50.06180
49.13700 7.281134 2.622354 50.01596
49.18033 7.194491 2.622541 50.10886
49.22367 7.107044 2.622796 49.95291
49.26700 7.021416 2.622766 49.89359
49.31033 6.934944 2.622646 50.12122
49.35367 6.848110 2.622594 50.01000
49.39700 6.761759 2.622400 50.09324
49.44033 6.675292 2.622072 50.05302
49.48367 6.588684 2.621791 50.03406
49.52700 6.501876 2.621643 49.85038
49.57033 6.415928 2.621148 49.95952
49.61367 6.329092 2.620969 49.90351
49.65700 6.242850 2.620662 49.81609
49.70033 6.156082 2.620386 49.68676
49.74367 6.069274 2.620330 50.01570
49.78700 5.983520 2.619978 50.03196
49.83033 5.895369 2.619747 50.06685
49.87366 5.809588 2.619692 49.97805
49.91700 5.723482 2.619656 49.97302
49.96033 5.636541 2.619758 50.04176
50.00367 5.550584 2.619851 49.98746
50.04700 5.462613 2.619769 50.00299
50.09033 5.376682 2.619896 50.07434
50.13367 5.289465 2.619800 50.02663
50.17700 5.203316 2.619777 50.00052
50.22033 5.116404 2.619764 50.22456
50.26367 5.030252 2.619672 50.14389
50.30700 4.942699 2.619402 50.01608
50.35034 4.856410 2.619350 50.18806
50.39366 4.770194 2.619184 50.08774
50.43700 4.683481 2.618990 50.06352
50.48033 4.598096 2.618906 49.78680
50.52367 4.510424 2.618830 49.95076
50.56700 4.423678 2.618680 49.97187
50.61033 4.336963 2.618660 50.12720
50.65367 4.251361 2.618553 49.89626
50.69700 4.163506 2.618417 49.90100
50.74033 4.076574 2.618338 50.25888
50.78366 3.990980 2.618244 49.91028
50.82700 3.904372 2.618065 49.93776
50.87033 3.817145 2.617810 50.01206
50.91367 3.730781 2.617623 50.01840
50.95700 3.644438 2.617328 49.88467
51.00033 3.557554 2.616968 49.95322
51.04367 3.471178 2.616754 49.91376
51.08700 3.384364 2.616452 49.87992
51.13033 3.297675 2.616196 50.19334
51.17366 3.211484 2.616055 49.93381
51.21700 3.123797 2.615845 50.13630
51.26033 3.038277 2.615886 50.28111
51.30366 2.951761 2.615926 49.91563
51.34700 2.864326 2.615995 49.98374
51.39033 2.777830 2.615955 50.19042
51.43367 2.691828 2.615928 49.88243
51.47700 2.605075 2.615730 49.91750
51.52033 2.518160 2.615580 50.19644
51.56367 2.431114 2.615266 50.09030
51.60700 2.344805 2.614989 49.83796
51.65034 2.257785 2.614736 49.85700
51.69366 2.171767 2.614458 49.92124
51.73700 2.085096 2.614097 50.26783
51.78033 1.997622 2.613742 50.09804
51.82366 1.910972 2.613478 50.16166
51.86700 1.824613 2.613110 49.92714
51.91033 1.736948 2.612827 50.19324
51.95367 1.652179 2.612477 49.99335
51.99700 1.564140 2.612052 50.09931
52.04033 1.479299 2.612040 50.07828
52.08367 1.411072 2.608946 49.99060
52.12700 1.364572 2.540824 49.85445
52.17034 1.327840 2.425487 49.94537
52.21367 1.297879 2.297550 49.98193
52.25700 1.269540 2.160948 49.96563
52.30033 1.244992 2.020132 50.17368
52.34366 1.223283 1.880218 50.05948
52.38700 1.203025 1.740618 50.15691
52.43033 1.184032 1.611558 50.09110
52.47368 1.169904 1.485406 50.02928
52.51700 1.153534 1.369178 49.93044
52.56033 1.140271 1.263835 50.08578
52.60366 1.128001 1.166803 49.99710
52.64700 1.117161 1.076388 49.81778
52.69033 1.106021 0.9892569 50.05948
52.73367 1.096279 0.9125666 49.86617
52.77700 1.089550 0.8443456 50.12066
52.82033 1.080929 0.7786549 49.82232
52.86367 1.073845 0.7206138 49.88718
52.90700 1.067131 0.6684553 50.05158
52.95033 1.061338 0.6188969 50.13880
52.99366 1.057002 0.5762050 49.97752
53.03700 1.051241 0.5410479 49.98376
53.08033 1.046583 0.5042396 49.94244
53.12366 1.042528 0.4730814 50.02854
53.16700 1.038825 0.4442670 50.07193
53.21033 1.035390 0.4190696 49.97618
53.25367 1.032436 0.3952571 50.03924
53.29700 1.030099 0.3730918 50.02717
53.34033 1.027460 0.3555570 49.96451
53.38367 1.024387 0.3380752 49.98396
53.42700 1.022925 0.3246892 49.81184
53.47033 1.020920 0.3085144 49.79617
53.51367 1.018119 0.2976693 49.99806
53.55700 1.016559 0.2868156 50.00898
53.60034 1.014938 0.2770011 50.04810
53.64366 1.015089 0.2680065 49.83097
53.68700 1.012213 0.2582934 50.11942
53.73033 1.012220 0.2490140 50.14284
53.77368 1.009696 0.2410152 49.96680
53.81700 1.009109 0.2333456 50.00807
53.86033 1.009602 0.2257812 49.98407
53.90367 1.006523 0.2183496 49.89428
53.94700 1.006483 0.2111081 49.96334
53.99033 1.006087 0.2043268 50.02934
54.03367 1.005095 0.1979390 50.13614
54.07700 1.004046 0.1917097 50.03332
54.12033 1.004097 0.1859450 50.15260
54.16367 1.003146 0.1803495 49.93375
54.20700 1.002595 0.1752196 49.98941
54.25033 1.002527 0.1702396 49.90500
54.29366 1.001149 0.1655975 49.85800
54.33700 1.001756 0.1613693 50.12441
54.38033 0.9999780 0.1575356 50.05112
54.42366 1.000028 0.1537950 49.94120
54.46700 0.9985832 0.1504689 50.09786
54.51033 0.9992432 0.1472760 50.00786
54.55366 0.9981772 0.1442716 49.98230
54.59700 0.9975730 0.1415701 49.93779
54.64033 0.9985941 0.1389738 49.88418
54.68367 0.9974681 0.1365639 50.02268
54.72700 0.9974770 0.1343420 50.01120
54.77033 0.9972582 0.1322842 50.10466
54.81367 0.9965582 0.1302102 50.01700
-2.000000 2.000000 0.0000000 0.0000000