File: imagens/notebooks/dados experimentais/dsc/Karl_CTAB100 Ur 43%.txt
CLOSED
Version	1.0
Language	English
Run	1
RunSerial	148
Instrument	DSC Q100 V9.9 Build 303
Module	DSC Standard Cell FC
Operator	LL
File	\\Niger\ta\Data\DSC\2018\Geral\Karl_CTAB100 Ur 43%.001
ProcName	Karl
InstSerial	0100-1211
Sample	CTAB100 Ur 43%
Size	10.6400	mg
Method	Karl
Comment
Xcomment	Pan: Aluminum Hermetic
Xcomment	Gas1: Nitrogen 50.0 ml/min
Xcomment	Gas2: Nitrogen 0.0 ml/min
Text
Exotherm	UP
Kcell	1.09030
Calib	-11.7822
TempCal	1	pts	158.71	156.60
TzeroDt	-90.0515 -0.0093 2.2263
TzeroDtz	-90.0515 0.0466 2.4421
InstCalFile	Tzero: \\Niger\ta\Data\DSC\CALIBRATION\20122016\CALIBRATION\0_RCS_12_20_2016 17_23_31.TZR
InstCalFile	Baseline: \\Niger\ta\Data\DSC\CALIBRATION\20122016\L.Base 20122016
InstCalFile	Sapphire: \\Niger\ta\Data\DSC\CALIBRATION\20122016\Safira 20122017.001
InstCalDate	Tzero 2016-12-20 Time 19:23:31
TempRange	-90.04 to 395.23 °C at 19.96 °C/min Heat Only
AutoZero	Delta T Offset 0.000 uV
AutoZero	Delta T0 Offset 0.000 uV
Controls	Gas 1  Event Off  Sampling 0.2
Cell#	FC-02451
CoolingUnit	RCS
SelHeatFlow	Heat Flow T4 (mW)
AutoAnalysis	Off
MacroFile
Nsig	4
Sig1	Time (min)
Sig2	Temperature (°C)
Sig3	Heat Flow (mW)
Sig4	Sample Purge Flow (mL/min)
Date	2018-05-16
Time	12:07:50
OrgMethod	1: Equilibrate at 1.00 °C
OrgMethod	2: Ramp 2.00 °C/min to 60.00 °C
OrgMethod	3: Isothermal for 3.00 min
OrgMethod	4: Mark end of cycle 1
OrgMethod	5: Ramp 2.00 °C/min to 1.00 °C
OrgMethod	6: Isothermal for 3.00 min
OrgMethod	7: Mark end of cycle 2
OrgFile	C:\TA\Data\DSC\2018\Geral\Karl_CTAB100 Ur 43%.001
3.33324E-4 1.169856 1.115070 49.94500
0.05033332 1.156518 0.9955014 49.99231
0.1003333 1.172378 0.8670950 49.85166
0.1503333 1.215094 0.7141785 49.84576
0.2003333 1.268425 0.5554203 49.94944
0.2503333 1.329944 0.3867910 50.00930
0.3003333 1.397217 0.2345140 50.01719
0.3503333 1.467994 0.09323634 49.90746
0.4003334 1.544005 -.03122861 50.12916
0.4503334 1.621424 -0.1537414 50.07314
0.5003334 1.702578 -0.2571420 50.15624
0.5503332 1.785658 -0.3457458 50.00836
0.6003332 1.872321 -0.4248406 50.00862
0.6503332 1.959391 -0.4943373 50.12912
0.7003332 2.047470 -0.5544510 49.97491
0.7503332 2.137830 -0.6049364 50.03223
0.8003332 2.228712 -0.6515217 50.10400
0.8503332 2.321066 -0.6915320 50.00996
0.9003332 2.413864 -0.7250046 49.94652
0.9503334 2.507790 -0.7556853 49.91139
1.000333 2.601990 -0.7821747 50.01729
1.050334 2.697735 -0.8027026 49.95876
1.100334 2.792328 -0.8232056 49.96811
1.150334 2.888743 -0.8394519 50.16150
1.200334 2.984184 -0.8537189 49.92254
1.250334 3.081408 -0.8664312 49.96756
1.300334 3.178318 -0.8776419 49.90156
1.350333 3.275234 -0.8880059 50.01822
1.400333 3.372966 -0.8978638 50.05752
1.450334 3.470485 -0.9066472 50.01645
1.500333 3.568733 -0.9158645 49.98088
1.550334 3.666782 -0.9247250 49.96600
1.600334 3.764736 -0.9334503 50.04504
1.650333 3.862146 -0.9416997 49.96716
1.700334 3.960538 -0.9498194 49.95429
1.750334 4.058903 -0.9574265 49.88674
1.800334 4.157850 -0.9646305 50.19400
1.850334 4.256504 -0.9714078 50.02261
1.900334 4.354940 -0.9777528 49.95252
1.950334 4.452600 -0.9837882 49.94434
2.000334 4.552631 -0.9892518 50.09296
2.050333 4.650948 -0.9944532 49.95090
2.100334 4.749710 -0.9993438 50.00605
2.150334 4.849167 -1.003971 49.98852
2.200334 4.948984 -1.008180 50.06966
2.250334 5.047803 -1.012247 49.98108
2.300333 5.145450 -1.016166 50.15798
2.350334 5.247095 -1.019546 49.79669
2.400334 5.344340 -1.023029 49.82828
2.450334 5.443695 -1.026144 50.05116
2.500334 5.542769 -1.029131 49.96030
2.550333 5.641660 -1.031996 50.06266
2.600333 5.742156 -1.034888 50.09510
2.650333 5.840855 -1.037521 50.00635
2.700333 5.940507 -1.040053 50.15466
2.750333 6.039858 -1.042424 50.07180
2.800333 6.139702 -1.044827 50.04532
2.850333 6.239136 -1.046951 49.87372
2.900333 6.339438 -1.049027 50.33469
2.950333 6.437996 -1.051053 49.89287
3.000333 6.538201 -1.053047 49.87842
3.050333 6.637400 -1.054951 49.77337
3.100333 6.737369 -1.056962 49.82034
3.150333 6.836376 -1.058886 50.08097
3.200333 6.935470 -1.060802 50.07710
3.250333 7.035258 -1.062647 50.08466
3.300333 7.135022 -1.064238 49.95590
3.350333 7.235665 -1.065672 50.11433
3.400333 7.334924 -1.066988 49.96117
3.450333 7.434650 -1.068134 49.88283
3.500333 7.534150 -1.069318 49.90661
3.550333 7.633484 -1.070466 50.15211
3.600333 7.733579 -1.071456 49.87851
3.650333 7.832265 -1.072497 50.04256
3.700333 7.932728 -1.073654 50.07304
3.750333 8.031106 -1.074759 50.08684
3.800333 8.132392 -1.075836 49.89070
3.850333 8.231610 -1.077056 50.09459
3.900333 8.332718 -1.078328 49.93032
3.950333 8.431412 -1.079608 50.13339
4.000333 8.531850 -1.080643 49.97778
4.050333 8.631147 -1.081726 49.95993
4.100333 8.730009 -1.082841 50.05676
4.150333 8.830676 -1.083887 49.96377
4.200333 8.931054 -1.084883 49.94210
4.250333 9.029962 -1.085885 50.04971
4.300333 9.130272 -1.086899 50.05781
4.350333 9.229755 -1.087684 50.05346
4.400333 9.329688 -1.088376 50.01122
4.450333 9.429272 -1.089434 49.83926
4.500333 9.528402 -1.090135 49.93000
4.550333 9.628340 -1.090926 50.07852
4.600333 9.727454 -1.091574 49.93644
4.650333 9.827480 -1.092189 49.93543
4.700333 9.927130 -1.092663 50.19738
4.750333 10.02728 -1.093354 50.06530
4.800333 10.12808 -1.094010 49.95028
4.850333 10.22697 -1.094662 50.04970
4.900333 10.32686 -1.095236 50.12018
4.950333 10.42614 -1.095888 49.95383
5.000333 10.52664 -1.096649 49.96734
5.050333 10.62614 -1.097450 50.09228
5.100333 10.72617 -1.098286 49.98512
5.150333 10.82635 -1.099127 49.92542
5.200333 10.92585 -1.100070 50.00232
5.250332 11.02644 -1.100822 49.84202
5.300332 11.12568 -1.101650 49.95538
5.350332 11.22598 -1.102507 49.86566
5.400332 11.32596 -1.103249 49.96295
5.450332 11.42544 -1.104099 50.02406
5.500332 11.52563 -1.104866 50.09739
5.550332 11.62505 -1.105641 50.04797
5.600332 11.72543 -1.106416 50.15473
5.650332 11.82530 -1.107121 50.07063
5.700332 11.92547 -1.107860 49.97183
5.750332 12.02565 -1.108402 50.13834
5.800332 12.12492 -1.108916 49.99639
5.850332 12.22497 -1.109442 49.94820
5.900332 12.32475 -1.109841 49.85712
5.950332 12.42484 -1.110352 50.09196
6.000332 12.52420 -1.110819 50.13315
6.050332 12.62531 -1.111175 50.06535
6.100332 12.72446 -1.111648 49.99834
6.150332 12.82516 -1.112038 49.92254
6.200332 12.92371 -1.112596 50.00354
6.250332 13.02463 -1.113102 49.91842
6.300332 13.12463 -1.113590 49.86960
6.350332 13.22406 -1.114254 49.91562
6.400332 13.32389 -1.114678 50.18368
6.450332 13.42374 -1.115128 50.12597
6.500332 13.52276 -1.115636 50.06790
6.550332 13.62329 -1.115890 50.04642
6.600332 13.72307 -1.116449 49.88641
6.650332 13.82264 -1.117002 49.85746
6.700332 13.92285 -1.117567 49.87859
6.750332 14.02207 -1.118163 50.01264
6.800332 14.12266 -1.118644 49.95607
6.850332 14.22357 -1.119214 49.94663
6.900332 14.32200 -1.119680 49.90467
6.950332 14.42203 -1.120317 50.15867
7.000332 14.52183 -1.120737 50.12020
7.050332 14.62149 -1.121177 49.94096
7.100332 14.72296 -1.121746 50.01892
7.150332 14.82230 -1.122407 49.91300
7.200332 14.92258 -1.122942 49.89843
7.250332 15.02141 -1.123580 49.94491
7.300332 15.12188 -1.124128 50.12468
7.350332 15.22162 -1.124310 50.13180
7.400332 15.32304 -1.124538 49.78986
7.450332 15.42074 -1.124692 50.00960
7.500332 15.52077 -1.124896 50.02100
7.550332 15.62097 -1.125252 49.99307
7.600332 15.72062 -1.125601 50.05080
7.650332 15.82039 -1.126291 50.16559
7.700332 15.92069 -1.126977 50.01230
7.750332 16.02035 -1.127734 49.85639
7.800332 16.12077 -1.128450 49.99188
7.850332 16.22139 -1.129229 50.10997
7.900332 16.32081 -1.129880 49.64886
7.950332 16.42062 -1.130506 50.02004
8.000334 16.52012 -1.131191 50.03133
8.050332 16.62044 -1.131954 49.78491
8.100332 16.72055 -1.132506 49.92996
8.150332 16.81996 -1.133120 49.92797
8.200332 16.92094 -1.133612 50.21754
8.250334 17.02138 -1.134194 50.12118
8.300332 17.11948 -1.134804 49.99395
8.350332 17.22064 -1.135226 49.90225
8.400332 17.32032 -1.135907 50.17830
8.450332 17.41998 -1.136282 50.05075
8.500334 17.52011 -1.136832 49.83963
8.550332 17.62143 -1.137513 50.27386
8.600332 17.72051 -1.138020 50.01153
8.650332 17.82091 -1.138634 49.99186
8.700332 17.92066 -1.139077 50.20156
8.750334 18.02170 -1.139590 49.90389
8.800332 18.12112 -1.139996 50.06133
8.850332 18.22044 -1.140518 50.04373
8.900332 18.32100 -1.140883 49.91300
8.950332 18.41996 -1.141197 50.06402
9.000334 18.52070 -1.141427 49.97074
9.050332 18.62010 -1.141754 50.00717
9.100332 18.72008 -1.141962 50.11129
9.150332 18.82038 -1.142204 50.01683
9.200332 18.92033 -1.142280 49.94543
9.250334 19.01929 -1.142373 49.93461
9.300332 19.11972 -1.142202 50.07356
9.350332 19.21896 -1.142253 49.92236
9.400332 19.31953 -1.142321 50.01502
9.450332 19.41854 -1.142451 50.04270
9.500334 19.51843 -1.142457 49.98728
9.550332 19.61876 -1.142774 49.93717
9.600332 19.71849 -1.142925 49.97652
9.650332 19.81830 -1.143316 49.81062
9.700332 19.91766 -1.143772 49.99377
9.750334 20.01815 -1.144274 50.08069
9.800332 20.11688 -1.144818 50.06575
9.850332 20.21752 -1.145297 49.83203
9.900332 20.31770 -1.145749 49.86438
9.950332 20.41802 -1.146250 49.99546
10.00033 20.51732 -1.146896 50.11428
10.05033 20.61744 -1.147703 50.01153
10.10033 20.71680 -1.148338 50.10884
10.15033 20.81794 -1.148994 50.01949
10.20033 20.91766 -1.149539 49.95759
10.25033 21.01769 -1.150098 49.97418
10.30033 21.11680 -1.150679 50.20300
10.35033 21.21762 -1.151024 49.92670
10.40033 21.31670 -1.151571 49.78500
10.45033 21.41700 -1.152004 50.05064
10.50034 21.51642 -1.152517 50.19270
10.55033 21.61713 -1.153010 50.08634
10.60033 21.71650 -1.153508 50.08704
10.65033 21.81684 -1.153921 49.88080
10.70033 21.91596 -1.154425 49.94574
10.75034 22.01598 -1.154676 49.83306
10.80033 22.11697 -1.155051 50.06384
10.85033 22.21578 -1.155294 50.06119
10.90033 22.31699 -1.155555 50.13017
10.95033 22.41647 -1.155939 49.95048
11.00034 22.51605 -1.156290 49.97900
11.05033 22.61639 -1.156548 49.93228
11.10033 22.71584 -1.157018 49.86281
11.15033 22.81572 -1.157526 50.07516
11.20033 22.91532 -1.157975 49.46771
11.25034 23.01544 -1.158404 49.89076
11.30033 23.11634 -1.158820 50.00130
11.35033 23.21578 -1.159238 50.18000
11.40033 23.31630 -1.159894 50.10891
11.45033 23.41523 -1.160476 49.89614
11.50034 23.51535 -1.161065 50.06398
11.55033 23.61510 -1.161687 49.95672
11.60033 23.71620 -1.162424 50.03924
11.65033 23.81613 -1.163192 49.81397
11.70033 23.91479 -1.163803 49.99039
11.75034 24.01523 -1.164475 49.92479
11.80033 24.11515 -1.165028 50.02556
11.85033 24.21494 -1.165577 50.04344
11.90033 24.31534 -1.166284 50.03766
11.95033 24.41422 -1.166860 50.01964
12.00034 24.51498 -1.167367 49.87465
12.05033 24.61476 -1.167875 50.08272
12.10033 24.71502 -1.168423 49.90660
12.15033 24.81455 -1.168793 50.18637
12.20033 24.91405 -1.169332 49.99586
12.25034 25.01451 -1.169761 50.05359
12.30033 25.11358 -1.170218 50.05117
12.35033 25.21439 -1.170709 50.01144
12.40033 25.31365 -1.171081 49.99398
12.45033 25.41474 -1.171530 50.11913
12.50034 25.51410 -1.172003 49.88272
12.55033 25.61413 -1.172340 49.94557
12.60033 25.71438 -1.172840 49.82180
12.65033 25.81333 -1.173383 49.94789
12.70033 25.91410 -1.174024 50.05761
12.75034 26.01496 -1.174648 50.14082
12.80033 26.11405 -1.175289 50.07138
12.85033 26.21400 -1.175910 49.79761
12.90033 26.31362 -1.176482 49.84158
12.95034 26.41406 -1.177154 50.10976
13.00034 26.51430 -1.177724 50.19250
13.05033 26.61424 -1.178294 50.01874
13.10033 26.71315 -1.178776 49.93982
13.15033 26.81335 -1.179304 50.02053
13.20034 26.91360 -1.179852 50.18791
13.25034 27.01350 -1.180395 49.99466
13.30033 27.11305 -1.180994 49.86426
13.35033 27.21309 -1.181370 50.14118
13.40033 27.31280 -1.181931 49.75913
13.45034 27.41377 -1.182462 50.09828
13.50034 27.51340 -1.182914 49.99332
13.55033 27.61358 -1.183742 50.11390
13.60033 27.71388 -1.184412 49.91522
13.65033 27.81426 -1.185106 49.94371
13.70034 27.91368 -1.185868 50.01938
13.75034 28.01384 -1.186550 50.02972
13.80033 28.11430 -1.187274 49.79392
13.85033 28.21386 -1.188079 50.06519
13.90033 28.31351 -1.188935 49.94597
13.95034 28.41382 -1.189642 50.01259
14.00034 28.51344 -1.190318 50.02666
14.05033 28.61264 -1.191004 49.90869
14.10033 28.71463 -1.191747 50.01018
14.15033 28.81262 -1.192444 49.93799
14.20034 28.91202 -1.193099 49.86670
14.25034 29.01244 -1.193680 49.89794
14.30033 29.11204 -1.194066 49.92717
14.35033 29.21268 -1.194579 50.04746
14.40033 29.31208 -1.195298 50.24342
14.45034 29.41200 -1.195957 50.13230
14.50034 29.51215 -1.196732 50.07483
14.55033 29.61182 -1.197460 50.03696
14.60033 29.71223 -1.198194 50.10993
14.65033 29.81164 -1.198997 50.01712
14.70034 29.91110 -1.199853 50.09160
14.75034 30.01222 -1.200553 49.95200
14.80033 30.11151 -1.201496 49.90724
14.85033 30.21143 -1.202210 50.02384
14.90033 30.31107 -1.203088 50.16602
14.95034 30.41130 -1.203786 50.01562
15.00034 30.51062 -1.204662 50.18757
15.05033 30.61075 -1.205513 50.01964
15.10033 30.71116 -1.206588 50.03100
15.15033 30.81059 -1.207546 50.08440
15.20034 30.91103 -1.208618 50.10727
15.25034 31.01032 -1.209517 49.89785
15.30033 31.10999 -1.210563 49.91860
15.35033 31.20857 -1.211786 49.85190
15.40033 31.30928 -1.212994 50.03146
15.45034 31.40957 -1.214336 50.05220
15.50034 31.50859 -1.215886 49.89340
15.55033 31.60902 -1.217587 49.80533
15.60033 31.70880 -1.219738 49.83280
15.65033 31.80894 -1.222378 50.10163
15.70034 31.90769 -1.225283 50.12450
15.75034 32.00760 -1.228910 50.20722
15.80033 32.10682 -1.233140 49.94176
15.85033 32.20660 -1.238052 49.99092
15.90033 32.30628 -1.243691 50.03933
15.95034 32.40506 -1.250245 49.91262
16.00033 32.50400 -1.258079 50.03679
16.05033 32.60352 -1.268917 50.09900
16.10033 32.70236 -1.286482 50.06613
16.15033 32.80161 -1.314312 50.00952
16.20033 32.89816 -1.348315 49.92762
16.25033 32.99594 -1.387170 49.98244
16.30033 33.09244 -1.430359 50.10498
16.35033 33.18881 -1.474315 49.84648
16.40033 33.28510 -1.522247 49.97554
16.45033 33.38152 -1.571525 49.93828
16.50033 33.47774 -1.622363 49.88526
16.55033 33.57444 -1.669632 50.13754
16.60033 33.66968 -1.712474 49.98507
16.65033 33.76626 -1.757352 50.03035
16.70033 33.86286 -1.797704 49.89277
16.75033 33.95950 -1.832279 50.15432
16.80033 34.05637 -1.866046 49.95337
16.85033 34.15378 -1.895399 50.12870
16.90033 34.25172 -1.925869 50.05930
16.95033 34.34838 -1.953518 49.88850
17.00033 34.44685 -1.978956 49.88187
17.05033 34.54468 -2.004594 50.08758
17.10033 34.64268 -2.030906 49.97070
17.15033 34.74090 -2.051072 49.94797
17.20033 34.83824 -2.073317 49.72580
17.25033 34.93636 -2.093144 50.01191
17.30033 35.03545 -2.110166 50.14954
17.35033 35.13369 -2.125921 49.91616
17.40033 35.23254 -2.138830 50.01074
17.45033 35.33130 -2.150154 49.82979
17.50033 35.42985 -2.159403 49.88515
17.55033 35.52806 -2.169033 49.97660
17.60033 35.62893 -2.177406 49.93510
17.65033 35.72776 -2.185098 49.88952
17.70033 35.82696 -2.192440 50.17390
17.75033 35.92668 -2.199046 49.94398
17.80033 36.02630 -2.205679 49.90243
17.85033 36.12525 -2.213567 49.87828
17.90033 36.22356 -2.225771 49.95898
17.95033 36.32278 -2.247853 50.05292
18.00033 36.42122 -2.276902 50.08894
18.05033 36.51898 -2.308548 49.92195
18.10033 36.61668 -2.339064 50.00739
18.15033 36.71411 -2.370390 50.12370
18.20033 36.81244 -2.399394 49.94379
18.25033 36.91057 -2.424994 49.94348
18.30033 37.00899 -2.450061 49.99078
18.35033 37.10641 -2.470025 49.94544
18.40033 37.20456 -2.490756 49.92169
18.45033 37.30240 -2.509262 50.05176
18.50033 37.40063 -2.528502 50.08856
18.55033 37.49996 -2.543935 50.09446
18.60033 37.59740 -2.558432 49.94425
18.65033 37.69610 -2.574422 50.02478
18.70033 37.79447 -2.588940 49.86479
18.75033 37.89410 -2.599521 50.06262
18.80033 37.99350 -2.610771 50.08210
18.85033 38.09200 -2.620706 49.93328
18.90033 38.19116 -2.630064 49.96484
18.95033 38.28980 -2.638842 49.77052
19.00033 38.38984 -2.646604 49.82410
19.05033 38.48904 -2.652914 49.97162
19.10033 38.59009 -2.657514 49.93084
19.15033 38.69023 -2.659876 49.92171
19.20033 38.79170 -2.657769 50.01019
19.25033 38.89212 -2.637680 50.04644
19.30033 38.99483 -2.582128 50.12014
19.35033 39.09833 -2.494306 50.14672
19.40033 39.20469 -2.382242 49.97207
19.45033 39.31287 -2.255916 50.00034
19.50033 39.42348 -2.122874 49.90088
19.55033 39.53396 -2.001239 50.12700
19.60033 39.64270 -1.893587 50.04275
19.65033 39.75195 -1.796465 49.87413
19.70033 39.86017 -1.718137 49.91370
19.75033 39.96705 -1.647258 49.89672
19.80033 40.07169 -1.590389 49.94476
19.85033 40.17770 -1.538919 50.15078
19.90033 40.28162 -1.496907 49.91821
19.95033 40.38538 -1.464027 49.97758
20.00033 40.48738 -1.435734 49.93897
20.05033 40.59050 -1.413243 49.97244
20.10033 40.69211 -1.397126 50.15574
20.15033 40.79450 -1.384244 50.00834
20.20033 40.89504 -1.373329 49.90131
20.25033 40.99676 -1.364877 50.08768
20.30033 41.09761 -1.357223 50.04842
20.35033 41.19893 -1.349687 50.03723
20.40033 41.29883 -1.342267 50.04070
20.45033 41.40033 -1.335305 49.83438
20.50033 41.50007 -1.328740 50.01930
20.55033 41.60025 -1.322961 49.90830
20.60033 41.70098 -1.317688 50.11022
20.65033 41.80019 -1.313124 50.07014
20.70033 41.90098 -1.309163 49.92074
20.75033 42.00118 -1.305746 49.91980
20.80033 42.10126 -1.303032 50.08559
20.85033 42.20094 -1.300548 49.90574
20.90033 42.30183 -1.298702 50.09086
20.95033 42.40094 -1.297021 49.98500
21.00033 42.50089 -1.295670 50.10440
21.05033 42.60122 -1.294713 50.07521
21.10033 42.70096 -1.293910 50.08521
21.15033 42.80160 -1.293422 49.93676
21.20033 42.90066 -1.293046 50.04736
21.25033 43.00104 -1.292869 49.98332
21.30033 43.10020 -1.292806 49.93734
21.35033 43.20060 -1.292862 50.08647
21.40033 43.30048 -1.293160 49.93658
21.45033 43.40062 -1.293356 49.93056
21.50033 43.49998 -1.293588 50.08383
21.55033 43.59914 -1.293864 50.02985
21.60033 43.69869 -1.294014 49.98302
21.65033 43.79902 -1.294563 49.96124
21.70033 43.89954 -1.295090 50.14782
21.75033 43.99781 -1.295624 49.88800
21.80033 44.09900 -1.296360 49.99371
21.85033 44.19820 -1.297083 49.87254
21.90033 44.29834 -1.298131 49.86738
21.95033 44.39858 -1.299280 49.94372
22.00033 44.49877 -1.300391 50.04223
22.05033 44.59850 -1.301631 49.96284
22.10033 44.69894 -1.302721 49.93312
22.15033 44.79784 -1.303832 50.08359
22.20033 44.89876 -1.304880 50.06108
22.25033 44.99722 -1.306171 50.14168
22.30033 45.09840 -1.307198 50.12766
22.35033 45.19819 -1.308286 49.97224
22.40033 45.29854 -1.309245 50.00888
22.45033 45.39830 -1.310170 49.96291
22.50033 45.49806 -1.311255 50.02961
22.55033 45.59786 -1.312184 49.94516
22.60033 45.69771 -1.313108 49.91114
22.65033 45.79797 -1.314037 49.92594
22.70033 45.89812 -1.315186 50.00626
22.75033 45.99728 -1.316262 49.79354
22.80033 46.09606 -1.317254 50.00461
22.85033 46.19703 -1.318280 50.17710
22.90033 46.29727 -1.319284 49.81244
22.95033 46.39556 -1.320056 49.96014
23.00033 46.49554 -1.320900 49.91916
23.05033 46.59558 -1.321658 49.92852
23.10033 46.69524 -1.322501 49.99953
23.15033 46.79586 -1.323344 49.99164
23.20033 46.89531 -1.324174 49.99130
23.25033 46.99522 -1.325275 50.05316
23.30033 47.09570 -1.326434 50.07166
23.35033 47.19542 -1.327490 49.88167
23.40033 47.29536 -1.328891 50.09214
23.45033 47.39478 -1.330150 50.04448
23.50033 47.49512 -1.331345 50.16303
23.55033 47.59422 -1.332627 49.85900
23.60033 47.69484 -1.333782 50.02011
23.65033 47.79519 -1.335090 49.97070
23.70033 47.89509 -1.336380 49.93725
23.75033 47.99463 -1.337501 49.95402
23.80033 48.09468 -1.338850 49.84454
23.85033 48.19472 -1.339764 49.61430
23.90033 48.29461 -1.340976 49.99440
23.95033 48.39408 -1.342125 49.95426
24.00033 48.49441 -1.343128 50.08359
24.05033 48.59409 -1.344272 50.00920
24.10033 48.69283 -1.345178 50.07297
24.15033 48.79425 -1.346078 49.92070
24.20033 48.89424 -1.347047 50.00076
24.25033 48.99322 -1.347980 50.01947
24.30033 49.09293 -1.348700 50.07598
24.35033 49.19325 -1.349595 49.97160
24.40033 49.29364 -1.350542 49.95370
24.45033 49.39285 -1.351495 50.14626
24.50033 49.49312 -1.352661 49.98967
24.55033 49.59244 -1.353948 50.12152
24.60033 49.69190 -1.355038 50.22529
24.65033 49.79248 -1.356164 50.07412
24.70033 49.89136 -1.357210 50.00796
24.75033 49.99158 -1.358432 49.83490
24.80033 50.09162 -1.359691 50.00941
24.85033 50.19065 -1.360863 49.81569
24.90033 50.29094 -1.362193 50.02821
24.95033 50.39170 -1.363723 50.00180
25.00033 50.49004 -1.365257 49.97141
25.05033 50.59085 -1.366547 50.08950
25.10033 50.69144 -1.367994 49.91379
25.15033 50.79013 -1.369436 49.96896
25.20033 50.89096 -1.370970 49.96604
25.25033 50.99047 -1.372428 50.06797
25.30033 51.09140 -1.373881 50.00552
25.35033 51.18970 -1.375152 50.03997
25.40033 51.28992 -1.376553 50.07522
25.45033 51.39049 -1.377983 49.93439
25.50033 51.49106 -1.379313 49.89537
25.55033 51.58972 -1.380746 49.90244
25.60033 51.69002 -1.382059 49.99968
25.65033 51.78854 -1.383344 50.19454
25.70033 51.88984 -1.384721 50.02527
25.75033 51.98947 -1.386369 50.02817
25.80033 52.08878 -1.387949 49.94467
25.85033 52.18956 -1.389501 49.85686
25.90033 52.28848 -1.390916 49.98968
25.95033 52.38860 -1.392408 50.09548
26.00033 52.48886 -1.393691 50.08600
26.05033 52.58887 -1.395128 49.82070
26.10033 52.68821 -1.396377 49.88688
26.15033 52.78785 -1.397862 49.87458
26.20033 52.88728 -1.399284 49.98413
26.25033 52.98741 -1.400695 50.03953
26.30033 53.08834 -1.402292 49.92632
26.35033 53.18802 -1.403891 49.99656
26.40033 53.28809 -1.405566 50.05000
26.45033 53.38724 -1.407128 50.10219
26.50033 53.48682 -1.408522 49.94368
26.55033 53.58734 -1.410112 50.19078
26.60033 53.68712 -1.411617 49.99068
26.65033 53.78707 -1.413098 50.05165
26.70033 53.88632 -1.414419 50.03965
26.75033 53.98649 -1.415928 50.08338
26.80033 54.08690 -1.417588 49.96463
26.85033 54.18616 -1.418920 49.75098
26.90033 54.28726 -1.420389 49.95080
26.95033 54.38535 -1.421931 49.86850
27.00033 54.48628 -1.423332 50.12300
27.05033 54.58585 -1.424670 49.95358
27.10033 54.68622 -1.426109 50.13698
27.15033 54.78555 -1.427470 49.99156
27.20033 54.88461 -1.428940 50.10588
27.25033 54.98582 -1.430625 50.13556
27.30033 55.08572 -1.432314 50.03288
27.35033 55.18495 -1.433974 50.13870
27.40033 55.28552 -1.435605 50.05093
27.45033 55.38414 -1.437163 50.08011
27.50033 55.48329 -1.438511 50.03262
27.55033 55.58340 -1.439872 50.12717
27.60033 55.68256 -1.441352 49.97004
27.65033 55.78284 -1.442699 49.98537
27.70033 55.88228 -1.444244 50.08656
27.75033 55.98180 -1.445846 49.95092
27.80033 56.08237 -1.447394 50.00434
27.85033 56.18261 -1.449024 49.87844
27.90033 56.28150 -1.450758 49.92218
27.95033 56.38169 -1.452540 49.93468
28.00033 56.48168 -1.454531 50.01683
28.05033 56.58218 -1.456400 49.87832
28.10033 56.68208 -1.458176 50.09324
28.15033 56.78257 -1.459841 50.03906
28.20033 56.88160 -1.461351 49.98152
28.25033 56.98072 -1.463102 50.02430
28.30033 57.08118 -1.465044 50.04898
28.35033 57.18070 -1.467200 49.88116
28.40033 57.28066 -1.469214 50.01990
28.45033 57.38051 -1.471087 50.03309
28.50033 57.48155 -1.472923 49.86003
28.55033 57.58080 -1.474872 50.08039
28.60033 57.68018 -1.476749 49.97346
28.65033 57.78090 -1.478523 50.12350
28.70033 57.87964 -1.480461 50.03664
28.75033 57.97907 -1.482246 50.14606
28.80033 58.07964 -1.484058 49.83458
28.85033 58.17950 -1.485931 50.07187
28.90033 58.28039 -1.487516 50.08318
28.95033 58.37838 -1.489337 50.00533
29.00033 58.47800 -1.491221 50.04731
29.05033 58.57951 -1.492915 49.97456
29.10033 58.67842 -1.494661 50.05802
29.15033 58.77839 -1.496498 49.86558
29.20033 58.87760 -1.498430 50.07510
29.25033 58.97754 -1.500108 49.94936
29.30033 59.07786 -1.501576 50.07194
29.35033 59.17687 -1.503310 49.91777
29.40033 59.27660 -1.505038 50.06638
29.45033 59.37649 -1.506722 50.03436
29.50033 59.47613 -1.508430 49.85318
29.55033 59.57307 -1.510944 49.99906
29.60033 59.64326 -1.510960 49.97579
29.65033 59.68946 -1.441256 49.92334
29.70033 59.72594 -1.329343 50.05658
29.75033 59.75678 -1.220952 50.05697
29.80033 59.78190 -1.114339 50.21081
29.85033 59.80228 -1.009089 50.00324
29.90033 59.82057 -0.9189891 49.84859
29.95033 59.83672 -0.8327432 49.95354
30.00033 59.84949 -0.7614679 50.07516
30.05033 59.85955 -0.6961882 50.11072
30.10033 59.86899 -0.6410034 49.95640
30.15033 59.87754 -0.5923655 50.01215
30.20033 59.88320 -0.5521832 49.88855
30.25033 59.88969 -0.5182793 49.98628
30.30033 59.89352 -0.4895026 49.96000
30.35033 59.89922 -0.4642083 49.90070
30.40033 59.90274 -0.4442604 49.97123
30.45033 59.90710 -0.4289074 50.16353
30.50033 59.90912 -0.4153183 49.94254
30.55033 59.91126 -0.4045438 49.92950
30.60033 59.91436 -0.3946730 50.09574
30.65033 59.91596 -0.3847198 50.04330
30.70033 59.91864 -0.3762140 50.00681
30.75033 59.91882 -0.3679543 49.93662
30.80033 59.91993 -0.3598484 50.09616
30.85033 59.91988 -0.3519194 50.14580
30.90033 59.92170 -0.3444433 49.99460
30.95033 59.92329 -0.3373988 50.05142
31.00033 59.92365 -0.3311252 49.96494
31.05033 59.92452 -0.3255170 49.90192
31.10033 59.92553 -0.3204570 50.13292
31.15033 59.92644 -0.3158567 50.00435
31.20033 59.92722 -0.3119228 50.22429
31.25033 59.92782 -0.3081886 50.10301
31.30033 59.92816 -0.3048120 49.91641
31.35033 59.92922 -0.3018510 50.08696
31.40033 59.92918 -0.2992224 49.79842
31.45033 59.92914 -0.2968495 49.94185
31.50033 59.93098 -0.2948065 50.06838
31.55033 59.93018 -0.2929400 49.87674
31.60033 59.93094 -0.2911000 50.06908
31.65033 59.93150 -0.2893628 49.85102
31.70033 59.93111 -0.2878853 50.00091
31.75033 59.93200 -0.2865450 49.98919
31.80033 59.93180 -0.2851796 50.04273
31.85034 59.93238 -0.2838246 49.87938
31.90033 59.93262 -0.2826098 49.99570
31.95033 59.93268 -0.2813342 49.99139
32.00033 59.93356 -0.2801914 50.01588
32.05033 59.93270 -0.2793041 49.99320
32.10034 59.93278 -0.2782736 50.10966
32.15033 59.93320 -0.2774076 50.01338
32.20033 59.93226 -0.2766122 49.93752
32.25033 59.93262 -0.2758479 49.97382
32.30033 59.93201 -0.2750930 49.92310
32.35034 59.93226 -0.2744250 49.88336
32.40033 59.93272 -0.2739278 49.83746
32.45033 59.93310 -0.2735900 50.06162
-2.000000 1.000000 0.0000000 0.0000000
32.54700 59.93062 -0.2738817 49.98507
32.59700 59.90208 -0.2720504 49.94261
32.64700 59.84931 -0.1901454 49.93262
32.69700 59.78516 -.07383015 50.00512
32.74700 59.71509 0.03646245 49.86617
32.79700 59.63946 0.1495601 50.07789
32.84700 59.56036 0.2530281 50.07940
32.89700 59.47646 0.3522315 49.89238
32.94700 59.39146 0.4370190 50.02568
32.99700 59.30352 0.5162556 49.77310
33.04700 59.21442 0.5812761 49.90734
33.09700 59.12332 0.6394800 50.03820
33.14700 59.03059 0.6884494 50.02432
33.19700 58.93784 0.7333338 50.10790
33.24700 58.84290 0.7669837 49.97161
33.29700 58.74914 0.7994432 49.92178
33.34700 58.65291 0.8243163 50.00254
33.39700 58.55703 0.8462457 50.13281
33.44700 58.45944 0.8638556 49.91110
33.49700 58.36216 0.8786486 49.85389
33.54700 58.26480 0.8909425 49.96795
33.59700 58.16657 0.9030816 49.99619
33.64700 58.06950 0.9122918 49.81376
33.69700 57.97049 0.9211386 50.16912
33.74700 57.87164 0.9304462 49.76898
33.79700 57.77349 0.9392163 50.16020
33.84700 57.67398 0.9478692 49.98584
33.89700 57.57576 0.9562359 49.92916
33.94700 57.47700 0.9641072 49.92538
33.99700 57.37805 0.9714452 50.02850
34.04700 57.27916 0.9783303 50.04594
34.09700 57.17990 0.9847187 50.06939
34.14700 57.08155 0.9906109 49.94478
34.19700 56.98209 0.9961566 50.06402
34.24700 56.88274 1.001302 49.88992
34.29700 56.78316 1.006058 49.94474
34.34700 56.68401 1.010663 49.98378
34.39700 56.58443 1.014959 49.94360
34.44700 56.48477 1.019167 50.04794
34.49700 56.38618 1.023161 50.02946
34.54700 56.28680 1.026745 49.96113
34.59700 56.18645 1.030418 49.93992
34.64700 56.08691 1.033898 49.91180
34.69700 55.98821 1.037315 49.96930
34.74700 55.88785 1.040606 49.87418
34.79700 55.78857 1.043736 49.85266
34.84700 55.68924 1.046773 50.11570
34.89700 55.58862 1.049661 49.98868
34.94700 55.48976 1.052422 49.93154
34.99700 55.39076 1.055166 50.01357
35.04700 55.29102 1.057756 50.12133
35.09700 55.19140 1.060328 49.93289
35.14700 55.09150 1.062820 50.17045
35.19700 54.99164 1.065205 50.13540
35.24700 54.89290 1.067400 50.08469
35.29700 54.79238 1.069516 50.16972
35.34700 54.69312 1.071812 49.96810
35.39700 54.59250 1.073931 50.12146
35.44700 54.49418 1.076060 49.97685
35.49700 54.39373 1.078066 49.96879
35.54700 54.29390 1.080055 49.94281
35.59700 54.19436 1.082111 50.00025
35.64700 54.09557 1.084093 50.13197
35.69700 53.99444 1.086086 49.97969
35.74700 53.89502 1.088291 50.02516
35.79700 53.79529 1.090446 49.86616
35.84700 53.69491 1.092590 49.75650
35.89700 53.59590 1.094551 50.15912
35.94700 53.49536 1.096546 50.05566
35.99700 53.39633 1.098341 50.17257
36.04700 53.29690 1.100055 50.03461
36.09700 53.19718 1.101573 50.06266
36.14700 53.09776 1.103238 50.09226
36.19700 52.99729 1.104715 50.09856
36.24700 52.89756 1.106301 49.95829
36.29700 52.79782 1.107810 49.83478
36.34700 52.69756 1.109425 50.09444
36.39700 52.59848 1.110973 50.18522
36.44700 52.49824 1.112526 50.13472
36.49700 52.39778 1.114016 49.89818
36.54700 52.29926 1.115597 49.99278
36.59700 52.19856 1.117070 49.95966
36.64700 52.09892 1.118560 49.31500
36.69700 52.00010 1.120065 50.01186
36.74700 51.89997 1.121514 49.94978
36.79700 51.80027 1.122932 50.09394
36.84700 51.70020 1.124585 50.10567
36.89700 51.60068 1.126036 50.01760
36.94700 51.50094 1.127604 49.89023
36.99700 51.40117 1.129253 50.21200
37.04700 51.30060 1.130918 49.92537
37.09700 51.20181 1.132286 50.01690
37.14700 51.10194 1.133841 49.99914
37.19700 51.00156 1.135422 50.05250
37.24700 50.90141 1.136860 50.08080
37.29700 50.80216 1.138492 49.97045
37.34700 50.70201 1.139886 49.96644
37.39700 50.60228 1.141557 49.91687
37.44700 50.50266 1.142998 49.94004
37.49700 50.40248 1.144310 50.19741
37.54700 50.30242 1.145732 50.04419
37.59700 50.20346 1.147113 50.10075
37.64700 50.10231 1.148326 49.79162
37.69700 50.00288 1.149604 49.80465
37.74700 49.90324 1.150784 49.92560
37.79700 49.80437 1.151881 50.05824
37.84700 49.70498 1.153103 50.11188
37.89700 49.60450 1.154382 50.07124
37.94700 49.50562 1.155813 49.96317
37.99700 49.40519 1.157107 50.24512
38.04700 49.30537 1.158427 49.88910
38.09700 49.20522 1.159911 50.01282
38.14700 49.10526 1.161269 50.26391
38.19700 49.00546 1.162598 50.00828
38.24700 48.90582 1.163972 50.00430
38.29700 48.80638 1.165368 49.93408
38.34700 48.70684 1.166589 49.91174
38.39700 48.60576 1.168001 49.98566
38.44700 48.50613 1.169264 50.13700
38.49700 48.40735 1.170716 50.00775
38.54700 48.30642 1.172100 50.14824
38.59700 48.20766 1.173508 49.85527
38.64700 48.10769 1.174930 49.86011
38.69700 48.00761 1.176181 50.06906
38.74700 47.90666 1.177478 49.90253
38.79700 47.80722 1.178562 50.14407
38.84700 47.70777 1.179762 50.00868
38.89700 47.60754 1.180994 50.11722
38.94700 47.50774 1.182245 49.86902
38.99700 47.40803 1.183418 49.89606
39.04700 47.30925 1.184705 49.99124
39.09700 47.20790 1.186104 50.11040
39.14700 47.10862 1.187378 50.02407
39.19700 47.00843 1.188460 49.84238
39.24700 46.90866 1.189660 50.04085
39.29700 46.80968 1.190799 49.90493
39.34700 46.71010 1.191982 49.95554
39.39700 46.60966 1.193080 49.82156
39.44700 46.51004 1.194035 49.87550
39.49700 46.41009 1.195263 49.88260
39.54700 46.31054 1.196384 49.86497
39.59700 46.21060 1.197461 49.94760
39.64700 46.11074 1.198382 50.23466
39.69700 46.01008 1.199423 49.95072
39.74700 45.91098 1.200534 49.80090
39.79700 45.81239 1.201709 50.05004
39.84700 45.71111 1.202872 49.95970
39.89700 45.61158 1.204015 50.01754
39.94700 45.51144 1.205179 49.93832
39.99700 45.41212 1.206348 49.90994
40.04700 45.31186 1.207310 50.01059
40.09700 45.21222 1.208270 49.99550
40.14700 45.11194 1.209217 50.06430
40.19700 45.01324 1.210065 50.16590
40.24700 44.91204 1.211176 49.84476
40.29700 44.81152 1.212148 49.95409
40.34700 44.71236 1.213132 49.91430
40.39700 44.61326 1.214301 49.70750
40.44700 44.51314 1.215369 49.97809
40.49700 44.41328 1.216406 50.09168
40.54700 44.31358 1.217480 50.05815
40.59700 44.21331 1.218462 49.88210
40.64700 44.11320 1.219441 50.14538
40.69700 44.01387 1.220762 50.02334
40.74700 43.91287 1.222034 50.07904
40.79700 43.81309 1.223321 50.02430
40.84700 43.71289 1.224486 49.85386
40.89700 43.61391 1.225556 49.99346
40.94700 43.51426 1.226640 50.11622
40.99700 43.41434 1.227714 49.98096
41.04700 43.31457 1.228702 49.97228
41.09700 43.21384 1.229477 50.05806
41.14700 43.11458 1.230026 49.79770
41.19700 43.01474 1.230703 49.97154
41.24700 42.91475 1.231470 49.91470
41.29700 42.81488 1.232132 50.10168
41.34700 42.71518 1.232701 50.07316
41.39700 42.61503 1.233495 50.05188
41.44700 42.51630 1.234230 49.96943
41.49700 42.41490 1.235003 49.64516
41.54700 42.31524 1.235880 50.04035
41.59700 42.21536 1.236908 49.85936
41.64700 42.11610 1.237870 49.93772
41.69700 42.01542 1.238917 49.35942
41.74700 41.91629 1.239901 50.01921
41.79700 41.81574 1.240754 49.93484
41.84700 41.71669 1.241549 50.02676
41.89700 41.61629 1.242262 50.10654
41.94700 41.51643 1.243134 49.43778
41.99700 41.41713 1.243799 49.96402
42.04700 41.31633 1.244549 49.99414
42.09700 41.21674 1.245249 50.05313
42.14700 41.11691 1.245932 50.02740
42.19700 41.01699 1.246442 50.04769
42.24700 40.91788 1.247044 50.07970
42.29700 40.81685 1.247507 50.06982
42.34700 40.71783 1.248160 50.04478
42.39700 40.61838 1.248766 50.02622
42.44700 40.51765 1.249461 49.31854
42.49700 40.41782 1.250129 50.02530
42.54700 40.31759 1.250875 50.04586
42.59700 40.21835 1.251611 50.01540
42.64700 40.11882 1.252425 50.07309
42.69700 40.01750 1.253153 49.89266
42.74700 39.91938 1.253990 49.82894
42.79700 39.81937 1.254839 50.06304
42.84700 39.71922 1.255716 50.11759
42.89700 39.61862 1.256725 50.09543
42.94700 39.51853 1.257761 50.14344
42.99700 39.41840 1.258733 50.11865
43.04700 39.31918 1.259539 50.05180
43.09700 39.21904 1.260379 49.96084
43.14700 39.11875 1.261098 50.07916
43.19700 39.01950 1.261766 49.95514
43.24700 38.91976 1.262339 50.24922
43.29700 38.82000 1.262922 50.10123
43.34700 38.71966 1.263386 50.00873
43.39700 38.61943 1.263797 50.02182
43.44700 38.52075 1.264355 50.67506
43.49700 38.42113 1.264859 50.16134
43.54700 38.32124 1.265337 50.03713
43.59700 38.22091 1.265935 50.12946
43.64700 38.12084 1.266577 50.07632
43.69700 38.02084 1.267245 50.12674
43.74700 37.92132 1.267927 49.80410
43.79700 37.82106 1.268724 50.03713
43.84700 37.72188 1.269470 49.86300
43.89700 37.62160 1.270162 50.09101
43.94700 37.52216 1.270865 50.04463
43.99700 37.42146 1.271582 49.92541
44.04700 37.32190 1.272291 50.03364
44.09700 37.22280 1.273045 50.20491
44.14700 37.12301 1.273717 49.98754
44.19700 37.02280 1.274346 49.99157
44.24700 36.92186 1.274993 49.94698
44.29700 36.82334 1.275768 50.06680
44.34700 36.72210 1.276622 50.02914
44.39700 36.62176 1.277533 49.98600
44.44700 36.52308 1.278549 50.00457
44.49700 36.42198 1.279272 50.14026
44.54700 36.32225 1.280259 49.91182
44.59700 36.22244 1.280904 50.06854
44.64700 36.12276 1.281616 50.02472
44.69700 36.02262 1.282078 49.98550
44.74700 35.92224 1.282624 50.20260
44.79700 35.82334 1.283285 50.05123
44.84700 35.72361 1.283805 50.03496
44.89700 35.62359 1.284334 49.92017
44.94700 35.52387 1.284918 50.00842
44.99700 35.42432 1.285450 49.95224
45.04700 35.32414 1.286098 50.00646
45.09700 35.22467 1.286772 50.01362
45.14700 35.12463 1.287378 50.11424
45.19700 35.02500 1.287851 50.08403
45.24700 34.92471 1.288457 50.16883
45.29700 34.82539 1.289066 50.01662
45.34700 34.72532 1.289555 50.05258
45.39700 34.62503 1.290037 50.04600
45.44700 34.52518 1.290500 49.94912
45.49700 34.42666 1.291014 50.17153
45.54700 34.32630 1.291510 49.94466
45.59700 34.22537 1.292040 50.18762
45.64700 34.12614 1.292642 50.05774
45.69700 34.02716 1.293279 49.82614
45.74700 33.92659 1.293859 49.83810
45.79700 33.82656 1.294490 50.03063
45.84700 33.72714 1.295148 49.94150
45.89700 33.62678 1.295803 49.97329
45.94700 33.52612 1.296575 50.02520
45.99700 33.42636 1.297427 50.05297
46.04700 33.32583 1.298290 50.21347
46.09700 33.22643 1.299097 50.02115
46.14700 33.12606 1.299989 50.03439
46.19700 33.02542 1.301007 49.97920
46.24700 32.92694 1.302139 49.99223
46.29700 32.82681 1.303547 50.05724
46.34700 32.72793 1.305748 49.78504
46.39700 32.62806 1.309159 50.12640
46.44700 32.52908 1.316758 49.97502
46.49700 32.43013 1.342020 50.06866
46.54700 32.33407 1.401106 50.02165
46.59700 32.23915 1.484698 49.91094
46.64700 32.14440 1.594028 50.07834
46.69700 32.05427 1.741682 50.03384
46.74700 31.96613 1.929244 49.98156
46.79700 31.88108 2.159449 49.95442
46.84700 31.80094 2.435286 50.21375
46.89700 31.72328 2.751579 49.95597
46.94700 31.64917 3.100386 49.84622
46.99700 31.57782 3.460716 49.92358
47.04700 31.50674 3.816083 49.91640
47.09700 31.43452 4.133408 49.98347
47.14700 31.35947 4.396300 49.96160
47.19700 31.28032 4.592278 50.09748
47.24700 31.19562 4.711684 49.95715
47.29700 31.10448 4.758544 49.90238
47.34700 31.00967 4.754668 50.06075
47.39700 30.90833 4.707136 50.15670
47.44700 30.80406 4.590528 50.08941
47.49700 30.69546 4.455736 49.89834
47.54700 30.58477 4.295520 49.98278
47.59700 30.47220 4.120375 49.84662
47.64700 30.35816 3.926475 49.97034
47.69700 30.24192 3.726454 50.18454
47.74700 30.12584 3.520218 49.96642
47.79700 30.00930 3.314280 49.97200
47.84700 29.89267 3.116248 49.99928
47.89700 29.77641 2.930000 50.03266
47.94700 29.66113 2.751500 50.12666
47.99700 29.54585 2.579605 50.11860
48.04700 29.43204 2.416103 49.85348
48.09700 29.31848 2.261787 49.94928
48.14700 29.20584 2.123039 49.96910
48.19700 29.09494 2.002711 49.94851
48.24700 28.98520 1.893596 49.84078
48.29700 28.87743 1.803561 49.96109
48.34700 28.77033 1.729322 50.09158
48.39700 28.66406 1.668031 50.15915
48.44700 28.55838 1.615360 49.97384
48.49700 28.45419 1.571210 49.99292
48.54700 28.34987 1.535342 50.08891
48.59700 28.24723 1.508253 50.40017
48.64700 28.14537 1.483738 50.03854
48.69700 28.04284 1.464300 49.93416
48.74700 27.94130 1.448017 50.05981
48.79700 27.83945 1.435178 49.84208
48.84700 27.73926 1.425346 49.97720
48.89700 27.63775 1.417350 50.09233
48.94700 27.53727 1.409358 50.60385
48.99700 27.43650 1.401374 50.01564
49.04700 27.33428 1.393434 49.94854
49.09700 27.23517 1.386180 50.00709
49.14700 27.13346 1.379264 49.76992
49.19700 27.03410 1.372780 49.87719
49.24700 26.93416 1.366921 49.91089
49.29700 26.83344 1.361601 50.13380
49.34700 26.73308 1.356966 50.19882
49.39700 26.63150 1.352698 50.02898
49.44700 26.53220 1.349074 50.13719
49.49700 26.43189 1.345940 49.86547
49.54700 26.33162 1.343100 50.19740
49.59700 26.23159 1.340612 49.93822
49.64700 26.13205 1.338196 49.96476
49.69700 26.03205 1.336088 49.97620
49.74700 25.93192 1.334181 49.99840
49.79700 25.83176 1.332579 49.98686
49.84700 25.73180 1.331155 49.81856
49.89700 25.63084 1.329767 50.04398
49.94700 25.53195 1.328650 50.17802
49.99700 25.43284 1.327824 49.98657
50.04700 25.33210 1.326928 49.90552
50.09700 25.23233 1.326077 49.83196
50.14700 25.13276 1.325342 49.85385
50.19700 25.03318 1.324757 50.09649
50.24700 24.93358 1.324219 50.01545
50.29700 24.83410 1.323741 50.12130
50.34700 24.73366 1.323397 50.08226
50.39700 24.63463 1.323224 50.00541
50.44700 24.53403 1.323034 49.98276
50.49700 24.43364 1.323064 50.06994
50.54700 24.33398 1.323124 50.02490
50.59700 24.23492 1.323336 50.15806
50.64700 24.13380 1.323426 49.90637
50.69700 24.03421 1.323480 49.80359
50.74700 23.93442 1.323716 49.98769
50.79700 23.83479 1.324008 49.96198
50.84700 23.73370 1.324304 50.02034
50.89700 23.63391 1.324710 49.99191
50.94700 23.53340 1.325144 49.85988
50.99700 23.43410 1.325369 49.97270
51.04700 23.33345 1.325638 49.91058
51.09700 23.23250 1.325690 49.92976
51.14700 23.13353 1.325666 50.11678
51.19700 23.03375 1.325637 49.81170
51.24700 22.93318 1.325428 50.02988
51.29700 22.83382 1.325330 50.07646
51.34700 22.73342 1.325099 49.93646
51.39700 22.63306 1.324929 50.05697
51.44700 22.53315 1.324907 50.08948
51.49700 22.43369 1.324777 49.94209
51.54700 22.33354 1.324922 49.85422
51.59700 22.23250 1.324960 50.15111
51.64700 22.13402 1.324929 50.09461
51.69700 22.03358 1.324898 49.96023
51.74700 21.93351 1.324904 50.07434
51.79700 21.83362 1.324858 50.14519
51.84700 21.73433 1.324826 50.09668
51.89700 21.63386 1.324791 49.83804
51.94700 21.53380 1.324742 49.82647
51.99700 21.43433 1.324716 50.04955
52.04700 21.33520 1.324755 50.03472
52.09700 21.23464 1.324848 50.09788
52.14700 21.13482 1.324829 49.88636
52.19700 21.03459 1.324964 49.88562
52.24700 20.93414 1.325220 50.07430
52.29700 20.83487 1.325514 50.32066
52.34700 20.73536 1.325667 50.26187
52.39700 20.63426 1.325909 49.94557
52.44700 20.53487 1.326016 50.02734
52.49700 20.43484 1.326152 49.94244
52.54700 20.33560 1.326254 49.95648
52.59700 20.23450 1.326459 49.85295
52.64700 20.13582 1.326466 50.10193
52.69700 20.03512 1.326382 49.89188
52.74700 19.93570 1.326460 50.13920
52.79700 19.83534 1.326512 50.11538
52.84700 19.73576 1.326461 50.00540
52.89700 19.63449 1.326603 50.13940
52.94700 19.53569 1.326523 50.06332
52.99700 19.43580 1.326393 50.01708
53.04700 19.33478 1.326285 49.93886
53.09700 19.23572 1.326176 50.32066
53.14700 19.13579 1.326056 50.09750
53.19700 19.03563 1.325887 50.22810
53.24700 18.93509 1.325914 49.77587
53.29700 18.83496 1.325990 50.04219
53.34700 18.73579 1.326202 49.87243
53.39700 18.63526 1.326241 50.02312
53.44700 18.53545 1.326360 49.91134
53.49700 18.43574 1.326506 49.92060
53.54700 18.33605 1.326603 50.06476
53.59700 18.23527 1.326806 50.11425
53.64700 18.13588 1.326732 49.95450
53.69700 18.03595 1.326830 49.92666
53.74700 17.93623 1.326822 49.86222
53.79700 17.83691 1.326780 50.05498
53.84700 17.73678 1.326666 50.12914
53.89700 17.63662 1.326673 49.89337
53.94700 17.53655 1.326622 49.93412
53.99700 17.43611 1.326644 50.00652
54.04700 17.33612 1.326549 49.96024
54.09700 17.23686 1.326743 50.00184
54.14700 17.13616 1.326962 50.00799
54.19700 17.03579 1.327175 49.98832
54.24700 16.93554 1.327351 49.93528
54.29700 16.83564 1.327406 50.10956
54.34700 16.73671 1.327568 50.17634
54.39700 16.63692 1.327539 49.35343
54.44700 16.53635 1.327549 50.07526
54.49700 16.43720 1.327542 49.20027
54.54700 16.33689 1.327452 49.90050
54.59700 16.23621 1.327412 50.04850
54.64700 16.13714 1.327396 50.00830
54.69700 16.03648 1.327396 49.89976
54.74700 15.93664 1.327714 49.86580
54.79700 15.83569 1.327815 49.95276
54.84700 15.73580 1.328254 50.00126
54.89700 15.63650 1.328489 49.99443
54.94700 15.53589 1.328583 49.98132
54.99700 15.43561 1.328779 50.04559
55.04700 15.33606 1.328892 50.00719
55.09700 15.23616 1.328821 50.02333
55.14700 15.13589 1.328733 50.00328
55.19700 15.03653 1.328547 49.92663
55.24700 14.93658 1.328452 50.10449
55.29700 14.83702 1.328357 49.93902
55.34700 14.73686 1.328176 50.02275
55.39700 14.63734 1.328121 50.01152
55.44700 14.53775 1.327865 49.95814
55.49700 14.43719 1.327736 49.86606
55.54700 14.33784 1.327650 49.81244
55.59700 14.23722 1.327524 50.11050
55.64700 14.13726 1.327266 50.03330
55.69700 14.03756 1.327079 49.99708
55.74700 13.93834 1.326943 49.99994
55.79700 13.83763 1.326825 50.11064
55.84700 13.73808 1.326914 50.07840
55.89700 13.63738 1.326881 50.11594
55.94700 13.53742 1.327014 49.91014
55.99700 13.43720 1.327246 49.80218
56.04700 13.33701 1.327440 50.03509
56.09700 13.23801 1.327514 49.86441
56.14700 13.13698 1.327751 49.94626
56.19700 13.03714 1.328084 49.90150
56.24700 12.93754 1.328328 50.10347
56.29700 12.83661 1.328566 49.92899
56.34700 12.73669 1.328791 50.10368
56.39700 12.63697 1.329003 49.95412
56.44700 12.53681 1.328926 50.12166
56.49700 12.43775 1.328844 50.02737
56.54700 12.33837 1.328710 49.90774
56.59700 12.23825 1.328600 49.78530
56.64700 12.13898 1.328293 49.84288
56.69700 12.03846 1.328092 49.91541
56.74700 11.93838 1.327882 50.05037
56.79700 11.83923 1.327786 50.00240
56.84700 11.73847 1.327717 49.99050
56.89700 11.63932 1.327620 49.84350
56.94700 11.53886 1.327640 49.92341
56.99700 11.43970 1.327600 49.99141
57.04700 11.33913 1.327563 50.14672
57.09700 11.23922 1.327453 50.11314
57.14700 11.13890 1.327500 49.88812
57.19700 11.03941 1.327594 49.98994
57.24700 10.93860 1.327487 50.05448
57.29700 10.83952 1.327302 50.05393
57.34700 10.73886 1.327291 50.06685
57.39700 10.63920 1.327401 50.09473
57.44700 10.53847 1.327638 49.85604
57.49700 10.43845 1.327901 49.95240
57.54700 10.33874 1.328056 49.94456
57.59700 10.23830 1.328119 50.08774
57.64700 10.13841 1.328108 49.88039
57.69700 10.03841 1.328035 50.22934
57.74700 9.938586 1.328018 50.09766
57.79700 9.838355 1.327992 49.88462
57.84700 9.738518 1.327866 50.06250
57.89700 9.638294 1.327656 50.07770
57.94700 9.538218 1.327459 49.92232
57.99700 9.439019 1.327316 49.99836
58.04700 9.338531 1.327227 50.04022
58.09700 9.239732 1.326947 49.84877
58.14700 9.139548 1.326735 49.99963
58.19700 9.040701 1.326447 49.97329
58.24700 8.939544 1.326328 50.01782
58.29700 8.839575 1.326337 49.83550
58.34700 8.739111 1.326337 50.09176
58.39700 8.639651 1.326196 49.95513
58.44700 8.539574 1.326107 49.98746
58.49700 8.440656 1.326051 50.00440
58.54700 8.340530 1.325984 50.08863
58.59700 8.240203 1.325897 50.03748
58.64700 8.140130 1.325849 49.93375
58.69700 8.038910 1.325657 49.95828
58.74700 7.940360 1.325664 50.11539
58.79700 7.841165 1.325664 50.12791
58.84700 7.739950 1.325580 49.87703
58.89700 7.640201 1.325512 49.97354
58.94700 7.540638 1.325477 50.15463
58.99700 7.440309 1.325460 50.10878
59.04700 7.340449 1.325521 49.85590
59.09700 7.240449 1.325533 49.97578
59.14700 7.141056 1.325671 49.87690
59.19700 7.039712 1.325646 49.97360
59.24700 6.939991 1.325724 49.94947
59.29700 6.840339 1.325622 50.05809
59.34700 6.740318 1.325801 50.08810
59.39700 6.640420 1.325813 50.07948
59.44700 6.539948 1.325750 50.06204
59.49700 6.439151 1.325711 49.84864
59.54700 6.339496 1.325538 49.91687
59.59700 6.239431 1.325529 49.97248
59.64700 6.139541 1.325369 49.96928
59.69700 6.039844 1.325170 49.95891
59.74700 5.940440 1.325035 50.10540
59.79700 5.841034 1.324928 50.01250
59.84700 5.739868 1.324713 49.92228
59.89700 5.639662 1.324396 50.13320
59.94700 5.540636 1.324290 49.98632
59.99700 5.440782 1.324034 49.90426
60.04700 5.341975 1.324042 49.79126
60.09700 5.240472 1.323897 49.95970
60.14700 5.140625 1.323921 49.88020
60.19700 5.040738 1.323882 50.02109
60.24700 4.941047 1.323921 50.00432
60.29700 4.840776 1.323950 49.91070
60.34700 4.741784 1.323764 50.09233
60.39700 4.641552 1.323734 49.95767
60.44700 4.541958 1.323649 50.13980
60.49700 4.440047 1.323360 50.02937
60.54700 4.342584 1.323220 49.84610
60.59700 4.240976 1.323154 50.10643
60.64700 4.141309 1.323215 50.03680
60.69700 4.041059 1.322976 50.07950
60.74700 3.942092 1.322986 49.90981
60.79700 3.841872 1.322926 49.96804
60.84700 3.741300 1.322787 50.09418
60.89700 3.641188 1.322733 50.01864
60.94700 3.542566 1.322756 49.85124
60.99700 3.442538 1.322669 50.12856
61.04700 3.341866 1.322677 49.94578
61.09700 3.242010 1.322802 50.08816
61.14700 3.142038 1.322705 49.88602
61.19700 3.041840 1.322649 50.18774
61.24700 2.941072 1.322680 49.91914
61.29700 2.842267 1.322682 50.01881
61.34700 2.741558 1.322635 50.75680
61.39700 2.641030 1.322660 49.96566
61.44700 2.542364 1.322709 50.11056
61.49700 2.441392 1.322647 49.87475
61.54700 2.342346 1.322636 49.94150
61.59700 2.242158 1.322634 50.13529
61.64700 2.141545 1.322714 50.12197
61.69700 2.041634 1.322480 49.93370
61.74700 1.942191 1.322390 49.95537
61.79700 1.842377 1.322069 50.08696
61.84700 1.741868 1.321902 50.16230
61.89700 1.641921 1.321886 50.12769
61.94700 1.542354 1.321853 50.00282
61.99700 1.442080 1.321714 49.81657
62.04700 1.346007 1.322093 50.02113
62.09700 1.274540 1.319338 49.99086
62.14700 1.228231 1.252814 49.93630
62.19700 1.192718 1.153564 49.98096
62.24700 1.164252 1.053109 49.89168
62.29700 1.141150 0.9505199 49.95343
62.34700 1.120717 0.8586476 49.99741
62.39700 1.104308 0.7710099 50.04300
62.44700 1.089083 0.6905571 50.00269
62.49700 1.077168 0.6199980 49.99510
62.54700 1.067825 0.5588960 50.12097
62.59700 1.058241 0.5051074 49.87330
62.64700 1.050031 0.4571015 50.08028
62.69700 1.044217 0.4179692 50.05224
62.74700 1.038768 0.3835024 50.13097
62.79700 1.034071 0.3530498 49.83388
62.84700 1.029628 0.3301722 50.08334
62.89700 1.026466 0.3119357 50.17828
62.94700 1.022558 0.2931745 50.10990
62.99700 1.019567 0.2807026 49.89587
63.04700 1.017361 0.2697828 50.13719
63.09700 1.015310 0.2602530 49.87090
63.14700 1.013618 0.2514736 49.99136
63.19700 1.010771 0.2431117 49.92189
63.24700 1.009104 0.2352000 50.06359
63.29700 1.007492 0.2275691 50.11890
63.34700 1.006436 0.2201332 49.89839
63.39700 1.006036 0.2132666 49.85644
63.44700 1.003997 0.2065571 49.91260
63.49700 1.004486 0.2003689 49.91922
63.54700 1.002950 0.1945330 50.02761
63.59700 1.001496 0.1891958 50.07300
63.64700 1.001064 0.1841229 49.98506
63.69700 1.000660 0.1796304 49.93074
63.74700 1.000163 0.1756268 49.95951
63.79700 0.9993082 0.1721098 49.97266
63.84700 0.9987335 0.1687917 50.02766
63.89700 0.9984009 0.1657088 49.95946
63.94700 0.9986563 0.1630493 49.96036
63.99700 0.9978455 0.1606735 49.84652
64.04700 0.9969876 0.1585598 49.88369
64.09700 0.9977616 0.1565434 50.05489
64.14700 0.9972452 0.1547965 49.76436
64.19701 0.9967608 0.1532913 49.97650
64.24700 0.9949456 0.1517670 50.03570
64.29700 0.9957362 0.1505894 49.89098
64.34700 0.9963566 0.1494968 49.83934
64.39700 0.9954626 0.1484018 49.82961
64.44701 0.9947858 0.1474002 50.14762
64.49700 0.9948465 0.1465104 49.92330
64.54700 0.9947564 0.1454709 50.08389
64.59700 0.9943922 0.1447772 50.03753
64.64700 0.9950282 0.1439807 50.02750
64.69701 0.9951441 0.1432277 50.07672
64.74700 0.9941750 0.1426027 50.06108
64.79700 0.9934899 0.1417854 50.01279
-2.000000 2.000000 0.0000000 0.0000000