File: imagens/notebooks/dados experimentais/dsc/Karl_DTAB300 Ur 45%.txt
CLOSED
Version	1.0
Language	English
Run	1
RunSerial	155
Instrument	DSC Q100 V9.9 Build 303
Module	DSC Standard Cell FC
Operator	LL
File	\\Niger\ta\Data\DSC\2018\Geral\Karl_DTAB300 Ur 45%.001
ProcName	Karl
InstSerial	0100-1211
Sample	DTAB300 Ur 45%
Size	16.0100	mg
Method	Karl
Comment
Xcomment	Pan: Aluminum Hermetic
Xcomment	Gas1: Nitrogen 50.0 ml/min
Xcomment	Gas2: Nitrogen 0.0 ml/min
Text
Exotherm	UP
Kcell	1.09030
Calib	-11.7822
TempCal	1	pts	158.71	156.60
TzeroDt	-90.0515 -0.0093 2.2263
TzeroDtz	-90.0515 0.0466 2.4421
InstCalFile	Tzero: \\Niger\ta\Data\DSC\CALIBRATION\20122016\CALIBRATION\0_RCS_12_20_2016 17_23_31.TZR
InstCalFile	Baseline: \\Niger\ta\Data\DSC\CALIBRATION\20122016\L.Base 20122016
InstCalFile	Sapphire: \\Niger\ta\Data\DSC\CALIBRATION\20122016\Safira 20122017.001
InstCalDate	Tzero 2016-12-20 Time 19:23:31
TempRange	-90.04 to 395.23 °C at 19.96 °C/min Heat Only
AutoZero	Delta T Offset 0.000 uV
AutoZero	Delta T0 Offset 0.000 uV
Controls	Gas 1  Event Off  Sampling 0.2
Cell#	FC-02451
CoolingUnit	RCS
SelHeatFlow	Heat Flow T4 (mW)
AutoAnalysis	Off
MacroFile
Nsig	4
Sig1	Time (min)
Sig2	Temperature (°C)
Sig3	Heat Flow (mW)
Sig4	Sample Purge Flow (mL/min)
Date	2018-05-17
Time	14:41:35
OrgMethod	1: Equilibrate at 1.00 °C
OrgMethod	2: Ramp 2.00 °C/min to 60.00 °C
OrgMethod	3: Isothermal for 3.00 min
OrgMethod	4: Mark end of cycle 1
OrgMethod	5: Ramp 2.00 °C/min to 1.00 °C
OrgMethod	6: Isothermal for 3.00 min
OrgMethod	7: Mark end of cycle 2
OrgFile	C:\TA\Data\DSC\2018\Geral\Karl_DTAB300 Ur 45%.001
3.33324E-4 1.259798 1.857207 49.91888
0.05033332 1.236894 1.657602 49.99312
0.1003333 1.244417 1.434614 50.16446
0.1503333 1.276068 1.190328 50.13367
0.2003333 1.320894 0.9377375 50.04353
0.2503333 1.373754 0.6922006 49.97646
0.3003333 1.432381 0.4584278 50.10162
0.3503333 1.495984 0.2392128 49.79415
0.4003334 1.565316 0.04650560 49.91228
0.4503334 1.636492 -0.1366043 49.86601
0.5003334 1.712730 -0.2964983 50.05303
0.5503332 1.789997 -0.4395611 49.93928
0.6003332 1.871160 -0.5628458 49.82010
0.6503332 1.954348 -0.6773405 49.98184
0.7003332 2.039042 -0.7768081 50.01865
0.7503332 2.125102 -0.8627012 50.08056
0.8003332 2.212617 -0.9403472 50.15150
0.8503332 2.301499 -1.008456 50.08456
0.9003332 2.393590 -1.069243 50.08210
0.9503334 2.484280 -1.121545 50.06724
1.000333 2.576073 -1.166494 50.18600
1.050334 2.669404 -1.209215 50.01482
1.100334 2.762438 -1.244656 49.84883
1.150334 2.857314 -1.275660 49.78590
1.200334 2.951975 -1.301822 50.00980
1.250334 3.046911 -1.326952 50.00418
1.300334 3.143191 -1.347160 49.95710
1.350333 3.238700 -1.365728 50.14344
1.400333 3.334444 -1.382336 50.01644
1.450334 3.431726 -1.396299 50.12404
1.500333 3.529008 -1.410058 50.07587
1.550334 3.625429 -1.421283 50.01820
1.600334 3.723602 -1.431073 49.89441
1.650333 3.820410 -1.440438 49.95328
1.700334 3.918060 -1.450496 50.01089
1.750334 4.016044 -1.460087 50.11618
1.800334 4.115616 -1.469740 50.01441
1.850334 4.212434 -1.478608 50.03932
1.900334 4.311328 -1.487042 49.96304
1.950334 4.409767 -1.495226 50.05222
2.000334 4.508072 -1.502967 50.09476
2.050333 4.606783 -1.510445 49.96314
2.100334 4.705310 -1.517389 50.09289
2.150334 4.803622 -1.524098 49.94348
2.200334 4.902352 -1.530380 49.98168
2.250334 5.001056 -1.536132 49.97960
2.300333 5.099902 -1.541729 50.07963
2.350334 5.198965 -1.547073 50.05590
2.400334 5.297870 -1.552078 49.93144
2.450334 5.397329 -1.556833 49.81602
2.500334 5.496003 -1.561400 50.09472
2.550333 5.595240 -1.565634 49.87808
2.600333 5.694626 -1.569711 50.07912
2.650333 5.793922 -1.573531 49.97955
2.700333 5.892852 -1.577304 49.97211
2.750333 5.991515 -1.580855 50.12659
2.800333 6.091747 -1.584311 49.89479
2.850333 6.190910 -1.587492 49.98977
2.900333 6.290473 -1.590496 50.00012
2.950333 6.389958 -1.593518 49.91041
3.000333 6.488682 -1.596141 49.91850
3.050333 6.588494 -1.598842 49.93020
3.100333 6.687880 -1.601384 50.10114
3.150333 6.787762 -1.603883 50.05222
3.200333 6.887028 -1.605916 49.99373
3.250333 6.987050 -1.608251 49.94601
3.300333 7.085991 -1.610354 49.90916
3.350333 7.185086 -1.612383 50.04600
3.400333 7.285312 -1.614374 50.15942
3.450333 7.385297 -1.616436 50.04045
3.500333 7.484585 -1.618420 50.02506
3.550333 7.583246 -1.620389 50.02610
3.600333 7.683856 -1.622241 50.05445
3.650333 7.783416 -1.624141 49.97622
3.700333 7.882718 -1.626150 49.98784
3.750333 7.981866 -1.627758 50.05568
3.800333 8.082684 -1.629522 50.03066
3.850333 8.181718 -1.631195 50.04604
3.900333 8.281656 -1.633017 50.05770
3.950333 8.381680 -1.634789 49.84196
4.000333 8.480718 -1.636292 50.03800
4.050333 8.580262 -1.637904 49.93114
4.100333 8.680676 -1.639523 49.90041
4.150333 8.780331 -1.641203 50.02868
4.200333 8.879605 -1.642685 50.06370
4.250333 8.980438 -1.644031 50.08898
4.300333 9.079609 -1.645570 49.92037
4.350333 9.179406 -1.647020 50.01498
4.400333 9.278866 -1.648497 49.89191
4.450333 9.378806 -1.650041 49.96796
4.500333 9.477899 -1.651581 50.06746
4.550333 9.578392 -1.652958 49.92758
4.600333 9.678662 -1.654634 50.01837
4.650333 9.779071 -1.655971 49.92000
4.700333 9.877994 -1.657510 49.90916
4.750333 9.976812 -1.658862 50.21949
4.800333 10.07745 -1.660442 50.02484
4.850333 10.17753 -1.661700 50.00778
4.900333 10.27716 -1.663024 50.02666
4.950333 10.37747 -1.664276 49.93478
5.000333 10.47646 -1.665694 50.08011
5.050333 10.57664 -1.666800 49.96545
5.100333 10.67562 -1.667850 49.96414
5.150333 10.77602 -1.669037 50.08544
5.200333 10.87556 -1.670096 49.86020
5.250332 10.97478 -1.671181 50.09127
5.300332 11.07442 -1.672194 49.91660
5.350332 11.17409 -1.673198 49.74597
5.400332 11.27427 -1.674232 49.97856
5.450332 11.37425 -1.675450 50.06279
5.500332 11.47316 -1.676614 49.99347
5.550332 11.57434 -1.677830 50.00828
5.600332 11.67258 -1.679149 49.87350
5.650332 11.77308 -1.680384 49.93574
5.700332 11.87236 -1.681806 50.01262
5.750332 11.97216 -1.683044 49.88863
5.800332 12.07188 -1.684458 50.10870
5.850332 12.17244 -1.685844 50.13524
5.900332 12.27232 -1.687353 50.05398
5.950332 12.37135 -1.688931 49.98016
6.000332 12.47120 -1.690646 49.94134
6.050332 12.57127 -1.692201 50.01682
6.100332 12.67071 -1.693894 49.92626
6.150332 12.77051 -1.695606 50.02111
6.200332 12.87052 -1.697437 50.18840
6.250332 12.97005 -1.699109 50.10522
6.300332 13.07160 -1.700836 49.94109
6.350332 13.17039 -1.702561 50.12424
6.400332 13.27069 -1.704086 50.12206
6.450332 13.37035 -1.705700 49.82922
6.500332 13.46932 -1.707241 49.94127
6.550332 13.56959 -1.708738 49.91797
6.600332 13.67000 -1.710328 50.14692
6.650332 13.76946 -1.711775 49.96646
6.700332 13.86935 -1.713324 49.90043
6.750332 13.96913 -1.714749 50.00060
6.800332 14.06914 -1.716091 49.96290
6.850332 14.16825 -1.717620 49.97100
6.900332 14.26879 -1.719236 50.00922
6.950332 14.36748 -1.720648 49.97920
7.000332 14.46719 -1.722248 50.08145
7.050332 14.56796 -1.723775 49.98902
7.100332 14.66862 -1.725536 50.16154
7.150332 14.76763 -1.727194 49.95170
7.200332 14.86710 -1.728966 50.11697
7.250332 14.96761 -1.730691 49.89416
7.300332 15.06689 -1.732500 49.86360
7.350332 15.16662 -1.734233 49.91388
7.400332 15.26704 -1.736014 49.99202
7.450332 15.36575 -1.737730 49.93328
7.500332 15.46551 -1.739424 50.10262
7.550332 15.56588 -1.741242 49.91668
7.600332 15.66507 -1.742892 50.03741
7.650332 15.76436 -1.744499 50.07733
7.700332 15.86478 -1.746270 49.97858
7.750332 15.96512 -1.748076 50.15162
7.800332 16.06428 -1.749966 49.94724
7.850332 16.16376 -1.752074 49.93840
7.900332 16.26430 -1.754021 50.02606
7.950332 16.36365 -1.755988 50.06688
8.000334 16.46388 -1.757906 49.94316
8.050332 16.56291 -1.760058 49.87832
8.100332 16.66290 -1.761968 49.96195
8.150332 16.76270 -1.764084 49.97391
8.200332 16.86207 -1.766184 49.96280
8.250334 16.96179 -1.768332 49.78817
8.300332 17.06212 -1.770532 50.02688
8.350332 17.16170 -1.772800 50.04600
8.400332 17.26140 -1.775058 50.12707
8.450332 17.36088 -1.777279 50.01672
8.500334 17.46151 -1.779486 50.02178
8.550332 17.56156 -1.781836 50.10244
8.600332 17.66006 -1.784156 49.96210
8.650332 17.76043 -1.786441 50.05568
8.700332 17.86022 -1.788788 50.02903
8.750334 17.95919 -1.791238 49.94320
8.800332 18.05905 -1.793462 49.87601
8.850332 18.16064 -1.795872 50.00383
8.900332 18.26013 -1.798288 49.97242
8.950332 18.35930 -1.800697 50.13328
9.000334 18.45880 -1.803152 50.14962
9.050332 18.55789 -1.805760 50.00839
9.100332 18.65921 -1.808225 50.18642
9.150332 18.75890 -1.810772 49.94603
9.200332 18.85755 -1.813503 50.00054
9.250334 18.95666 -1.816072 50.01012
9.300332 19.05747 -1.818686 49.99018
9.350332 19.15808 -1.821316 50.00550
9.400332 19.25592 -1.824050 50.12212
9.450332 19.35722 -1.826691 49.86524
9.500334 19.45621 -1.829394 50.09070
9.550332 19.55657 -1.832222 50.07496
9.600332 19.65591 -1.834960 49.94180
9.650332 19.75520 -1.837739 49.94272
9.700332 19.85528 -1.840652 50.03884
9.750334 19.95476 -1.843489 49.90410
9.800332 20.05499 -1.846415 49.86368
9.850332 20.15414 -1.849142 49.93446
9.900332 20.25410 -1.852100 49.94972
9.950332 20.35341 -1.855001 49.88598
10.00033 20.45379 -1.857778 49.95690
10.05033 20.55342 -1.860671 50.00848
10.10033 20.65292 -1.863448 49.98767
10.15033 20.75170 -1.866452 49.88187
10.20033 20.85170 -1.869551 50.03020
10.25033 20.95144 -1.872639 50.07525
10.30033 21.05242 -1.875838 50.07820
10.35033 21.15223 -1.879230 50.10874
10.40033 21.25043 -1.882664 49.94924
10.45033 21.35086 -1.886244 49.90137
10.50034 21.45019 -1.889971 50.12183
10.55033 21.55039 -1.893946 50.00500
10.60033 21.65005 -1.898136 49.92216
10.65033 21.74898 -1.902806 50.10893
10.70033 21.84883 -1.907742 50.01736
10.75034 21.94877 -1.912931 49.99280
10.80033 22.04698 -1.919146 49.99288
10.85033 22.14644 -1.926424 50.02554
10.90033 22.24486 -1.937162 49.97837
10.95033 22.34346 -1.954905 49.86877
11.00034 22.44166 -1.985168 49.90890
11.05033 22.53845 -2.023900 50.09940
11.10033 22.63612 -2.065250 49.98789
11.15033 22.73411 -2.110614 50.10235
11.20033 22.83023 -2.159041 49.96928
11.25034 22.92646 -2.207920 50.01708
11.30033 23.02305 -2.261251 49.99303
11.35033 23.11823 -2.309960 50.08333
11.40033 23.21442 -2.362002 50.02090
11.45033 23.31024 -2.412196 49.96779
11.50034 23.40537 -2.461993 49.94192
11.55033 23.50162 -2.509548 50.07746
11.60033 23.59753 -2.555617 49.87444
11.65033 23.69348 -2.599727 49.94496
11.70033 23.79014 -2.641043 50.21913
11.75034 23.88622 -2.684575 50.02906
11.80033 23.98362 -2.722848 49.88144
11.85033 24.07921 -2.759176 50.13082
11.90033 24.17682 -2.794594 50.05347
11.95033 24.27384 -2.830642 50.09789
12.00034 24.37012 -2.863294 50.04385
12.05033 24.46742 -2.896286 50.11958
12.10033 24.56534 -2.923995 50.02973
12.15033 24.66270 -2.951786 50.00474
12.20033 24.75908 -2.979672 49.95993
12.25034 24.85839 -3.004975 49.99560
12.30033 24.95482 -3.030302 50.04301
12.35033 25.05354 -3.052363 49.94038
12.40033 25.15166 -3.076312 50.05283
12.45033 25.24883 -3.097035 49.95712
12.50034 25.34780 -3.117047 49.88168
12.55033 25.44534 -3.138365 50.01278
12.60033 25.54500 -3.156263 49.95014
12.65033 25.64270 -3.173798 49.93715
12.70033 25.74145 -3.189946 49.99367
12.75034 25.83990 -3.205420 49.95491
12.80033 25.93801 -3.220105 49.93354
12.85033 26.03647 -3.236740 50.16754
12.90033 26.13590 -3.249654 49.90994
12.95034 26.23462 -3.263772 49.95310
13.00034 26.33231 -3.276251 50.02788
13.05033 26.43252 -3.289302 50.07826
13.10033 26.53050 -3.302590 49.92266
13.15033 26.63002 -3.313732 49.89295
13.20034 26.72842 -3.326016 49.95994
13.25034 26.82808 -3.336877 50.06928
13.30033 26.92688 -3.348237 50.04868
13.35033 27.02544 -3.358925 50.01888
13.40033 27.12484 -3.370666 49.95117
13.45034 27.22411 -3.381836 49.96769
13.50034 27.32221 -3.392714 50.03101
13.55033 27.42155 -3.402940 49.88790
13.60033 27.52109 -3.412988 49.83788
13.65033 27.62092 -3.423047 49.96152
13.70034 27.71963 -3.432770 50.04100
13.75034 27.81832 -3.442242 50.06266
13.80033 27.91904 -3.451466 50.04500
13.85033 28.01720 -3.461018 50.08098
13.90033 28.11658 -3.469976 50.02478
13.95034 28.21558 -3.478711 49.92317
14.00034 28.31476 -3.487390 49.86708
14.05033 28.41434 -3.496016 49.97956
14.10033 28.51338 -3.504421 49.95686
14.15033 28.61321 -3.512713 50.13542
14.20034 28.71147 -3.520750 50.09668
14.25034 28.81172 -3.528824 50.03547
14.30033 28.91089 -3.536829 50.00624
14.35033 29.01028 -3.544710 49.88312
14.40033 29.10990 -3.552890 49.97214
14.45034 29.20824 -3.560848 49.89684
14.50034 29.30691 -3.568818 50.15209
14.55033 29.40779 -3.576630 50.01648
14.60033 29.50710 -3.584504 49.89126
14.65033 29.60715 -3.592192 50.19962
14.70034 29.70594 -3.599452 50.06632
14.75034 29.80542 -3.606900 49.97410
14.80033 29.90446 -3.614018 50.15450
14.85033 30.00405 -3.621208 49.80302
14.90033 30.10406 -3.628416 49.91428
14.95034 30.20328 -3.635566 50.17736
15.00034 30.30295 -3.642722 50.05213
15.05033 30.40290 -3.649700 50.06964
15.10033 30.50195 -3.656507 50.01522
15.15033 30.60082 -3.663414 49.89622
15.20034 30.70037 -3.670150 49.89604
15.25034 30.79984 -3.677042 49.82447
15.30033 30.89892 -3.683788 50.08316
15.35033 30.99922 -3.690545 49.99319
15.40033 31.09818 -3.697247 50.02866
15.45034 31.19675 -3.704006 50.06626
15.50034 31.29774 -3.710584 49.96867
15.55033 31.39734 -3.717354 49.97518
15.60033 31.49635 -3.723822 50.09209
15.65033 31.59554 -3.730274 50.03563
15.70034 31.69510 -3.736816 49.81594
15.75034 31.79417 -3.743340 49.93664
15.80033 31.89330 -3.749939 50.00064
15.85033 31.99350 -3.756700 50.02878
15.90033 32.09246 -3.763406 49.93794
15.95034 32.19112 -3.770178 50.00180
16.00033 32.29158 -3.776867 50.01584
16.05033 32.39131 -3.783713 50.03447
16.10033 32.49092 -3.790258 49.97497
16.15033 32.58972 -3.796948 50.02658
16.20033 32.68834 -3.803085 50.09351
16.25033 32.78956 -3.809105 49.93338
16.30033 32.88822 -3.815060 50.06133
16.35033 32.98813 -3.820681 50.05961
16.40033 33.08813 -3.826120 50.07542
16.45033 33.18765 -3.830957 50.06394
16.50033 33.28743 -3.835350 50.16009
16.55033 33.38735 -3.838520 50.04339
16.60033 33.48703 -3.840280 50.19018
16.65033 33.58661 -3.840192 49.94691
16.70033 33.68820 -3.836817 50.15344
16.75033 33.78930 -3.828037 49.99942
16.80033 33.89134 -3.801442 49.98883
16.85033 33.99440 -3.759156 49.84279
16.90033 34.09685 -3.707376 49.86758
16.95033 34.20130 -3.641720 49.94391
17.00033 34.30594 -3.558450 50.04492
17.05033 34.41262 -3.459331 50.01336
17.10033 34.52070 -3.333858 50.20532
17.15033 34.63136 -3.179055 50.04019
17.20033 34.74289 -3.012751 49.97876
17.25033 34.85691 -2.840602 50.04624
17.30033 34.97008 -2.681720 50.15660
17.35033 35.08324 -2.549392 50.07838
17.40033 35.19378 -2.436950 50.05250
17.45033 35.30298 -2.337644 49.90158
17.50033 35.41104 -2.250984 49.94082
17.55033 35.51746 -2.184570 50.04122
17.60033 35.62361 -2.126155 49.90068
17.65033 35.72862 -2.076804 50.00000
17.70033 35.83267 -2.031689 49.86690
17.75033 35.93644 -1.994332 50.00688
17.80033 36.03874 -1.965004 50.06991
17.85033 36.14119 -1.940726 50.13224
17.90033 36.24440 -1.918924 50.01710
17.95033 36.34510 -1.903047 49.98009
18.00033 36.44728 -1.888494 49.91713
18.05033 36.54896 -1.876495 49.98386
18.10033 36.65037 -1.866418 50.17278
18.15033 36.75101 -1.858120 49.97474
18.20033 36.85098 -1.850081 50.00376
18.25033 36.95216 -1.841966 49.85117
18.30033 37.05221 -1.834138 49.90508
18.35033 37.15190 -1.826678 49.86484
18.40033 37.25378 -1.819838 50.00299
18.45033 37.35462 -1.813611 50.01650
18.50033 37.45433 -1.808031 49.83391
18.55033 37.55504 -1.802949 50.09333
18.60033 37.65533 -1.798274 49.94590
18.65033 37.75460 -1.794289 50.01179
18.70033 37.85450 -1.790848 49.81504
18.75033 37.95482 -1.787728 49.93224
18.80033 38.05495 -1.785245 49.99610
18.85033 38.15544 -1.783028 50.04530
18.90033 38.25544 -1.781275 49.98250
18.95033 38.35610 -1.779931 50.07344
19.00033 38.45532 -1.778785 49.90840
19.05033 38.55586 -1.777733 50.09216
19.10033 38.65578 -1.777002 49.94143
19.15033 38.75641 -1.776359 49.93986
19.20033 38.85604 -1.775825 49.88152
19.25033 38.95568 -1.775337 49.96472
19.30033 39.05572 -1.775021 50.03153
19.35033 39.15652 -1.774459 50.04371
19.40033 39.25621 -1.774214 49.98396
19.45033 39.35546 -1.774084 50.05094
19.50033 39.45644 -1.773944 49.94574
19.55033 39.55428 -1.773781 50.08906
19.60033 39.65580 -1.773608 50.03161
19.65033 39.75524 -1.773353 49.86654
19.70033 39.85562 -1.773015 49.88436
19.75033 39.95559 -1.772906 50.00970
19.80033 40.05471 -1.772731 50.11359
19.85033 40.15535 -1.772461 50.06488
19.90033 40.25559 -1.772380 49.94472
19.95033 40.35477 -1.772382 49.92062
20.00033 40.45527 -1.772425 50.11086
20.05033 40.55469 -1.772556 50.13878
20.10033 40.65496 -1.772842 50.07256
20.15033 40.75496 -1.773036 50.00404
20.20033 40.85443 -1.773447 50.06436
20.25033 40.95439 -1.773816 49.80590
20.30033 41.05400 -1.774196 49.99350
20.35033 41.15400 -1.774644 49.90836
20.40033 41.25485 -1.775085 50.16098
20.45033 41.35338 -1.775700 49.92502
20.50033 41.45396 -1.776144 49.91699
20.55033 41.55416 -1.776825 50.08914
20.60033 41.65421 -1.777449 49.82644
20.65033 41.75348 -1.778127 49.99839
20.70033 41.85445 -1.778826 50.09070
20.75033 41.95369 -1.779437 49.93441
20.80033 42.05348 -1.780074 49.95390
20.85033 42.15437 -1.780757 50.00587
20.90033 42.25394 -1.781305 49.93809
20.95033 42.35371 -1.781731 49.97410
21.00033 42.45362 -1.782075 49.85059
21.05033 42.55376 -1.782258 50.01582
21.10033 42.65184 -1.782422 49.95367
21.15033 42.75320 -1.782609 50.00160
21.20033 42.85289 -1.782576 49.95706
21.25033 42.95338 -1.782728 49.94403
21.30033 43.05257 -1.783016 49.98594
21.35033 43.15268 -1.783424 50.02406
21.40033 43.25226 -1.783604 50.05740
21.45033 43.35153 -1.783714 50.15454
21.50033 43.45298 -1.784013 49.87040
21.55033 43.55142 -1.784232 49.95417
21.60033 43.65186 -1.784266 50.06879
21.65033 43.75137 -1.784605 50.07342
21.70033 43.85168 -1.784983 50.02524
21.75033 43.95260 -1.785266 50.08149
21.80033 44.05235 -1.785516 49.86344
21.85033 44.15166 -1.785991 49.94828
21.90033 44.25188 -1.786404 49.97065
21.95033 44.35164 -1.786825 50.05484
22.00033 44.45213 -1.787230 50.01126
22.05033 44.55142 -1.787656 50.11396
22.10033 44.65180 -1.788178 49.93009
22.15033 44.75087 -1.788560 50.13067
22.20033 44.85222 -1.788731 50.10622
22.25033 44.95184 -1.789020 49.84830
22.30033 45.05176 -1.789327 49.92665
22.35033 45.15193 -1.789596 50.18896
22.40033 45.25197 -1.789987 49.95533
22.45033 45.35126 -1.790361 50.15136
22.50033 45.45226 -1.790710 50.01846
22.55033 45.55228 -1.790970 49.98261
22.60033 45.65228 -1.791389 50.02641
22.65033 45.75199 -1.791830 49.97272
22.70033 45.85152 -1.792115 49.98572
22.75033 45.95211 -1.792565 49.86480
22.80033 46.05196 -1.793023 50.06644
22.85033 46.15144 -1.793231 50.09773
22.90033 46.25176 -1.793540 50.05881
22.95033 46.35235 -1.793694 50.06942
23.00033 46.45174 -1.793964 50.03468
23.05033 46.55164 -1.794058 49.94082
23.10033 46.65194 -1.794390 49.98105
23.15033 46.75152 -1.794612 50.00373
23.20033 46.85178 -1.794719 49.96820
23.25033 46.95066 -1.794878 49.97048
23.30033 47.05063 -1.794862 50.02726
23.35033 47.15096 -1.795000 49.76747
23.40033 47.24982 -1.795056 50.06699
23.45033 47.35094 -1.795034 49.94214
23.50033 47.45048 -1.795288 50.08538
23.55033 47.55088 -1.795367 49.98348
23.60033 47.65057 -1.795743 49.83336
23.65033 47.75102 -1.796064 50.04076
23.70033 47.85029 -1.796246 49.94748
23.75033 47.95088 -1.796441 49.84141
23.80033 48.05070 -1.796674 50.05648
23.85033 48.15018 -1.796808 49.86226
23.90033 48.25034 -1.797041 49.90244
23.95033 48.34962 -1.797255 49.95593
24.00033 48.44996 -1.797476 49.93146
24.05033 48.54928 -1.797756 50.10608
24.10033 48.64850 -1.798052 50.11576
24.15033 48.74902 -1.798496 49.87261
24.20033 48.84838 -1.798984 49.98609
24.25033 48.94956 -1.799633 49.98010
24.30033 49.04716 -1.820722 49.98230
24.35033 49.14608 -1.875880 49.87060
24.40033 49.24324 -1.890309 49.97039
24.45033 49.34302 -1.888156 49.89900
24.50033 49.44331 -1.884303 49.88566
24.55033 49.54562 -1.879738 49.98936
24.60033 49.64600 -1.874612 49.94143
24.65033 49.74628 -1.869186 50.06766
24.70033 49.84549 -1.863835 49.88217
24.75033 49.94632 -1.858518 49.92560
24.80033 50.04730 -1.853256 49.98326
24.85033 50.14686 -1.848270 49.94903
24.90033 50.24797 -1.843770 50.00304
24.95033 50.34708 -1.839801 50.03619
25.00033 50.44770 -1.836085 50.10794
25.05033 50.54780 -1.832962 50.05988
25.10033 50.64824 -1.830092 49.92546
25.15033 50.74790 -1.827261 50.02098
25.20033 50.84893 -1.824755 49.91226
25.25033 50.94912 -1.822650 49.93150
25.30033 51.04844 -1.820546 49.89758
25.35033 51.14846 -1.818773 49.93904
25.40033 51.24854 -1.817284 50.06550
25.45033 51.34903 -1.816016 49.84053
25.50033 51.44908 -1.815090 50.07309
25.55033 51.54930 -1.814313 49.95716
25.60033 51.65004 -1.813745 50.06723
25.65033 51.74870 -1.813301 49.96606
25.70033 51.84950 -1.813021 50.07522
25.75033 51.94873 -1.812636 49.96766
25.80033 52.04879 -1.812184 50.16118
25.85033 52.14986 -1.811832 50.00686
25.90033 52.24938 -1.811749 49.93550
25.95033 52.34969 -1.811801 49.87093
26.00033 52.44931 -1.812000 49.88330
26.05033 52.54934 -1.812390 49.93453
26.10033 52.64860 -1.812570 50.06320
26.15033 52.74895 -1.812847 49.84146
26.20033 52.84876 -1.813129 49.81128
26.25033 52.94810 -1.813370 49.91891
26.30033 53.04842 -1.813822 50.09869
26.35033 53.14926 -1.814303 49.79263
26.40033 53.24843 -1.814734 50.05433
26.45033 53.34902 -1.815195 50.00280
26.50033 53.44943 -1.815794 49.86119
26.55033 53.54976 -1.816294 49.97484
26.60033 53.64802 -1.816685 50.01676
26.65033 53.74892 -1.817005 50.04485
26.70033 53.84879 -1.817430 50.01289
26.75033 53.94795 -1.817760 49.99428
26.80033 54.04885 -1.818154 50.04569
26.85033 54.14864 -1.818751 49.93958
26.90033 54.24840 -1.819265 50.10590
26.95033 54.34853 -1.819825 50.01672
27.00033 54.44824 -1.820148 49.96704
27.05033 54.54782 -1.820392 50.12947
27.10033 54.64835 -1.820718 49.90948
27.15033 54.74734 -1.821025 49.96164
27.20033 54.84724 -1.821369 49.97424
27.25033 54.94658 -1.821703 50.13016
27.30033 55.04682 -1.822069 50.03214
27.35033 55.14651 -1.822512 49.94816
27.40033 55.24683 -1.823004 49.95143
27.45033 55.34692 -1.823364 50.11434
27.50033 55.44683 -1.823722 50.13700
27.55033 55.54570 -1.824100 49.99266
27.60033 55.64619 -1.824470 50.05340
27.65033 55.74454 -1.824606 49.89200
27.70033 55.84600 -1.824886 50.12619
27.75033 55.94532 -1.825512 49.98250
27.80033 56.04552 -1.826003 49.98884
27.85033 56.14568 -1.826627 49.90033
27.90033 56.24613 -1.827474 50.09817
27.95033 56.34560 -1.828331 49.89627
28.00033 56.44641 -1.829326 49.93016
28.05033 56.54572 -1.830510 50.10187
28.10033 56.64562 -1.831845 49.86360
28.15033 56.74607 -1.833134 49.83359
28.20033 56.84621 -1.834011 49.95306
28.25033 56.94594 -1.834714 49.94355
28.30033 57.04452 -1.835077 49.92280
28.35033 57.14368 -1.835165 49.90952
28.40033 57.24350 -1.835141 49.93386
28.45033 57.34325 -1.834858 49.91348
28.50033 57.44247 -1.834452 50.04381
28.55033 57.54088 -1.834010 49.88776
28.60033 57.64130 -1.833706 50.01913
28.65033 57.74056 -1.833229 50.07900
28.70033 57.84130 -1.833152 50.03910
28.75033 57.93980 -1.832906 50.02417
28.80033 58.04062 -1.832851 49.99860
28.85033 58.13956 -1.833034 50.01584
28.90033 58.24016 -1.833349 50.14066
28.95033 58.33912 -1.833552 50.08406
29.00033 58.43987 -1.834032 50.11318
29.05033 58.54032 -1.834325 50.01104
29.10033 58.63936 -1.834814 49.99678
29.15033 58.74035 -1.835502 49.88252
29.20033 58.83952 -1.836145 50.02268
29.25033 58.93921 -1.836857 50.05706
29.30033 59.04049 -1.837226 49.77015
29.35033 59.14011 -1.837984 49.96104
29.40033 59.23926 -1.838554 50.07726
29.45033 59.33996 -1.839133 49.88110
29.50033 59.43938 -1.839471 49.85553
29.55033 59.53598 -1.840724 49.97476
29.60033 59.60855 -1.832106 50.03509
29.65033 59.65754 -1.709764 50.04582
29.70033 59.69695 -1.572521 50.07261
29.75033 59.72998 -1.424232 49.93278
29.80033 59.75776 -1.281528 49.87153
29.85033 59.78305 -1.136603 49.93674
29.90033 59.80411 -1.006902 49.95980
29.95033 59.82292 -0.8835381 50.03133
30.00033 59.83838 -0.7728724 49.85560
30.05033 59.85190 -0.6773085 50.02562
30.10033 59.86318 -0.5902138 49.99023
30.15033 59.87437 -0.5151572 50.11226
30.20033 59.88338 -0.4524533 50.02326
30.25033 59.89220 -0.3960414 50.00613
30.30033 59.89930 -0.3479035 50.02278
30.35033 59.90608 -0.3083916 50.00574
30.40033 59.91150 -0.2695012 49.93813
30.45033 59.91470 -0.2358875 50.13269
30.50033 59.91889 -0.2054230 49.88762
30.55033 59.92222 -0.1799574 49.96409
30.60033 59.92488 -0.1585791 49.97553
30.65033 59.92727 -0.1396757 49.89916
30.70033 59.92884 -0.1231703 49.84610
30.75033 59.93139 -0.1106443 49.94931
30.80033 59.93188 -.09865969 49.81416
30.85033 59.93415 -.08811874 49.93394
30.90033 59.93560 -.08030061 50.12456
30.95033 59.93736 -.07222270 49.98410
31.00033 59.93793 -.06393753 49.95040
31.05033 59.93970 -.05639222 49.92087
31.10033 59.94042 -.04912613 50.12684
31.15033 59.94076 -.04245231 49.87364
31.20033 59.94306 -.03612104 49.94400
31.25033 59.94245 -.03051570 49.98056
31.30033 59.94416 -.02520754 50.05220
31.35033 59.94404 -.02016478 49.84994
31.40033 59.94518 -.01559285 49.99528
31.45033 59.94540 -.01146352 49.88984
31.50033 59.94690 -7.6669E-3 50.07536
31.55033 59.94708 -4.3570E-3 50.01776
31.60033 59.94705 -1.1157E-3 50.07559
31.65033 59.94859 .001746316 49.97454
31.70033 59.94862 .004229126 50.14674
31.75033 59.94914 .006503350 49.98993
31.80033 59.94902 .008539862 50.01094
31.85034 59.95037 0.01041187 49.89402
31.90033 59.95090 0.01206828 49.87146
31.95033 59.95110 0.01372013 50.09176
32.00033 59.95093 0.01520636 50.10730
32.05033 59.95098 0.01663534 50.07512
32.10034 59.95170 0.01788521 49.97882
32.15033 59.95226 0.01901199 50.07654
32.20033 59.95232 0.02031604 49.97778
32.25033 59.95272 0.02151286 49.96036
32.30033 59.95316 0.02264883 49.89984
32.35034 59.95295 0.02377112 50.05109
32.40033 59.95297 0.02469984 49.94120
32.45033 59.95401 0.02564122 49.91444
-2.000000 1.000000 0.0000000 0.0000000
32.54700 59.95059 0.02662245 49.92242
32.59700 59.92476 0.03554790 50.02146
32.64700 59.87410 0.1589702 50.06961
32.69700 59.81199 0.2964020 50.00854
32.74700 59.74451 0.4513514 49.99434
32.79700 59.67195 0.6056858 50.07837
32.84700 59.59595 0.7508288 49.97564
32.89700 59.51544 0.8817469 49.96106
32.94700 59.43428 1.005313 50.07761
32.99700 59.34847 1.113616 49.89747
33.04700 59.26186 1.209444 50.12228
33.09700 59.17242 1.300548 49.92519
33.14700 59.08392 1.373180 49.94228
33.19700 58.99229 1.439293 49.85934
33.24700 58.89980 1.496850 49.95560
33.29700 58.80649 1.546826 50.06504
33.34700 58.71257 1.589286 50.08490
33.39700 58.61657 1.625184 50.03626
33.44700 58.52218 1.657090 50.00474
33.49700 58.42585 1.684237 50.14078
33.54700 58.32950 1.707169 49.93728
33.59700 58.23243 1.725920 50.17687
33.64700 58.13540 1.743427 50.02418
33.69700 58.03754 1.757016 50.13510
33.74700 57.94066 1.769344 49.93545
33.79700 57.84178 1.780174 50.01484
33.84700 57.74256 1.790000 50.08320
33.89700 57.64545 1.798878 50.05896
33.94700 57.54684 1.807422 49.92889
33.99700 57.44800 1.815900 49.90553
34.04700 57.34928 1.824323 49.91213
34.09700 57.25084 1.832057 49.93950
34.14700 57.15087 1.839506 50.08388
34.19700 57.05240 1.846432 50.04148
34.24700 56.95303 1.853063 50.05758
34.29700 56.85442 1.859199 49.99500
34.34700 56.75425 1.865096 49.93402
34.39700 56.65526 1.870557 50.02036
34.44700 56.55610 1.875786 50.09991
34.49700 56.45622 1.880460 49.91158
34.54700 56.35656 1.884738 50.02507
34.59700 56.25753 1.888850 50.02944
34.64700 56.15801 1.892408 50.14194
34.69700 56.05796 1.895895 50.02638
34.74700 55.95742 1.898900 50.14467
34.79700 55.85997 1.901714 49.92117
34.84700 55.75997 1.904367 50.01014
34.89700 55.65960 1.906747 49.89004
34.94700 55.56114 1.908953 49.78671
34.99700 55.46082 1.910927 50.14870
35.04700 55.36126 1.912692 49.93594
35.09700 55.26152 1.914412 49.91418
35.14700 55.16168 1.915993 49.84365
35.19700 55.06145 1.917448 50.04053
35.24700 54.96250 1.918890 50.04578
35.29700 54.86270 1.920277 49.94360
35.34700 54.76344 1.921789 49.96558
35.39700 54.66293 1.923128 50.13124
35.44700 54.56332 1.924369 50.05180
35.49700 54.46305 1.925440 49.99309
35.54700 54.36538 1.926384 50.16192
35.59700 54.26486 1.927196 49.94184
35.64700 54.16530 1.928138 50.17908
35.69700 54.06467 1.928891 49.93648
35.74700 53.96562 1.929732 49.94402
35.79700 53.86516 1.930560 49.91754
35.84700 53.76538 1.931357 50.00056
35.89700 53.66568 1.932141 49.94930
35.94700 53.56608 1.932813 49.91250
35.99700 53.46656 1.933408 50.08917
36.04700 53.36578 1.934102 50.11700
36.09700 53.26632 1.934788 50.03354
36.14700 53.16761 1.935367 49.94882
36.19700 53.06798 1.936078 49.97112
36.24700 52.96762 1.936956 50.12609
36.29700 52.86752 1.937834 50.10282
36.34700 52.76826 1.938682 49.88242
36.39700 52.66809 1.939586 50.03828
36.44700 52.56819 1.940206 49.86739
36.49700 52.46821 1.940969 50.12535
36.54700 52.36787 1.941612 49.96409
36.59700 52.26765 1.942067 50.03310
36.64700 52.16863 1.942749 50.17968
36.69700 52.06904 1.943244 49.91058
36.74700 51.96946 1.943905 49.91426
36.79700 51.86944 1.944561 50.21403
36.84700 51.76914 1.945143 49.92772
36.89700 51.66936 1.945825 49.94930
36.94700 51.56943 1.946430 49.86413
36.99700 51.46920 1.946989 50.09698
37.04700 51.37037 1.947561 50.03522
37.09700 51.27004 1.948092 50.08724
37.14700 51.17054 1.948832 49.97086
37.19700 51.07101 1.949532 50.03812
37.24700 50.97080 1.950041 50.02483
37.29700 50.87006 1.950588 49.96063
37.34700 50.77122 1.951127 49.99781
37.39700 50.67128 1.951823 49.82231
37.44700 50.57139 1.952617 49.90778
37.49700 50.47041 1.953220 50.09656
37.54700 50.37088 1.954033 49.91834
37.59700 50.27100 1.954779 50.00816
37.64700 50.17041 1.955460 50.01180
37.69700 50.07037 1.955876 50.04517
37.74700 49.97080 1.956244 49.95289
37.79700 49.87076 1.956648 49.89466
37.84700 49.77168 1.956818 50.00750
37.89700 49.67162 1.957176 49.94366
37.94700 49.57211 1.957396 49.99197
37.99700 49.47228 1.957620 50.11343
38.04700 49.37250 1.957937 50.03886
38.09700 49.27250 1.958176 49.93875
38.14700 49.17340 1.958684 50.21008
38.19700 49.07342 1.959085 49.87508
38.24700 48.97324 1.959628 50.01986
38.29700 48.87338 1.960348 50.09024
38.34700 48.77352 1.961112 49.86360
38.39700 48.67466 1.961986 49.98306
38.44700 48.57412 1.962887 50.08583
38.49700 48.47414 1.963742 49.99703
38.54700 48.37528 1.964751 50.15808
38.59700 48.27482 1.965586 50.08778
38.64700 48.17498 1.966595 50.00510
38.69700 48.07511 1.967474 49.89463
38.74700 47.97531 1.968216 49.97213
38.79700 47.87563 1.968962 49.83556
38.84700 47.77597 1.969752 50.07706
38.89700 47.67606 1.970259 49.89288
38.94700 47.57571 1.970828 49.93525
38.99700 47.47546 1.971407 49.93998
39.04700 47.37696 1.971889 49.95144
39.09700 47.27592 1.972189 50.16113
39.14700 47.17648 1.972563 50.01796
39.19700 47.07639 1.973006 50.09570
39.24700 46.97647 1.973309 49.79981
39.29700 46.87711 1.973830 49.92133
39.34700 46.77656 1.974105 49.99742
39.39700 46.67678 1.974549 50.08342
39.44700 46.57702 1.974955 49.99600
39.49700 46.47658 1.975102 50.14698
39.54700 46.37683 1.975287 50.12928
39.59700 46.27661 1.975415 49.85012
39.64700 46.17682 1.975413 49.95589
39.69700 46.07680 1.975506 49.92037
39.74700 45.97714 1.975466 50.00147
39.79700 45.87666 1.975354 50.08030
39.84700 45.77754 1.975254 50.06746
39.89700 45.67710 1.975094 50.03301
39.94700 45.57720 1.974971 49.89080
39.99700 45.47772 1.974808 49.89622
40.04700 45.37723 1.974582 49.93466
40.09700 45.27713 1.974678 50.13070
40.14700 45.17691 1.974714 50.11210
40.19700 45.07750 1.974763 50.08940
40.24700 44.97800 1.974910 49.91538
40.29700 44.87740 1.974974 49.92718
40.34700 44.77874 1.975127 50.00654
40.39700 44.67786 1.975239 49.83912
40.44700 44.57731 1.975324 49.95959
40.49700 44.47746 1.975448 49.90230
40.54700 44.37867 1.975552 49.95126
40.59700 44.27890 1.975431 50.02492
40.64700 44.17829 1.975513 50.08506
40.69700 44.07879 1.975325 49.99180
40.74700 43.97734 1.975122 49.99128
40.79700 43.87854 1.974905 49.97136
40.84700 43.77828 1.974806 50.03433
40.89700 43.67934 1.974767 49.87206
40.94700 43.57933 1.974716 49.96969
40.99700 43.47944 1.974626 50.06428
41.04700 43.37984 1.974730 49.97500
41.09700 43.27985 1.974784 50.02649
41.14700 43.17984 1.974669 50.04953
41.19700 43.07942 1.974608 50.21421
41.24700 42.97892 1.974600 50.09291
41.29700 42.87910 1.974675 49.99298
41.34700 42.77982 1.974666 49.98303
41.39700 42.67989 1.974594 50.13714
41.44700 42.57938 1.974544 50.07544
41.49700 42.47924 1.974356 49.93956
41.54700 42.38022 1.974188 50.11674
41.59700 42.27972 1.973868 49.89953
41.64700 42.18066 1.973567 49.97789
41.69700 42.08139 1.973308 50.12196
41.74700 41.97974 1.972981 50.03267
41.79700 41.87998 1.972634 50.02450
41.84700 41.78040 1.972265 49.96896
41.89700 41.68030 1.972007 50.03165
41.94700 41.58049 1.971768 49.92466
41.99700 41.48070 1.971516 50.05928
42.04700 41.38076 1.971315 50.16866
42.09700 41.27952 1.971079 50.09623
42.14700 41.17950 1.970881 50.08900
42.19700 41.08006 1.970752 49.95472
42.24700 40.98074 1.970679 50.04706
42.29700 40.88012 1.970768 50.06432
42.34700 40.77963 1.970709 49.91694
42.39700 40.68088 1.970454 49.94217
42.44700 40.58070 1.970552 49.88217
42.49700 40.48092 1.970589 50.07908
42.54700 40.38134 1.970694 49.89630
42.59700 40.28132 1.970601 49.90982
42.64700 40.18131 1.970653 50.09794
42.69700 40.08147 1.970637 49.99131
42.74700 39.98170 1.970568 50.05544
42.79700 39.88081 1.970688 49.95541
42.84700 39.78106 1.970646 49.88522
42.89700 39.68260 1.970755 50.02416
42.94700 39.58203 1.970744 49.96028
42.99700 39.48180 1.970631 50.06809
43.04700 39.38155 1.970534 50.00039
43.09700 39.28170 1.970499 49.97754
43.14700 39.18145 1.970264 50.12676
43.19700 39.08172 1.970168 50.04818
43.24700 38.98288 1.969943 49.94538
43.29700 38.88257 1.969634 50.05724
43.34700 38.78242 1.969362 50.02422
43.39700 38.68352 1.969080 50.04231
43.44700 38.58303 1.968782 50.02190
43.49700 38.48386 1.968550 49.96812
43.54700 38.38336 1.968398 49.92475
43.59700 38.28358 1.968250 50.02020
43.64700 38.18218 1.968110 49.77600
43.69700 38.08355 1.968049 50.03568
43.74700 37.98358 1.968097 50.00069
43.79700 37.88339 1.967990 49.99053
43.84700 37.78360 1.967898 50.21246
43.89700 37.68332 1.967864 49.97524
43.94700 37.58241 1.967766 49.94044
43.99700 37.48291 1.967610 49.95703
44.04700 37.38339 1.967448 50.04434
44.09700 37.28350 1.967106 50.12793
44.14700 37.18350 1.966810 49.95490
44.19700 37.08384 1.966577 50.04908
44.24700 36.98356 1.966344 50.03994
44.29700 36.88406 1.966231 50.19266
44.34700 36.78372 1.966074 49.94094
44.39700 36.68414 1.965692 49.89478
44.44700 36.58465 1.965526 49.83444
44.49700 36.48512 1.965284 50.02794
44.54700 36.38482 1.965015 50.00207
44.59700 36.28482 1.964788 49.99182
44.64700 36.18505 1.964532 50.06039
44.69700 36.08378 1.964427 49.85467
44.74700 35.98574 1.964169 50.14661
44.79700 35.88473 1.963922 50.16441
44.84700 35.78490 1.963776 50.23887
44.89700 35.68587 1.963452 50.13547
44.94700 35.58519 1.963209 50.00554
44.99700 35.48406 1.962958 49.99219
45.04700 35.38489 1.962809 49.93938
45.09700 35.28454 1.962630 49.98150
45.14700 35.18536 1.962506 50.17586
45.19700 35.08555 1.962479 50.04476
45.24700 34.98484 1.962568 50.06388
45.29700 34.88528 1.962561 50.13748
45.34700 34.78498 1.962506 49.98289
45.39700 34.68438 1.962408 50.04103
45.44700 34.58456 1.962279 50.17592
45.49700 34.48547 1.962232 49.97219
45.54700 34.38455 1.962205 49.95817
45.59700 34.28562 1.962147 50.00832
45.64700 34.18501 1.962143 49.96510
45.69700 34.08526 1.962087 49.81734
45.74700 33.98526 1.962021 50.05942
45.79700 33.88507 1.961986 50.13009
45.84700 33.78561 1.961994 49.93546
45.89700 33.68539 1.962025 50.13654
45.94700 33.58491 1.961924 49.98337
45.99700 33.48444 1.961833 49.87592
46.04700 33.38530 1.961762 50.06696
46.09700 33.28536 1.961615 50.11224
46.14700 33.18597 1.961337 49.90934
46.19700 33.08625 1.961054 49.99317
46.24700 32.98574 1.960652 49.96910
46.29700 32.88613 1.960192 49.83770
46.34700 32.78584 1.959926 49.97378
46.39700 32.68676 1.959602 49.77412
46.44700 32.58604 1.959356 49.97953
46.49700 32.48644 1.959132 50.15336
46.54700 32.38644 1.958856 49.82444
46.59700 32.28681 1.958754 49.91250
46.64700 32.18662 1.958737 50.11153
46.69700 32.08692 1.958647 50.10886
46.74700 31.98623 1.958582 49.90692
46.79700 31.88664 1.958736 49.95440
46.84700 31.78648 1.958724 49.93706
46.89700 31.68640 1.958747 50.12567
46.94700 31.58668 1.958815 50.01909
46.99700 31.48700 1.958775 49.99770
47.04700 31.38751 1.958799 49.98504
47.09700 31.28696 1.958700 49.99762
47.14700 31.18677 1.958756 49.98697
47.19700 31.08723 1.958728 50.12979
47.24700 30.98772 1.958737 50.00019
47.29700 30.88655 1.959127 50.04352
47.34700 30.78785 1.961238 50.07840
47.39700 30.69026 1.988799 50.03800
47.44700 30.59453 2.103240 50.03598
47.49700 30.50354 2.298787 49.84422
47.54700 30.42056 2.606642 50.12480
47.59700 30.34778 3.050489 49.84690
47.64700 30.28488 3.617040 50.09030
47.69700 30.23010 4.245534 49.90902
47.74700 30.17956 4.863768 49.97672
47.79700 30.12783 5.393560 50.13206
47.84700 30.06960 5.798428 49.97659
47.89700 30.00047 6.070771 49.97281
47.94700 29.92218 6.209854 50.07978
47.99700 29.83451 6.254188 50.01102
48.04700 29.73823 6.239400 49.94650
48.09700 29.63770 6.183386 49.88098
48.14700 29.53142 6.077107 50.06372
48.19700 29.42505 5.961675 49.88734
48.24700 29.31662 5.845352 50.04163
48.29700 29.20758 5.726425 49.97768
48.34700 29.09800 5.607598 49.97795
48.39700 28.98793 5.495710 50.09076
48.44700 28.87915 5.384693 49.94522
48.49700 28.77082 5.277621 49.86275
48.54700 28.66057 5.177081 49.94449
48.59700 28.55337 5.085361 50.06542
48.64700 28.44556 4.997002 50.10106
48.69700 28.33862 4.914703 50.16982
48.74700 28.23162 4.837210 50.12344
48.79700 28.12584 4.761672 50.05766
48.84700 28.02017 4.696652 49.96384
48.89700 27.91392 4.633187 49.86924
48.94700 27.80914 4.574981 49.99851
48.99700 27.70444 4.518485 50.19358
49.04700 27.59999 4.467456 50.05646
49.09700 27.49546 4.418378 49.92484
49.14700 27.39221 4.373646 49.96548
49.19700 27.28804 4.333130 50.05044
49.24700 27.18400 4.293606 50.00489
49.29700 27.08108 4.256383 50.15714
49.34700 26.97788 4.222519 49.84188
49.39700 26.87662 4.191718 50.07808
49.44700 26.77305 4.160368 50.08122
49.49700 26.66988 4.134320 50.08636
49.54700 26.56807 4.107110 50.09554
49.59700 26.46665 4.084014 49.98750
49.64700 26.36320 4.060767 49.88806
49.69700 26.26230 4.039285 49.96650
49.74700 26.15988 4.017593 49.97004
49.79700 26.05833 3.999837 49.99003
49.84700 25.95656 3.981530 50.08437
49.89700 25.85596 3.964254 49.87578
49.94700 25.75396 3.947917 49.86188
49.99700 25.65270 3.931343 49.96557
50.04700 25.55220 3.915994 49.87672
50.09700 25.45084 3.902203 50.08992
50.14700 25.34852 3.888722 50.01377
50.19700 25.24805 3.875886 50.18811
50.24700 25.14722 3.862596 50.10496
50.29700 25.04653 3.850146 49.94412
50.34700 24.94544 3.836220 49.99691
50.39700 24.84501 3.824703 49.86340
50.44700 24.74281 3.812698 49.94203
50.49700 24.64272 3.801291 50.01580
50.54700 24.54090 3.789234 50.12889
50.59700 24.44043 3.777465 50.01426
50.64700 24.33925 3.765872 50.13620
50.69700 24.23797 3.754983 50.00299
50.74700 24.13707 3.743048 49.83324
50.79700 24.03584 3.731020 49.91774
50.84700 23.93474 3.719038 50.07204
50.89700 23.83451 3.706559 49.90226
50.94700 23.73450 3.692793 50.12420
50.99700 23.63186 3.680506 50.08328
51.04700 23.53076 3.663551 50.11616
51.09700 23.42972 3.647834 50.04950
51.14700 23.32884 3.630894 50.04516
51.19700 23.22696 3.612250 50.05088
51.24700 23.12590 3.591454 50.10404
51.29700 23.02394 3.569520 49.98848
51.34700 22.92337 3.543509 50.04116
51.39700 22.82157 3.514740 50.11632
51.44700 22.71976 3.483858 49.96385
51.49700 22.61710 3.446790 50.05914
51.54700 22.51486 3.406750 49.93137
51.59700 22.41183 3.361022 50.04938
51.64700 22.30725 3.310250 49.94818
51.69700 22.20360 3.249166 50.09339
51.74700 22.09938 3.184496 49.97347
51.79700 21.99385 3.112644 50.01262
51.84700 21.88770 3.036762 49.84970
51.89700 21.78210 2.955701 49.97534
51.94700 21.67530 2.873940 49.98212
51.99700 21.57011 2.801248 49.83825
52.04700 21.46237 2.727236 50.04538
52.09700 21.35736 2.664568 49.93969
52.14700 21.25138 2.607362 50.04383
52.19700 21.14768 2.552213 50.18921
52.24700 21.04292 2.502676 49.84134
52.29700 20.93798 2.463115 49.78944
52.34700 20.83494 2.425902 49.95067
52.39700 20.73151 2.394035 49.85996
52.44700 20.62879 2.366026 49.97313
52.49700 20.52718 2.340469 50.10050
52.54700 20.42426 2.318812 49.86088
52.59700 20.32324 2.298620 50.13742
52.64700 20.22060 2.281629 49.91622
52.69700 20.11979 2.267235 49.98006
52.74700 20.01832 2.252974 49.94672
52.79700 19.91730 2.241687 49.93250
52.84700 19.81608 2.231275 50.08909
52.89700 19.71402 2.221130 49.98747
52.94700 19.61397 2.211576 50.06506
52.99700 19.51278 2.202397 49.79291
53.04700 19.41316 2.193315 49.87814
53.09700 19.31223 2.184360 50.05442
53.14700 19.21095 2.175652 49.91359
53.19700 19.11064 2.167314 50.04820
53.24700 19.00996 2.159128 49.96971
53.29700 18.91011 2.151261 50.00076
53.34700 18.80971 2.143960 49.88981
53.39700 18.70826 2.136860 50.10530
53.44700 18.60874 2.130235 50.12211
53.49700 18.50760 2.123956 49.92410
53.54700 18.40773 2.118101 49.92288
53.59700 18.30738 2.112441 49.86613
53.64700 18.20689 2.106818 50.15497
53.69700 18.10609 2.101735 49.95125
53.74700 18.00578 2.096726 50.09649
53.79700 17.90631 2.092100 49.93656
53.84700 17.80547 2.087510 49.79426
53.89700 17.70517 2.083254 49.92210
53.94700 17.60506 2.078888 49.98609
53.99700 17.50392 2.074634 50.07575
54.04700 17.40509 2.070583 50.01570
54.09700 17.30383 2.066651 49.86670
54.14700 17.20434 2.062874 50.10515
54.19700 17.10389 2.059104 50.13676
54.24700 17.00410 2.055539 50.12231
54.29700 16.90374 2.052042 50.12112
54.34700 16.80348 2.048741 50.07772
54.39700 16.70382 2.045444 49.90290
54.44700 16.60374 2.042200 49.97344
54.49700 16.50264 2.039060 49.93143
54.54700 16.40366 2.035974 50.17690
54.59700 16.30219 2.033003 49.90180
54.64700 16.20322 2.030140 49.85918
54.69700 16.10211 2.027459 49.98209
54.74700 16.00194 2.024643 49.98566
54.79700 15.90213 2.021778 50.08300
54.84700 15.80169 2.019184 49.97096
54.89700 15.70138 2.016480 49.93450
54.94700 15.60120 2.013950 49.94598
54.99700 15.50086 2.011357 49.93974
55.04700 15.40098 2.008981 50.11850
55.09700 15.30099 2.006489 49.85438
55.14700 15.20057 2.004067 50.04853
55.19700 15.10161 2.001682 49.97829
55.24700 15.00078 1.999647 50.01011
55.29700 14.90087 1.997266 49.95115
55.34700 14.80058 1.995150 49.97403
55.39700 14.70048 1.993034 49.92867
55.44700 14.60132 1.991045 49.84980
55.49700 14.50045 1.989073 49.87510
55.54700 14.40034 1.987001 49.78854
55.59700 14.30015 1.984944 49.88670
55.64700 14.19989 1.982974 50.01535
55.69700 14.09910 1.981084 49.97474
55.74700 13.99993 1.979113 50.07558
55.79700 13.89921 1.977305 49.95948
55.84700 13.79945 1.975469 49.94680
55.89700 13.70034 1.973538 49.90877
55.94700 13.59926 1.971662 49.92283
55.99700 13.49934 1.969807 49.88474
56.04700 13.39858 1.967827 49.88132
56.09700 13.30022 1.965754 49.95852
56.14700 13.19916 1.963626 49.81710
56.19700 13.10032 1.961724 50.21724
56.24700 12.99940 1.959688 50.03598
56.29700 12.89842 1.957962 49.86484
56.34700 12.79893 1.956180 50.09152
56.39700 12.69822 1.954464 50.05010
56.44700 12.59817 1.952896 50.03486
56.49700 12.49852 1.951352 50.11888
56.54700 12.39779 1.949718 49.83511
56.59700 12.29773 1.947986 50.17148
56.64700 12.19802 1.946375 49.86344
56.69700 12.09773 1.944815 50.04084
56.74700 11.99768 1.942975 50.01861
56.79700 11.89745 1.941286 49.90287
56.84700 11.79785 1.939468 50.00500
56.89700 11.69763 1.937851 49.97978
56.94700 11.59735 1.936144 50.06384
56.99700 11.49748 1.934500 50.03470
57.04700 11.39802 1.932858 50.06366
57.09700 11.29798 1.931525 50.11556
57.14700 11.19800 1.930019 49.91050
57.19700 11.09759 1.928660 50.05741
57.24700 10.99744 1.927415 50.05250
57.29700 10.89777 1.926178 49.97829
57.34700 10.79676 1.925022 49.91430
57.39700 10.69686 1.923858 49.86783
57.44700 10.59644 1.922642 49.94406
57.49700 10.49705 1.921254 49.99635
57.54700 10.39658 1.919983 49.93758
57.59700 10.29693 1.918817 50.08215
57.64700 10.19707 1.917486 50.04393
57.69700 10.09601 1.916210 49.91788
57.74700 9.997062 1.914799 49.97598
57.79700 9.897870 1.913210 49.82769
57.84700 9.796555 1.911844 49.84220
57.89700 9.696097 1.910471 50.11596
57.94700 9.596016 1.909301 50.23604
57.99700 9.496868 1.908142 49.92950
58.04700 9.396965 1.906934 50.03244
58.09700 9.296699 1.905752 49.94943
58.14700 9.196235 1.904735 50.05961
58.19700 9.097281 1.903577 49.84270
58.24700 8.996337 1.902623 49.90965
58.29700 8.896028 1.901528 49.87918
58.34700 8.796785 1.900493 50.15768
58.39700 8.695786 1.899599 50.04585
58.44700 8.596308 1.898621 50.04052
58.49700 8.496078 1.897608 50.09071
58.54700 8.396451 1.896557 50.06044
58.59700 8.296369 1.895490 49.91598
58.64700 8.196455 1.894470 49.99172
58.69700 8.097385 1.893394 49.83081
58.74700 7.996916 1.892532 50.11106
58.79700 7.896558 1.891759 49.84016
58.84700 7.796890 1.890857 50.16225
58.89700 7.696870 1.890060 49.92266
58.94700 7.596748 1.889285 49.93254
58.99700 7.496338 1.888594 50.19738
59.04700 7.397540 1.887926 50.04715
59.09700 7.297348 1.887164 50.01031
59.14700 7.196446 1.886386 49.97406
59.19700 7.096305 1.885745 50.02616
59.24700 6.996680 1.885106 50.02303
59.29700 6.896347 1.884509 49.96266
59.34700 6.796765 1.884088 49.89930
59.39700 6.696600 1.883388 50.00429
59.44700 6.596084 1.882823 50.06266
59.49700 6.496910 1.882041 49.95502
59.54700 6.396809 1.881409 49.99710
59.59700 6.296178 1.880758 50.10282
59.64700 6.195715 1.879929 50.06353
59.69700 6.097040 1.879192 49.97660
59.74700 5.995940 1.878426 50.11390
59.79700 5.895430 1.877534 50.15772
59.84700 5.797100 1.876840 50.02726
59.89700 5.695992 1.875952 49.92820
59.94700 5.596152 1.875197 49.91329
59.99700 5.496230 1.874412 49.99374
60.04700 5.396457 1.873688 49.99297
60.09700 5.296538 1.872878 50.14696
60.14700 5.196858 1.872174 50.05476
60.19700 5.095962 1.871661 50.15004
60.24700 4.996880 1.871088 49.95809
60.29700 4.896230 1.870452 50.02076
60.34700 4.796360 1.869903 49.85678
60.39700 4.696824 1.869224 50.01463
60.44700 4.596230 1.868744 50.05146
60.49700 4.496682 1.868034 49.96058
60.54700 4.396869 1.867618 49.85332
60.59700 4.295838 1.867277 49.93914
60.64700 4.197559 1.866736 49.91780
60.69700 4.096313 1.866316 50.02472
60.74700 3.996628 1.865893 50.05522
60.79700 3.895918 1.865547 50.07912
60.84700 3.796267 1.864970 49.93648
60.89700 3.696972 1.864428 49.94062
60.94700 3.596362 1.864014 50.12154
60.99700 3.496292 1.863596 50.03563
61.04700 3.396559 1.863141 50.12656
61.09700 3.297080 1.862588 50.04581
61.14700 3.196882 1.862120 49.78550
61.19700 3.096980 1.861712 50.00052
61.24700 2.997278 1.861209 50.08442
61.29700 2.896265 1.860766 49.95936
61.34700 2.796346 1.860239 49.99690
61.39700 2.697405 1.859792 49.96188
61.44700 2.597438 1.859361 50.15893
61.49700 2.496824 1.858855 50.09750
61.54700 2.396828 1.858210 50.00030
61.59700 2.297937 1.857752 49.84697
61.64700 2.197154 1.857451 49.90933
61.69700 2.096622 1.857240 49.87398
61.74700 1.997020 1.856912 49.74439
61.79700 1.897128 1.856568 50.09705
61.84700 1.797662 1.856020 49.81660
61.89700 1.697218 1.855513 50.10004
61.94700 1.597423 1.854869 50.06424
61.99700 1.496671 1.854528 50.01672
62.04700 1.398920 1.854535 50.10026
62.09700 1.326888 1.843214 49.82544
62.14700 1.279023 1.743844 49.94420
62.19700 1.241044 1.617451 49.95671
62.24700 1.210134 1.485468 50.04500
62.29700 1.182982 1.353676 50.02372
62.34700 1.160699 1.225936 50.06938
62.39700 1.140559 1.103330 50.00682
62.44700 1.122525 0.9947988 50.13114
62.49700 1.107144 0.8943574 50.06432
62.54700 1.094164 0.8026818 49.98318
62.59700 1.083830 0.7222314 50.08426
62.64700 1.073626 0.6547871 50.08100
62.69700 1.064996 0.5950156 50.11563
62.74700 1.057379 0.5356270 49.91524
62.79700 1.050262 0.4908710 50.06386
62.84700 1.045141 0.4491668 49.92383
62.89700 1.040194 0.4160404 49.88052
62.94700 1.034835 0.3847704 50.04818
62.99700 1.031163 0.3589456 49.95346
63.04700 1.028029 0.3365306 49.93744
63.09700 1.025185 0.3194324 50.03042
63.14700 1.021825 0.3034140 50.14722
63.19700 1.019393 0.2882516 50.04371
63.24700 1.018276 0.2770744 49.86721
63.29700 1.016080 0.2673935 50.02580
63.34700 1.014586 0.2584926 50.14086
63.39700 1.012740 0.2493369 49.82632
63.44700 1.010909 0.2405306 49.84273
63.49700 1.011235 0.2321840 50.13134
63.54700 1.008872 0.2241698 49.98986
63.59700 1.008044 0.2163896 49.89492
63.64700 1.006693 0.2092783 50.02104
63.69700 1.006337 0.2025945 49.99900
63.74700 1.006233 0.1963475 50.03266
63.79700 1.005468 0.1905538 50.14346
63.84700 1.004438 0.1852801 50.06968
63.89700 1.004355 0.1803568 50.03460
63.94700 1.003212 0.1760315 50.06330
63.99700 1.002752 0.1721029 50.02393
64.04700 1.002448 0.1685086 49.96240
64.09700 1.002808 0.1652762 50.03090
64.14700 1.000814 0.1624326 50.08484
64.19701 1.001126 0.1598548 50.06407
64.24700 1.000740 0.1574039 49.94446
64.29700 1.000327 0.1553752 50.06885
64.34700 1.000306 0.1535278 50.01175
64.39700 0.9992486 0.1516569 50.02354
64.44701 0.9994569 0.1501000 50.04326
64.49700 0.9996874 0.1487533 50.18936
64.54700 0.9986962 0.1474398 49.79947
64.59700 0.9993934 0.1461257 50.01000
64.64700 0.9986350 0.1450901 50.05844
64.69701 0.9984610 0.1440776 49.89425
64.74700 0.9988266 0.1431284 49.92076
64.79700 0.9987588 0.1421804 50.13320
-2.000000 2.000000 0.0000000 0.0000000