File: imagens/notebooks/dados experimentais/dsc/Karl_CTAB100 Ur 38%.txt
CLOSED
Version	1.0
Language	English
Run	1
RunSerial	143
Instrument	DSC Q100 V9.9 Build 303
Module	DSC Standard Cell FC
Operator	LL
File	\\Niger\ta\Data\DSC\2018\Geral\Karl_CTAB100 Ur 38%.001
ProcName	Karl
InstSerial	0100-1211
Sample	CTAB100 Ur 38%
Size	13.7500	mg
Method	Karl
Comment
Xcomment	Pan: Aluminum Hermetic
Xcomment	Gas1: Nitrogen 50.0 ml/min
Xcomment	Gas2: Nitrogen 0.0 ml/min
Text
Exotherm	UP
Kcell	1.09030
Calib	-11.7822
TempCal	1	pts	158.71	156.60
TzeroDt	-90.0515 -0.0093 2.2263
TzeroDtz	-90.0515 0.0466 2.4421
InstCalFile	Tzero: \\Niger\ta\Data\DSC\CALIBRATION\20122016\CALIBRATION\0_RCS_12_20_2016 17_23_31.TZR
InstCalFile	Baseline: \\Niger\ta\Data\DSC\CALIBRATION\20122016\L.Base 20122016
InstCalFile	Sapphire: \\Niger\ta\Data\DSC\CALIBRATION\20122016\Safira 20122017.001
InstCalDate	Tzero 2016-12-20 Time 19:23:31
TempRange	-90.04 to 395.23 °C at 19.96 °C/min Heat Only
AutoZero	Delta T Offset 0.000 uV
AutoZero	Delta T0 Offset 0.000 uV
Controls	Gas 1  Event Off  Sampling 0.2
Cell#	FC-02451
CoolingUnit	RCS
SelHeatFlow	Heat Flow T4 (mW)
AutoAnalysis	Off
MacroFile
Nsig	4
Sig1	Time (min)
Sig2	Temperature (°C)
Sig3	Heat Flow (mW)
Sig4	Sample Purge Flow (mL/min)
Date	2018-05-15
Time	13:12:49
OrgMethod	1: Equilibrate at 1.00 °C
OrgMethod	2: Ramp 2.00 °C/min to 60.00 °C
OrgMethod	3: Isothermal for 3.00 min
OrgMethod	4: Mark end of cycle 1
OrgMethod	5: Ramp 2.00 °C/min to 1.00 °C
OrgMethod	6: Isothermal for 3.00 min
OrgMethod	7: Mark end of cycle 2
OrgFile	C:\TA\Data\DSC\2018\Geral\Karl_CTAB100 Ur 38%.001
3.33324E-4 1.212475 1.488581 49.95198
0.05033332 1.193960 1.309759 50.08984
0.1003333 1.202119 1.092157 49.98530
0.1503333 1.235252 0.8423899 49.96090
0.2003333 1.281229 0.5963672 50.16222
0.2503333 1.335938 0.3525724 50.08258
0.3003333 1.394572 0.1354932 49.93234
0.3503333 1.459997 -.05798111 50.01023
0.4003334 1.530896 -0.2405084 49.91894
0.4503334 1.603383 -0.4010385 50.11552
0.5003334 1.681418 -0.5387385 49.98093
0.5503332 1.761452 -0.6657990 49.91562
0.6003332 1.843646 -0.7757100 50.02440
0.6503332 1.929076 -0.8628891 49.81012
0.7003332 2.014771 -0.9469788 50.04764
0.7503332 2.103568 -1.018585 50.00053
0.8003332 2.191725 -1.081748 50.09597
0.8503332 2.283556 -1.138444 49.88516
0.9003332 2.374057 -1.185454 49.82472
0.9503334 2.467377 -1.223711 50.03540
1.000333 2.560360 -1.260205 49.95186
1.050334 2.654031 -1.292826 50.08468
1.100334 2.749616 -1.319258 50.02324
1.150334 2.844032 -1.341872 49.97540
1.200334 2.940288 -1.361908 50.00834
1.250334 3.035135 -1.378319 50.05691
1.300334 3.131102 -1.394028 49.93574
1.350333 3.227924 -1.407424 48.96931
1.400333 3.324033 -1.419316 50.09220
1.450334 3.422580 -1.430108 50.03253
1.500333 3.519944 -1.439555 49.80822
1.550334 3.616485 -1.450033 49.88388
1.600334 3.714420 -1.459206 49.84836
1.650333 3.812702 -1.468314 50.17786
1.700334 3.909640 -1.477592 49.82974
1.750334 4.009519 -1.486389 49.86478
1.800334 4.106856 -1.495702 49.84617
1.850334 4.205998 -1.502957 50.04072
1.900334 4.303412 -1.510040 50.11396
1.950334 4.402596 -1.516625 49.95506
2.000334 4.501310 -1.523402 49.88330
2.050333 4.601372 -1.529489 49.96950
2.100334 4.699394 -1.535292 49.87553
2.150334 4.798717 -1.540789 50.07698
2.200334 4.896868 -1.545936 49.89064
2.250334 4.996216 -1.550601 49.94633
2.300333 5.094996 -1.555200 49.93271
2.350334 5.195209 -1.559195 49.90470
2.400334 5.295230 -1.563035 50.00145
2.450334 5.393545 -1.566505 49.94344
2.500334 5.493242 -1.569336 50.08002
2.550333 5.592693 -1.572043 49.97920
2.600333 5.691008 -1.574601 50.02867
2.650333 5.789994 -1.577090 50.04094
2.700333 5.888620 -1.579448 50.10356
2.750333 5.987964 -1.581748 50.11592
2.800333 6.087781 -1.584211 50.01570
2.850333 6.186456 -1.586538 50.80364
2.900333 6.286798 -1.588922 49.97668
2.950333 6.386161 -1.591332 49.95266
3.000333 6.483832 -1.593596 50.10297
3.050333 6.584780 -1.595868 50.02850
3.100333 6.684388 -1.598073 49.86828
3.150333 6.784856 -1.600121 50.10766
3.200333 6.883511 -1.602176 50.02038
3.250333 6.983296 -1.603982 49.90557
3.300333 7.082790 -1.605730 50.04178
3.350333 7.183155 -1.607440 50.02873
3.400333 7.281943 -1.608967 49.85698
3.450333 7.382700 -1.610183 50.12546
3.500333 7.482558 -1.611256 49.29101
3.550333 7.581108 -1.612717 50.07165
3.600333 7.680238 -1.613681 49.92636
3.650333 7.779941 -1.614690 49.97180
3.700333 7.878884 -1.615911 49.82598
3.750333 7.979741 -1.616748 49.97867
3.800333 8.079094 -1.617901 49.91874
3.850333 8.179369 -1.618788 50.04190
3.900333 8.278680 -1.619915 50.02770
3.950333 8.379068 -1.620851 50.05398
4.000333 8.478270 -1.621882 50.06800
4.050333 8.577179 -1.622894 49.83324
4.100333 8.676189 -1.624202 50.08276
4.150333 8.776466 -1.625156 49.94938
4.200333 8.876694 -1.626151 50.18454
4.250333 8.976399 -1.627312 49.82797
4.300333 9.076974 -1.628462 50.06922
4.350333 9.177006 -1.629624 50.06834
4.400333 9.275356 -1.630688 49.97229
4.450333 9.376881 -1.631706 50.04959
4.500333 9.475488 -1.632858 49.87560
4.550333 9.575312 -1.633948 50.12910
4.600333 9.675129 -1.635053 49.95830
4.650333 9.776700 -1.636003 50.08678
4.700333 9.875756 -1.636942 50.03067
4.750333 9.974924 -1.637778 49.97253
4.800333 10.07573 -1.638356 49.91272
4.850333 10.17558 -1.639073 49.98884
4.900333 10.27391 -1.639825 49.96444
4.950333 10.37521 -1.640281 49.95190
5.000333 10.47421 -1.641167 49.79059
5.050333 10.57330 -1.641784 49.99956
5.100333 10.67398 -1.642379 49.95810
5.150333 10.77461 -1.642880 50.37960
5.200333 10.87380 -1.643448 49.91348
5.250332 10.97341 -1.644128 49.80793
5.300332 11.07281 -1.644795 49.89004
5.350332 11.17337 -1.645311 49.96026
5.400332 11.27317 -1.645992 49.86316
5.450332 11.37314 -1.646640 49.92208
5.500332 11.47246 -1.647077 49.89532
5.550332 11.57362 -1.647871 49.95236
5.600332 11.67293 -1.648413 50.24154
5.650332 11.77349 -1.649089 48.92076
5.700332 11.87279 -1.650026 49.84239
5.750332 11.97289 -1.650601 50.06986
5.800332 12.07318 -1.651089 49.88157
5.850332 12.17340 -1.651514 50.08814
5.900332 12.27290 -1.651980 49.88724
5.950332 12.37295 -1.652486 49.87460
6.000332 12.47205 -1.653045 49.78824
6.050332 12.57241 -1.653722 49.81620
6.100332 12.67239 -1.654121 50.07134
6.150332 12.77210 -1.654766 50.00108
6.200332 12.87260 -1.655084 50.12626
6.250332 12.97144 -1.655542 50.12411
6.300332 13.07084 -1.655874 50.03276
6.350332 13.17160 -1.656387 49.88541
6.400332 13.27252 -1.656725 50.15746
6.450332 13.37102 -1.657333 50.04426
6.500332 13.47115 -1.657953 49.73240
6.550332 13.57112 -1.658581 50.06438
6.600332 13.67252 -1.658908 50.08426
6.650332 13.77149 -1.659579 50.11297
6.700332 13.87142 -1.659878 50.03372
6.750332 13.97054 -1.660379 50.07934
6.800332 14.07026 -1.660880 50.00760
6.850332 14.17128 -1.661411 49.85052
6.900332 14.27069 -1.661910 49.91090
6.950332 14.37114 -1.662504 50.02209
7.000332 14.47235 -1.662974 50.01646
7.050332 14.57014 -1.663784 50.04856
7.100332 14.67034 -1.664499 49.84560
7.150332 14.77080 -1.665064 50.05420
7.200332 14.87134 -1.665651 50.11394
7.250332 14.97209 -1.666319 49.77387
7.300332 15.07143 -1.666912 49.96106
7.350332 15.17040 -1.667600 49.86284
7.400332 15.27140 -1.667941 50.05568
7.450332 15.37050 -1.668311 49.94992
7.500332 15.47242 -1.668426 49.37344
7.550332 15.57037 -1.668399 50.16562
7.600332 15.67071 -1.668520 50.09048
7.650332 15.77010 -1.668621 50.10380
7.700332 15.87008 -1.668529 50.04355
7.750332 15.97034 -1.668536 50.09807
7.800332 16.06945 -1.668785 50.14141
7.850332 16.17001 -1.668950 50.07429
7.900332 16.27132 -1.669144 49.91140
7.950332 16.37040 -1.669509 49.84356
8.000334 16.46971 -1.669937 50.11788
8.050332 16.57055 -1.670343 49.99754
8.100332 16.67009 -1.670944 50.08316
8.150332 16.77037 -1.671388 49.99746
8.200332 16.86951 -1.671998 50.08068
8.250334 16.97064 -1.672302 49.88006
8.300332 17.06894 -1.672896 50.10634
8.350332 17.16971 -1.673300 49.96760
8.400332 17.26917 -1.673591 50.12500
8.450332 17.36904 -1.674019 49.85828
8.500334 17.46945 -1.674056 50.18154
8.550332 17.56874 -1.674194 50.02011
8.600332 17.66798 -1.674472 50.02424
8.650332 17.76763 -1.674633 49.92947
8.700332 17.86813 -1.674789 50.04050
8.750334 17.96758 -1.674986 49.94017
8.800332 18.06766 -1.675262 49.92276
8.850332 18.16778 -1.675721 50.06795
8.900332 18.26618 -1.676338 50.05885
8.950332 18.36755 -1.676735 50.01590
9.000334 18.46718 -1.677392 49.97074
9.050332 18.56636 -1.677915 49.93150
9.100332 18.66743 -1.678386 49.80774
9.150332 18.76780 -1.679198 49.72352
9.200332 18.86689 -1.679966 49.89522
9.250334 18.96726 -1.680592 50.08054
9.300332 19.06758 -1.681358 49.93560
9.350332 19.16606 -1.682012 49.50119
9.400332 19.26689 -1.682771 50.19688
9.450332 19.36676 -1.683472 49.83008
9.500334 19.46748 -1.684139 50.01550
9.550332 19.56763 -1.684416 49.76834
9.600332 19.66783 -1.684801 49.87008
9.650332 19.76773 -1.685059 50.04330
9.700332 19.86750 -1.685546 50.00899
9.750334 19.96750 -1.685903 49.92804
9.800332 20.06748 -1.686282 49.97055
9.850332 20.16597 -1.686853 50.03920
9.900332 20.26692 -1.687138 49.88719
9.950332 20.36604 -1.687759 49.93152
10.00033 20.46686 -1.688208 49.93008
10.05033 20.56670 -1.688671 49.94620
10.10033 20.66668 -1.689168 50.02816
10.15033 20.76602 -1.689560 50.14336
10.20033 20.86598 -1.690284 48.86041
10.25033 20.96690 -1.690705 50.05728
10.30033 21.06689 -1.691236 49.99726
10.35033 21.16566 -1.691536 50.12266
10.40033 21.26706 -1.691740 50.00180
10.45033 21.36553 -1.692257 50.02810
10.50034 21.46548 -1.692538 49.82137
10.55033 21.56590 -1.693041 50.05786
10.60033 21.66589 -1.693733 50.01562
10.65033 21.76583 -1.694420 50.06756
10.70033 21.86603 -1.695028 49.96738
10.75034 21.96626 -1.695595 49.86496
10.80033 22.06549 -1.696084 49.89482
10.85033 22.16508 -1.696474 49.87330
10.90033 22.26572 -1.697014 49.99214
10.95033 22.36555 -1.697486 50.07868
11.00034 22.46511 -1.697860 49.91037
11.05033 22.56570 -1.698051 49.94928
11.10033 22.66508 -1.698376 49.86383
11.15033 22.76446 -1.699040 50.03034
11.20033 22.86463 -1.699545 49.87800
11.25034 22.96435 -1.700289 50.03639
11.30033 23.06439 -1.701178 50.10515
11.35033 23.16460 -1.701948 50.03367
11.40033 23.26426 -1.702635 49.87164
11.45033 23.36421 -1.703689 49.98872
11.50034 23.46464 -1.704552 49.80802
11.55033 23.56429 -1.705504 50.16140
11.60033 23.66405 -1.706426 50.16804
11.65033 23.76477 -1.707328 50.17086
11.70033 23.86537 -1.708097 50.02389
11.75034 23.96414 -1.709216 49.93566
11.80033 24.06379 -1.710426 49.95589
11.85033 24.16498 -1.711756 50.09859
11.90033 24.26502 -1.712904 49.86784
11.95033 24.36538 -1.714020 49.99593
12.00034 24.46548 -1.715274 49.36392
12.05033 24.56592 -1.716453 49.95166
12.10033 24.66433 -1.717728 49.90219
12.15033 24.76537 -1.718820 50.08936
12.20033 24.86465 -1.720117 50.13564
12.25034 24.96558 -1.721811 49.91638
12.30033 25.06276 -1.723492 50.13100
12.35033 25.16352 -1.725675 50.14308
12.40033 25.26185 -1.728473 50.77067
12.45033 25.36172 -1.731836 49.93134
12.50034 25.46148 -1.735963 50.15842
12.55033 25.56060 -1.740549 49.98568
12.60033 25.65906 -1.747275 49.88966
12.65033 25.75751 -1.756258 50.03322
12.70033 25.85740 -1.770676 50.06006
12.75034 25.95613 -1.795216 49.98646
12.80033 26.05459 -1.826687 49.97642
12.85033 26.15130 -1.866256 50.11054
12.90033 26.24862 -1.915866 50.16339
12.95034 26.34425 -1.967487 49.82657
13.00034 26.44077 -2.030403 50.08428
13.05033 26.53690 -2.090212 49.80196
13.10033 26.63224 -2.157606 49.86320
13.15033 26.72546 -2.234708 49.90208
13.20034 26.82071 -2.303879 49.94437
13.25034 26.91374 -2.376924 49.95886
13.30033 27.00754 -2.449093 50.01028
13.35033 27.10235 -2.517691 49.92773
13.40033 27.19590 -2.588873 49.99444
13.45034 27.29120 -2.654870 50.04478
13.50034 27.38574 -2.709166 50.08119
13.55033 27.48176 -2.769310 50.03956
13.60033 27.57664 -2.820688 49.91684
13.65033 27.67289 -2.866599 50.01786
13.70034 27.76814 -2.913645 50.00532
13.75034 27.86277 -2.951673 49.97711
13.80033 27.96047 -2.989255 50.07043
13.85033 28.05666 -3.025478 50.15213
13.90033 28.15423 -3.058724 49.90778
13.95034 28.25009 -3.087043 49.80964
14.00034 28.34756 -3.118742 49.71241
14.05033 28.44550 -3.140450 49.97016
14.10033 28.54495 -3.161562 49.87144
14.15033 28.64145 -3.182279 49.89218
14.20034 28.74030 -3.200602 50.08689
14.25034 28.83831 -3.217144 49.74398
14.30033 28.93610 -3.234259 50.01022
14.35033 29.03544 -3.245535 50.00697
14.40033 29.13537 -3.258491 50.00322
14.45034 29.23258 -3.271670 50.00967
14.50034 29.33138 -3.282782 50.00342
14.55033 29.43167 -3.291516 50.00924
14.60033 29.53052 -3.301941 49.93036
14.65033 29.63030 -3.311870 50.03120
14.70034 29.72858 -3.320044 50.09189
14.75034 29.82791 -3.327781 50.05174
14.80033 29.92832 -3.334790 49.99411
14.85033 30.02680 -3.341115 50.12122
14.90033 30.12622 -3.346553 50.20216
14.95034 30.22758 -3.351288 50.62125
15.00034 30.32776 -3.355084 50.05750
15.05033 30.42840 -3.357600 50.13564
15.10033 30.52660 -3.358682 49.90086
15.15033 30.62856 -3.358265 50.01188
15.20034 30.72805 -3.356032 50.07194
15.25034 30.82766 -3.351578 50.01122
15.30033 30.93081 -3.344580 49.91746
15.35033 31.02996 -3.331494 49.76638
15.40033 31.13203 -3.311762 50.25976
15.45034 31.23534 -3.286636 50.15213
15.50034 31.33686 -3.253009 50.11194
15.55033 31.43864 -3.215040 49.32842
15.60033 31.54120 -3.174925 49.92037
15.65033 31.64398 -3.139494 49.29589
15.70034 31.74805 -3.096100 49.95530
15.75034 31.85134 -3.057840 49.94270
15.80033 31.95531 -3.028408 50.08040
15.85033 32.05631 -3.000949 49.82618
15.90033 32.15936 -2.976921 49.95422
15.95034 32.26042 -2.948278 50.03951
16.00033 32.36293 -2.909525 50.18894
16.05033 32.46740 -2.836522 50.02836
16.10033 32.57378 -2.737681 49.74072
16.15033 32.68008 -2.610445 50.05738
16.20033 32.79065 -2.478615 49.94662
16.25033 32.90040 -2.365888 50.03700
16.30033 33.00780 -2.271336 50.14757
16.35033 33.11692 -2.186017 49.86222
16.40033 33.22249 -2.123348 50.04156
16.45033 33.32910 -2.065147 49.97246
16.50033 33.43366 -2.018724 50.06186
16.55033 33.53713 -1.979550 50.00918
16.60033 33.63965 -1.946092 49.70724
16.65033 33.74305 -1.918566 50.21588
16.70033 33.84667 -1.897167 50.00216
16.75033 33.94882 -1.879733 50.10712
16.80033 34.04988 -1.866526 50.00672
16.85033 34.15214 -1.853962 49.97446
16.90033 34.25222 -1.843633 49.93186
16.95033 34.35372 -1.833959 50.70059
17.00033 34.45388 -1.826090 49.79414
17.05033 34.55546 -1.818289 49.94752
17.10033 34.65596 -1.810929 50.14428
17.15033 34.75542 -1.804298 49.91800
17.20033 34.85690 -1.798108 49.88044
17.25033 34.95722 -1.792588 50.00738
17.30033 35.05764 -1.787194 50.34951
17.35033 35.15788 -1.782546 49.84484
17.40033 35.25802 -1.778432 50.00152
17.45033 35.35656 -1.774764 50.15180
17.50033 35.45769 -1.771236 50.07746
17.55033 35.55690 -1.768380 50.82232
17.60033 35.65652 -1.765756 49.83276
17.65033 35.75717 -1.763938 50.03203
17.70033 35.85700 -1.762265 50.15336
17.75033 35.95720 -1.761224 49.94998
17.80033 36.05780 -1.760296 49.85312
17.85033 36.15607 -1.759747 49.88830
17.90033 36.25710 -1.759295 50.00699
17.95033 36.35798 -1.759026 50.12442
18.00033 36.45640 -1.759140 50.22292
18.05033 36.55768 -1.759279 50.02443
18.10033 36.65786 -1.759494 50.11994
18.15033 36.75776 -1.759875 49.84880
18.20033 36.85702 -1.760044 50.75162
18.25033 36.95700 -1.760296 50.13461
18.30033 37.05697 -1.760516 50.13016
18.35033 37.15825 -1.760555 50.03835
18.40033 37.25813 -1.760708 50.04303
18.45033 37.35657 -1.760938 50.01334
18.50033 37.45542 -1.760982 49.78430
18.55033 37.55696 -1.761196 49.92084
18.60033 37.65676 -1.761252 49.87125
18.65033 37.75669 -1.761418 49.99680
18.70033 37.85534 -1.761525 50.12883
18.75033 37.95598 -1.761524 49.96304
18.80033 38.05566 -1.761707 50.14462
18.85033 38.15606 -1.762108 50.02340
18.90033 38.25528 -1.762619 50.02967
18.95033 38.35527 -1.762868 50.03214
19.00033 38.45556 -1.763218 50.02643
19.05033 38.55420 -1.763852 49.94843
19.10033 38.65505 -1.764393 49.94876
19.15033 38.75590 -1.764787 50.03536
19.20033 38.85512 -1.765313 49.95843
19.25033 38.95544 -1.765936 49.91608
19.30033 39.05393 -1.766614 50.00408
19.35033 39.15420 -1.767352 49.96106
19.40033 39.25560 -1.767967 50.07252
19.45033 39.35456 -1.768708 49.97220
19.50033 39.45600 -1.769288 50.07878
19.55033 39.55498 -1.770026 50.07633
19.60033 39.65537 -1.770576 49.87750
19.65033 39.75508 -1.770839 50.01002
19.70033 39.85465 -1.771391 50.00446
19.75033 39.95558 -1.771744 49.87783
19.80033 40.05476 -1.772035 50.30256
19.85033 40.15452 -1.772598 50.06934
19.90033 40.25280 -1.773172 49.14130
19.95033 40.35440 -1.773530 49.96522
20.00033 40.45486 -1.774090 50.00832
20.05033 40.55269 -1.774657 50.00484
20.10033 40.65358 -1.775400 49.89860
20.15033 40.75317 -1.775990 49.84797
20.20033 40.85358 -1.776695 50.11426
20.25033 40.95456 -1.777599 49.93628
20.30033 41.05350 -1.778629 50.03294
20.35033 41.15394 -1.779103 50.05422
20.40033 41.25370 -1.779923 50.01359
20.45033 41.35351 -1.780566 49.93868
20.50033 41.45348 -1.781275 49.92045
20.55033 41.55326 -1.781841 50.06709
20.60033 41.65395 -1.782596 50.00717
20.65033 41.75325 -1.782944 50.00606
20.70033 41.85378 -1.783560 49.89276
20.75033 41.95460 -1.783999 50.01416
20.80033 42.05334 -1.784422 50.05629
20.85033 42.15308 -1.784974 50.02133
20.90033 42.25287 -1.785548 50.07444
20.95033 42.35174 -1.785816 50.03305
21.00033 42.45340 -1.785883 50.00772
21.05033 42.55188 -1.786178 50.01267
21.10033 42.65246 -1.786066 49.99367
21.15033 42.75066 -1.786447 49.87705
21.20033 42.85154 -1.786791 50.08803
21.25033 42.95258 -1.787165 50.04980
21.30033 43.05188 -1.788035 49.91296
21.35033 43.15128 -1.788728 49.81563
21.40033 43.25183 -1.789611 50.14776
21.45033 43.35132 -1.790496 50.16342
21.50033 43.45062 -1.791508 49.85630
21.55033 43.55053 -1.792337 50.18451
21.60033 43.65107 -1.793176 49.99804
21.65033 43.75129 -1.794108 50.02160
21.70033 43.85118 -1.795139 50.02646
21.75033 43.95313 -1.796042 49.91414
21.80033 44.05092 -1.797021 49.93804
21.85033 44.15124 -1.797827 50.06116
21.90033 44.25137 -1.798676 49.98314
21.95033 44.35178 -1.799384 50.02780
22.00033 44.45324 -1.800126 50.09102
22.05033 44.55153 -1.800787 50.09724
22.10033 44.65060 -1.801286 50.19150
22.15033 44.75126 -1.801912 49.93166
22.20033 44.85214 -1.802536 50.08243
22.25033 44.95150 -1.803259 49.94700
22.30033 45.05157 -1.804011 49.89637
22.35033 45.15056 -1.804723 49.86158
22.40033 45.25120 -1.805333 50.03621
22.45033 45.35054 -1.806181 49.99634
22.50033 45.45150 -1.806508 50.05796
22.55033 45.54982 -1.807202 50.12766
22.60033 45.65048 -1.807286 50.07402
22.65033 45.74918 -1.807492 49.96446
22.70033 45.84902 -1.807634 49.81438
22.75033 45.94900 -1.808094 49.78934
22.80033 46.04891 -1.808678 49.88166
22.85033 46.14871 -1.809444 49.82163
22.90033 46.24928 -1.810268 50.05622
22.95033 46.34974 -1.811171 50.10415
23.00033 46.44866 -1.812228 49.92678
23.05033 46.54990 -1.813049 49.87172
23.10033 46.65024 -1.814046 50.07540
23.15033 46.75040 -1.815080 49.93230
23.20033 46.84880 -1.816285 49.93246
23.25033 46.94877 -1.817332 49.90893
23.30033 47.04840 -1.818142 49.91411
23.35033 47.14791 -1.818850 49.91913
23.40033 47.24715 -1.819577 49.88912
23.45033 47.34824 -1.820203 49.93670
23.50033 47.44847 -1.820881 49.97317
23.55033 47.54914 -1.821577 50.15764
23.60033 47.64758 -1.822195 49.86002
23.65033 47.74784 -1.822749 49.87486
23.70033 47.84850 -1.823568 50.01596
23.75033 47.94670 -1.824247 49.94941
23.80033 48.04822 -1.824994 50.07670
23.85033 48.14824 -1.825915 49.90538
23.90033 48.24709 -1.826836 49.81742
23.95033 48.34646 -1.827842 50.08658
24.00033 48.44688 -1.828780 49.91720
24.05033 48.54656 -1.829608 49.98737
24.10033 48.64719 -1.830488 49.93741
24.15033 48.74727 -1.831209 49.81672
24.20033 48.84670 -1.832088 49.90311
24.25033 48.94762 -1.833153 49.91085
24.30033 49.04684 -1.834287 49.91234
24.35033 49.14679 -1.835329 50.06094
24.40033 49.24691 -1.836679 49.99493
24.45033 49.34694 -1.837874 49.87190
24.50033 49.44601 -1.839064 50.16856
24.55033 49.54610 -1.839861 50.07372
24.60033 49.64586 -1.840458 50.04620
24.65033 49.74446 -1.841189 49.93800
24.70033 49.84486 -1.841553 50.06382
24.75033 49.94494 -1.842167 49.39518
24.80033 50.04410 -1.842594 50.02646
24.85033 50.14431 -1.843211 50.04956
24.90033 50.24448 -1.843942 49.84415
24.95033 50.34581 -1.844644 50.10974
25.00033 50.44420 -1.845510 50.09803
25.05033 50.54424 -1.846394 49.84474
25.10033 50.64414 -1.847621 50.16869
25.15033 50.74502 -1.848622 49.94250
25.20033 50.84572 -1.849794 49.77526
25.25033 50.94424 -1.851041 49.95570
25.30033 51.04436 -1.852399 49.91050
25.35033 51.14478 -1.853612 50.21489
25.40033 51.24434 -1.854752 49.92669
25.45033 51.34321 -1.856086 50.04662
25.50033 51.44432 -1.857251 50.04500
25.55033 51.54326 -1.858517 49.89406
25.60033 51.64356 -1.859512 49.97937
25.65033 51.74437 -1.860504 50.06240
25.70033 51.84406 -1.861339 49.98697
25.75033 51.94433 -1.862369 49.90148
25.80033 52.04360 -1.863328 50.16687
25.85033 52.14356 -1.864656 50.11606
25.90033 52.24322 -1.865813 50.04532
25.95033 52.34352 -1.866920 49.83227
26.00033 52.44459 -1.867754 49.95078
26.05033 52.54363 -1.868752 50.12784
26.10033 52.64326 -1.869690 50.03580
26.15033 52.74242 -1.870371 49.95100
26.20033 52.84318 -1.871177 50.04188
26.25033 52.94184 -1.872202 50.00675
26.30033 53.04192 -1.873074 50.08028
26.35033 53.14171 -1.873954 50.02776
26.40033 53.24168 -1.874975 49.89539
26.45033 53.34121 -1.875814 50.06188
26.50033 53.44137 -1.876850 49.86850
26.55033 53.54099 -1.877848 49.89146
26.60033 53.64250 -1.878834 49.94199
26.65033 53.74116 -1.880072 50.06702
26.70033 53.84026 -1.881328 49.97574
26.75033 53.93989 -1.882532 50.03160
26.80033 54.04093 -1.883188 50.06930
26.85033 54.13991 -1.884310 49.99563
26.90033 54.24006 -1.885226 49.97812
26.95033 54.33974 -1.886154 50.02891
27.00033 54.43970 -1.887296 50.01726
27.05033 54.53954 -1.888631 50.15334
27.10033 54.63880 -1.890025 49.93969
27.15033 54.74008 -1.891341 50.00590
27.20033 54.84081 -1.892724 49.97379
27.25033 54.93940 -1.894199 49.97400
27.30033 55.03950 -1.895537 49.97924
27.35033 55.13954 -1.896652 49.93102
27.40033 55.24014 -1.897770 49.80684
27.45033 55.33963 -1.899063 49.99187
27.50033 55.43899 -1.900258 49.93242
27.55033 55.53994 -1.901379 50.00218
27.60033 55.63934 -1.902596 50.02640
27.65033 55.73764 -1.903906 49.99965
27.70033 55.83936 -1.905090 49.78654
27.75033 55.93900 -1.906319 50.00418
27.80033 56.03746 -1.907562 49.89097
27.85033 56.13922 -1.908581 49.87602
27.90033 56.23782 -1.909766 50.05645
27.95033 56.33798 -1.910772 50.04286
28.00033 56.43738 -1.911756 49.91455
28.05033 56.53735 -1.913008 50.11454
28.10033 56.63809 -1.913841 50.05228
28.15033 56.73668 -1.915234 50.00736
28.20033 56.83620 -1.916295 49.97790
28.25033 56.93635 -1.917577 50.14550
28.30033 57.03670 -1.918885 50.07171
28.35033 57.13687 -1.920056 50.20696
28.40033 57.23557 -1.921372 49.99970
28.45033 57.33578 -1.922678 49.92939
28.50033 57.43638 -1.923770 50.01387
28.55033 57.53554 -1.925000 50.06317
28.60033 57.63476 -1.926406 50.07821
28.65033 57.73518 -1.927780 50.02446
28.70033 57.83496 -1.929108 50.12444
28.75033 57.93479 -1.930421 49.94414
28.80033 58.03446 -1.931809 49.98414
28.85033 58.13514 -1.933112 49.84824
28.90033 58.23508 -1.934336 50.05309
28.95033 58.33558 -1.935781 49.36060
29.00033 58.43379 -1.937352 49.94291
29.05033 58.53457 -1.938720 50.09810
29.10033 58.63394 -1.940122 50.00400
29.15033 58.73400 -1.941507 49.95877
29.20033 58.83424 -1.943036 49.88530
29.25033 58.93366 -1.944552 50.05086
29.30033 59.03332 -1.946242 49.85446
29.35033 59.13398 -1.947611 50.10378
29.40033 59.23318 -1.949096 49.83309
29.45033 59.33235 -1.950198 50.05725
29.50033 59.43346 -1.951446 49.99369
29.55033 59.52926 -1.953672 49.93260
29.60033 59.60234 -1.912900 49.85398
29.65033 59.65318 -1.760928 49.88316
29.70033 59.69506 -1.612718 49.98678
29.75033 59.72870 -1.453126 49.96040
29.80033 59.75744 -1.308511 49.95384
29.85033 59.78108 -1.165717 50.03056
29.90033 59.80297 -1.041295 50.02229
29.95033 59.82024 -0.9348975 50.01262
30.00033 59.83579 -0.8321235 49.97739
30.05033 59.84858 -0.7406111 49.95788
30.10033 59.85922 -0.6642475 49.98190
30.15033 59.86884 -0.5980484 49.97498
30.20033 59.87720 -0.5436030 50.07696
30.25033 59.88496 -0.4947188 50.11367
30.30033 59.89122 -0.4549933 49.83131
30.35033 59.89645 -0.4178735 49.99242
30.40033 59.90220 -0.3864362 49.92179
30.45033 59.90482 -0.3644341 50.00676
30.50033 59.90976 -0.3394540 50.01797
30.55033 59.91169 -0.3247363 50.07804
30.60033 59.91424 -0.3102356 50.02274
30.65033 59.91716 -0.2991256 49.89502
30.70033 59.92000 -0.2872499 49.76897
30.75033 59.92180 -0.2786795 49.97221
30.80033 59.92453 -0.2692168 50.01639
30.85033 59.92554 -0.2613106 49.86364
30.90033 59.92691 -0.2534852 49.93794
30.95033 59.92874 -0.2456562 49.65848
31.00033 59.92972 -0.2379752 49.95469
31.05033 59.92957 -0.2310903 49.96866
31.10033 59.93103 -0.2245881 50.15086
31.15033 59.93309 -0.2181450 50.12914
31.20033 59.93342 -0.2126514 50.02875
31.25033 59.93289 -0.2074978 50.11601
31.30033 59.93416 -0.2026010 49.82434
31.35033 59.93344 -0.1983922 49.95898
31.40033 59.93392 -0.1943312 50.09653
31.45033 59.93489 -0.1909261 49.89122
31.50033 59.93503 -0.1877588 50.23782
31.55033 59.93532 -0.1845880 50.14459
31.60033 59.93593 -0.1813120 49.93039
31.65033 59.93627 -0.1783291 49.84693
31.70033 59.93629 -0.1753777 50.10086
31.75033 59.93611 -0.1725894 50.11583
31.80033 59.93668 -0.1698790 49.99737
31.85034 59.93658 -0.1677947 49.87303
31.90033 59.93705 -0.1659251 50.10328
31.95033 59.93671 -0.1641779 50.11902
32.00033 59.93628 -0.1628986 49.87672
32.05033 59.93738 -0.1617838 50.12449
32.10034 59.93735 -0.1608076 49.96542
32.15033 59.93726 -0.1601318 50.19420
32.20033 59.93744 -0.1593988 49.41380
32.25033 59.93843 -0.1589608 49.91934
32.30033 59.93829 -0.1584524 49.91248
32.35034 59.93780 -0.1581783 50.02722
32.40033 59.93925 -0.1579765 49.87622
32.45033 59.93962 -0.1577121 49.89792
-2.000000 1.000000 0.0000000 0.0000000
32.54700 59.93602 -0.1577584 50.06470
32.59700 59.91139 -0.1121414 49.91196
32.64700 59.86169 0.04488886 50.01544
32.69700 59.80169 0.1998794 50.00542
32.74700 59.73516 0.3516750 49.87892
32.79700 59.66406 0.5083138 50.02224
32.84700 59.58674 0.6545372 50.14488
32.89700 59.50830 0.7843020 50.04126
32.94700 59.42506 0.8995962 49.95902
32.99700 59.34033 0.9994953 49.91902
33.04700 59.25359 1.087142 49.93508
33.09700 59.16337 1.165066 49.90326
33.14700 59.07348 1.235999 50.00494
33.19700 58.98156 1.293898 50.22761
33.24700 58.88840 1.342434 49.90717
33.29700 58.79391 1.383733 50.13617
33.34700 58.69941 1.418811 50.10906
33.39700 58.60530 1.451918 50.02428
33.44700 58.50828 1.477095 50.05070
33.49700 58.41168 1.501176 49.97396
33.54700 58.31440 1.518518 49.96694
33.59700 58.21750 1.534672 49.87057
33.64700 58.12022 1.550075 50.06519
33.69700 58.02230 1.563235 50.02552
33.74700 57.92414 1.571023 50.08190
33.79700 57.82532 1.579334 50.00162
33.84700 57.72690 1.588098 49.93094
33.89700 57.62843 1.596197 49.93049
33.94700 57.53103 1.604570 49.98990
33.99700 57.43086 1.611947 49.83352
34.04700 57.33298 1.619562 49.98948
34.09700 57.23424 1.626588 49.80800
34.14700 57.13590 1.632999 50.17676
34.19700 57.03558 1.639200 50.00192
34.24700 56.93665 1.645117 50.08606
34.29700 56.83703 1.650636 50.17816
34.34700 56.73842 1.655861 49.83806
34.39700 56.63889 1.660761 49.90770
34.44700 56.54084 1.665503 50.07669
34.49700 56.44004 1.669639 50.03220
34.54700 56.34124 1.673646 50.01733
34.59700 56.24178 1.677292 49.88456
34.64700 56.14211 1.680946 50.00131
34.69700 56.04212 1.684280 49.88467
34.74700 55.94329 1.687671 49.95188
34.79700 55.84496 1.690833 49.93567
34.84700 55.74365 1.693790 49.99911
34.89700 55.64458 1.696755 49.98540
34.94700 55.54539 1.699271 49.94422
34.99700 55.44424 1.701817 50.00204
35.04700 55.34649 1.704220 50.15990
35.09700 55.24496 1.706737 49.87988
35.14700 55.14596 1.709074 49.41669
35.19700 55.04539 1.711472 50.23831
35.24700 54.94617 1.713411 49.85566
35.29700 54.84545 1.715437 49.82528
35.34700 54.74680 1.717453 49.99957
35.39700 54.64644 1.719069 50.02858
35.44700 54.54800 1.720725 50.66250
35.49700 54.44780 1.722311 49.76440
35.54700 54.34790 1.723580 50.14482
35.59700 54.24864 1.724948 49.97452
35.64700 54.14941 1.726272 50.15406
35.69700 54.04894 1.727590 50.06563
35.74700 53.95056 1.729038 49.82580
35.79700 53.85020 1.730304 49.93814
35.84700 53.75034 1.731563 49.93739
35.89700 53.65092 1.732804 49.89090
35.94700 53.55140 1.734171 49.91542
35.99700 53.45028 1.735286 50.05881
36.04700 53.35193 1.736734 49.90493
36.09700 53.25028 1.737908 49.95754
36.14700 53.15219 1.739086 49.83550
36.19700 53.05268 1.740393 50.05448
36.24700 52.95176 1.741808 50.02700
36.29700 52.85316 1.743011 50.11676
36.34700 52.75297 1.744303 50.07954
36.39700 52.65347 1.745795 50.05800
36.44700 52.55371 1.747328 50.00792
36.49700 52.45350 1.748954 50.13122
36.54700 52.35352 1.750370 49.91794
36.59700 52.25410 1.751688 49.94816
36.64700 52.15320 1.752859 49.82404
36.69700 52.05418 1.754116 49.82640
36.74700 51.95500 1.755552 49.90940
36.79700 51.85444 1.756575 50.21344
36.84700 51.75594 1.757782 49.69422
36.89700 51.65680 1.758652 49.92861
36.94700 51.55524 1.759642 50.02970
36.99700 51.45554 1.760649 49.95928
37.04700 51.35471 1.761776 49.99167
37.09700 51.25516 1.763044 50.04120
37.14700 51.15611 1.764102 49.95770
37.19700 51.05613 1.765217 50.05768
37.24700 50.95634 1.766112 50.00110
37.29700 50.85692 1.767201 49.87735
37.34700 50.75805 1.768237 50.21330
37.39700 50.65688 1.769402 50.56036
37.44700 50.55694 1.770310 50.04006
37.49700 50.45860 1.771360 50.03472
37.54700 50.35719 1.772276 50.04873
37.59700 50.25844 1.773538 49.93004
37.64700 50.15869 1.774590 49.95702
37.69700 50.05792 1.775515 49.84400
37.74700 49.95842 1.776520 49.97743
37.79700 49.85800 1.777520 50.08120
37.84700 49.75768 1.778780 50.04511
37.89700 49.65822 1.779862 49.94948
37.94700 49.55826 1.780864 50.05659
37.99700 49.45830 1.781847 49.99007
38.04700 49.35782 1.782623 50.05548
38.09700 49.25915 1.783401 50.09398
38.14700 49.15943 1.784175 50.07520
38.19700 49.05879 1.784671 50.09209
38.24700 48.96092 1.785373 49.99856
38.29700 48.86022 1.786443 50.03637
38.34700 48.76093 1.787278 50.05871
38.39700 48.65978 1.788318 49.47104
38.44700 48.55998 1.789368 49.94242
38.49700 48.46000 1.790896 50.07382
38.54700 48.35946 1.791872 50.06456
38.59700 48.26060 1.792968 50.13835
38.64700 48.16096 1.793852 50.09794
38.69700 48.05937 1.794501 50.01593
38.74700 47.96145 1.795196 49.88944
38.79700 47.86113 1.795643 49.85206
38.84700 47.76126 1.796096 49.94172
38.89700 47.66164 1.796464 49.99246
38.94700 47.56246 1.797058 50.10899
38.99700 47.46064 1.797694 50.05887
39.04700 47.36216 1.798357 50.09426
39.09700 47.26219 1.799053 50.01266
39.14700 47.16316 1.799884 50.09400
39.19700 47.06354 1.800516 50.09592
39.24700 46.96269 1.801215 50.12594
39.29700 46.86372 1.802146 49.94430
39.34700 46.76325 1.802943 49.98278
39.39700 46.66351 1.803948 50.01627
39.44700 46.56348 1.804939 49.96386
39.49700 46.46492 1.806028 49.84922
39.54700 46.36472 1.807042 50.04583
39.59700 46.26407 1.807932 49.94288
39.64700 46.16340 1.808711 50.07420
39.69700 46.06514 1.809494 50.03647
39.74700 45.96480 1.810324 49.90944
39.79700 45.86441 1.810944 49.94359
39.84700 45.76484 1.811934 49.87506
39.89700 45.66408 1.812837 50.04830
39.94700 45.56544 1.813674 50.16364
39.99700 45.46530 1.814215 50.07122
40.04700 45.36496 1.815078 50.06814
40.09700 45.26409 1.815870 50.19860
40.14700 45.16467 1.816732 50.05029
40.19700 45.06574 1.817568 50.09256
40.24700 44.96582 1.818206 49.92284
40.29700 44.86516 1.818717 49.88360
40.34700 44.76539 1.819626 50.08647
40.39700 44.66544 1.820280 50.01734
40.44700 44.56620 1.820809 49.99418
40.49700 44.46520 1.821286 50.06450
40.54700 44.36600 1.821643 49.99042
40.59700 44.26720 1.822188 49.89766
40.64700 44.16640 1.822540 50.14387
40.69700 44.06648 1.823020 49.96859
40.74700 43.96608 1.823526 49.91150
40.79700 43.86719 1.824098 49.96332
40.84700 43.76758 1.824516 50.11924
40.89700 43.66733 1.824856 49.99874
40.94700 43.56761 1.825413 49.87385
40.99700 43.46822 1.825837 49.77168
41.04700 43.36765 1.826444 50.21510
41.09700 43.26817 1.827090 49.82675
41.14700 43.16873 1.827666 49.90900
41.19700 43.06939 1.828400 50.08516
41.24700 42.96766 1.828887 50.03967
41.29700 42.86840 1.829534 49.97964
41.34700 42.76899 1.830243 50.08383
41.39700 42.66981 1.830917 50.07002
41.44700 42.57004 1.831724 49.98941
41.49700 42.46928 1.832744 50.16975
41.54700 42.37034 1.833774 50.03217
41.59700 42.26928 1.834735 49.88072
41.64700 42.17014 1.835719 49.96646
41.69700 42.06787 1.836474 49.97646
41.74700 41.96916 1.837148 49.91910
41.79700 41.86920 1.837537 49.87572
41.84700 41.76981 1.838129 49.87314
41.89700 41.67112 1.838611 50.08118
41.94700 41.56989 1.838884 50.04832
41.99700 41.46904 1.839279 49.92874
42.04700 41.37016 1.839452 49.92270
42.09700 41.27017 1.839771 50.04780
42.14700 41.17109 1.840060 49.84276
42.19700 41.07016 1.840219 49.57273
42.24700 40.97102 1.840495 49.95800
42.29700 40.87111 1.841041 50.12648
42.34700 40.77170 1.841489 49.82019
42.39700 40.67142 1.841909 50.04566
42.44700 40.57126 1.842214 49.96130
42.49700 40.47376 1.842799 50.73382
42.54700 40.37107 1.843108 50.09262
42.59700 40.27122 1.843719 49.95762
42.64700 40.17334 1.844381 49.99310
42.69700 40.07292 1.845063 50.02172
42.74700 39.97224 1.845461 49.92396
42.79700 39.87200 1.846191 50.13542
42.84700 39.77115 1.846790 49.99036
42.89700 39.67230 1.847516 50.22050
42.94700 39.57160 1.848378 50.03278
42.99700 39.47219 1.849331 50.09090
43.04700 39.37209 1.850034 49.85712
43.09700 39.27097 1.850694 50.06791
43.14700 39.17135 1.851357 49.97496
43.19700 39.07204 1.851600 50.09732
43.24700 38.97294 1.851851 50.01039
43.29700 38.87161 1.851970 49.90572
43.34700 38.77380 1.852364 50.04776
43.39700 38.67385 1.852345 50.01238
43.44700 38.57298 1.852408 50.00461
43.49700 38.47438 1.852372 49.89000
43.54700 38.37247 1.852434 49.97500
43.59700 38.27288 1.852334 50.03231
43.64700 38.17494 1.852829 49.92914
43.69700 38.07378 1.852891 50.06482
43.74700 37.97384 1.853168 50.02291
43.79700 37.87383 1.853408 49.87888
43.84700 37.77536 1.853923 49.96890
43.89700 37.67500 1.854279 49.92254
43.94700 37.57471 1.854845 50.02730
43.99700 37.47533 1.855307 50.01335
44.04700 37.37574 1.855812 49.99148
44.09700 37.27693 1.856232 49.90947
44.14700 37.17645 1.856644 50.07515
44.19700 37.07542 1.856947 50.05818
44.24700 36.97589 1.857498 49.90470
44.29700 36.87531 1.858197 49.85458
44.34700 36.77498 1.858868 49.96313
44.39700 36.67526 1.859567 49.90165
44.44700 36.57684 1.860090 49.94006
44.49700 36.47455 1.860658 50.05850
44.54700 36.37677 1.861096 49.92840
44.59700 36.27440 1.861271 49.86554
44.64700 36.17502 1.861522 49.83637
44.69700 36.07590 1.861766 49.91312
44.74700 35.97519 1.861796 49.91516
44.79700 35.87518 1.861933 50.13223
44.84700 35.77550 1.862092 49.94706
44.89700 35.67618 1.862334 49.98398
44.94700 35.57608 1.862475 50.05790
44.99700 35.47641 1.862670 49.78694
45.04700 35.37806 1.863045 49.87637
45.09700 35.27712 1.863035 50.00254
45.14700 35.17694 1.863061 49.96575
45.19700 35.07767 1.863247 49.96124
45.24700 34.97808 1.863541 50.02524
45.29700 34.87729 1.863758 50.14282
45.34700 34.77792 1.863970 50.10866
45.39700 34.67818 1.864399 49.94996
45.44700 34.57834 1.864728 49.81122
45.49700 34.47913 1.865207 49.87670
45.54700 34.37746 1.865659 50.16484
45.59700 34.27700 1.866142 49.90580
45.64700 34.17842 1.866568 50.23129
45.69700 34.07859 1.867086 49.91433
45.74700 33.97776 1.867447 50.02692
45.79700 33.87705 1.867649 50.07810
45.84700 33.77690 1.868004 50.00276
45.89700 33.67811 1.868234 49.55768
45.94700 33.57864 1.868750 49.89606
45.99700 33.47833 1.868786 50.10144
46.04700 33.37946 1.869047 49.97553
46.09700 33.27712 1.869139 50.10813
46.14700 33.17869 1.869717 50.07440
46.19700 33.07926 1.869847 50.09176
46.24700 32.97945 1.870158 49.94157
46.29700 32.87952 1.870425 50.13117
46.34700 32.77830 1.870482 49.86796
46.39700 32.67876 1.870468 49.85896
46.44700 32.57807 1.870617 49.87890
46.49700 32.47925 1.870989 49.95437
46.54700 32.37839 1.871058 49.92385
46.59700 32.27898 1.871445 50.04956
46.64700 32.17768 1.871442 49.85712
46.69700 32.08000 1.871705 50.05204
46.74700 31.97871 1.871764 49.88034
46.79700 31.87766 1.872124 49.96510
46.84700 31.78110 1.872636 49.86230
46.89700 31.68018 1.872910 50.18802
46.94700 31.58112 1.873140 50.09060
46.99700 31.47966 1.873335 49.33467
47.04700 31.37944 1.873664 49.57724
47.09700 31.27950 1.873830 49.97396
47.14700 31.18047 1.873992 49.96109
47.19700 31.07948 1.874142 49.99674
47.24700 30.98124 1.874300 49.91210
47.29700 30.88041 1.873959 49.89263
47.34700 30.77937 1.873810 50.03671
47.39700 30.68166 1.873858 50.03960
47.44700 30.58115 1.873837 49.98786
47.49700 30.48130 1.873816 50.11324
47.54700 30.38286 1.874522 50.18094
47.59700 30.28359 1.874826 50.00480
47.64700 30.18154 1.875392 50.05156
47.69700 30.08085 1.875807 50.07984
47.74700 29.98009 1.876196 49.98781
47.79700 29.88191 1.876610 49.94274
47.84700 29.78082 1.877081 50.01040
47.89700 29.68216 1.877233 49.97180
47.94700 29.58100 1.877587 49.87303
47.99700 29.48118 1.877724 50.08990
48.04700 29.38269 1.877800 50.03469
48.09700 29.28306 1.877978 49.96458
48.14700 29.18127 1.877875 50.07416
48.19700 29.08162 1.877628 49.95156
48.24700 28.98210 1.877708 49.89339
48.29700 28.88310 1.877492 50.02530
48.34700 28.78236 1.877521 49.97666
48.39700 28.68187 1.877506 49.86866
48.44700 28.58352 1.877560 50.15372
48.49700 28.48287 1.877557 49.92804
48.54700 28.38306 1.877699 49.92043
48.59700 28.28329 1.877670 49.95348
48.64700 28.18310 1.877609 49.98662
48.69700 28.08404 1.877533 50.03409
48.74700 27.98318 1.877801 50.13047
48.79700 27.88325 1.878365 49.93824
48.84700 27.78459 1.878821 49.85289
48.89700 27.68350 1.879268 50.00793
48.94700 27.58374 1.880059 50.15347
48.99700 27.48216 1.880586 50.10672
49.04700 27.38284 1.880947 50.00410
49.09700 27.28232 1.881298 50.03820
49.14700 27.18278 1.881424 49.87504
49.19700 27.08342 1.881398 50.12008
49.24700 26.98400 1.881278 50.05583
49.29700 26.88247 1.881085 49.97406
49.34700 26.78323 1.881155 50.13046
49.39700 26.68400 1.881061 50.05978
49.44700 26.58574 1.881065 49.96512
49.49700 26.48467 1.881052 50.08872
49.54700 26.38361 1.881098 49.88818
49.59700 26.28451 1.881214 50.05780
49.64700 26.18613 1.881474 50.02813
49.69700 26.08388 1.881264 49.96498
49.74700 25.98367 1.881086 50.08150
49.79700 25.88378 1.881195 50.01437
49.84700 25.78363 1.881014 49.92209
49.89700 25.68526 1.881106 50.07976
49.94700 25.58386 1.880960 49.95663
49.99700 25.48530 1.881277 50.04124
50.04700 25.38390 1.881415 50.16046
50.09700 25.28542 1.881808 50.01154
50.14700 25.18547 1.881990 50.00600
50.19700 25.08471 1.881980 49.90722
50.24700 24.98538 1.882319 50.13542
50.29700 24.88521 1.882339 49.98926
50.34700 24.78731 1.882539 49.88030
50.39700 24.68600 1.882727 50.09028
50.44700 24.58570 1.882718 50.11654
50.49700 24.48685 1.883162 49.99528
50.54700 24.38501 1.883540 49.83800
50.59700 24.28417 1.884363 49.84596
50.64700 24.18609 1.885175 49.86350
50.69700 24.08492 1.885546 49.32816
50.74700 23.98692 1.886318 49.95900
50.79700 23.88685 1.886443 49.87204
50.84700 23.78505 1.886638 49.94496
50.89700 23.68689 1.886930 49.90657
50.94700 23.58529 1.887470 49.98410
50.99700 23.48477 1.888102 50.01780
51.04700 23.38718 1.889320 49.90770
51.09700 23.28852 1.890704 49.94560
51.14700 23.19024 1.892821 50.05325
51.19700 23.08792 1.895329 49.95180
51.24700 22.98882 1.899142 50.04092
51.29700 22.88928 1.903891 49.94756
51.34700 22.79188 1.912512 49.94890
51.39700 22.69050 1.920072 50.11916
51.44700 22.59392 1.935289 50.03970
51.49700 22.49494 1.954916 49.99630
51.54700 22.39514 1.976645 50.06890
51.59700 22.29760 2.004884 50.11264
51.64700 22.20054 2.039672 49.97616
51.69700 22.10387 2.081085 49.92854
51.74700 22.00587 2.122563 49.83754
51.79700 21.91006 2.171902 49.97928
51.84700 21.81300 2.230177 50.04076
51.89700 21.71677 2.291485 49.93116
51.94700 21.62323 2.357754 49.94064
51.99700 21.52912 2.429210 49.94925
52.04700 21.43497 2.518048 50.07467
52.09700 21.34085 2.612526 49.98706
52.14700 21.25184 2.705132 49.96880
52.19700 21.15601 2.811555 49.98856
52.24700 21.06585 2.925076 50.00112
52.29700 20.97588 3.048735 50.00160
52.34700 20.88489 3.165581 50.11304
52.39700 20.79418 3.281537 49.93416
52.44700 20.70442 3.419682 50.00559
52.49700 20.61663 3.549083 49.94093
52.54700 20.52754 3.673734 50.03387
52.59700 20.43716 3.804714 50.12954
52.64700 20.35078 3.934557 50.05709
52.69700 20.25979 4.057804 50.02466
52.74700 20.16963 4.169150 50.00728
52.79700 20.07876 4.273699 49.94439
52.84700 19.98745 4.366360 50.02248
52.89700 19.89682 4.454166 49.98922
52.94700 19.80202 4.515448 50.06548
52.99700 19.70735 4.559152 50.00718
53.04700 19.61194 4.599922 49.99196
53.09700 19.51536 4.617541 50.05414
53.14700 19.41681 4.624993 49.91714
53.19700 19.31681 4.626856 50.05029
53.24700 19.21674 4.621955 50.11024
53.29700 19.11441 4.583734 50.03564
53.34700 19.01245 4.523120 49.99735
53.39700 18.90516 4.442370 49.97016
53.44700 18.79976 4.350758 50.06060
53.49700 18.69316 4.251561 50.07697
53.54700 18.58564 4.138924 50.06071
53.59700 18.47624 4.016706 50.00606
53.64700 18.36531 3.884480 50.13514
53.69700 18.25475 3.752434 50.17426
53.74700 18.14380 3.619952 49.96616
53.79700 18.03164 3.483808 50.16218
53.84700 17.92097 3.346652 49.93541
53.89700 17.81011 3.221888 50.03643
53.94700 17.69836 3.088650 50.21317
53.99700 17.58988 2.975148 50.11185
54.04700 17.47913 2.866668 49.92736
54.09700 17.36994 2.754481 50.05346
54.14700 17.26030 2.659286 49.99900
54.19700 17.15312 2.568394 49.95690
54.24700 17.04785 2.495282 49.92996
54.29700 16.94064 2.426549 49.99222
54.34700 16.83370 2.353270 49.92866
54.39700 16.73042 2.303715 49.99026
54.44700 16.62472 2.247790 50.08625
54.49700 16.52117 2.206856 50.00554
54.54700 16.41574 2.169878 49.96389
54.59700 16.31454 2.135501 50.09976
54.64700 16.21060 2.104718 50.13184
54.69700 16.10916 2.079930 49.97491
54.74700 16.00535 2.055181 50.07040
54.79700 15.90452 2.037338 49.92898
54.84700 15.80160 2.022073 50.00653
54.89700 15.70172 2.008235 50.07422
54.94700 15.59924 1.992077 50.04022
54.99700 15.49807 1.980723 49.91870
55.04700 15.39802 1.970692 50.05393
55.09700 15.29749 1.962743 49.90824
55.14700 15.19579 1.954495 49.98840
55.19700 15.09539 1.948267 50.00500
55.24700 14.99269 1.941668 50.02050
55.29700 14.89411 1.935572 50.03042
55.34700 14.79483 1.929484 49.96303
55.39700 14.69401 1.923406 49.88481
55.44700 14.59354 1.918156 50.14777
55.49700 14.49269 1.913317 49.82666
55.54700 14.39314 1.908824 49.83705
55.59700 14.29157 1.904604 49.98134
55.64700 14.19118 1.901128 50.13566
55.69700 14.09114 1.897804 50.07883
55.74700 13.99110 1.894501 49.94256
55.79700 13.89112 1.891659 49.96117
55.84700 13.79354 1.889310 49.84553
55.89700 13.69275 1.886656 50.01367
55.94700 13.59066 1.884647 50.34060
55.99700 13.49202 1.882909 50.00282
56.04700 13.39339 1.881289 49.95973
56.09700 13.29198 1.879974 49.88734
56.14700 13.19363 1.878894 49.85937
56.19700 13.09120 1.877793 50.00778
56.24700 12.99171 1.876959 50.00319
56.29700 12.89152 1.876409 50.06626
56.34700 12.79040 1.875999 50.10624
56.39700 12.69122 1.875536 49.96680
56.44700 12.59171 1.875220 49.93606
56.49700 12.49040 1.874447 50.00706
56.54700 12.39236 1.874352 50.06266
56.59700 12.29049 1.873672 50.03559
56.64700 12.19184 1.873147 50.01006
56.69700 12.09038 1.872316 50.08174
56.74700 11.99147 1.871894 50.10803
56.79700 11.89241 1.871175 49.98600
56.84700 11.79019 1.870402 50.03098
56.89700 11.69242 1.869624 50.04850
56.94700 11.59145 1.869136 49.90560
56.99700 11.49150 1.868276 49.96528
57.04700 11.39403 1.868088 50.00027
57.09700 11.29196 1.867449 50.00488
57.14700 11.19337 1.866848 50.09111
57.19700 11.09330 1.866310 49.98488
57.24700 10.99485 1.866057 50.10613
57.29700 10.89298 1.865636 49.76906
57.34700 10.79401 1.865486 50.06416
57.39700 10.69443 1.865336 49.94236
57.44700 10.59260 1.865058 49.93250
57.49700 10.49334 1.864888 50.20410
57.54700 10.39255 1.864590 50.02350
57.59700 10.29346 1.864878 50.01244
57.64700 10.19209 1.864841 50.03591
57.69700 10.09097 1.864978 49.94969
57.74700 9.991621 1.864931 49.95242
57.79700 9.891814 1.864873 49.91662
57.84700 9.792710 1.864922 50.11199
57.89700 9.692520 1.865029 49.90898
57.94700 9.591157 1.864966 50.19580
57.99700 9.490429 1.864754 49.96878
58.04700 9.391548 1.864557 50.04612
58.09700 9.291610 1.864369 50.02769
58.14700 9.191131 1.864194 50.03788
58.19700 9.092476 1.863722 50.02434
58.24700 8.993025 1.863473 50.10183
58.29700 8.891020 1.863103 49.84797
58.34700 8.791466 1.862694 50.05041
58.39700 8.692378 1.862279 50.03328
58.44700 8.592359 1.861796 50.17622
58.49700 8.492746 1.861369 49.88879
58.54700 8.393243 1.860850 49.91859
58.59700 8.292626 1.860559 50.09052
58.64700 8.193081 1.860245 49.98388
58.69700 8.093700 1.860077 50.05380
58.74700 7.993218 1.859550 49.95967
58.79700 7.894270 1.859518 50.02034
58.84700 7.792736 1.858930 49.99866
58.89700 7.693604 1.859128 50.03264
58.94700 7.593991 1.858864 50.04463
58.99700 7.492655 1.858745 49.97978
59.04700 7.394470 1.858294 50.02414
59.09700 7.292300 1.858272 50.08096
59.14700 7.194790 1.858232 49.97678
59.19700 7.093868 1.858018 50.03840
59.24700 6.993591 1.857999 49.97654
59.29700 6.895928 1.858270 50.09844
59.34700 6.793115 1.858259 49.97652
59.39700 6.693397 1.858222 49.98150
59.44700 6.593201 1.858205 50.00186
59.49700 6.493332 1.858388 50.18352
59.54700 6.394008 1.858624 50.14354
59.59700 6.295300 1.858860 50.03480
59.64700 6.194202 1.858714 50.00336
59.69700 6.093540 1.858167 49.95131
59.74700 5.995046 1.858107 50.06450
59.79700 5.893764 1.857745 49.93689
59.84700 5.795150 1.857513 49.95703
59.89700 5.692608 1.856935 49.97176
59.94700 5.593502 1.856908 49.27803
59.99700 5.494140 1.856619 49.95254
60.04700 5.395519 1.856435 50.11496
60.09700 5.292908 1.856002 50.05386
60.14700 5.193272 1.856044 49.83540
60.19700 5.095373 1.855254 49.96335
60.24700 4.994548 1.854685 49.84218
60.29700 4.894740 1.854744 50.07309
60.34700 4.795116 1.854603 49.92278
60.39700 4.694684 1.854405 49.97326
60.44700 4.593330 1.854307 49.95534
60.49700 4.494966 1.854394 50.01320
60.54700 4.393936 1.854349 49.98694
60.59700 4.295438 1.854618 49.87937
60.64700 4.194334 1.854394 49.96602
60.69700 4.096830 1.854296 49.98920
60.74700 3.995734 1.854084 50.01021
60.79700 3.895637 1.853780 49.98972
60.84700 3.796030 1.853589 49.88884
60.89700 3.695459 1.853342 50.10906
60.94700 3.594359 1.853052 49.94968
60.99700 3.495479 1.853068 49.90930
61.04700 3.395132 1.852660 50.00606
61.09700 3.296272 1.852676 50.14367
61.14700 3.195550 1.852576 50.02126
61.19700 3.095575 1.852677 50.10062
61.24700 2.995015 1.852572 49.87979
61.29700 2.894782 1.852630 50.02209
61.34700 2.796495 1.852722 50.17874
61.39700 2.695202 1.852404 49.98437
61.44700 2.595052 1.852316 50.01266
61.49700 2.496372 1.852222 50.05624
61.54700 2.396151 1.852231 50.06076
61.59700 2.295765 1.852277 49.89326
61.64700 2.194656 1.852075 50.02536
61.69700 2.096028 1.851903 49.95032
61.74700 1.995575 1.851922 50.02902
61.79700 1.895460 1.851673 49.89188
61.84700 1.796770 1.851393 50.04710
61.89700 1.697585 1.850949 50.08254
61.94700 1.597876 1.850476 49.98630
61.99700 1.495807 1.849739 49.95118
62.04700 1.398085 1.849757 49.96354
62.09700 1.325787 1.799931 50.03588
62.14700 1.275190 1.663634 50.03096
62.19700 1.236448 1.523318 49.99224
62.24700 1.202899 1.382246 50.06336
62.29700 1.173805 1.240137 50.11706
62.34700 1.150136 1.113564 49.85412
62.39700 1.130183 0.9927820 50.00234
62.44700 1.112531 0.8815368 49.90659
62.49700 1.099371 0.7889434 49.92196
62.54700 1.085986 0.7065862 49.95154
62.59700 1.073481 0.6329798 50.04804
62.64700 1.064430 0.5654918 50.14356
62.69700 1.056638 0.5168264 49.89289
62.74700 1.050503 0.4659846 49.89356
62.79700 1.042433 0.4193270 49.94986
62.84700 1.036425 0.3884083 50.04454
62.89700 1.033324 0.3606222 50.03396
62.94700 1.032076 0.3337856 49.97691
62.99700 1.026106 0.3060415 50.06120
63.04700 1.023536 0.2923157 49.92954
63.09700 1.020354 0.2766042 49.81070
63.14700 1.016439 0.2652859 49.88881
63.19700 1.014616 0.2521306 49.82746
63.24700 1.012876 0.2408072 49.97291
63.29700 1.011963 0.2330630 50.09740
63.34700 1.011562 0.2257634 49.93860
63.39700 1.010278 0.2177314 50.03670
63.44700 1.008738 0.2093026 49.86697
63.49700 1.006790 0.2021502 50.02106
63.54700 1.006361 0.1960555 50.07912
63.59700 1.004818 0.1901835 50.07324
63.64700 1.003419 0.1844688 49.93039
63.69700 1.003726 0.1792006 49.91797
63.74700 1.000913 0.1742174 50.15914
63.79700 1.001714 0.1698936 50.00513
63.84700 1.000750 0.1663687 49.92390
63.89700 0.9997909 0.1630836 49.90045
63.94700 0.9997672 0.1598298 49.97803
63.99700 0.9999829 0.1571465 50.04667
64.04700 0.9987420 0.1544297 50.06126
64.09700 0.9988746 0.1521478 49.94797
64.14700 0.9976665 0.1499944 49.91276
64.19701 0.9972071 0.1478880 49.95352
64.24700 0.9978257 0.1459460 49.90156
64.29700 0.9957446 0.1443262 49.99318
64.34700 0.9988541 0.1428350 49.97622
64.39700 0.9977601 0.1412829 49.84543
64.44701 0.9963744 0.1397071 49.98362
64.49700 0.9959582 0.1384088 50.08455
64.54700 0.9959069 0.1370645 49.95636
64.59700 0.9957804 0.1359768 50.00204
64.64700 0.9952816 0.1348854 50.05972
64.69701 0.9950256 0.1342356 49.90973
64.74700 0.9968153 0.1335306 50.08344
64.79700 0.9948224 0.1331353 50.11146
-2.000000 2.000000 0.0000000 0.0000000