File: imagens/notebooks/dados experimentais/dsc/Karl_CTAB100 Ur 45%.txt
CLOSED
Version	1.0
Language	English
Run	1
RunSerial	150
Instrument	DSC Q100 V9.9 Build 303
Module	DSC Standard Cell FC
Operator	LL
File	\\Niger\ta\Data\DSC\2018\Geral\Karl_CTAB100 Ur 45%.001
ProcName	Karl
InstSerial	0100-1211
Sample	CTAB100 Ur 45%
Size	10.0000	mg
Method	Karl
Comment
Xcomment	Pan: Aluminum Hermetic
Xcomment	Gas1: Nitrogen 50.0 ml/min
Xcomment	Gas2: Nitrogen 0.0 ml/min
Text
Exotherm	UP
Kcell	1.09030
Calib	-11.7822
TempCal	1	pts	158.71	156.60
TzeroDt	-90.0515 -0.0093 2.2263
TzeroDtz	-90.0515 0.0466 2.4421
InstCalFile	Tzero: \\Niger\ta\Data\DSC\CALIBRATION\20122016\CALIBRATION\0_RCS_12_20_2016 17_23_31.TZR
InstCalFile	Baseline: \\Niger\ta\Data\DSC\CALIBRATION\20122016\L.Base 20122016
InstCalFile	Sapphire: \\Niger\ta\Data\DSC\CALIBRATION\20122016\Safira 20122017.001
InstCalDate	Tzero 2016-12-20 Time 19:23:31
TempRange	-90.04 to 395.23 °C at 19.96 °C/min Heat Only
AutoZero	Delta T Offset 0.000 uV
AutoZero	Delta T0 Offset 0.000 uV
Controls	Gas 1  Event Off  Sampling 0.2
Cell#	FC-02451
CoolingUnit	RCS
SelHeatFlow	Heat Flow T4 (mW)
AutoAnalysis	Off
MacroFile
Nsig	4
Sig1	Time (min)
Sig2	Temperature (°C)
Sig3	Heat Flow (mW)
Sig4	Sample Purge Flow (mL/min)
Date	2018-05-16
Time	15:48:53
OrgMethod	1: Equilibrate at 1.00 °C
OrgMethod	2: Ramp 2.00 °C/min to 60.00 °C
OrgMethod	3: Isothermal for 3.00 min
OrgMethod	4: Mark end of cycle 1
OrgMethod	5: Ramp 2.00 °C/min to 1.00 °C
OrgMethod	6: Isothermal for 3.00 min
OrgMethod	7: Mark end of cycle 2
OrgFile	C:\TA\Data\DSC\2018\Geral\Karl_CTAB100 Ur 45%.001
3.33324E-4 1.154236 0.7921332 50.08284
0.05033332 1.143598 0.7052415 50.04578
0.1003333 1.161495 0.5612964 50.00410
0.1503333 1.202056 0.3869426 49.94913
0.2003333 1.254201 0.2259520 49.94154
0.2503333 1.315042 0.07300394 50.06059
0.3003333 1.381840 -.05983956 49.85034
0.3503333 1.456047 -0.1833098 50.01221
0.4003334 1.529495 -0.2963680 49.88670
0.4503334 1.609231 -0.3929720 50.08402
0.5003334 1.692151 -0.4758096 50.01032
0.5503332 1.777899 -0.5445139 50.11208
0.6003332 1.865095 -0.6047018 49.90540
0.6503332 1.951076 -0.6643424 50.44641
0.7003332 2.042098 -0.7066010 49.92200
0.7503332 2.135027 -0.7451990 49.70059
0.8003332 2.224634 -0.7816058 50.08976
0.8503332 2.318598 -0.8066803 49.40230
0.9003332 2.410837 -0.8321384 49.91162
0.9503334 2.507818 -0.8519395 50.13738
1.000333 2.601699 -0.8720997 50.04808
1.050334 2.698426 -0.8865875 49.93200
1.100334 2.794539 -0.8993749 50.15889
1.150334 2.888144 -0.9125363 50.00183
1.200334 2.984560 -0.9236444 50.03224
1.250334 3.082993 -0.9345015 50.01304
1.300334 3.180612 -0.9435530 49.81866
1.350333 3.276926 -0.9515250 50.13964
1.400333 3.373700 -0.9603074 49.92008
1.450334 3.471398 -0.9678712 50.14980
1.500333 3.570952 -0.9751793 49.90054
1.550334 3.667691 -0.9824432 49.93056
1.600334 3.765953 -0.9893706 50.09474
1.650333 3.864046 -0.9953656 49.93156
1.700334 3.962117 -1.001182 50.04880
1.750334 4.060963 -1.006439 49.97484
1.800334 4.159563 -1.012299 49.89176
1.850334 4.257174 -1.017073 50.02304
1.900334 4.356543 -1.021553 50.31422
1.950334 4.453300 -1.025844 50.12880
2.000334 4.552414 -1.029420 49.98235
2.050333 4.652461 -1.033287 50.11772
2.100334 4.751041 -1.036554 50.15893
2.150334 4.849437 -1.040359 49.97016
2.200334 4.949404 -1.043668 49.93828
2.250334 5.046214 -1.046967 49.86559
2.300333 5.146270 -1.049654 49.72861
2.350334 5.244630 -1.052661 50.09053
2.400334 5.345945 -1.055356 50.44848
2.450334 5.443232 -1.058118 49.70689
2.500334 5.545020 -1.060374 49.94804
2.550333 5.642562 -1.062829 49.97647
2.600333 5.741870 -1.065043 50.07088
2.650333 5.841192 -1.067028 50.01985
2.700333 5.939162 -1.068870 49.94139
2.750333 6.039810 -1.070394 49.92203
2.800333 6.138141 -1.072180 50.02222
2.850333 6.237215 -1.074236 49.81412
2.900333 6.336038 -1.076153 49.96475
2.950333 6.436420 -1.077956 49.78710
3.000333 6.535070 -1.079995 49.41924
3.050333 6.635696 -1.081981 49.99635
3.100333 6.735234 -1.083672 49.99062
3.150333 6.834670 -1.085632 50.12150
3.200333 6.935559 -1.086898 49.94178
3.250333 7.033456 -1.088824 50.00497
3.300333 7.133478 -1.090406 50.16067
3.350333 7.234051 -1.091690 49.93512
3.400333 7.333120 -1.093093 49.98304
3.450333 7.431950 -1.094475 50.15328
3.500333 7.531870 -1.095588 49.93850
3.550333 7.632874 -1.096687 50.12788
3.600333 7.729953 -1.097613 49.90928
3.650333 7.830765 -1.098328 50.06026
3.700333 7.931294 -1.098960 49.94046
3.750333 8.029660 -1.099824 50.27350
3.800333 8.129642 -1.100757 50.03356
3.850333 8.229870 -1.101432 50.12824
3.900333 8.328366 -1.102412 49.84164
3.950333 8.428360 -1.103462 49.94107
4.000333 8.529166 -1.104285 49.98503
4.050333 8.628716 -1.105456 49.93480
4.100333 8.727968 -1.106646 49.96075
4.150333 8.829258 -1.107409 50.35965
4.200333 8.927506 -1.108343 50.02670
4.250333 9.028611 -1.109121 50.02779
4.300333 9.129257 -1.109858 50.01012
4.350333 9.228670 -1.110844 50.04346
4.400333 9.325992 -1.111773 49.91696
4.450333 9.426492 -1.112298 50.05777
4.500333 9.528144 -1.112930 49.83094
4.550333 9.627469 -1.113598 49.99012
4.600333 9.726789 -1.113961 49.94120
4.650333 9.826043 -1.114590 50.06941
4.700333 9.924961 -1.114914 50.09052
4.750333 10.02453 -1.115807 50.01162
4.800333 10.12457 -1.116223 49.77660
4.850333 10.22373 -1.116785 50.07522
4.900333 10.32389 -1.117348 49.92567
4.950333 10.42439 -1.117903 49.98063
5.000333 10.52388 -1.118576 49.93692
5.050333 10.62394 -1.119246 49.36868
5.100333 10.72434 -1.120114 49.85299
5.150333 10.82391 -1.120900 49.94952
5.200333 10.92394 -1.121570 49.89674
5.250332 11.02362 -1.122084 50.14020
5.300332 11.12365 -1.122834 49.88775
5.350332 11.22379 -1.123464 49.55622
5.400332 11.32378 -1.124141 49.91084
5.450332 11.42355 -1.124803 49.97992
5.500332 11.52314 -1.125576 49.85332
5.550332 11.62302 -1.126404 50.10490
5.600332 11.72501 -1.126909 50.11063
5.650332 11.82447 -1.127481 49.95513
5.700332 11.92381 -1.127781 50.05444
5.750332 12.02341 -1.128107 50.07200
5.800332 12.12388 -1.128363 49.81167
5.850332 12.22431 -1.128842 50.08994
5.900332 12.32316 -1.129197 49.96600
5.950332 12.42243 -1.129694 49.28213
6.000332 12.52337 -1.130071 50.12957
6.050332 12.62226 -1.130308 50.11777
6.100332 12.72306 -1.130602 50.06156
6.150332 12.82166 -1.130830 50.02750
6.200332 12.92194 -1.130951 50.05115
6.250332 13.02114 -1.131251 50.09992
6.300332 13.12131 -1.131378 49.96556
6.350332 13.22239 -1.131815 50.02030
6.400332 13.32082 -1.132374 49.92476
6.450332 13.42018 -1.132764 49.88889
6.500332 13.52106 -1.133328 49.92304
6.550332 13.62054 -1.133833 50.13850
6.600332 13.72030 -1.134539 50.02022
6.650332 13.82198 -1.135167 50.43658
6.700332 13.92014 -1.135841 50.02544
6.750332 14.02106 -1.136595 50.00559
6.800332 14.12192 -1.137087 50.55004
6.850332 14.21990 -1.137725 50.10154
6.900332 14.32167 -1.138182 50.10803
6.950332 14.42127 -1.138787 50.13515
7.000332 14.51972 -1.139160 50.09832
7.050332 14.62058 -1.139652 50.06194
7.100332 14.72037 -1.140105 50.15728
7.150332 14.82004 -1.140424 50.93009
7.200332 14.92099 -1.140640 50.09766
7.250332 15.01953 -1.141212 50.04203
7.300332 15.11980 -1.141300 50.09740
7.350332 15.21887 -1.141659 49.99636
7.400332 15.32040 -1.141943 50.20615
7.450332 15.41842 -1.142292 49.81934
7.500332 15.51990 -1.142949 50.21946
7.550332 15.62014 -1.143488 50.20540
7.600332 15.72014 -1.144249 50.09051
7.650332 15.82019 -1.144566 49.36493
7.700332 15.92069 -1.145109 49.98290
7.750332 16.01938 -1.145728 49.95880
7.800332 16.11947 -1.146204 49.93902
7.850332 16.22005 -1.146610 50.01410
7.900332 16.32064 -1.146759 49.96534
7.950332 16.42019 -1.146968 50.16918
8.000334 16.52037 -1.147085 49.90543
8.050332 16.61934 -1.147103 50.12480
8.100332 16.71934 -1.147254 49.87726
8.150332 16.81880 -1.147522 49.97054
8.200332 16.91889 -1.147503 50.04750
8.250334 17.01945 -1.147560 50.01507
8.300332 17.11834 -1.147634 49.95340
8.350332 17.21817 -1.147793 50.06010
8.400332 17.31815 -1.148207 49.97324
8.450332 17.41786 -1.148643 49.96974
8.500334 17.51855 -1.149189 50.18470
8.550332 17.61826 -1.149557 49.76280
8.600332 17.71814 -1.150088 49.87676
8.650332 17.81824 -1.150699 50.28112
8.700332 17.91770 -1.151088 49.75457
8.750334 18.01814 -1.151555 49.95298
8.800332 18.11743 -1.151993 49.84993
8.850332 18.21791 -1.152593 49.80408
8.900332 18.31920 -1.152940 49.98716
8.950332 18.41759 -1.153365 49.90752
9.000334 18.51813 -1.153752 49.98957
9.050332 18.61756 -1.153868 50.00909
9.100332 18.71722 -1.153735 49.92100
9.150332 18.81799 -1.153752 49.99096
9.200332 18.91712 -1.153958 49.94403
9.250334 19.01746 -1.154080 50.03014
9.300332 19.11648 -1.154301 49.98266
9.350332 19.21820 -1.154436 49.79466
9.400332 19.31610 -1.155046 50.11328
9.450332 19.41696 -1.155263 49.91422
9.500334 19.51778 -1.155919 50.18715
9.550332 19.61687 -1.156487 50.04494
9.600332 19.71921 -1.156710 50.31010
9.650332 19.81661 -1.157476 50.07428
9.700332 19.91640 -1.157951 49.44417
9.750334 20.01744 -1.158476 49.84814
9.800332 20.11681 -1.158752 50.03946
9.850332 20.21861 -1.158982 49.87545
9.900332 20.31678 -1.159462 50.01030
9.950332 20.41774 -1.159773 49.86810
10.00033 20.51608 -1.159866 50.06740
10.05033 20.61691 -1.160027 49.92947
10.10033 20.71645 -1.160245 49.88434
10.15033 20.81708 -1.160511 49.94394
10.20033 20.91606 -1.160751 50.01980
10.25033 21.01555 -1.161034 49.35904
10.30033 21.11491 -1.161342 50.00076
10.35033 21.21464 -1.161392 49.96594
10.40033 21.31541 -1.161540 50.10442
10.45033 21.41618 -1.161918 49.75344
10.50034 21.51524 -1.162085 49.74224
10.55033 21.61608 -1.162614 50.04356
10.60033 21.71464 -1.163114 49.91438
10.65033 21.81534 -1.163523 49.98444
10.70033 21.91646 -1.164103 49.97452
10.75034 22.01586 -1.164264 50.17204
10.80033 22.11662 -1.164745 50.54630
10.85033 22.21489 -1.165152 49.92306
10.90033 22.31396 -1.165345 50.17256
10.95033 22.41549 -1.165368 49.84918
11.00034 22.51420 -1.165595 50.06634
11.05033 22.61428 -1.165826 50.08159
11.10033 22.71556 -1.166026 49.95730
11.15033 22.81476 -1.166487 49.82046
11.20033 22.91522 -1.166734 49.19797
11.25034 23.01444 -1.167116 49.94418
11.30033 23.11455 -1.167306 50.04492
11.35033 23.21458 -1.167648 50.01026
11.40033 23.31414 -1.167604 49.91425
11.45033 23.41376 -1.167943 50.05450
11.50034 23.51488 -1.168227 49.89756
11.55033 23.61581 -1.168514 49.47184
11.60033 23.71478 -1.168888 49.73813
11.65033 23.81452 -1.169261 49.88682
11.70033 23.91502 -1.169699 49.85470
11.75034 24.01363 -1.170140 49.94476
11.80033 24.11382 -1.170476 49.85313
11.85033 24.21382 -1.170804 49.71702
11.90033 24.31404 -1.171291 49.98590
11.95033 24.41252 -1.171490 50.07049
12.00034 24.51277 -1.171726 49.97997
12.05033 24.61346 -1.172032 49.71848
12.10033 24.71407 -1.172201 49.14878
12.15033 24.81402 -1.172497 49.77406
12.20033 24.91292 -1.172716 49.66924
12.25034 25.01232 -1.173221 49.83310
12.30033 25.11356 -1.173747 50.04609
12.35033 25.21210 -1.174414 50.00424
12.40033 25.31394 -1.174770 49.96738
12.45033 25.41254 -1.175158 49.92685
12.50034 25.51326 -1.175640 49.91992
12.55033 25.61322 -1.176151 50.15966
12.60033 25.71298 -1.176568 49.90870
12.65033 25.81356 -1.177268 49.95172
12.70033 25.91358 -1.177600 49.97665
12.75034 26.01267 -1.177979 50.13004
12.80033 26.11442 -1.178209 49.99312
12.85033 26.21417 -1.178466 49.95338
12.90033 26.31357 -1.178860 49.92130
12.95034 26.41274 -1.179124 50.15672
13.00034 26.51248 -1.179551 49.89856
13.05033 26.61309 -1.179564 50.00750
13.10033 26.71184 -1.180003 49.94708
13.15033 26.81116 -1.180202 49.95306
13.20034 26.91175 -1.180450 49.75052
13.25034 27.01175 -1.180510 50.03876
13.30033 27.11178 -1.180810 49.78696
13.35033 27.21201 -1.181177 49.89879
13.40033 27.31050 -1.181412 49.95992
13.45034 27.41073 -1.181746 50.05866
13.50034 27.51070 -1.182086 50.01062
13.55033 27.61073 -1.182439 50.01978
13.60033 27.71041 -1.182976 49.99696
13.65033 27.81028 -1.183500 50.01220
13.70034 27.91081 -1.184090 49.96914
13.75034 28.01218 -1.184717 50.09668
13.80033 28.11170 -1.185457 49.75425
13.85033 28.21041 -1.186046 49.92078
13.90033 28.31057 -1.186798 50.14730
13.95034 28.41084 -1.187439 49.87850
14.00034 28.51138 -1.188017 50.13634
14.05033 28.61122 -1.188274 50.00774
14.10033 28.71194 -1.188806 49.84364
14.15033 28.81118 -1.189103 49.76928
14.20034 28.90996 -1.189310 50.06958
14.25034 29.00992 -1.189654 50.13463
14.30033 29.11047 -1.190168 50.10215
14.35033 29.20994 -1.190836 50.13054
14.40033 29.31086 -1.191470 50.15800
14.45034 29.41050 -1.192216 49.95960
14.50034 29.51012 -1.192834 50.10552
14.55033 29.61074 -1.193665 49.97022
14.60033 29.71008 -1.194166 50.09102
14.65033 29.80970 -1.194520 50.09516
14.70034 29.91014 -1.194898 49.80000
14.75034 30.00908 -1.195290 49.88409
14.80033 30.10864 -1.195755 50.11520
14.85033 30.20815 -1.196288 50.01562
14.90033 30.30957 -1.196680 50.06033
14.95034 30.40922 -1.197217 49.97247
15.00034 30.50909 -1.197648 49.85307
15.05033 30.60852 -1.198145 49.80603
15.10033 30.70941 -1.198766 50.04324
15.15033 30.80787 -1.199464 49.99350
15.20034 30.90907 -1.200019 49.95691
15.25034 31.00872 -1.200889 49.95228
15.30033 31.10889 -1.201634 49.99521
15.35033 31.21000 -1.202507 50.08717
15.40033 31.30985 -1.203416 49.99081
15.45034 31.40884 -1.204313 50.10434
15.50034 31.50883 -1.205294 50.10762
15.55033 31.60787 -1.206057 50.03810
15.60033 31.70888 -1.206840 49.91097
15.65033 31.80759 -1.207662 49.85426
15.70034 31.90832 -1.208514 49.98644
15.75034 32.00841 -1.209158 49.91410
15.80033 32.10845 -1.209846 50.01157
15.85033 32.20870 -1.210763 50.13791
15.90033 32.30834 -1.211556 49.96622
15.95034 32.40943 -1.212175 50.09878
16.00033 32.50688 -1.213021 50.02576
16.05033 32.60749 -1.213800 50.14970
16.10033 32.70705 -1.214448 50.07266
16.15033 32.80702 -1.214815 50.09541
16.20033 32.90690 -1.215274 50.08170
16.25033 33.00652 -1.215742 50.02631
16.30033 33.10710 -1.216008 50.10887
16.35033 33.20622 -1.216366 49.94556
16.40033 33.30447 -1.216983 49.93886
16.45033 33.40515 -1.217650 49.85547
16.50033 33.50584 -1.218485 50.08145
16.55033 33.60440 -1.219677 50.10064
16.60033 33.70400 -1.220991 50.11842
16.65033 33.80586 -1.222192 49.77746
16.70033 33.90546 -1.223521 49.87280
16.75033 34.00437 -1.224956 49.93889
16.80033 34.10447 -1.226140 50.21806
16.85033 34.20481 -1.227224 50.02369
16.90033 34.30476 -1.228676 50.07390
16.95033 34.40510 -1.230072 49.87048
17.00033 34.50456 -1.231614 49.87606
17.05033 34.60440 -1.233164 49.95484
17.10033 34.70426 -1.234957 49.87789
17.15033 34.80406 -1.236798 49.88090
17.20033 34.90473 -1.239108 49.82574
17.25033 35.00430 -1.241414 50.07856
17.30033 35.10300 -1.244029 49.99613
17.35033 35.20300 -1.247090 50.10986
17.40033 35.30256 -1.250732 50.02122
17.45033 35.40281 -1.255102 50.03246
17.50033 35.50143 -1.260944 49.84520
17.55033 35.60004 -1.267145 50.20260
17.60033 35.69974 -1.273910 50.15219
17.65033 35.79861 -1.282532 50.06049
17.70033 35.89731 -1.292897 49.89466
17.75033 35.99644 -1.305550 49.86500
17.80033 36.09475 -1.324534 50.02063
17.85033 36.19421 -1.349134 50.01019
17.90033 36.29230 -1.381556 50.18189
17.95033 36.38875 -1.418346 49.98898
18.00033 36.48660 -1.459826 49.97676
18.05033 36.58328 -1.505133 49.97415
18.10033 36.68030 -1.555717 50.00464
18.15033 36.77789 -1.602423 49.92484
18.20033 36.87252 -1.658498 50.02170
18.25033 36.96808 -1.715111 50.08128
18.30033 37.06430 -1.773165 49.92835
18.35033 37.16000 -1.834492 50.02663
18.40033 37.25530 -1.892606 49.86373
18.45033 37.35009 -1.952009 50.06189
18.50033 37.44535 -2.009160 49.92950
18.55033 37.54051 -2.066604 50.13699
18.60033 37.63643 -2.116034 49.98587
18.65033 37.73097 -2.163240 49.77295
18.70033 37.82736 -2.211914 50.13632
18.75033 37.92348 -2.255039 49.96840
18.80033 38.02024 -2.293321 49.89604
18.85033 38.11680 -2.327763 50.11570
18.90033 38.21394 -2.359127 49.94492
18.95033 38.31180 -2.387777 49.97391
19.00033 38.40820 -2.417270 49.98675
19.05033 38.50518 -2.439818 49.84910
19.10033 38.60420 -2.460884 50.15350
19.15033 38.70139 -2.478405 50.11018
19.20033 38.79998 -2.494330 50.00613
19.25033 38.89831 -2.509777 49.98154
19.30033 38.99759 -2.524348 50.09307
19.35033 39.09637 -2.536770 49.91274
19.40033 39.19412 -2.549625 50.04180
19.45033 39.29434 -2.561977 50.05596
19.50033 39.39265 -2.572451 50.02763
19.55033 39.49134 -2.583237 49.30256
19.60033 39.59141 -2.592976 49.89116
19.65033 39.69053 -2.602050 49.67321
19.70033 39.78959 -2.611239 49.97180
19.75033 39.88894 -2.619794 50.11854
19.80033 39.98716 -2.628595 49.93811
19.85033 40.08685 -2.636945 49.88036
19.90033 40.18640 -2.645732 50.04204
19.95033 40.28490 -2.654172 49.94094
20.00033 40.38474 -2.662194 49.98574
20.05033 40.48429 -2.669934 50.07889
20.10033 40.58338 -2.678655 50.10872
20.15033 40.68170 -2.693475 49.95900
20.20033 40.78046 -2.728590 49.88697
20.25033 40.87700 -2.809050 50.00878
20.30033 40.97449 -2.818270 49.86234
20.35033 41.07512 -2.819390 49.97968
20.40033 41.17458 -2.816200 49.98801
20.45033 41.27609 -2.805366 49.96684
20.50033 41.37848 -2.766711 49.95122
20.55033 41.48209 -2.699258 50.06854
20.60033 41.58694 -2.589462 50.06894
20.65033 41.69534 -2.442133 49.85199
20.70033 41.80758 -2.275107 49.99538
20.75033 41.92138 -2.110386 50.08592
20.80033 42.03082 -1.967826 49.90056
20.85033 42.14362 -1.848330 50.00283
20.90033 42.25296 -1.750758 50.14378
20.95033 42.36143 -1.663372 49.96265
21.00033 42.46872 -1.592046 49.98739
21.05033 42.57452 -1.530458 49.77214
21.10033 42.67938 -1.485598 49.90586
21.15033 42.78347 -1.448359 49.94916
21.20033 42.88560 -1.418392 50.27144
21.25033 42.98933 -1.395838 49.88106
21.30033 43.09050 -1.378489 50.14282
21.35033 43.19062 -1.364317 50.13178
21.40033 43.29271 -1.356400 50.06320
21.45033 43.39447 -1.348140 50.16590
21.50033 43.49412 -1.340827 49.83086
21.55033 43.59592 -1.333718 49.91783
21.60033 43.69566 -1.327011 50.19922
21.65033 43.79581 -1.321196 49.87968
21.70033 43.89718 -1.315825 50.00918
21.75033 43.99720 -1.311237 50.15920
21.80033 44.09722 -1.307186 49.99050
21.85033 44.19808 -1.303802 50.04971
21.90033 44.29722 -1.300789 50.06357
21.95033 44.39803 -1.298378 49.90922
22.00033 44.49800 -1.296464 50.08974
22.05033 44.59712 -1.294703 49.73984
22.10033 44.69768 -1.293327 49.93362
22.15033 44.79790 -1.292224 49.95254
22.20033 44.89721 -1.291246 50.08590
22.25033 44.99734 -1.290849 49.85762
22.30033 45.09754 -1.290477 50.01722
22.35033 45.19782 -1.290445 50.10390
22.40033 45.29748 -1.290468 49.97421
22.45033 45.39888 -1.290938 50.08583
22.50033 45.49754 -1.291431 49.88576
22.55033 45.59769 -1.291781 49.75840
22.60033 45.69830 -1.291993 49.91758
22.65033 45.79746 -1.292279 49.78137
22.70033 45.89770 -1.292648 49.99347
22.75033 45.99671 -1.292922 49.92605
22.80033 46.09691 -1.293376 50.02857
22.85033 46.19672 -1.293909 50.08433
22.90033 46.29628 -1.294160 50.05342
22.95033 46.39708 -1.294762 50.05889
23.00033 46.49750 -1.295032 50.02844
23.05033 46.59592 -1.295587 49.98174
23.10033 46.69598 -1.296260 50.18102
23.15033 46.79661 -1.296869 50.02036
23.20033 46.89622 -1.297207 50.00546
23.25033 46.99517 -1.297681 49.94954
23.30033 47.09497 -1.298115 50.06728
23.35033 47.19506 -1.298715 49.98932
23.40033 47.29447 -1.299302 50.04582
23.45033 47.39419 -1.299938 50.03503
23.50033 47.49554 -1.300981 49.97035
23.55033 47.59538 -1.302042 49.99976
23.60033 47.69456 -1.303375 50.01598
23.65033 47.79397 -1.304564 49.84602
23.70033 47.89389 -1.305430 49.85709
23.75033 47.99426 -1.306178 50.22493
23.80033 48.09384 -1.307000 50.12343
23.85033 48.19388 -1.307524 49.93062
23.90033 48.29363 -1.308203 50.10263
23.95033 48.39309 -1.309252 50.09802
24.00033 48.49346 -1.310359 49.94555
24.05033 48.59406 -1.311252 50.07762
24.10033 48.69380 -1.312278 49.99050
24.15033 48.79248 -1.313414 49.43664
24.20033 48.89355 -1.314814 49.82990
24.25033 48.99276 -1.315953 49.93179
24.30033 49.09464 -1.316848 50.01196
24.35033 49.19402 -1.317585 50.06796
24.40033 49.29333 -1.318191 50.11431
24.45033 49.39250 -1.318398 49.92409
24.50033 49.49238 -1.318829 49.81572
24.55033 49.59272 -1.319048 49.81560
24.60033 49.69218 -1.319229 50.04604
24.65033 49.79228 -1.319409 49.93060
24.70033 49.89018 -1.319572 49.53904
24.75033 49.99053 -1.319698 49.88338
24.80033 50.09026 -1.320218 49.99926
24.85033 50.19038 -1.321098 50.09410
24.90033 50.29053 -1.321920 50.05990
24.95033 50.38992 -1.323126 49.94672
25.00033 50.48978 -1.324340 50.09326
25.05033 50.58954 -1.325635 49.88531
25.10033 50.68990 -1.326902 50.18070
25.15033 50.78966 -1.328396 49.77402
25.20033 50.88890 -1.330101 49.96652
25.25033 50.98886 -1.331632 50.02560
25.30033 51.08940 -1.333172 50.15096
25.35033 51.18900 -1.334641 50.01447
25.40033 51.28862 -1.335908 50.10706
25.45033 51.38922 -1.337198 50.00098
25.50033 51.48962 -1.338670 50.04590
25.55033 51.58994 -1.340216 49.83752
25.60033 51.68871 -1.341439 50.13631
25.65033 51.78926 -1.342449 49.86961
25.70033 51.88912 -1.343704 50.00294
25.75033 51.98816 -1.344777 49.84386
25.80033 52.08875 -1.345794 49.94892
25.85033 52.18775 -1.346706 50.12404
25.90033 52.28937 -1.347334 50.04244
25.95033 52.38843 -1.348198 50.03205
26.00033 52.48774 -1.349115 50.08826
26.05033 52.58762 -1.349919 49.92976
26.10033 52.68774 -1.350951 50.50411
26.15033 52.78715 -1.352001 50.11742
26.20033 52.88780 -1.353381 50.07926
26.25033 52.98695 -1.354546 49.90295
26.30033 53.08812 -1.355795 49.48840
26.35033 53.18735 -1.357222 50.04202
26.40033 53.28768 -1.358602 49.45601
26.45033 53.38695 -1.360302 49.67261
26.50033 53.48824 -1.361816 50.20770
26.55033 53.58709 -1.363358 50.02610
26.60033 53.68748 -1.364800 49.67469
26.65033 53.78764 -1.366206 49.83907
26.70033 53.88660 -1.367154 49.94537
26.75033 53.98628 -1.368134 49.90746
26.80033 54.08622 -1.368853 49.40364
26.85033 54.18606 -1.369469 49.99441
26.90033 54.28542 -1.370327 49.90552
26.95033 54.38557 -1.370972 50.04030
27.00033 54.48487 -1.371858 50.06168
27.05033 54.58409 -1.372629 49.86142
27.10033 54.68532 -1.373543 49.92962
27.15033 54.78458 -1.374653 49.56712
27.20033 54.88489 -1.375926 49.88665
27.25033 54.98489 -1.377312 50.15746
27.30033 55.08480 -1.378879 49.99965
27.35033 55.18496 -1.380418 50.02592
27.40033 55.28528 -1.382170 50.08988
27.45033 55.38430 -1.383529 49.96914
27.50033 55.48453 -1.385175 50.11382
27.55033 55.58458 -1.386757 50.15822
27.60033 55.68430 -1.388557 49.97545
27.65033 55.78440 -1.390068 50.01225
27.70033 55.88481 -1.391602 49.95837
27.75033 55.98457 -1.393224 50.17719
27.80033 56.08410 -1.394212 49.92032
27.85033 56.18438 -1.395210 50.05074
27.90033 56.28414 -1.396237 50.00713
27.95033 56.38314 -1.397061 49.92607
28.00033 56.48452 -1.398131 49.87206
28.05033 56.58278 -1.399265 49.94512
28.10033 56.68376 -1.400456 49.85939
28.15033 56.78288 -1.401715 49.93366
28.20033 56.88242 -1.403044 50.20291
28.25033 56.98203 -1.404301 50.05141
28.30033 57.08282 -1.405174 49.82500
28.35033 57.18086 -1.405861 49.98444
28.40033 57.28086 -1.406633 49.95137
28.45033 57.38121 -1.407404 49.82776
28.50033 57.47984 -1.408432 49.91836
28.55033 57.58060 -1.409502 49.99622
28.60033 57.68098 -1.410774 49.98492
28.65033 57.78059 -1.412244 50.07613
28.70033 57.88056 -1.414055 49.97430
28.75033 57.98066 -1.416142 50.03614
28.80033 58.08062 -1.418001 49.62488
28.85033 58.18084 -1.419876 50.08554
28.90033 58.28110 -1.421877 50.00220
28.95033 58.38026 -1.424011 50.12738
29.00033 58.47972 -1.425863 49.98502
29.05033 58.58136 -1.427582 50.00780
29.10033 58.68125 -1.429270 50.05180
29.15033 58.78101 -1.430750 50.11092
29.20033 58.87904 -1.432216 49.86090
29.25033 58.98118 -1.433486 50.00306
29.30033 59.07974 -1.434841 49.99250
29.35033 59.17937 -1.436050 49.90424
29.40033 59.27979 -1.437326 49.93532
29.45033 59.37964 -1.438789 50.07247
29.50033 59.47947 -1.439867 49.99998
29.55033 59.57559 -1.441587 49.90441
29.60033 59.64676 -1.388819 49.95091
29.65033 59.69732 -1.253977 50.13874
29.70033 59.73668 -1.124483 49.97711
29.75033 59.76970 -1.006433 50.14453
29.80033 59.79588 -0.8949250 49.83028
29.85033 59.81660 -0.7955382 50.18814
29.90033 59.83543 -0.7081290 50.03726
29.95033 59.84994 -0.6306754 49.90862
30.00033 59.86209 -0.5637564 50.00734
30.05033 59.87182 -0.5129222 50.65591
30.10033 59.88095 -0.4657430 49.99756
30.15033 59.88784 -0.4313793 49.90007
30.20033 59.89329 -0.3935720 49.87762
30.25033 59.89882 -0.3714390 49.94016
30.30033 59.90366 -0.3498794 49.92969
30.35033 59.90759 -0.3341767 50.05988
30.40033 59.91096 -0.3233425 50.06378
30.45033 59.91358 -0.3116202 50.10990
30.50033 59.91624 -0.3017951 50.00664
30.55033 59.91812 -0.2937142 49.86796
30.60033 59.92016 -0.2852251 50.03062
30.65033 59.92212 -0.2770692 49.95888
30.70033 59.92412 -0.2692299 50.05262
30.75033 59.92504 -0.2618185 49.79047
30.80033 59.92545 -0.2550725 49.93787
30.85033 59.92715 -0.2490422 50.12608
30.90033 59.92812 -0.2437694 49.88699
30.95033 59.92910 -0.2389223 50.12214
31.00033 59.93026 -0.2344586 50.06369
31.05033 59.93188 -0.2304350 48.35116
31.10033 59.93130 -0.2270900 49.96490
31.15033 59.93251 -0.2239520 49.85050
31.20033 59.93340 -0.2209354 49.79126
31.25033 59.93331 -0.2176323 49.96222
31.30033 59.93433 -0.2145312 50.03726
31.35033 59.93452 -0.2119886 49.98026
31.40033 59.93526 -0.2094948 50.10865
31.45033 59.93629 -0.2073990 49.87881
31.50033 59.93523 -0.2053692 50.05504
31.55033 59.93582 -0.2033958 49.91756
31.60033 59.93594 -0.2017591 49.97019
31.65033 59.93557 -0.2005172 49.88016
31.70033 59.93647 -0.1995552 49.93850
31.75033 59.93704 -0.1985940 49.92492
31.80033 59.93712 -0.1977399 50.12964
31.85034 59.93771 -0.1969429 50.11458
31.90033 59.93725 -0.1963382 50.10265
31.95033 59.93750 -0.1956796 49.68696
32.00033 59.93760 -0.1950914 49.94858
32.05033 59.93879 -0.1944708 49.93509
32.10034 59.93837 -0.1938875 49.72260
32.15033 59.93840 -0.1931905 49.93968
32.20033 59.93824 -0.1922763 49.95456
32.25033 59.93859 -0.1917896 50.56922
32.30033 59.93880 -0.1912405 49.95698
32.35034 59.93900 -0.1906224 49.96545
32.40033 59.93940 -0.1901929 49.95696
32.45033 59.93990 -0.1896347 50.06889
-2.000000 1.000000 0.0000000 0.0000000
32.54700 59.93632 -0.1890804 50.06612
32.59700 59.90998 -0.1306355 49.94942
32.64700 59.86124 0.01226717 49.99928
32.69700 59.79966 0.1410693 50.02884
32.74700 59.73046 0.2660590 49.81208
32.79700 59.65672 0.3797797 50.13871
32.84700 59.57734 0.4853473 49.92511
32.89700 59.49500 0.5735976 50.02753
32.94700 59.40873 0.6499566 50.14828
32.99700 59.32121 0.7191596 49.97280
33.04700 59.22984 0.7748389 50.04250
33.09700 59.13850 0.8227270 49.57062
33.14700 59.04530 0.8608032 50.01478
33.19700 58.95037 0.8918824 49.81094
33.24700 58.85682 0.9171020 50.11298
33.29700 58.76120 0.9398058 50.28350
33.34700 58.66484 0.9556426 50.20870
33.39700 58.56790 0.9703186 50.44875
33.44700 58.47107 0.9828047 49.81412
33.49700 58.37341 0.9920136 49.93686
33.54700 58.27630 1.001360 50.12988
33.59700 58.17828 1.010276 49.94418
33.64700 58.08012 1.018501 50.15160
33.69700 57.98266 1.026845 50.02753
33.74700 57.88324 1.034845 49.98940
33.79700 57.78560 1.042269 49.97436
33.84700 57.68670 1.049081 50.13556
33.89700 57.58687 1.055848 49.88050
33.94700 57.48795 1.062064 49.24838
33.99700 57.38932 1.067905 49.76511
34.04700 57.29036 1.073377 49.86868
34.09700 57.19068 1.078510 49.96400
34.14700 57.09325 1.083279 50.08172
34.19700 56.99238 1.087582 49.94111
34.24700 56.89386 1.091637 49.98665
34.29700 56.79336 1.095652 49.57660
34.34700 56.69540 1.099354 50.00635
34.39700 56.59549 1.102890 50.04200
34.44700 56.49496 1.106212 50.18520
34.49700 56.39543 1.109294 50.18934
34.54700 56.29616 1.112037 50.01557
34.59700 56.19632 1.115019 50.00104
34.64700 56.09678 1.117814 49.92875
34.69700 55.99747 1.120388 49.97968
34.74700 55.89832 1.122790 49.94383
34.79700 55.79773 1.125208 49.86597
34.84700 55.69868 1.127432 49.95768
34.89700 55.59990 1.129469 50.14127
34.94700 55.50009 1.131369 50.06408
34.99700 55.40128 1.133213 49.82188
35.04700 55.30116 1.135028 49.97694
35.09700 55.20139 1.136920 49.97791
35.14700 55.10194 1.138513 49.85951
35.19700 55.00262 1.140338 50.18442
35.24700 54.90234 1.142068 49.77212
35.29700 54.80157 1.143879 50.05344
35.34700 54.70300 1.145681 49.98594
35.39700 54.60251 1.147186 49.57300
35.44700 54.50262 1.148701 50.06711
35.49700 54.40405 1.150267 50.13467
35.54700 54.30356 1.151888 49.95924
35.59700 54.20371 1.153548 50.11404
35.64700 54.10455 1.154993 49.93296
35.69700 54.00498 1.156485 50.04913
35.74700 53.90500 1.158074 49.45231
35.79700 53.80527 1.159451 49.89160
35.84700 53.70520 1.160926 49.73261
35.89700 53.60541 1.162326 50.31754
35.94700 53.50610 1.163603 50.30873
35.99700 53.40600 1.164700 49.95404
36.04700 53.30669 1.165897 50.32513
36.09700 53.20661 1.167025 49.95122
36.14700 53.10734 1.168396 50.07187
36.19700 53.00704 1.169682 49.98977
36.24700 52.90744 1.171137 49.86887
36.29700 52.80822 1.172638 49.84128
36.34700 52.70836 1.174120 50.00117
36.39700 52.60840 1.175679 50.00944
36.44700 52.50726 1.177440 49.96802
36.49700 52.40769 1.179093 49.95234
36.54700 52.30829 1.180581 49.83738
36.59700 52.20824 1.182098 49.98170
36.64700 52.10792 1.183416 49.92695
36.69700 52.00826 1.184819 49.98532
36.74700 51.90961 1.186032 49.91472
36.79700 51.80884 1.187187 50.01730
36.84700 51.71026 1.188308 50.17304
36.89700 51.61022 1.189260 50.01993
36.94700 51.51006 1.190314 49.99598
36.99700 51.41020 1.191447 50.04680
37.04700 51.31074 1.192325 50.06317
37.09700 51.21026 1.193450 50.30324
37.14700 51.11098 1.194572 50.17139
37.19700 51.01180 1.195770 49.82857
37.24700 50.91126 1.197026 49.93770
37.29700 50.81158 1.198234 49.97402
37.34700 50.71211 1.199540 49.98042
37.39700 50.61231 1.200581 49.96716
37.44700 50.51230 1.201579 49.99866
37.49700 50.41228 1.202730 50.07524
37.54700 50.31240 1.203788 49.99224
37.59700 50.21290 1.204815 50.06865
37.64700 50.11266 1.205755 49.91562
37.69700 50.01352 1.206466 49.43966
37.74700 49.91322 1.207426 49.92026
37.79700 49.81331 1.208319 49.98510
37.84700 49.71364 1.209331 50.02976
37.89700 49.61339 1.210126 49.75308
37.94700 49.51382 1.211134 50.05835
37.99700 49.41412 1.212226 50.08850
38.04700 49.31324 1.213522 50.00422
38.09700 49.21388 1.214652 49.87058
38.14700 49.11444 1.215794 49.83227
38.19700 49.01400 1.216953 49.88886
38.24700 48.91396 1.217929 49.98646
38.29700 48.81426 1.218830 49.95032
38.34700 48.71491 1.219996 50.17796
38.39700 48.61447 1.220914 49.43648
38.44700 48.51471 1.221783 49.88303
38.49700 48.41522 1.222697 50.54717
38.54700 48.31592 1.223451 50.04528
38.59700 48.21536 1.224350 50.05784
38.64700 48.11572 1.225209 50.12986
38.69700 48.01618 1.226200 49.97553
38.74700 47.91551 1.226993 50.13329
38.79700 47.81544 1.227853 49.92891
38.84700 47.71669 1.228858 50.15506
38.89700 47.61746 1.229658 50.22079
38.94700 47.51659 1.230569 49.56414
38.99700 47.41723 1.231487 50.12506
39.04700 47.31792 1.232406 50.02224
39.09700 47.21759 1.233334 50.03041
39.14700 47.11734 1.234053 50.16201
39.19700 47.01787 1.234918 49.91711
39.24700 46.91858 1.235751 49.92039
39.29700 46.81742 1.236712 49.36648
39.34700 46.71863 1.237748 50.04799
39.39700 46.61856 1.238656 50.13217
39.44700 46.51760 1.239781 50.33794
39.49700 46.41952 1.240782 49.21478
39.54700 46.31797 1.241943 49.90390
39.59700 46.21887 1.243296 50.02167
39.64700 46.11902 1.244230 49.96700
39.69700 46.01868 1.245278 49.98201
39.74700 45.91915 1.246145 49.99766
39.79700 45.81930 1.246827 50.30744
39.84700 45.71984 1.247772 49.93493
39.89700 45.61906 1.248453 50.02666
39.94700 45.51980 1.249078 50.09458
39.99700 45.42011 1.249922 49.83437
40.04700 45.32004 1.250538 50.05350
40.09700 45.22042 1.250985 50.12910
40.14700 45.12071 1.251591 49.81390
40.19700 45.02084 1.252335 50.19864
40.24700 44.92132 1.253094 50.03645
40.29700 44.82174 1.253818 49.94421
40.34700 44.72171 1.254664 49.87570
40.39700 44.62150 1.255394 49.92880
40.44700 44.52168 1.256197 49.78974
40.49700 44.42170 1.256963 49.94130
40.54700 44.32197 1.257568 50.16284
40.59700 44.22254 1.258172 50.24669
40.64700 44.12204 1.258844 49.99362
40.69700 44.02172 1.259433 49.90454
40.74700 43.92320 1.260046 50.06228
40.79700 43.82334 1.260841 50.17960
40.84700 43.72257 1.261743 49.80868
40.89700 43.62211 1.262980 49.94598
40.94700 43.52209 1.264146 49.90996
40.99700 43.42306 1.265252 49.99504
41.04700 43.32200 1.266139 50.14392
41.09700 43.22178 1.267022 49.90014
41.14700 43.12268 1.267758 49.88414
41.19700 43.02252 1.268262 49.81594
41.24700 42.92290 1.268736 50.14298
41.29700 42.82272 1.269200 49.86312
41.34700 42.72338 1.269713 49.99358
41.39700 42.62278 1.270170 49.97800
41.44700 42.52358 1.270838 50.10067
41.49700 42.42422 1.271113 50.07790
41.54700 42.32374 1.271641 49.95863
41.59700 42.22354 1.271968 50.10347
41.64700 42.12376 1.272316 49.95419
41.69700 42.02544 1.272869 49.96707
41.74700 41.92440 1.273239 50.06970
41.79700 41.82430 1.273698 50.02563
41.84700 41.72498 1.274099 50.00433
41.89700 41.62450 1.274628 49.97065
41.94700 41.52551 1.275057 49.89578
41.99700 41.42540 1.275641 49.98989
42.04700 41.32540 1.276147 50.03511
42.09700 41.22650 1.276851 49.94224
42.14700 41.12541 1.277639 49.94956
42.19700 41.02661 1.278396 50.07694
42.24700 40.92539 1.279280 50.04463
42.29700 40.82565 1.280136 49.96888
42.34700 40.72622 1.281077 49.97835
42.39700 40.62631 1.281982 49.79010
42.44700 40.52606 1.282702 49.93594
42.49700 40.42698 1.283268 49.81278
42.54700 40.32669 1.283859 49.98555
42.59700 40.22646 1.284431 49.76504
42.64700 40.12659 1.284806 50.01102
42.69700 40.02653 1.285279 49.92950
42.74700 39.92699 1.285870 50.07697
42.79700 39.82693 1.286333 50.08093
42.84700 39.72785 1.286865 50.08672
42.89700 39.62808 1.287353 49.78639
42.94700 39.52820 1.287816 49.92159
42.99700 39.42789 1.288444 50.06796
43.04700 39.32732 1.289318 49.52333
43.09700 39.22734 1.290110 49.89813
43.14700 39.12716 1.290784 50.06611
43.19700 39.02745 1.291388 49.97676
43.24700 38.92827 1.292114 50.33219
43.29700 38.82813 1.292614 49.98574
43.34700 38.72750 1.293030 49.90954
43.39700 38.62796 1.293402 50.16330
43.44700 38.52822 1.293759 49.91052
43.49700 38.42825 1.293942 49.93915
43.54700 38.32788 1.294138 49.93043
43.59700 38.22842 1.294519 49.95490
43.64700 38.12810 1.294873 50.08072
43.69700 38.02784 1.295032 49.91761
43.74700 37.92945 1.295466 49.93546
43.79700 37.82982 1.295823 49.88478
43.84700 37.73000 1.296376 50.00580
43.89700 37.62939 1.296995 50.11287
43.94700 37.53014 1.297408 49.99802
43.99700 37.42847 1.298013 50.13948
44.04700 37.32930 1.298395 49.99585
44.09700 37.23000 1.298840 50.01580
44.14700 37.13011 1.299341 50.02139
44.19700 37.02958 1.299689 50.01196
44.24700 36.93027 1.300245 50.07170
44.29700 36.82985 1.300717 50.05262
44.34700 36.73064 1.301318 49.92729
44.39700 36.63028 1.302062 50.03128
44.44700 36.53016 1.302952 49.99772
44.49700 36.43006 1.303745 50.00694
44.54700 36.32931 1.304738 49.98303
44.59700 36.23008 1.305618 49.97500
44.64700 36.13147 1.306891 50.24250
44.69700 36.03181 1.308385 49.82441
44.74700 35.93137 1.310432 50.09084
44.79700 35.83176 1.313559 50.09744
44.84700 35.73367 1.318707 49.90768
44.89700 35.63428 1.340472 49.99539
44.94700 35.53713 1.396736 49.93984
44.99700 35.44214 1.494511 49.78170
45.04700 35.34910 1.640436 49.94272
45.09700 35.26187 1.844102 49.35167
45.14700 35.17926 2.129229 49.95831
45.19700 35.10344 2.507218 49.97584
45.24700 35.03470 2.968574 50.12713
45.29700 34.97140 3.471091 49.99126
45.34700 34.91152 3.978595 49.89934
45.39700 34.85008 4.425296 49.97231
45.44700 34.78548 4.772494 49.99252
45.49700 34.71230 4.997822 50.05608
45.54700 34.62967 5.100540 50.04154
45.59700 34.53774 5.100074 50.05170
45.64700 34.43844 5.039596 49.83560
45.69700 34.33242 4.897476 49.83285
45.74700 34.22258 4.721484 49.99988
45.79700 34.10831 4.524613 50.08672
45.84700 33.99246 4.307981 49.88760
45.89700 33.87548 4.078834 50.18076
45.94700 33.75706 3.839550 49.92690
45.99700 33.63705 3.593276 50.20060
46.04700 33.51703 3.344630 50.12336
46.09700 33.39801 3.108876 49.87895
46.14700 33.27902 2.887477 50.12510
46.19700 33.16294 2.704937 49.95297
46.24700 33.04844 2.546144 49.95982
46.29700 32.93429 2.396094 49.82756
46.34700 32.82162 2.246440 50.14481
46.39700 32.71084 2.103034 49.99266
46.44700 32.59908 1.978768 50.05716
46.49700 32.48830 1.871189 49.85633
46.54700 32.37898 1.779694 50.18216
46.59700 32.27168 1.703020 50.10434
46.64700 32.16692 1.642112 50.13469
46.69700 32.06120 1.592305 50.07826
46.74700 31.95688 1.550797 49.99403
46.79700 31.85353 1.517049 50.13038
46.84700 31.75054 1.488245 50.20044
46.89700 31.64866 1.468874 49.97520
46.94700 31.54630 1.451073 50.04957
46.99700 31.44451 1.438645 50.19992
47.04700 31.34305 1.428588 50.00231
47.09700 31.24248 1.420716 48.86302
47.14700 31.13974 1.412957 49.85390
47.19700 31.03914 1.405464 50.10987
47.24700 30.93807 1.397696 49.38781
47.29700 30.83753 1.390500 50.05832
47.34700 30.73776 1.383848 49.96640
47.39700 30.63714 1.377484 49.31763
47.44700 30.53641 1.371629 50.01594
47.49700 30.43705 1.366396 50.09809
47.54700 30.33666 1.361728 50.01306
47.59700 30.23666 1.357409 49.90606
47.64700 30.13793 1.353592 49.50615
47.69700 30.03721 1.350261 49.79825
47.74700 29.93760 1.347227 49.87612
47.79700 29.83736 1.344531 49.94394
47.84700 29.73830 1.342039 50.13004
47.89700 29.63828 1.339976 50.21069
47.94700 29.53886 1.338313 49.90348
47.99700 29.43804 1.336942 50.03383
48.04700 29.33680 1.335648 49.89172
48.09700 29.23783 1.334476 49.89757
48.14700 29.13740 1.333585 50.07840
48.19700 29.03763 1.332804 49.98446
48.24700 28.93916 1.331956 50.00276
48.29700 28.83757 1.331374 49.94959
48.34700 28.73881 1.330868 49.24504
48.39700 28.63814 1.330312 50.12094
48.44700 28.53850 1.329845 50.04356
48.49700 28.43860 1.329348 50.12284
48.54700 28.33887 1.329052 50.27711
48.59700 28.23851 1.329013 50.04058
48.64700 28.13796 1.328990 49.75072
48.69700 28.03923 1.329090 49.93536
48.74700 27.93826 1.329290 50.02525
48.79700 27.83800 1.329572 49.93628
48.84700 27.73676 1.329928 49.86563
48.89700 27.63706 1.330188 50.01425
48.94700 27.53718 1.330309 49.93566
48.99700 27.43630 1.330378 50.09446
49.04700 27.33740 1.330047 50.15207
49.09700 27.23724 1.329733 49.95214
49.14700 27.13682 1.329311 49.98960
49.19700 27.03734 1.328690 50.04848
49.24700 26.93730 1.328016 49.95130
49.29700 26.83859 1.327316 50.23691
49.34700 26.73837 1.326856 49.73193
49.39700 26.63742 1.326601 50.14383
49.44700 26.53882 1.326474 50.00320
49.49700 26.43765 1.326517 49.92862
49.54700 26.33802 1.326264 49.72596
49.59700 26.23921 1.326260 49.95872
49.64700 26.13817 1.326119 50.00602
49.69700 26.03865 1.326003 50.06064
49.74700 25.93912 1.325892 50.22945
49.79700 25.83853 1.325738 49.88842
49.84700 25.73944 1.325672 50.02616
49.89700 25.63877 1.325559 50.25130
49.94700 25.53888 1.325731 50.13594
49.99700 25.43884 1.325869 50.29865
50.04700 25.33944 1.326098 49.92440
50.09700 25.23894 1.326207 50.06567
50.14700 25.13956 1.326432 49.89317
50.19700 25.03846 1.326581 50.11246
50.24700 24.93934 1.326673 49.90674
50.29700 24.83952 1.326772 49.95066
50.34700 24.73866 1.326987 49.99081
50.39700 24.63944 1.327146 49.98944
50.44700 24.53931 1.327402 49.83266
50.49700 24.43915 1.327628 49.98042
50.54700 24.33835 1.327981 50.06236
50.59700 24.23822 1.328522 50.00676
50.64700 24.13802 1.328867 49.90340
50.69700 24.03796 1.329048 49.83944
50.74700 23.93855 1.329318 50.08148
50.79700 23.83863 1.329397 49.90689
50.84700 23.73810 1.329448 49.92782
50.89700 23.63916 1.329534 49.96750
50.94700 23.53880 1.329506 49.86272
50.99700 23.43885 1.329372 49.96511
51.04700 23.34018 1.329094 50.05169
51.09700 23.23926 1.328996 49.97898
51.14700 23.13927 1.328745 50.06753
51.19700 23.03954 1.328472 50.18360
51.24700 22.93984 1.328147 49.98786
51.29700 22.84070 1.327734 50.17152
51.34700 22.74119 1.327513 49.90645
51.39700 22.64086 1.327502 50.07122
51.44700 22.54170 1.327322 50.12904
51.49700 22.44138 1.327444 49.93958
51.54700 22.34101 1.327466 49.91606
51.59700 22.24156 1.327633 50.27136
51.64700 22.14170 1.327918 49.99536
51.69700 22.04152 1.328121 50.08736
51.74700 21.94150 1.328178 49.86407
51.79700 21.84113 1.328273 49.99716
51.84700 21.74117 1.328285 50.13708
51.89700 21.64106 1.328437 49.98938
51.94700 21.54192 1.328356 49.89022
51.99700 21.44211 1.328499 49.81652
52.04700 21.34216 1.328850 50.16520
52.09700 21.24090 1.329202 50.13346
52.14700 21.14202 1.329396 50.07406
52.19700 21.04096 1.329788 50.11259
52.24700 20.94235 1.330209 50.03339
52.29700 20.84086 1.330439 49.96464
52.34700 20.74172 1.330534 49.92917
52.39700 20.64057 1.330482 50.00620
52.44700 20.54190 1.330550 50.01370
52.49700 20.44135 1.330442 50.18786
52.54700 20.34208 1.330244 50.02050
52.59700 20.24158 1.330011 49.96006
52.64700 20.14289 1.329696 50.01666
52.69700 20.04251 1.329438 50.19362
52.74700 19.94251 1.329106 49.82020
52.79700 19.84310 1.329015 50.05500
52.84700 19.74238 1.328845 49.90234
52.89700 19.64250 1.328834 50.12704
52.94700 19.54318 1.328825 50.08779
52.99700 19.44298 1.328675 50.00708
53.04700 19.34240 1.328614 49.84133
53.09700 19.24333 1.328642 50.00471
53.14700 19.14337 1.328748 50.00988
53.19700 19.04352 1.328514 49.92720
53.24700 18.94365 1.328539 50.08592
53.29700 18.84343 1.328555 50.10814
53.34700 18.74352 1.328727 50.03452
53.39700 18.64284 1.328744 50.14802
53.44700 18.54373 1.328745 50.04214
53.49700 18.44344 1.328746 50.01266
53.54700 18.34323 1.328827 49.97934
53.59700 18.24342 1.328920 50.10012
53.64700 18.14265 1.329313 50.04272
53.69700 18.04277 1.329614 50.13052
53.74700 17.94298 1.329866 49.95926
53.79700 17.84300 1.330037 49.74174
53.84700 17.74312 1.330226 50.05020
53.89700 17.64162 1.330359 50.00907
53.94700 17.54257 1.330430 49.87769
53.99700 17.44219 1.330203 49.94287
54.04700 17.34277 1.330124 50.04996
54.09700 17.24336 1.329867 50.09030
54.14700 17.14395 1.329672 49.88974
54.19700 17.04327 1.329403 50.15500
54.24700 16.94328 1.329222 49.88300
54.29700 16.84389 1.329108 49.43984
54.34700 16.74428 1.329112 49.48881
54.39700 16.64431 1.329112 50.01946
54.44700 16.54449 1.328970 50.10822
54.49700 16.44394 1.328822 49.96624
54.54700 16.34434 1.328561 49.93342
54.59700 16.24466 1.328648 49.86627
54.64700 16.14370 1.328467 50.01772
54.69700 16.04458 1.328539 49.22590
54.74700 15.94449 1.328588 50.10528
54.79700 15.84402 1.328544 49.87048
54.84700 15.74561 1.328528 49.87800
54.89700 15.64416 1.328576 50.04325
54.94700 15.54542 1.328574 49.97384
54.99700 15.44492 1.328588 50.03428
55.04700 15.34481 1.328705 49.95291
55.09700 15.24444 1.328668 49.81847
55.14700 15.14502 1.328637 50.17461
55.19700 15.04481 1.328629 50.08785
55.24700 14.94583 1.328437 49.97728
55.29700 14.84439 1.328311 49.95028
55.34700 14.74484 1.328384 50.02322
55.39700 14.64522 1.328466 49.95146
55.44700 14.54461 1.328479 50.03711
55.49700 14.44454 1.328480 50.05141
55.54700 14.34445 1.328550 49.83550
55.59700 14.24421 1.328574 49.94550
55.64700 14.14499 1.328576 50.01310
55.69700 14.04496 1.328618 49.86194
55.74700 13.94524 1.328618 50.03271
55.79700 13.84497 1.328751 49.92110
55.84700 13.74354 1.328779 49.96840
55.89700 13.64501 1.328708 50.14990
55.94700 13.54463 1.328572 49.90800
55.99700 13.44469 1.328518 50.10051
56.04700 13.34454 1.328368 49.93604
56.09700 13.24556 1.328275 50.04390
56.14700 13.14562 1.328238 50.20346
56.19700 13.04573 1.328000 49.91770
56.24700 12.94547 1.327768 50.01748
56.29700 12.84550 1.327604 49.91097
56.34700 12.74561 1.327376 50.04220
56.39700 12.64528 1.327223 50.16510
56.44700 12.54572 1.327089 49.96856
56.49700 12.44510 1.326746 50.00988
56.54700 12.34556 1.326483 50.16328
56.59700 12.24581 1.326461 49.99580
56.64700 12.14593 1.326219 50.05737
56.69700 12.04576 1.326122 50.00890
56.74700 11.94644 1.326116 50.03522
56.79700 11.84559 1.326027 49.96476
56.84700 11.74685 1.325780 50.00550
56.89700 11.64532 1.325642 49.49750
56.94700 11.54675 1.325326 50.07876
56.99700 11.44633 1.325073 49.95094
57.04700 11.34684 1.324712 50.02817
57.09700 11.24763 1.324310 49.86878
57.14700 11.14716 1.324248 49.97894
57.19700 11.04743 1.324104 50.02276
57.24700 10.94783 1.323977 49.90710
57.29700 10.84705 1.324109 50.06459
57.34700 10.74705 1.324305 50.21412
57.39700 10.64685 1.324186 49.97388
57.44700 10.54757 1.324266 50.05836
57.49700 10.44751 1.324319 49.94284
57.54700 10.34692 1.324406 49.95226
57.59700 10.24819 1.324452 49.95698
57.64700 10.14669 1.324605 50.01186
57.69700 10.04736 1.324686 50.04914
57.74700 9.947363 1.324709 50.15361
57.79700 9.847358 1.324514 49.96460
57.84700 9.746840 1.324618 50.08204
57.89700 9.647194 1.324573 49.85086
57.94700 9.546944 1.324574 50.15982
57.99700 9.446795 1.324473 49.76176
58.04700 9.347101 1.324291 50.05644
58.09700 9.247019 1.324211 49.81598
58.14700 9.147119 1.324176 49.95447
58.19700 9.047766 1.323883 50.31046
58.24700 8.946876 1.323694 49.84307
58.29700 8.847629 1.323485 50.13940
58.34700 8.746674 1.323292 49.93590
58.39700 8.647684 1.323164 49.96016
58.44700 8.547488 1.323061 50.14810
58.49700 8.446921 1.322986 49.92792
58.54700 8.348121 1.322860 50.08386
58.59700 8.247662 1.322759 49.99431
58.64700 8.147739 1.322508 49.92989
58.69700 8.048339 1.322092 50.02223
58.74700 7.947362 1.321952 49.83946
58.79700 7.847856 1.321925 49.96350
58.84700 7.747270 1.321640 50.22420
58.89700 7.648311 1.321669 50.06416
58.94700 7.547821 1.321463 49.88172
58.99700 7.447482 1.321458 50.10172
59.04700 7.347890 1.321195 50.01321
59.09700 7.248329 1.321190 49.94146
59.14700 7.147795 1.321283 49.94594
59.19700 7.048461 1.321013 49.80539
59.24700 6.947214 1.320932 49.96352
59.29700 6.847858 1.321075 49.88437
59.34700 6.748042 1.320892 49.94434
59.39700 6.648506 1.320821 49.95994
59.44700 6.548774 1.320770 49.71528
59.49700 6.449658 1.320468 50.04410
59.54700 6.348838 1.320164 50.09847
59.59700 6.248783 1.319848 50.00836
59.64700 6.149807 1.319619 49.59161
59.69700 6.049530 1.319352 50.08896
59.74700 5.950140 1.319344 50.02810
59.79700 5.848887 1.319259 50.12970
59.84700 5.749852 1.319139 50.01902
59.89700 5.650925 1.319052 50.13714
59.94700 5.549380 1.318934 49.86861
59.99700 5.451397 1.318793 50.06420
60.04700 5.350176 1.318761 49.92163
60.09700 5.249928 1.318816 49.85876
60.14700 5.151031 1.318770 50.00394
60.19700 5.050303 1.318726 50.11426
60.24700 4.950332 1.318667 50.08982
60.29700 4.850629 1.318833 50.00385
60.34700 4.750088 1.318982 49.98682
60.39700 4.650550 1.319105 49.99958
60.44700 4.550319 1.319308 50.16068
60.49700 4.450064 1.319482 49.91640
60.54700 4.349544 1.319746 49.86360
60.59700 4.249780 1.319938 49.77506
60.64700 4.149750 1.320079 50.03925
60.69700 4.049917 1.320115 49.95966
60.74700 3.949451 1.320163 49.82134
60.79700 3.849977 1.320221 50.04667
60.84700 3.750364 1.320299 49.87946
60.89700 3.650241 1.320263 49.89694
60.94700 3.550278 1.319974 49.93489
60.99700 3.450188 1.319755 50.04365
61.04700 3.349925 1.319652 49.91484
61.09700 3.248972 1.319499 49.98010
61.14700 3.150464 1.319256 49.96668
61.19700 3.050160 1.318911 50.06508
61.24700 2.949518 1.318870 49.94272
61.29700 2.850393 1.318576 49.95840
61.34700 2.750772 1.318228 49.89322
61.39700 2.649453 1.318070 50.17130
61.44700 2.550176 1.318174 50.10652
61.49700 2.448958 1.318450 49.95598
61.54700 2.349514 1.318648 49.84983
61.59700 2.249222 1.318809 50.14659
61.64700 2.149523 1.319044 50.04406
61.69700 2.049078 1.319177 50.21039
61.74700 1.948729 1.319142 50.08484
61.79700 1.848938 1.318970 49.81790
61.84700 1.750156 1.318861 50.01352
61.89700 1.648734 1.318598 49.92350
61.94700 1.548386 1.318486 50.04740
61.99700 1.448616 1.318032 50.31964
62.04700 1.352429 1.317989 49.99656
62.09700 1.278920 1.260838 49.94773
62.14700 1.229649 1.130357 50.04355
62.19700 1.189927 1.011314 49.90130
62.24700 1.159244 0.9021137 49.90984
62.29700 1.134134 0.7944700 50.09490
62.34700 1.112272 0.7029866 50.01705
62.39700 1.095757 0.6176526 49.85078
62.44700 1.080467 0.5493191 49.98056
62.49700 1.068598 0.4861542 50.11584
62.54700 1.058273 0.4334393 49.79793
62.59700 1.050887 0.3894100 49.89636
62.64700 1.044095 0.3517160 50.17408
62.69700 1.037388 0.3207260 49.97567
62.74700 1.032520 0.2975500 49.98722
62.79700 1.027947 0.2752352 50.01162
62.84700 1.025817 0.2596330 50.19978
62.89700 1.021479 0.2457199 50.02908
62.94700 1.019311 0.2354436 49.99797
62.99700 1.017601 0.2267098 49.91343
63.04700 1.015174 0.2186014 49.89837
63.09700 1.013384 0.2103996 49.85756
63.14700 1.011856 0.2024264 49.78264
63.19700 1.011060 0.1947568 50.07461
63.24700 1.009627 0.1874012 50.00840
63.29700 1.008481 0.1805448 50.21344
63.34700 1.007404 0.1744920 49.86554
63.39700 1.007222 0.1687284 50.12900
63.44700 1.005660 0.1637392 50.00752
63.49700 1.005457 0.1590788 50.04094
63.54700 1.004201 0.1548408 49.90214
63.59700 1.003639 0.1511078 50.01294
63.64700 1.003241 0.1477359 50.16033
63.69700 1.003001 0.1448283 50.15116
63.74700 1.002043 0.1421745 50.13754
63.79700 1.001924 0.1397975 50.08128
63.84700 1.000339 0.1377774 50.04124
63.89700 1.000194 0.1359031 50.10308
63.94700 1.000105 0.1343643 49.95109
63.99700 0.9997428 0.1328242 49.96548
64.04700 0.9993120 0.1315212 49.96197
64.09700 0.9984791 0.1302846 49.99780
64.14700 0.9976374 0.1292674 50.04996
64.19701 0.9976618 0.1282090 50.01196
64.24700 0.9968969 0.1273542 49.87642
64.29700 0.9965536 0.1265355 50.07758
64.34700 0.9963451 0.1257242 49.97430
64.39700 0.9964589 0.1247202 50.09915
64.44701 0.9966004 0.1237894 50.07322
64.49700 0.9972008 0.1229518 50.02254
64.54700 0.9963795 0.1219541 49.92370
64.59700 0.9962076 0.1209962 50.22004
64.64700 0.9956606 0.1201148 49.90328
64.69701 0.9966205 0.1194817 49.72512
64.74700 0.9973207 0.1187632 50.12980
64.79700 0.9961766 0.1182479 50.01516
-2.000000 2.000000 0.0000000 0.0000000