File: imagens/notebooks/dados experimentais/dsc/Karl_CTAB Sol-Liq.txt
CLOSED
Version	1.0
Language	English
Run	1
RunSerial	142
Instrument	DSC Q100 V9.9 Build 303
Module	DSC Standard Cell FC
Operator	LL
File	\\Niger\ta\Data\DSC\2018\Geral\Karl_CTAB Sol-Liq.001
ProcName	Karl
InstSerial	0100-1211
Sample	CTAB Sol+Liq
Size	8.80000	mg
Method	Karl
Comment
Xcomment	Pan: Aluminum Hermetic
Xcomment	Gas1: Nitrogen 50.0 ml/min
Xcomment	Gas2: Nitrogen 0.0 ml/min
Text
Exotherm	UP
Kcell	1.09030
Calib	-11.7822
TempCal	1	pts	158.71	156.60
TzeroDt	-90.0515 -0.0093 2.2263
TzeroDtz	-90.0515 0.0466 2.4421
InstCalFile	Tzero: \\Niger\ta\Data\DSC\CALIBRATION\20122016\CALIBRATION\0_RCS_12_20_2016 17_23_31.TZR
InstCalFile	Baseline: \\Niger\ta\Data\DSC\CALIBRATION\20122016\L.Base 20122016
InstCalFile	Sapphire: \\Niger\ta\Data\DSC\CALIBRATION\20122016\Safira 20122017.001
InstCalDate	Tzero 2016-12-20 Time 19:23:31
TempRange	-90.04 to 395.23 °C at 19.96 °C/min Heat Only
AutoZero	Delta T Offset 0.000 uV
AutoZero	Delta T0 Offset 0.000 uV
Controls	Gas 1  Event Off  Sampling 0.2
Cell#	FC-02451
CoolingUnit	RCS
SelHeatFlow	Heat Flow T4 (mW)
AutoAnalysis	Off
MacroFile
Nsig	4
Sig1	Time (min)
Sig2	Temperature (°C)
Sig3	Heat Flow (mW)
Sig4	Sample Purge Flow (mL/min)
Date	2018-05-15
Time	12:00:41
OrgMethod	1: Equilibrate at 1.00 °C
OrgMethod	2: Ramp 2.00 °C/min to 60.00 °C
OrgMethod	3: Isothermal for 3.00 min
OrgMethod	4: Mark end of cycle 1
OrgMethod	5: Ramp 2.00 °C/min to 1.00 °C
OrgMethod	6: Isothermal for 3.00 min
OrgMethod	7: Mark end of cycle 2
OrgFile	C:\TA\Data\DSC\2018\Geral\Karl_CTAB Sol-Liq.001
3.33324E-4 1.189074 1.327636 50.10722
0.05033332 1.174152 1.194097 49.95808
0.1003333 1.188533 1.027186 49.91876
0.1503333 1.227223 0.8392218 50.10498
0.2003333 1.278248 0.6476612 49.94033
0.2503333 1.337182 0.4510955 50.04781
0.3003333 1.399813 0.2920329 49.80030
0.3503333 1.469758 0.1149581 50.09944
0.4003334 1.541547 -.02521807 50.09303
0.4503334 1.618729 -0.1596993 50.06182
0.5003334 1.699294 -0.2714333 50.10996
0.5503332 1.782662 -0.3738164 50.07766
0.6003332 1.866457 -0.4595878 49.97916
0.6503332 1.951842 -0.5375076 49.99698
0.7003332 2.042878 -0.6038974 50.01953
0.7503332 2.130039 -0.6652838 49.99258
0.8003332 2.218872 -0.7170496 50.01861
0.8503332 2.312510 -0.7594366 50.01453
0.9003332 2.404163 -0.8004953 50.14357
0.9503334 2.497358 -0.8283369 50.17784
1.000333 2.591497 -0.8609832 49.92028
1.050334 2.685844 -0.8873086 50.04518
1.100334 2.781202 -0.9097512 50.11813
1.150334 2.877615 -0.9283431 49.87127
1.200334 2.973623 -0.9467170 49.95563
1.250334 3.068379 -0.9672828 50.15144
1.300334 3.166778 -0.9790897 49.88834
1.350333 3.262567 -0.9922519 50.15164
1.400333 3.360244 -1.000864 49.86254
1.450334 3.456766 -1.010990 50.15536
1.500333 3.554881 -1.020392 50.06373
1.550334 3.652432 -1.029604 50.17582
1.600334 3.749481 -1.040721 50.09714
1.650333 3.847174 -1.047668 50.03556
1.700334 3.946224 -1.055813 49.97493
1.750334 4.044705 -1.064816 50.05242
1.800334 4.144308 -1.072257 49.99629
1.850334 4.242176 -1.079533 50.04352
1.900334 4.339466 -1.084855 50.14256
1.950334 4.441181 -1.090369 49.95902
2.000334 4.537400 -1.095801 49.97860
2.050333 4.637178 -1.100695 50.06511
2.100334 4.735465 -1.105454 49.92020
2.150334 4.834420 -1.110004 50.04480
2.200334 4.932602 -1.114235 49.95771
2.250334 5.031148 -1.119449 49.92555
2.300333 5.134610 -1.122683 49.79650
2.350334 5.232269 -1.126077 49.99197
2.400334 5.330674 -1.130886 50.09465
2.450334 5.430569 -1.133755 50.02944
2.500334 5.530328 -1.136506 49.92076
2.550333 5.627498 -1.139529 49.89727
2.600333 5.728876 -1.142240 50.04150
2.650333 5.826489 -1.145077 50.11986
2.700333 5.925988 -1.147462 50.04962
2.750333 6.025278 -1.150154 49.91954
2.800333 6.125506 -1.152319 49.96732
2.850333 6.226851 -1.155508 49.94370
2.900333 6.325394 -1.157363 50.14038
2.950333 6.424207 -1.159331 50.12165
3.000333 6.524024 -1.160641 50.09544
3.050333 6.624571 -1.162006 50.13203
3.100333 6.724555 -1.163770 49.96370
3.150333 6.822434 -1.164993 50.02415
3.200333 6.921916 -1.166436 49.96754
3.250333 7.021636 -1.167474 49.90226
3.300333 7.120706 -1.169066 49.77494
3.350333 7.221032 -1.170022 49.93140
3.400333 7.319335 -1.170766 49.88520
3.450333 7.423260 -1.171063 49.98761
3.500333 7.519424 -1.171908 50.06375
3.550333 7.620554 -1.172668 50.23935
3.600333 7.717847 -1.173198 50.02528
3.650333 7.819171 -1.173406 50.21042
3.700333 7.919614 -1.173656 50.03833
3.750333 8.017370 -1.174420 50.10513
3.800333 8.118632 -1.174758 49.84524
3.850333 8.215532 -1.175236 49.94780
3.900333 8.316764 -1.175548 50.00879
3.950333 8.418631 -1.176008 49.88735
4.000333 8.515919 -1.176555 49.92728
4.050333 8.619922 -1.175248 50.04534
4.100333 8.718018 -1.176015 49.90725
4.150333 8.817553 -1.176664 49.89649
4.200333 8.917724 -1.176802 50.03162
4.250333 9.016411 -1.177355 50.13624
4.300333 9.116272 -1.177376 49.99686
4.350333 9.216869 -1.177612 50.08972
4.400333 9.315278 -1.177666 49.96878
4.450333 9.415524 -1.178069 49.99054
4.500333 9.517694 -1.178100 49.98200
4.550333 9.614476 -1.177976 49.89500
4.600333 9.715650 -1.177784 50.00262
4.650333 9.817547 -1.177418 49.98656
4.700333 9.916905 -1.176932 50.01481
4.750333 10.01526 -1.176586 49.98453
4.800333 10.11544 -1.176312 49.94531
4.850333 10.21552 -1.175894 49.77758
4.900333 10.31504 -1.175208 49.79090
4.950333 10.41451 -1.174740 49.98689
5.000333 10.51592 -1.174108 49.98497
5.050333 10.61569 -1.173135 50.00665
5.100333 10.71485 -1.172466 50.12844
5.150333 10.81372 -1.171625 49.86250
5.200333 10.91336 -1.171001 49.98752
5.250332 11.01336 -1.170312 50.17782
5.300332 11.11433 -1.169386 50.00590
5.350332 11.21413 -1.168848 49.97844
5.400332 11.31735 -1.167962 50.11291
5.450332 11.41523 -1.168096 49.91703
5.500332 11.51542 -1.169344 50.00418
5.550332 11.61367 -1.169890 49.98661
5.600332 11.71589 -1.171524 49.82811
5.650332 11.81252 -1.175836 50.10764
5.700332 11.91207 -1.187678 50.04824
5.750332 12.01166 -1.210824 50.02903
5.800332 12.10966 -1.233724 49.94644
5.850332 12.20585 -1.256442 50.04553
5.900332 12.30478 -1.291793 50.03115
5.950332 12.40331 -1.314837 49.77157
6.000332 12.50033 -1.346141 50.04564
6.050332 12.59625 -1.379016 49.81417
6.100332 12.69374 -1.417149 49.94676
6.150332 12.79152 -1.456026 50.20666
6.200332 12.88902 -1.501521 50.09628
6.250332 12.98512 -1.547820 50.08336
6.300332 13.07835 -1.600241 49.94630
6.350332 13.17706 -1.653710 50.02836
6.400332 13.27120 -1.704464 49.98839
6.450332 13.36819 -1.753594 50.15445
6.500332 13.46254 -1.810570 50.02866
6.550332 13.56022 -1.869667 50.15189
6.600332 13.65382 -1.934035 49.93118
6.650332 13.74788 -1.980206 49.90232
6.700332 13.84384 -2.034590 49.98866
6.750332 13.93825 -2.097119 50.02079
6.800332 14.03557 -2.145709 49.84844
6.850332 14.12888 -2.203867 50.06591
6.900332 14.22396 -2.255626 50.11515
6.950332 14.32234 -2.294813 50.08496
7.000332 14.41676 -2.347680 50.03921
7.050332 14.51263 -2.389510 50.00545
7.100332 14.60948 -2.431556 50.06360
7.150332 14.70766 -2.467484 49.94228
7.200332 14.80305 -2.498862 49.94351
7.250332 14.90075 -2.522240 49.92532
7.300332 15.00010 -2.542617 49.96189
7.350332 15.09562 -2.554900 50.07676
7.400332 15.19674 -2.561133 50.15180
7.450332 15.29689 -2.564767 49.91480
7.500332 15.39627 -2.563932 50.01134
7.550332 15.49827 -2.537432 50.06258
7.600332 15.60226 -2.463558 50.03943
7.650332 15.70966 -2.370240 49.97637
7.700332 15.81184 -2.281000 50.16702
7.750332 15.92252 -2.157972 49.89974
7.800332 16.03180 -2.047889 49.80147
7.850332 16.14110 -1.920350 49.91980
7.900332 16.25161 -1.794890 49.96311
7.950332 16.36049 -1.672360 49.94320
8.000334 16.47102 -1.560426 50.05650
8.050332 16.58144 -1.440310 49.92824
8.100332 16.68968 -1.327759 50.02454
8.150332 16.79972 -1.216821 50.18287
8.200332 16.90912 -1.110148 49.93236
8.250334 17.01890 -1.018616 50.05292
8.300332 17.12541 -0.9279014 49.99160
8.350332 17.23325 -0.8390488 49.96024
8.400332 17.34129 -0.7533631 49.87902
8.450332 17.44557 -0.6904954 50.03796
8.500334 17.55428 -0.6163960 50.04762
8.550332 17.65832 -0.5581989 50.21497
8.600332 17.76245 -0.5038660 50.05700
8.650332 17.86797 -0.4529574 49.99472
8.700332 17.97183 -0.4138806 49.89757
8.750334 18.07412 -0.3850733 50.02252
8.800332 18.17765 -0.3602746 49.93358
8.850332 18.27872 -0.3444306 49.96022
8.900332 18.38031 -0.3287312 49.93753
8.950332 18.48345 -0.3130569 50.01977
9.000334 18.58603 -0.3023087 49.98386
9.050332 18.68633 -0.2892694 49.83783
9.100332 18.78472 -0.2823225 50.00434
9.150332 18.88780 -0.2723760 49.79261
9.200332 18.98830 -0.2632240 50.09393
9.250334 19.08678 -0.2581580 49.98276
9.300332 19.18732 -0.2538658 49.92880
9.350332 19.29086 -0.2506485 49.90066
9.400332 19.38904 -0.2483152 49.87071
9.450332 19.48696 -0.2471438 50.16098
9.500334 19.58762 -0.2469220 49.93704
9.550332 19.68891 -0.2475788 49.82150
9.600332 19.78726 -0.2493601 50.08298
9.650332 19.88512 -0.2522672 50.09383
9.700332 19.98366 -0.2587508 49.96184
9.750334 20.08534 -0.2643676 50.08050
9.800332 20.18414 -0.2792034 50.09664
9.850332 20.28183 -0.2904154 50.07787
9.900332 20.37912 -0.3052757 49.94344
9.950332 20.47916 -0.3227096 49.90680
10.00033 20.57828 -0.3422674 50.15114
10.05033 20.67641 -0.3650376 50.06224
10.10033 20.77388 -0.3836626 49.85789
10.15033 20.87166 -0.4066125 49.94241
10.20033 20.97518 -0.4259085 50.03900
10.25033 21.06866 -0.4528614 49.86060
10.30033 21.16871 -0.4749284 50.11817
10.35033 21.26770 -0.4955814 49.96951
10.40033 21.36255 -0.5236362 49.91028
10.45033 21.46309 -0.5423059 50.03567
10.50034 21.56235 -0.5642488 50.16590
10.55033 21.65603 -0.5905039 50.05124
10.60033 21.75520 -0.6132290 50.16028
10.65033 21.85360 -0.6402848 49.96146
10.70033 21.95137 -0.6590960 49.90665
10.75034 22.05152 -0.6819732 50.16350
10.80033 22.14990 -0.7005781 49.95010
10.85033 22.24674 -0.7193738 50.08916
10.90033 22.34464 -0.7426294 50.01876
10.95033 22.44368 -0.7594388 49.93336
11.00034 22.54010 -0.7794032 50.02542
11.05033 22.63940 -0.7966368 49.88366
11.10033 22.73818 -0.8166687 50.01355
11.15033 22.83928 -0.8312634 49.91018
11.20033 22.93560 -0.8496806 50.15022
11.25034 23.03266 -0.8664405 50.03941
11.30033 23.13237 -0.8789551 50.01269
11.35033 23.23351 -0.8967866 50.07834
11.40033 23.33236 -0.9087186 50.07584
11.45033 23.42782 -0.9252114 49.89481
11.50034 23.52625 -0.9357691 50.04716
11.55033 23.62542 -0.9460125 50.02869
11.60033 23.72474 -0.9564672 50.07170
11.65033 23.82392 -0.9720226 49.93884
11.70033 23.92072 -0.9841132 49.94654
11.75034 24.02111 -0.9946166 49.92489
11.80033 24.11900 -1.008022 49.95608
11.85033 24.21708 -1.021693 50.15676
11.90033 24.31632 -1.036193 49.87176
11.95033 24.41820 -1.051748 49.86690
12.00034 24.51480 -1.066130 49.94500
12.05033 24.61597 -1.082811 50.04934
12.10033 24.71414 -1.094524 50.18152
12.15033 24.80996 -1.115978 49.99367
12.20033 24.90887 -1.136589 49.96470
12.25034 25.00823 -1.159821 50.15377
12.30033 25.10752 -1.174905 50.01730
12.35033 25.20456 -1.205021 50.00269
12.40033 25.30256 -1.237588 50.07778
12.45033 25.40059 -1.265733 50.03660
12.50034 25.49770 -1.299891 50.10909
12.55033 25.59615 -1.329773 50.14130
12.60033 25.69490 -1.365292 50.16389
12.65033 25.79234 -1.407602 49.96566
12.70033 25.88978 -1.451362 50.02750
12.75034 25.98353 -1.498684 50.02568
12.80033 26.08269 -1.554254 50.19040
12.85033 26.17525 -1.617646 49.96373
12.90033 26.27119 -1.686466 50.12038
12.95034 26.36507 -1.768934 50.03389
13.00034 26.45781 -1.854865 49.93746
13.05033 26.55063 -1.947168 50.04508
13.10033 26.64270 -2.040851 50.08804
13.15033 26.73479 -2.153386 49.96894
13.20034 26.82690 -2.243322 50.13817
13.25034 26.91816 -2.348615 50.00220
13.30033 27.00956 -2.454210 50.12571
13.35033 27.10320 -2.560252 49.97817
13.40033 27.19289 -2.662768 49.90703
13.45034 27.28510 -2.762314 50.15176
13.50034 27.37591 -2.885490 50.02280
13.55033 27.46880 -2.973461 49.93574
13.60033 27.55944 -3.068555 49.96913
13.65033 27.65240 -3.148780 50.13518
13.70034 27.74849 -3.207296 50.12079
13.75034 27.83998 -3.264888 49.90289
13.80033 27.93722 -3.304373 49.99698
13.85033 28.03005 -3.343606 49.87902
13.90033 28.12772 -3.373426 50.05270
13.95034 28.22561 -3.397314 49.85366
14.00034 28.32188 -3.418313 49.85482
14.05033 28.42252 -3.430128 49.98266
14.10033 28.52014 -3.438702 50.00168
14.15033 28.61904 -3.444883 49.89246
14.20034 28.71933 -3.449254 49.96567
14.25034 28.81984 -3.450950 49.99726
14.30033 28.92017 -3.444922 50.06517
14.35033 29.02194 -3.417694 49.96256
14.40033 29.12516 -3.365646 50.08828
14.45034 29.22919 -3.294152 49.96774
14.50034 29.33565 -3.210438 50.13869
14.55033 29.44463 -3.106326 50.05689
14.60033 29.54758 -2.991065 50.02209
14.65033 29.65924 -2.863715 50.04156
14.70034 29.76828 -2.710840 49.85796
14.75034 29.88200 -2.551033 50.10862
14.80033 29.99322 -2.394077 49.85160
14.85033 30.10870 -2.230545 49.85382
14.90033 30.21832 -2.078117 49.82316
14.95034 30.33128 -1.943903 49.98067
15.00034 30.44318 -1.819642 50.09415
15.05033 30.55268 -1.715045 50.06198
15.10033 30.66106 -1.635192 50.03563
15.15033 30.77060 -1.566078 49.92178
15.20034 30.87346 -1.512272 49.83523
15.25034 30.97866 -1.463516 50.10430
15.30033 31.08171 -1.433707 49.95209
15.35033 31.18444 -1.400150 50.05404
15.40033 31.28725 -1.380338 49.90117
15.45034 31.38889 -1.357539 49.88067
15.50034 31.49170 -1.342289 49.86088
15.55033 31.59473 -1.328681 50.10716
15.60033 31.69388 -1.320566 49.95967
15.65033 31.79614 -1.313374 50.16567
15.70034 31.89517 -1.306764 49.97470
15.75034 31.99754 -1.300044 49.97684
15.80033 32.09686 -1.294575 50.00861
15.85033 32.19675 -1.289356 50.05390
15.90033 32.29944 -1.283670 50.10773
15.95034 32.39832 -1.278889 49.89654
16.00033 32.49874 -1.274906 50.07294
16.05033 32.59936 -1.271087 49.85152
16.10033 32.69727 -1.267634 49.86422
16.15033 32.79937 -1.264431 49.89309
16.20033 32.89653 -1.261887 49.98162
16.25033 32.99760 -1.259432 49.93186
16.30033 33.09802 -1.257784 50.01754
16.35033 33.19750 -1.256311 49.89910
16.40033 33.29742 -1.255086 50.09400
16.45033 33.39780 -1.254659 49.91778
16.50033 33.49973 -1.254029 50.02490
16.55033 33.60031 -1.253783 50.11400
16.60033 33.69941 -1.253572 50.05836
16.65033 33.80016 -1.253496 50.05634
16.70033 33.89993 -1.253412 50.00559
16.75033 34.00022 -1.253462 50.10648
16.80033 34.10078 -1.253654 49.89864
16.85033 34.19948 -1.254090 50.09426
16.90033 34.29969 -1.254042 49.86720
16.95033 34.40037 -1.254070 49.46264
17.00033 34.49690 -1.254198 50.08594
17.05033 34.59748 -1.254398 50.06352
17.10033 34.69934 -1.254362 50.02309
17.15033 34.80026 -1.254604 50.01531
17.20033 34.89763 -1.254720 49.89521
17.25033 35.00005 -1.254661 49.99007
17.30033 35.09815 -1.255060 49.97239
17.35033 35.19917 -1.254976 50.07976
17.40033 35.29932 -1.254993 49.89583
17.45033 35.39792 -1.255454 49.78864
17.50033 35.49707 -1.255703 50.08362
17.55033 35.59912 -1.256159 50.09672
17.60033 35.70062 -1.256477 49.82854
17.65033 35.79741 -1.257715 49.92550
17.70033 35.89770 -1.257959 49.98117
17.75033 35.99748 -1.258381 49.95383
17.80033 36.09852 -1.258593 49.82406
17.85033 36.19648 -1.259031 50.03041
17.90033 36.29617 -1.259622 50.14797
17.95033 36.39736 -1.260614 49.90739
18.00033 36.49933 -1.260568 50.08763
18.05033 36.59756 -1.260876 50.12642
18.10033 36.69605 -1.260876 49.94332
18.15033 36.79619 -1.260669 49.98109
18.20033 36.89759 -1.260578 50.08223
18.25033 36.99476 -1.260822 49.88626
18.30033 37.09853 -1.260796 50.00437
18.35033 37.19861 -1.261436 49.95272
18.40033 37.29573 -1.261826 50.12607
18.45033 37.39506 -1.262478 50.01196
18.50033 37.49578 -1.263391 49.93054
18.55033 37.59866 -1.263706 50.01587
18.60033 37.69720 -1.264942 49.88348
18.65033 37.79551 -1.265152 49.95356
18.70033 37.89696 -1.265736 49.94887
18.75033 37.99518 -1.266116 49.96456
18.80033 38.09654 -1.266547 49.93637
18.85033 38.19594 -1.267120 49.99039
18.90033 38.29597 -1.267575 50.10076
18.95033 38.39685 -1.268161 49.95990
19.00033 38.49690 -1.268695 49.96445
19.05033 38.59510 -1.269377 50.14039
19.10033 38.69639 -1.269735 50.13938
19.15033 38.79588 -1.270212 49.87782
19.20033 38.89535 -1.271081 49.91339
19.25033 38.99640 -1.271387 49.94976
19.30033 39.09392 -1.271894 50.14070
19.35033 39.19522 -1.272165 50.01096
19.40033 39.29552 -1.272633 50.06441
19.45033 39.39622 -1.272931 50.14361
19.50033 39.49492 -1.273341 50.02440
19.55033 39.59366 -1.273451 49.89740
19.60033 39.69658 -1.273845 49.94314
19.65033 39.79511 -1.274793 50.10703
19.70033 39.89402 -1.275069 49.94154
19.75033 39.99448 -1.275690 50.02116
19.80033 40.09388 -1.276294 49.93326
19.85033 40.19612 -1.276415 50.02039
19.90033 40.29220 -1.277049 49.99436
19.95033 40.39356 -1.277084 49.92106
20.00033 40.49294 -1.277561 49.92008
20.05033 40.59260 -1.278076 50.12622
20.10033 40.69391 -1.278346 49.95690
20.15033 40.79280 -1.278716 49.89917
20.20033 40.89150 -1.279321 50.07402
20.25033 40.99175 -1.280200 50.10141
20.30033 41.09164 -1.280843 49.86641
20.35033 41.19283 -1.281696 50.12116
20.40033 41.29490 -1.282718 49.90482
20.45033 41.39397 -1.283654 50.02668
20.50033 41.49415 -1.284785 49.99626
20.55033 41.59062 -1.285873 50.05797
20.60033 41.69199 -1.287036 50.11690
20.65033 41.79390 -1.287888 50.10802
20.70033 41.89332 -1.289131 50.14398
20.75033 41.99281 -1.289935 49.96407
20.80033 42.09506 -1.290596 50.01872
20.85033 42.19267 -1.291367 49.95224
20.90033 42.29100 -1.292081 49.90584
20.95033 42.39209 -1.292461 50.15309
21.00033 42.49288 -1.292892 49.94741
21.05033 42.59180 -1.293281 50.18452
21.10033 42.69285 -1.293735 50.00978
21.15033 42.79244 -1.294351 50.14937
21.20033 42.89415 -1.294893 50.15484
21.25033 42.99182 -1.295713 50.10316
21.30033 43.09257 -1.296510 50.03054
21.35033 43.18948 -1.297046 50.03678
21.40033 43.29108 -1.297831 49.96878
21.45033 43.38974 -1.298793 50.09082
21.50033 43.49157 -1.299829 49.96326
21.55033 43.59088 -1.300979 49.94126
21.60033 43.69080 -1.301700 50.05178
21.65033 43.78956 -1.302720 50.06625
21.70033 43.89101 -1.303354 50.16036
21.75033 43.99038 -1.303867 50.15114
21.80033 44.09148 -1.304839 49.94196
21.85033 44.18986 -1.305494 50.08622
21.90033 44.28911 -1.306661 49.33718
21.95033 44.39042 -1.307457 50.05866
22.00033 44.49020 -1.308371 49.83933
22.05033 44.59208 -1.308802 50.16610
22.10033 44.68882 -1.309894 50.06478
22.15033 44.78909 -1.311028 50.01969
22.20033 44.88988 -1.312054 49.97879
22.25033 44.98972 -1.313025 50.04941
22.30033 45.08926 -1.314026 50.06378
22.35033 45.18872 -1.314750 49.92887
22.40033 45.28816 -1.315983 50.00910
22.45033 45.39040 -1.316668 50.07355
22.50033 45.48894 -1.317632 49.95139
22.55033 45.59123 -1.318550 49.97296
22.60033 45.68915 -1.319499 49.93496
22.65033 45.78972 -1.320327 49.99106
22.70033 45.88890 -1.321263 49.96914
22.75033 45.99011 -1.322324 49.92211
22.80033 46.08958 -1.323216 49.98984
22.85033 46.18956 -1.324566 49.98793
22.90033 46.28821 -1.325762 50.00060
22.95033 46.38776 -1.326648 49.89466
23.00033 46.48840 -1.327646 49.95474
23.05033 46.58856 -1.328282 49.86526
23.10033 46.68820 -1.328838 49.84308
23.15033 46.78616 -1.329844 49.89700
23.20033 46.88578 -1.330441 49.93140
23.25033 46.98750 -1.331305 50.08363
23.30033 47.08546 -1.332140 49.95383
23.35033 47.18759 -1.332906 49.84666
23.40033 47.28568 -1.333872 49.85903
23.45033 47.38523 -1.334672 50.26378
23.50033 47.48568 -1.335659 49.81332
23.55033 47.58616 -1.336733 49.77172
23.60033 47.68553 -1.337755 50.00457
23.65033 47.78812 -1.338717 50.19717
23.70033 47.88484 -1.340069 50.09316
23.75033 47.98549 -1.341620 50.21297
23.80033 48.08474 -1.343188 50.01350
23.85033 48.18567 -1.344460 49.82478
23.90033 48.28446 -1.345590 49.97350
23.95033 48.38355 -1.346818 50.05472
24.00033 48.48402 -1.348230 50.09424
24.05033 48.58413 -1.349382 50.15156
24.10033 48.68604 -1.350452 50.12698
24.15033 48.78516 -1.351743 49.92796
24.20033 48.88350 -1.352844 49.80637
24.25033 48.98391 -1.354272 49.93600
24.30033 49.08413 -1.355423 50.18533
24.35033 49.18661 -1.356666 50.01903
24.40033 49.28450 -1.357825 50.00687
24.45033 49.38612 -1.358555 50.03365
24.50033 49.48321 -1.359576 49.97574
24.55033 49.58372 -1.360790 50.08211
24.60033 49.68410 -1.361604 50.05847
24.65033 49.78278 -1.362491 50.10724
24.70033 49.88388 -1.363453 50.10502
24.75033 49.98382 -1.364519 49.97348
24.80033 50.08365 -1.365579 49.93192
24.85033 50.18470 -1.366975 49.17589
24.90033 50.28217 -1.368297 49.81137
24.95033 50.38141 -1.369883 49.98881
25.00033 50.48244 -1.371319 50.02237
25.05033 50.58188 -1.372644 49.90614
25.10033 50.68187 -1.373974 49.78680
25.15033 50.78075 -1.375796 50.23635
25.20033 50.88098 -1.377226 49.91820
25.25033 50.98098 -1.378406 49.97281
25.30033 51.08087 -1.379844 49.88360
25.35033 51.18146 -1.381052 50.13928
25.40033 51.28092 -1.382286 49.91602
25.45033 51.37982 -1.383699 49.94728
25.50033 51.48022 -1.385194 49.96723
25.55033 51.58043 -1.386681 49.86976
25.60033 51.68087 -1.388174 50.00761
25.65033 51.78079 -1.389585 50.03569
25.70033 51.87994 -1.391360 50.13803
25.75033 51.97954 -1.392922 49.88030
25.80033 52.08082 -1.394236 50.03912
25.85033 52.17958 -1.395958 50.05996
25.90033 52.27790 -1.397732 49.72888
25.95033 52.37784 -1.399587 49.87040
26.00033 52.47832 -1.401348 49.87006
26.05033 52.57778 -1.403432 49.99542
26.10033 52.67838 -1.404956 50.16546
26.15033 52.77844 -1.406970 50.15449
26.20033 52.87724 -1.408569 49.93984
26.25033 52.97519 -1.411163 50.02370
26.30033 53.07705 -1.412785 49.88200
26.35033 53.17663 -1.414744 49.87478
26.40033 53.27730 -1.416622 50.22860
26.45033 53.37618 -1.418813 50.13824
26.50033 53.47532 -1.421537 50.44072
26.55033 53.57615 -1.423398 50.09819
26.60033 53.67609 -1.425748 49.93724
26.65033 53.77701 -1.427730 49.85668
26.70033 53.87572 -1.429839 49.98929
26.75033 53.97586 -1.432054 50.12252
26.80033 54.07693 -1.434138 49.90844
26.85033 54.17548 -1.436283 49.94574
26.90033 54.27490 -1.438288 50.02910
26.95033 54.37479 -1.440742 49.91064
27.00033 54.47410 -1.442964 49.95297
27.05033 54.57502 -1.445070 49.91447
27.10033 54.67414 -1.446998 49.95081
27.15033 54.77375 -1.449094 49.99282
27.20033 54.87324 -1.451154 49.89218
27.25033 54.97246 -1.453103 49.99680
27.30033 55.07370 -1.455414 50.09729
27.35033 55.17178 -1.457401 49.90460
27.40033 55.27322 -1.459534 49.97817
27.45033 55.37276 -1.461903 49.94638
27.50033 55.47220 -1.464124 50.05600
27.55033 55.57340 -1.466402 49.94966
27.60033 55.67059 -1.468618 50.13426
27.65033 55.77053 -1.470579 50.06589
27.70033 55.87158 -1.472632 49.91410
27.75033 55.97139 -1.474921 49.90019
27.80033 56.07050 -1.477038 49.91914
27.85033 56.17132 -1.479114 50.03986
27.90033 56.27188 -1.481334 49.98571
27.95033 56.37000 -1.483756 50.11540
28.00033 56.47140 -1.486221 50.04988
28.05033 56.56973 -1.488584 50.00379
28.10033 56.67140 -1.490520 50.06494
28.15033 56.76950 -1.493094 50.07120
28.20033 56.86890 -1.495725 50.04334
28.25033 56.96938 -1.497898 49.81876
28.30033 57.06884 -1.500148 50.07120
28.35033 57.16974 -1.502371 50.04825
28.40033 57.26884 -1.504862 49.94394
28.45033 57.36801 -1.506837 50.01520
28.50033 57.47004 -1.509124 49.94075
28.55033 57.56768 -1.511200 49.91832
28.60033 57.66790 -1.512978 49.95620
28.65033 57.76734 -1.514730 50.02616
28.70033 57.86739 -1.516541 49.90579
28.75033 57.96703 -1.518026 49.90019
28.80033 58.06645 -1.519576 50.05614
28.85033 58.16692 -1.521470 49.94568
28.90033 58.26724 -1.522994 50.06842
28.95033 58.36543 -1.524634 50.05809
29.00033 58.46769 -1.526068 49.95162
29.05033 58.56775 -1.527627 50.23490
29.10033 58.66830 -1.529053 49.99277
29.15033 58.76600 -1.530887 50.03093
29.20033 58.86506 -1.532257 50.11442
29.25033 58.96426 -1.533734 50.12676
29.30033 59.06616 -1.534973 49.83404
29.35033 59.16370 -1.536111 49.90453
29.40033 59.26385 -1.537313 49.96194
29.45033 59.36530 -1.538576 50.05604
29.50033 59.46584 -1.539662 49.94126
29.55033 59.56004 -1.541474 49.82988
29.60033 59.63379 -1.523851 49.86180
29.65033 59.68433 -1.400221 50.03891
29.70033 59.72041 -1.289342 49.15921
29.75033 59.75312 -1.166072 49.94543
29.80033 59.77838 -1.057349 49.76715
29.85033 59.80157 -0.9495832 49.96398
29.90033 59.81959 -0.8505250 49.99362
29.95033 59.83429 -0.7696878 50.01260
30.00033 59.84850 -0.7008180 49.90454
30.05033 59.85870 -0.6391581 50.03656
30.10033 59.86813 -0.5798516 50.05788
30.15033 59.87746 -0.5350526 50.01856
30.20033 59.88364 -0.4953272 49.97717
30.25033 59.89063 -0.4633645 49.86453
30.30033 59.89328 -0.4358384 49.96540
30.35033 59.89965 -0.4142692 49.95713
30.40033 59.90135 -0.3930975 49.96614
30.45033 59.90508 -0.3779234 50.01219
30.50033 59.90814 -0.3630954 50.10707
30.55033 59.91180 -0.3501895 50.04753
30.60033 59.91433 -0.3422519 49.96478
30.65033 59.91426 -0.3330372 49.97160
30.70033 59.91813 -0.3236620 49.96127
30.75033 59.91845 -0.3153162 50.02285
30.80033 59.91982 -0.3080356 49.96920
30.85033 59.92236 -0.3005952 50.09912
30.90033 59.92318 -0.2938585 50.16928
30.95033 59.92442 -0.2869910 50.04020
31.00033 59.92617 -0.2811441 49.90730
31.05033 59.92534 -0.2756959 50.12144
31.10033 59.92802 -0.2701409 50.08312
31.15033 59.92579 -0.2652784 49.85348
31.20033 59.92695 -0.2610168 50.09014
31.25033 59.92817 -0.2565290 49.91267
31.30033 59.92893 -0.2533254 49.76988
31.35033 59.92919 -0.2501592 49.97702
31.40033 59.92904 -0.2473732 50.01248
31.45033 59.92969 -0.2445454 49.80710
31.50033 59.92970 -0.2420117 49.94403
31.55033 59.93086 -0.2395354 49.82114
31.60033 59.93116 -0.2372520 50.18706
31.65033 59.93200 -0.2350420 50.07739
31.70033 59.93126 -0.2331709 49.94784
31.75033 59.93339 -0.2312496 50.06191
31.80033 59.93344 -0.2293815 50.03760
31.85034 59.93278 -0.2275716 50.11710
31.90033 59.93232 -0.2259428 50.00518
31.95033 59.93130 -0.2244272 50.03044
32.00033 59.93277 -0.2231614 50.03418
32.05033 59.93363 -0.2218806 50.02090
32.10034 59.93365 -0.2209035 50.15163
32.15033 59.93406 -0.2200010 50.01931
32.20033 59.93418 -0.2190605 49.96420
32.25033 59.93494 -0.2183898 50.00410
32.30033 59.93271 -0.2176709 50.00934
32.35034 59.93414 -0.2169289 49.75843
32.40033 59.93326 -0.2164182 49.84032
32.45033 59.93434 -0.2157661 49.97547
-2.000000 1.000000 0.0000000 0.0000000
32.54700 59.93225 -0.2152323 49.79510
32.59700 59.90618 -0.1942442 50.13223
32.64700 59.85682 -.07018997 50.01774
32.69700 59.79336 0.05948852 50.10678
32.74700 59.72312 0.1787280 49.91806
32.79700 59.64904 0.2923617 50.05496
32.84700 59.57224 0.3980132 50.16220
32.89700 59.48914 0.4997746 50.02876
32.94700 59.40316 0.5822403 49.82022
32.99700 59.31520 0.6597955 49.96761
33.04700 59.22588 0.7229597 50.05806
33.09700 59.13364 0.7773266 49.95253
33.14700 59.04265 0.8223532 49.98969
33.19700 58.94816 0.8603616 49.93537
33.24700 58.85440 0.8919480 50.07038
33.29700 58.75910 0.9218634 49.89884
33.34700 58.66250 0.9461306 50.07963
33.39700 58.56824 0.9660011 50.01204
33.44700 58.47014 0.9804289 49.93560
33.49700 58.37217 0.9940644 50.08160
33.54700 58.27590 1.003551 50.08174
33.59700 58.17597 1.016114 49.87568
33.64700 58.07938 1.026652 49.90774
33.69700 57.98132 1.035510 49.85772
33.74700 57.88094 1.042651 50.03419
33.79700 57.78252 1.050819 50.05162
33.84700 57.68566 1.058398 49.95139
33.89700 57.58722 1.065255 49.87798
33.94700 57.48514 1.071614 49.93217
33.99700 57.38660 1.077379 50.07348
34.04700 57.28878 1.082831 49.92533
34.09700 57.18924 1.088318 50.08550
34.14700 57.09162 1.093170 49.95528
34.19700 56.98996 1.097772 50.00076
34.24700 56.89026 1.102270 49.99756
34.29700 56.79180 1.106708 49.94280
34.34700 56.69380 1.111142 49.14016
34.39700 56.59152 1.115141 50.00176
34.44700 56.49239 1.118906 50.57740
34.49700 56.39432 1.122539 49.92578
34.54700 56.29359 1.125868 50.07488
34.59700 56.19538 1.129201 49.87670
34.64700 56.09450 1.132177 49.81243
34.69700 55.99536 1.134860 49.93650
34.74700 55.89675 1.137496 50.10414
34.79700 55.79650 1.139936 49.88960
34.84700 55.69706 1.141997 49.89158
34.89700 55.59716 1.144107 49.94108
34.94700 55.50037 1.146290 50.05011
34.99700 55.39826 1.148281 49.98604
35.04700 55.29949 1.150577 49.95026
35.09700 55.19851 1.152704 50.08344
35.14700 55.10041 1.154777 50.00949
35.19700 55.00090 1.156498 49.89130
35.24700 54.90050 1.158542 50.07957
35.29700 54.80022 1.160457 49.93178
35.34700 54.70045 1.162184 50.01762
35.39700 54.60216 1.164529 49.85515
35.44700 54.49995 1.166446 50.05840
35.49700 54.40056 1.168625 49.68969
35.54700 54.29945 1.170657 50.21594
35.59700 54.20321 1.172830 49.91134
35.64700 54.10359 1.174490 49.96431
35.69700 54.00287 1.176176 50.05153
35.74700 53.90105 1.177637 49.98046
35.79700 53.80420 1.179146 49.96131
35.84700 53.70340 1.180339 49.94362
35.89700 53.60394 1.181503 50.10944
35.94700 53.50649 1.182692 50.04420
35.99700 53.40593 1.184311 50.14291
36.04700 53.30523 1.185547 50.12152
36.09700 53.20592 1.186710 49.98626
36.14700 53.10532 1.188196 50.15876
36.19700 53.00489 1.189348 49.97244
36.24700 52.90674 1.190960 49.95810
36.29700 52.80660 1.191998 49.98802
36.34700 52.70664 1.193316 49.98558
36.39700 52.60713 1.195058 49.93770
36.44700 52.50782 1.196295 50.10082
36.49700 52.40619 1.197766 50.09430
36.54700 52.30883 1.199366 50.01953
36.59700 52.20798 1.200869 49.96754
36.64700 52.10694 1.202469 50.12306
36.69700 52.00632 1.203928 50.16228
36.74700 51.90720 1.205458 49.81280
36.79700 51.80722 1.206615 49.94384
36.84700 51.70859 1.208318 49.91904
36.89700 51.60894 1.209400 50.06707
36.94700 51.50796 1.210630 49.90684
36.99700 51.40981 1.211937 50.61014
37.04700 51.31088 1.213138 50.07117
37.09700 51.20796 1.214318 50.08764
37.14700 51.10904 1.215580 49.93516
37.19700 51.01127 1.216795 50.01498
37.24700 50.91104 1.218083 50.03634
37.29700 50.81059 1.219219 49.94580
37.34700 50.70990 1.220110 49.98522
37.39700 50.61168 1.221504 49.93811
37.44700 50.51300 1.222618 49.90958
37.49700 50.41202 1.223816 50.01142
37.54700 50.31178 1.224748 50.02634
37.59700 50.21171 1.226045 49.80760
37.64700 50.11084 1.227084 49.89054
37.69700 50.01200 1.228206 50.09675
37.74700 49.91212 1.229154 50.04854
37.79700 49.81172 1.230140 50.06711
37.84700 49.71104 1.231246 49.89310
37.89700 49.61190 1.232546 49.66900
37.94700 49.51328 1.233628 50.04340
37.99700 49.41236 1.234909 50.01122
38.04700 49.31260 1.236415 49.91083
38.09700 49.21278 1.237624 50.00966
38.14700 49.11216 1.238998 49.46294
38.19700 49.01190 1.240242 49.98930
38.24700 48.91264 1.241600 50.02576
38.29700 48.81392 1.243010 50.07219
38.34700 48.71342 1.244186 49.91688
38.39700 48.61386 1.245112 50.08940
38.44700 48.51268 1.246023 50.07000
38.49700 48.41479 1.247083 49.81280
38.54700 48.31313 1.247886 50.05820
38.59700 48.21452 1.248636 49.96234
38.64700 48.11374 1.249363 49.86570
38.69700 48.01474 1.249946 50.10590
38.74700 47.91450 1.250814 50.06304
38.79700 47.81395 1.251642 49.87472
38.84700 47.71411 1.252518 49.82859
38.89700 47.61486 1.253357 50.08769
38.94700 47.51620 1.254277 50.17820
38.99700 47.41518 1.255392 49.82290
39.04700 47.31718 1.256252 49.96002
39.09700 47.21626 1.257263 50.05026
39.14700 47.11604 1.258163 50.02478
39.19700 47.01641 1.259192 50.08889
39.24700 46.91688 1.260255 49.93944
39.29700 46.81809 1.261206 49.99742
39.34700 46.71634 1.262021 49.86810
39.39700 46.61887 1.263224 50.13101
39.44700 46.51868 1.264284 50.03042
39.49700 46.41663 1.264923 49.95258
39.54700 46.31910 1.266196 50.03272
39.59700 46.21694 1.266958 50.11234
39.64700 46.11750 1.268173 50.15594
39.69700 46.01832 1.269149 50.05078
39.74700 45.91791 1.269900 49.84021
39.79700 45.81836 1.270838 49.92820
39.84700 45.71743 1.271812 50.12338
39.89700 45.61963 1.272694 49.85660
39.94700 45.52041 1.273469 50.00864
39.99700 45.42126 1.274319 49.95011
40.04700 45.31846 1.274840 50.04932
40.09700 45.21866 1.275680 50.02729
40.14700 45.11852 1.276843 49.95618
40.19700 45.01773 1.277732 50.14184
40.24700 44.91868 1.278905 49.96736
40.29700 44.82010 1.280009 50.05767
40.34700 44.71824 1.280726 49.87009
40.39700 44.62109 1.281555 50.02731
40.44700 44.52050 1.282142 50.05381
40.49700 44.41968 1.282809 50.11921
40.54700 44.31961 1.283652 49.99134
40.59700 44.22014 1.284386 49.93361
40.64700 44.12146 1.284929 49.88411
40.69700 44.02028 1.286031 49.86554
40.74700 43.92091 1.286699 50.03606
40.79700 43.82437 1.287444 50.00224
40.84700 43.72182 1.288368 49.97544
40.89700 43.62078 1.289182 50.02622
40.94700 43.52194 1.290090 49.96017
40.99700 43.42144 1.291110 50.07288
41.04700 43.32331 1.291726 49.95444
41.09700 43.22254 1.292488 50.01616
41.14700 43.12114 1.293080 50.06682
41.19700 43.02257 1.293939 49.51406
41.24700 42.92198 1.294678 50.10412
41.29700 42.82200 1.295262 50.04660
41.34700 42.72252 1.296294 49.82088
41.39700 42.62160 1.296998 50.03078
41.44700 42.52441 1.297989 50.06231
41.49700 42.42100 1.298590 49.92974
41.54700 42.32324 1.299343 50.06866
41.59700 42.22390 1.300066 50.57666
41.64700 42.12289 1.300576 50.12794
41.69700 42.02244 1.301125 50.12739
41.74700 41.92384 1.301902 49.98509
41.79700 41.82516 1.302747 50.02908
41.84700 41.72418 1.303156 49.88359
41.89700 41.62297 1.303743 49.90302
41.94700 41.52428 1.304009 49.97574
41.99700 41.42580 1.304670 49.93633
42.04700 41.32568 1.305473 49.97094
42.09700 41.22428 1.305898 50.04493
42.14700 41.12540 1.306454 49.92154
42.19700 41.02616 1.307268 50.11877
42.24700 40.92610 1.307922 49.90127
42.29700 40.82545 1.308688 49.80275
42.34700 40.72525 1.309142 49.80166
42.39700 40.62530 1.309888 49.82748
42.44700 40.52814 1.310959 50.02372
42.49700 40.42483 1.311480 49.92847
42.54700 40.32630 1.312298 49.92004
42.59700 40.22600 1.313135 50.05350
42.64700 40.12486 1.313694 49.99624
42.69700 40.02636 1.314654 49.84351
42.74700 39.92707 1.315096 50.20264
42.79700 39.82546 1.315782 49.95464
42.84700 39.72563 1.316111 50.11254
42.89700 39.62718 1.316725 49.83282
42.94700 39.52582 1.316896 49.89350
42.99700 39.42670 1.317525 49.97120
43.04700 39.32722 1.317882 49.90492
43.09700 39.22716 1.318557 49.98474
43.14700 39.12800 1.319090 50.01627
43.19700 39.02864 1.319994 49.96916
43.24700 38.92785 1.320577 50.01112
43.29700 38.82693 1.321510 50.24908
43.34700 38.72633 1.322226 50.07411
43.39700 38.62710 1.322838 50.07273
43.44700 38.52825 1.323387 50.07739
43.49700 38.42681 1.323904 49.78054
43.54700 38.32717 1.324394 49.85244
43.59700 38.22728 1.325097 49.95691
43.64700 38.12744 1.325608 50.06879
43.69700 38.02841 1.325912 49.53648
43.74700 37.92808 1.326237 49.97190
43.79700 37.82866 1.326434 49.83540
43.84700 37.72752 1.326690 49.84261
43.89700 37.62930 1.327054 49.99978
43.94700 37.52914 1.327517 49.80842
43.99700 37.43053 1.328067 50.15310
44.04700 37.32816 1.328133 49.39322
44.09700 37.23093 1.328682 50.01289
44.14700 37.12930 1.328987 50.15504
44.19700 37.03018 1.329603 49.96711
44.24700 36.92952 1.330258 49.87922
44.29700 36.82887 1.330845 50.02034
44.34700 36.72863 1.331258 50.08866
44.39700 36.63166 1.332181 50.10974
44.44700 36.53041 1.332756 49.99683
44.49700 36.43036 1.333494 50.01248
44.54700 36.33100 1.334142 50.02966
44.59700 36.22968 1.334586 50.21378
44.64700 36.12973 1.334976 50.01306
44.69700 36.03010 1.335394 50.04252
44.74700 35.93038 1.335476 50.03421
44.79700 35.83142 1.336006 50.12636
44.84700 35.73175 1.336352 50.08055
44.89700 35.63190 1.336626 49.89340
44.94700 35.53209 1.336934 50.09631
44.99700 35.43130 1.337192 50.23703
45.04700 35.33054 1.337682 49.25908
45.09700 35.23281 1.338111 49.42754
45.14700 35.13229 1.338723 50.01984
45.19700 35.03159 1.339094 49.93500
45.24700 34.93181 1.339874 49.93926
45.29700 34.83316 1.340563 49.92204
45.34700 34.73250 1.341277 50.07110
45.39700 34.63296 1.341944 49.98070
45.44700 34.53287 1.342618 49.97662
45.49700 34.43141 1.343170 49.92062
45.54700 34.33156 1.343939 49.96248
45.59700 34.23338 1.344692 49.92688
45.64700 34.13269 1.345227 49.92160
45.69700 34.03350 1.345756 50.04304
45.74700 33.93288 1.346160 49.90925
45.79700 33.83202 1.346686 50.07696
45.84700 33.73175 1.346781 49.94888
45.89700 33.63272 1.347160 50.04684
45.94700 33.53332 1.347473 49.81230
45.99700 33.43292 1.347533 50.00752
46.04700 33.33300 1.348010 50.07078
46.09700 33.23219 1.348416 50.20084
46.14700 33.13381 1.348861 49.79676
46.19700 33.03412 1.349056 49.90761
46.24700 32.93453 1.349408 50.05572
46.29700 32.83306 1.349461 49.88403
46.34700 32.73331 1.349885 50.10110
46.39700 32.63500 1.350072 49.86248
46.44700 32.53350 1.350224 50.11858
46.49700 32.43285 1.350534 49.95855
46.54700 32.33406 1.350864 49.88004
46.59700 32.23485 1.351330 50.03944
46.64700 32.13418 1.351658 50.06448
46.69700 32.03494 1.351953 49.94496
46.74700 31.93514 1.352426 50.01993
46.79700 31.83479 1.352614 49.96862
46.84700 31.73607 1.353372 49.91020
46.89700 31.63560 1.353683 50.06108
46.94700 31.53455 1.354274 49.96381
46.99700 31.43612 1.354910 49.82632
47.04700 31.33427 1.355076 49.99470
47.09700 31.23462 1.355413 49.96550
47.14700 31.13525 1.355775 50.04550
47.19700 31.03419 1.356100 49.98780
47.24700 30.93475 1.356474 49.95426
47.29700 30.83375 1.356566 49.92300
47.34700 30.73485 1.356707 49.94000
47.39700 30.63453 1.356928 50.01392
47.44700 30.53580 1.357250 50.02498
47.49700 30.43607 1.357673 50.01773
47.54700 30.33487 1.357893 49.92304
47.59700 30.23578 1.358420 50.07382
47.64700 30.13644 1.358739 49.89318
47.69700 30.03485 1.359180 50.01865
47.74700 29.93606 1.359839 49.87510
47.79700 29.83499 1.360591 49.99023
47.84700 29.73672 1.361503 49.83380
47.89700 29.63531 1.361750 49.93399
47.94700 29.53362 1.362292 50.01544
47.99700 29.43558 1.362643 49.90623
48.04700 29.33576 1.362923 50.23004
48.09700 29.23630 1.363046 49.85680
48.14700 29.13742 1.363191 49.88424
48.19700 29.03602 1.363194 50.02617
48.24700 28.93604 1.362869 49.95125
48.29700 28.83708 1.363308 49.91169
48.34700 28.73728 1.363233 50.13466
48.39700 28.63684 1.363549 50.13525
48.44700 28.53875 1.363469 50.13282
48.49700 28.43682 1.363592 49.90796
48.54700 28.33645 1.363739 50.01946
48.59700 28.23727 1.363957 50.06988
48.64700 28.13784 1.364285 50.07516
48.69700 28.03806 1.364318 49.85426
48.74700 27.93791 1.364466 50.19476
48.79700 27.83899 1.364918 50.05582
48.84700 27.73768 1.365090 50.07752
48.89700 27.63838 1.365281 50.03633
48.94700 27.53899 1.365690 49.94252
48.99700 27.43799 1.366049 50.04283
49.04700 27.33842 1.366544 49.80989
49.09700 27.23865 1.366947 50.07724
49.14700 27.13964 1.367333 49.93216
49.19700 27.03789 1.368357 50.01215
49.24700 26.93904 1.369081 49.96972
49.29700 26.83788 1.369591 50.10163
49.34700 26.73856 1.370014 49.89292
49.39700 26.63830 1.370589 50.11172
49.44700 26.53836 1.370886 50.02313
49.49700 26.43783 1.371020 49.79828
49.54700 26.33842 1.371097 50.05337
49.59700 26.23836 1.371122 49.77876
49.64700 26.13867 1.370877 50.00883
49.69700 26.04076 1.370646 50.12481
49.74700 25.93924 1.370514 50.09144
49.79700 25.83884 1.370571 50.05420
49.84700 25.74080 1.370856 49.85071
49.89700 25.64074 1.371002 49.81075
49.94700 25.54054 1.371255 50.06904
49.99700 25.43953 1.371314 49.80981
50.04700 25.34085 1.371424 49.89617
50.09700 25.24046 1.371722 49.97266
50.14700 25.14074 1.372012 49.99000
50.19700 25.04183 1.372011 50.05250
50.24700 24.94138 1.372437 50.12284
50.29700 24.84187 1.372302 49.99111
50.34700 24.74001 1.372820 49.88198
50.39700 24.64048 1.373040 49.98390
50.44700 24.54132 1.373507 49.95714
50.49700 24.44211 1.373805 50.05141
50.54700 24.34134 1.374279 50.03706
50.59700 24.24093 1.374911 50.15602
50.64700 24.14172 1.375482 49.96809
50.69700 24.04153 1.376053 49.88794
50.74700 23.94149 1.376799 50.06761
50.79700 23.84122 1.377501 49.87026
50.84700 23.74057 1.378032 49.97418
50.89700 23.64182 1.378591 49.94229
50.94700 23.54051 1.378746 49.93309
50.99700 23.44028 1.379034 49.84728
51.04700 23.34201 1.379316 50.08679
51.09700 23.24150 1.379501 49.93575
51.14700 23.14115 1.379392 50.12098
51.19700 23.04127 1.379395 50.01582
51.24700 22.94088 1.379398 49.96768
51.29700 22.84207 1.379468 49.97773
51.34700 22.74126 1.379435 50.04135
51.39700 22.64368 1.379664 49.20726
51.44700 22.54098 1.379659 50.04134
51.49700 22.44300 1.380049 49.86892
51.54700 22.34350 1.379861 50.05134
51.59700 22.24234 1.379932 50.23350
51.64700 22.14367 1.380114 49.92808
51.69700 22.04430 1.379919 49.95294
51.74700 21.94248 1.379896 49.98672
51.79700 21.84262 1.380082 49.98994
51.84700 21.74350 1.380139 49.99502
51.89700 21.64356 1.380469 50.18860
51.94700 21.54262 1.380806 50.04650
51.99700 21.44277 1.381325 49.97426
52.04700 21.34186 1.381980 50.00273
52.09700 21.24192 1.382343 49.87258
52.14700 21.14238 1.382661 49.95978
52.19700 21.04197 1.383029 49.99659
52.24700 20.94341 1.383296 49.89582
52.29700 20.84281 1.383524 49.92086
52.34700 20.74178 1.383664 49.39346
52.39700 20.64263 1.383694 50.02481
52.44700 20.54371 1.383856 50.03847
52.49700 20.44307 1.383906 49.97660
52.54700 20.34372 1.383908 50.02880
52.59700 20.24276 1.384054 50.02420
52.64700 20.14470 1.383892 49.98187
52.69700 20.04309 1.384073 49.72003
52.74700 19.94380 1.384160 50.02613
52.79700 19.84458 1.384060 50.10490
52.84700 19.74348 1.384119 49.98518
52.89700 19.64438 1.384092 49.05380
52.94700 19.54388 1.384389 50.01986
52.99700 19.44425 1.384551 50.04200
53.04700 19.34380 1.384857 50.00007
53.09700 19.24504 1.385120 49.98144
53.14700 19.14497 1.385378 49.93308
53.19700 19.04622 1.385484 50.19848
53.24700 18.94495 1.385559 50.05048
53.29700 18.84512 1.385561 49.89011
53.34700 18.74401 1.385697 50.03668
53.39700 18.64622 1.386157 50.09545
53.44700 18.54403 1.386422 49.99270
53.49700 18.44330 1.386960 49.90895
53.54700 18.34321 1.387500 48.95190
53.59700 18.24435 1.388018 50.02296
53.64700 18.14322 1.388528 50.04748
53.69700 18.04363 1.388740 50.01274
53.74700 17.94424 1.389044 49.94452
53.79700 17.84281 1.389030 49.87480
53.84700 17.74365 1.389028 50.14016
53.89700 17.64413 1.389102 50.15881
53.94700 17.54388 1.388934 50.13834
53.99700 17.44463 1.388953 50.06007
54.04700 17.34494 1.388845 49.92285
54.09700 17.24478 1.388484 49.96752
54.14700 17.14467 1.388447 50.02747
54.19700 17.04553 1.388417 48.99197
54.24700 16.94595 1.388362 50.07836
54.29700 16.84449 1.388102 49.84308
54.34700 16.74539 1.387872 49.95378
54.39700 16.64508 1.387921 49.91188
54.44700 16.54642 1.387944 50.05508
54.49700 16.44636 1.388042 49.90396
54.54700 16.34684 1.388202 50.07709
54.59700 16.24688 1.388360 50.01711
54.64700 16.14751 1.388504 50.01476
54.69700 16.04600 1.388930 49.93559
54.74700 15.94679 1.389121 49.94539
54.79700 15.84881 1.389690 49.84921
54.84700 15.74868 1.390167 49.86873
54.89700 15.64496 1.390366 49.98880
54.94700 15.54548 1.390564 49.97060
54.99700 15.44752 1.390887 49.95046
55.04700 15.34701 1.390941 49.54117
55.09700 15.24676 1.391378 50.25720
55.14700 15.14497 1.391441 50.11454
55.19700 15.04678 1.391682 49.97622
55.24700 14.94556 1.391790 49.98450
55.29700 14.84777 1.391921 49.97434
55.34700 14.74838 1.392099 50.14708
55.39700 14.64734 1.392074 50.16304
55.44700 14.54744 1.392074 48.23922
55.49700 14.44609 1.391820 49.93148
55.54700 14.34775 1.391930 49.99334
55.59700 14.24683 1.391706 50.01724
55.64700 14.14735 1.391731 49.86050
55.69700 14.04785 1.391727 50.14520
55.74700 13.94925 1.391906 50.04138
55.79700 13.84888 1.392195 50.03274
55.84700 13.74770 1.392354 49.94991
55.89700 13.64674 1.392732 50.10300
55.94700 13.54872 1.393146 49.85837
55.99700 13.44729 1.393512 50.01474
56.04700 13.34758 1.393984 50.20189
56.09700 13.24868 1.394146 49.93910
56.14700 13.14685 1.394359 50.11039
56.19700 13.04870 1.394651 49.87183
56.24700 12.94852 1.394677 49.82618
56.29700 12.84881 1.394720 50.17446
56.34700 12.74745 1.394794 49.87454
56.39700 12.64925 1.395400 50.37078
56.44700 12.55109 1.397099 50.15604
56.49700 12.45023 1.401819 50.21924
56.54700 12.35272 1.434799 50.21066
56.59700 12.25577 1.526777 49.89438
56.64700 12.16475 1.658087 49.81511
56.69700 12.07337 1.840800 49.56570
56.74700 11.98868 2.059126 49.97838
56.79700 11.90653 2.320162 49.86718
56.84700 11.82744 2.589530 49.91894
56.89700 11.74904 2.843476 49.90658
56.94700 11.67051 3.091128 49.79567
56.99700 11.59173 3.310324 50.14642
57.04700 11.50932 3.501340 50.02500
57.09700 11.42527 3.650232 50.06176
57.14700 11.33794 3.774611 49.85108
57.19700 11.24727 3.852918 49.94736
57.24700 11.15560 3.902063 50.04145
57.29700 11.05977 3.916922 49.83742
57.34700 10.96166 3.914582 49.96438
57.39700 10.85873 3.877590 50.04628
57.44700 10.75587 3.790054 49.95182
57.49700 10.64799 3.681168 50.05474
57.54700 10.54073 3.563295 49.90515
57.59700 10.43146 3.435107 49.96104
57.64700 10.31937 3.285513 49.98383
57.69700 10.20909 3.138420 49.89920
57.74700 10.09587 2.989156 50.00414
57.79700 9.984391 2.848022 50.15097
57.84700 9.872899 2.710842 50.00340
57.89700 9.761163 2.583974 49.94698
57.94700 9.650561 2.451947 49.89298
57.99700 9.539582 2.346071 49.95236
58.04700 9.430731 2.233913 50.02584
58.09700 9.319950 2.143752 49.82540
58.14700 9.212656 2.065569 50.07754
58.19700 9.105170 1.990533 49.99382
58.24700 8.999058 1.927195 49.98492
58.29700 8.894731 1.873225 49.34100
58.34700 8.790085 1.828112 50.10480
58.39700 8.685205 1.782414 49.85308
58.44700 8.581125 1.747694 50.29373
58.49700 8.479203 1.721102 50.12712
58.54700 8.375239 1.692692 49.69890
58.59700 8.273068 1.671534 50.02096
58.64700 8.171700 1.653104 50.01118
58.69700 8.069768 1.633095 50.14479
58.74700 7.969649 1.620584 49.42704
58.79700 7.866528 1.607560 50.05445
58.84700 7.765852 1.597544 49.75280
58.89700 7.666831 1.589141 50.14695
58.94700 7.564062 1.579598 49.90606
58.99700 7.465778 1.571049 49.27200
59.04700 7.364594 1.562347 49.85309
59.09700 7.263465 1.554761 50.00834
59.14700 7.162525 1.547294 49.90478
59.19700 7.062304 1.540812 50.14759
59.24700 6.961846 1.533775 50.01778
59.29700 6.859893 1.527914 49.91520
59.34700 6.759457 1.522375 50.01786
59.39700 6.660076 1.517289 49.97380
59.44700 6.558991 1.512454 50.02048
59.49700 6.461448 1.508229 50.12300
59.54700 6.358222 1.504049 50.27333
59.59700 6.259270 1.500454 49.94244
59.64700 6.159109 1.497105 50.08138
59.69700 6.059002 1.493747 50.12574
59.74700 5.958613 1.490704 50.15148
59.79700 5.858632 1.487878 50.13460
59.84700 5.757626 1.485184 49.96460
59.89700 5.657773 1.482789 50.25226
59.94700 5.558271 1.480441 50.09735
59.99700 5.458400 1.478479 50.02580
60.04700 5.358186 1.476383 50.17398
60.09700 5.259096 1.474674 49.94631
60.14700 5.157266 1.472672 50.00566
60.19700 5.059046 1.471004 49.89440
60.24700 4.959254 1.469499 49.73903
60.29700 4.858262 1.467969 49.88940
60.34700 4.757560 1.466894 49.94621
60.39700 4.658486 1.466014 49.95082
60.44700 4.558709 1.464960 49.92978
60.49700 4.459672 1.464185 49.91584
60.54700 4.360272 1.463521 50.06421
60.59700 4.257602 1.462644 49.89490
60.64700 4.158542 1.462382 49.59630
60.69700 4.058480 1.461968 50.12628
60.74700 3.958634 1.461586 50.00632
60.79700 3.857200 1.461312 50.01278
60.84700 3.757236 1.461128 49.86190
60.89700 3.657887 1.460706 50.05157
60.94700 3.559013 1.460330 49.95410
60.99700 3.457970 1.459887 48.51165
61.04700 3.357864 1.459888 49.54698
61.09700 3.257349 1.459680 50.06695
61.14700 3.159030 1.459474 49.84774
61.19700 3.059755 1.459176 49.89654
61.24700 2.958187 1.458587 50.13268
61.29700 2.858900 1.458492 50.00086
61.34700 2.759373 1.458074 50.13299
61.39700 2.656933 1.457559 50.11110
61.44700 2.557539 1.457147 49.89752
61.49700 2.458641 1.456808 49.95106
61.54700 2.357046 1.456428 49.99550
61.59700 2.257908 1.456281 49.95243
61.64700 2.158062 1.455867 50.05116
61.69700 2.057639 1.455606 50.05977
61.74700 1.958614 1.455304 49.95980
61.79700 1.858183 1.454949 49.99717
61.84700 1.759862 1.454745 49.80883
61.89700 1.659877 1.454646 49.80172
61.94700 1.558906 1.454335 50.05836
61.99700 1.458804 1.453934 49.82736
62.04700 1.363017 1.454266 50.11382
62.09700 1.288834 1.429973 50.00142
62.14700 1.239753 1.318828 50.06406
62.19700 1.202517 1.209638 50.00207
62.24700 1.170597 1.094246 49.78317
62.29700 1.147158 0.9838650 50.15786
62.34700 1.124971 0.8802612 50.01904
62.39700 1.106884 0.7850532 49.91494
62.44700 1.090988 0.7104478 49.92120
62.49700 1.080426 0.6326812 49.79287
62.54700 1.068153 0.5708334 50.01081
62.59700 1.058357 0.5152012 50.07752
62.64700 1.051254 0.4714612 50.05104
62.69700 1.044194 0.4288814 50.06760
62.74700 1.038473 0.3945672 50.02168
62.79700 1.034131 0.3672110 49.85082
62.84700 1.028662 0.3391232 50.08631
62.89700 1.025340 0.3202216 50.13092
62.94700 1.022733 0.3021760 49.95172
62.99700 1.019900 0.2874034 49.93743
63.04700 1.018663 0.2741690 49.88306
63.09700 1.015280 0.2632950 50.12439
63.14700 1.014130 0.2531367 49.81913
63.19700 1.011119 0.2444230 49.91394
63.24700 1.011035 0.2363157 49.88889
63.29700 1.009475 0.2275522 50.20570
63.34700 1.007217 0.2196782 49.96692
63.39700 1.008328 0.2132344 50.13519
63.44700 1.005647 0.2067896 50.10756
63.49700 1.003544 0.2006491 50.19082
63.54700 1.002862 0.1951146 50.12086
63.59700 1.003387 0.1900011 49.85707
63.64700 1.002126 0.1850606 50.22840
63.69700 1.001127 0.1801138 49.87296
63.74700 1.000710 0.1758750 50.09156
63.79700 0.9992035 0.1718406 50.10738
63.84700 0.9998569 0.1681967 50.08539
63.89700 1.000065 0.1649381 49.92729
63.94700 0.9984348 0.1617421 50.07370
63.99700 0.9979034 0.1589602 49.94224
64.04700 0.9979975 0.1562642 49.93616
64.09700 0.9974624 0.1538577 50.30331
64.14700 0.9972111 0.1517602 50.07307
64.19701 0.9968616 0.1497636 50.11222
64.24700 0.9962335 0.1478388 50.19428
64.29700 0.9964601 0.1463054 49.93606
64.34700 0.9965408 0.1447629 50.18633
64.39700 0.9953672 0.1434691 49.82998
64.44701 0.9968794 0.1423869 50.04430
64.49700 0.9952612 0.1409478 50.02720
64.54700 0.9955262 0.1397634 50.04912
64.59700 0.9937178 0.1386498 49.92859
64.64700 0.9966079 0.1377796 49.98933
64.69701 0.9946571 0.1364898 49.95184
64.74700 0.9945394 0.1356854 49.86768
64.79700 0.9955325 0.1348209 50.03840
-2.000000 2.000000 0.0000000 0.0000000