File: imagens/notebooks/dados experimentais/dsc/Karl_DTAB100 Ur 45%.txt
CLOSED
Version	1.0
Language	English
Run	1
RunSerial	153
Instrument	DSC Q100 V9.9 Build 303
Module	DSC Standard Cell FC
Operator	LL
File	\\Niger\ta\Data\DSC\2018\Geral\Karl_DTAB100 Ur 45%.001
ProcName	Karl
InstSerial	0100-1211
Sample	DTAB100 Ur 45%
Size	12.4700	mg
Method	Karl
Comment
Xcomment	Pan: Aluminum Hermetic
Xcomment	Gas1: Nitrogen 50.0 ml/min
Xcomment	Gas2: Nitrogen 0.0 ml/min
Text
Exotherm	UP
Kcell	1.09030
Calib	-11.7822
TempCal	1	pts	158.71	156.60
TzeroDt	-90.0515 -0.0093 2.2263
TzeroDtz	-90.0515 0.0466 2.4421
InstCalFile	Tzero: \\Niger\ta\Data\DSC\CALIBRATION\20122016\CALIBRATION\0_RCS_12_20_2016 17_23_31.TZR
InstCalFile	Baseline: \\Niger\ta\Data\DSC\CALIBRATION\20122016\L.Base 20122016
InstCalFile	Sapphire: \\Niger\ta\Data\DSC\CALIBRATION\20122016\Safira 20122017.001
InstCalDate	Tzero 2016-12-20 Time 19:23:31
TempRange	-90.04 to 395.23 °C at 19.96 °C/min Heat Only
AutoZero	Delta T Offset 0.000 uV
AutoZero	Delta T0 Offset 0.000 uV
Controls	Gas 1  Event Off  Sampling 0.2
Cell#	FC-02451
CoolingUnit	RCS
SelHeatFlow	Heat Flow T4 (mW)
AutoAnalysis	Off
MacroFile
Nsig	4
Sig1	Time (min)
Sig2	Temperature (°C)
Sig3	Heat Flow (mW)
Sig4	Sample Purge Flow (mL/min)
Date	2018-05-17
Time	11:59:16
OrgMethod	1: Equilibrate at 1.00 °C
OrgMethod	2: Ramp 2.00 °C/min to 60.00 °C
OrgMethod	3: Isothermal for 3.00 min
OrgMethod	4: Mark end of cycle 1
OrgMethod	5: Ramp 2.00 °C/min to 1.00 °C
OrgMethod	6: Isothermal for 3.00 min
OrgMethod	7: Mark end of cycle 2
OrgFile	C:\TA\Data\DSC\2018\Geral\Karl_DTAB100 Ur 45%.001
3.33324E-4 1.181894 1.122552 50.02689
0.05033332 1.166809 0.9972730 49.94952
0.1003333 1.180656 0.8258250 49.90980
0.1503333 1.217925 0.6294070 49.92998
0.2003333 1.267000 0.4268053 49.92679
0.2503333 1.324790 0.2362187 49.95359
0.3003333 1.387933 0.05757321 50.16785
0.3503333 1.456899 -0.1033162 50.12684
0.4003334 1.529535 -0.2483008 50.03785
0.4503334 1.606668 -0.3746623 49.90783
0.5003334 1.686333 -0.4877068 50.03388
0.5503332 1.768851 -0.5843008 50.00068
0.6003332 1.852997 -0.6716762 49.96379
0.6503332 1.940146 -0.7462989 49.88732
0.7003332 2.028222 -0.8093582 50.01728
0.7503332 2.118196 -0.8647551 50.02884
0.8003332 2.207984 -0.9140176 50.08420
0.8503332 2.300440 -0.9573663 49.93213
0.9003332 2.392698 -0.9893274 49.95771
0.9503334 2.485670 -1.020731 49.93872
1.000333 2.579842 -1.047757 49.92944
1.050334 2.674803 -1.070580 49.84910
1.100334 2.770048 -1.089454 49.95492
1.150334 2.866712 -1.107825 49.99025
1.200334 2.961462 -1.121053 50.01120
1.250334 3.058421 -1.133512 50.11418
1.300334 3.155302 -1.143992 50.07568
1.350333 3.251958 -1.154885 50.07594
1.400333 3.348318 -1.163618 50.14646
1.450334 3.446025 -1.173378 49.95344
1.500333 3.543605 -1.181877 50.11918
1.550334 3.641705 -1.190437 49.97122
1.600334 3.739214 -1.198764 49.98714
1.650333 3.837493 -1.206852 50.08670
1.700334 3.935007 -1.214548 50.05796
1.750334 4.033752 -1.222084 49.89622
1.800334 4.131708 -1.229194 49.94101
1.850334 4.230512 -1.235720 50.08102
1.900334 4.328261 -1.242018 49.88502
1.950334 4.427193 -1.247853 50.01716
2.000334 4.526373 -1.253302 50.10490
2.050333 4.624690 -1.258566 49.92119
2.100334 4.723500 -1.263303 50.06957
2.150334 4.822232 -1.267820 50.20467
2.200334 4.921094 -1.272245 49.92363
2.250334 5.020603 -1.276183 49.86708
2.300333 5.119376 -1.279962 49.96085
2.350334 5.218643 -1.283452 49.97467
2.400334 5.317579 -1.286782 50.14809
2.450334 5.416800 -1.290060 49.86722
2.500334 5.516018 -1.293139 49.86676
2.550333 5.615555 -1.296170 49.90922
2.600333 5.714600 -1.299029 49.84888
2.650333 5.814495 -1.301949 49.97722
2.700333 5.913150 -1.304717 49.90411
2.750333 6.012104 -1.307045 49.84970
2.800333 6.113229 -1.309430 50.12207
2.850333 6.211499 -1.311776 49.92832
2.900333 6.311314 -1.313900 49.86618
2.950333 6.410722 -1.316136 50.12418
3.000333 6.509498 -1.318358 49.99202
3.050333 6.609860 -1.320350 50.10494
3.100333 6.709568 -1.322304 49.93075
3.150333 6.809288 -1.324237 50.16066
3.200333 6.908544 -1.326058 50.00466
3.250333 7.008656 -1.327794 50.14450
3.300333 7.108000 -1.329570 50.01672
3.350333 7.207378 -1.331216 50.03806
3.400333 7.307408 -1.332866 50.01410
3.450333 7.406921 -1.334364 50.05030
3.500333 7.506416 -1.335946 49.97102
3.550333 7.606376 -1.337296 50.00919
3.600333 7.705718 -1.338671 49.92874
3.650333 7.805076 -1.339924 50.08908
3.700333 7.905488 -1.341035 50.11794
3.750333 8.003630 -1.342292 49.75808
3.800333 8.104406 -1.343276 50.09969
3.850333 8.204571 -1.344340 50.00592
3.900333 8.303466 -1.345136 49.84462
3.950333 8.402884 -1.346076 50.11557
4.000333 8.503116 -1.346973 50.03118
4.050333 8.602164 -1.348029 50.22528
4.100333 8.701913 -1.349141 50.19224
4.150333 8.801245 -1.350190 50.03970
4.200333 8.901576 -1.351236 49.98909
4.250333 9.001366 -1.352269 49.96977
4.300333 9.101074 -1.353329 50.21456
4.350333 9.200047 -1.354652 49.98084
4.400333 9.300403 -1.355733 50.16844
4.450333 9.400368 -1.356906 50.00444
4.500333 9.500718 -1.358134 50.03660
4.550333 9.599181 -1.359136 50.03870
4.600333 9.699051 -1.360174 49.85776
4.650333 9.798756 -1.361313 49.98780
4.700333 9.897501 -1.362299 50.15110
4.750333 9.998234 -1.363278 50.12814
4.800333 10.09831 -1.364455 49.98382
4.850333 10.19849 -1.365249 50.00351
4.900333 10.29766 -1.366362 50.10719
4.950333 10.39809 -1.367281 50.04519
5.000333 10.49760 -1.368329 49.96541
5.050333 10.59792 -1.369345 50.00921
5.100333 10.69737 -1.370349 49.92252
5.150333 10.79749 -1.371348 49.91382
5.200333 10.89788 -1.372518 49.81304
5.250332 10.99634 -1.373502 50.01223
5.300332 11.09766 -1.374552 49.95550
5.350332 11.19731 -1.375611 49.99340
5.400332 11.29647 -1.376873 49.96488
5.450332 11.39613 -1.378003 49.96862
5.500332 11.49604 -1.379277 49.97294
5.550332 11.59579 -1.380425 49.86470
5.600332 11.69614 -1.381530 49.84998
5.650332 11.79574 -1.382554 50.05759
5.700332 11.89639 -1.383651 49.92079
5.750332 11.99597 -1.384589 50.06292
5.800332 12.09614 -1.385479 50.03476
5.850332 12.19568 -1.386432 49.81960
5.900332 12.29508 -1.387184 50.15912
5.950332 12.39536 -1.388112 49.84781
6.000332 12.49462 -1.388876 50.12804
6.050332 12.59594 -1.389823 50.04234
6.100332 12.69400 -1.390807 50.06048
6.150332 12.79479 -1.391368 50.03717
6.200332 12.89392 -1.392359 49.92992
6.250332 12.99425 -1.393245 49.97420
6.300332 13.09430 -1.394113 50.04704
6.350332 13.19406 -1.394942 49.93880
6.400332 13.29324 -1.395831 49.91661
6.450332 13.39412 -1.396772 50.08440
6.500332 13.49391 -1.397937 49.98978
6.550332 13.59312 -1.398827 49.92676
6.600332 13.69420 -1.399686 50.10288
6.650332 13.79277 -1.400684 49.82384
6.700332 13.89224 -1.401678 49.95320
6.750332 13.99287 -1.402800 49.96370
6.800332 14.09253 -1.403865 49.81835
6.850332 14.19303 -1.405010 49.88950
6.900332 14.29344 -1.405824 50.14298
6.950332 14.39177 -1.406775 50.16898
7.000332 14.49291 -1.407926 49.95990
7.050332 14.59189 -1.408915 50.06260
7.100332 14.69256 -1.409954 50.23684
7.150332 14.79206 -1.410816 50.09929
7.200332 14.89143 -1.411874 50.08950
7.250332 14.99104 -1.412769 50.00761
7.300332 15.09049 -1.413784 50.03656
7.350332 15.18986 -1.414812 50.06106
7.400332 15.29011 -1.415980 49.96740
7.450332 15.38977 -1.417152 50.09094
7.500332 15.49064 -1.418311 50.04062
7.550332 15.58997 -1.419656 50.13848
7.600332 15.68999 -1.420864 49.97876
7.650332 15.78963 -1.422111 50.07360
7.700332 15.88948 -1.423228 49.91976
7.750332 15.98967 -1.424408 50.08917
7.800332 16.08946 -1.425582 50.06596
7.850332 16.18934 -1.426714 50.10492
7.900332 16.28898 -1.427898 49.87133
7.950332 16.38880 -1.429238 50.08994
8.000334 16.48838 -1.430449 49.86552
8.050332 16.58866 -1.431714 50.02361
8.100332 16.68961 -1.432928 49.85034
8.150332 16.78892 -1.434216 50.07948
8.200332 16.88852 -1.435418 49.77967
8.250334 16.98901 -1.436630 49.86424
8.300332 17.08888 -1.438032 50.10309
8.350332 17.18848 -1.439165 50.00261
8.400332 17.28855 -1.440720 50.09834
8.450332 17.38888 -1.442058 50.02806
8.500334 17.48828 -1.443530 50.11886
8.550332 17.58811 -1.444967 50.14889
8.600332 17.68909 -1.446264 49.92215
8.650332 17.78868 -1.447654 50.07418
8.700332 17.88803 -1.449084 50.20030
8.750334 17.98915 -1.450366 49.95054
8.800332 18.08807 -1.451654 50.12518
8.850332 18.18801 -1.452910 50.10024
8.900332 18.28727 -1.454062 49.97879
8.950332 18.38790 -1.455101 50.08936
9.000334 18.48752 -1.456204 50.10200
9.050332 18.58713 -1.457276 49.99915
9.100332 18.68630 -1.458362 49.85540
9.150332 18.78636 -1.459542 49.88390
9.200332 18.88594 -1.460813 50.12182
9.250334 18.98541 -1.462197 49.91670
9.300332 19.08572 -1.463695 50.17266
9.350332 19.18497 -1.465126 49.87029
9.400332 19.28498 -1.466575 50.06422
9.450332 19.38564 -1.468031 49.98032
9.500334 19.48369 -1.469694 49.95336
9.550332 19.58453 -1.471269 50.02260
9.600332 19.68466 -1.472828 49.99117
9.650332 19.78402 -1.474580 50.11318
9.700332 19.88396 -1.476300 50.18741
9.750334 19.98365 -1.478056 50.09835
9.800332 20.08395 -1.479896 50.01318
9.850332 20.18304 -1.481617 50.07126
9.900332 20.28306 -1.483296 49.93720
9.950332 20.38249 -1.484825 50.14004
10.00033 20.48296 -1.486541 49.89046
10.05033 20.58283 -1.488170 49.91617
10.10033 20.68237 -1.489875 49.99706
10.15033 20.78119 -1.491538 50.02033
10.20033 20.88206 -1.493372 49.95613
10.25033 20.98156 -1.495034 50.04034
10.30033 21.08115 -1.496982 50.01648
10.35033 21.18180 -1.498905 50.00797
10.40033 21.28177 -1.500704 49.98712
10.45033 21.38165 -1.502447 50.05768
10.50034 21.48090 -1.504361 49.90303
10.55033 21.58024 -1.505992 49.93086
10.60033 21.68084 -1.507830 50.03035
10.65033 21.78045 -1.509562 50.07816
10.70033 21.88022 -1.511315 50.01217
10.75034 21.97962 -1.513091 49.89424
10.80033 22.07910 -1.515028 49.91684
10.85033 22.17924 -1.517034 49.93042
10.90033 22.27944 -1.519152 49.90394
10.95033 22.37933 -1.521271 49.99610
11.00034 22.47839 -1.523260 49.95400
11.05033 22.57868 -1.525442 50.13664
11.10033 22.67928 -1.527582 49.94503
11.15033 22.77872 -1.529960 49.89183
11.20033 22.87783 -1.532039 50.06960
11.25034 22.97820 -1.534189 49.87794
11.30033 23.07828 -1.536419 49.99774
11.35033 23.17852 -1.538271 49.84130
11.40033 23.27686 -1.540338 49.99543
11.45033 23.37755 -1.542212 50.19662
11.50034 23.47763 -1.544052 49.98578
11.55033 23.57712 -1.545934 50.01550
11.60033 23.67687 -1.547746 49.99572
11.65033 23.77640 -1.549646 49.94146
11.70033 23.87573 -1.551550 50.04016
11.75034 23.97618 -1.553520 49.89640
11.80033 24.07568 -1.555592 50.09916
11.85033 24.17502 -1.557444 49.98184
11.90033 24.27554 -1.559524 50.04800
11.95033 24.37514 -1.561450 49.91802
12.00034 24.47490 -1.563360 50.07820
12.05033 24.57442 -1.565312 49.93352
12.10033 24.67485 -1.567279 49.95384
12.15033 24.77435 -1.569394 50.06190
12.20033 24.87426 -1.571596 50.07171
12.25034 24.97354 -1.573628 49.93372
12.30033 25.07352 -1.575980 49.98400
12.35033 25.17367 -1.578077 49.92972
12.40033 25.27320 -1.580426 49.89768
12.45033 25.37290 -1.583033 49.92602
12.50034 25.47388 -1.585397 50.05527
12.55033 25.57352 -1.587936 50.14258
12.60033 25.67266 -1.590488 49.93948
12.65033 25.77206 -1.593204 50.16602
12.70033 25.87229 -1.596048 50.10874
12.75034 25.97211 -1.598770 49.91804
12.80033 26.07144 -1.601819 49.96167
12.85033 26.17156 -1.605007 50.13831
12.90033 26.27124 -1.608322 49.95524
12.95034 26.37039 -1.611528 49.86533
13.00034 26.46992 -1.614994 50.06950
13.05033 26.56956 -1.618500 50.14414
13.10033 26.66912 -1.622271 49.96380
13.15033 26.76862 -1.626129 49.81444
13.20034 26.86837 -1.629932 49.97568
13.25034 26.96780 -1.634131 49.84187
13.30033 27.06690 -1.638291 49.97136
13.35033 27.16816 -1.642468 49.87944
13.40033 27.26664 -1.646716 50.14204
13.45034 27.36667 -1.651168 50.01124
13.50034 27.46655 -1.655584 50.05438
13.55033 27.56543 -1.660204 49.94201
13.60033 27.66556 -1.664749 50.02812
13.65033 27.76486 -1.669317 49.93531
13.70034 27.86565 -1.674044 49.93914
13.75034 27.96442 -1.678704 49.97283
13.80033 28.06382 -1.683310 50.00088
13.85033 28.16487 -1.687829 49.98461
13.90033 28.26440 -1.692204 50.00704
13.95034 28.36362 -1.696644 50.04598
14.00034 28.46276 -1.701141 50.10780
14.05033 28.56308 -1.705574 49.91697
14.10033 28.66176 -1.710006 50.02564
14.15033 28.76158 -1.714505 50.00972
14.20034 28.86126 -1.718894 49.91664
14.25034 28.95971 -1.723593 50.01179
14.30033 29.06001 -1.728326 50.08116
14.35033 29.15914 -1.733002 49.98934
14.40033 29.25890 -1.737899 50.03597
14.45034 29.35828 -1.742883 50.06206
14.50034 29.45864 -1.747988 49.88816
14.55033 29.55718 -1.753366 49.92933
14.60033 29.65618 -1.758932 49.97180
14.65033 29.75575 -1.765254 50.15108
14.70034 29.85463 -1.772096 49.81611
14.75034 29.95419 -1.779997 49.98407
14.80033 30.05288 -1.789680 50.12484
14.85033 30.15220 -1.805044 50.11353
14.90033 30.25034 -1.824145 49.84782
14.95034 30.34931 -1.856942 50.07908
15.00034 30.44715 -1.892422 49.94578
15.05033 30.54407 -1.936924 50.09584
15.10033 30.64074 -1.985167 49.90770
15.15033 30.73739 -2.034218 50.00891
15.20034 30.83390 -2.088874 50.11422
15.25034 30.93027 -2.145004 49.97967
15.30033 31.02486 -2.199630 50.05756
15.35033 31.12154 -2.256992 49.98360
15.40033 31.21592 -2.311194 49.99680
15.45034 31.31168 -2.366886 49.85554
15.50034 31.40770 -2.418362 50.04697
15.55033 31.50394 -2.468593 49.85567
15.60033 31.59890 -2.516684 49.92338
15.65033 31.69526 -2.564564 49.94206
15.70034 31.79102 -2.607852 50.23166
15.75034 31.88759 -2.648056 49.99287
15.80033 31.98398 -2.684944 50.14254
15.85033 32.08164 -2.721183 50.10461
15.90033 32.17844 -2.752916 50.00896
15.95034 32.27592 -2.783130 49.88270
16.00033 32.37285 -2.811622 49.99731
16.05033 32.47142 -2.837378 49.97324
16.10033 32.56873 -2.859820 50.00212
16.15033 32.66696 -2.879922 49.91770
16.20033 32.76502 -2.894598 49.98135
16.25033 32.86331 -2.904332 50.13425
16.30033 32.96301 -2.909262 49.95890
16.35033 33.06398 -2.898911 49.88984
16.40033 33.16814 -2.790985 50.10690
16.45033 33.27809 -2.604794 49.97968
16.50033 33.39202 -2.403167 50.00531
16.55033 33.50633 -2.249571 50.05948
16.60033 33.61892 -2.120590 50.01554
16.65033 33.72891 -2.010905 50.10234
16.70033 33.83859 -1.921086 50.06964
16.75033 33.94520 -1.845269 49.93701
16.80033 34.05167 -1.785097 49.92571
16.85033 34.15678 -1.735502 49.94536
16.90033 34.26107 -1.694978 49.99089
16.95033 34.36438 -1.662594 49.86770
17.00033 34.46840 -1.636794 50.00974
17.05033 34.56926 -1.614017 50.05704
17.10033 34.67212 -1.597061 49.80476
17.15033 34.77400 -1.584561 49.98808
17.20033 34.87539 -1.575128 49.97818
17.25033 34.97668 -1.566088 50.11013
17.30033 35.07774 -1.557450 49.85944
17.35033 35.17789 -1.549643 50.08333
17.40033 35.27951 -1.542120 50.17834
17.45033 35.37994 -1.535009 49.87084
17.50033 35.47994 -1.528486 50.12224
17.55033 35.57935 -1.522377 49.91016
17.60033 35.68064 -1.517088 49.87039
17.65033 35.77991 -1.512510 49.98110
17.70033 35.88019 -1.508679 49.95238
17.75033 35.97988 -1.505372 50.05147
17.80033 36.08162 -1.502539 50.06262
17.85033 36.18105 -1.500238 50.01274
17.90033 36.28105 -1.498190 50.04625
17.95033 36.38069 -1.496455 49.99722
18.00033 36.48038 -1.495188 49.87634
18.05033 36.58111 -1.494033 49.94526
18.10033 36.68204 -1.493150 49.83297
18.15033 36.78168 -1.492575 50.08750
18.20033 36.88102 -1.492231 50.13776
18.25033 36.98096 -1.491976 49.89049
18.30033 37.08132 -1.491986 50.02036
18.35033 37.18135 -1.492156 49.88926
18.40033 37.28094 -1.492406 49.89448
18.45033 37.38138 -1.492667 50.11846
18.50033 37.48086 -1.493229 49.85767
18.55033 37.58125 -1.493813 50.21759
18.60033 37.68086 -1.494507 50.01238
18.65033 37.78204 -1.495101 50.04006
18.70033 37.88208 -1.495825 49.94283
18.75033 37.98194 -1.496532 49.96044
18.80033 38.08232 -1.497189 50.05449
18.85033 38.18342 -1.497992 49.88610
18.90033 38.28308 -1.498944 49.94600
18.95033 38.38300 -1.499935 50.00278
19.00033 38.48360 -1.500763 50.11576
19.05033 38.58297 -1.501611 50.14340
19.10033 38.68262 -1.502069 50.13294
19.15033 38.78278 -1.502376 50.07610
19.20033 38.88130 -1.502521 49.96958
19.25033 38.98253 -1.502451 49.81322
19.30033 39.08100 -1.502081 49.93984
19.35033 39.18031 -1.501758 50.02824
19.40033 39.28041 -1.501733 49.90694
19.45033 39.38018 -1.501740 49.99866
19.50033 39.48014 -1.502129 49.98365
19.55033 39.57942 -1.502656 49.95768
19.60033 39.67914 -1.503229 50.00470
19.65033 39.77935 -1.503552 49.99263
19.70033 39.87730 -1.503735 49.99558
19.75033 39.97437 -1.503072 49.87937
19.80033 40.07225 -1.501297 49.83683
19.85033 40.16839 -1.498801 50.04108
19.90033 40.26695 -1.495737 49.94230
19.95033 40.36436 -1.492795 50.08917
20.00033 40.46274 -1.490225 49.88938
20.05033 40.56168 -1.488177 50.04570
20.10033 40.65880 -1.486662 49.94813
20.15033 40.75898 -1.486215 50.07715
20.20033 40.85864 -1.486302 49.89541
20.25033 40.95752 -1.487282 49.86896
20.30033 41.05709 -1.488715 50.02326
20.35033 41.15746 -1.490838 49.93428
20.40033 41.25678 -1.493388 50.00637
20.45033 41.35866 -1.496161 49.97990
20.50033 41.45937 -1.499061 50.03484
20.55033 41.55790 -1.502264 50.03180
20.60033 41.65971 -1.505339 50.16322
20.65033 41.75915 -1.508361 50.09974
20.70033 41.86046 -1.511385 50.01129
20.75033 41.96026 -1.514152 49.99100
20.80033 42.06100 -1.516881 49.87028
20.85033 42.16206 -1.519341 50.02900
20.90033 42.26233 -1.521587 50.01338
20.95033 42.36304 -1.523746 50.08808
21.00033 42.46344 -1.525772 50.18306
21.05033 42.56442 -1.527515 49.76398
21.10033 42.66460 -1.529167 50.06113
21.15033 42.76504 -1.530778 50.16318
21.20033 42.86448 -1.532288 50.13150
21.25033 42.96540 -1.533588 49.92023
21.30033 43.06617 -1.534824 50.18799
21.35033 43.16555 -1.535842 49.99164
21.40033 43.26611 -1.537025 50.18820
21.45033 43.36566 -1.538061 50.03012
21.50033 43.46750 -1.539026 49.89484
21.55033 43.56691 -1.539855 49.86280
21.60033 43.66725 -1.540705 49.86124
21.65033 43.76646 -1.541310 50.04538
21.70033 43.86822 -1.542003 50.01562
21.75033 43.96839 -1.542677 49.96820
21.80033 44.06786 -1.543120 50.05523
21.85033 44.16716 -1.543519 50.05537
21.90033 44.26784 -1.543882 49.97973
21.95033 44.36804 -1.544393 50.09356
22.00033 44.46779 -1.544861 49.88141
22.05033 44.56730 -1.545527 49.93544
22.10033 44.66752 -1.545957 49.98248
22.15033 44.76785 -1.546474 49.87063
22.20033 44.86660 -1.546940 50.01176
22.25033 44.96640 -1.547427 50.00930
22.30033 45.06816 -1.548039 50.08232
22.35033 45.16702 -1.548791 49.92770
22.40033 45.26639 -1.549464 49.92698
22.45033 45.36630 -1.550164 49.99064
22.50033 45.46646 -1.550910 50.16000
22.55033 45.56638 -1.551760 49.78936
22.60033 45.66608 -1.552428 50.02866
22.65033 45.76669 -1.553435 49.92898
22.70033 45.86630 -1.554551 49.96418
22.75033 45.96684 -1.555789 50.03060
22.80033 46.06624 -1.557074 49.91530
22.85033 46.16664 -1.558343 50.03768
22.90033 46.26648 -1.559764 49.98806
22.95033 46.36702 -1.560986 49.94006
23.00033 46.46672 -1.562127 50.07221
23.05033 46.56746 -1.563206 49.90454
23.10033 46.66676 -1.564372 50.04093
23.15033 46.76709 -1.565589 50.06899
23.20033 46.86720 -1.566804 49.92490
23.25033 46.96720 -1.567750 50.02192
23.30033 47.06713 -1.568802 50.10713
23.35033 47.16694 -1.569797 50.02620
23.40033 47.26672 -1.570856 49.96373
23.45033 47.36678 -1.571652 49.91084
23.50033 47.46634 -1.572467 49.95946
23.55033 47.56660 -1.573351 50.07670
23.60033 47.66648 -1.574118 50.05600
23.65033 47.76629 -1.574987 50.02880
23.70033 47.86558 -1.575859 50.01363
23.75033 47.96571 -1.576672 49.85263
23.80033 48.06594 -1.577569 49.94226
23.85033 48.16674 -1.578492 50.08048
23.90033 48.26511 -1.579536 49.96504
23.95033 48.36593 -1.580460 49.86118
24.00033 48.46472 -1.581393 50.15122
24.05033 48.56526 -1.582456 50.18204
24.10033 48.66441 -1.583285 49.97357
24.15033 48.76522 -1.584445 49.95492
24.20033 48.86507 -1.585171 50.03524
24.25033 48.96438 -1.586099 49.93554
24.30033 49.06453 -1.586903 50.09762
24.35033 49.16415 -1.588054 49.92453
24.40033 49.26518 -1.589069 50.11685
24.45033 49.36275 -1.590188 49.93057
24.50033 49.46402 -1.591319 50.00586
24.55033 49.56354 -1.592389 49.86848
24.60033 49.66375 -1.593468 50.02996
24.65033 49.76400 -1.594590 50.10415
24.70033 49.86346 -1.595744 50.17552
24.75033 49.96384 -1.596914 49.87706
24.80033 50.06266 -1.598218 50.21290
24.85033 50.16150 -1.599495 49.81156
24.90033 50.26158 -1.600876 50.05375
24.95033 50.36220 -1.602290 49.99517
25.00033 50.46181 -1.603694 50.08239
25.05033 50.56189 -1.605005 50.01764
25.10033 50.66236 -1.606460 49.95067
25.15033 50.76150 -1.607861 50.00412
25.20033 50.86172 -1.609241 50.06045
25.25033 50.96086 -1.610872 50.15344
25.30033 51.06143 -1.612219 49.85953
25.35033 51.16194 -1.613660 50.09825
25.40033 51.26034 -1.614996 49.93819
25.45033 51.36052 -1.616245 49.96015
25.50033 51.46106 -1.617488 50.01510
25.55033 51.56060 -1.618712 49.93554
25.60033 51.66078 -1.620002 49.95487
25.65033 51.76050 -1.621241 50.03262
25.70033 51.86024 -1.622569 50.04096
25.75033 51.96034 -1.624025 50.00300
25.80033 52.06063 -1.625406 50.06884
25.85033 52.16007 -1.626736 49.94351
25.90033 52.25960 -1.628093 49.89888
25.95033 52.36000 -1.629306 49.95952
26.00033 52.45871 -1.630468 50.15457
26.05033 52.55879 -1.631927 49.92744
26.10033 52.65911 -1.633459 49.93014
26.15033 52.75894 -1.634884 49.84809
26.20033 52.85941 -1.636420 49.98318
26.25033 52.95904 -1.637732 49.91782
26.30033 53.05906 -1.639075 50.20510
26.35033 53.15810 -1.640687 50.01170
26.40033 53.25843 -1.642271 49.93317
26.45033 53.35776 -1.644106 49.96924
26.50033 53.45787 -1.645660 49.91632
26.55033 53.55703 -1.647362 50.05041
26.60033 53.65750 -1.648646 50.00060
26.65033 53.75680 -1.650040 49.94078
26.70033 53.85636 -1.651251 50.12233
26.75033 53.95605 -1.652580 50.04242
26.80033 54.05613 -1.653883 50.05136
26.85033 54.15606 -1.655246 50.04544
26.90033 54.25598 -1.656521 50.02496
26.95033 54.35463 -1.657787 50.17227
27.00033 54.45530 -1.659046 50.11976
27.05033 54.55459 -1.660461 50.03146
27.10033 54.65441 -1.662150 49.99202
27.15033 54.75506 -1.663824 49.91758
27.20033 54.85479 -1.665529 49.97384
27.25033 54.95522 -1.667233 49.96436
27.30033 55.05424 -1.669066 49.93562
27.35033 55.15432 -1.670946 50.10869
27.40033 55.25437 -1.672846 49.96049
27.45033 55.35411 -1.674706 50.01432
27.50033 55.45373 -1.676681 49.91059
27.55033 55.55442 -1.678626 50.02430
27.60033 55.65442 -1.680401 50.02504
27.65033 55.75411 -1.682092 49.96374
27.70033 55.85404 -1.683616 50.07584
27.75033 55.95406 -1.685079 50.06470
27.80033 56.05337 -1.686861 49.96549
27.85033 56.15402 -1.688382 50.02740
27.90033 56.25394 -1.690078 49.97705
27.95033 56.35354 -1.691514 49.99036
28.00033 56.45286 -1.692981 50.06480
28.05033 56.55302 -1.694660 50.11539
28.10033 56.65200 -1.696130 50.08747
28.15033 56.75281 -1.697646 50.02590
28.20033 56.85298 -1.699066 50.08024
28.25033 56.95222 -1.700550 49.95078
28.30033 57.05265 -1.702038 49.96668
28.35033 57.15153 -1.703319 49.95152
28.40033 57.25123 -1.704694 49.99150
28.45033 57.35128 -1.705961 49.90276
28.50033 57.45110 -1.707672 49.96224
28.55033 57.55149 -1.709128 50.03448
28.60033 57.65134 -1.710900 49.89088
28.65033 57.75031 -1.712708 50.05730
28.70033 57.85095 -1.714458 50.03671
28.75033 57.95040 -1.716294 50.10934
28.80033 58.05072 -1.717979 49.91818
28.85033 58.15051 -1.719787 50.01060
28.90033 58.24926 -1.721519 49.90781
28.95033 58.34974 -1.723258 49.94028
29.00033 58.44988 -1.724785 49.83105
29.05033 58.55006 -1.726246 50.05488
29.10033 58.64860 -1.727796 49.99869
29.15033 58.74796 -1.729278 49.97639
29.20033 58.84836 -1.730888 50.00813
29.25033 58.94824 -1.732472 49.93484
29.30033 59.04835 -1.734261 50.15700
29.35033 59.14780 -1.735979 49.86504
29.40033 59.24712 -1.737830 50.01848
29.45033 59.34774 -1.739685 50.03389
29.50033 59.44635 -1.741516 49.96039
29.55033 59.54458 -1.743866 50.02062
29.60033 59.61625 -1.718831 50.05782
29.65033 59.66570 -1.583202 49.89800
29.70033 59.70624 -1.455901 49.98754
29.75033 59.73862 -1.315614 50.01915
29.80033 59.76682 -1.187467 50.15281
29.85033 59.78938 -1.065996 50.04937
29.90033 59.80951 -0.9619736 49.86524
29.95033 59.82537 -0.8628407 50.02621
30.00033 59.84011 -0.7809152 50.01117
30.05033 59.85208 -0.7073905 49.99930
30.10033 59.86206 -0.6450734 49.89765
30.15033 59.87040 -0.5926926 50.02710
30.20033 59.87796 -0.5446074 50.08631
30.25033 59.88489 -0.5081437 50.04600
30.30033 59.89062 -0.4742295 49.97688
30.35033 59.89472 -0.4502766 49.97843
30.40033 59.89875 -0.4263370 49.95828
30.45033 59.90224 -0.4082107 50.11880
30.50033 59.90546 -0.3914120 49.90974
30.55033 59.90780 -0.3802060 50.00869
30.60033 59.91106 -0.3697740 49.89312
30.65033 59.91306 -0.3614574 50.11244
30.70033 59.91470 -0.3520506 49.93168
30.75033 59.91654 -0.3438900 50.06883
30.80033 59.91769 -0.3354812 49.93372
30.85033 59.91926 -0.3274915 50.08566
30.90033 59.91993 -0.3199115 50.05527
30.95033 59.92192 -0.3129985 50.05028
31.00033 59.92250 -0.3064410 49.94508
31.05033 59.92346 -0.3005744 49.98462
31.10033 59.92444 -0.2950044 50.11624
31.15033 59.92512 -0.2900961 49.91447
31.20033 59.92453 -0.2854612 50.15467
31.25033 59.92570 -0.2811724 49.86878
31.30033 59.92632 -0.2777040 50.10812
31.35033 59.92731 -0.2743289 50.01859
31.40033 59.92770 -0.2713596 49.99676
31.45033 59.92795 -0.2686222 50.03360
31.50033 59.92850 -0.2660095 49.88110
31.55033 59.92886 -0.2635982 49.95317
31.60033 59.92863 -0.2614360 50.03013
31.65033 59.92898 -0.2593805 49.99408
31.70033 59.92899 -0.2576400 50.15987
31.75033 59.92978 -0.2559948 49.99511
31.80033 59.92908 -0.2547047 49.98616
31.85034 59.93102 -0.2535052 49.92504
31.90033 59.93015 -0.2525915 49.89313
31.95033 59.93023 -0.2517350 49.98498
32.00033 59.93164 -0.2511016 49.86914
32.05033 59.93062 -0.2503695 49.90744
32.10034 59.93122 -0.2498360 50.07180
32.15033 59.93174 -0.2491827 50.08730
32.20033 59.93137 -0.2485734 50.02569
32.25033 59.93193 -0.2480798 49.95404
32.30033 59.93153 -0.2475504 50.04120
32.35034 59.93286 -0.2470980 50.03873
32.40033 59.93226 -0.2467248 49.99314
32.45033 59.93270 -0.2463196 49.98593
-2.000000 1.000000 0.0000000 0.0000000
32.54700 59.93078 -0.2460987 50.01276
32.59700 59.90540 -0.2186160 50.00561
32.64700 59.85440 -.07475218 50.08458
32.69700 59.79400 0.06480808 49.92386
32.74700 59.72598 0.2048805 49.99490
32.79700 59.65302 0.3367652 49.94721
32.84700 59.57500 0.4617422 50.08282
32.89700 59.49430 0.5735465 50.02741
32.94700 59.41030 0.6752242 50.22726
32.99700 59.32328 0.7584407 49.99458
33.04700 59.23477 0.8351740 50.04150
33.09700 59.14456 0.8972401 50.11240
33.14700 59.05324 0.9535444 50.03780
33.19700 58.96028 0.9997969 50.15610
33.24700 58.86600 1.041487 49.84687
33.29700 58.77132 1.074304 49.82539
33.34700 58.67615 1.102486 49.98554
33.39700 58.57915 1.125887 49.79895
33.44700 58.48351 1.146528 49.91305
33.49700 58.38670 1.163627 49.95252
33.54700 58.28845 1.176949 49.90997
33.59700 58.19141 1.187451 50.01065
33.64700 58.09404 1.197494 49.85700
33.69700 57.99656 1.206254 50.04520
33.74700 57.89769 1.214780 50.05313
33.79700 57.80009 1.223533 49.93582
33.84700 57.70110 1.231633 50.04294
33.89700 57.60149 1.239680 49.88276
33.94700 57.50447 1.247434 50.01252
33.99700 57.40470 1.254894 50.05041
34.04700 57.30471 1.261826 49.90082
34.09700 57.20650 1.268667 49.88628
34.14700 57.10709 1.274726 50.02478
34.19700 57.00810 1.280598 49.96554
34.24700 56.90994 1.285881 49.81756
34.29700 56.81043 1.291076 49.98797
34.34700 56.71042 1.295867 49.84746
34.39700 56.61101 1.300508 50.11916
34.44700 56.51228 1.305005 49.98650
34.49700 56.41216 1.309096 49.94518
34.54700 56.31361 1.312992 49.99694
34.59700 56.21314 1.316504 49.89656
34.64700 56.11355 1.319898 50.09588
34.69700 56.01436 1.323155 50.13048
34.74700 55.91474 1.326179 50.02638
34.79700 55.81534 1.329073 49.95911
34.84700 55.71568 1.331834 50.06526
34.89700 55.61639 1.334468 50.12576
34.94700 55.51645 1.337155 50.07511
34.99700 55.41666 1.339757 49.96048
35.04700 55.31738 1.342399 49.93244
35.09700 55.21689 1.344856 50.06162
35.14700 55.11843 1.347266 49.87219
35.19700 55.01801 1.349706 50.06458
35.24700 54.91887 1.351966 49.88098
35.29700 54.81900 1.354099 49.98230
35.34700 54.71900 1.355950 49.88594
35.39700 54.62001 1.357820 50.00166
35.44700 54.52038 1.359453 50.03606
35.49700 54.42132 1.361235 49.97206
35.54700 54.32058 1.363162 49.98284
35.59700 54.22106 1.364958 50.04110
35.64700 54.12144 1.366899 49.91562
35.69700 54.02194 1.368790 49.97252
35.74700 53.92217 1.370653 50.16650
35.79700 53.82280 1.372433 49.88222
35.84700 53.72256 1.374126 49.95940
35.89700 53.62262 1.375670 50.06988
35.94700 53.52369 1.377353 49.89711
35.99700 53.42344 1.378970 49.92860
36.04700 53.32312 1.380578 49.98377
36.09700 53.22472 1.382242 50.01252
36.14700 53.12370 1.383940 50.06624
36.19700 53.02428 1.385553 49.82437
36.24700 52.92516 1.387067 50.13728
36.29700 52.82470 1.388770 49.98842
36.34700 52.72600 1.390439 49.99846
36.39700 52.62584 1.392050 49.96146
36.44700 52.52676 1.393604 50.12474
36.49700 52.42582 1.395339 49.96600
36.54700 52.32684 1.396899 49.99889
36.59700 52.22661 1.398531 49.96632
36.64700 52.12734 1.400077 50.12744
36.69700 52.02691 1.401700 50.06008
36.74700 51.92671 1.403340 49.94359
36.79700 51.82705 1.404834 50.04550
36.84700 51.72712 1.406524 50.01802
36.89700 51.62756 1.408044 50.08512
36.94700 51.52727 1.409630 49.91867
36.99700 51.42765 1.411127 49.94132
37.04700 51.32782 1.412465 50.09209
37.09700 51.22828 1.413785 50.01507
37.14700 51.12804 1.414982 50.05418
37.19700 51.02876 1.416293 50.01722
37.24700 50.92982 1.417600 50.00730
37.29700 50.82956 1.418765 49.95740
37.34700 50.72890 1.420043 50.07852
37.39700 50.62946 1.421199 49.89700
37.44700 50.53051 1.422418 50.14068
37.49700 50.43007 1.423692 49.95402
37.54700 50.33039 1.424804 49.85100
37.59700 50.23050 1.425971 50.09915
37.64700 50.13100 1.427249 50.13334
37.69700 50.03046 1.428357 49.91386
37.74700 49.93070 1.429330 50.01363
37.79700 49.83194 1.430494 49.94778
37.84700 49.73153 1.431648 50.06588
37.89700 49.63196 1.432970 49.91687
37.94700 49.53281 1.434192 50.06078
37.99700 49.43180 1.435418 49.91078
38.04700 49.33269 1.436689 50.04722
38.09700 49.23242 1.437921 50.08230
38.14700 49.13305 1.439367 49.90600
38.19700 49.03347 1.440625 49.94300
38.24700 48.93371 1.441938 50.05630
38.29700 48.83303 1.443342 49.88795
38.34700 48.73432 1.444490 50.01634
38.39700 48.63500 1.445770 49.96774
38.44700 48.53404 1.446946 49.96516
38.49700 48.43466 1.448084 50.13152
38.54700 48.33519 1.449100 50.04820
38.59700 48.23506 1.450224 50.02307
38.64700 48.13471 1.451394 49.86774
38.69700 48.03482 1.452622 49.93438
38.74700 47.93463 1.453731 50.02268
38.79700 47.83589 1.454715 49.82717
38.84700 47.73582 1.455921 49.97848
38.89700 47.63626 1.457005 49.84531
38.94700 47.53631 1.458158 49.96369
38.99700 47.43587 1.459379 49.89630
39.04700 47.33602 1.460610 49.99782
39.09700 47.23588 1.461734 49.88485
39.14700 47.13630 1.462971 49.82571
39.19700 47.03726 1.464106 49.88603
39.24700 46.93683 1.465261 50.00128
39.29700 46.83730 1.466300 49.98188
39.34700 46.73738 1.467358 49.94998
39.39700 46.63706 1.468454 50.02078
39.44700 46.53839 1.469438 50.14378
39.49700 46.43759 1.470358 50.18562
39.54700 46.33794 1.471324 49.93310
39.59700 46.23806 1.472400 49.89332
39.64700 46.13848 1.473385 50.09413
39.69700 46.03821 1.474539 50.13031
39.74700 45.93837 1.475628 49.95904
39.79700 45.83886 1.476728 50.00840
39.84700 45.73853 1.477788 49.89522
39.89700 45.63912 1.478840 50.15600
39.94700 45.53882 1.479723 49.89096
39.99700 45.43924 1.480628 50.13772
40.04700 45.33796 1.481606 49.97276
40.09700 45.23978 1.482511 50.08720
40.14700 45.14004 1.483284 50.06008
40.19700 45.04014 1.484090 50.12704
40.24700 44.93978 1.484928 50.07412
40.29700 44.83998 1.485662 50.02672
40.34700 44.73986 1.486550 50.04156
40.39700 44.64087 1.487471 49.93295
40.44700 44.54089 1.488303 49.95082
40.49700 44.44020 1.489042 49.98444
40.54700 44.34041 1.489917 50.00712
40.59700 44.24090 1.490745 49.94894
40.64700 44.14131 1.491516 50.08322
40.69700 44.04118 1.492372 49.91804
40.74700 43.94148 1.493326 49.97706
40.79700 43.84239 1.494252 49.96373
40.84700 43.74194 1.495127 50.09492
40.89700 43.64281 1.496119 49.81447
40.94700 43.54263 1.496995 50.15169
40.99700 43.44316 1.497841 49.97893
41.04700 43.34296 1.498823 50.13270
41.09700 43.24296 1.499666 49.95190
41.14700 43.14361 1.500476 49.97516
41.19700 43.04289 1.501379 50.10112
41.24700 42.94328 1.502287 50.00582
41.29700 42.84336 1.503137 49.94041
41.34700 42.74320 1.503874 49.92369
41.39700 42.64351 1.504861 50.02261
41.44700 42.54380 1.505826 50.00867
41.49700 42.44354 1.506760 50.04846
41.54700 42.34378 1.507770 50.01972
41.59700 42.24356 1.508872 49.99050
41.64700 42.14390 1.509828 50.14248
41.69700 42.04312 1.510824 49.99500
41.74700 41.94412 1.511682 49.86622
41.79700 41.84388 1.512518 50.16034
41.84700 41.74430 1.513192 49.91820
41.89700 41.64440 1.513889 49.86222
41.94700 41.54455 1.514485 50.04496
41.99700 41.44391 1.515129 49.77782
42.04700 41.34550 1.515758 49.99906
42.09700 41.24588 1.516287 49.95178
42.14700 41.14609 1.516805 49.97192
42.19700 41.04605 1.517150 49.93408
42.24700 40.94564 1.517818 50.08074
42.29700 40.84549 1.518595 49.90947
42.34700 40.74565 1.519250 49.99358
42.39700 40.64594 1.519841 50.03271
42.44700 40.54610 1.520438 49.95105
42.49700 40.44625 1.521229 49.92546
42.54700 40.34592 1.521940 49.80981
42.59700 40.24688 1.522358 49.98446
42.64700 40.14662 1.523010 50.10238
42.69700 40.04728 1.523717 50.00404
42.74700 39.94675 1.524338 50.07178
42.79700 39.84768 1.525012 49.91340
42.84700 39.74675 1.525411 50.11783
42.89700 39.64680 1.525905 49.92246
42.94700 39.54787 1.526563 49.87594
42.99700 39.44780 1.526924 49.95117
43.04700 39.34800 1.527345 49.94261
43.09700 39.24820 1.527839 50.05107
43.14700 39.14789 1.528187 49.84003
43.19700 39.04895 1.528730 50.18747
43.24700 38.94841 1.529588 49.89729
43.29700 38.84797 1.530258 50.01424
43.34700 38.74902 1.531242 49.90610
43.39700 38.64847 1.532022 49.89159
43.44700 38.54847 1.533004 50.05618
43.49700 38.44916 1.533966 50.14502
43.54700 38.34838 1.534799 50.03189
43.59700 38.24914 1.535575 50.03738
43.64700 38.14942 1.536194 49.98897
43.69700 38.04972 1.536688 50.03966
43.74700 37.94999 1.537311 50.08821
43.79700 37.84983 1.537846 49.90154
43.84700 37.74956 1.538480 50.13476
43.89700 37.64937 1.538897 50.07264
43.94700 37.55043 1.539347 50.01268
43.99700 37.45026 1.539898 50.06289
44.04700 37.35072 1.540337 49.99578
44.09700 37.25064 1.540759 49.92029
44.14700 37.15124 1.541370 50.04372
44.19700 37.05100 1.541771 50.05207
44.24700 36.95028 1.542192 49.92093
44.29700 36.85121 1.542544 50.06802
44.34700 36.75148 1.543099 50.01984
44.39700 36.65138 1.543619 49.89775
44.44700 36.55186 1.544173 49.95840
44.49700 36.45160 1.544784 50.13699
44.54700 36.35244 1.545348 50.08972
44.59700 36.25164 1.546000 50.12691
44.64700 36.15164 1.546624 50.01992
44.69700 36.05203 1.547370 50.03376
44.74700 35.95106 1.548021 50.03241
44.79700 35.85263 1.548650 49.97478
44.84700 35.75176 1.549260 50.00915
44.89700 35.65212 1.549768 50.01460
44.94700 35.55240 1.550328 49.96944
44.99700 35.45255 1.550841 50.16134
45.04700 35.35158 1.551355 50.01106
45.09700 35.25224 1.551890 50.09363
45.14700 35.15280 1.552450 49.88658
45.19700 35.05237 1.552945 49.90020
45.24700 34.95298 1.553492 50.07881
45.29700 34.85204 1.554039 50.04956
45.34700 34.75328 1.554497 50.07554
45.39700 34.65268 1.554827 49.99088
45.44700 34.55283 1.555216 49.99425
45.49700 34.45337 1.555576 49.93969
45.54700 34.35346 1.555889 50.05422
45.59700 34.25370 1.556311 50.03912
45.64700 34.15444 1.556633 50.01825
45.69700 34.05364 1.556929 50.02203
45.74700 33.95395 1.557441 50.04752
45.79700 33.85478 1.557763 49.95846
45.84700 33.75408 1.558266 49.93256
45.89700 33.65450 1.558696 50.09063
45.94700 33.55327 1.559070 49.96050
45.99700 33.45469 1.559536 50.16037
46.04700 33.35453 1.560004 49.88754
46.09700 33.25494 1.560334 50.12836
46.14700 33.15520 1.560709 50.01283
46.19700 33.05519 1.560859 50.02954
46.24700 32.95525 1.561226 49.82413
46.29700 32.85532 1.561428 49.92145
46.34700 32.75476 1.561940 50.12914
46.39700 32.65654 1.562255 49.92169
46.44700 32.55597 1.562475 50.06920
46.49700 32.45568 1.562801 49.87738
46.54700 32.35696 1.563109 49.94578
46.59700 32.25629 1.563512 50.08343
46.64700 32.15717 1.563870 50.10074
46.69700 32.05608 1.564110 50.01298
46.74700 31.95612 1.564536 50.05370
46.79700 31.85622 1.564728 49.97816
46.84700 31.75762 1.564973 50.03962
46.89700 31.65681 1.565196 49.93481
46.94700 31.55728 1.565477 49.98820
46.99700 31.45834 1.565836 50.11156
47.04700 31.35744 1.566405 49.97081
47.09700 31.25772 1.566926 49.91720
47.14700 31.15713 1.567644 49.87781
47.19700 31.05709 1.568333 50.06877
47.24700 30.95672 1.569071 49.90626
47.29700 30.85644 1.569579 49.90157
47.34700 30.75709 1.570238 49.94348
47.39700 30.65634 1.571696 49.92727
47.44700 30.55755 1.576403 50.10746
47.49700 30.46150 1.669365 49.99354
47.54700 30.37212 1.964506 50.01111
47.59700 30.30274 2.615017 49.98444
47.64700 30.25763 3.517094 50.03290
47.69700 30.22121 4.242374 49.96262
47.74700 30.17121 4.650207 49.98734
47.79700 30.10254 4.798182 49.93963
47.84700 30.01650 4.787426 50.13632
47.89700 29.91591 4.672053 49.98877
47.94700 29.80738 4.455665 49.87964
47.99700 29.69046 4.183040 50.03227
48.04700 29.57026 3.894610 49.81262
48.09700 29.44790 3.628203 49.84796
48.14700 29.32676 3.388763 49.86332
48.19700 29.20840 3.179380 49.95504
48.24700 29.09125 2.998538 49.87302
48.29700 28.97586 2.845187 50.00129
48.34700 28.86353 2.713144 50.05051
48.39700 28.75312 2.596664 49.95324
48.44700 28.64363 2.499664 49.92696
48.49700 28.53514 2.412533 49.90240
48.54700 28.42822 2.341237 49.89029
48.59700 28.32120 2.278343 50.10912
48.64700 28.21602 2.223172 50.00484
48.69700 28.11182 2.177730 49.88222
48.74700 28.00800 2.137386 49.99335
48.79700 27.90466 2.102824 50.04633
48.84700 27.80036 2.071989 49.90871
48.89700 27.69914 2.046316 50.05801
48.94700 27.59672 2.025481 49.95276
48.99700 27.49514 2.007274 49.76074
49.04700 27.39320 1.991324 49.87526
49.09700 27.29133 1.977454 50.00580
49.14700 27.19004 1.965380 49.98419
49.19700 27.08957 1.953200 50.05691
49.24700 26.98813 1.944130 49.89936
49.29700 26.88744 1.933927 49.89222
49.34700 26.78607 1.924760 50.00668
49.39700 26.68567 1.915587 49.96048
49.44700 26.58540 1.906161 49.88730
49.49700 26.48538 1.896960 49.95556
49.54700 26.38452 1.888565 50.13821
49.59700 26.28404 1.880377 49.90540
49.64700 26.18375 1.872714 50.04882
49.69700 26.08136 1.865315 50.06112
49.74700 25.98226 1.858456 49.98531
49.79700 25.88187 1.852001 49.90972
49.84700 25.78117 1.845903 49.90200
49.89700 25.68020 1.840062 49.97520
49.94700 25.57991 1.834503 50.01032
49.99700 25.47946 1.829284 49.97604
50.04700 25.37984 1.824174 50.15442
50.09700 25.27967 1.819232 49.87741
50.14700 25.17801 1.814502 50.02545
50.19700 25.07870 1.809890 49.98761
50.24700 24.97808 1.805423 49.93600
50.29700 24.87894 1.801056 50.00926
50.34700 24.77844 1.796909 50.10116
50.39700 24.67848 1.793086 50.00010
50.44700 24.57839 1.789333 49.94948
50.49700 24.47832 1.785573 50.02096
50.54700 24.37748 1.782211 49.99200
50.59700 24.27773 1.778920 49.91391
50.64700 24.17735 1.775810 50.05389
50.69700 24.07702 1.772484 49.92868
50.74700 23.97802 1.769584 50.04659
50.79700 23.87693 1.766702 50.15562
50.84700 23.77698 1.763881 50.04063
50.89700 23.67676 1.761102 49.89768
50.94700 23.57732 1.758416 50.13634
50.99700 23.47639 1.755874 50.05959
51.04700 23.37675 1.753391 50.00611
51.09700 23.27661 1.750845 49.90979
51.14700 23.17604 1.748313 50.11414
51.19700 23.07606 1.745749 50.11526
51.24700 22.97596 1.743256 49.85254
51.29700 22.87586 1.740838 49.99226
51.34700 22.77567 1.738535 50.10950
51.39700 22.67548 1.736262 50.05900
51.44700 22.57614 1.733954 50.08062
51.49700 22.47525 1.731563 50.12781
51.54700 22.37480 1.729407 50.04626
51.59700 22.27513 1.727080 49.98435
51.64700 22.17526 1.724926 49.86656
51.69700 22.07501 1.722571 49.94759
51.74700 21.97443 1.720207 50.10367
51.79700 21.87551 1.718112 49.99990
51.84700 21.77411 1.715773 49.83214
51.89700 21.67422 1.713745 49.92760
51.94700 21.57434 1.711762 49.82750
51.99700 21.47484 1.709748 49.93315
52.04700 21.37467 1.707824 50.00516
52.09700 21.27429 1.705820 49.99097
52.14700 21.17491 1.703938 49.90222
52.19700 21.07371 1.701914 50.09211
52.24700 20.97465 1.699936 50.00248
52.29700 20.87478 1.698023 49.91822
52.34700 20.77532 1.696296 50.01522
52.39700 20.67505 1.694341 50.01319
52.44700 20.57406 1.692557 49.90190
52.49700 20.47447 1.690759 49.96226
52.54700 20.37456 1.689158 50.04374
52.59700 20.27366 1.687697 50.04922
52.64700 20.17289 1.686150 49.97530
52.69700 20.07380 1.684781 49.93026
52.74700 19.97399 1.683302 49.96875
52.79700 19.87329 1.681785 50.15100
52.84700 19.77291 1.680213 50.02100
52.89700 19.67305 1.678726 49.97197
52.94700 19.57272 1.677147 49.98883
52.99700 19.47265 1.675661 49.98219
53.04700 19.37384 1.674010 50.15395
53.09700 19.27218 1.672479 49.88382
53.14700 19.17308 1.671012 49.86903
53.19700 19.07294 1.669452 49.89400
53.24700 18.97227 1.667982 50.11632
53.29700 18.87259 1.666654 50.01890
53.34700 18.77264 1.665319 50.10496
53.39700 18.67308 1.663783 50.03409
53.44700 18.57288 1.662325 49.99614
53.49700 18.47123 1.661053 50.01011
53.54700 18.37252 1.659543 50.04062
53.59700 18.27252 1.658140 50.15822
53.64700 18.17159 1.656797 50.07800
53.69700 18.07287 1.655399 50.16261
53.74700 17.97160 1.653914 50.04164
53.79700 17.87284 1.652502 50.06598
53.84700 17.77234 1.651210 50.03909
53.89700 17.67183 1.649886 50.09404
53.94700 17.57101 1.648735 50.03969
53.99700 17.47144 1.647691 49.95900
54.04700 17.37042 1.646566 50.14539
54.09700 17.27121 1.645574 50.09172
54.14700 17.17124 1.644498 49.82244
54.19700 17.07146 1.643463 50.05339
54.24700 16.97147 1.642388 49.99584
54.29700 16.87092 1.641370 50.08625
54.34700 16.77055 1.640234 50.04963
54.39700 16.67128 1.639163 49.95826
54.44700 16.56972 1.638152 50.04472
54.49700 16.47145 1.637141 50.08968
54.54700 16.37060 1.636114 49.79462
54.59700 16.27090 1.635103 50.01657
54.64700 16.17025 1.634081 50.00960
54.69700 16.07138 1.632815 49.97922
54.74700 15.97097 1.631744 50.00527
54.79700 15.87060 1.630503 49.93160
54.84700 15.77128 1.629234 50.00064
54.89700 15.67049 1.628187 50.01391
54.94700 15.57036 1.626989 50.03227
54.99700 15.47092 1.626065 49.77803
55.04700 15.37172 1.625060 49.97670
55.09700 15.27179 1.624239 49.95582
55.14700 15.17035 1.623359 49.75385
55.19700 15.07014 1.622637 49.91962
55.24700 14.97066 1.622151 50.12610
55.29700 14.87044 1.621329 50.08648
55.34700 14.77060 1.620621 49.99792
55.39700 14.67043 1.620104 49.85390
55.44700 14.57110 1.619344 50.00240
55.49700 14.47087 1.618690 49.97182
55.54700 14.37022 1.618021 49.91506
55.59700 14.26933 1.617282 49.93162
55.64700 14.17014 1.616627 50.14152
55.69700 14.07006 1.615698 50.00426
55.74700 13.97013 1.615003 49.89165
55.79700 13.87077 1.614277 50.02414
55.84700 13.76956 1.613549 49.99802
55.89700 13.67042 1.612612 49.90776
55.94700 13.57112 1.611730 50.03450
55.99700 13.47076 1.610919 50.13763
56.04700 13.37022 1.609994 50.01480
56.09700 13.27008 1.609102 49.88528
56.14700 13.17084 1.608226 49.97114
56.19700 13.07152 1.607331 50.07489
56.24700 12.97146 1.606375 50.01570
56.29700 12.87100 1.605444 49.97042
56.34700 12.76968 1.604691 49.93793
56.39700 12.67050 1.603874 49.97419
56.44700 12.57084 1.603276 49.95119
56.49700 12.47071 1.602652 50.00082
56.54700 12.37222 1.602092 50.04391
56.59700 12.27164 1.601532 50.06748
56.64700 12.17104 1.601130 50.15030
56.69700 12.07140 1.600683 49.99353
56.74700 11.97116 1.600109 50.08422
56.79700 11.87046 1.599596 50.06530
56.84700 11.77076 1.599081 50.02950
56.89700 11.66984 1.598722 49.96676
56.94700 11.57143 1.598239 50.07138
56.99700 11.47161 1.597916 49.96984
57.04700 11.37142 1.597442 50.02728
57.09700 11.27144 1.596896 49.93698
57.14700 11.17092 1.596442 49.94748
57.19700 11.07129 1.595916 50.13906
57.24700 10.97140 1.595409 50.06090
57.29700 10.87096 1.595030 50.09652
57.34700 10.77061 1.594415 49.99002
57.39700 10.67079 1.593925 49.91644
57.44700 10.57096 1.593442 49.94428
57.49700 10.47109 1.592784 49.98938
57.54700 10.37117 1.592294 50.10080
57.59700 10.27108 1.591693 49.96754
57.64700 10.17181 1.591064 50.13510
57.69700 10.07116 1.590665 50.16312
57.74700 9.970858 1.590008 50.03386
57.79700 9.870912 1.589394 49.91036
57.84700 9.770608 1.588743 50.04034
57.89700 9.670782 1.588124 50.13925
57.94700 9.572336 1.587766 50.01402
57.99700 9.471228 1.587232 50.15483
58.04700 9.371399 1.586684 49.93543
58.09700 9.271149 1.586320 50.04100
58.14700 9.171661 1.585987 50.12964
58.19700 9.071853 1.585534 49.93726
58.24700 8.971600 1.585106 49.98104
58.29700 8.871906 1.584833 49.98806
58.34700 8.771481 1.584505 49.97111
58.39700 8.672119 1.584062 49.95254
58.44700 8.572089 1.583755 49.88036
58.49700 8.472309 1.583443 50.03884
58.54700 8.372270 1.582952 50.02936
58.59700 8.272500 1.582689 50.07469
58.64700 8.171730 1.582470 49.95851
58.69700 8.071562 1.582230 49.91320
58.74700 7.972051 1.581960 50.09300
58.79700 7.872674 1.581814 49.99202
58.84700 7.771386 1.581559 49.86210
58.89700 7.671705 1.581160 49.93020
58.94700 7.572318 1.580916 49.98940
58.99700 7.471512 1.580557 50.01611
59.04700 7.371825 1.580253 50.00386
59.09700 7.271536 1.579932 50.04620
59.14700 7.171303 1.579680 50.14090
59.19700 7.072979 1.579325 49.99824
59.24700 6.970386 1.578980 50.08954
59.29700 6.872384 1.578531 49.87903
59.34700 6.771388 1.578217 49.84079
59.39700 6.671924 1.577919 49.90344
59.44700 6.571972 1.577476 50.02262
59.49700 6.472051 1.577116 49.98134
59.54700 6.372060 1.576694 49.97250
59.59700 6.272012 1.576414 50.03033
59.64700 6.171470 1.575939 49.82824
59.69700 6.071612 1.575534 50.06818
59.74700 5.972078 1.575246 50.04518
59.79700 5.871722 1.574820 50.12140
59.84700 5.773152 1.574562 50.01014
59.89700 5.671456 1.574168 49.86346
59.94700 5.571626 1.573945 49.89100
59.99700 5.472207 1.573632 50.13724
60.04700 5.371830 1.573349 50.08435
60.09700 5.273032 1.573397 49.87696
60.14700 5.172779 1.573121 49.98906
60.19700 5.072652 1.572923 50.06678
60.24700 4.971910 1.572747 49.96297
60.29700 4.872211 1.572604 50.04185
60.34700 4.772998 1.572334 49.93736
60.39700 4.672486 1.572124 49.85982
60.44700 4.572374 1.571733 50.02843
60.49700 4.472758 1.571683 50.16316
60.54700 4.372693 1.571467 50.06274
60.59700 4.272592 1.571136 49.98740
60.64700 4.171951 1.571008 49.84410
60.69700 4.072150 1.570679 49.82988
60.74700 3.972316 1.570371 50.15482
60.79700 3.873050 1.570163 49.98520
60.84700 3.772781 1.569921 50.10442
60.89700 3.673172 1.569600 49.95194
60.94700 3.572178 1.569467 50.08566
60.99700 3.473658 1.569261 50.02748
61.04700 3.373455 1.568966 50.12859
61.09700 3.272370 1.568693 50.08550
61.14700 3.173322 1.568536 50.11080
61.19700 3.072790 1.568219 49.96469
61.24700 2.972436 1.568008 49.85440
61.29700 2.873514 1.567783 49.93353
61.34700 2.773877 1.567558 49.92910
61.39700 2.673826 1.567191 50.15956
61.44700 2.573144 1.566977 50.12411
61.49700 2.472674 1.566592 49.90116
61.54700 2.373398 1.566486 49.88966
61.59700 2.273432 1.566379 50.08606
61.64700 2.173963 1.566297 50.00977
61.69700 2.073058 1.566176 50.08952
61.74700 1.972746 1.565946 50.08039
61.79700 1.872857 1.565785 50.10210
61.84700 1.774083 1.565644 50.04356
61.89700 1.673282 1.565370 50.05783
61.94700 1.573523 1.565114 49.99437
61.99700 1.473278 1.564849 50.00727
62.04700 1.377568 1.565026 49.83839
62.09700 1.303014 1.530653 50.12156
62.14700 1.254008 1.406254 50.18547
62.19700 1.215131 1.279370 50.26334
62.24700 1.183089 1.154231 50.05798
62.29700 1.156280 1.035337 50.09492
62.34700 1.134082 0.9207220 49.88086
62.39700 1.115966 0.8217976 49.82490
62.44700 1.100167 0.7303449 50.04625
62.49700 1.087160 0.6500449 49.91236
62.54700 1.075971 0.5778598 50.05126
62.59700 1.065632 0.5190328 50.08382
62.64700 1.057691 0.4695433 50.05865
62.69700 1.049781 0.4240062 50.12682
62.74700 1.044766 0.3886390 50.07799
62.79700 1.038857 0.3563086 50.02076
62.84700 1.033867 0.3314937 50.08820
62.89700 1.030156 0.3073060 49.99831
62.94700 1.025735 0.2905098 49.90702
62.99700 1.022378 0.2754618 49.98270
63.04700 1.020693 0.2630209 50.07269
63.09700 1.017840 0.2523012 49.98359
63.14700 1.015325 0.2438904 50.13316
63.19700 1.015018 0.2351684 50.04105
63.24700 1.013415 0.2267682 50.05626
63.29700 1.011440 0.2182356 49.99214
63.34700 1.010020 0.2102586 49.84955
63.39700 1.009488 0.2024731 49.94860
63.44700 1.007777 0.1953949 49.97944
63.49700 1.006833 0.1887940 50.00653
63.54700 1.006078 0.1827051 50.17052
63.59700 1.006182 0.1772094 49.89988
63.64700 1.004721 0.1723196 49.89006
63.69700 1.004239 0.1678601 49.94582
63.74700 1.002985 0.1639306 50.05900
63.79700 1.002493 0.1602735 49.85258
63.84700 1.002487 0.1570621 50.07838
63.89700 1.002388 0.1543431 50.13228
63.94700 1.001169 0.1517211 50.03244
63.99700 1.000617 0.1494819 50.06246
64.04700 1.000775 0.1474754 50.05889
64.09700 0.9997992 0.1453977 49.98540
64.14700 0.9997418 0.1437368 50.08912
64.19701 0.9985559 0.1419857 49.86658
64.24700 0.9984108 0.1402908 50.04458
64.29700 0.9989952 0.1390044 50.05760
64.34700 0.9989234 0.1375656 50.15030
64.39700 0.9980682 0.1363928 49.96945
64.44701 0.9984303 0.1352151 49.99882
64.49700 0.9989191 0.1341149 49.99896
64.54700 0.9972171 0.1333806 49.94864
64.59700 0.9971871 0.1326736 49.94680
64.64700 0.9981049 0.1318352 50.13731
64.69701 0.9967766 0.1312174 49.99508
64.74700 0.9974653 0.1304483 49.99719
64.79700 0.9971028 0.1299036 49.95185
-2.000000 2.000000 0.0000000 0.0000000