File: imagens/notebooks/dados experimentais/dsc/Karl_TTAB300 Ur 45%.txt
CLOSED
Version	1.0
Language	English
Run	1
RunSerial	158
Instrument	DSC Q100 V9.9 Build 303
Module	DSC Standard Cell FC
Operator	LL
File	\\Niger\ta\Data\DSC\2018\Geral\Karl_TTAB300 Ur 45%.001
ProcName	Karl
InstSerial	0100-1211
Sample	TTAB300 Ur 45%
Size	12.3600	mg
Method	Karl
Comment
Xcomment	Pan: Aluminum Hermetic
Xcomment	Gas1: Nitrogen 50.0 ml/min
Xcomment	Gas2: Nitrogen 0.0 ml/min
Text
Exotherm	UP
Kcell	1.09030
Calib	-11.7822
TempCal	1	pts	158.71	156.60
TzeroDt	-90.0515 -0.0093 2.2263
TzeroDtz	-90.0515 0.0466 2.4421
InstCalFile	Tzero: \\Niger\ta\Data\DSC\CALIBRATION\20122016\CALIBRATION\0_RCS_12_20_2016 17_23_31.TZR
InstCalFile	Baseline: \\Niger\ta\Data\DSC\CALIBRATION\20122016\L.Base 20122016
InstCalFile	Sapphire: \\Niger\ta\Data\DSC\CALIBRATION\20122016\Safira 20122017.001
InstCalDate	Tzero 2016-12-20 Time 19:23:31
TempRange	-90.04 to 395.23 °C at 19.96 °C/min Heat Only
AutoZero	Delta T Offset 0.000 uV
AutoZero	Delta T0 Offset 0.000 uV
Controls	Gas 1  Event Off  Sampling 0.2
Cell#	FC-02451
CoolingUnit	RCS
SelHeatFlow	Heat Flow T4 (mW)
AutoAnalysis	Off
MacroFile
Nsig	4
Sig1	Time (min)
Sig2	Temperature (°C)
Sig3	Heat Flow (mW)
Sig4	Sample Purge Flow (mL/min)
Date	2018-05-17
Time	18:09:47
OrgMethod	1: Equilibrate at 1.00 °C
OrgMethod	2: Ramp 2.00 °C/min to 60.00 °C
OrgMethod	3: Isothermal for 3.00 min
OrgMethod	4: Mark end of cycle 1
OrgMethod	5: Ramp 2.00 °C/min to 1.00 °C
OrgMethod	6: Isothermal for 3.00 min
OrgMethod	7: Mark end of cycle 2
OrgFile	C:\TA\Data\DSC\2018\Geral\Karl_TTAB300 Ur 45%.001
3.33324E-4 1.165390 1.087710 49.89810
0.05033332 1.150147 0.9586016 49.92548
0.1003333 1.163614 0.7963036 49.88821
0.1503333 1.201413 0.6068226 50.03478
0.2003333 1.252957 0.4105808 50.10425
0.2503333 1.311685 0.2228906 49.87242
0.3003333 1.376212 0.05166900 50.03097
0.3503333 1.445673 -0.1118540 49.98308
0.4003334 1.519886 -0.2533198 50.02109
0.4503334 1.597300 -0.3820082 50.00075
0.5003334 1.678394 -0.4893558 50.05703
0.5503332 1.762389 -0.5876430 49.88150
0.6003332 1.845905 -0.6701818 49.91306
0.6503332 1.933260 -0.7459176 49.90780
0.7003332 2.022432 -0.8107700 50.10226
0.7503332 2.111818 -0.8634445 50.09207
0.8003332 2.203752 -0.9111329 49.94584
0.8503332 2.296145 -0.9507000 49.89135
0.9003332 2.388922 -0.9876891 50.12187
0.9503334 2.483193 -1.015835 49.82666
1.000333 2.578396 -1.043058 50.10230
1.050334 2.671926 -1.063706 50.09772
1.100334 2.768004 -1.081490 50.03433
1.150334 2.864324 -1.096923 50.08310
1.200334 2.960765 -1.109720 50.01660
1.250334 3.056875 -1.122425 49.91590
1.300334 3.154234 -1.132600 49.82574
1.350333 3.251916 -1.141875 49.97248
1.400333 3.347931 -1.150858 49.99161
1.450334 3.447080 -1.160190 49.86824
1.500333 3.544170 -1.168996 50.03332
1.550334 3.641828 -1.177554 49.94772
1.600334 3.740582 -1.185790 49.88072
1.650333 3.838741 -1.193776 49.97728
1.700334 3.936377 -1.201314 50.00556
1.750334 4.035496 -1.208502 49.96078
1.800334 4.133694 -1.215203 50.11660
1.850334 4.232320 -1.221358 50.05102
1.900334 4.330955 -1.227160 50.09775
1.950334 4.429579 -1.232595 49.97214
2.000334 4.529030 -1.237741 49.91738
2.050333 4.627970 -1.242388 49.84874
2.100334 4.725964 -1.246659 50.11446
2.150334 4.826236 -1.250751 49.88966
2.200334 4.924994 -1.254672 49.97862
2.250334 5.024286 -1.258208 50.14797
2.300333 5.123363 -1.261454 49.78743
2.350334 5.222485 -1.264544 50.11468
2.400334 5.321280 -1.267492 49.76560
2.450334 5.420720 -1.270273 49.87683
2.500334 5.521593 -1.272808 50.08766
2.550333 5.620193 -1.275344 49.99316
2.600333 5.720081 -1.277694 49.91690
2.650333 5.819034 -1.279877 50.01570
2.700333 5.918866 -1.282034 49.82681
2.750333 6.018116 -1.283892 50.06303
2.800333 6.117515 -1.285938 50.05164
2.850333 6.218552 -1.287736 50.03486
2.900333 6.317336 -1.289551 50.30243
2.950333 6.417022 -1.291317 49.85666
3.000333 6.515873 -1.292974 49.86472
3.050333 6.615941 -1.294566 49.84798
3.100333 6.715282 -1.296121 49.93040
3.150333 6.815180 -1.297562 49.94986
3.200333 6.915000 -1.298893 50.06761
3.250333 7.015063 -1.300180 49.93690
3.300333 7.114307 -1.301434 49.95100
3.350333 7.213616 -1.302642 50.13110
3.400333 7.313989 -1.303734 49.85876
3.450333 7.413751 -1.304795 50.05658
3.500333 7.512878 -1.305746 49.95956
3.550333 7.612820 -1.306701 49.91434
3.600333 7.712507 -1.307546 50.15020
3.650333 7.812690 -1.308522 50.25844
3.700333 7.912828 -1.309368 49.97861
3.750333 8.012182 -1.310153 49.91869
3.800333 8.111338 -1.311104 49.98736
3.850333 8.210812 -1.311984 50.05041
3.900333 8.311456 -1.312614 50.16865
3.950333 8.411600 -1.313453 49.91560
4.000333 8.509249 -1.314055 49.86488
4.050333 8.610444 -1.314739 50.03365
4.100333 8.710578 -1.315539 49.97048
4.150333 8.809784 -1.316257 50.24902
4.200333 8.909920 -1.316999 49.91426
4.250333 9.009668 -1.317787 49.85310
4.300333 9.108892 -1.318508 50.11676
4.350333 9.210438 -1.319103 49.91726
4.400333 9.308972 -1.319830 49.96898
4.450333 9.408595 -1.320464 49.86208
4.500333 9.509119 -1.320999 49.92270
4.550333 9.608422 -1.321705 49.80030
4.600333 9.708330 -1.322508 49.97864
4.650333 9.808201 -1.323485 50.24041
4.700333 9.909364 -1.324382 49.87136
4.750333 10.00927 -1.325346 50.06953
4.800333 10.10863 -1.326354 50.09578
4.850333 10.20876 -1.327106 49.89006
4.900333 10.30875 -1.327939 50.20228
4.950333 10.40832 -1.328448 49.99843
5.000333 10.50752 -1.328889 50.04168
5.050333 10.60758 -1.329182 49.79502
5.100333 10.70718 -1.329631 49.99938
5.150333 10.80684 -1.329747 49.98783
5.200333 10.90723 -1.330070 50.06051
5.250332 11.00670 -1.330287 49.98004
5.300332 11.10671 -1.330584 50.01822
5.350332 11.20755 -1.330989 50.16181
5.400332 11.30576 -1.331281 50.01934
5.450332 11.40643 -1.331706 49.88919
5.500332 11.50675 -1.332161 50.13136
5.550332 11.60716 -1.332779 50.02493
5.600332 11.70628 -1.333254 50.05889
5.650332 11.80582 -1.333864 50.12952
5.700332 11.90596 -1.334427 50.00162
5.750332 12.00601 -1.334756 50.18628
5.800332 12.10599 -1.335231 50.04304
5.850332 12.20522 -1.335672 50.10220
5.900332 12.30543 -1.336123 49.94922
5.950332 12.40514 -1.336538 50.04210
6.000332 12.50334 -1.336819 49.82690
6.050332 12.60529 -1.337366 50.08270
6.100332 12.70514 -1.337756 49.95393
6.150332 12.80477 -1.338309 50.10571
6.200332 12.90440 -1.339006 50.00694
6.250332 13.00364 -1.339580 49.93078
6.300332 13.10414 -1.340197 50.03803
6.350332 13.20373 -1.340881 50.08986
6.400332 13.30414 -1.341553 50.13304
6.450332 13.40372 -1.342207 49.83834
6.500332 13.50419 -1.342738 49.90847
6.550332 13.60309 -1.343434 49.96530
6.600332 13.70399 -1.343990 50.05774
6.650332 13.80404 -1.344575 50.08452
6.700332 13.90429 -1.345105 49.95117
6.750332 14.00384 -1.345554 49.92100
6.800332 14.10347 -1.345732 49.92022
6.850332 14.20314 -1.346311 49.88674
6.900332 14.30269 -1.346699 49.89320
6.950332 14.40351 -1.347171 50.06406
7.000332 14.50340 -1.347626 49.87492
7.050332 14.60262 -1.348161 50.11053
7.100332 14.70315 -1.348774 49.91187
7.150332 14.80340 -1.349300 50.11441
7.200332 14.90244 -1.349779 49.89774
7.250332 15.00262 -1.350225 49.90380
7.300332 15.10334 -1.350762 50.10502
7.350332 15.20278 -1.351266 49.86683
7.400332 15.30265 -1.351692 50.03760
7.450332 15.40253 -1.352054 50.07800
7.500332 15.50244 -1.352578 49.88676
7.550332 15.60274 -1.352933 49.99414
7.600332 15.70296 -1.353384 50.05011
7.650332 15.80236 -1.353790 49.96344
7.700332 15.90205 -1.354320 50.04326
7.750332 16.00227 -1.354706 49.90348
7.800332 16.10237 -1.355194 50.13424
7.850332 16.20187 -1.355628 49.99084
7.900332 16.30098 -1.356040 49.99731
7.950332 16.40239 -1.356604 50.01108
8.000334 16.50093 -1.357055 49.99270
8.050332 16.60159 -1.357536 50.01484
8.100332 16.70168 -1.358201 49.88180
8.150332 16.80101 -1.358656 50.05546
8.200332 16.90125 -1.359094 50.02978
8.250334 17.00112 -1.359764 50.07203
8.300332 17.10101 -1.360226 50.10090
8.350332 17.20130 -1.360914 50.03986
8.400332 17.30164 -1.361377 49.99043
8.450332 17.40154 -1.361890 50.00672
8.500334 17.50154 -1.362334 49.97086
8.550332 17.60114 -1.362724 50.10022
8.600332 17.70120 -1.363096 50.07770
8.650332 17.80075 -1.363373 50.07610
8.700332 17.90001 -1.363729 49.98317
8.750334 18.00162 -1.364362 49.98882
8.800332 18.10114 -1.364706 50.11550
8.850332 18.20070 -1.365077 49.96297
8.900332 18.30014 -1.365597 49.91519
8.950332 18.40010 -1.366122 49.86241
9.000334 18.50140 -1.366556 49.94724
9.050332 18.59917 -1.367068 49.77393
9.100332 18.69926 -1.367790 50.12215
9.150332 18.79942 -1.368458 49.98928
9.200332 18.89931 -1.369206 49.87990
9.250334 19.00056 -1.369977 50.01253
9.300332 19.09929 -1.370726 50.04280
9.350332 19.19931 -1.371580 50.09898
9.400332 19.29891 -1.372403 50.08981
9.450332 19.39948 -1.373284 49.95704
9.500334 19.49924 -1.374072 50.01866
9.550332 19.59937 -1.374936 50.11247
9.600332 19.69880 -1.375751 49.95615
9.650332 19.79926 -1.376668 49.89835
9.700332 19.89836 -1.377532 49.95840
9.750334 19.99829 -1.378617 50.01791
9.800332 20.09859 -1.379635 49.97371
9.850332 20.19929 -1.380878 50.18030
9.900332 20.29964 -1.381974 49.89965
9.950332 20.39967 -1.383146 49.96604
10.00033 20.49970 -1.384248 49.96133
10.05033 20.59941 -1.385136 49.92645
10.10033 20.69925 -1.385987 50.06162
10.15033 20.80017 -1.386732 50.02683
10.20033 20.89976 -1.387335 50.10878
10.25033 20.99900 -1.388087 50.00672
10.30033 21.09967 -1.388743 49.98871
10.35033 21.19853 -1.389424 50.17537
10.40033 21.29813 -1.389985 50.00442
10.45033 21.39949 -1.390864 50.19742
10.50034 21.49904 -1.391361 50.16476
10.55033 21.59910 -1.391976 49.97165
10.60033 21.69894 -1.392448 49.91962
10.65033 21.79790 -1.393171 49.93383
10.70033 21.89783 -1.393639 49.87170
10.75034 21.99750 -1.394240 49.92737
10.80033 22.09751 -1.394819 49.84528
10.85033 22.19656 -1.395675 49.96240
10.90033 22.29659 -1.396448 49.84918
10.95033 22.39675 -1.397311 49.92608
11.00034 22.49607 -1.398433 49.94247
11.05033 22.59572 -1.399460 50.09311
11.10033 22.69567 -1.400575 50.01782
11.15033 22.79514 -1.401620 49.92984
11.20033 22.89496 -1.402772 49.96600
11.25034 22.99529 -1.403965 50.03596
11.30033 23.09484 -1.405372 50.02985
11.35033 23.19553 -1.406768 50.09818
11.40033 23.29414 -1.408332 50.05108
11.45033 23.39460 -1.409749 50.12303
11.50034 23.49467 -1.411186 50.05696
11.55033 23.59551 -1.412712 50.06615
11.60033 23.69360 -1.414286 50.09280
11.65033 23.79362 -1.415702 49.92226
11.70033 23.89352 -1.417145 49.81538
11.75034 23.99320 -1.418770 50.03344
11.80033 24.09340 -1.420609 49.97912
11.85033 24.19254 -1.422759 50.07680
11.90033 24.29217 -1.425406 50.00498
11.95033 24.39186 -1.429187 50.00437
12.00034 24.49131 -1.434338 50.12942
12.05033 24.58964 -1.444729 49.88374
12.10033 24.68711 -1.464222 50.12581
12.15033 24.78570 -1.504146 49.89264
12.20033 24.88319 -1.550861 50.04355
12.25034 24.97930 -1.603561 49.86890
12.30033 25.07590 -1.659780 50.17925
12.35033 25.17209 -1.715528 50.01570
12.40033 25.26812 -1.770415 50.08684
12.45033 25.36319 -1.830380 50.15900
12.50034 25.45715 -1.883868 50.18781
12.55033 25.55400 -1.933741 49.78814
12.60033 25.64900 -1.983380 49.95864
12.65033 25.74440 -2.026051 49.96668
12.70033 25.84121 -2.063284 50.04766
12.75034 25.93794 -2.098482 50.12090
12.80033 26.03603 -2.130957 49.87702
12.85033 26.13237 -2.156120 49.99424
12.90033 26.23030 -2.182131 49.81433
12.95034 26.32814 -2.203002 50.11550
13.00034 26.42568 -2.222825 50.01860
13.05033 26.52448 -2.238873 49.87270
13.10033 26.62356 -2.253647 50.06227
13.15033 26.72113 -2.267846 50.10230
13.20034 26.81944 -2.282152 50.10746
13.25034 26.91844 -2.293306 49.98138
13.30033 27.01748 -2.304468 49.94980
13.35033 27.11620 -2.315498 50.01865
13.40033 27.21435 -2.327257 49.94467
13.45034 27.31470 -2.337135 50.14168
13.50034 27.41227 -2.347234 49.94760
13.55033 27.51362 -2.357043 49.98136
13.60033 27.61274 -2.366570 50.01758
13.65033 27.71140 -2.376031 49.95616
13.70034 27.81077 -2.385248 50.01638
13.75034 27.91050 -2.394152 50.00306
13.80033 28.00962 -2.403098 49.97684
13.85033 28.10814 -2.411409 50.03453
13.90033 28.20852 -2.419714 50.03790
13.95034 28.30846 -2.427733 50.00534
14.00034 28.40676 -2.435470 50.06902
14.05033 28.50600 -2.443002 50.08377
14.10033 28.60588 -2.450310 50.07596
14.15033 28.70513 -2.457368 49.82200
14.20034 28.80408 -2.464361 49.97354
14.25034 28.90365 -2.471233 50.08992
14.30033 29.00404 -2.477603 50.21332
14.35033 29.10288 -2.484030 50.07376
14.40033 29.20284 -2.490148 50.15476
14.45034 29.30140 -2.496344 50.11906
14.50034 29.40062 -2.502403 49.89210
14.55033 29.50000 -2.508672 49.97744
14.60033 29.59932 -2.514926 50.10044
14.65033 29.69904 -2.521236 50.00828
14.70034 29.79914 -2.527624 49.92895
14.75034 29.89879 -2.534182 50.04644
14.80033 29.99802 -2.540640 49.95910
14.85033 30.09722 -2.547209 50.00575
14.90033 30.19693 -2.553712 50.03934
14.95034 30.29704 -2.560447 49.82500
15.00034 30.39598 -2.567075 49.81480
15.05033 30.49477 -2.573931 50.05545
15.10033 30.59482 -2.580794 50.14697
15.15033 30.69398 -2.588033 49.82625
15.20034 30.79346 -2.595424 50.12110
15.25034 30.89298 -2.603142 50.04205
15.30033 30.99235 -2.610820 49.99016
15.35033 31.09174 -2.618616 49.93718
15.40033 31.19128 -2.626871 50.01341
15.45034 31.28976 -2.635913 49.80266
15.50034 31.38991 -2.644232 50.02974
15.55033 31.48980 -2.652811 50.04650
15.60033 31.58805 -2.661878 49.84492
15.65033 31.68790 -2.671106 50.09107
15.70034 31.78769 -2.681417 49.92832
15.75034 31.88635 -2.690672 49.89494
15.80033 31.98566 -2.700166 49.88728
15.85033 32.08458 -2.709885 50.00754
15.90033 32.18306 -2.719147 49.98935
15.95034 32.28267 -2.728815 49.90832
16.00033 32.38089 -2.738140 49.99878
16.05033 32.48062 -2.748194 50.05758
16.10033 32.57930 -2.757710 50.14254
16.15033 32.67804 -2.767483 49.95520
16.20033 32.77672 -2.777273 49.93611
16.25033 32.87689 -2.787451 50.09549
16.30033 32.97524 -2.797028 50.02613
16.35033 33.07470 -2.806483 50.10458
16.40033 33.17369 -2.815874 49.90295
16.45033 33.27223 -2.825049 49.82844
16.50033 33.37271 -2.834057 49.89466
16.55033 33.47192 -2.843080 49.79966
16.60033 33.57122 -2.852168 50.02051
16.65033 33.67020 -2.861062 49.99409
16.70033 33.76960 -2.869531 50.06886
16.75033 33.87062 -2.877612 50.01037
16.80033 33.96920 -2.885492 49.96175
16.85033 34.06855 -2.893206 49.99391
16.90033 34.16800 -2.900598 50.07724
16.95033 34.26775 -2.907790 49.99874
17.00033 34.36695 -2.914566 49.91111
17.05033 34.46674 -2.921179 50.01119
17.10033 34.56566 -2.927430 49.92410
17.15033 34.66580 -2.933528 49.94250
17.20033 34.76504 -2.939368 49.94908
17.25033 34.86533 -2.945010 49.99103
17.30033 34.96317 -2.950602 49.95594
17.35033 35.06396 -2.955996 50.22034
17.40033 35.16348 -2.961323 50.04941
17.45033 35.26268 -2.966417 49.98340
17.50033 35.36241 -2.971184 50.07094
17.55033 35.46173 -2.975965 50.01388
17.60033 35.56112 -2.980432 49.96335
17.65033 35.66020 -2.984890 49.87636
17.70033 35.76091 -2.989263 50.09109
17.75033 35.86028 -2.993618 49.86937
17.80033 35.96014 -2.998060 50.01717
17.85033 36.05880 -3.002364 49.81680
17.90033 36.15925 -3.006601 49.86240
17.95033 36.25844 -3.010965 49.96258
18.00033 36.35867 -3.015284 50.07103
18.05033 36.45856 -3.019568 49.96021
18.10033 36.55822 -3.024018 50.03804
18.15033 36.65860 -3.028267 50.08926
18.20033 36.75760 -3.032552 49.89078
18.25033 36.85782 -3.036456 49.89496
18.30033 36.95747 -3.039984 49.93274
18.35033 37.05697 -3.043486 50.07762
18.40033 37.15720 -3.046494 50.18914
18.45033 37.25667 -3.049436 49.99884
18.50033 37.35768 -3.051973 49.92191
18.55033 37.45688 -3.054079 49.90852
18.60033 37.55736 -3.056050 49.85324
18.65033 37.65632 -3.057424 49.82639
18.70033 37.75646 -3.058220 50.12771
18.75033 37.85620 -3.058806 49.99320
18.80033 37.95688 -3.058909 50.06706
18.85033 38.05680 -3.058446 50.08134
18.90033 38.15758 -3.057563 50.19194
18.95033 38.25757 -3.055983 50.13485
19.00033 38.35782 -3.054117 50.06758
19.05033 38.45825 -3.051524 50.16231
19.10033 38.55854 -3.047854 50.13070
19.15033 38.65882 -3.043232 50.14390
19.20033 38.75912 -3.037172 49.93254
19.25033 38.86020 -3.030907 50.02820
19.30033 38.96078 -3.023010 50.12460
19.35033 39.06119 -3.016067 50.22000
19.40033 39.16198 -3.004416 49.91800
19.45033 39.26331 -2.978362 49.97922
19.50033 39.36539 -2.947334 49.91440
19.55033 39.46752 -2.909719 49.86392
19.60033 39.56994 -2.873380 50.09078
19.65033 39.67208 -2.834055 49.99774
19.70033 39.77488 -2.791030 49.92850
19.75033 39.87805 -2.746685 50.06374
19.80033 39.98237 -2.696039 49.85970
19.85033 40.08631 -2.640881 49.99460
19.90033 40.19009 -2.577374 49.92697
19.95033 40.29470 -2.513433 49.91852
20.00033 40.40187 -2.445090 49.90767
20.05033 40.50645 -2.379220 49.84678
20.10033 40.61183 -2.314908 50.04438
20.15033 40.71680 -2.255190 49.98049
20.20033 40.82132 -2.192640 49.97376
20.25033 40.92656 -2.131184 49.98178
20.30033 41.03155 -2.072127 50.02964
20.35033 41.13544 -2.012652 50.04000
20.40033 41.24150 -1.956930 50.04376
20.45033 41.34592 -1.903655 49.91452
20.50033 41.45067 -1.852808 50.01848
20.55033 41.55351 -1.807340 49.88562
20.60033 41.65842 -1.763211 49.96000
20.65033 41.76160 -1.724112 49.90722
20.70033 41.86413 -1.690170 50.04288
20.75033 41.96760 -1.661123 50.11633
20.80033 42.07059 -1.632296 50.02669
20.85033 42.17270 -1.609216 50.05816
20.90033 42.27488 -1.591710 50.02671
20.95033 42.37629 -1.576553 49.97779
21.00033 42.47632 -1.565332 49.97447
21.05033 42.57787 -1.556703 49.96766
21.10033 42.67896 -1.548581 50.08062
21.15033 42.77861 -1.540443 49.95208
21.20033 42.87936 -1.532569 50.04998
21.25033 42.98068 -1.525058 49.88428
21.30033 43.08097 -1.518354 50.03491
21.35033 43.17998 -1.512144 50.09394
21.40033 43.28047 -1.506328 50.04642
21.45033 43.38022 -1.501936 50.09896
21.50033 43.48010 -1.498536 49.98561
21.55033 43.58133 -1.495722 50.07778
21.60033 43.68072 -1.493338 49.87910
21.65033 43.78046 -1.491073 50.12959
21.70033 43.88067 -1.489111 49.86940
21.75033 43.98087 -1.487524 49.95362
21.80033 44.08191 -1.486078 50.03770
21.85033 44.18130 -1.484746 50.11861
21.90033 44.28134 -1.483525 50.04230
21.95033 44.38148 -1.482556 50.06488
22.00033 44.48213 -1.481630 49.97080
22.05033 44.58150 -1.480760 50.23090
22.10033 44.68200 -1.479944 49.82360
22.15033 44.78330 -1.479366 50.00464
22.20033 44.88213 -1.478697 50.09918
22.25033 44.98209 -1.478130 50.00914
22.30033 45.08242 -1.477807 49.89054
22.35033 45.18246 -1.477209 50.00820
22.40033 45.28334 -1.476586 49.93184
22.45033 45.38241 -1.475980 49.98420
22.50033 45.48189 -1.475358 49.97391
22.55033 45.58300 -1.474784 49.82804
22.60033 45.68231 -1.474220 49.87883
22.65033 45.78296 -1.473714 49.99900
22.70033 45.88197 -1.473380 50.09506
22.75033 45.98265 -1.473132 50.14810
22.80033 46.08140 -1.473106 49.77004
22.85033 46.18122 -1.473048 50.10868
22.90033 46.28220 -1.473022 50.04422
22.95033 46.38262 -1.473223 50.07106
23.00033 46.48240 -1.473136 50.02280
23.05033 46.58186 -1.473252 49.98489
23.10033 46.68277 -1.473181 49.89355
23.15033 46.78130 -1.473066 50.06225
23.20033 46.88148 -1.472528 50.07719
23.25033 46.98123 -1.472026 50.05103
23.30033 47.08110 -1.471262 49.99040
23.35033 47.18209 -1.470580 49.91165
23.40033 47.28111 -1.469925 50.02340
23.45033 47.38205 -1.469600 50.01469
23.50033 47.48148 -1.469337 49.89059
23.55033 47.58118 -1.469351 49.93260
23.60033 47.68154 -1.469364 50.17682
23.65033 47.78146 -1.469710 49.98992
23.70033 47.88094 -1.469927 50.09207
23.75033 47.98050 -1.470221 49.90353
23.80033 48.08090 -1.470584 50.07178
23.85033 48.18066 -1.470854 50.09158
23.90033 48.28112 -1.471282 50.08291
23.95033 48.38134 -1.471562 50.03504
24.00033 48.48100 -1.471847 50.03216
24.05033 48.57980 -1.472250 49.99328
24.10033 48.68046 -1.472710 49.98156
24.15033 48.78096 -1.473088 49.96000
24.20033 48.88120 -1.473502 49.96796
24.25033 48.98062 -1.474042 50.01834
24.30033 49.08106 -1.474506 49.93274
24.35033 49.18042 -1.474947 50.00180
24.40033 49.28071 -1.475301 50.02568
24.45033 49.38045 -1.475875 49.93924
24.50033 49.48050 -1.476372 50.05244
24.55033 49.58056 -1.476763 50.07133
24.60033 49.68140 -1.477224 49.93350
24.65033 49.78076 -1.477468 49.95544
24.70033 49.88043 -1.477932 49.89150
24.75033 49.98053 -1.478323 50.10730
24.80033 50.08004 -1.478898 49.93103
24.85033 50.17938 -1.479072 50.11863
24.90033 50.27956 -1.479511 50.08598
24.95033 50.37980 -1.479967 50.04098
25.00033 50.48045 -1.480658 50.00748
25.05033 50.58003 -1.481315 50.10257
25.10033 50.67949 -1.481778 49.88120
25.15033 50.77939 -1.482544 50.03162
25.20033 50.87954 -1.483387 49.81728
25.25033 50.97874 -1.484025 50.00037
25.30033 51.07861 -1.484604 50.10931
25.35033 51.17900 -1.485126 50.03863
25.40033 51.27872 -1.485553 50.08167
25.45033 51.37761 -1.486053 49.99432
25.50033 51.47806 -1.486440 49.94443
25.55033 51.57797 -1.486999 50.01023
25.60033 51.67727 -1.487485 49.96416
25.65033 51.77716 -1.488187 49.85244
25.70033 51.87717 -1.488991 49.93363
25.75033 51.97766 -1.489860 50.08840
25.80033 52.07740 -1.491063 50.05596
25.85033 52.17672 -1.492006 49.94385
25.90033 52.27680 -1.492884 49.89322
25.95033 52.37726 -1.493872 50.08517
26.00033 52.47803 -1.494662 50.13810
26.05033 52.57718 -1.495562 50.09730
26.10033 52.67716 -1.496597 49.89032
26.15033 52.77713 -1.497474 50.04744
26.20033 52.87756 -1.498365 50.11078
26.25033 52.97761 -1.499109 50.04437
26.30033 53.07611 -1.499895 50.18715
26.35033 53.17626 -1.500601 49.86296
26.40033 53.27720 -1.501513 49.93383
26.45033 53.37666 -1.502248 49.95226
26.50033 53.47626 -1.503147 49.76267
26.55033 53.57553 -1.503982 49.75134
26.60033 53.67734 -1.504845 50.17959
26.65033 53.77615 -1.505604 49.92138
26.70033 53.87620 -1.506191 50.07863
26.75033 53.97615 -1.507002 49.94200
26.80033 54.07494 -1.507747 50.13476
26.85033 54.17553 -1.508461 50.04840
26.90033 54.27574 -1.509051 50.14269
26.95033 54.37560 -1.509851 49.90567
27.00033 54.47481 -1.510695 49.92951
27.05033 54.57467 -1.511555 49.96563
27.10033 54.67467 -1.512790 50.14152
27.15033 54.77429 -1.513852 50.02488
27.20033 54.87470 -1.514993 50.10449
27.25033 54.97437 -1.515909 49.97122
27.30033 55.07403 -1.517107 49.89074
27.35033 55.17382 -1.518099 50.01258
27.40033 55.27324 -1.519119 49.93320
27.45033 55.37449 -1.520202 50.04846
27.50033 55.47429 -1.521062 49.88126
27.55033 55.57394 -1.522075 49.97092
27.60033 55.67412 -1.523129 50.02910
27.65033 55.77474 -1.524086 50.05679
27.70033 55.87346 -1.525089 50.08360
27.75033 55.97430 -1.525911 50.05463
27.80033 56.07441 -1.526686 49.99628
27.85033 56.17425 -1.527255 49.87759
27.90033 56.27415 -1.528099 49.87698
27.95033 56.37428 -1.528771 50.12244
28.00033 56.47354 -1.529517 50.07457
28.05033 56.57416 -1.530351 50.04220
28.10033 56.67401 -1.531044 49.88552
28.15033 56.77334 -1.531934 50.15626
28.20033 56.87376 -1.532645 49.99167
28.25033 56.97370 -1.533307 50.00207
28.30033 57.07302 -1.533960 49.83160
28.35033 57.17307 -1.534616 49.89048
28.40033 57.27172 -1.535107 49.96381
28.45033 57.37247 -1.535734 49.89684
28.50033 57.47253 -1.536620 49.99931
28.55033 57.57284 -1.537680 50.04772
28.60033 57.67348 -1.538647 49.96942
28.65033 57.77246 -1.539561 49.94428
28.70033 57.87220 -1.540372 50.04469
28.75033 57.97260 -1.541351 50.12738
28.80033 58.07224 -1.542308 49.96722
28.85033 58.17145 -1.543018 50.00254
28.90033 58.27164 -1.543610 49.91524
28.95033 58.37156 -1.544313 50.16326
29.00033 58.47090 -1.544827 49.90000
29.05033 58.57046 -1.545412 49.98486
29.10033 58.67034 -1.545952 50.11348
29.15033 58.77000 -1.546616 50.09872
29.20033 58.87029 -1.547317 49.94148
29.25033 58.97100 -1.548093 49.90420
29.30033 59.07012 -1.548882 50.06606
29.35033 59.17084 -1.549773 50.13946
29.40033 59.26925 -1.550917 50.03160
29.45033 59.36975 -1.552152 49.96532
29.50033 59.46961 -1.553393 49.92148
29.55033 59.56648 -1.555021 49.99565
29.60033 59.63932 -1.529905 50.01708
29.65033 59.68790 -1.394830 49.90479
29.70033 59.72842 -1.264381 49.97545
29.75033 59.75989 -1.123679 49.75106
29.80033 59.78743 -0.9946418 50.05159
29.85033 59.81055 -0.8701547 50.00385
29.90033 59.82959 -0.7603576 50.02676
29.95033 59.84534 -0.6664257 49.99222
30.00033 59.85938 -0.5808658 49.87624
30.05033 59.87024 -0.5094902 49.98286
30.10033 59.88018 -0.4431622 50.06074
30.15033 59.88840 -0.3920194 49.99326
30.20033 59.89631 -0.3466790 49.96488
30.25033 59.90282 -0.3101532 50.18942
30.30033 59.90723 -0.2750478 49.90280
30.35033 59.91257 -0.2479329 50.08078
30.40033 59.91620 -0.2270891 49.99783
30.45033 59.91912 -0.2057456 50.00878
30.50033 59.92220 -0.1904220 50.11168
30.55033 59.92519 -0.1776433 49.94089
30.60033 59.92724 -0.1677348 50.02607
30.65033 59.92939 -0.1585416 50.09842
30.70033 59.93161 -0.1495710 50.07974
30.75033 59.93293 -0.1413258 49.90246
30.80033 59.93388 -0.1331206 50.04329
30.85033 59.93516 -0.1251820 49.98428
30.90033 59.93666 -0.1179573 50.08484
30.95033 59.93822 -0.1110250 49.91135
31.00033 59.93889 -0.1048249 49.97783
31.05033 59.94039 -.09899108 50.01119
31.10033 59.94125 -.09368819 50.01631
31.15033 59.94121 -.08877556 49.92415
31.20033 59.94068 -.08430176 49.90209
31.25033 59.94234 -.08043335 49.87537
31.30033 59.94220 -.07680090 49.93140
31.35033 59.94332 -.07352610 49.96594
31.40033 59.94361 -.07043919 49.88262
31.45033 59.94406 -.06775556 50.13078
31.50033 59.94410 -.06544972 50.01284
31.55033 59.94528 -.06342094 50.24648
31.60033 59.94452 -.06148090 49.79150
31.65033 59.94467 -.05963634 49.82430
31.70033 59.94644 -.05815241 49.93548
31.75033 59.94588 -.05678418 50.08118
31.80033 59.94656 -.05513512 49.88219
31.85034 59.94628 -.05369568 49.92098
31.90033 59.94682 -.05247837 50.21940
31.95033 59.94624 -.05123398 49.49484
32.00033 59.94757 -.05019612 49.94988
32.05033 59.94668 -.04933119 49.97393
32.10034 59.94672 -.04860117 50.03622
32.15033 59.94760 -.04785791 50.01861
32.20033 59.94825 -.04740788 49.98131
32.25033 59.94795 -.04686523 50.04835
32.30033 59.94802 -.04636726 50.19258
32.35034 59.94846 -.04582631 50.07420
32.40033 59.94804 -.04537787 49.93130
32.45033 59.94836 -.04491111 49.89081
-2.000000 1.000000 0.0000000 0.0000000
32.54700 59.94580 -.04485756 50.06058
32.59700 59.92090 -.01843054 49.83386
32.64700 59.86997 0.1197852 50.06078
32.69700 59.80948 0.2551892 50.12974
32.74700 59.74130 0.3959637 49.99638
32.79700 59.66750 0.5312076 49.90962
32.84700 59.59088 0.6533594 50.06452
32.89700 59.50896 0.7664634 50.03702
32.94700 59.42480 0.8615140 49.83337
32.99700 59.33772 0.9508759 49.89041
33.04700 59.24970 1.023750 50.07662
33.09700 59.15900 1.088202 50.04884
33.14700 59.06791 1.145958 50.05917
33.19700 58.97482 1.190922 49.85704
33.24700 58.88070 1.232736 50.05502
33.29700 58.78661 1.263931 49.97480
33.34700 58.69141 1.289978 50.06368
33.39700 58.59620 1.314117 49.85160
33.44700 58.49940 1.333717 49.88278
33.49700 58.40200 1.348983 49.99380
33.54700 58.30492 1.362900 50.16641
33.59700 58.20684 1.374082 50.04506
33.64700 58.10916 1.383844 49.92044
33.69700 58.01118 1.392306 49.84848
33.74700 57.91200 1.400898 49.90713
33.79700 57.81454 1.409541 50.09824
33.84700 57.71705 1.418008 49.89032
33.89700 57.61716 1.425877 50.11684
33.94700 57.51804 1.433290 50.14016
33.99700 57.41994 1.440324 49.90129
34.04700 57.32084 1.446827 49.95898
34.09700 57.22211 1.452962 50.15718
34.14700 57.12245 1.458839 49.92656
34.19700 57.02363 1.464182 50.15860
34.24700 56.92336 1.469010 50.13194
34.29700 56.82411 1.473562 49.99478
34.34700 56.72474 1.477478 49.96836
34.39700 56.62554 1.481223 50.03389
34.44700 56.52659 1.484622 49.91940
34.49700 56.42729 1.488106 50.04547
34.54700 56.32779 1.491177 49.98653
34.59700 56.22800 1.494015 49.96283
34.64700 56.12842 1.496528 50.05026
34.69700 56.02886 1.499025 50.12722
34.74700 55.92920 1.501341 50.07540
34.79700 55.82994 1.503630 50.11739
34.84700 55.73012 1.505678 50.26676
34.89700 55.63059 1.507743 49.87111
34.94700 55.53047 1.509820 50.00102
34.99700 55.43097 1.511924 49.97496
35.04700 55.33064 1.513681 50.12890
35.09700 55.23085 1.515351 49.86444
35.14700 55.13158 1.517054 50.10106
35.19700 55.03194 1.518334 49.96516
35.24700 54.93270 1.519639 50.05167
35.29700 54.83310 1.520889 50.03765
35.34700 54.73264 1.522086 49.91344
35.39700 54.63340 1.523362 50.03628
35.44700 54.53384 1.524403 49.97798
35.49700 54.43300 1.525549 49.82787
35.54700 54.33411 1.526625 50.05636
35.59700 54.23468 1.527605 49.92804
35.64700 54.13472 1.528608 49.99809
35.69700 54.03530 1.529564 50.07209
35.74700 53.93524 1.530589 49.96030
35.79700 53.83582 1.531468 50.03880
35.84700 53.73635 1.532494 50.06284
35.89700 53.63645 1.533573 50.16510
35.94700 53.53625 1.534423 49.90137
35.99700 53.43664 1.535468 50.04524
36.04700 53.33674 1.536505 50.11630
36.09700 53.23618 1.537655 50.03531
36.14700 53.13746 1.538612 50.02320
36.19700 53.03738 1.539791 50.02016
36.24700 52.93762 1.541096 49.91372
36.29700 52.83701 1.542321 49.94184
36.34700 52.73740 1.543692 50.01728
36.39700 52.63799 1.545004 50.17945
36.44700 52.53758 1.546158 49.97226
36.49700 52.43700 1.547107 49.99281
36.54700 52.33789 1.548180 50.05962
36.59700 52.23862 1.548892 50.10670
36.64700 52.13775 1.549542 49.97490
36.69700 52.03869 1.550156 49.99202
36.74700 51.93904 1.550859 49.99703
36.79700 51.83941 1.551546 49.96861
36.84700 51.73933 1.552077 50.03747
36.89700 51.63958 1.552989 50.04802
36.94700 51.53964 1.553486 49.90064
36.99700 51.43989 1.554150 49.97148
37.04700 51.34062 1.554912 49.99439
37.09700 51.24032 1.555649 49.87286
37.14700 51.14114 1.556314 49.94552
37.19700 51.04137 1.557101 49.88366
37.24700 50.94134 1.557706 49.99258
37.29700 50.84204 1.558589 50.15185
37.34700 50.74200 1.559302 50.05279
37.39700 50.64176 1.560221 50.03447
37.44700 50.54145 1.561038 50.01772
37.49700 50.44206 1.561677 49.88413
37.54700 50.34254 1.562516 49.97752
37.59700 50.24304 1.563383 50.00152
37.64700 50.14184 1.564244 49.96278
37.69700 50.04260 1.564914 49.98582
37.74700 49.94278 1.565772 50.06789
37.79700 49.84376 1.566459 50.04961
37.84700 49.74250 1.567152 49.83918
37.89700 49.64317 1.567820 50.01379
37.94700 49.54384 1.568652 50.04545
37.99700 49.44314 1.569471 50.02475
38.04700 49.34382 1.570214 49.97017
38.09700 49.24365 1.571089 50.15361
38.14700 49.14446 1.571883 49.84416
38.19700 49.04426 1.572731 50.03204
38.24700 48.94387 1.573592 49.87063
38.29700 48.84424 1.574212 49.94684
38.34700 48.74434 1.574784 50.12451
38.39700 48.64506 1.575162 49.87420
38.44700 48.54564 1.575704 50.02100
38.49700 48.44458 1.576344 49.99100
38.54700 48.34493 1.577346 49.86894
38.59700 48.24502 1.578302 50.05778
38.64700 48.14444 1.579271 49.97338
38.69700 48.04482 1.580262 50.01280
38.74700 47.94522 1.581101 49.89088
38.79700 47.84532 1.581929 50.06206
38.84700 47.74580 1.582628 49.95476
38.89700 47.64639 1.583107 49.95356
38.94700 47.54632 1.583686 49.98218
38.99700 47.44688 1.584284 49.89810
39.04700 47.34613 1.584876 49.80630
39.09700 47.24632 1.585453 49.99496
39.14700 47.14534 1.586055 50.06974
39.19700 47.04629 1.586732 50.13768
39.24700 46.94654 1.587281 50.02146
39.29700 46.84674 1.587912 50.14566
39.34700 46.74672 1.588408 49.95000
39.39700 46.64750 1.588782 50.12820
39.44700 46.54726 1.589395 50.04424
39.49700 46.44760 1.589897 50.03256
39.54700 46.34826 1.590538 49.99062
39.59700 46.24744 1.591004 50.00583
39.64700 46.14778 1.591515 50.02925
39.69700 46.04778 1.592143 50.04384
39.74700 45.94830 1.592975 49.77076
39.79700 45.84859 1.593656 50.04172
39.84700 45.74757 1.594528 49.94793
39.89700 45.64833 1.595420 49.96682
39.94700 45.54799 1.596392 50.03597
39.99700 45.44776 1.597273 49.89887
40.04700 45.34804 1.598129 50.00826
40.09700 45.24844 1.598823 49.87203
40.14700 45.14802 1.599485 49.96050
40.19700 45.04869 1.599924 50.02360
40.24700 44.94910 1.600409 49.89074
40.29700 44.84992 1.600845 49.96242
40.34700 44.74957 1.601315 50.07139
40.39700 44.65058 1.601706 50.03258
40.44700 44.54953 1.602053 49.86470
40.49700 44.45025 1.602403 49.98223
40.54700 44.35065 1.603046 50.04636
40.59700 44.25034 1.603361 49.99828
40.64700 44.15146 1.603991 50.02217
40.69700 44.05110 1.604539 50.15694
40.74700 43.95126 1.605118 49.88474
40.79700 43.85153 1.605702 50.12912
40.84700 43.75122 1.606373 49.88376
40.89700 43.65086 1.607187 49.98979
40.94700 43.55154 1.607694 50.13482
40.99700 43.45110 1.608413 50.15250
41.04700 43.35128 1.608803 50.07019
41.09700 43.25214 1.609382 49.99956
41.14700 43.15292 1.609887 50.12126
41.19700 43.05331 1.610274 49.98012
41.24700 42.95270 1.610835 49.95224
41.29700 42.85204 1.611336 50.06865
41.34700 42.75334 1.611671 49.87320
41.39700 42.65272 1.612100 50.07784
41.44700 42.55274 1.612540 49.91111
41.49700 42.45380 1.613148 49.92550
41.54700 42.35312 1.613824 49.99560
41.59700 42.25265 1.614508 49.89065
41.64700 42.15306 1.615054 50.04886
41.69700 42.05322 1.615696 49.96168
41.74700 41.95357 1.616177 49.99840
41.79700 41.85293 1.616745 50.01944
41.84700 41.75333 1.617087 50.16516
41.89700 41.65303 1.617503 50.08152
41.94700 41.55279 1.617918 49.97588
41.99700 41.45372 1.618144 50.09946
42.04700 41.35387 1.618436 49.95709
42.09700 41.25418 1.618629 49.96206
42.14700 41.15416 1.618759 49.98528
42.19700 41.05351 1.618944 50.09705
42.24700 40.95412 1.619034 50.00502
42.29700 40.85313 1.619178 49.97281
42.34700 40.75368 1.619218 50.05581
42.39700 40.65437 1.619273 50.00670
42.44700 40.55418 1.619362 50.10520
42.49700 40.45575 1.619596 49.97220
42.54700 40.35484 1.619768 49.88496
42.59700 40.25462 1.619908 49.96780
42.64700 40.15508 1.620163 50.00489
42.69700 40.05576 1.620416 50.06702
42.74700 39.95510 1.620685 49.84194
42.79700 39.85582 1.620976 49.96238
42.84700 39.75586 1.621424 49.89194
42.89700 39.65610 1.621740 49.99100
42.94700 39.55572 1.622294 50.05715
42.99700 39.45531 1.622647 49.95351
43.04700 39.35586 1.622967 50.12517
43.09700 39.25640 1.623356 49.92672
43.14700 39.15555 1.623654 50.09108
43.19700 39.05660 1.623905 49.95718
43.24700 38.95660 1.624296 50.00730
43.29700 38.85662 1.624556 49.93658
43.34700 38.75660 1.624884 50.12993
43.39700 38.65541 1.625294 50.20114
43.44700 38.55682 1.625846 50.05566
43.49700 38.45611 1.626492 50.01628
43.54700 38.35574 1.626866 50.06747
43.59700 38.25644 1.627211 49.97269
43.64700 38.15620 1.627502 49.91368
43.69700 38.05594 1.627739 49.99096
43.74700 37.95648 1.627874 50.11420
43.79700 37.85526 1.627996 49.89180
43.84700 37.75593 1.628016 50.02032
43.89700 37.65588 1.628184 49.90791
43.94700 37.55716 1.628071 49.86381
43.99700 37.45686 1.628072 50.04273
44.04700 37.35731 1.628142 50.02130
44.09700 37.25736 1.628157 50.13281
44.14700 37.15655 1.628190 49.91192
44.19700 37.05703 1.628034 50.05080
44.24700 36.95720 1.628115 49.79330
44.29700 36.85779 1.628026 49.91220
44.34700 36.75741 1.628208 50.03818
44.39700 36.65753 1.628317 50.04784
44.44700 36.55792 1.628454 50.10475
44.49700 36.45776 1.628576 49.99426
44.54700 36.35840 1.628948 49.92410
44.59700 36.25855 1.629550 50.09268
44.64700 36.15933 1.630399 49.94438
44.69700 36.05872 1.631874 49.93080
44.74700 35.96019 1.634157 50.06050
44.79700 35.86113 1.638060 50.16306
44.84700 35.76192 1.646010 50.07575
44.89700 35.66389 1.667741 50.04836
44.94700 35.56591 1.706146 49.85530
44.99700 35.46875 1.763528 50.04372
45.04700 35.37203 1.830807 49.96416
45.09700 35.27765 1.912926 49.93698
45.14700 35.18508 2.009960 49.97122
45.19700 35.09177 2.117122 50.00444
45.24700 34.99996 2.246490 49.89463
45.29700 34.91030 2.391436 49.98342
45.34700 34.82292 2.548640 49.80378
45.39700 34.73534 2.716787 49.90634
45.44700 34.64961 2.898489 50.07006
45.49700 34.56445 3.089898 50.16998
45.54700 34.48046 3.293828 49.91620
45.59700 34.39578 3.496525 49.99956
45.64700 34.31340 3.706361 50.06433
45.69700 34.23038 3.911557 50.07717
45.74700 34.14746 4.120976 50.07812
45.79700 34.06338 4.315665 50.14657
45.84700 33.97988 4.503048 50.09674
45.89700 33.89431 4.670996 50.01850
45.94700 33.80906 4.819467 49.89404
45.99700 33.72075 4.944553 50.06088
46.04700 33.63115 5.047293 49.98564
46.09700 33.53934 5.116164 49.91915
46.14700 33.44422 5.169200 49.98906
46.19700 33.34833 5.193284 50.01512
46.24700 33.25110 5.200489 50.14238
46.29700 33.15173 5.202266 49.98728
46.34700 33.05036 5.188450 49.99080
46.39700 32.94770 5.140016 50.05217
46.44700 32.84436 5.072572 50.00924
46.49700 32.73889 4.997310 50.00470
46.54700 32.63352 4.916106 50.05657
46.59700 32.52838 4.833950 49.98860
46.64700 32.42075 4.748547 49.87468
46.69700 32.31425 4.655456 50.06097
46.74700 32.20734 4.563342 50.02533
46.79700 32.10008 4.473520 49.87568
46.84700 31.99209 4.382832 50.15612
46.89700 31.88623 4.294503 50.02040
46.94700 31.77845 4.209729 50.13994
46.99700 31.67157 4.125522 50.11266
47.04700 31.56514 4.051274 49.97744
47.09700 31.45954 3.972105 50.01312
47.14700 31.35272 3.903603 49.97165
47.19700 31.24734 3.837015 49.81486
47.24700 31.14194 3.772790 50.00432
47.29700 31.03657 3.715009 50.01456
47.34700 30.93213 3.660854 49.86326
47.39700 30.82732 3.607595 49.80596
47.44700 30.72330 3.560766 50.07978
47.49700 30.61784 3.515652 50.05286
47.54700 30.51512 3.474292 49.89106
47.59700 30.41179 3.435946 50.02191
47.64700 30.30884 3.402510 50.02097
47.69700 30.20672 3.371736 50.04590
47.74700 30.10280 3.339417 49.93113
47.79700 30.00140 3.312245 49.93640
47.84700 29.89882 3.284665 49.85304
47.89700 29.79631 3.261558 49.86355
47.94700 29.69412 3.238484 49.98344
47.99700 29.59295 3.217471 49.88093
48.04700 29.49106 3.199045 49.95772
48.09700 29.38862 3.179104 50.20987
48.14700 29.28777 3.162212 50.20662
48.19700 29.18666 3.146582 50.08090
48.24700 29.08579 3.132461 49.94130
48.29700 28.98400 3.118109 50.02570
48.34700 28.88322 3.104206 49.95756
48.39700 28.78100 3.090885 50.05157
48.44700 28.68134 3.079273 49.93338
48.49700 28.57926 3.067395 50.00772
48.54700 28.47796 3.054422 49.86679
48.59700 28.37754 3.041459 49.87767
48.64700 28.27664 3.029732 50.08924
48.69700 28.17598 3.018460 49.84856
48.74700 28.07457 3.007926 50.08974
48.79700 27.97331 2.996564 50.05050
48.84700 27.87249 2.985213 49.90549
48.89700 27.77218 2.973815 50.11150
48.94700 27.67136 2.962090 49.85533
48.99700 27.56970 2.951258 49.99984
49.04700 27.46930 2.939978 50.04658
49.09700 27.36760 2.928471 49.99708
49.14700 27.26775 2.917006 50.08692
49.19700 27.16631 2.905214 50.00520
49.24700 27.06474 2.893350 49.90490
49.29700 26.96352 2.880578 50.01284
49.34700 26.86290 2.864472 50.07102
49.39700 26.76254 2.849185 49.96328
49.44700 26.66154 2.835103 49.99450
49.49700 26.55981 2.820466 50.00098
49.54700 26.45886 2.804356 49.82320
49.59700 26.35840 2.787700 50.00836
49.64700 26.25708 2.769816 50.05048
49.69700 26.15526 2.751260 49.86531
49.74700 26.05472 2.730621 49.96130
49.79700 25.95294 2.708817 50.05195
49.84700 25.85084 2.687416 50.20053
49.89700 25.75002 2.661886 50.02054
49.94700 25.64821 2.636402 49.98857
49.99700 25.54778 2.610302 50.07027
50.04700 25.44608 2.582654 50.05609
50.09700 25.34288 2.560458 50.13037
50.14700 25.24096 2.541018 50.07930
50.19700 25.14036 2.525860 49.91641
50.24700 25.03802 2.516459 50.19086
50.29700 24.93736 2.507516 50.09692
50.34700 24.83664 2.498905 49.87146
50.39700 24.73537 2.485807 49.94694
50.44700 24.63398 2.459606 50.06778
50.49700 24.53144 2.420434 49.84030
50.54700 24.42802 2.370239 50.02804
50.59700 24.32585 2.319349 49.99164
50.64700 24.22141 2.265829 49.99650
50.69700 24.11797 2.209530 49.91797
50.74700 24.01314 2.155407 49.92406
50.79700 23.90972 2.098983 50.00060
50.84700 23.80459 2.045550 50.01959
50.89700 23.70129 1.995785 50.06740
50.94700 23.59662 1.952008 50.10110
50.99700 23.49349 1.909892 50.02782
51.04700 23.38938 1.873488 50.11772
51.09700 23.28698 1.842557 50.17022
51.14700 23.18411 1.815766 49.97642
51.19700 23.08262 1.793944 50.02404
51.24700 22.98035 1.773748 50.12371
51.29700 22.87810 1.758672 50.04643
51.34700 22.77659 1.744815 49.86480
51.39700 22.67502 1.734269 50.07109
51.44700 22.57426 1.724988 49.90748
51.49700 22.47316 1.715586 49.82597
51.54700 22.37251 1.707091 50.04012
51.59700 22.27168 1.698598 49.87747
51.64700 22.17098 1.690581 50.01930
51.69700 22.06983 1.682905 50.04636
51.74700 21.96980 1.675858 49.95243
51.79700 21.86881 1.669341 49.81566
51.84700 21.76820 1.663320 50.03026
51.89700 21.66706 1.657926 50.00950
51.94700 21.56779 1.652828 49.96137
51.99700 21.46675 1.648179 49.92119
52.04700 21.36704 1.643875 49.89168
52.09700 21.26670 1.639984 50.07382
52.14700 21.16735 1.636285 50.04556
52.19700 21.06657 1.633011 49.85040
52.24700 20.96658 1.630206 50.05535
52.29700 20.86648 1.627437 50.13286
52.34700 20.76723 1.624708 50.12581
52.39700 20.66709 1.622380 50.06510
52.44700 20.56655 1.620002 50.15982
52.49700 20.46674 1.617899 50.17050
52.54700 20.36788 1.616042 49.89290
52.59700 20.26876 1.614432 49.91477
52.64700 20.16716 1.612878 50.07668
52.69700 20.06749 1.611374 49.97494
52.74700 19.96666 1.610354 50.16269
52.79700 19.86776 1.609335 49.93900
52.84700 19.76790 1.608523 50.03486
52.89700 19.66766 1.607692 50.10502
52.94700 19.56712 1.606992 49.92080
52.99700 19.46789 1.606287 50.10540
53.04700 19.36739 1.605489 50.01147
53.09700 19.26756 1.604958 50.00915
53.14700 19.16694 1.604339 50.14331
53.19700 19.06711 1.603651 49.97801
53.24700 18.96747 1.603202 50.03924
53.29700 18.86650 1.602732 50.00072
53.34700 18.76644 1.602053 49.95216
53.39700 18.66685 1.601428 50.10082
53.44700 18.56646 1.600718 50.01152
53.49700 18.46616 1.600151 49.93303
53.54700 18.36618 1.599391 49.77900
53.59700 18.26688 1.598632 50.10709
53.64700 18.16645 1.597962 49.97920
53.69700 18.06612 1.597541 49.98264
53.74700 17.96641 1.596742 50.02207
53.79700 17.86658 1.596127 49.92879
53.84700 17.76668 1.595324 50.12324
53.89700 17.66716 1.594668 50.18741
53.94700 17.56663 1.593921 50.00053
53.99700 17.46722 1.593446 49.90122
54.04700 17.36726 1.592775 49.99278
54.09700 17.26772 1.592146 49.82060
54.14700 17.16709 1.591599 50.13296
54.19700 17.06659 1.591058 49.99464
54.24700 16.96759 1.590510 49.89429
54.29700 16.86724 1.589897 50.12286
54.34700 16.76715 1.589358 49.98504
54.39700 16.66811 1.588963 50.06253
54.44700 16.56663 1.588767 49.97194
54.49700 16.46694 1.588537 50.07746
54.54700 16.36664 1.588256 49.99560
54.59700 16.26682 1.587871 50.03520
54.64700 16.16767 1.587731 50.04581
54.69700 16.06705 1.587483 50.04302
54.74700 15.96622 1.587337 50.02590
54.79700 15.86755 1.587196 49.85932
54.84700 15.76676 1.586799 49.89554
54.89700 15.66608 1.586644 50.06648
54.94700 15.56598 1.586161 50.10206
54.99700 15.46686 1.585755 50.02902
55.04700 15.36693 1.585276 49.93574
55.09700 15.26735 1.584967 49.95926
55.14700 15.16719 1.584406 49.83435
55.19700 15.06834 1.583998 49.98916
55.24700 14.96766 1.583473 49.95470
55.29700 14.86644 1.583107 50.01914
55.34700 14.76803 1.582554 50.02014
55.39700 14.66739 1.582133 49.94898
55.44700 14.56781 1.581776 49.98578
55.49700 14.46852 1.581334 50.04058
55.54700 14.36807 1.580870 50.02037
55.59700 14.26769 1.580615 49.81304
55.64700 14.16785 1.580425 50.06660
55.69700 14.06844 1.580124 49.99540
55.74700 13.96781 1.579835 49.98646
55.79700 13.86744 1.579601 49.99660
55.84700 13.76724 1.579411 50.20630
55.89700 13.66813 1.579077 49.80287
55.94700 13.56788 1.578754 49.85989
55.99700 13.46849 1.578656 49.98694
56.04700 13.36802 1.578325 50.02665
56.09700 13.26876 1.577950 50.12040
56.14700 13.16798 1.577726 49.83714
56.19700 13.06930 1.577451 50.03202
56.24700 12.96824 1.577202 50.15257
56.29700 12.86898 1.576875 49.98552
56.34700 12.76873 1.576583 50.05433
56.39700 12.66907 1.576359 49.91718
56.44700 12.56810 1.576068 50.06624
56.49700 12.46880 1.575644 50.00392
56.54700 12.36838 1.575345 50.01453
56.59700 12.26850 1.575091 50.02280
56.64700 12.16862 1.574592 50.04872
56.69700 12.06890 1.574178 50.20188
56.74700 11.96908 1.573775 50.10074
56.79700 11.86920 1.573266 50.13774
56.84700 11.76868 1.572920 49.90165
56.89700 11.66905 1.572669 50.03984
56.94700 11.56899 1.572291 50.04370
56.99700 11.46971 1.572096 50.06006
57.04700 11.36965 1.571826 50.13202
57.09700 11.26892 1.571681 50.05420
57.14700 11.16932 1.571344 49.78087
57.19700 11.06916 1.571206 49.83260
57.24700 10.96940 1.570910 49.97320
57.29700 10.86943 1.570568 50.09040
57.34700 10.76919 1.570189 50.01204
57.39700 10.67041 1.569736 50.06269
57.44700 10.57046 1.569275 49.82774
57.49700 10.47082 1.568901 50.02796
57.54700 10.37009 1.568738 49.99641
57.59700 10.27009 1.568572 50.00758
57.64700 10.17054 1.568717 50.04844
57.69700 10.07007 1.568664 50.12246
57.74700 9.969728 1.568835 50.04697
57.79700 9.869337 1.568948 50.01719
57.84700 9.769049 1.568868 49.92087
57.89700 9.668938 1.568878 50.05444
57.94700 9.569220 1.568752 49.89722
57.99700 9.469819 1.568718 49.91244
58.04700 9.369845 1.568503 50.03226
58.09700 9.269034 1.568169 50.02010
58.14700 9.169056 1.567727 49.93152
58.19700 9.070038 1.567244 50.09684
58.24700 8.969856 1.566859 49.93012
58.29700 8.868680 1.566349 50.25760
58.34700 8.769149 1.566007 49.94020
58.39700 8.669434 1.565502 50.09963
58.44700 8.568722 1.565166 50.15662
58.49700 8.469222 1.564838 50.14054
58.54700 8.369484 1.564410 50.09316
58.59700 8.269278 1.564041 49.81296
58.64700 8.170562 1.563586 49.92450
58.69700 8.069366 1.563098 49.85200
58.74700 7.970437 1.562728 49.95460
58.79700 7.869500 1.562394 50.12766
58.84700 7.769960 1.562000 49.88938
58.89700 7.670281 1.561867 50.15184
58.94700 7.569990 1.561714 49.98719
58.99700 7.469626 1.561422 50.13324
59.04700 7.370368 1.561264 49.98656
59.09700 7.269680 1.561067 49.89084
59.14700 7.170113 1.560818 50.12760
59.19700 7.069685 1.560558 50.09782
59.24700 6.970474 1.560289 49.95500
59.29700 6.870824 1.559996 49.95656
59.34700 6.770225 1.559565 50.10388
59.39700 6.670297 1.559227 50.11856
59.44700 6.570388 1.558860 50.04628
59.49700 6.470780 1.558712 50.04470
59.54700 6.370894 1.558372 49.89214
59.59700 6.270862 1.558190 50.06856
59.64700 6.171188 1.557876 50.07500
59.69700 6.071274 1.557666 50.07885
59.74700 5.970148 1.557509 50.03985
59.79700 5.871771 1.557247 50.17284
59.84700 5.770706 1.557016 50.05723
59.89700 5.670574 1.556953 49.96033
59.94700 5.571421 1.556783 50.08176
59.99700 5.471122 1.556561 49.98586
60.04700 5.371365 1.556598 49.90541
60.09700 5.271372 1.556668 49.93600
60.14700 5.170424 1.556348 49.88858
60.19700 5.071022 1.556193 50.02350
60.24700 4.970730 1.556009 50.13354
60.29700 4.871674 1.555939 49.98371
60.34700 4.771546 1.555762 49.97134
60.39700 4.670734 1.555546 50.03100
60.44700 4.570946 1.555313 49.91544
60.49700 4.470711 1.555166 49.97414
60.54700 4.372082 1.554991 49.92324
60.59700 4.271638 1.554796 50.03764
60.64700 4.171448 1.554701 50.03741
60.69700 4.071512 1.554713 50.05289
60.74700 3.971328 1.554690 49.97122
60.79700 3.871264 1.554550 50.13281
60.84700 3.771704 1.554389 50.11717
60.89700 3.671703 1.554084 49.90374
60.94700 3.570961 1.553828 49.92346
60.99700 3.471772 1.553549 49.92469
61.04700 3.371333 1.553247 50.06690
61.09700 3.272074 1.552968 49.95462
61.14700 3.171830 1.552586 50.10104
61.19700 3.071482 1.552292 49.98711
61.24700 2.971447 1.551925 50.05820
61.29700 2.872194 1.551486 49.94687
61.34700 2.772360 1.551294 49.90296
61.39700 2.671930 1.550813 49.92664
61.44700 2.572281 1.550551 50.03762
61.49700 2.472520 1.550415 49.80831
61.54700 2.373128 1.550151 49.86922
61.59700 2.272603 1.549948 50.06434
61.64700 2.172652 1.549905 50.05936
61.69700 2.072776 1.549730 50.08617
61.74700 1.972944 1.549448 49.97879
61.79700 1.871830 1.549283 50.00010
61.84700 1.772707 1.549256 50.06403
61.89700 1.671610 1.548933 50.03948
61.94700 1.573072 1.548685 50.09556
61.99700 1.472799 1.548322 49.88110
62.04700 1.375155 1.548526 49.85422
62.09700 1.301646 1.519845 50.05133
62.14700 1.251915 1.398384 50.05793
62.19700 1.212593 1.277263 50.14350
62.24700 1.182309 1.154138 50.04414
62.29700 1.155728 1.038573 49.93636
62.34700 1.133588 0.9260934 50.03000
62.39700 1.114630 0.8254374 49.90660
62.44700 1.099134 0.7355190 49.99874
62.49700 1.085451 0.6575437 49.87003
62.54700 1.073989 0.5864756 50.04694
62.59700 1.065017 0.5285628 50.09858
62.64700 1.056438 0.4743769 49.92188
62.69700 1.049805 0.4308536 50.24228
62.74700 1.043681 0.3932816 49.81964
62.79700 1.038590 0.3614270 49.87717
62.84700 1.033750 0.3356622 49.96374
62.89700 1.029802 0.3144916 50.00836
62.94700 1.026653 0.2933824 50.09332
62.99700 1.022846 0.2799063 49.96013
63.04700 1.021436 0.2686902 50.07786
63.09700 1.017614 0.2579556 49.96734
63.14700 1.015859 0.2490930 50.10172
63.19700 1.014492 0.2412016 50.02058
63.24700 1.011925 0.2330928 49.93277
63.29700 1.010384 0.2252826 49.88891
63.34700 1.010008 0.2175606 49.99758
63.39700 1.008458 0.2101672 49.99761
63.44700 1.007605 0.2033072 50.01511
63.49700 1.005944 0.1968755 49.98434
63.54700 1.005047 0.1907688 50.12250
63.59700 1.004821 0.1852281 50.11710
63.64700 1.004064 0.1801136 49.91980
63.69700 1.003912 0.1756512 50.05334
63.74700 1.003642 0.1713985 50.08887
63.79700 1.002086 0.1676817 49.95130
63.84700 1.003621 0.1641355 50.17652
63.89700 1.002428 0.1611859 50.02713
63.94700 1.001225 0.1583756 49.94660
63.99700 1.001746 0.1559551 49.89674
64.04700 1.000628 0.1538636 49.88652
64.09700 0.9997250 0.1518772 49.94039
64.14700 1.000246 0.1501651 49.86234
64.19701 0.9998047 0.1488345 50.17974
64.24700 0.9992905 0.1475668 50.03192
64.29700 0.9989422 0.1463693 49.98482
64.34700 0.9986538 0.1454030 49.85794
64.39700 0.9984671 0.1442323 49.82130
64.44701 0.9985953 0.1432760 50.14732
64.49700 0.9980995 0.1423544 49.88366
64.54700 0.9984603 0.1414319 49.93481
64.59700 0.9978942 0.1406291 49.81650
64.64700 0.9978550 0.1399748 49.98892
64.69701 0.9976086 0.1391798 49.85760
64.74700 0.9964288 0.1386527 49.98382
64.79700 0.9970244 0.1380276 50.08848
-2.000000 2.000000 0.0000000 0.0000000