File: imagens/notebooks/dados experimentais/dsc/Karl_CTAB200 Ur 45%.txt
CLOSED
Version	1.0
Language	English
Run	1
RunSerial	151
Instrument	DSC Q100 V9.9 Build 303
Module	DSC Standard Cell FC
Operator	LL
File	\\Niger\ta\Data\DSC\2018\Geral\Karl_CTAB200 Ur 45%.001
ProcName	Karl
InstSerial	0100-1211
Sample	CTAB200 Ur 45%
Size	9.88000	mg
Method	Karl
Comment
Xcomment	Pan: Aluminum Hermetic
Xcomment	Gas1: Nitrogen 50.0 ml/min
Xcomment	Gas2: Nitrogen 0.0 ml/min
Text
Exotherm	UP
Kcell	1.09030
Calib	-11.7822
TempCal	1	pts	158.71	156.60
TzeroDt	-90.0515 -0.0093 2.2263
TzeroDtz	-90.0515 0.0466 2.4421
InstCalFile	Tzero: \\Niger\ta\Data\DSC\CALIBRATION\20122016\CALIBRATION\0_RCS_12_20_2016 17_23_31.TZR
InstCalFile	Baseline: \\Niger\ta\Data\DSC\CALIBRATION\20122016\L.Base 20122016
InstCalFile	Sapphire: \\Niger\ta\Data\DSC\CALIBRATION\20122016\Safira 20122017.001
InstCalDate	Tzero 2016-12-20 Time 19:23:31
TempRange	-90.04 to 395.23 °C at 19.96 °C/min Heat Only
AutoZero	Delta T Offset 0.000 uV
AutoZero	Delta T0 Offset 0.000 uV
Controls	Gas 1  Event Off  Sampling 0.2
Cell#	FC-02451
CoolingUnit	RCS
SelHeatFlow	Heat Flow T4 (mW)
AutoAnalysis	Off
MacroFile
Nsig	4
Sig1	Time (min)
Sig2	Temperature (°C)
Sig3	Heat Flow (mW)
Sig4	Sample Purge Flow (mL/min)
Date	2018-05-17
Time	09:33:58
OrgMethod	1: Equilibrate at 1.00 °C
OrgMethod	2: Ramp 2.00 °C/min to 60.00 °C
OrgMethod	3: Isothermal for 3.00 min
OrgMethod	4: Mark end of cycle 1
OrgMethod	5: Ramp 2.00 °C/min to 1.00 °C
OrgMethod	6: Isothermal for 3.00 min
OrgMethod	7: Mark end of cycle 2
OrgFile	C:\TA\Data\DSC\2018\Geral\Karl_CTAB200 Ur 45%.001
3.33324E-4 1.144582 0.6946143 50.02687
0.05033332 1.134393 0.6251908 49.81303
0.1003333 1.151247 0.4837262 49.95928
0.1503333 1.193248 0.3187042 50.13380
0.2003333 1.246082 0.1617942 49.79184
0.2503333 1.307149 0.01971944 49.91976
0.3003333 1.374612 -0.1121782 49.96460
0.3503333 1.447302 -0.2294080 50.02167
0.4003334 1.523529 -0.3331206 50.04031
0.4503334 1.605047 -0.4217686 50.06486
0.5003334 1.686877 -0.4972724 50.01309
0.5503332 1.773210 -0.5604008 49.82880
0.6003332 1.860166 -0.6159558 49.99933
0.6503332 1.949656 -0.6629981 50.03198
0.7003332 2.039807 -0.7031640 49.97506
0.7503332 2.132048 -0.7365341 50.07168
0.8003332 2.223804 -0.7647382 50.09430
0.8503332 2.316740 -0.7889514 50.07205
0.9003332 2.411749 -0.8086757 50.06900
0.9503334 2.505600 -0.8254879 50.05789
1.000333 2.601464 -0.8387020 50.04366
1.050334 2.696323 -0.8508136 50.02602
1.100334 2.792270 -0.8611100 49.88803
1.150334 2.888787 -0.8718445 50.07217
1.200334 2.986137 -0.8808666 49.99770
1.250334 3.082650 -0.8897718 50.06154
1.300334 3.180136 -0.8981544 50.00557
1.350333 3.277149 -0.9063111 49.81692
1.400333 3.375453 -0.9141732 49.94348
1.450334 3.473203 -0.9215641 50.07797
1.500333 3.571381 -0.9286444 50.05484
1.550334 3.669160 -0.9352444 49.97778
1.600334 3.767225 -0.9415844 50.07951
1.650333 3.865958 -0.9474234 49.92848
1.700334 3.964226 -0.9530186 50.05906
1.750334 4.062960 -0.9582508 50.07732
1.800334 4.161632 -0.9631546 49.98976
1.850334 4.259693 -0.9678689 49.97559
1.900334 4.357547 -0.9722053 50.01844
1.950334 4.456874 -0.9759411 49.88774
2.000334 4.555678 -0.9794218 49.97816
2.050333 4.653628 -0.9826178 50.06516
2.100334 4.752787 -0.9855216 50.10217
2.150334 4.852496 -0.9881531 50.06744
2.200334 4.950131 -0.9907826 49.91408
2.250334 5.049942 -0.9931809 49.92563
2.300333 5.148414 -0.9955855 50.03809
2.350334 5.247944 -0.9977759 50.16043
2.400334 5.346650 -0.9998053 49.88770
2.450334 5.445800 -1.001816 49.96344
2.500334 5.544728 -1.003803 50.03863
2.550333 5.644409 -1.005920 50.05646
2.600333 5.744007 -1.008034 49.90240
2.650333 5.844151 -1.009933 50.05984
2.700333 5.942896 -1.011956 50.06416
2.750333 6.041750 -1.013655 49.99976
2.800333 6.141410 -1.015285 50.13041
2.850333 6.240550 -1.016993 49.96516
2.900333 6.340438 -1.018629 49.98641
2.950333 6.439491 -1.020110 50.03020
3.000333 6.538898 -1.021519 50.10629
3.050333 6.637671 -1.022721 50.04377
3.100333 6.737466 -1.023999 49.93642
3.150333 6.837622 -1.025222 50.08156
3.200333 6.937324 -1.026397 49.95270
3.250333 7.036626 -1.027497 50.01138
3.300333 7.136284 -1.028780 50.06555
3.350333 7.235412 -1.029927 49.92415
3.400333 7.335538 -1.031266 50.16109
3.450333 7.434070 -1.032406 50.06776
3.500333 7.534463 -1.033466 50.08480
3.550333 7.633145 -1.034583 50.04248
3.600333 7.734572 -1.035497 50.12188
3.650333 7.833680 -1.036507 50.12714
3.700333 7.934290 -1.037460 50.10014
3.750333 8.031784 -1.038446 50.11252
3.800333 8.132461 -1.039292 50.06012
3.850333 8.232797 -1.040334 50.00914
3.900333 8.332246 -1.041239 49.87120
3.950333 8.432258 -1.042083 50.03720
4.000333 8.531158 -1.042972 50.01048
4.050333 8.632141 -1.043825 49.98928
4.100333 8.730824 -1.044637 50.10926
4.150333 8.831082 -1.045526 49.88592
4.200333 8.930236 -1.046456 50.00219
4.250333 9.029804 -1.047157 50.13352
4.300333 9.129790 -1.048000 50.10842
4.350333 9.229709 -1.048954 50.05000
4.400333 9.330222 -1.049634 49.93634
4.450333 9.429086 -1.050302 50.09478
4.500333 9.529559 -1.051000 49.98698
4.550333 9.629212 -1.051705 50.11989
4.600333 9.729379 -1.052302 50.13687
4.650333 9.828574 -1.052799 49.45138
4.700333 9.928231 -1.053414 49.83013
4.750333 10.02724 -1.053879 50.05090
4.800333 10.12754 -1.054468 49.96356
4.850333 10.22740 -1.055176 49.84650
4.900333 10.32810 -1.055730 50.13100
4.950333 10.42723 -1.056306 50.16872
5.000333 10.52704 -1.056847 49.96410
5.050333 10.62595 -1.057313 49.93466
5.100333 10.72683 -1.057953 50.17116
5.150333 10.82565 -1.058599 50.17400
5.200333 10.92558 -1.059227 49.94772
5.250332 11.02490 -1.060027 49.77768
5.300332 11.12504 -1.060612 49.96240
5.350332 11.22562 -1.061241 50.07566
5.400332 11.32540 -1.061744 49.88074
5.450332 11.42444 -1.062369 50.00736
5.500332 11.52458 -1.062874 50.14605
5.550332 11.62444 -1.063568 50.03891
5.600332 11.72406 -1.064205 49.87817
5.650332 11.82388 -1.064782 50.02370
5.700332 11.92412 -1.065427 50.01627
5.750332 12.02465 -1.066028 50.04239
5.800332 12.12385 -1.066667 50.07281
5.850332 12.22434 -1.067264 50.06572
5.900332 12.32361 -1.067925 50.06136
5.950332 12.42341 -1.068581 49.93404
6.000332 12.52356 -1.069317 49.92910
6.050332 12.62286 -1.069890 50.06472
6.100332 12.72342 -1.070402 49.93566
6.150332 12.82353 -1.070963 49.88821
6.200332 12.92332 -1.071457 49.84519
6.250332 13.02283 -1.071853 49.83237
6.300332 13.12262 -1.072439 50.01416
6.350332 13.22255 -1.073106 49.92628
6.400332 13.32158 -1.073715 50.04640
6.450332 13.42220 -1.074251 49.97648
6.500332 13.52170 -1.074798 50.20860
6.550332 13.62222 -1.075375 49.90102
6.600332 13.72066 -1.076013 49.97161
6.650332 13.82219 -1.076439 49.95273
6.700332 13.92197 -1.076980 49.96539
6.750332 14.02201 -1.077571 49.85878
6.800332 14.12114 -1.078092 49.94860
6.850332 14.22109 -1.078617 50.02414
6.900332 14.32108 -1.079279 50.12242
6.950332 14.42160 -1.079940 50.05108
7.000332 14.52156 -1.080661 50.11930
7.050332 14.62091 -1.081360 50.04484
7.100332 14.72186 -1.081944 49.97872
7.150332 14.82250 -1.082602 50.01137
7.200332 14.92072 -1.083288 49.93838
7.250332 15.02203 -1.083948 50.04134
7.300332 15.12064 -1.084674 50.05921
7.350332 15.22224 -1.085181 49.98910
7.400332 15.32084 -1.085745 50.02246
7.450332 15.42186 -1.086165 49.96195
7.500332 15.52062 -1.086572 49.98868
7.550332 15.62052 -1.086779 50.14371
7.600332 15.72079 -1.086902 50.05724
7.650332 15.82002 -1.086974 49.94522
7.700332 15.92016 -1.087216 50.14290
7.750332 16.01981 -1.087378 49.94788
7.800332 16.12074 -1.087491 50.01898
7.850332 16.21833 -1.087704 50.20298
7.900332 16.31996 -1.088198 49.95769
7.950332 16.41957 -1.088541 49.77197
8.000334 16.51926 -1.088885 50.08387
8.050332 16.61828 -1.089234 49.85402
8.100332 16.71866 -1.089717 49.93560
8.150332 16.81832 -1.090123 49.81824
8.200332 16.91915 -1.090601 50.08404
8.250334 17.01848 -1.090884 50.04998
8.300332 17.11827 -1.091285 50.07321
8.350332 17.21826 -1.091668 49.88934
8.400332 17.31876 -1.091932 50.01292
8.450332 17.41771 -1.092345 50.15188
8.500334 17.51801 -1.092580 49.98492
8.550332 17.61729 -1.092912 50.09075
8.600332 17.71716 -1.093363 49.88254
8.650332 17.81682 -1.093858 49.96190
8.700332 17.91760 -1.094356 50.18138
8.750334 18.01741 -1.095038 49.84512
8.800332 18.11716 -1.095516 50.03556
8.850332 18.21682 -1.096139 50.00660
8.900332 18.31666 -1.096722 50.04444
8.950332 18.41670 -1.097160 49.93871
9.000334 18.51680 -1.097603 49.93239
9.050332 18.61684 -1.097988 49.85000
9.100332 18.71697 -1.098362 49.92940
9.150332 18.81636 -1.098822 49.88064
9.200332 18.91656 -1.099111 50.05362
9.250334 19.01601 -1.099478 49.95298
9.300332 19.11722 -1.099938 50.19180
9.350332 19.21682 -1.100216 49.80092
9.400332 19.31601 -1.100704 50.09534
9.450332 19.41628 -1.101146 50.29428
9.500334 19.51570 -1.101547 50.00522
9.550332 19.61623 -1.101913 50.09272
9.600332 19.71584 -1.102480 49.83298
9.650332 19.81692 -1.102790 50.00222
9.700332 19.91526 -1.103319 49.90302
9.750334 20.01617 -1.103688 49.99386
9.800332 20.11654 -1.104130 49.94940
9.850332 20.21589 -1.104705 49.97085
9.900332 20.31578 -1.105145 50.06767
9.950332 20.41534 -1.105610 50.10535
10.00033 20.51599 -1.106006 49.96812
10.05033 20.61548 -1.106420 50.11061
10.10033 20.71561 -1.106862 49.90234
10.15033 20.81561 -1.107304 49.97220
10.20033 20.91495 -1.107786 50.03799
10.25033 21.01525 -1.108086 49.95154
10.30033 21.11520 -1.108623 50.02822
10.35033 21.21604 -1.109047 49.96396
10.40033 21.31503 -1.109533 50.14576
10.45033 21.41493 -1.109944 50.01328
10.50034 21.51510 -1.110294 49.93036
10.55033 21.61450 -1.110688 50.10498
10.60033 21.71465 -1.111114 49.96170
10.65033 21.81499 -1.111632 49.98855
10.70033 21.91492 -1.112151 49.93906
10.75034 22.01501 -1.112752 49.91068
10.80033 22.11480 -1.113242 49.82970
10.85033 22.21414 -1.113749 50.06317
10.90033 22.31392 -1.114345 49.93050
10.95033 22.41488 -1.114984 50.00070
11.00034 22.51392 -1.115429 49.95361
11.05033 22.61321 -1.116097 50.04678
11.10033 22.71362 -1.116646 50.11672
11.15033 22.81445 -1.117213 50.04031
11.20033 22.91403 -1.117932 49.98676
11.25034 23.01350 -1.118392 50.10959
11.30033 23.11413 -1.118909 49.90266
11.35033 23.21371 -1.119451 49.88284
11.40033 23.31296 -1.119964 49.97647
11.45033 23.41345 -1.120660 50.16762
11.50034 23.51279 -1.121225 49.88572
11.55033 23.61346 -1.121974 50.02914
11.60033 23.71340 -1.122865 49.92683
11.65033 23.81369 -1.123605 50.02566
11.70033 23.91371 -1.124305 50.07500
11.75034 24.01402 -1.125245 49.92862
11.80033 24.11379 -1.125904 50.19384
11.85033 24.21422 -1.126756 49.87254
11.90033 24.31335 -1.127469 50.07006
11.95033 24.41360 -1.128065 50.02372
12.00034 24.51294 -1.128416 50.04210
12.05033 24.61248 -1.128847 50.01676
12.10033 24.71288 -1.129031 49.95626
12.15033 24.81286 -1.129346 49.89518
12.20033 24.91230 -1.129833 49.95636
12.25034 25.01164 -1.130242 50.20372
12.30033 25.11202 -1.130629 50.14549
12.35033 25.21161 -1.131139 49.91548
12.40033 25.31208 -1.131693 50.05530
12.45033 25.41184 -1.132328 50.01176
12.50034 25.51081 -1.132829 49.86476
12.55033 25.61150 -1.133548 49.97388
12.60033 25.71146 -1.134360 50.07966
12.65033 25.81143 -1.135210 50.13303
12.70033 25.91175 -1.136143 50.03672
12.75034 26.01188 -1.136844 49.85610
12.80033 26.11105 -1.137714 49.95330
12.85033 26.21089 -1.138598 50.01329
12.90033 26.31096 -1.139312 49.84543
12.95034 26.41039 -1.140264 49.95332
13.00034 26.51025 -1.141103 49.93384
13.05033 26.61021 -1.141865 49.97076
13.10033 26.71046 -1.142665 50.11078
13.15033 26.81099 -1.143544 50.12569
13.20034 26.91037 -1.144264 49.96236
13.25034 27.01080 -1.144977 49.80086
13.30033 27.11046 -1.145752 49.97408
13.35033 27.20956 -1.146443 50.05039
13.40033 27.30980 -1.147206 49.89730
13.45034 27.40982 -1.147798 50.11885
13.50034 27.51014 -1.148523 50.01000
13.55033 27.60839 -1.149168 49.90547
13.60033 27.70894 -1.149979 50.03328
13.65033 27.80865 -1.150713 49.96002
13.70034 27.90925 -1.151602 50.10104
13.75034 28.00880 -1.152436 49.81394
13.80033 28.10860 -1.153382 50.08838
13.85033 28.20852 -1.154278 49.86306
13.90033 28.30896 -1.155341 49.92722
13.95034 28.40900 -1.156533 50.04678
14.00034 28.50837 -1.157659 50.02084
14.05033 28.60822 -1.158687 49.93500
14.10033 28.70760 -1.159864 50.03068
14.15033 28.80810 -1.160840 50.10746
14.20034 28.90710 -1.162079 50.12250
14.25034 29.00822 -1.163418 49.92615
14.30033 29.10698 -1.164766 50.02120
14.35033 29.20792 -1.166167 49.97795
14.40033 29.30686 -1.167702 50.13088
14.45034 29.40672 -1.169416 49.99152
14.50034 29.50662 -1.171443 50.13128
14.55033 29.60650 -1.173693 49.97511
14.60033 29.70691 -1.175947 49.88668
14.65033 29.80645 -1.178922 49.94642
14.70034 29.90555 -1.182250 49.96860
14.75034 30.00400 -1.186443 49.96946
14.80033 30.10355 -1.191478 49.93728
14.85033 30.20334 -1.196964 49.92688
14.90033 30.30182 -1.203772 49.99158
14.95034 30.40178 -1.211140 50.16413
15.00034 30.50159 -1.221757 49.89556
15.05033 30.59940 -1.233174 49.94534
15.10033 30.69766 -1.246857 49.85796
15.15033 30.79609 -1.269763 50.05594
15.20034 30.89436 -1.295652 50.10382
15.25034 30.99228 -1.324475 49.87804
15.30033 31.09036 -1.360673 50.08572
15.35033 31.18759 -1.396991 49.97832
15.40033 31.28578 -1.432716 49.99156
15.45034 31.38210 -1.469664 50.09753
15.50034 31.47870 -1.508095 50.01220
15.55033 31.57628 -1.547703 49.92040
15.60033 31.67330 -1.583536 49.94108
15.65033 31.77068 -1.622010 50.08780
15.70034 31.86624 -1.656986 49.93522
15.75034 31.96522 -1.692691 50.11558
15.80033 32.06173 -1.728298 50.04298
15.85033 32.15924 -1.757921 49.97436
15.90033 32.25606 -1.789187 49.87778
15.95034 32.35419 -1.817531 49.93254
16.00033 32.45228 -1.845249 50.03387
16.05033 32.54968 -1.870834 50.06582
16.10033 32.64717 -1.896068 49.89228
16.15033 32.74452 -1.918512 50.13049
16.20033 32.84207 -1.939220 49.87781
16.25033 32.94138 -1.960157 50.15702
16.30033 33.03841 -1.979534 50.03430
16.35033 33.13758 -1.995415 49.95380
16.40033 33.23612 -2.008774 50.15248
16.45033 33.33403 -2.022923 49.95684
16.50033 33.43265 -2.037820 50.05640
16.55033 33.53215 -2.051984 50.03234
16.60033 33.62986 -2.063027 49.95421
16.65033 33.72925 -2.074189 49.91460
16.70033 33.82878 -2.083914 49.98226
16.75033 33.92700 -2.095089 50.07425
16.80033 34.02620 -2.104858 49.81156
16.85033 34.12622 -2.114509 50.14852
16.90033 34.22551 -2.123824 49.87616
16.95033 34.32410 -2.132768 49.91347
17.00033 34.42374 -2.141042 50.21044
17.05033 34.52400 -2.149022 49.87247
17.10033 34.62344 -2.156337 49.83661
17.15033 34.72273 -2.163160 49.95036
17.20033 34.82269 -2.169456 50.03860
17.25033 34.92255 -2.175167 50.04389
17.30033 35.02194 -2.180520 49.94450
17.35033 35.12175 -2.185155 50.14981
17.40033 35.22229 -2.189258 49.89548
17.45033 35.32174 -2.192710 49.93707
17.50033 35.42169 -2.195584 50.20988
17.55033 35.52145 -2.198308 50.00365
17.60033 35.62172 -2.200622 49.94667
17.65033 35.72164 -2.202586 50.01902
17.70033 35.82063 -2.204611 50.17720
17.75033 35.92078 -2.206972 50.11340
17.80033 36.02112 -2.209861 49.97438
17.85033 36.12082 -2.213470 49.98547
17.90033 36.22024 -2.218082 49.83464
17.95033 36.31885 -2.223704 50.21418
18.00033 36.41775 -2.230437 50.05450
18.05033 36.51700 -2.238370 49.86133
18.10033 36.61534 -2.247437 50.03746
18.15033 36.71496 -2.257832 50.00568
18.20033 36.81324 -2.269236 49.86939
18.25033 36.91228 -2.279963 50.07808
18.30033 37.01028 -2.292152 50.10204
18.35033 37.10958 -2.306688 50.05797
18.40033 37.20868 -2.319416 50.02286
18.45033 37.30725 -2.331075 49.81730
18.50033 37.40741 -2.344028 50.00594
18.55033 37.50540 -2.356414 49.83980
18.60033 37.60461 -2.367197 49.94803
18.65033 37.70366 -2.377726 49.94216
18.70033 37.80300 -2.389156 50.01864
18.75033 37.90166 -2.399397 50.02474
18.80033 38.00162 -2.409575 49.94650
18.85033 38.10000 -2.419514 49.95402
18.90033 38.19958 -2.429014 49.90395
18.95033 38.29952 -2.438058 50.00627
19.00033 38.39792 -2.446994 50.14196
19.05033 38.49814 -2.455692 50.09130
19.10033 38.59753 -2.463863 49.87852
19.15033 38.69646 -2.471777 49.98303
19.20033 38.79583 -2.479236 50.10664
19.25033 38.89473 -2.486442 49.95441
19.30033 38.99420 -2.493354 50.04364
19.35033 39.09446 -2.499900 49.97359
19.40033 39.19390 -2.506441 49.96529
19.45033 39.29344 -2.512820 50.10480
19.50033 39.39280 -2.519002 49.92554
19.55033 39.49200 -2.525058 50.12566
19.60033 39.59165 -2.531052 50.06104
19.65033 39.69201 -2.536955 50.04944
19.70033 39.79038 -2.542666 50.04633
19.75033 39.88989 -2.548224 50.01069
19.80033 39.99046 -2.553590 49.91785
19.85033 40.08945 -2.559038 50.06560
19.90033 40.18918 -2.564330 50.17387
19.95033 40.28760 -2.569397 50.00652
20.00033 40.38735 -2.574320 50.13228
20.05033 40.48749 -2.579425 49.84447
20.10033 40.58679 -2.584484 50.00588
20.15033 40.68670 -2.589780 50.01239
20.20033 40.78628 -2.595354 49.90222
20.25033 40.88455 -2.600856 50.10800
20.30033 40.98400 -2.606321 49.88176
20.35033 41.08464 -2.611315 49.93668
20.40033 41.18439 -2.615990 49.95489
20.45033 41.28384 -2.620277 49.99804
20.50033 41.38375 -2.624180 49.94486
20.55033 41.48370 -2.627592 50.02190
20.60033 41.58354 -2.630012 49.93601
20.65033 41.68444 -2.631220 50.19597
20.70033 41.78500 -2.630078 49.92750
20.75033 41.88494 -2.624024 50.11862
20.80033 41.98722 -2.605198 49.80500
20.85033 42.08931 -2.561670 50.02613
20.90033 42.19338 -2.504599 49.93160
20.95033 42.29657 -2.432452 50.03582
21.00033 42.40287 -2.353294 49.99175
21.05033 42.50850 -2.260837 49.90638
21.10033 42.61540 -2.165825 50.17844
21.15033 42.72315 -2.065977 50.13653
21.20033 42.83146 -1.966459 49.95404
21.25033 42.93866 -1.868002 49.92233
21.30033 43.04660 -1.783093 49.96518
21.35033 43.15210 -1.709155 50.12674
21.40033 43.25833 -1.649615 49.93619
21.45033 43.36334 -1.596482 50.07904
21.50033 43.46720 -1.552408 50.00028
21.55033 43.57163 -1.515108 49.99975
21.60033 43.67362 -1.483929 50.09047
21.65033 43.77636 -1.460168 49.93596
21.70033 43.87870 -1.440811 49.86460
21.75033 43.98038 -1.423194 50.08997
21.80033 44.08252 -1.411520 49.97559
21.85033 44.18321 -1.401804 50.10098
21.90033 44.28389 -1.393777 50.10726
21.95033 44.38523 -1.386321 49.92544
22.00033 44.48602 -1.378921 50.07560
22.05033 44.58696 -1.371807 49.86137
22.10033 44.68698 -1.365086 49.92938
22.15033 44.78840 -1.358458 50.06364
22.20033 44.88887 -1.352122 50.10287
22.25033 44.98874 -1.346099 49.97613
22.30033 45.08950 -1.340656 49.83873
22.35033 45.18918 -1.335858 50.00842
22.40033 45.28976 -1.331660 49.87534
22.45033 45.38980 -1.327971 50.03074
22.50033 45.48968 -1.325139 49.98183
22.55033 45.58975 -1.322668 49.99967
22.60033 45.69002 -1.320632 50.07656
22.65033 45.79101 -1.318989 49.94228
22.70033 45.88934 -1.317726 50.09957
22.75033 45.99003 -1.316720 50.06609
22.80033 46.08972 -1.316215 49.97561
22.85033 46.18966 -1.315724 50.06692
22.90033 46.28970 -1.315533 49.99407
22.95033 46.39016 -1.315369 49.91461
23.00033 46.48897 -1.315554 49.99176
23.05033 46.58982 -1.316109 49.99062
23.10033 46.68955 -1.316668 49.89270
23.15033 46.78888 -1.317283 50.10428
23.20033 46.88782 -1.318082 50.03238
23.25033 46.98832 -1.318866 49.92030
23.30033 47.08836 -1.319873 50.00846
23.35033 47.18806 -1.320855 50.03494
23.40033 47.28790 -1.321889 49.99106
23.45033 47.38769 -1.322880 50.06266
23.50033 47.48774 -1.324066 50.01778
23.55033 47.58660 -1.325181 50.09625
23.60033 47.68692 -1.326466 50.05942
23.65033 47.78656 -1.327667 50.01506
23.70033 47.88630 -1.329056 50.07056
23.75033 47.98633 -1.330326 49.98234
23.80033 48.08698 -1.331724 49.91210
23.85033 48.18614 -1.333125 50.10358
23.90033 48.28638 -1.334609 50.14234
23.95033 48.38633 -1.336180 49.94166
24.00033 48.48586 -1.337483 49.99864
24.05033 48.58541 -1.338851 50.03616
24.10033 48.68547 -1.340264 49.96994
24.15033 48.78559 -1.341665 49.94283
24.20033 48.88524 -1.343014 49.93483
24.25033 48.98498 -1.344279 49.99196
24.30033 49.08450 -1.345286 50.07854
24.35033 49.18388 -1.346406 49.83786
24.40033 49.28391 -1.347654 50.02404
24.45033 49.38354 -1.349078 49.90974
24.50033 49.48308 -1.350561 50.05784
24.55033 49.58352 -1.351955 49.89992
24.60033 49.68350 -1.353511 49.94406
24.65033 49.78352 -1.355044 49.94850
24.70033 49.88337 -1.356584 49.84046
24.75033 49.98304 -1.358310 49.93056
24.80033 50.08254 -1.359979 49.93070
24.85033 50.18291 -1.361765 50.02688
24.90033 50.28222 -1.363328 50.16131
24.95033 50.38203 -1.364991 49.89458
25.00033 50.48208 -1.366714 49.95955
25.05033 50.58190 -1.368432 50.07926
25.10033 50.68197 -1.370106 50.04602
25.15033 50.78192 -1.371910 50.05972
25.20033 50.88118 -1.373713 50.14430
25.25033 50.98148 -1.375409 50.08892
25.30033 51.08141 -1.377053 49.99278
25.35033 51.18102 -1.378662 50.06082
25.40033 51.28078 -1.380290 49.97400
25.45033 51.38049 -1.381798 49.90262
25.50033 51.48026 -1.383347 49.95582
25.55033 51.57970 -1.384958 49.94916
25.60033 51.67919 -1.386644 50.06830
25.65033 51.77994 -1.388358 49.84124
25.70033 51.88022 -1.390030 49.97668
25.75033 51.98042 -1.391663 49.88206
25.80033 52.07930 -1.393390 49.95422
25.85033 52.17903 -1.395094 49.95383
25.90033 52.27869 -1.396761 49.82135
25.95033 52.37832 -1.398430 49.87058
26.00033 52.47812 -1.400156 49.80326
26.05033 52.57847 -1.402145 50.01616
26.10033 52.67800 -1.403972 49.87059
26.15033 52.77758 -1.405742 50.12006
26.20033 52.87812 -1.407592 50.01256
26.25033 52.97759 -1.409423 49.89117
26.30033 53.07773 -1.411136 50.12468
26.35033 53.17756 -1.413025 49.97574
26.40033 53.27680 -1.414851 49.96178
26.45033 53.37758 -1.416826 49.99606
26.50033 53.47720 -1.418791 50.04430
26.55033 53.57700 -1.420681 49.98410
26.60033 53.67724 -1.422820 50.00787
26.65033 53.77652 -1.424733 50.04949
26.70033 53.87553 -1.426683 49.85550
26.75033 53.97582 -1.428514 50.12915
26.80033 54.07622 -1.430412 50.05406
26.85033 54.17529 -1.432306 49.96832
26.90033 54.27526 -1.434358 49.82701
26.95033 54.37564 -1.436369 49.98954
27.00033 54.47571 -1.438376 49.97035
27.05033 54.57496 -1.440366 50.00325
27.10033 54.67525 -1.442249 50.01208
27.15033 54.77497 -1.444134 49.90915
27.20033 54.87486 -1.445920 50.01413
27.25033 54.97478 -1.447821 50.09584
27.30033 55.07414 -1.449704 50.08016
27.35033 55.17445 -1.451665 49.95967
27.40033 55.27380 -1.453605 50.08991
27.45033 55.37406 -1.455555 49.92970
27.50033 55.47316 -1.457410 50.15300
27.55033 55.57366 -1.459631 50.00034
27.60033 55.67280 -1.461727 50.11298
27.65033 55.77229 -1.463692 49.97690
27.70033 55.87276 -1.465620 50.19488
27.75033 55.97160 -1.467744 49.97224
27.80033 56.07183 -1.469760 50.18822
27.85033 56.17086 -1.471778 50.04494
27.90033 56.27115 -1.473778 49.90924
27.95033 56.37104 -1.475756 50.01124
28.00033 56.47063 -1.478024 49.94929
28.05033 56.57026 -1.480067 50.11787
28.10033 56.67018 -1.482218 50.03088
28.15033 56.77050 -1.484432 50.08862
28.20033 56.87079 -1.486829 49.93364
28.25033 56.97007 -1.489178 50.05082
28.30033 57.06972 -1.491570 49.97852
28.35033 57.16958 -1.494023 49.99484
28.40033 57.26921 -1.496106 49.85046
28.45033 57.36951 -1.498410 49.95360
28.50033 57.46887 -1.500685 50.12070
28.55033 57.56920 -1.503058 50.01270
28.60033 57.66884 -1.505246 49.99775
28.65033 57.76741 -1.507557 50.06104
28.70033 57.86786 -1.509799 49.83219
28.75033 57.96810 -1.512091 50.07483
28.80033 58.06768 -1.514243 50.03100
28.85033 58.16642 -1.516593 50.06118
28.90033 58.26627 -1.518838 50.09201
28.95033 58.36715 -1.521273 50.04480
29.00033 58.46642 -1.523672 49.91242
29.05033 58.56694 -1.525942 50.14476
29.10033 58.66565 -1.528292 49.71934
29.15033 58.76608 -1.530500 50.04566
29.20033 58.86562 -1.532627 49.89728
29.25033 58.96540 -1.534748 50.06696
29.30033 59.06489 -1.536978 49.94012
29.35033 59.16452 -1.539234 50.05803
29.40033 59.26345 -1.541514 49.95790
29.45033 59.36410 -1.544000 49.90217
29.50033 59.46380 -1.546617 49.92338
29.55033 59.56037 -1.549704 50.07219
29.60033 59.63286 -1.512290 50.10406
29.65033 59.68396 -1.377449 49.94322
29.70033 59.72302 -1.259109 49.90852
29.75033 59.75472 -1.138825 50.03944
29.80033 59.78104 -1.030234 49.92326
29.85033 59.80263 -0.9362231 49.97330
29.90033 59.82038 -0.8498268 49.91052
29.95033 59.83456 -0.7790356 49.97467
30.00033 59.84670 -0.7148947 50.13416
30.05033 59.85709 -0.6639134 49.97150
30.10033 59.86426 -0.6213774 49.98924
30.15033 59.87222 -0.5845660 50.11906
30.20033 59.87810 -0.5572958 49.99133
30.25033 59.88380 -0.5317104 50.10542
30.30033 59.88785 -0.5132351 49.95840
30.35033 59.89168 -0.4979878 50.07080
30.40033 59.89429 -0.4843360 49.83662
30.45033 59.89701 -0.4743794 49.95976
30.50033 59.89926 -0.4657456 50.05170
30.55033 59.90144 -0.4573786 49.79127
30.60033 59.90354 -0.4496844 49.93594
30.65033 59.90608 -0.4419229 50.08796
30.70033 59.90757 -0.4347516 50.01346
30.75033 59.90774 -0.4279492 50.14878
30.80033 59.90904 -0.4213560 50.01404
30.85033 59.91010 -0.4154217 49.92753
30.90033 59.91116 -0.4099610 49.96586
30.95033 59.91155 -0.4051050 50.00546
31.00033 59.91224 -0.4006601 50.02171
31.05033 59.91355 -0.3966214 50.10821
31.10033 59.91414 -0.3932466 50.07200
31.15033 59.91445 -0.3900659 49.89916
31.20033 59.91498 -0.3872719 49.99009
31.25033 59.91553 -0.3849870 50.09436
31.30033 59.91594 -0.3830287 50.14256
31.35033 59.91596 -0.3812370 49.83220
31.40033 59.91742 -0.3796469 49.96911
31.45033 59.91772 -0.3784626 50.02546
31.50033 59.91858 -0.3771760 49.95360
31.55033 59.91884 -0.3758222 49.89628
31.60033 59.91758 -0.3746681 49.86861
31.65033 59.91946 -0.3735776 50.06615
31.70033 59.91876 -0.3726578 50.15032
31.75033 59.91924 -0.3714889 50.11783
31.80033 59.91912 -0.3705149 50.03024
31.85034 59.91916 -0.3698818 49.86146
31.90033 59.92030 -0.3691167 49.97562
31.95033 59.91968 -0.3684642 49.98584
32.00033 59.92021 -0.3678620 49.96498
32.05033 59.92100 -0.3672500 50.20570
32.10034 59.92051 -0.3668006 50.01244
32.15033 59.92060 -0.3664560 50.04024
32.20033 59.92120 -0.3660332 50.07932
32.25033 59.92127 -0.3656520 49.94434
32.30033 59.92203 -0.3652536 50.07153
32.35034 59.92121 -0.3648800 50.07358
32.40033 59.92118 -0.3645867 49.86734
32.45033 59.92224 -0.3642084 49.97176
-2.000000 1.000000 0.0000000 0.0000000
32.54700 59.91858 -0.3639624 49.89277
32.59700 59.89451 -0.3170572 49.90782
32.64700 59.84526 -0.1787324 50.00908
32.69700 59.78360 -.04817240 49.93630
32.74700 59.71587 0.07352543 49.85826
32.79700 59.64065 0.1863206 49.95346
32.84700 59.56114 0.2868798 50.04547
32.89700 59.47816 0.3728466 50.02607
32.94700 59.39151 0.4515640 49.99116
32.99700 59.30371 0.5148852 49.98520
33.04700 59.21264 0.5713711 50.05616
33.09700 59.12049 0.6178340 49.94866
33.14700 59.02828 0.6542462 49.88446
33.19700 58.93314 0.6859335 49.88369
33.24700 58.83912 0.7125160 50.06080
33.29700 58.74256 0.7337097 49.91274
33.34700 58.64578 0.7494091 50.05868
33.39700 58.55027 0.7649415 50.06598
33.44700 58.45390 0.7760620 49.92211
33.49700 58.35544 0.7859526 49.93828
33.54700 58.25723 0.7952890 50.05169
33.59700 58.15934 0.8036996 49.82822
33.64700 58.06216 0.8121434 50.00913
33.69700 57.96353 0.8203444 50.14295
33.74700 57.86400 0.8284980 49.90507
33.79700 57.76580 0.8361630 49.97790
33.84700 57.66664 0.8436084 50.14528
33.89700 57.56787 0.8507901 50.05202
33.94700 57.46829 0.8573824 50.12219
33.99700 57.36979 0.8637142 49.93772
34.04700 57.27078 0.8697941 50.00680
34.09700 57.17115 0.8754512 50.05226
34.14700 57.07182 0.8809082 49.93292
34.19700 56.97201 0.8857913 49.96850
34.24700 56.87366 0.8903724 49.98626
34.29700 56.77428 0.8945125 50.01381
34.34700 56.67500 0.8987515 49.81764
34.39700 56.57563 0.9024884 49.88470
34.44700 56.47650 0.9062506 49.98356
34.49700 56.37837 0.9098820 50.03804
34.54700 56.27850 0.9134681 49.93420
34.59700 56.17805 0.9167769 50.07914
34.64700 56.07855 0.9201486 49.89266
34.69700 55.97978 0.9233456 50.16084
34.74700 55.88076 0.9265009 50.08766
34.79700 55.78016 0.9294995 50.02946
34.84700 55.68111 0.9323876 50.08264
34.89700 55.58190 0.9353242 49.85736
34.94700 55.48337 0.9381689 50.03958
34.99700 55.38352 0.9409941 50.04429
35.04700 55.28359 0.9438290 50.07175
35.09700 55.18438 0.9465575 49.90410
35.14700 55.08459 0.9492908 49.99126
35.19700 54.98412 0.9519936 49.95572
35.24700 54.88486 0.9548074 49.97072
35.29700 54.78545 0.9573856 49.95654
35.34700 54.68582 0.9600226 49.97197
35.39700 54.58518 0.9628022 50.10534
35.44700 54.48632 0.9654426 49.89570
35.49700 54.38678 0.9679834 50.01844
35.54700 54.28653 0.9703793 50.02080
35.59700 54.18714 0.9726269 49.97862
35.64700 54.08738 0.9749468 49.95310
35.69700 53.98812 0.9771884 49.98061
35.74700 53.88770 0.9794432 50.08532
35.79700 53.78925 0.9816486 49.98957
35.84700 53.68910 0.9838672 49.90671
35.89700 53.58932 0.9861061 49.98963
35.94700 53.48930 0.9883912 49.94420
35.99700 53.38956 0.9903610 50.00425
36.04700 53.29082 0.9925945 49.79703
36.09700 53.19060 0.9946701 50.04930
36.14700 53.09080 0.9967007 49.85938
36.19700 52.99063 0.9989406 49.95676
36.24700 52.89158 1.001072 50.00600
36.29700 52.79168 1.003245 50.04656
36.34700 52.69178 1.005428 50.00909
36.39700 52.59172 1.007427 50.10846
36.44700 52.49288 1.009446 49.98489
36.49700 52.39262 1.011484 49.80988
36.54700 52.29282 1.013491 49.89889
36.59700 52.19306 1.015445 49.87618
36.64700 52.09312 1.017544 50.09339
36.69700 51.99422 1.019711 50.02470
36.74700 51.89346 1.021879 49.99692
36.79700 51.79449 1.023958 49.74184
36.84700 51.69459 1.025981 49.99206
36.89700 51.59450 1.027988 50.13124
36.94700 51.49458 1.029803 49.90164
36.99700 51.39512 1.031540 50.05516
37.04700 51.29500 1.033197 50.02731
37.09700 51.19702 1.034783 50.07641
37.14700 51.09643 1.036627 49.88311
37.19700 50.99650 1.038508 50.01507
37.24700 50.89678 1.040181 49.89121
37.29700 50.79690 1.042043 49.90710
37.34700 50.69721 1.043829 49.93438
37.39700 50.59804 1.045689 49.90969
37.44700 50.49748 1.047469 49.91610
37.49700 50.39834 1.049469 49.96783
37.54700 50.29831 1.051224 49.89463
37.59700 50.19830 1.053114 50.12300
37.64700 50.09838 1.054965 49.98950
37.69700 49.99828 1.056384 49.83008
37.74700 49.89868 1.057938 49.83784
37.79700 49.79958 1.059603 50.04676
37.84700 49.69925 1.061292 50.11509
37.89700 49.59982 1.062858 50.04786
37.94700 49.49932 1.064498 50.05360
37.99700 49.40008 1.066053 50.02442
38.04700 49.30106 1.067758 49.88136
38.09700 49.20104 1.069512 50.01969
38.14700 49.10139 1.071159 49.93239
38.19700 49.00193 1.072674 49.93004
38.24700 48.90180 1.074275 50.05744
38.29700 48.80044 1.075958 50.09650
38.34700 48.70210 1.077614 49.97040
38.39700 48.60184 1.079429 49.80366
38.44700 48.50217 1.081133 49.94200
38.49700 48.40215 1.082919 49.99367
38.54700 48.30285 1.084631 49.96836
38.59700 48.20270 1.086304 49.93570
38.64700 48.10348 1.088026 49.93111
38.69700 48.00369 1.089852 50.01791
38.74700 47.90298 1.091605 50.03921
38.79700 47.80410 1.093443 49.97734
38.84700 47.70288 1.095010 49.96222
38.89700 47.60396 1.096775 49.99643
38.94700 47.50385 1.098217 50.06234
38.99700 47.40358 1.099816 50.20369
39.04700 47.30488 1.101273 49.84181
39.09700 47.20508 1.102758 49.98907
39.14700 47.10428 1.104038 49.97424
39.19700 47.00451 1.105394 50.08638
39.24700 46.90456 1.106714 50.08528
39.29700 46.80654 1.107956 49.95944
39.34700 46.70611 1.109297 50.03598
39.39700 46.60642 1.110657 50.07951
39.44700 46.50602 1.112015 50.16034
39.49700 46.40645 1.113474 49.92180
39.54700 46.30704 1.114790 50.19388
39.59700 46.20709 1.116266 49.96666
39.64700 46.10799 1.117717 50.08806
39.69700 46.00714 1.119135 49.73027
39.74700 45.90744 1.120480 49.99610
39.79700 45.80824 1.121887 50.04356
39.84700 45.70704 1.123347 49.88017
39.89700 45.60817 1.124638 50.04805
39.94700 45.50806 1.125993 49.99314
39.99700 45.40778 1.127337 50.04743
40.04700 45.30806 1.128682 49.96270
40.09700 45.20824 1.130034 49.91548
40.14700 45.10936 1.131251 50.02646
40.19700 45.00940 1.132678 49.81759
40.24700 44.90922 1.133871 49.88922
40.29700 44.81057 1.135266 49.85320
40.34700 44.71004 1.136496 49.86581
40.39700 44.61069 1.137791 50.02544
40.44700 44.51087 1.139112 50.12488
40.49700 44.40996 1.140615 50.19739
40.54700 44.31038 1.141926 49.93574
40.59700 44.21080 1.143280 50.06938
40.64700 44.11139 1.144772 49.90610
40.69700 44.01076 1.146142 50.12986
40.74700 43.91040 1.147512 49.98500
40.79700 43.81143 1.148876 49.92137
40.84700 43.71134 1.150308 49.98047
40.89700 43.61146 1.151560 49.93234
40.94700 43.51242 1.152936 50.15072
40.99700 43.41246 1.154166 49.85188
41.04700 43.31290 1.155352 50.15047
41.09700 43.21283 1.156789 49.89126
41.14700 43.11180 1.157726 49.95810
41.19700 43.01141 1.158742 50.17930
41.24700 42.91293 1.159847 49.84370
41.29700 42.81274 1.160961 50.00678
41.34700 42.71265 1.161991 49.94760
41.39700 42.61366 1.163019 50.02598
41.44700 42.51310 1.164155 50.09008
41.49700 42.41337 1.165156 49.84450
41.54700 42.31346 1.166219 49.99137
41.59700 42.21450 1.167172 49.87254
41.64700 42.11414 1.168162 50.11449
41.69700 42.01410 1.169241 49.78915
41.74700 41.91416 1.170322 50.17059
41.79700 41.81492 1.171290 49.97487
41.84700 41.71516 1.172166 50.20468
41.89700 41.61498 1.173094 50.06486
41.94700 41.51481 1.174110 49.96836
41.99700 41.41563 1.175176 49.88086
42.04700 41.31584 1.176062 49.86289
42.09700 41.21560 1.177197 49.89040
42.14700 41.11531 1.178166 50.06232
42.19700 41.01650 1.179122 50.09686
42.24700 40.91581 1.180332 49.87272
42.29700 40.81530 1.181426 50.02973
42.34700 40.71604 1.182548 49.96460
42.39700 40.61570 1.183684 49.94804
42.44700 40.51675 1.184774 50.06366
42.49700 40.41590 1.185910 50.02022
42.54700 40.31632 1.186716 49.87754
42.59700 40.21641 1.187798 50.14230
42.64700 40.11630 1.188800 49.94620
42.69700 40.01609 1.189685 50.17350
42.74700 39.91641 1.190673 50.00605
42.79700 39.81732 1.191576 49.94836
42.84700 39.71681 1.192184 50.01602
42.89700 39.61770 1.193092 50.04611
42.94700 39.51745 1.193925 49.97002
42.99700 39.41794 1.194825 50.06112
43.04700 39.31826 1.195689 50.14016
43.09700 39.21726 1.196664 49.94515
43.14700 39.11814 1.197390 50.03676
43.19700 39.01817 1.198355 50.03652
43.24700 38.91925 1.199198 50.00606
43.29700 38.82012 1.200014 50.08239
43.34700 38.71856 1.200813 49.90898
43.39700 38.61994 1.201774 49.92166
43.44700 38.51969 1.202754 50.07205
43.49700 38.41865 1.203659 50.12392
43.54700 38.32090 1.204709 50.00534
43.59700 38.22002 1.205814 50.03643
43.64700 38.12006 1.206764 50.01034
43.69700 38.02032 1.207799 49.75278
43.74700 37.92128 1.209058 50.06398
43.79700 37.82129 1.210321 50.05334
43.84700 37.72063 1.211871 49.83159
43.89700 37.62209 1.213755 50.03584
43.94700 37.52094 1.215964 49.98859
43.99700 37.42193 1.219045 50.07122
44.04700 37.32258 1.223224 49.89094
44.09700 37.22324 1.229289 50.06975
44.14700 37.12472 1.244350 50.17553
44.19700 37.02705 1.277694 50.03632
44.24700 36.92970 1.331553 49.95484
44.29700 36.83330 1.399020 49.97500
44.34700 36.73906 1.477824 50.17044
44.39700 36.64421 1.570446 50.03879
44.44700 36.55228 1.684059 50.02928
44.49700 36.46125 1.820056 49.95058
44.54700 36.37280 1.970791 49.93506
44.59700 36.28509 2.141518 50.10998
44.64700 36.19896 2.322842 49.95052
44.69700 36.11300 2.514472 50.16180
44.74700 36.02839 2.710852 49.91572
44.79700 35.94380 2.909720 50.16522
44.84700 35.86000 3.110190 50.10160
44.89700 35.77554 3.304202 49.85610
44.94700 35.69294 3.488320 49.97034
44.99700 35.60803 3.664104 49.92325
45.04700 35.52096 3.823242 50.00079
45.09700 35.43481 3.961172 50.05490
45.14700 35.34494 4.082730 50.11547
45.19700 35.25473 4.180362 49.92366
45.24700 35.16279 4.245835 50.27836
45.29700 35.06842 4.291574 49.96084
45.34700 34.97272 4.308736 49.96059
45.39700 34.87399 4.314016 49.96476
45.44700 34.77434 4.312131 50.05266
45.49700 34.67297 4.283109 49.94990
45.54700 34.56970 4.219216 50.05837
45.59700 34.46607 4.152798 49.87600
45.64700 34.36033 4.076462 50.00830
45.69700 34.25482 3.998063 49.77594
45.74700 34.14952 3.915443 50.09728
45.79700 34.04272 3.831096 49.98854
45.84700 33.93515 3.743578 49.93166
45.89700 33.82888 3.659628 50.07633
45.94700 33.72131 3.572334 49.93489
45.99700 33.61525 3.489113 49.89052
46.04700 33.50820 3.407158 49.96424
46.09700 33.40098 3.328914 49.99067
46.14700 33.29497 3.250556 49.84284
46.19700 33.18869 3.178472 49.94100
46.24700 33.08362 3.109514 50.11378
46.29700 32.97622 3.042201 50.14786
46.34700 32.87166 2.977580 50.05839
46.39700 32.76653 2.918390 50.09894
46.44700 32.66070 2.858668 50.19668
46.49700 32.55713 2.806436 50.17398
46.54700 32.45298 2.756504 50.09734
46.59700 32.34851 2.706810 49.97570
46.64700 32.24472 2.662191 50.04492
46.69700 32.14082 2.618286 50.09367
46.74700 32.03860 2.579494 50.03048
46.79700 31.93539 2.542020 49.95290
46.84700 31.83199 2.503360 49.89016
46.89700 31.72916 2.469486 50.17250
46.94700 31.62604 2.435427 50.07924
46.99700 31.52426 2.402984 49.98974
47.04700 31.41980 2.372754 49.99384
47.09700 31.31816 2.340709 49.89963
47.14700 31.21592 2.310031 50.11626
47.19700 31.11316 2.281606 49.86600
47.24700 31.01047 2.248071 50.01409
47.29700 30.90760 2.215504 50.05796
47.34700 30.80492 2.184252 50.06676
47.39700 30.70356 2.155810 50.07391
47.44700 30.60066 2.122182 49.93190
47.49700 30.49890 2.094555 49.99966
47.54700 30.39554 2.065121 49.86983
47.59700 30.29365 2.037842 49.92162
47.64700 30.19052 2.012156 50.08796
47.69700 30.08887 1.986312 49.92453
47.74700 29.98712 1.959426 49.84127
47.79700 29.88429 1.930322 50.04242
47.84700 29.78210 1.899553 50.00926
47.89700 29.67974 1.861188 50.09222
47.94700 29.57698 1.824912 50.05578
47.99700 29.47264 1.781770 50.02890
48.04700 29.37033 1.738366 49.92532
48.09700 29.26754 1.698457 50.04234
48.14700 29.16424 1.656625 50.04678
48.19700 29.05988 1.618716 49.94170
48.24700 28.95756 1.580066 50.01804
48.29700 28.85517 1.546458 49.80926
48.34700 28.75125 1.517615 50.14734
48.39700 28.64942 1.489902 49.88910
48.44700 28.54709 1.465740 49.95899
48.49700 28.44536 1.445443 49.92994
48.54700 28.34280 1.428549 50.19726
48.59700 28.24146 1.414600 49.87188
48.64700 28.14118 1.401531 50.13665
48.69700 28.03995 1.391186 50.00459
48.74700 27.93942 1.381962 49.91791
48.79700 27.83800 1.373394 49.95596
48.84700 27.73750 1.364885 50.10728
48.89700 27.63653 1.356222 49.91311
48.94700 27.53642 1.348175 49.90370
48.99700 27.43650 1.340460 49.81360
49.04700 27.33520 1.333083 49.78192
49.09700 27.23435 1.326294 49.80602
49.14700 27.13404 1.320222 50.10119
49.19700 27.03396 1.314542 50.08353
49.24700 26.93462 1.309641 50.10944
49.29700 26.83304 1.305248 50.01133
49.34700 26.73387 1.301336 50.07727
49.39700 26.63377 1.297787 50.08550
49.44700 26.53314 1.294459 49.97394
49.49700 26.43254 1.291542 50.04350
49.54700 26.33318 1.288851 49.98816
49.59700 26.23279 1.286468 50.10290
49.64700 26.13249 1.284370 49.98012
49.69700 26.03274 1.282454 49.97239
49.74700 25.93310 1.280781 49.93023
49.79700 25.83215 1.279353 50.16962
49.84700 25.73265 1.278027 49.91740
49.89700 25.63359 1.276857 50.01011
49.94700 25.53277 1.275840 49.92984
49.99700 25.43285 1.274933 49.88624
50.04700 25.33311 1.274076 49.97650
50.09700 25.23266 1.273433 50.11547
50.14700 25.13280 1.272801 50.03829
50.19700 25.03338 1.272156 49.99532
50.24700 24.93285 1.271632 50.01156
50.29700 24.83353 1.271192 49.93282
50.34700 24.73256 1.270859 50.06662
50.39700 24.63330 1.270470 49.91476
50.44700 24.53352 1.270210 49.97146
50.49700 24.43325 1.269778 50.14332
50.54700 24.33342 1.269634 50.01940
50.59700 24.23351 1.269324 49.91108
50.64700 24.13369 1.269238 49.84220
50.69700 24.03416 1.269069 50.13678
50.74700 23.93416 1.268982 50.08784
50.79700 23.83400 1.268843 50.18082
50.84700 23.73410 1.268730 49.90019
50.89700 23.63382 1.268606 50.00062
50.94700 23.53328 1.268402 50.03262
50.99700 23.43433 1.268261 49.94869
51.04700 23.33436 1.268321 50.13100
51.09700 23.23494 1.268242 50.18526
51.14700 23.13540 1.268313 50.05804
51.19700 23.03428 1.268277 50.08521
51.24700 22.93457 1.268535 49.90356
51.29700 22.83438 1.268751 50.03810
51.34700 22.73361 1.268831 50.01997
51.39700 22.63494 1.268917 50.10180
51.44700 22.53378 1.268800 49.92377
51.49700 22.43454 1.268844 50.01284
51.54700 22.33418 1.268745 49.76253
51.59700 22.23472 1.269135 50.03835
51.64700 22.13396 1.269146 50.23672
51.69700 22.03504 1.269332 50.13818
51.74700 21.93458 1.269268 50.03190
51.79700 21.83446 1.269304 50.00589
51.84700 21.73527 1.269309 49.89706
51.89700 21.63506 1.269306 49.98779
51.94700 21.53496 1.269297 49.92717
51.99700 21.43581 1.269339 49.96056
52.04700 21.33456 1.269339 50.08748
52.09700 21.23555 1.269410 49.96513
52.14700 21.13567 1.269460 50.05506
52.19700 21.03587 1.269490 49.96875
52.24700 20.93672 1.269464 49.94608
52.29700 20.83462 1.269550 50.26680
52.34700 20.73572 1.269798 50.09628
52.39700 20.63545 1.269899 50.01080
52.44700 20.53530 1.270135 49.85037
52.49700 20.43566 1.270254 49.96474
52.54700 20.33579 1.270268 49.92437
52.59700 20.23609 1.270450 49.77333
52.64700 20.13561 1.270542 50.13374
52.69700 20.03644 1.270645 49.90940
52.74700 19.93649 1.270464 50.11967
52.79700 19.83744 1.270457 50.02602
52.84700 19.73605 1.270351 50.11572
52.89700 19.63763 1.270425 50.01646
52.94700 19.53746 1.270446 50.02354
52.99700 19.43692 1.270504 49.76938
53.04700 19.33697 1.270593 49.87369
53.09700 19.23780 1.270754 49.91665
53.14700 19.13751 1.270872 50.07358
53.19700 19.03876 1.271002 50.09648
53.24700 18.93766 1.271215 50.18295
53.29700 18.83809 1.271289 50.13032
53.34700 18.73777 1.271436 50.06040
53.39700 18.63776 1.271810 50.03488
53.44700 18.53791 1.272023 49.94074
53.49700 18.43712 1.272338 50.10539
53.54700 18.33740 1.272527 50.10746
53.59700 18.23750 1.272669 49.83885
53.64700 18.13770 1.272980 50.01549
53.69700 18.03793 1.273076 50.12728
53.74700 17.93780 1.273184 50.05994
53.79700 17.83836 1.273411 49.91922
53.84700 17.73778 1.273636 49.93079
53.89700 17.63817 1.273570 50.01520
53.94700 17.53733 1.273648 50.15108
53.99700 17.43777 1.273890 49.88610
54.04700 17.33773 1.273935 50.03294
54.09700 17.23786 1.273909 50.14479
54.14700 17.13822 1.274098 49.99720
54.19700 17.03802 1.274191 50.02006
54.24700 16.93785 1.274388 50.08874
54.29700 16.83730 1.274496 50.02169
54.34700 16.73782 1.274548 50.12822
54.39700 16.63706 1.274383 49.92860
54.44700 16.53865 1.274244 49.86285
54.49700 16.43839 1.274224 49.94219
54.54700 16.33879 1.274271 50.04686
54.59700 16.23799 1.274337 49.81088
54.64700 16.13825 1.274232 49.74743
54.69700 16.03870 1.274126 50.04191
54.74700 15.93858 1.273981 50.02730
54.79700 15.83885 1.274090 50.05438
54.84700 15.73984 1.274026 50.08441
54.89700 15.63896 1.273922 50.11885
54.94700 15.54014 1.273889 50.03287
54.99700 15.43872 1.273800 49.98988
55.04700 15.33953 1.273841 49.85761
55.09700 15.23847 1.273691 49.86748
55.14700 15.13918 1.273831 49.93330
55.19700 15.03929 1.273746 49.99150
55.24700 14.93929 1.273668 50.09930
55.29700 14.83976 1.273790 49.93785
55.34700 14.73836 1.273782 50.07944
55.39700 14.63971 1.273937 49.97716
55.44700 14.53921 1.273930 50.05760
55.49700 14.44018 1.274006 50.16128
55.54700 14.33972 1.274396 50.02579
55.59700 14.23995 1.274581 50.00429
55.64700 14.14042 1.274581 49.89970
55.69700 14.04053 1.274682 50.05180
55.74700 13.94047 1.274795 49.97873
55.79700 13.83932 1.275028 50.03810
55.84700 13.74002 1.275105 50.09990
55.89700 13.63988 1.275052 50.13759
55.94700 13.53992 1.275166 49.86008
55.99700 13.43974 1.275119 50.01561
56.04700 13.34030 1.275075 50.08081
56.09700 13.23956 1.275017 50.07616
56.14700 13.14070 1.274972 50.14294
56.19700 13.04049 1.274849 49.93370
56.24700 12.94041 1.274445 50.03646
56.29700 12.83977 1.274190 50.09833
56.34700 12.74169 1.273970 50.14214
56.39700 12.64092 1.273805 50.07444
56.44700 12.54125 1.273610 49.96218
56.49700 12.44099 1.273572 50.02163
56.54700 12.34131 1.273407 50.01924
56.59700 12.24229 1.273199 50.03364
56.64700 12.14198 1.273117 50.06496
56.69700 12.04050 1.273192 50.02789
56.74700 11.94269 1.273300 49.97510
56.79700 11.84104 1.273480 50.08956
56.84700 11.74071 1.273630 50.00972
56.89700 11.64039 1.273735 49.93261
56.94700 11.54139 1.273880 49.99876
56.99700 11.44099 1.273919 49.94736
57.04700 11.34167 1.274093 49.87722
57.09700 11.24210 1.274094 49.89994
57.14700 11.14185 1.274023 49.95176
57.19700 11.04158 1.274120 49.90065
57.24700 10.94157 1.274275 50.15970
57.29700 10.84162 1.274213 50.13962
57.34700 10.74158 1.274047 49.96924
57.39700 10.64218 1.274079 50.02881
57.44700 10.54159 1.273815 50.02197
57.49700 10.44205 1.273783 50.07879
57.54700 10.34121 1.273529 50.06579
57.59700 10.24206 1.273357 49.99526
57.64700 10.14205 1.273036 50.11176
57.69700 10.04198 1.272941 50.01549
57.74700 9.942059 1.272908 50.02754
57.79700 9.843090 1.272829 50.05313
57.84700 9.741780 1.272853 50.12390
57.89700 9.642018 1.272896 49.99290
57.94700 9.541714 1.272849 49.98606
57.99700 9.441570 1.272783 49.91870
58.04700 9.341422 1.272883 49.88417
58.09700 9.242258 1.272812 49.89656
58.14700 9.141891 1.272770 50.06586
58.19700 9.042286 1.272814 50.02688
58.24700 8.941738 1.272664 49.90850
58.29700 8.842559 1.272434 50.07888
58.34700 8.741626 1.272160 49.89610
58.39700 8.642410 1.272110 50.19993
58.44700 8.543270 1.271826 49.89512
58.49700 8.443475 1.271814 50.11288
58.54700 8.341942 1.271686 49.91502
58.59700 8.242382 1.271629 49.90646
58.64700 8.141532 1.271452 49.83938
58.69700 8.041874 1.271519 50.13907
58.74700 7.942630 1.271325 50.00400
58.79700 7.841926 1.271348 50.11041
58.84700 7.742874 1.271383 49.91150
58.89700 7.643099 1.271412 50.14982
58.94700 7.543164 1.271469 49.94360
58.99700 7.443456 1.271511 50.06382
59.04700 7.342245 1.271470 50.04131
59.09700 7.243820 1.271254 50.05454
59.14700 7.143366 1.271083 50.00922
59.19700 7.042928 1.271410 50.22056
59.24700 6.942312 1.271440 49.98152
59.29700 6.842019 1.271250 49.97964
59.34700 6.743268 1.271250 49.94884
59.39700 6.642813 1.271105 50.10813
59.44700 6.542896 1.271002 50.02829
59.49700 6.442645 1.270882 49.99197
59.54700 6.344276 1.270800 49.99002
59.59700 6.242450 1.270644 50.17570
59.64700 6.142914 1.270330 50.07660
59.69700 6.044624 1.270102 49.89141
59.74700 5.942702 1.269950 49.96752
59.79700 5.843934 1.269800 50.01180
59.84700 5.742937 1.269658 50.00354
59.89700 5.644186 1.269652 49.87418
59.94700 5.543744 1.269577 49.92211
59.99700 5.444000 1.269371 50.03040
60.04700 5.344302 1.269117 50.17002
60.09700 5.244213 1.269169 49.89176
60.14700 5.144024 1.269024 50.08929
60.19700 5.043979 1.268992 50.02098
60.24700 4.944306 1.269004 49.90613
60.29700 4.843300 1.269036 49.98560
60.34700 4.744678 1.268984 50.09497
60.39700 4.644637 1.268914 49.96263
60.44700 4.545100 1.268841 49.92952
60.49700 4.445210 1.268811 49.93698
60.54700 4.344516 1.268666 49.91343
60.59700 4.245189 1.268741 49.84174
60.64700 4.144170 1.268671 50.03046
60.69700 4.044898 1.268691 49.94384
60.74700 3.945341 1.268678 50.03188
60.79700 3.844796 1.268624 49.99758
60.84700 3.745007 1.268562 50.05344
60.89700 3.644934 1.268596 50.00184
60.94700 3.545009 1.268647 50.13070
60.99700 3.443512 1.268530 49.94426
61.04700 3.345200 1.268488 49.97620
61.09700 3.245098 1.268407 50.07472
61.14700 3.143944 1.268244 49.94551
61.19700 3.045012 1.268064 50.07709
61.24700 2.944630 1.267930 49.88172
61.29700 2.845056 1.267783 49.83864
61.34700 2.745545 1.267645 49.95985
61.39700 2.645942 1.267670 49.83762
61.44700 2.545169 1.267453 50.03590
61.49700 2.445090 1.267291 50.02031
61.54700 2.345666 1.267305 50.06730
61.59700 2.245594 1.267206 49.99056
61.64700 2.146126 1.267239 50.22292
61.69700 2.045236 1.267255 49.94740
61.74700 1.945810 1.267058 49.90033
61.79700 1.845351 1.266989 50.00840
61.84700 1.745666 1.266718 49.96884
61.89700 1.645914 1.266464 50.13436
61.94700 1.545663 1.266413 50.03617
61.99700 1.446466 1.266020 50.19760
62.04700 1.348361 1.266253 50.01339
62.09700 1.275524 1.218140 49.96586
62.14700 1.225132 1.089086 49.86735
62.19700 1.185302 0.9768159 49.93254
62.24700 1.155525 0.8680019 50.05080
62.29700 1.131416 0.7640857 49.82556
62.34700 1.110224 0.6782300 49.97833
62.39700 1.094127 0.5998386 49.98787
62.44700 1.080084 0.5315903 49.97541
62.49700 1.067950 0.4748348 49.90784
62.54700 1.058717 0.4259119 50.07324
62.59700 1.050592 0.3851975 50.12268
62.64700 1.043175 0.3518312 50.04498
62.69700 1.038204 0.3236814 50.06052
62.74700 1.032904 0.3020970 50.01410
62.79700 1.028493 0.2843813 49.96380
62.84700 1.024492 0.2692357 49.82230
62.89700 1.021608 0.2580806 49.99346
62.94700 1.019202 0.2485172 50.03238
62.99700 1.017470 0.2399168 49.97150
63.04700 1.014855 0.2309717 50.07840
63.09700 1.013099 0.2231724 50.06731
63.14700 1.012343 0.2154144 49.91688
63.19700 1.010720 0.2079577 50.17441
63.24700 1.009888 0.2009977 50.08228
63.29700 1.008529 0.1947884 50.15690
63.34700 1.008541 0.1890389 50.17518
63.39700 1.007190 0.1837578 49.92806
63.44700 1.005377 0.1790171 50.10730
63.49700 1.005736 0.1749408 50.00179
63.54700 1.005006 0.1712994 50.03159
63.59700 1.003906 0.1680509 49.98652
63.64700 1.003437 0.1649760 50.01889
63.69700 1.001508 0.1623821 49.92266
63.74700 1.002650 0.1600089 50.15274
63.79700 1.002975 0.1577464 50.05222
63.84700 1.001255 0.1558165 49.94710
63.89700 1.001640 0.1542009 49.89597
63.94700 1.001036 0.1526850 50.05774
63.99700 1.000278 0.1513794 50.04582
64.04700 0.9999454 0.1501370 49.89012
64.09700 0.9994395 0.1489181 49.98684
64.14700 0.9998782 0.1479168 50.01453
64.19701 0.9991800 0.1469586 49.92906
64.24700 0.9999024 0.1459696 50.08304
64.29700 0.9992376 0.1449914 49.98953
64.34700 0.9983826 0.1442902 50.15411
64.39700 0.9979613 0.1436349 50.10034
64.44701 0.9983912 0.1428559 49.99602
64.49700 0.9980750 0.1423189 49.94700
64.54700 0.9981799 0.1417619 50.11203
64.59700 0.9975491 0.1412314 50.01031
64.64700 0.9980425 0.1409352 50.05402
64.69701 0.9979028 0.1403261 50.04142
64.74700 0.9975128 0.1399407 50.18775
64.79700 0.9968015 0.1395294 50.04740
-2.000000 2.000000 0.0000000 0.0000000