File: imagens/notebooks/dados experimentais/dsc/Karl_CTAB100 Ur 44%.txt
CLOSED
Version	1.0
Language	English
Run	1
RunSerial	149
Instrument	DSC Q100 V9.9 Build 303
Module	DSC Standard Cell FC
Operator	LL
File	\\Niger\ta\Data\DSC\2018\Geral\Karl_CTAB100 Ur 44%.001
ProcName	Karl
InstSerial	0100-1211
Sample	CTAB100 Ur 44%
Size	9.42000	mg
Method	Karl
Comment
Xcomment	Pan: Aluminum Hermetic
Xcomment	Gas1: Nitrogen 50.0 ml/min
Xcomment	Gas2: Nitrogen 0.0 ml/min
Text
Exotherm	UP
Kcell	1.09030
Calib	-11.7822
TempCal	1	pts	158.71	156.60
TzeroDt	-90.0515 -0.0093 2.2263
TzeroDtz	-90.0515 0.0466 2.4421
InstCalFile	Tzero: \\Niger\ta\Data\DSC\CALIBRATION\20122016\CALIBRATION\0_RCS_12_20_2016 17_23_31.TZR
InstCalFile	Baseline: \\Niger\ta\Data\DSC\CALIBRATION\20122016\L.Base 20122016
InstCalFile	Sapphire: \\Niger\ta\Data\DSC\CALIBRATION\20122016\Safira 20122017.001
InstCalDate	Tzero 2016-12-20 Time 19:23:31
TempRange	-90.04 to 395.23 °C at 19.96 °C/min Heat Only
AutoZero	Delta T Offset 0.000 uV
AutoZero	Delta T0 Offset 0.000 uV
Controls	Gas 1  Event Off  Sampling 0.2
Cell#	FC-02451
CoolingUnit	RCS
SelHeatFlow	Heat Flow T4 (mW)
AutoAnalysis	Off
MacroFile
Nsig	4
Sig1	Time (min)
Sig2	Temperature (°C)
Sig3	Heat Flow (mW)
Sig4	Sample Purge Flow (mL/min)
Date	2018-05-16
Time	13:43:42
OrgMethod	1: Equilibrate at 1.00 °C
OrgMethod	2: Ramp 2.00 °C/min to 60.00 °C
OrgMethod	3: Isothermal for 3.00 min
OrgMethod	4: Mark end of cycle 1
OrgMethod	5: Ramp 2.00 °C/min to 1.00 °C
OrgMethod	6: Isothermal for 3.00 min
OrgMethod	7: Mark end of cycle 2
OrgFile	C:\TA\Data\DSC\2018\Geral\Karl_CTAB100 Ur 44%.001
3.33324E-4 1.148719 0.8057450 50.01498
0.05033332 1.139075 0.7233500 49.79500
0.1003333 1.155652 0.6000679 49.85756
0.1503333 1.198481 0.4455338 49.90500
0.2003333 1.252804 0.2957126 49.93118
0.2503333 1.315587 0.1538231 49.87912
0.3003333 1.383547 0.02062479 50.20966
0.3503333 1.456230 -.09867821 49.85656
0.4003334 1.533928 -0.2063284 50.04298
0.4503334 1.611446 -0.3033190 50.03481
0.5003334 1.695993 -0.3847948 50.16526
0.5503332 1.781031 -0.4520896 50.08587
0.6003332 1.868252 -0.5146143 49.40252
0.6503332 1.956592 -0.5695637 49.85808
0.7003332 2.046956 -0.6103499 49.92559
0.7503332 2.137409 -0.6502066 49.90483
0.8003332 2.228790 -0.6847208 49.85281
0.8503332 2.322119 -0.7118191 50.08426
0.9003332 2.416436 -0.7353747 49.69370
0.9503334 2.510264 -0.7563422 49.52298
1.000333 2.605547 -0.7758491 49.90534
1.050334 2.701194 -0.7890611 49.79772
1.100334 2.796079 -0.8021182 50.30309
1.150334 2.893476 -0.8130136 49.96126
1.200334 2.990602 -0.8226294 50.03021
1.250334 3.085884 -0.8325282 49.96991
1.300334 3.183615 -0.8418644 49.87896
1.350333 3.281748 -0.8512086 50.09036
1.400333 3.378927 -0.8596469 50.04825
1.450334 3.476838 -0.8678474 49.31437
1.500333 3.573550 -0.8757508 49.64003
1.550334 3.672595 -0.8831986 50.00752
1.600334 3.770278 -0.8903147 50.02551
1.650333 3.867822 -0.8970755 49.97970
1.700334 3.967003 -0.9034801 49.87784
1.750334 4.065186 -0.9095792 49.21480
1.800334 4.164056 -0.9151491 50.01500
1.850334 4.262918 -0.9203945 49.73306
1.900334 4.360854 -0.9253855 49.83618
1.950334 4.459080 -0.9299991 49.24640
2.000334 4.558213 -0.9343700 50.08653
2.050333 4.657089 -0.9383045 50.06881
2.100334 4.756461 -0.9422084 49.86670
2.150334 4.855112 -0.9457363 50.11660
2.200334 4.954219 -0.9493559 50.41870
2.250334 5.053448 -0.9527495 49.47922
2.300333 5.152274 -0.9561332 50.05460
2.350334 5.252960 -0.9593238 49.92128
2.400334 5.351230 -0.9623478 50.10200
2.450334 5.451116 -0.9653832 50.17474
2.500334 5.550514 -0.9681741 49.49610
2.550333 5.649620 -0.9707470 50.00034
2.600333 5.749212 -0.9731499 50.01716
2.650333 5.848145 -0.9753681 49.93208
2.700333 5.947074 -0.9774350 49.82654
2.750333 6.047618 -0.9791766 49.90934
2.800333 6.146150 -0.9806280 49.97681
2.850333 6.245686 -0.9822251 50.18384
2.900333 6.345413 -0.9836195 50.10265
2.950333 6.444278 -0.9850613 49.91348
3.000333 6.543194 -0.9866129 49.94362
3.050333 6.642439 -0.9881278 50.07026
3.100333 6.742895 -0.9895224 49.91914
3.150333 6.841616 -0.9911420 50.02076
3.200333 6.941538 -0.9926085 49.84883
3.250333 7.041684 -0.9941637 49.90463
3.300333 7.140546 -0.9956014 49.79404
3.350333 7.240941 -0.9971772 50.12933
3.400333 7.340046 -0.9986699 49.72473
3.450333 7.440000 -1.000072 49.90974
3.500333 7.539415 -1.001255 50.09086
3.550333 7.639524 -1.002752 50.02964
3.600333 7.739694 -1.004090 49.83220
3.650333 7.838569 -1.005444 49.93074
3.700333 7.938310 -1.006659 50.04430
3.750333 8.038718 -1.007662 49.93131
3.800333 8.138260 -1.008916 49.92976
3.850333 8.237687 -1.009882 50.02812
3.900333 8.337296 -1.011041 50.16946
3.950333 8.437676 -1.011951 50.01398
4.000333 8.536598 -1.012798 50.08548
4.050333 8.636046 -1.013625 50.12758
4.100333 8.736402 -1.014431 50.06542
4.150333 8.836285 -1.015014 49.91257
4.200333 8.935078 -1.015586 50.03083
4.250333 9.034794 -1.015941 50.01382
4.300333 9.134684 -1.016390 49.95041
4.350333 9.234008 -1.017074 49.98422
4.400333 9.334321 -1.017755 50.10118
4.450333 9.433722 -1.018375 49.98052
4.500333 9.532671 -1.018987 50.04112
4.550333 9.633066 -1.019629 49.88950
4.600333 9.732657 -1.020405 50.03201
4.650333 9.832421 -1.021219 49.96433
4.700333 9.932657 -1.021992 49.96696
4.750333 10.03203 -1.022877 50.14706
4.800333 10.13192 -1.023646 50.01154
4.850333 10.23264 -1.024561 49.88764
4.900333 10.33176 -1.025214 49.83990
4.950333 10.43201 -1.025984 49.97881
5.000333 10.53144 -1.026930 49.98264
5.050333 10.63170 -1.027801 49.95454
5.100333 10.73207 -1.028822 49.99792
5.150333 10.83219 -1.029840 49.81998
5.200333 10.93258 -1.030706 49.91598
5.250332 11.03141 -1.031694 50.03113
5.300332 11.13187 -1.032498 50.07362
5.350332 11.23149 -1.033406 50.14071
5.400332 11.33122 -1.034289 50.27972
5.450332 11.43133 -1.034903 49.99883
5.500332 11.53100 -1.035817 49.89746
5.550332 11.63074 -1.036616 49.89087
5.600332 11.73139 -1.037147 49.98515
5.650332 11.83191 -1.037891 50.11902
5.700332 11.93102 -1.038362 49.88168
5.750332 12.03120 -1.038956 50.11139
5.800332 12.13057 -1.039450 50.07475
5.850332 12.23070 -1.039866 50.08633
5.900332 12.33099 -1.040436 50.07314
5.950332 12.43084 -1.040978 50.15738
6.000332 12.53034 -1.041341 49.85276
6.050332 12.63021 -1.041869 50.14648
6.100332 12.72941 -1.042591 49.96278
6.150332 12.82980 -1.043096 50.09283
6.200332 12.93027 -1.043697 49.99684
6.250332 13.02956 -1.044171 50.10445
6.300332 13.12904 -1.044686 50.06104
6.350332 13.22849 -1.045116 50.05447
6.400332 13.32976 -1.045583 49.89059
6.450332 13.42917 -1.045948 49.97217
6.500332 13.52828 -1.046415 49.92672
6.550332 13.62935 -1.046944 50.06384
6.600332 13.72702 -1.047708 50.08709
6.650332 13.82927 -1.048240 49.92840
6.700332 13.92780 -1.049134 50.00078
6.750332 14.02828 -1.049615 50.08103
6.800332 14.12852 -1.050297 49.94028
6.850332 14.22849 -1.051058 50.02359
6.900332 14.32876 -1.051834 50.13052
6.950332 14.42808 -1.052710 49.89466
7.000332 14.52918 -1.053428 50.27822
7.050332 14.62856 -1.054338 49.84292
7.100332 14.72897 -1.055150 50.11277
7.150332 14.83028 -1.055865 50.04055
7.200332 14.92902 -1.056551 50.18944
7.250332 15.02878 -1.057110 50.08612
7.300332 15.12963 -1.057485 50.04643
7.350332 15.22860 -1.057816 50.10704
7.400332 15.32831 -1.058136 50.05844
7.450332 15.42822 -1.058593 49.94322
7.500332 15.52715 -1.058820 50.06160
7.550332 15.62761 -1.059039 50.13578
7.600332 15.72600 -1.059316 50.01192
7.650332 15.82765 -1.059750 50.16187
7.700332 15.92584 -1.060372 50.08252
7.750332 16.02699 -1.060793 49.93820
7.800332 16.12729 -1.061369 50.10411
7.850332 16.22666 -1.061851 50.22580
7.900332 16.32610 -1.062526 49.95474
7.950332 16.42606 -1.063166 50.00568
8.000334 16.52732 -1.063810 50.05922
8.050332 16.62651 -1.064599 50.24115
8.100332 16.72686 -1.065345 50.00250
8.150332 16.82699 -1.065983 50.04844
8.200332 16.92681 -1.066692 49.94674
8.250334 17.02690 -1.067251 49.92538
8.300332 17.12682 -1.068064 49.93761
8.350332 17.22645 -1.068682 50.18802
8.400332 17.32660 -1.069321 49.99129
8.450332 17.42543 -1.069942 50.20512
8.500334 17.52666 -1.070521 50.09472
8.550332 17.62594 -1.071050 50.00360
8.600332 17.72547 -1.071427 50.01554
8.650332 17.82496 -1.071649 49.93070
8.700332 17.92539 -1.072021 49.89357
8.750334 18.02458 -1.072248 50.00722
8.800332 18.12489 -1.072680 50.07734
8.850332 18.22490 -1.072901 49.93246
8.900332 18.32447 -1.073125 50.07132
8.950332 18.42428 -1.073472 50.01508
9.000334 18.52368 -1.073798 49.94361
9.050332 18.62298 -1.074208 50.12408
9.100332 18.72386 -1.074529 50.08504
9.150332 18.82381 -1.075127 50.02520
9.200332 18.92361 -1.075812 50.11742
9.250334 19.02408 -1.076472 49.85909
9.300332 19.12355 -1.077228 50.06844
9.350332 19.22391 -1.077816 50.07984
9.400332 19.32280 -1.078624 50.04202
9.450332 19.42396 -1.079422 49.95162
9.500334 19.52420 -1.080201 49.95387
9.550332 19.62435 -1.080917 49.99194
9.600332 19.72426 -1.081774 50.07392
9.650332 19.82287 -1.082717 49.94617
9.700332 19.92330 -1.083542 50.16132
9.750334 20.02417 -1.084362 50.00040
9.800332 20.12378 -1.085139 49.85547
9.850332 20.22308 -1.085925 50.13070
9.900332 20.32511 -1.086411 49.81186
9.950332 20.42443 -1.086961 50.00014
10.00033 20.52390 -1.087551 50.08256
10.05033 20.62291 -1.088007 50.00470
10.10033 20.72372 -1.088236 49.92785
10.15033 20.82305 -1.088690 49.98410
10.20033 20.92304 -1.089066 50.05111
10.25033 21.02334 -1.089409 49.99040
10.30033 21.12227 -1.089823 49.95188
10.35033 21.22298 -1.090058 50.00048
10.40033 21.32212 -1.090495 50.03333
10.45033 21.42202 -1.090942 50.09934
10.50034 21.52246 -1.091472 49.99333
10.55033 21.62217 -1.092266 50.09554
10.60033 21.72339 -1.092872 49.99371
10.65033 21.82140 -1.093606 50.03180
10.70033 21.92242 -1.094298 49.97037
10.75034 22.02286 -1.095010 49.87898
10.80033 22.12210 -1.095576 50.07260
10.85033 22.22273 -1.096178 50.08286
10.90033 22.32154 -1.096775 49.96170
10.95033 22.42195 -1.097097 49.91698
11.00034 22.52227 -1.097744 50.18230
11.05033 22.62080 -1.098141 49.89213
11.10033 22.72163 -1.098556 50.06796
11.15033 22.82139 -1.099141 49.94972
11.20033 22.92079 -1.099729 50.22378
11.25034 23.02109 -1.100184 49.94854
11.30033 23.12122 -1.100611 49.80898
11.35033 23.22075 -1.100893 50.06033
11.40033 23.32071 -1.101234 50.03647
11.45033 23.42013 -1.101401 49.89368
11.50034 23.52126 -1.101872 49.91540
11.55033 23.62152 -1.102388 50.07220
11.60033 23.71988 -1.103059 49.98864
11.65033 23.82054 -1.103850 49.98936
11.70033 23.92012 -1.104559 49.97134
11.75034 24.02016 -1.105198 49.82679
11.80033 24.11938 -1.105808 49.92090
11.85033 24.21830 -1.106684 50.09840
11.90033 24.31974 -1.107415 49.96990
11.95033 24.41975 -1.108260 50.03531
12.00034 24.52038 -1.108975 49.94192
12.05033 24.62017 -1.109762 49.97283
12.10033 24.72092 -1.110543 49.96524
12.15033 24.81998 -1.111166 50.03236
12.20033 24.91947 -1.111846 50.03766
12.25034 25.01993 -1.112427 50.16288
12.30033 25.11962 -1.112976 49.99296
12.35033 25.21978 -1.113532 50.09674
12.40033 25.31867 -1.114060 50.22016
12.45033 25.41889 -1.114551 49.88254
12.50034 25.51852 -1.115075 50.15172
12.55033 25.61818 -1.115548 50.07338
12.60033 25.71743 -1.116144 49.97326
12.65033 25.81882 -1.116761 50.04031
12.70033 25.91836 -1.117552 50.13237
12.75034 26.01870 -1.118402 49.96124
12.80033 26.11796 -1.119157 50.05250
12.85033 26.21794 -1.119913 50.11363
12.90033 26.31812 -1.120720 49.87961
12.95034 26.41888 -1.121536 50.04130
13.00034 26.51690 -1.122316 49.93566
13.05033 26.61780 -1.122940 50.08026
13.10033 26.71809 -1.123861 50.09100
13.15033 26.81785 -1.124688 49.93028
13.20034 26.91792 -1.125700 49.95000
13.25034 27.01934 -1.126494 49.85697
13.30033 27.11800 -1.127354 49.91370
13.35033 27.21860 -1.128182 50.22936
13.40033 27.31783 -1.129027 49.89059
13.45034 27.41706 -1.129694 50.08598
13.50034 27.51748 -1.130261 49.86902
13.55033 27.61780 -1.130868 49.96044
13.60033 27.71722 -1.131638 50.04226
13.65033 27.81705 -1.132361 49.92942
13.70034 27.91711 -1.133173 49.97500
13.75034 28.01738 -1.133863 50.13648
13.80033 28.11625 -1.134757 50.00784
13.85033 28.21588 -1.135775 49.95776
13.90033 28.31831 -1.136822 50.01299
13.95034 28.41646 -1.137981 50.08588
14.00034 28.51644 -1.138966 49.83964
14.05033 28.61593 -1.139702 49.83629
14.10033 28.71614 -1.140271 49.99140
14.15033 28.81587 -1.141124 50.11344
14.20034 28.91612 -1.141875 49.98663
14.25034 29.01653 -1.142490 49.91512
14.30033 29.11681 -1.143242 49.94644
14.35033 29.21504 -1.143910 50.00024
14.40033 29.31603 -1.144817 50.01949
14.45034 29.41534 -1.145605 50.24459
14.50034 29.51604 -1.146638 50.10996
14.55033 29.61625 -1.147701 49.96742
14.60033 29.71578 -1.148559 50.00369
14.65033 29.81615 -1.149466 50.16850
14.70034 29.91564 -1.150580 49.94691
14.75034 30.01656 -1.151535 49.88200
14.80033 30.11510 -1.152535 49.99213
14.85033 30.21516 -1.153371 50.01196
14.90033 30.31440 -1.154174 49.99950
14.95034 30.41484 -1.155023 49.98480
15.00034 30.51428 -1.155635 49.88809
15.05033 30.61454 -1.156154 49.88042
15.10033 30.71381 -1.156682 50.03290
15.15033 30.81295 -1.157539 49.93478
15.20034 30.91296 -1.158458 49.89248
15.25034 31.01339 -1.159542 49.86925
15.30033 31.11389 -1.160683 50.07040
15.35033 31.21337 -1.161926 50.05516
15.40033 31.31374 -1.163322 49.83442
15.45034 31.41255 -1.164783 50.02547
15.50034 31.51290 -1.166237 50.14148
15.55033 31.61237 -1.167624 49.94304
15.60033 31.71318 -1.168898 49.94742
15.65033 31.81282 -1.170368 50.01034
15.70034 31.91322 -1.171551 49.90369
15.75034 32.01328 -1.172820 50.05350
15.80033 32.11361 -1.174269 49.74441
15.85033 32.21245 -1.175780 50.04594
15.90033 32.31215 -1.177032 50.05025
15.95034 32.41165 -1.178416 49.99012
16.00033 32.51273 -1.179637 50.02852
16.05033 32.61182 -1.180956 49.95726
16.10033 32.71274 -1.182481 49.83493
16.15033 32.81268 -1.183893 49.93304
16.20033 32.91150 -1.185344 49.94278
16.25033 33.01166 -1.186888 50.03910
16.30033 33.11185 -1.188661 49.99351
16.35033 33.21094 -1.190468 49.97801
16.40033 33.31076 -1.192211 50.03970
16.45033 33.41109 -1.194145 50.01226
16.50033 33.51060 -1.196217 49.96013
16.55033 33.61038 -1.198645 50.06728
16.60033 33.71044 -1.201388 49.94060
16.65033 33.80947 -1.204653 49.93063
16.70033 33.90902 -1.208544 49.80511
16.75033 34.00847 -1.213001 49.93793
16.80033 34.10776 -1.218257 50.00152
16.85033 34.20642 -1.224171 50.04612
16.90033 34.30683 -1.230755 49.91700
16.95033 34.40437 -1.238381 49.96348
17.00033 34.50336 -1.248499 49.96046
17.05033 34.60256 -1.262920 49.93168
17.10033 34.70060 -1.281931 50.11959
17.15033 34.79838 -1.310020 49.90422
17.20033 34.89690 -1.340258 49.90067
17.25033 34.99600 -1.373927 49.85593
17.30033 35.09244 -1.412683 49.92004
17.35033 35.18998 -1.450369 49.97460
17.40033 35.28680 -1.487087 50.00336
17.45033 35.38366 -1.525141 50.08652
17.50033 35.48040 -1.568064 49.95625
17.55033 35.57866 -1.604635 49.93769
17.60033 35.67628 -1.643033 49.99600
17.65033 35.77185 -1.678439 49.93772
17.70033 35.86985 -1.713342 50.13628
17.75033 35.96738 -1.747728 49.86770
17.80033 36.06340 -1.779716 50.08210
17.85033 36.16092 -1.809433 49.99585
17.90033 36.25816 -1.837511 49.93410
17.95033 36.35698 -1.863184 50.03806
18.00033 36.45410 -1.885419 49.86460
18.05033 36.55152 -1.906845 50.54832
18.10033 36.65100 -1.926385 50.12914
18.15033 36.74826 -1.945744 50.17566
18.20033 36.84728 -1.961900 50.01510
18.25033 36.94565 -1.981099 50.06885
18.30033 37.04400 -2.001474 49.91311
18.35033 37.14130 -2.022684 50.08784
18.40033 37.24088 -2.045846 49.82466
18.45033 37.33849 -2.075701 49.84690
18.50033 37.43478 -2.107953 49.81683
18.55033 37.53333 -2.137978 49.94326
18.60033 37.63052 -2.168067 50.13111
18.65033 37.72840 -2.201669 49.83703
18.70033 37.82605 -2.231787 49.90824
18.75033 37.92231 -2.258900 50.03336
18.80033 38.02038 -2.286087 49.83616
18.85033 38.11921 -2.306294 50.02942
18.90033 38.21669 -2.334224 50.00230
18.95033 38.31453 -2.352912 50.10020
19.00033 38.41302 -2.371637 49.91110
19.05033 38.51113 -2.389629 50.11824
19.10033 38.61003 -2.405500 50.05243
19.15033 38.70937 -2.416818 49.97766
19.20033 38.80768 -2.430962 50.24421
19.25033 38.90703 -2.443004 49.95284
19.30033 39.00556 -2.454380 50.02813
19.35033 39.10464 -2.464790 50.11496
19.40033 39.20380 -2.475138 49.98192
19.45033 39.30202 -2.486491 49.97991
19.50033 39.40183 -2.497916 49.76163
19.55033 39.50105 -2.508345 50.02731
19.60033 39.60040 -2.519152 50.01630
19.65033 39.69870 -2.529663 49.88562
19.70033 39.79800 -2.539430 49.98987
19.75033 39.89778 -2.548366 49.75334
19.80033 39.99720 -2.557096 50.00388
19.85033 40.09589 -2.563986 49.93872
19.90033 40.19630 -2.569067 49.97589
19.95033 40.29796 -2.571052 49.90258
20.00033 40.39871 -2.566358 50.00487
20.05033 40.50097 -2.529338 50.12072
20.10033 40.60390 -2.453772 50.01975
20.15033 40.70950 -2.350963 50.15717
20.20033 40.81680 -2.242886 49.93097
20.25033 40.92534 -2.125782 49.89678
20.30033 41.03402 -2.015116 50.00482
20.35033 41.14382 -1.913502 49.85594
20.40033 41.25142 -1.825319 49.85998
20.45033 41.35828 -1.740306 49.81094
20.50033 41.46536 -1.676192 49.96370
20.55033 41.57076 -1.619409 49.81398
20.60033 41.67390 -1.569493 49.84580
20.65033 41.77974 -1.529864 49.84770
20.70033 41.88333 -1.496543 50.14917
20.75033 41.98456 -1.470116 49.87126
20.80033 42.08778 -1.448121 50.12510
20.85033 42.18959 -1.431313 49.98754
20.90033 42.29150 -1.415516 50.06844
20.95033 42.39288 -1.405408 49.98942
21.00033 42.49402 -1.395936 49.91562
21.05033 42.59395 -1.386856 50.13804
21.10033 42.69548 -1.378158 49.88944
21.15033 42.79578 -1.370051 50.17270
21.20033 42.89602 -1.362339 50.10282
21.25033 42.99592 -1.354990 49.90518
21.30033 43.09754 -1.348033 50.03234
21.35033 43.19639 -1.341886 49.89312
21.40033 43.29754 -1.336559 50.03213
21.45033 43.39874 -1.332071 50.04984
21.50033 43.49688 -1.328326 50.16597
21.55033 43.59697 -1.325125 50.01418
21.60033 43.69766 -1.322575 50.08426
21.65033 43.79852 -1.320580 49.89281
21.70033 43.89858 -1.318964 50.12532
21.75033 43.99768 -1.317878 50.09062
21.80033 44.09800 -1.317195 49.99942
21.85033 44.19765 -1.316950 49.96726
21.90033 44.29811 -1.316846 49.86287
21.95033 44.39820 -1.317017 49.98518
22.00033 44.49850 -1.317410 49.98664
22.05033 44.59771 -1.317947 49.95094
22.10033 44.69836 -1.318742 49.98418
22.15033 44.79770 -1.319474 50.03146
22.20033 44.89752 -1.320176 50.02325
22.25033 44.99874 -1.321202 49.96490
22.30033 45.09757 -1.322336 50.08252
22.35033 45.19766 -1.323319 49.95896
22.40033 45.29746 -1.324685 49.85855
22.45033 45.39691 -1.326206 49.98224
22.50033 45.49752 -1.327667 49.95988
22.55033 45.59649 -1.328966 50.12179
22.60033 45.69583 -1.330428 49.94060
22.65033 45.79663 -1.331764 50.05142
22.70033 45.89665 -1.333058 50.16850
22.75033 45.99581 -1.334551 50.07910
22.80033 46.09524 -1.336083 50.02850
22.85033 46.19542 -1.337636 49.98994
22.90033 46.29566 -1.339384 50.01403
22.95033 46.39604 -1.340973 49.94426
23.00033 46.49498 -1.342849 50.07306
23.05033 46.59578 -1.344358 50.00492
23.10033 46.69470 -1.346010 50.01720
23.15033 46.79470 -1.347594 49.92468
23.20033 46.89587 -1.349090 50.01165
23.25033 46.99356 -1.350819 50.05984
23.30033 47.09438 -1.352250 50.12489
23.35033 47.19287 -1.353756 49.96280
23.40033 47.29292 -1.355040 50.08578
23.45033 47.39246 -1.356302 50.02746
23.50033 47.49219 -1.357526 50.16686
23.55033 47.59301 -1.358823 50.08512
23.60033 47.69250 -1.360439 50.06420
23.65033 47.79187 -1.362344 49.98623
23.70033 47.89258 -1.364318 49.93038
23.75033 47.99194 -1.366192 50.03684
23.80033 48.09170 -1.368180 49.88108
23.85033 48.19133 -1.370433 50.03625
23.90033 48.29248 -1.372419 49.93580
23.95033 48.39122 -1.374540 49.99248
24.00033 48.49188 -1.376154 49.91554
24.05033 48.59170 -1.378050 50.10194
24.10033 48.69136 -1.379967 49.95350
24.15033 48.79134 -1.381704 50.00214
24.20033 48.89148 -1.383177 50.02581
24.25033 48.99062 -1.384594 49.85013
24.30033 49.09198 -1.386480 49.92912
24.35033 49.19096 -1.388534 50.06912
24.40033 49.29141 -1.390573 50.02630
24.45033 49.39094 -1.392918 49.98973
24.50033 49.49036 -1.395012 49.93566
24.55033 49.58996 -1.396924 50.06611
24.60033 49.69024 -1.398776 49.86066
24.65033 49.78981 -1.400523 49.90174
24.70033 49.88876 -1.402030 50.06652
24.75033 49.98830 -1.403464 49.92884
24.80033 50.08738 -1.405122 50.03492
24.85033 50.18790 -1.406728 49.99420
24.90033 50.28854 -1.408606 49.93072
24.95033 50.38742 -1.410639 49.91478
25.00033 50.48660 -1.412612 49.94775
25.05033 50.58689 -1.414902 49.98754
25.10033 50.68630 -1.417399 50.07850
25.15033 50.78700 -1.419560 50.07198
25.20033 50.88643 -1.422018 49.82840
25.25033 50.98581 -1.424445 50.07965
25.30033 51.08660 -1.426894 49.93252
25.35033 51.18704 -1.429315 50.02153
25.40033 51.28736 -1.431530 50.06840
25.45033 51.38657 -1.433789 49.75262
25.50033 51.48694 -1.435972 49.94352
25.55033 51.58638 -1.438160 50.19465
25.60033 51.68603 -1.440119 49.95769
25.65033 51.78546 -1.442346 49.92153
25.70033 51.88634 -1.444442 50.06710
25.75033 51.98570 -1.446606 49.95090
25.80033 52.08543 -1.448472 50.10242
25.85033 52.18491 -1.450536 50.13890
25.90033 52.28523 -1.452223 49.93547
25.95033 52.38407 -1.453901 50.08080
26.00033 52.48392 -1.455834 49.96697
26.05033 52.58312 -1.457953 50.08536
26.10033 52.68345 -1.459833 49.97318
26.15033 52.78198 -1.462194 50.01982
26.20033 52.88272 -1.464557 49.81086
26.25033 52.98310 -1.467082 49.87991
26.30033 53.08314 -1.469604 49.93694
26.35033 53.18261 -1.471980 49.87902
26.40033 53.28258 -1.474499 50.06284
26.45033 53.38168 -1.476901 49.94320
26.50033 53.48198 -1.479441 50.05796
26.55033 53.58169 -1.482004 50.06958
26.60033 53.68154 -1.484295 50.03766
26.65033 53.78050 -1.486602 50.22674
26.70033 53.87958 -1.488555 50.12976
26.75033 53.98023 -1.490728 49.93565
26.80033 54.07922 -1.493013 49.90930
26.85033 54.17944 -1.495400 49.93237
26.90033 54.27821 -1.497993 50.10776
26.95033 54.37854 -1.500470 49.89990
27.00033 54.47839 -1.502976 50.14993
27.05033 54.57858 -1.505673 50.13194
27.10033 54.67822 -1.508315 50.05176
27.15033 54.77789 -1.511188 49.95545
27.20033 54.87835 -1.513658 49.81811
27.25033 54.97832 -1.516425 49.88550
27.30033 55.07879 -1.519065 50.08566
27.35033 55.17828 -1.521702 49.96552
27.40033 55.27665 -1.524616 50.01524
27.45033 55.37778 -1.527177 49.97237
27.50033 55.47714 -1.530203 50.07776
27.55033 55.57809 -1.532784 50.06687
27.60033 55.67578 -1.535337 49.95723
27.65033 55.77732 -1.537965 50.13102
27.70033 55.87778 -1.540328 50.12645
27.75033 55.97613 -1.542929 50.11368
27.80033 56.07722 -1.545309 49.91068
27.85033 56.17578 -1.547990 49.82799
27.90033 56.27568 -1.550354 49.72236
27.95033 56.37639 -1.552893 50.12021
28.00033 56.47571 -1.555564 49.97525
28.05033 56.57543 -1.558322 49.97623
28.10033 56.67515 -1.561039 49.96326
28.15033 56.77515 -1.563784 49.97218
28.20033 56.87394 -1.566452 50.05490
28.25033 56.97474 -1.569099 49.87522
28.30033 57.07385 -1.571528 49.88239
28.35033 57.17402 -1.574171 49.91496
28.40033 57.27291 -1.577004 49.89383
28.45033 57.37312 -1.579569 49.88276
28.50033 57.47232 -1.582252 49.91500
28.55033 57.57184 -1.584788 49.94380
28.60033 57.67113 -1.587530 50.09200
28.65033 57.77171 -1.590329 50.07641
28.70033 57.87125 -1.593154 50.09997
28.75033 57.97026 -1.595691 50.00610
28.80033 58.06998 -1.598413 50.19413
28.85033 58.17002 -1.600963 49.89704
28.90033 58.26968 -1.604182 50.06839
28.95033 58.36990 -1.607039 49.96125
29.00033 58.47024 -1.610060 50.05250
29.05033 58.57085 -1.613094 49.98476
29.10033 58.67030 -1.616134 49.83075
29.15033 58.76916 -1.619118 49.95266
29.20033 58.86918 -1.622229 49.84338
29.25033 58.96885 -1.625296 49.97490
29.30033 59.06814 -1.628474 50.11246
29.35033 59.16848 -1.631456 50.06898
29.40033 59.26872 -1.634488 50.04154
29.45033 59.36688 -1.637370 49.98429
29.50033 59.46739 -1.640508 49.95204
29.55033 59.56398 -1.644140 49.91711
29.60033 59.63352 -1.631970 50.04310
29.65033 59.68265 -1.525925 50.05056
29.70033 59.71986 -1.417352 49.84117
29.75033 59.74948 -1.305550 50.04478
29.80033 59.77585 -1.205278 50.06154
29.85033 59.79500 -1.113658 50.02633
29.90033 59.81232 -1.033642 49.86508
29.95033 59.82628 -0.9623712 50.01157
30.00033 59.83996 -0.9001781 50.06793
30.05033 59.84942 -0.8521836 50.04016
30.10033 59.85793 -0.8040463 50.05500
30.15033 59.86448 -0.7664126 50.03394
30.20033 59.87005 -0.7359179 49.89412
30.25033 59.87476 -0.7119897 50.12358
30.30033 59.87991 -0.6887102 50.05515
30.35033 59.88322 -0.6723782 50.13287
30.40033 59.88637 -0.6588310 49.95126
30.45033 59.88891 -0.6469624 50.00183
30.50033 59.89291 -0.6376375 49.98318
30.55033 59.89380 -0.6290288 49.86874
30.60033 59.89587 -0.6211400 49.94466
30.65033 59.89834 -0.6132359 50.04671
30.70033 59.89965 -0.6062674 49.80434
30.75033 59.90049 -0.5986670 50.10450
30.80033 59.90234 -0.5922812 50.02750
30.85033 59.90441 -0.5865088 50.10780
30.90033 59.90294 -0.5814020 49.97708
30.95033 59.90575 -0.5765970 49.90502
31.00033 59.90675 -0.5724476 50.36198
31.05033 59.90594 -0.5685890 50.25297
31.10033 59.90732 -0.5650120 50.04011
31.15033 59.90811 -0.5616505 50.10010
31.20033 59.90809 -0.5585093 50.09700
31.25033 59.90884 -0.5558834 49.84742
31.30033 59.90974 -0.5534348 49.86908
31.35033 59.91035 -0.5511094 50.20642
31.40033 59.91060 -0.5492382 49.99561
31.45033 59.91050 -0.5475628 50.15256
31.50033 59.91226 -0.5459864 49.95946
31.55033 59.91261 -0.5443496 49.96357
31.60033 59.91186 -0.5429869 49.92971
31.65033 59.91260 -0.5417004 50.24072
31.70033 59.91368 -0.5405391 49.95635
31.75033 59.91229 -0.5393976 50.05893
31.80033 59.91236 -0.5384360 50.02494
31.85034 59.91163 -0.5376253 49.93428
31.90033 59.91334 -0.5364643 49.88878
31.95033 59.91340 -0.5356826 49.95769
32.00033 59.91220 -0.5347942 49.92433
32.05033 59.91254 -0.5337493 49.93444
32.10034 59.91347 -0.5329242 49.90988
32.15033 59.91290 -0.5324024 50.04020
32.20033 59.91370 -0.5319412 49.80697
32.25033 59.91320 -0.5320106 50.16369
32.30033 59.91426 -0.5316646 50.11214
32.35034 59.91590 -0.5314550 50.09646
32.40033 59.91528 -0.5311982 50.13128
32.45033 59.91560 -0.5310969 49.80485
-2.000000 1.000000 0.0000000 0.0000000
32.54700 59.91234 -0.5313848 50.21281
32.59700 59.88600 -0.5152625 50.02960
32.64700 59.83474 -0.3960714 50.00769
32.69700 59.77156 -0.2811008 49.81406
32.74700 59.70004 -0.1630854 49.89133
32.79700 59.62479 -.05652870 49.98783
32.84700 59.54590 0.03745472 49.92972
32.89700 59.46235 0.1216096 49.99800
32.94700 59.37560 0.1943542 50.04766
32.99700 59.28736 0.2600502 49.88097
33.04700 59.19684 0.3181125 50.10972
33.09700 59.10359 0.3645641 50.16788
33.14700 59.01244 0.4060794 49.99716
33.19700 58.91888 0.4396004 50.04314
33.24700 58.82490 0.4659058 50.00370
33.29700 58.72695 0.4907746 49.84544
33.34700 58.63158 0.5109804 49.94386
33.39700 58.53486 0.5292084 50.01234
33.44700 58.43838 0.5414170 49.92500
33.49700 58.34112 0.5557172 50.06947
33.54700 58.24091 0.5660149 50.04494
33.59700 58.14440 0.5761780 50.12017
33.64700 58.04680 0.5836418 50.13254
33.69700 57.94671 0.5917059 49.97876
33.74700 57.84809 0.6002332 50.15184
33.79700 57.74946 0.6075639 50.00970
33.84700 57.65264 0.6150050 49.96404
33.89700 57.55369 0.6227722 50.02303
33.94700 57.45400 0.6295470 49.98126
33.99700 57.35404 0.6359340 50.01465
34.04700 57.25641 0.6422956 49.90562
34.09700 57.15730 0.6481506 50.07834
34.14700 57.05706 0.6541472 50.14875
34.19700 56.95891 0.6599151 50.06885
34.24700 56.85904 0.6652682 50.10888
34.29700 56.76104 0.6705555 50.00438
34.34700 56.65997 0.6756443 49.88129
34.39700 56.56182 0.6803241 50.03829
34.44700 56.46219 0.6848447 50.13108
34.49700 56.36184 0.6892066 50.09459
34.54700 56.26318 0.6935241 50.01291
34.59700 56.16222 0.6977548 50.11241
34.64700 56.06412 0.7024855 50.00163
34.69700 55.96504 0.7064088 50.04364
34.74700 55.86413 0.7103093 50.08219
34.79700 55.76478 0.7142764 49.95248
34.84700 55.66596 0.7182412 49.98582
34.89700 55.56564 0.7221272 50.19718
34.94700 55.46739 0.7258843 50.10196
34.99700 55.36736 0.7296870 49.95170
35.04700 55.26928 0.7333851 50.08047
35.09700 55.16774 0.7367372 50.19581
35.14700 55.06816 0.7400957 49.95794
35.19700 54.96914 0.7434276 49.92506
35.24700 54.86940 0.7469721 50.03324
35.29700 54.77107 0.7503418 50.13200
35.34700 54.67080 0.7534826 50.11894
35.39700 54.57150 0.7564952 49.94722
35.44700 54.47190 0.7595728 50.05362
35.49700 54.37063 0.7624291 49.81793
35.54700 54.27115 0.7653549 50.17078
35.59700 54.17305 0.7682764 49.93920
35.64700 54.07408 0.7712211 49.96372
35.69700 53.97300 0.7741968 50.12616
35.74700 53.87348 0.7770844 49.90847
35.79700 53.77343 0.7799561 49.93106
35.84700 53.67384 0.7825116 50.02488
35.89700 53.57430 0.7854049 50.13172
35.94700 53.47566 0.7881509 49.91772
35.99700 53.37466 0.7908847 50.08074
36.04700 53.27622 0.7933876 50.08896
36.09700 53.17649 0.7958050 50.07693
36.14700 53.07623 0.7983196 49.93656
36.19700 52.97646 0.8006019 49.96846
36.24700 52.87622 0.8032226 50.05356
36.29700 52.77762 0.8056892 49.97662
36.34700 52.67691 0.8080139 49.99692
36.39700 52.57747 0.8104828 50.10380
36.44700 52.47749 0.8130462 50.07340
36.49700 52.37815 0.8154975 50.00232
36.54700 52.27859 0.8180269 49.93911
36.59700 52.17840 0.8206564 49.85988
36.64700 52.07964 0.8237176 50.11300
36.69700 51.97973 0.8260999 50.03365
36.74700 51.87959 0.8289278 49.93493
36.79700 51.78009 0.8314243 49.86179
36.84700 51.67972 0.8338374 49.91776
36.89700 51.57981 0.8363649 49.91824
36.94700 51.47982 0.8387490 50.07719
36.99700 51.38183 0.8409613 50.00352
37.04700 51.28124 0.8430757 49.90976
37.09700 51.18130 0.8452446 50.12225
37.14700 51.08246 0.8472657 50.08791
37.19700 50.98236 0.8493968 50.01541
37.24700 50.88243 0.8516488 49.86190
37.29700 50.78268 0.8539928 50.00023
37.34700 50.68320 0.8559246 50.00383
37.39700 50.58467 0.8582431 49.87376
37.44700 50.48281 0.8605405 50.17741
37.49700 50.38364 0.8628124 50.02746
37.54700 50.28516 0.8651226 50.02012
37.59700 50.18396 0.8670868 50.10754
37.64700 50.08390 0.8695326 50.01269
37.69700 49.98474 0.8714843 49.93070
37.74700 49.88564 0.8737174 50.10632
37.79700 49.78610 0.8760421 50.04285
37.84700 49.68716 0.8781488 50.13025
37.89700 49.58533 0.8802879 49.99680
37.94700 49.48636 0.8825689 49.93442
37.99700 49.38672 0.8847540 49.87358
38.04700 49.28698 0.8869881 49.99888
38.09700 49.18690 0.8892938 50.08521
38.14700 49.08926 0.8910747 50.00366
38.19700 48.98730 0.8929975 50.11789
38.24700 48.88741 0.8948662 50.00190
38.29700 48.78726 0.8968934 49.79613
38.34700 48.68996 0.8989462 50.21774
38.39700 48.58840 0.9006311 50.05523
38.44700 48.48900 0.9027046 50.12272
38.49700 48.38817 0.9048880 50.02624
38.54700 48.28752 0.9071746 50.01739
38.59700 48.18862 0.9095691 49.93521
38.64700 48.08768 0.9115939 50.03218
38.69700 47.98871 0.9137080 50.13671
38.74700 47.88974 0.9155469 49.95394
38.79700 47.79078 0.9175431 50.08616
38.84700 47.68994 0.9194296 50.15622
38.89700 47.59006 0.9213108 49.96958
38.94700 47.48855 0.9230542 49.94328
38.99700 47.39116 0.9249419 49.89254
39.04700 47.29012 0.9267086 49.86246
39.09700 47.19144 0.9286001 50.02134
39.14700 47.09058 0.9302579 50.02590
39.19700 46.99106 0.9321686 49.96096
39.24700 46.89294 0.9341528 50.14111
39.29700 46.79312 0.9359468 50.01091
39.34700 46.69178 0.9378136 50.01724
39.39700 46.59254 0.9397884 49.98873
39.44700 46.49273 0.9418778 50.04561
39.49700 46.39110 0.9441330 50.04476
39.54700 46.29252 0.9460175 50.00370
39.59700 46.19288 0.9481141 49.95860
39.64700 46.09340 0.9497837 49.98742
39.69700 45.99328 0.9517894 49.93042
39.74700 45.89367 0.9533738 50.03232
39.79700 45.79483 0.9550957 49.95586
39.84700 45.69504 0.9567101 50.07022
39.89700 45.59390 0.9582172 50.05916
39.94700 45.49530 0.9598578 49.87480
39.99700 45.39458 0.9612372 50.16201
40.04700 45.29534 0.9626147 50.13422
40.09700 45.19719 0.9640728 50.01558
40.14700 45.09558 0.9655144 49.98738
40.19700 44.99668 0.9670132 49.97403
40.24700 44.89664 0.9683063 50.13254
40.29700 44.79717 0.9700358 49.99398
40.34700 44.69648 0.9715997 50.08579
40.39700 44.59828 0.9730066 49.90435
40.44700 44.49932 0.9747962 49.90958
40.49700 44.39735 0.9763982 49.97398
40.54700 44.29806 0.9782170 49.89453
40.59700 44.19778 0.9796978 50.02812
40.64700 44.09821 0.9812759 50.04106
40.69700 43.99914 0.9829101 49.90456
40.74700 43.89810 0.9844247 50.16744
40.79700 43.79828 0.9860978 49.89366
40.84700 43.69962 0.9877876 49.90650
40.89700 43.59879 0.9894676 50.11054
40.94700 43.49953 0.9912712 49.89002
40.99700 43.39934 0.9929632 49.98912
41.04700 43.29996 0.9947628 49.96246
41.09700 43.20004 0.9964981 50.14896
41.14700 43.09970 0.9982784 50.01328
41.19700 42.99948 0.9999765 49.93633
41.24700 42.89961 1.001574 50.05650
41.29700 42.79844 1.003002 50.11772
41.34700 42.70113 1.004595 50.01239
41.39700 42.59979 1.005863 49.93698
41.44700 42.50106 1.007153 50.03222
41.49700 42.40146 1.008594 50.03432
41.54700 42.30213 1.009881 50.08328
41.59700 42.20027 1.011158 49.95936
41.64700 42.10160 1.012330 50.00308
41.69700 42.00126 1.013609 49.85536
41.74700 41.90180 1.014845 49.90302
41.79700 41.80422 1.016206 50.01922
41.84700 41.70174 1.017525 49.83517
41.89700 41.60330 1.018961 49.92204
41.94700 41.50336 1.020398 49.90263
41.99700 41.40371 1.021737 49.90141
42.04700 41.30333 1.022998 49.91456
42.09700 41.20307 1.024265 50.08879
42.14700 41.10281 1.025574 49.94594
42.19700 41.00284 1.026788 49.86181
42.24700 40.90540 1.028400 49.95964
42.29700 40.80352 1.029419 50.02100
42.34700 40.70512 1.030790 49.96781
42.39700 40.60495 1.032210 49.83952
42.44700 40.50412 1.033342 49.86775
42.49700 40.40690 1.034795 50.08676
42.54700 40.30432 1.035853 49.99770
42.59700 40.20414 1.037183 49.93070
42.64700 40.10510 1.038557 50.13600
42.69700 40.00418 1.040122 49.91072
42.74700 39.90563 1.041289 49.99403
42.79700 39.80538 1.042652 50.15336
42.84700 39.70730 1.043830 49.93168
42.89700 39.60496 1.044969 49.78369
42.94700 39.50579 1.046031 50.04761
42.99700 39.40645 1.047234 50.01837
43.04700 39.30802 1.048389 50.02512
43.09700 39.20906 1.049610 49.83425
43.14700 39.10628 1.050544 49.82611
43.19700 39.00794 1.052449 49.95268
43.24700 38.90579 1.053564 50.01752
43.29700 38.80647 1.054865 50.15430
43.34700 38.70697 1.056082 50.00783
43.39700 38.60570 1.057173 50.17812
43.44700 38.50737 1.058245 49.97003
43.49700 38.40730 1.059375 49.89192
43.54700 38.30808 1.060414 50.16485
43.59700 38.20948 1.061562 50.12113
43.64700 38.11014 1.062575 49.94951
43.69700 38.00886 1.063545 50.11197
43.74700 37.90700 1.064417 49.81418
43.79700 37.80893 1.065629 50.00380
43.84700 37.70949 1.066246 49.94078
43.89700 37.60902 1.067368 49.84060
43.94700 37.50877 1.068508 49.90542
43.99700 37.40830 1.069639 49.90720
44.04700 37.31080 1.071044 50.00511
44.09700 37.20810 1.072321 49.99982
44.14700 37.11024 1.073804 49.97873
44.19700 37.00960 1.074851 49.87015
44.24700 36.91158 1.076260 49.91801
44.29700 36.80906 1.077265 49.92140
44.34700 36.71025 1.078632 49.95780
44.39700 36.61026 1.079944 49.94716
44.44700 36.51124 1.081434 50.01034
44.49700 36.41150 1.082803 50.05396
44.54700 36.31149 1.084462 50.00172
44.59700 36.21059 1.086481 50.03938
44.64700 36.11276 1.088949 50.02297
44.69700 36.01255 1.093071 50.09838
44.74700 35.91270 1.098503 49.98110
44.79700 35.81381 1.111872 49.97938
44.84700 35.71622 1.152382 50.07674
44.89700 35.62010 1.221256 49.91010
44.94700 35.52425 1.311649 50.00074
44.99700 35.43228 1.449240 50.10862
45.04700 35.34271 1.633393 50.02090
45.09700 35.25925 1.879791 49.97867
45.14700 35.17735 2.177592 50.14326
45.19700 35.10391 2.540998 49.92007
45.24700 35.03130 2.939497 49.91637
45.29700 34.96590 3.341624 49.91744
45.34700 34.89744 3.731928 49.96808
45.39700 34.82614 4.058530 50.04468
45.44700 34.75254 4.295665 50.03947
45.49700 34.67186 4.438750 49.97624
45.54700 34.58256 4.484034 50.02190
45.59700 34.48514 4.463460 50.06567
45.64700 34.38402 4.368226 50.02074
45.69700 34.27630 4.222717 50.13348
45.74700 34.16622 4.051462 49.88644
45.79700 34.05353 3.875762 50.14571
45.84700 33.93848 3.679145 49.85246
45.89700 33.82204 3.467080 50.14570
45.94700 33.70530 3.258080 50.03214
45.99700 33.58968 3.043870 50.16724
46.04700 33.47144 2.827422 49.96150
46.09700 33.35322 2.636608 49.94152
46.14700 33.23846 2.452887 49.96706
46.19700 33.12416 2.298840 50.02445
46.24700 33.01197 2.172865 49.98740
46.29700 32.90118 2.046073 50.00096
46.34700 32.79130 1.919236 49.84724
46.39700 32.67878 1.793259 50.09524
46.44700 32.56976 1.697170 49.89004
46.49700 32.46187 1.598083 50.05269
46.54700 32.35523 1.524386 50.04844
46.59700 32.24895 1.457910 49.90417
46.64700 32.14255 1.403450 49.88774
46.69700 32.03850 1.362870 49.97322
46.74700 31.93567 1.327090 50.05140
46.79700 31.83368 1.303087 50.05120
46.84700 31.73076 1.278654 50.07376
46.89700 31.62799 1.259284 49.97556
46.94700 31.52647 1.243279 49.97656
46.99700 31.42470 1.232184 50.02416
47.04700 31.32358 1.221328 49.94209
47.09700 31.22405 1.213115 50.01046
47.14700 31.12304 1.206013 49.93411
47.19700 31.02191 1.199212 50.14891
47.24700 30.92166 1.192599 50.11188
47.29700 30.81962 1.186447 50.11998
47.34700 30.72052 1.181212 49.99452
47.39700 30.61902 1.175992 49.99869
47.44700 30.52126 1.171641 49.85984
47.49700 30.42022 1.167701 49.92231
47.54700 30.32075 1.163961 49.88915
47.59700 30.21928 1.161031 49.93350
47.64700 30.12049 1.158576 49.88616
47.69700 30.01861 1.156623 49.99121
47.74700 29.91950 1.155067 49.84992
47.79700 29.81898 1.153620 50.10502
47.84700 29.71790 1.152285 50.00930
47.89700 29.61984 1.151510 49.88976
47.94700 29.51921 1.150256 50.00610
47.99700 29.42014 1.149411 49.93818
48.04700 29.31912 1.148422 50.03606
48.09700 29.22009 1.147587 50.06702
48.14700 29.12033 1.147140 49.91348
48.19700 29.01948 1.146567 50.05478
48.24700 28.91928 1.146364 49.84539
48.29700 28.81925 1.145972 49.92206
48.34700 28.71861 1.145991 50.09718
48.39700 28.62229 1.145924 49.97688
48.44700 28.52093 1.145449 49.85275
48.49700 28.41941 1.145331 50.02861
48.54700 28.32178 1.145391 49.95273
48.59700 28.22126 1.145440 49.88657
48.64700 28.12076 1.145562 50.01748
48.69700 28.02014 1.145553 49.88389
48.74700 27.92128 1.145536 50.20054
48.79700 27.82070 1.145652 50.06880
48.84700 27.72026 1.146048 50.07188
48.89700 27.62020 1.146517 50.01127
48.94700 27.52050 1.146752 50.20854
48.99700 27.42100 1.147409 50.05474
49.04700 27.31966 1.147939 49.91276
49.09700 27.22102 1.148484 50.02502
49.14700 27.12064 1.149091 50.01477
49.19700 27.02007 1.149620 49.86742
49.24700 26.91970 1.150139 49.94287
49.29700 26.82082 1.150624 50.09633
49.34700 26.72082 1.150900 49.85762
49.39700 26.62040 1.151232 49.89491
49.44700 26.52030 1.151294 49.93870
49.49700 26.42133 1.151709 50.17332
49.54700 26.32117 1.151732 49.93348
49.59700 26.22153 1.152040 49.79579
49.64700 26.12312 1.152257 50.08490
49.69700 26.02262 1.152264 50.09906
49.74700 25.92203 1.152493 49.94009
49.79700 25.82238 1.152861 50.07024
49.84700 25.72261 1.153170 49.88214
49.89700 25.62384 1.153224 49.96637
49.94700 25.52348 1.153462 50.10044
49.99700 25.42548 1.154213 50.14800
50.04700 25.32467 1.154544 49.91269
50.09700 25.22320 1.155113 49.88440
50.14700 25.12338 1.155633 50.02858
50.19700 25.02380 1.156258 49.78980
50.24700 24.92208 1.157034 49.82590
50.29700 24.82447 1.157667 49.96328
50.34700 24.72342 1.158327 49.93632
50.39700 24.62390 1.158784 49.91079
50.44700 24.52346 1.159011 50.05722
50.49700 24.42392 1.159204 49.97937
50.54700 24.32368 1.159562 50.06554
50.59700 24.22438 1.160151 49.97824
50.64700 24.12517 1.160978 49.93578
50.69700 24.02441 1.161492 50.01533
50.74700 23.92497 1.162266 50.12121
50.79700 23.82305 1.162890 50.13606
50.84700 23.72330 1.163614 50.02558
50.89700 23.62558 1.164346 50.08188
50.94700 23.52437 1.164684 49.82083
50.99700 23.42476 1.165236 50.06682
51.04700 23.32207 1.165429 50.17910
51.09700 23.22410 1.166094 50.12570
51.14700 23.12383 1.166503 49.85742
51.19700 23.02279 1.166539 50.09063
51.24700 22.92384 1.167001 49.97153
51.29700 22.82494 1.167350 50.14120
51.34700 22.72296 1.167757 49.89496
51.39700 22.62551 1.167883 50.10580
51.44700 22.52395 1.168152 50.00545
51.49700 22.42566 1.168361 50.14197
51.54700 22.32555 1.168511 50.08359
51.59700 22.22640 1.168599 49.92597
51.64700 22.12465 1.168631 50.15380
51.69700 22.02468 1.168873 50.00387
51.74700 21.92454 1.168718 50.08866
51.79700 21.82491 1.169092 49.86914
51.84700 21.72663 1.169571 50.05706
51.89700 21.62555 1.169793 49.93176
51.94700 21.52470 1.170142 49.97916
51.99700 21.42802 1.170712 49.98044
52.04700 21.32524 1.170947 50.11466
52.09700 21.22609 1.171377 49.93403
52.14700 21.12604 1.171897 49.96050
52.19700 21.02642 1.172402 49.99219
52.24700 20.92550 1.172772 50.10006
52.29700 20.82490 1.172896 49.97229
52.34700 20.72515 1.173289 49.89366
52.39700 20.62728 1.173534 49.91989
52.44700 20.52582 1.173529 50.06043
52.49700 20.42763 1.173933 49.86120
52.54700 20.32680 1.174473 50.07852
52.59700 20.22711 1.174599 49.72242
52.64700 20.12510 1.174724 49.95084
52.69700 20.02617 1.174804 50.03111
52.74700 19.92804 1.175320 49.89708
52.79700 19.82758 1.175389 50.23021
52.84700 19.72908 1.175771 50.24674
52.89700 19.62618 1.176056 50.04862
52.94700 19.52692 1.175808 50.07666
52.99700 19.42680 1.176628 49.83400
53.04700 19.32546 1.176640 50.09449
53.09700 19.22725 1.177117 49.86875
53.14700 19.12721 1.177491 49.90696
53.19700 19.03030 1.177999 50.07062
53.24700 18.92880 1.177957 49.91772
53.29700 18.82796 1.178574 50.14260
53.34700 18.72821 1.178570 50.17959
53.39700 18.62982 1.179094 49.93378
53.44700 18.52653 1.179472 49.99140
53.49700 18.42759 1.179613 49.92854
53.54700 18.32705 1.179680 49.92960
53.59700 18.22885 1.179730 50.04968
53.64700 18.12741 1.179608 49.91758
53.69700 18.02760 1.179574 50.02058
53.74700 17.92888 1.179893 50.03388
53.79700 17.82907 1.179621 49.99484
53.84700 17.72931 1.179667 50.15339
53.89700 17.63000 1.179761 49.86750
53.94700 17.53108 1.179564 50.00162
53.99700 17.43085 1.179554 50.00940
54.04700 17.33101 1.179996 50.03205
54.09700 17.23074 1.180388 50.01428
54.14700 17.13168 1.180880 50.05000
54.19700 17.03073 1.181356 50.05867
54.24700 16.93013 1.181737 49.93698
54.29700 16.83031 1.182301 50.06140
54.34700 16.72901 1.182595 50.56622
54.39700 16.62889 1.182839 50.03076
54.44700 16.53042 1.183764 49.99392
54.49700 16.42958 1.184079 49.98904
54.54700 16.33049 1.184178 50.00904
54.59700 16.23122 1.184698 50.08961
54.64700 16.13123 1.184548 50.20200
54.69700 16.02978 1.184760 49.87362
54.74700 15.93091 1.184980 50.12808
54.79700 15.82978 1.184837 49.89125
54.84700 15.72934 1.184510 49.98076
54.89700 15.62970 1.184549 49.88833
54.94700 15.53242 1.185051 49.93234
54.99700 15.43286 1.185045 50.08470
55.04700 15.33076 1.185261 49.95062
55.09700 15.23021 1.185372 49.95557
55.14700 15.13223 1.185869 49.85358
55.19700 15.03203 1.186075 49.96214
55.24700 14.92859 1.185962 50.01476
55.29700 14.83071 1.186462 50.03697
55.34700 14.73093 1.186392 50.00830
55.39700 14.63130 1.186852 50.10054
55.44700 14.53016 1.187070 49.95917
55.49700 14.43133 1.187754 49.97957
55.54700 14.32883 1.186803 49.97111
55.59700 14.23046 1.188293 50.00907
55.64700 14.13301 1.188616 50.10998
55.69700 14.02974 1.188769 50.02164
55.74700 13.93124 1.188702 50.15054
55.79700 13.83046 1.188716 49.99354
55.84700 13.73063 1.188920 49.93436
55.89700 13.63179 1.188882 49.87113
55.94700 13.53077 1.188870 50.00506
55.99700 13.43140 1.188883 49.91858
56.04700 13.33074 1.189327 50.13254
56.09700 13.23247 1.189668 49.95067
56.14700 13.12968 1.189600 49.89922
56.19700 13.03090 1.189770 49.99526
56.24700 12.93026 1.189617 50.00436
56.29700 12.82947 1.189879 50.08861
56.34700 12.73141 1.189800 49.98933
56.39700 12.63068 1.189739 49.99990
56.44700 12.53234 1.189953 50.20889
56.49700 12.43226 1.189637 49.91504
56.54700 12.33163 1.189763 49.97408
56.59700 12.23041 1.190330 50.15709
56.64700 12.13004 1.190462 50.00369
56.69700 12.03348 1.190600 50.04617
56.74700 11.93347 1.190920 49.89367
56.79700 11.83107 1.190689 50.12529
56.84700 11.73154 1.190774 49.95886
56.89700 11.63226 1.190769 50.09006
56.94700 11.53200 1.190643 50.06936
56.99700 11.43452 1.191109 49.95624
57.04700 11.33187 1.190981 49.96287
57.09700 11.23279 1.190812 49.93793
57.14700 11.13247 1.190406 50.15804
57.19700 11.03559 1.190590 50.06630
57.24700 10.93215 1.190569 49.99347
57.29700 10.83542 1.190518 49.98391
57.34700 10.73516 1.190412 49.98687
57.39700 10.63474 1.190922 50.13026
57.44700 10.53318 1.190836 50.07900
57.49700 10.43191 1.191054 50.10406
57.54700 10.33302 1.191242 50.10593
57.59700 10.23287 1.191418 50.10000
57.64700 10.13289 1.191340 49.95066
57.69700 10.03570 1.191724 49.94140
57.74700 9.932862 1.191480 50.09604
57.79700 9.832849 1.191959 50.09792
57.84700 9.732482 1.192539 49.98940
57.89700 9.635204 1.191914 50.02124
57.94700 9.532845 1.191404 49.98170
57.99700 9.435668 1.191462 50.16574
58.04700 9.333048 1.191517 50.07936
58.09700 9.234043 1.191725 49.90526
58.14700 9.135662 1.191738 49.84150
58.19700 9.032688 1.191577 50.12724
58.24700 8.933320 1.191898 49.81474
58.29700 8.832351 1.191623 49.90562
58.34700 8.734228 1.191797 50.04139
58.39700 8.633508 1.191509 50.08652
58.44700 8.534492 1.192564 49.91067
58.49700 8.433141 1.192102 50.02480
58.54700 8.332781 1.191834 50.09750
58.59700 8.233380 1.192008 50.04700
58.64700 8.136055 1.192167 49.95250
58.69700 8.034049 1.192105 49.99638
58.74700 7.936684 1.192247 49.86020
58.79700 7.836057 1.192037 50.02545
58.84700 7.735047 1.191900 49.97906
58.89700 7.634869 1.191919 50.15408
58.94700 7.534474 1.191883 50.02826
58.99700 7.434980 1.191056 49.98494
59.04700 7.335525 1.191547 49.96909
59.09700 7.235193 1.192228 50.05360
59.14700 7.136260 1.192340 50.13182
59.19700 7.032662 1.192530 50.06240
59.24700 6.934155 1.192446 50.06002
59.29700 6.832024 1.192020 50.08944
59.34700 6.737300 1.193252 50.19075
59.39700 6.633212 1.193443 49.87011
59.44700 6.534339 1.193726 50.13160
59.49700 6.437866 1.193458 49.93362
59.54700 6.333549 1.193336 50.02412
59.59700 6.235618 1.193573 50.07153
59.64700 6.137750 1.193715 50.01715
59.69700 6.033738 1.193374 49.97992
59.74700 5.937820 1.193041 49.93617
59.79700 5.833882 1.192770 49.94597
59.84700 5.735193 1.193072 50.06154
59.89700 5.636141 1.193480 50.08034
59.94700 5.532329 1.192924 49.89558
59.99700 5.432947 1.192918 50.14385
60.04700 5.333700 1.193177 49.89552
60.09700 5.234254 1.193586 49.86125
60.14700 5.135418 1.193817 49.81390
60.19700 5.034148 1.193683 49.96959
60.24700 4.935558 1.193992 50.02371
60.29700 4.837316 1.194054 50.04547
60.34700 4.736359 1.193981 49.89250
60.39700 4.635588 1.193810 49.93959
60.44700 4.536252 1.194116 50.14367
60.49700 4.437068 1.193968 50.00830
60.54700 4.333424 1.193887 49.88478
60.59700 4.234175 1.193752 50.11085
60.64700 4.135887 1.193618 49.93176
60.69700 4.037305 1.193445 50.12361
60.74700 3.936856 1.193397 50.19218
60.79700 3.834987 1.193026 49.93794
60.84700 3.737420 1.192848 49.98875
60.89700 3.638239 1.192856 50.00817
60.94700 3.536256 1.192441 49.82484
60.99700 3.436008 1.192872 49.92276
61.04700 3.334424 1.192796 49.86486
61.09700 3.236186 1.192700 50.10056
61.14700 3.134048 1.192401 50.20756
61.19700 3.035760 1.192784 49.86624
61.24700 2.935273 1.192252 49.93408
61.29700 2.838713 1.192876 50.08498
61.34700 2.736398 1.192925 49.89308
61.39700 2.635040 1.193072 49.96570
61.44700 2.535516 1.192678 49.87378
61.49700 2.437367 1.193250 49.82981
61.54700 2.340114 1.193184 50.04342
61.59700 2.236834 1.192839 50.00195
61.64700 2.138886 1.192544 50.15310
61.69700 2.036559 1.192380 49.89864
61.74700 1.938904 1.192362 50.07958
61.79700 1.838320 1.192160 49.83585
61.84700 1.737454 1.192369 49.96598
61.89700 1.639084 1.192345 50.14690
61.94700 1.537144 1.192691 49.96306
61.99700 1.436754 1.192275 50.08278
62.04700 1.344318 1.194575 50.01384
62.09700 1.267000 1.163985 49.97807
62.14700 1.221013 1.070677 50.02948
62.19700 1.186038 0.9644868 49.98497
62.24700 1.155151 0.8672730 49.96147
62.29700 1.129806 0.7782585 49.89294
62.34700 1.108938 0.6874274 49.79148
62.39700 1.091271 0.6135005 50.04082
62.44700 1.079659 0.5398868 49.96291
62.49700 1.069385 0.4830500 49.98058
62.54700 1.056836 0.4297578 50.09446
62.59700 1.050986 0.3951808 50.03866
62.64700 1.041610 0.3533641 49.89510
62.69700 1.037683 0.3246443 49.89026
62.74700 1.033222 0.2969134 50.02988
62.79700 1.028636 0.2769742 49.79257
62.84700 1.023257 0.2595005 50.11774
62.89700 1.019714 0.2380414 49.89024
62.94700 1.016035 0.2254524 50.11378
62.99700 1.016474 0.2174748 49.99198
63.04700 1.011551 0.2082762 49.94172
63.09700 1.010624 0.1961730 49.97640
63.14700 1.011475 0.1913474 50.09257
63.19700 1.011113 0.1844525 49.92475
63.24700 1.007597 0.1789992 49.94082
63.29700 1.007166 0.1743944 50.09550
63.34700 1.004422 0.1677244 50.12740
63.39700 1.004545 0.1613336 50.02981
63.44700 1.002653 0.1580398 50.00553
63.49700 1.004395 0.1550940 49.97376
63.54700 1.001837 0.1519674 50.07464
63.59700 1.001574 0.1483132 50.06659
63.64700 1.002012 0.1463179 49.92813
63.69700 0.9999725 0.1434908 49.87174
63.74700 1.001976 0.1413147 50.31398
63.79700 1.002765 0.1395474 50.24942
63.84700 0.9975206 0.1369987 50.06524
63.89700 0.9996222 0.1353333 49.99156
63.94700 0.9960080 0.1338910 49.75150
63.99700 0.9970559 0.1322641 50.17146
64.04700 1.000063 0.1316275 49.92770
64.09700 0.9966099 0.1292074 50.01394
64.14700 0.9953539 0.1278574 50.24358
64.19701 0.9955201 0.1269710 49.96879
64.24700 0.9984330 0.1264068 49.82062
64.29700 1.000332 0.1257233 50.06150
64.34700 0.9940701 0.1222308 49.87860
64.39700 0.9944991 0.1221820 50.09231
64.44701 0.9958850 0.1218288 49.01354
64.49700 0.9957962 0.1215806 49.95070
64.54700 0.9947458 0.1211680 49.98328
64.59700 0.9935253 0.1206386 50.04276
64.64700 0.9991424 0.1206078 49.88022
64.69701 0.9978392 0.1200648 49.85889
64.74700 0.9959922 0.1190679 49.80998
64.79700 0.9957236 0.1189252 50.06210
-2.000000 2.000000 0.0000000 0.0000000