File: imagens/notebooks/dados experimentais/dsc/Karl_CTAB300 Ur 45%.txt
CLOSED
Version	1.0
Language	English
Run	1
RunSerial	152
Instrument	DSC Q100 V9.9 Build 303
Module	DSC Standard Cell FC
Operator	LL
File	\\Niger\ta\Data\DSC\2018\Geral\Karl_CTAB300 Ur 45%.001
ProcName	Karl
InstSerial	0100-1211
Sample	CTAB300 Ur 45%
Size	13.2700	mg
Method	Karl
Comment
Xcomment	Pan: Aluminum Hermetic
Xcomment	Gas1: Nitrogen 50.0 ml/min
Xcomment	Gas2: Nitrogen 0.0 ml/min
Text
Exotherm	UP
Kcell	1.09030
Calib	-11.7822
TempCal	1	pts	158.71	156.60
TzeroDt	-90.0515 -0.0093 2.2263
TzeroDtz	-90.0515 0.0466 2.4421
InstCalFile	Tzero: \\Niger\ta\Data\DSC\CALIBRATION\20122016\CALIBRATION\0_RCS_12_20_2016 17_23_31.TZR
InstCalFile	Baseline: \\Niger\ta\Data\DSC\CALIBRATION\20122016\L.Base 20122016
InstCalFile	Sapphire: \\Niger\ta\Data\DSC\CALIBRATION\20122016\Safira 20122017.001
InstCalDate	Tzero 2016-12-20 Time 19:23:31
TempRange	-90.04 to 395.23 °C at 19.96 °C/min Heat Only
AutoZero	Delta T Offset 0.000 uV
AutoZero	Delta T0 Offset 0.000 uV
Controls	Gas 1  Event Off  Sampling 0.2
Cell#	FC-02451
CoolingUnit	RCS
SelHeatFlow	Heat Flow T4 (mW)
AutoAnalysis	Off
MacroFile
Nsig	4
Sig1	Time (min)
Sig2	Temperature (°C)
Sig3	Heat Flow (mW)
Sig4	Sample Purge Flow (mL/min)
Date	2018-05-17
Time	10:43:36
OrgMethod	1: Equilibrate at 1.00 °C
OrgMethod	2: Ramp 2.00 °C/min to 60.00 °C
OrgMethod	3: Isothermal for 3.00 min
OrgMethod	4: Mark end of cycle 1
OrgMethod	5: Ramp 2.00 °C/min to 1.00 °C
OrgMethod	6: Isothermal for 3.00 min
OrgMethod	7: Mark end of cycle 2
OrgFile	C:\TA\Data\DSC\2018\Geral\Karl_CTAB300 Ur 45%.001
3.33324E-4 1.166373 1.183240 50.12829
0.05033332 1.153388 1.044015 49.90376
0.1003333 1.164912 0.8666588 49.96368
0.1503333 1.202857 0.6628554 50.00950
0.2003333 1.252756 0.4553522 49.97144
0.2503333 1.309466 0.2582457 49.86828
0.3003333 1.374581 0.07531112 49.88224
0.3503333 1.443180 -.09377722 49.78940
0.4003334 1.515334 -0.2449861 49.95285
0.4503334 1.593107 -0.3779876 49.96778
0.5003334 1.673488 -0.4934131 49.89548
0.5503332 1.756008 -0.5964262 50.01116
0.6003332 1.840975 -0.6877188 49.88489
0.6503332 1.926763 -0.7649570 50.01761
0.7003332 2.015422 -0.8330684 49.98816
0.7503332 2.104417 -0.8902644 50.10362
0.8003332 2.195610 -0.9420849 50.07498
0.8503332 2.287415 -0.9843563 49.99373
0.9003332 2.381180 -1.020780 49.87256
0.9503334 2.473662 -1.053909 49.91598
1.000333 2.568990 -1.085192 49.94780
1.050334 2.663529 -1.108665 49.97702
1.100334 2.759261 -1.127656 50.07924
1.150334 2.854388 -1.146479 49.98344
1.200334 2.951043 -1.162419 50.00317
1.250334 3.047700 -1.175873 49.96804
1.300334 3.143818 -1.187507 49.93578
1.350333 3.242192 -1.197909 50.03363
1.400333 3.339946 -1.207372 50.11230
1.450334 3.438052 -1.216476 49.98555
1.500333 3.535606 -1.225382 49.87133
1.550334 3.633499 -1.234302 49.91918
1.600334 3.732434 -1.243058 50.16844
1.650333 3.829906 -1.251529 50.08338
1.700334 3.928481 -1.259860 49.91352
1.750334 4.026318 -1.267479 49.99376
1.800334 4.126895 -1.274471 50.06052
1.850334 4.225261 -1.281024 49.97390
1.900334 4.323616 -1.287374 50.14918
1.950334 4.422394 -1.293247 50.09106
2.000334 4.522616 -1.298649 49.80646
2.050333 4.620617 -1.303616 50.08008
2.100334 4.719659 -1.308346 49.97669
2.150334 4.819281 -1.312646 49.93853
2.200334 4.917862 -1.316653 49.92998
2.250334 5.017570 -1.320474 50.08335
2.300333 5.116810 -1.323917 50.02615
2.350334 5.215674 -1.326950 49.98896
2.400334 5.314941 -1.330046 50.06384
2.450334 5.414485 -1.332955 49.89997
2.500334 5.512641 -1.335639 49.99130
2.550333 5.612393 -1.338177 50.02798
2.600333 5.712662 -1.340784 49.92650
2.650333 5.810986 -1.343041 50.10528
2.700333 5.910980 -1.345314 49.95272
2.750333 6.009269 -1.347473 49.91342
2.800333 6.108990 -1.349593 49.99791
2.850333 6.208550 -1.351569 50.31058
2.900333 6.308545 -1.353426 49.99940
2.950333 6.408438 -1.355278 50.16485
3.000333 6.508074 -1.356968 50.06448
3.050333 6.607562 -1.358768 50.16459
3.100333 6.707245 -1.360490 50.02187
3.150333 6.807035 -1.362138 49.93775
3.200333 6.906571 -1.363827 49.92088
3.250333 7.007012 -1.365440 49.91472
3.300333 7.106784 -1.367029 49.93291
3.350333 7.206009 -1.368352 49.84494
3.400333 7.305518 -1.369776 49.95758
3.450333 7.405228 -1.371033 49.89100
3.500333 7.503994 -1.372287 49.84840
3.550333 7.605194 -1.373624 50.00037
3.600333 7.704799 -1.374895 49.91556
3.650333 7.803978 -1.376062 49.90782
3.700333 7.904151 -1.377140 50.07467
3.750333 8.004231 -1.378250 49.81556
3.800333 8.104119 -1.379233 50.08181
3.850333 8.203368 -1.380012 49.99378
3.900333 8.303405 -1.380922 49.85618
3.950333 8.402650 -1.381708 50.04396
4.000333 8.502191 -1.382658 49.88709
4.050333 8.602309 -1.383466 50.01967
4.100333 8.701886 -1.384260 50.12567
4.150333 8.801912 -1.385315 49.87354
4.200333 8.903134 -1.386178 50.00136
4.250333 9.000849 -1.386804 49.97136
4.300333 9.101851 -1.387756 50.10988
4.350333 9.201281 -1.388516 50.00250
4.400333 9.301069 -1.389369 50.01800
4.450333 9.400406 -1.390207 50.00567
4.500333 9.499687 -1.390901 50.14472
4.550333 9.600574 -1.391583 49.93978
4.600333 9.700562 -1.392345 50.10796
4.650333 9.799745 -1.393134 50.02652
4.700333 9.900624 -1.393811 50.03490
4.750333 9.999962 -1.394511 49.93376
4.800333 10.09961 -1.395338 50.00500
4.850333 10.19963 -1.396012 50.12402
4.900333 10.29895 -1.396844 50.16080
4.950333 10.39917 -1.397528 49.86547
5.000333 10.49882 -1.398160 50.02640
5.050333 10.59867 -1.398914 49.97766
5.100333 10.69870 -1.399486 50.04680
5.150333 10.79808 -1.400170 50.06700
5.200333 10.89855 -1.400890 49.80020
5.250332 10.99828 -1.401606 49.90680
5.300332 11.09816 -1.402319 50.10534
5.350332 11.19810 -1.403016 49.93941
5.400332 11.29860 -1.403624 50.00613
5.450332 11.39771 -1.404207 49.90191
5.500332 11.49708 -1.404867 49.98170
5.550332 11.59783 -1.405374 49.84114
5.600332 11.69711 -1.406157 50.08259
5.650332 11.79689 -1.406590 49.85309
5.700332 11.89758 -1.407109 49.97860
5.750332 11.99668 -1.407712 49.85382
5.800332 12.09696 -1.408265 50.04190
5.850332 12.19706 -1.408900 49.96609
5.900332 12.29709 -1.409381 50.13433
5.950332 12.39785 -1.409985 50.15844
6.000332 12.49715 -1.410591 50.06662
6.050332 12.59682 -1.411136 49.95890
6.100332 12.69690 -1.411722 49.95436
6.150332 12.79697 -1.412158 50.03320
6.200332 12.89614 -1.412616 50.02902
6.250332 12.99684 -1.413116 49.88089
6.300332 13.09630 -1.413511 49.79060
6.350332 13.19635 -1.413881 49.92403
6.400332 13.29636 -1.414402 49.87372
6.450332 13.39581 -1.414842 50.09858
6.500332 13.49646 -1.415303 50.08572
6.550332 13.59568 -1.415703 49.95742
6.600332 13.69510 -1.416058 50.03450
6.650332 13.79554 -1.416599 50.02690
6.700332 13.89526 -1.417208 50.05692
6.750332 13.99534 -1.417881 49.90494
6.800332 14.09547 -1.418469 49.95569
6.850332 14.19437 -1.419118 50.19944
6.900332 14.29467 -1.419515 50.07110
6.950332 14.39518 -1.420167 49.96390
7.000332 14.49471 -1.420549 50.04117
7.050332 14.59478 -1.421020 50.07757
7.100332 14.69507 -1.421512 50.14240
7.150332 14.79531 -1.421870 50.10904
7.200332 14.89448 -1.422320 49.74965
7.250332 14.99462 -1.422852 49.98252
7.300332 15.09435 -1.423340 49.87696
7.350332 15.19455 -1.423920 49.89458
7.400332 15.29446 -1.424504 50.03136
7.450332 15.39378 -1.424955 49.91272
7.500332 15.49397 -1.425365 49.98549
7.550332 15.59515 -1.425811 50.07490
7.600332 15.69398 -1.426249 50.07474
7.650332 15.79451 -1.426647 49.94926
7.700332 15.89418 -1.427091 50.03461
7.750332 15.99384 -1.427699 50.07706
7.800332 16.09396 -1.428093 50.07434
7.850332 16.19390 -1.428605 49.90928
7.900332 16.29363 -1.429026 49.94023
7.950332 16.39301 -1.429681 50.02280
8.000334 16.49332 -1.430208 50.06440
8.050332 16.59408 -1.430772 50.08986
8.100332 16.69437 -1.431213 49.94168
8.150332 16.79409 -1.431643 50.18958
8.200332 16.89344 -1.432125 50.03030
8.250334 16.99384 -1.432730 49.83722
8.300332 17.09389 -1.433488 50.00470
8.350332 17.19306 -1.434088 50.04837
8.400332 17.29418 -1.434730 50.08164
8.450332 17.39373 -1.435304 49.91903
8.500334 17.49394 -1.435936 49.96698
8.550332 17.59449 -1.436379 49.98778
8.600332 17.69364 -1.436952 49.94889
8.650332 17.79400 -1.437444 49.97638
8.700332 17.89345 -1.437832 50.05857
8.750334 17.99381 -1.438215 50.13274
8.800332 18.09341 -1.438471 49.87904
8.850332 18.19342 -1.438688 49.91636
8.900332 18.29364 -1.439014 49.95027
8.950332 18.39287 -1.439366 50.13182
9.000334 18.49430 -1.439459 50.00086
9.050332 18.59378 -1.439626 50.00622
9.100332 18.69286 -1.439886 49.84343
9.150332 18.79250 -1.440214 50.18890
9.200332 18.89254 -1.440760 49.86974
9.250334 18.99220 -1.441030 50.01910
9.300332 19.09226 -1.441624 50.04312
9.350332 19.19262 -1.441984 49.88847
9.400332 19.29241 -1.442380 50.01126
9.450332 19.39108 -1.442729 50.09037
9.500334 19.49166 -1.443134 49.91336
9.550332 19.59123 -1.443320 50.02176
9.600332 19.69125 -1.443694 49.96440
9.650332 19.79006 -1.444225 49.77578
9.700332 19.89134 -1.444744 49.92880
9.750334 19.99129 -1.445149 49.97556
9.800332 20.09106 -1.445586 50.15283
9.850332 20.19049 -1.446146 50.08859
9.900332 20.29025 -1.446650 50.00244
9.950332 20.39082 -1.447330 49.94720
10.00033 20.49106 -1.447994 50.07424
10.05033 20.59020 -1.448735 49.91848
10.10033 20.69046 -1.449349 49.89144
10.15033 20.78994 -1.450203 50.07030
10.20033 20.89038 -1.450872 50.03904
10.25033 20.98975 -1.451588 49.95582
10.30033 21.08908 -1.452207 50.00744
10.35033 21.18980 -1.452776 50.14678
10.40033 21.28902 -1.453421 50.04643
10.45033 21.38950 -1.453971 49.99304
10.50034 21.48960 -1.454670 50.08947
10.55033 21.58893 -1.455230 50.09680
10.60033 21.69022 -1.455996 49.93981
10.65033 21.78928 -1.456594 49.99223
10.70033 21.89004 -1.457230 49.98897
10.75034 21.98910 -1.458081 49.97119
10.80033 22.08895 -1.458718 49.90428
10.85033 22.18936 -1.459456 50.16441
10.90033 22.28994 -1.460018 50.15124
10.95033 22.38912 -1.460772 49.96864
11.00034 22.48861 -1.461394 50.02130
11.05033 22.58858 -1.461968 49.93072
11.10033 22.68896 -1.462576 49.89806
11.15033 22.78856 -1.463358 49.87450
11.20033 22.88836 -1.464128 50.11626
11.25034 22.98828 -1.464991 50.10724
11.30033 23.08920 -1.465864 49.98487
11.35033 23.18838 -1.466792 50.01832
11.40033 23.28802 -1.467759 49.96054
11.45033 23.38800 -1.468344 50.00871
11.50034 23.48782 -1.469241 50.01690
11.55033 23.58683 -1.470157 49.97797
11.60033 23.68582 -1.471163 49.95848
11.65033 23.78564 -1.472238 49.87838
11.70033 23.88486 -1.473631 50.01790
11.75034 23.98510 -1.475499 50.03213
11.80033 24.08415 -1.477950 49.95510
11.85033 24.18318 -1.480689 50.04744
11.90033 24.28401 -1.484214 49.99717
11.95033 24.38212 -1.488341 49.89416
12.00034 24.48123 -1.493250 50.05980
12.05033 24.58114 -1.499133 50.01134
12.10033 24.68092 -1.505838 49.81922
12.15033 24.78015 -1.514624 49.89324
12.20033 24.87910 -1.526256 49.90646
12.25034 24.97787 -1.539981 49.94491
12.30033 25.07664 -1.558497 49.96668
12.35033 25.17561 -1.580926 49.87856
12.40033 25.27394 -1.606334 49.97739
12.45033 25.37233 -1.634043 49.92958
12.50034 25.46959 -1.667485 50.02816
12.55033 25.56732 -1.699831 49.96430
12.60033 25.66602 -1.735627 49.93574
12.65033 25.76204 -1.769886 50.22149
12.70033 25.85964 -1.804204 49.97108
12.75034 25.95745 -1.839714 49.84954
12.80033 26.05416 -1.876575 50.00972
12.85033 26.15134 -1.912938 50.13946
12.90033 26.24860 -1.949116 50.07621
12.95034 26.34585 -1.983570 49.95846
13.00034 26.44287 -2.017599 49.80241
13.05033 26.53945 -2.053206 49.92201
13.10033 26.63750 -2.086370 49.95303
13.15033 26.73495 -2.115367 49.88660
13.20034 26.83169 -2.146670 49.97031
13.25034 26.93006 -2.174686 50.13696
13.30033 27.02770 -2.200326 49.97704
13.35033 27.12426 -2.224705 50.01624
13.40033 27.22240 -2.250238 49.91738
13.45034 27.32120 -2.274540 50.01145
13.50034 27.41863 -2.294159 50.17047
13.55033 27.51710 -2.316463 49.91257
13.60033 27.61448 -2.337002 50.01050
13.65033 27.71272 -2.354446 50.11344
13.70034 27.81161 -2.370926 50.03738
13.75034 27.90918 -2.388005 50.06680
13.80033 28.00832 -2.402925 50.04465
13.85033 28.10608 -2.418828 49.99228
13.90033 28.20474 -2.432326 50.06003
13.95034 28.30397 -2.445650 50.09192
14.00034 28.40233 -2.459398 50.08500
14.05033 28.50138 -2.471620 50.05074
14.10033 28.60136 -2.481840 49.84402
14.15033 28.70080 -2.492270 49.95166
14.20034 28.80028 -2.502506 50.15650
14.25034 28.89888 -2.512775 50.02813
14.30033 28.99751 -2.522514 50.09148
14.35033 29.09660 -2.532248 50.06566
14.40033 29.19662 -2.542054 49.95136
14.45034 29.29576 -2.551282 50.17446
14.50034 29.39538 -2.560175 50.03051
14.55033 29.49524 -2.568925 50.11467
14.60033 29.59383 -2.577154 50.02600
14.65033 29.69352 -2.585189 50.07397
14.70034 29.79356 -2.592695 49.92676
14.75034 29.89350 -2.599880 50.14053
14.80033 29.99204 -2.606604 50.07981
14.85033 30.09220 -2.612892 49.97672
14.90033 30.19200 -2.618878 50.03672
14.95034 30.29084 -2.624445 49.88938
15.00034 30.39064 -2.629462 49.90551
15.05033 30.49114 -2.634191 49.96694
15.10033 30.59037 -2.638396 50.06891
15.15033 30.68854 -2.642181 50.08780
15.20034 30.78998 -2.645718 49.91828
15.25034 30.88900 -2.649091 49.89346
15.30033 30.98837 -2.651974 49.96416
15.35033 31.08807 -2.654945 50.03281
15.40033 31.18736 -2.657663 50.10287
15.45034 31.28816 -2.660482 50.00422
15.50034 31.38705 -2.663338 50.03602
15.55033 31.48782 -2.665919 50.09686
15.60033 31.58655 -2.668837 50.01386
15.65033 31.68704 -2.671831 50.04117
15.70034 31.78620 -2.675070 49.88731
15.75034 31.88582 -2.678366 49.97794
15.80033 31.98554 -2.682140 50.05150
15.85033 32.08424 -2.686343 50.01430
15.90033 32.18414 -2.691037 50.05636
15.95034 32.28364 -2.696240 49.91993
16.00033 32.38403 -2.701946 50.10406
16.05033 32.48242 -2.708386 50.06848
16.10033 32.58178 -2.715482 49.83107
16.15033 32.68080 -2.722792 50.04160
16.20033 32.78089 -2.730719 50.12440
16.25033 32.87882 -2.738992 49.80106
16.30033 32.97848 -2.747862 50.07798
16.35033 33.07722 -2.757036 50.03428
16.40033 33.17633 -2.766682 49.94474
16.45033 33.27534 -2.776440 49.95685
16.50033 33.37502 -2.786942 49.98776
16.55033 33.47426 -2.797410 50.16504
16.60033 33.57306 -2.807245 49.76471
16.65033 33.67242 -2.817094 50.11632
16.70033 33.77084 -2.827015 50.01768
16.75033 33.87045 -2.836972 49.88544
16.80033 33.96932 -2.846383 50.00072
16.85033 34.06982 -2.855774 50.03145
16.90033 34.16946 -2.865004 50.08229
16.95033 34.26775 -2.874374 49.93346
17.00033 34.36750 -2.883374 50.11793
17.05033 34.46714 -2.892030 50.06950
17.10033 34.56606 -2.900740 50.08686
17.15033 34.66493 -2.909097 49.97660
17.20033 34.76550 -2.917032 49.91425
17.25033 34.86454 -2.925024 50.02379
17.30033 34.96365 -2.932707 49.83496
17.35033 35.06330 -2.940030 50.09641
17.40033 35.16270 -2.947140 49.98362
17.45033 35.26230 -2.954059 50.10904
17.50033 35.36145 -2.960848 50.05152
17.55033 35.46109 -2.967570 49.98230
17.60033 35.56066 -2.973926 50.06361
17.65033 35.65933 -2.980171 49.91122
17.70033 35.75970 -2.986516 50.13360
17.75033 35.85910 -2.992715 49.88819
17.80033 35.95780 -2.998710 50.06821
17.85033 36.05813 -3.004675 50.09569
17.90033 36.15595 -3.010633 50.06070
17.95033 36.25590 -3.016890 49.99441
18.00033 36.35639 -3.022514 49.95850
18.05033 36.45596 -3.028268 49.82130
18.10033 36.55496 -3.034096 49.87748
18.15033 36.65451 -3.039658 50.03031
18.20033 36.75553 -3.045176 49.94070
18.25033 36.85467 -3.050572 49.91576
18.30033 36.95355 -3.055758 50.05124
18.35033 37.05338 -3.060920 49.89378
18.40033 37.15306 -3.066162 49.93804
18.45033 37.25212 -3.071238 49.92294
18.50033 37.35250 -3.076378 50.01448
18.55033 37.45220 -3.081595 50.14610
18.60033 37.55139 -3.086758 49.89437
18.65033 37.65060 -3.091926 50.02090
18.70033 37.75075 -3.097068 50.16264
18.75033 37.84964 -3.102320 50.01534
18.80033 37.94957 -3.107456 49.88592
18.85033 38.04970 -3.112876 49.85292
18.90033 38.15009 -3.118118 49.91296
18.95033 38.24910 -3.123607 49.97330
19.00033 38.34790 -3.129174 50.13640
19.05033 38.44897 -3.134564 49.94690
19.10033 38.54894 -3.140232 50.03230
19.15033 38.64812 -3.145750 50.02315
19.20033 38.74667 -3.151191 49.94837
19.25033 38.84755 -3.156368 49.90054
19.30033 38.94624 -3.161202 50.09252
19.35033 39.04641 -3.165897 50.08234
19.40033 39.14613 -3.170645 50.03630
19.45033 39.24524 -3.175535 49.88090
19.50033 39.34481 -3.180325 49.80946
19.55033 39.44441 -3.184946 50.05813
19.60033 39.54396 -3.189412 49.98538
19.65033 39.64389 -3.193618 49.88250
19.70033 39.74237 -3.197800 49.95222
19.75033 39.84325 -3.202157 50.02223
19.80033 39.94230 -3.206267 50.06413
19.85033 40.04192 -3.210081 49.97113
19.90033 40.14105 -3.213680 50.04204
19.95033 40.24125 -3.217222 50.08731
20.00033 40.34059 -3.220562 49.90866
20.05033 40.44122 -3.223593 49.99912
20.10033 40.54013 -3.226548 49.97340
20.15033 40.64050 -3.229502 49.98472
20.20033 40.73996 -3.232412 49.87867
20.25033 40.83946 -3.235532 50.16763
20.30033 40.93864 -3.238785 49.94312
20.35033 41.03920 -3.242178 50.11330
20.40033 41.13804 -3.245625 50.05266
20.45033 41.23877 -3.248699 49.85000
20.50033 41.33772 -3.251418 49.87490
20.55033 41.43875 -3.252531 49.84030
20.60033 41.53951 -3.249621 50.08053
20.65033 41.64120 -3.236528 49.95989
20.70033 41.74324 -3.211826 50.04054
20.75033 41.84438 -3.178406 49.96552
20.80033 41.94747 -3.145783 49.85002
20.85033 42.04980 -3.107013 50.04929
20.90033 42.15328 -3.069060 49.92312
20.95033 42.25530 -3.027252 50.06616
21.00033 42.35850 -2.982308 50.08638
21.05033 42.46224 -2.934192 49.96419
21.10033 42.56572 -2.880725 49.88083
21.15033 42.67032 -2.822146 50.09028
21.20033 42.77403 -2.751910 49.91299
21.25033 42.88000 -2.679887 50.01496
21.30033 42.98602 -2.591214 50.01720
21.35033 43.09182 -2.501593 49.99912
21.40033 43.19926 -2.402712 50.07428
21.45033 43.30752 -2.301424 49.85666
21.50033 43.41537 -2.202208 49.93856
21.55033 43.52252 -2.109058 49.96462
21.60033 43.63118 -2.019206 50.03049
21.65033 43.73794 -1.939260 50.05410
21.70033 43.84402 -1.876152 50.09067
21.75033 43.94965 -1.817276 50.07590
21.80033 44.05476 -1.771192 49.97146
21.85033 44.15861 -1.729752 50.02320
21.90033 44.26134 -1.696616 49.97882
21.95033 44.36453 -1.666080 49.86861
22.00033 44.46766 -1.642938 49.99470
22.05033 44.56942 -1.626389 50.08944
22.10033 44.67226 -1.609951 50.05837
22.15033 44.77308 -1.597259 49.94070
22.20033 44.87343 -1.587694 49.85469
22.25033 44.97520 -1.579420 49.89420
22.30033 45.07620 -1.571184 50.01342
22.35033 45.17576 -1.563238 49.93045
22.40033 45.27687 -1.555261 49.96616
22.45033 45.37762 -1.547930 49.99648
22.50033 45.47854 -1.541180 50.02515
22.55033 45.57800 -1.534780 50.18704
22.60033 45.67794 -1.529020 49.95044
22.65033 45.77838 -1.524008 50.17832
22.70033 45.87799 -1.519740 50.01778
22.75033 45.97894 -1.515869 49.90890
22.80033 46.07889 -1.512480 50.12062
22.85033 46.17918 -1.509574 50.07705
22.90033 46.27958 -1.507026 50.01474
22.95033 46.37889 -1.504796 49.84600
23.00033 46.47952 -1.502698 50.06504
23.05033 46.57932 -1.500941 49.97656
23.10033 46.67982 -1.499479 50.04414
23.15033 46.77902 -1.498081 50.06512
23.20033 46.87914 -1.496884 50.05500
23.25033 46.97876 -1.495872 50.00660
23.30033 47.07910 -1.495030 50.12366
23.35033 47.17884 -1.494266 49.89348
23.40033 47.27855 -1.493718 50.08506
23.45033 47.37910 -1.493499 50.02030
23.50033 47.47891 -1.493348 50.11080
23.55033 47.57884 -1.493356 49.94446
23.60033 47.67950 -1.493530 49.93491
23.65033 47.77891 -1.493768 50.11791
23.70033 47.87890 -1.494014 49.95934
23.75033 47.97828 -1.494137 50.02636
23.80033 48.07883 -1.494305 49.91582
23.85033 48.17836 -1.494403 50.15280
23.90033 48.27818 -1.494663 49.96744
23.95033 48.37952 -1.494898 50.03296
24.00033 48.47896 -1.495339 49.94680
24.05033 48.57828 -1.495625 50.12041
24.10033 48.67916 -1.496070 50.08041
24.15033 48.77840 -1.496571 49.86916
24.20033 48.87881 -1.496869 49.96826
24.25033 48.97870 -1.497233 50.12138
24.30033 49.07821 -1.497782 50.13459
24.35033 49.17879 -1.498298 50.09853
24.40033 49.27822 -1.499074 50.09360
24.45033 49.37878 -1.499736 50.03296
24.50033 49.47947 -1.500152 49.97966
24.55033 49.57803 -1.500520 50.08779
24.60033 49.67930 -1.500859 50.08471
24.65033 49.77842 -1.501231 50.03660
24.70033 49.87864 -1.501224 50.19441
24.75033 49.97853 -1.501447 49.81163
24.80033 50.07844 -1.501642 49.82072
24.85033 50.17856 -1.502005 50.05996
24.90033 50.27809 -1.502222 49.99664
24.95033 50.37740 -1.502608 49.88532
25.00033 50.47757 -1.503053 49.85717
25.05033 50.57822 -1.503194 49.84126
25.10033 50.67805 -1.503449 50.04510
25.15033 50.77794 -1.503746 49.89011
25.20033 50.87695 -1.503749 50.04668
25.25033 50.97720 -1.503853 50.11470
25.30033 51.07697 -1.504117 50.03566
25.35033 51.17748 -1.504558 49.92444
25.40033 51.27668 -1.504826 50.04068
25.45033 51.37684 -1.505141 49.93810
25.50033 51.47690 -1.505623 49.96924
25.55033 51.57666 -1.505840 50.08435
25.60033 51.67646 -1.506159 49.95526
25.65033 51.77600 -1.506535 49.95977
25.70033 51.87654 -1.506816 49.83717
25.75033 51.97704 -1.507201 49.87861
25.80033 52.07662 -1.507532 50.02232
25.85033 52.17722 -1.508051 49.93272
25.90033 52.27674 -1.508361 49.91515
25.95033 52.37683 -1.508711 49.89284
26.00033 52.47605 -1.508906 49.97760
26.05033 52.57622 -1.509206 50.05740
26.10033 52.67657 -1.509504 49.99283
26.15033 52.77703 -1.509834 49.99235
26.20033 52.87666 -1.510068 49.96389
26.25033 52.97659 -1.510276 49.91493
26.30033 53.07626 -1.510620 49.91364
26.35033 53.17674 -1.510724 49.97780
26.40033 53.27600 -1.511116 49.98170
26.45033 53.37624 -1.511591 49.95209
26.50033 53.47657 -1.512086 49.92746
26.55033 53.57563 -1.512428 50.01664
26.60033 53.67624 -1.512790 49.98344
26.65033 53.77592 -1.513299 49.97216
26.70033 53.87578 -1.513444 50.17440
26.75033 53.97521 -1.513489 49.92354
26.80033 54.07566 -1.513565 49.95806
26.85033 54.17549 -1.513577 49.97601
26.90033 54.27568 -1.513754 50.09698
26.95033 54.37546 -1.513844 49.91597
27.00033 54.47461 -1.513984 50.19301
27.05033 54.57566 -1.514191 49.84934
27.10033 54.67510 -1.514501 50.14746
27.15033 54.77474 -1.514871 49.93109
27.20033 54.87520 -1.515233 49.91086
27.25033 54.97393 -1.515748 50.02480
27.30033 55.07476 -1.516250 49.95352
27.35033 55.17392 -1.516934 50.15957
27.40033 55.27528 -1.517366 50.00370
27.45033 55.37444 -1.517728 49.99032
27.50033 55.47445 -1.518296 50.00152
27.55033 55.57450 -1.518772 49.98977
27.60033 55.67482 -1.519135 49.97124
27.65033 55.77436 -1.519247 49.94067
27.70033 55.87436 -1.519490 49.84140
27.75033 55.97528 -1.519689 50.09475
27.80033 56.07449 -1.519902 50.01448
27.85033 56.17456 -1.520259 50.19124
27.90033 56.27451 -1.520652 50.08636
27.95033 56.37482 -1.520978 50.09772
28.00033 56.47465 -1.521358 49.92497
28.05033 56.57441 -1.521716 50.05829
28.10033 56.67364 -1.522039 49.94334
28.15033 56.77410 -1.522294 49.98216
28.20033 56.87349 -1.522436 50.13430
28.25033 56.97348 -1.522542 50.02280
28.30033 57.07370 -1.523099 49.89375
28.35033 57.17282 -1.523496 49.93864
28.40033 57.27338 -1.524078 49.83152
28.45033 57.37287 -1.524802 49.83297
28.50033 57.47315 -1.525261 50.07046
28.55033 57.57232 -1.525821 50.08179
28.60033 57.67288 -1.526286 50.06982
28.65033 57.77305 -1.526609 49.93664
28.70033 57.87280 -1.526761 49.96425
28.75033 57.97200 -1.526904 50.05104
28.80033 58.07299 -1.526958 49.84869
28.85033 58.17276 -1.527337 50.04370
28.90033 58.27309 -1.527542 50.11250
28.95033 58.37328 -1.527838 49.99572
29.00033 58.47262 -1.528208 49.98678
29.05033 58.57276 -1.528644 49.98236
29.10033 58.67241 -1.528935 50.01208
29.15033 58.77280 -1.529283 49.87295
29.20033 58.87300 -1.529459 50.02533
29.25033 58.97304 -1.529849 49.99550
29.30033 59.07236 -1.530254 50.14010
29.35033 59.17222 -1.530611 50.05992
29.40033 59.27238 -1.531210 49.96008
29.45033 59.37128 -1.531570 50.02070
29.50033 59.47287 -1.531842 50.13684
29.55033 59.56810 -1.532651 49.94828
29.60033 59.64102 -1.500224 49.99622
29.65033 59.69132 -1.355328 50.20321
29.70033 59.73179 -1.216735 50.09359
29.75033 59.76456 -1.071279 49.98970
29.80033 59.79281 -0.9336997 50.13997
29.85033 59.81532 -0.8079304 50.06536
29.90033 59.83545 -0.6962671 50.08270
29.95033 59.85145 -0.5955000 50.06734
30.00033 59.86645 -0.5027592 50.05746
30.05033 59.87739 -0.4262815 50.11359
30.10033 59.88770 -0.3591110 49.95331
30.15033 59.89746 -0.3000276 49.92542
30.20033 59.90388 -0.2529366 49.90879
30.25033 59.91172 -0.2104472 50.08047
30.30033 59.91657 -0.1753922 50.09679
30.35033 59.92130 -0.1465946 49.92768
30.40033 59.92660 -0.1200984 49.88190
30.45033 59.92969 -.09919215 50.00058
30.50033 59.93313 -.08357254 49.89609
30.55033 59.93586 -.07004978 49.99580
30.60033 59.93820 -.05695470 49.98554
30.65033 59.94036 -.04785933 49.92139
30.70033 59.94243 -.03866666 49.90676
30.75033 59.94297 -.02987818 50.12298
30.80033 59.94529 -.02166184 49.84896
30.85033 59.94641 -.01352602 49.93526
30.90033 59.94780 -5.7185E-3 50.00711
30.95033 59.94855 .001925093 49.85708
31.00033 59.95012 .008899161 49.91968
31.05033 59.94986 0.01525632 49.92098
31.10033 59.95194 0.02109854 49.86638
31.15033 59.95165 0.02644048 49.89813
31.20033 59.95211 0.03140201 49.83463
31.25033 59.95262 0.03589478 49.98960
31.30033 59.95276 0.04004740 49.97775
31.35033 59.95476 0.04359780 50.16898
31.40033 59.95415 0.04695234 49.86951
31.45033 59.95398 0.04993635 50.02692
31.50033 59.95476 0.05273345 50.18123
31.55033 59.95489 0.05516682 49.97332
31.60033 59.95544 0.05723796 49.93662
31.65033 59.95464 0.05909994 49.89896
31.70033 59.95527 0.06065781 50.08554
31.75033 59.95588 0.06226552 49.95182
31.80033 59.95596 0.06340950 49.98600
31.85034 59.95656 0.06464270 49.97157
31.90033 59.95747 0.06536011 50.06516
31.95033 59.95644 0.06626539 50.07178
32.00033 59.95707 0.06694775 49.97404
32.05033 59.95782 0.06746850 49.98463
32.10034 59.95768 0.06810462 49.96800
32.15033 59.95754 0.06865380 50.05669
32.20033 59.95801 0.06923992 50.07692
32.25033 59.95739 0.06965386 49.93981
32.30033 59.95761 0.07003656 49.93030
32.35034 59.95834 0.07026894 50.02324
32.40033 59.95813 0.07065522 50.15747
32.45033 59.95928 0.07104144 50.13824
-2.000000 1.000000 0.0000000 0.0000000
32.54700 59.95637 0.07113189 50.10492
32.59700 59.93084 0.1013763 49.98504
32.64700 59.88098 0.2449362 49.99872
32.69700 59.82100 0.3857563 49.96872
32.74700 59.75272 0.5353819 49.87863
32.79700 59.68018 0.6753399 50.03666
32.84700 59.60322 0.8057504 49.91000
32.89700 59.52192 0.9163132 49.96586
32.94700 59.43757 1.026068 49.84906
32.99700 59.35289 1.113403 50.09750
33.04700 59.26385 1.193397 50.07660
33.09700 59.17498 1.261996 49.99087
33.14700 59.08279 1.320312 50.08816
33.19700 58.98956 1.371092 50.06960
33.24700 58.89687 1.411474 50.05890
33.29700 58.80115 1.446558 49.86160
33.34700 58.70558 1.475232 50.10476
33.39700 58.61040 1.497964 50.18433
33.44700 58.51357 1.517731 49.93980
33.49700 58.41711 1.535492 49.96231
33.54700 58.32041 1.547892 50.15787
33.59700 58.22100 1.559334 49.90059
33.64700 58.12457 1.569066 49.85053
33.69700 58.02684 1.577344 50.09844
33.74700 57.92756 1.586188 49.97744
33.79700 57.82966 1.594521 50.14703
33.84700 57.73070 1.602818 49.98816
33.89700 57.63215 1.610638 50.15291
33.94700 57.53295 1.618052 49.87338
33.99700 57.43460 1.625226 50.02194
34.04700 57.33550 1.631502 50.12146
34.09700 57.23678 1.637481 50.08586
34.14700 57.13670 1.643078 49.87070
34.19700 57.03722 1.648139 49.97932
34.24700 56.93865 1.652795 49.92529
34.29700 56.83912 1.656819 49.89052
34.34700 56.73974 1.660563 50.03992
34.39700 56.63970 1.663759 50.05026
34.44700 56.54032 1.666791 50.13415
34.49700 56.44003 1.669572 50.11098
34.54700 56.34156 1.671914 50.03131
34.59700 56.24065 1.674198 50.04889
34.64700 56.14238 1.676298 50.02276
34.69700 56.04141 1.678116 50.06083
34.74700 55.94246 1.679902 50.07196
34.79700 55.84230 1.681413 50.06950
34.84700 55.74312 1.682904 50.12039
34.89700 55.64325 1.684505 49.94441
34.94700 55.54456 1.685775 49.98484
34.99700 55.44343 1.687075 50.05127
35.04700 55.34524 1.688151 50.14921
35.09700 55.24510 1.689375 49.95184
35.14700 55.14492 1.690411 49.98250
35.19700 55.04576 1.691586 49.81128
35.24700 54.94586 1.692524 50.02990
35.29700 54.84656 1.693547 49.90624
35.34700 54.74636 1.694696 49.96512
35.39700 54.64641 1.695670 49.89046
35.44700 54.54650 1.696656 50.03588
35.49700 54.44695 1.697602 50.03156
35.54700 54.34739 1.698361 50.08074
35.59700 54.24761 1.699130 49.95130
35.64700 54.14736 1.699798 49.89836
35.69700 54.04760 1.700350 49.98244
35.74700 53.94834 1.701084 50.13555
35.79700 53.84788 1.701834 50.06704
35.84700 53.74834 1.702588 49.99735
35.89700 53.64807 1.703266 49.98374
35.94700 53.54871 1.704006 50.08284
35.99700 53.44840 1.704638 49.93934
36.04700 53.34908 1.705122 50.05700
36.09700 53.24984 1.705530 49.93862
36.14700 53.14910 1.706107 49.98929
36.19700 53.04834 1.706599 49.93985
36.24700 52.94971 1.706790 49.92088
36.29700 52.84925 1.706988 50.06006
36.34700 52.74924 1.707178 50.04602
36.39700 52.65040 1.707341 49.99086
36.44700 52.54990 1.707530 49.96364
36.49700 52.45010 1.707728 50.07278
36.54700 52.35049 1.708151 50.11846
36.59700 52.25000 1.708554 50.02691
36.64700 52.15006 1.708879 49.91957
36.69700 52.05122 1.709174 50.06951
36.74700 51.95058 1.709586 49.92574
36.79700 51.85122 1.709860 50.01116
36.84700 51.75104 1.710206 50.00648
36.89700 51.65176 1.710703 49.94359
36.94700 51.55168 1.711095 49.98020
36.99700 51.45092 1.711437 50.13386
37.04700 51.35172 1.711660 49.96998
37.09700 51.25165 1.712109 50.08808
37.14700 51.15170 1.712589 50.00328
37.19700 51.05184 1.713056 50.11279
37.24700 50.95238 1.713438 50.03276
37.29700 50.85205 1.713905 50.02638
37.34700 50.75259 1.714266 50.09550
37.39700 50.65266 1.714599 50.00858
37.44700 50.55274 1.714722 49.98828
37.49700 50.45346 1.715034 50.06850
37.54700 50.35250 1.715226 50.01337
37.59700 50.25366 1.715532 49.93854
37.64700 50.15250 1.715928 49.98516
37.69700 50.05339 1.716299 49.97719
37.74700 49.95426 1.716380 50.05624
37.79700 49.85297 1.716710 50.04083
37.84700 49.75283 1.716916 50.04898
37.89700 49.65316 1.717209 49.95683
37.94700 49.55352 1.717516 50.00680
37.99700 49.45369 1.717712 49.95618
38.04700 49.35344 1.717991 50.02280
38.09700 49.25362 1.718092 49.89072
38.14700 49.15422 1.718131 50.12394
38.19700 49.05376 1.718302 50.11596
38.24700 48.95430 1.718359 50.00044
38.29700 48.85410 1.718446 50.05776
38.34700 48.75458 1.718656 49.98240
38.39700 48.65542 1.718929 50.02174
38.44700 48.55396 1.719153 50.06124
38.49700 48.45429 1.719386 50.15580
38.54700 48.35494 1.719455 49.94656
38.59700 48.25498 1.719691 50.02066
38.64700 48.15450 1.719782 50.10516
38.69700 48.05466 1.719985 49.83280
38.74700 47.95550 1.720120 50.01778
38.79700 47.85584 1.720245 50.13959
38.84700 47.75541 1.720384 50.11542
38.89700 47.65578 1.720609 50.01504
38.94700 47.55554 1.720777 49.89037
38.99700 47.45633 1.721008 50.09131
39.04700 47.35649 1.721393 50.01549
39.09700 47.25584 1.721643 49.98201
39.14700 47.15619 1.721934 50.10828
39.19700 47.05590 1.722262 49.80876
39.24700 46.95588 1.722690 49.83870
39.29700 46.85742 1.723214 50.05394
39.34700 46.75732 1.723685 49.94160
39.39700 46.65557 1.724275 50.10235
39.44700 46.55797 1.724603 50.04348
39.49700 46.45670 1.724930 50.15044
39.54700 46.35720 1.725341 50.18250
39.59700 46.25722 1.725552 49.97228
39.64700 46.15625 1.725722 50.00343
39.69700 46.05686 1.726000 50.15358
39.74700 45.95737 1.725980 50.06928
39.79700 45.85698 1.726255 50.04840
39.84700 45.75709 1.726342 50.16032
39.89700 45.65713 1.726469 50.04851
39.94700 45.55727 1.726514 50.05117
39.99700 45.45833 1.726652 49.95678
40.04700 45.35742 1.726806 49.96324
40.09700 45.25762 1.726905 49.89900
40.14700 45.15715 1.727008 49.98119
40.19700 45.05884 1.727019 49.86631
40.24700 44.95872 1.727038 50.02611
40.29700 44.85903 1.727049 50.08896
40.34700 44.75894 1.727152 50.08524
40.39700 44.65943 1.727373 49.96894
40.44700 44.55861 1.727552 49.99712
40.49700 44.45856 1.727781 50.03552
40.54700 44.35884 1.727947 49.99715
40.59700 44.25867 1.728137 49.93852
40.64700 44.15878 1.728240 49.89748
40.69700 44.05912 1.728316 49.91632
40.74700 43.95928 1.728332 50.06774
40.79700 43.85976 1.728565 49.96467
40.84700 43.75973 1.728709 50.08902
40.89700 43.65957 1.728996 49.82725
40.94700 43.55972 1.729216 50.05004
40.99700 43.45972 1.729343 50.12678
41.04700 43.36033 1.729534 49.93306
41.09700 43.26004 1.729789 50.12725
41.14700 43.15946 1.730026 50.04145
41.19700 43.06088 1.730180 49.88547
41.24700 42.95945 1.730404 50.03344
41.29700 42.86056 1.730714 50.08559
41.34700 42.76056 1.730826 50.07024
41.39700 42.66050 1.731101 49.94652
41.44700 42.56116 1.731328 49.97506
41.49700 42.46087 1.731503 50.06703
41.54700 42.36050 1.731627 50.11754
41.59700 42.26096 1.731749 49.84797
41.64700 42.16081 1.732182 49.97315
41.69700 42.06110 1.732478 49.92324
41.74700 41.96104 1.732800 49.98639
41.79700 41.86087 1.732825 49.87994
41.84700 41.76172 1.732915 50.03846
41.89700 41.66080 1.732978 50.02098
41.94700 41.56039 1.732961 50.08656
41.99700 41.46175 1.732894 50.05285
42.04700 41.36120 1.732951 50.07694
42.09700 41.26041 1.732960 50.01231
42.14700 41.16088 1.732915 49.95088
42.19700 41.06089 1.732939 50.07701
42.24700 40.96164 1.732938 50.07754
42.29700 40.86146 1.732978 49.92791
42.34700 40.76129 1.732933 49.94496
42.39700 40.66172 1.732876 49.97486
42.44700 40.56169 1.732785 50.14084
42.49700 40.46197 1.732631 50.19576
42.54700 40.36188 1.732522 49.95262
42.59700 40.26202 1.732532 50.03350
42.64700 40.16151 1.732514 49.87760
42.69700 40.06302 1.732592 49.99006
42.74700 39.96280 1.732650 49.96128
42.79700 39.86346 1.732802 49.82200
42.84700 39.76352 1.732996 49.98750
42.89700 39.66333 1.733256 49.89762
42.94700 39.56344 1.733401 50.08203
42.99700 39.46365 1.733459 49.95338
43.04700 39.36304 1.733661 49.96950
43.09700 39.26394 1.733726 50.00464
43.14700 39.16296 1.733804 50.05550
43.19700 39.06356 1.733916 50.06950
43.24700 38.96356 1.734131 49.84116
43.29700 38.86356 1.734292 50.01547
43.34700 38.76354 1.734594 49.95201
43.39700 38.66290 1.734913 50.07030
43.44700 38.56414 1.735169 50.00777
43.49700 38.46294 1.735444 49.86406
43.54700 38.36365 1.735517 50.06268
43.59700 38.26342 1.735565 49.93276
43.64700 38.16363 1.735548 49.99100
43.69700 38.06412 1.735561 50.09424
43.74700 37.96375 1.735547 50.06418
43.79700 37.86430 1.735451 50.12856
43.84700 37.76344 1.735542 50.03000
43.89700 37.66509 1.735523 50.13360
43.94700 37.56490 1.735350 49.77496
43.99700 37.46479 1.735484 49.98636
44.04700 37.36490 1.735463 49.87720
44.09700 37.26480 1.735551 49.84659
44.14700 37.16510 1.735548 49.82196
44.19700 37.06470 1.735566 49.94126
44.24700 36.96492 1.735757 49.99370
44.29700 36.86548 1.735726 50.13678
44.34700 36.76560 1.735797 49.97772
44.39700 36.66498 1.735964 49.89697
44.44700 36.56528 1.736206 49.96837
44.49700 36.46494 1.736520 50.05296
44.54700 36.36621 1.737094 50.02137
44.59700 36.26534 1.737928 50.00054
44.64700 36.16648 1.738725 49.95110
44.69700 36.06636 1.740183 50.08957
44.74700 35.96660 1.742407 49.97828
44.79700 35.86707 1.745444 49.99250
44.84700 35.76775 1.750311 50.03174
44.89700 35.66945 1.760098 50.17754
44.94700 35.56948 1.782329 50.02926
44.99700 35.47292 1.826969 49.98871
45.04700 35.37462 1.885652 50.04218
45.09700 35.27956 1.955606 50.09441
45.14700 35.18498 2.040559 50.01192
45.19700 35.09224 2.146014 49.85568
45.24700 34.99994 2.270815 49.95840
45.29700 34.91061 2.404135 49.89040
45.34700 34.82226 2.560112 50.10069
45.39700 34.73422 2.734774 49.87668
45.44700 34.64932 2.911300 50.03891
45.49700 34.56416 3.096215 49.92730
45.54700 34.47898 3.290198 49.81776
45.59700 34.39460 3.482815 49.84162
45.64700 34.31015 3.671779 49.92984
45.69700 34.22687 3.852196 50.02016
45.74700 34.14033 4.034256 50.04246
45.79700 34.05459 4.200476 50.12516
45.84700 33.96884 4.362466 50.05585
45.89700 33.88123 4.506281 50.02256
45.94700 33.79410 4.635146 50.02031
45.99700 33.70513 4.751944 50.11122
46.04700 33.61390 4.851012 49.97450
46.09700 33.52188 4.929665 50.07510
46.14700 33.42856 4.995574 49.89471
46.19700 33.33369 5.044630 49.95466
46.24700 33.23787 5.077147 49.95331
46.29700 33.14040 5.095596 50.05242
46.34700 33.04198 5.102833 49.92478
46.39700 32.94304 5.106958 50.02140
46.44700 32.84272 5.107850 49.96280
46.49700 32.74180 5.102522 50.13895
46.54700 32.64062 5.082300 49.92374
46.59700 32.53798 5.045728 50.09287
46.64700 32.43655 5.000938 50.02254
46.69700 32.33298 4.953472 50.06866
46.74700 32.22981 4.903594 50.03859
46.79700 32.12583 4.850971 50.02110
46.84700 32.02237 4.798092 50.02158
46.89700 31.91769 4.742472 49.96560
46.94700 31.81368 4.686730 50.13123
46.99700 31.70942 4.629653 50.05596
47.04700 31.60430 4.568979 49.90776
47.09700 31.50015 4.514550 50.11690
47.14700 31.39531 4.459994 49.96410
47.19700 31.29130 4.401012 50.00996
47.24700 31.18628 4.345606 49.85786
47.29700 31.08238 4.292831 50.12287
47.34700 30.97690 4.238075 49.92761
47.39700 30.87317 4.187207 49.84531
47.44700 30.76906 4.135857 50.09726
47.49700 30.66428 4.088118 49.83241
47.54700 30.56100 4.041016 50.07244
47.59700 30.45740 3.994903 49.82161
47.64700 30.35282 3.950072 49.88086
47.69700 30.24928 3.906450 49.95762
47.74700 30.14666 3.866350 50.00793
47.79700 30.04293 3.826172 50.09770
47.84700 29.93956 3.788476 50.12978
47.89700 29.83648 3.751589 49.98816
47.94700 29.73381 3.714008 49.93512
47.99700 29.63080 3.679911 49.99045
48.04700 29.52845 3.648366 49.95556
48.09700 29.42513 3.616928 49.83090
48.14700 29.32316 3.586787 50.10197
48.19700 29.22024 3.558540 49.97688
48.24700 29.11828 3.527693 50.02354
48.29700 29.01598 3.499854 50.04265
48.34700 28.91516 3.476226 50.15980
48.39700 28.81221 3.452034 49.95918
48.44700 28.70994 3.426888 49.82418
48.49700 28.60825 3.404450 49.94968
48.54700 28.50606 3.382175 49.85908
48.59700 28.40456 3.359909 50.06240
48.64700 28.30296 3.339464 49.90799
48.69700 28.20120 3.317984 49.92575
48.74700 28.09886 3.299778 50.08436
48.79700 27.99823 3.279308 50.03430
48.84700 27.89618 3.261461 50.02744
48.89700 27.79416 3.242362 50.20850
48.94700 27.69170 3.222502 50.01026
48.99700 27.59068 3.205192 49.96210
49.04700 27.49024 3.188252 50.11554
49.09700 27.38747 3.170127 50.02894
49.14700 27.28626 3.152065 49.90909
49.19700 27.18547 3.136549 50.07830
49.24700 27.08368 3.118260 50.02217
49.29700 26.98170 3.101745 49.94747
49.34700 26.88155 3.083596 50.00633
49.39700 26.77947 3.067316 49.92454
49.44700 26.67898 3.047665 50.01124
49.49700 26.57618 3.031742 49.84384
49.54700 26.47636 3.015876 50.07904
49.59700 26.37456 2.997114 50.09969
49.64700 26.27377 2.979573 50.11024
49.69700 26.17158 2.961872 50.00766
49.74700 26.07028 2.946396 50.09010
49.79700 25.96834 2.927937 49.83489
49.84700 25.86767 2.911518 50.00778
49.89700 25.76653 2.894684 49.95574
49.94700 25.66449 2.878694 50.03896
49.99700 25.56360 2.863152 49.89234
50.04700 25.46219 2.846565 49.92213
50.09700 25.36088 2.831545 49.91484
50.14700 25.25950 2.816692 50.03152
50.19700 25.15800 2.803163 49.85113
50.24700 25.05720 2.788746 50.06912
50.29700 24.95596 2.775794 49.94894
50.34700 24.85452 2.762660 50.02986
50.39700 24.75363 2.750975 49.87320
50.44700 24.65262 2.738172 49.98770
50.49700 24.55160 2.726612 50.10174
50.54700 24.45081 2.715726 49.84070
50.59700 24.35023 2.704624 50.01906
50.64700 24.24919 2.693589 50.06956
50.69700 24.14768 2.681991 49.85239
50.74700 24.04736 2.671390 50.11445
50.79700 23.94639 2.660346 50.03538
50.84700 23.84565 2.648034 50.10719
50.89700 23.74498 2.636646 50.06524
50.94700 23.64375 2.623894 50.06634
50.99700 23.54262 2.609658 50.05811
51.04700 23.44230 2.595444 49.98578
51.09700 23.33972 2.578074 50.08039
51.14700 23.23960 2.561973 49.92404
51.19700 23.13834 2.544019 50.13228
51.24700 23.03668 2.524143 49.91276
51.29700 22.93510 2.503352 50.01772
51.34700 22.83430 2.480847 50.02367
51.39700 22.73298 2.456636 50.00478
51.44700 22.63070 2.432247 49.98869
51.49700 22.52899 2.404385 49.99042
51.54700 22.42670 2.380696 50.05550
51.59700 22.32566 2.353381 50.08736
51.64700 22.22306 2.324986 50.08914
51.69700 22.12254 2.299469 49.85068
51.74700 22.01906 2.269211 50.00445
51.79700 21.91698 2.244510 49.94711
51.84700 21.81455 2.216999 49.97726
51.89700 21.71280 2.188385 49.96686
51.94700 21.60955 2.164604 49.90813
51.99700 21.50797 2.136303 50.14336
52.04700 21.40550 2.110375 50.06848
52.09700 21.30392 2.085203 50.03418
52.14700 21.20302 2.061473 50.00304
52.19700 21.10020 2.038880 49.88660
52.24700 20.99926 2.017588 49.96417
52.29700 20.89718 1.996804 50.09702
52.34700 20.79517 1.977972 50.00056
52.39700 20.69380 1.960710 49.95694
52.44700 20.59162 1.943993 50.04460
52.49700 20.49037 1.928855 50.14614
52.54700 20.38824 1.914862 50.01124
52.59700 20.28806 1.901569 50.06820
52.64700 20.18602 1.889542 49.99956
52.69700 20.08475 1.877917 49.95524
52.74700 19.98278 1.866696 50.03094
52.79700 19.88303 1.855554 49.90174
52.84700 19.78219 1.845043 49.99628
52.89700 19.68159 1.835554 49.92571
52.94700 19.58059 1.826398 49.88184
52.99700 19.48059 1.817332 49.91057
53.04700 19.38016 1.808541 49.96550
53.09700 19.27848 1.800133 50.00928
53.14700 19.17852 1.792019 50.12437
53.19700 19.07856 1.784298 49.94639
53.24700 18.97768 1.777168 49.98579
53.29700 18.87766 1.770555 49.94956
53.34700 18.77728 1.764025 49.89273
53.39700 18.67674 1.757974 50.09896
53.44700 18.57614 1.752476 49.90344
53.49700 18.47586 1.747242 49.79871
53.54700 18.37598 1.742711 50.23131
53.59700 18.27570 1.738371 49.98660
53.64700 18.17634 1.734420 49.95817
53.69700 18.07624 1.730572 50.08457
53.74700 17.97537 1.727125 49.95582
53.79700 17.87596 1.723778 49.84320
53.84700 17.77582 1.720866 49.99679
53.89700 17.67546 1.717993 49.99511
53.94700 17.57565 1.715572 50.15738
53.99700 17.47556 1.713297 50.02294
54.04700 17.37476 1.711125 50.01898
54.09700 17.27537 1.709228 49.98826
54.14700 17.17489 1.707582 50.06540
54.19700 17.07416 1.706066 49.92798
54.24700 16.97435 1.704782 49.92071
54.29700 16.87436 1.703599 50.04064
54.34700 16.77372 1.702276 50.12456
54.39700 16.67362 1.700916 50.01238
54.44700 16.57324 1.699742 50.03348
54.49700 16.47321 1.698508 50.08066
54.54700 16.37379 1.697399 49.96582
54.59700 16.27520 1.696331 50.03642
54.64700 16.17388 1.695232 50.02328
54.69700 16.07429 1.694275 49.93388
54.74700 15.97389 1.693303 49.95250
54.79700 15.87453 1.692448 49.89159
54.84700 15.77356 1.691504 50.14246
54.89700 15.67422 1.690691 49.89954
54.94700 15.57482 1.689901 49.91485
54.99700 15.47467 1.689172 49.98108
55.04700 15.37481 1.688510 49.96028
55.09700 15.27408 1.687756 50.09481
55.14700 15.17452 1.687079 49.87414
55.19700 15.07451 1.686417 50.07707
55.24700 14.97389 1.685840 50.06916
55.29700 14.87373 1.685098 49.94120
55.34700 14.77440 1.684455 50.04648
55.39700 14.67472 1.683710 50.03087
55.44700 14.57429 1.682997 49.89100
55.49700 14.47446 1.682306 50.05722
55.54700 14.37432 1.681617 49.99280
55.59700 14.27418 1.680917 50.06174
55.64700 14.17414 1.680366 50.08656
55.69700 14.07446 1.679829 50.01406
55.74700 13.97455 1.679219 50.17011
55.79700 13.87376 1.678691 50.16455
55.84700 13.77410 1.678026 49.89616
55.89700 13.67438 1.677296 49.90567
55.94700 13.57406 1.676838 49.87991
55.99700 13.47458 1.676410 49.96820
56.04700 13.37370 1.675968 49.84511
56.09700 13.27509 1.675691 49.87824
56.14700 13.17450 1.675344 49.88325
56.19700 13.07388 1.674864 50.06246
56.24700 12.97496 1.674434 49.77646
56.29700 12.87495 1.674056 49.91324
56.34700 12.77434 1.673693 49.96453
56.39700 12.67449 1.673384 50.13242
56.44700 12.57451 1.672658 50.04162
56.49700 12.47468 1.672205 49.88783
56.54700 12.37493 1.671692 50.02834
56.59700 12.27414 1.671219 49.91800
56.64700 12.17540 1.670665 50.13390
56.69700 12.07458 1.670154 50.08356
56.74700 11.97494 1.669819 49.86940
56.79700 11.87470 1.669284 49.97656
56.84700 11.77384 1.668916 49.85724
56.89700 11.67483 1.668404 49.87844
56.94700 11.57500 1.668236 50.08530
56.99700 11.47521 1.667881 50.04444
57.04700 11.37452 1.667468 50.05384
57.09700 11.27427 1.667261 50.06324
57.14700 11.17450 1.666894 49.93940
57.19700 11.07532 1.666708 50.03000
57.24700 10.97500 1.666515 49.96768
57.29700 10.87480 1.666302 49.80847
57.34700 10.77410 1.665766 50.08602
57.39700 10.67542 1.665419 50.07787
57.44700 10.57531 1.665226 49.96848
57.49700 10.47499 1.664806 50.07370
57.54700 10.37406 1.664458 50.09421
57.59700 10.27469 1.664176 50.15649
57.64700 10.17575 1.663742 49.90148
57.69700 10.07502 1.663332 49.96113
57.74700 9.975043 1.662961 49.99537
57.79700 9.875024 1.662363 49.89936
57.84700 9.775268 1.661937 49.90678
57.89700 9.675868 1.661304 50.11559
57.94700 9.575587 1.660737 50.05092
57.99700 9.475402 1.660176 49.99883
58.04700 9.375594 1.659589 49.93381
58.09700 9.275478 1.659158 50.04444
58.14700 9.176049 1.658814 49.89854
58.19700 9.075207 1.658613 49.97822
58.24700 8.975538 1.658400 49.97498
58.29700 8.875235 1.658412 49.96934
58.34700 8.775247 1.658401 49.95596
58.39700 8.676482 1.658248 50.02016
58.44700 8.575528 1.658038 49.94903
58.49700 8.475174 1.657940 50.03050
58.54700 8.376274 1.657716 50.08082
58.59700 8.276522 1.657344 50.16584
58.64700 8.174872 1.657153 50.05606
58.69700 8.075687 1.656974 49.93861
58.74700 7.976093 1.656683 49.98784
58.79700 7.876672 1.656349 50.08172
58.84700 7.776352 1.655936 49.91110
58.89700 7.675976 1.655676 49.99780
58.94700 7.576270 1.655402 49.94117
58.99700 7.476728 1.654948 50.14394
59.04700 7.376856 1.654638 50.01197
59.09700 7.276550 1.654385 50.03437
59.14700 7.176912 1.653993 50.16597
59.19700 7.076349 1.653678 50.07170
59.24700 6.976868 1.653561 50.05750
59.29700 6.876985 1.653643 50.10687
59.34700 6.776145 1.653595 49.87556
59.39700 6.676392 1.653527 49.86688
59.44700 6.576030 1.653394 49.86890
59.49700 6.476922 1.653373 49.82582
59.54700 6.376403 1.653085 49.95402
59.59700 6.276965 1.652966 49.96260
59.64700 6.176074 1.652847 50.07449
59.69700 6.076293 1.652524 50.11346
59.74700 5.975995 1.652192 49.96342
59.79700 5.875772 1.651963 50.06994
59.84700 5.776637 1.651644 50.09068
59.89700 5.675918 1.651288 49.90504
59.94700 5.576320 1.651017 50.03842
59.99700 5.476194 1.650681 50.01881
60.04700 5.376520 1.650346 50.05426
60.09700 5.276752 1.650018 49.96403
60.14700 5.176616 1.649512 50.07947
60.19700 5.076252 1.649206 50.04508
60.24700 4.977518 1.648957 49.92596
60.29700 4.878120 1.648582 49.99950
60.34700 4.777475 1.648297 50.16382
60.39700 4.677434 1.648031 49.99970
60.44700 4.577330 1.647742 50.09075
60.49700 4.477554 1.647446 50.03256
60.54700 4.377373 1.647412 50.11437
60.59700 4.278239 1.647208 49.99476
60.64700 4.177925 1.647030 50.00034
60.69700 4.077600 1.647014 49.86633
60.74700 3.977286 1.646840 50.11769
60.79700 3.876935 1.646708 50.08414
60.84700 3.777731 1.646518 50.03076
60.89700 3.677425 1.646473 50.01830
60.94700 3.577582 1.646335 50.12996
60.99700 3.477481 1.646130 49.81626
61.04700 3.377880 1.645866 50.05309
61.09700 3.277316 1.645546 50.03931
61.14700 3.177631 1.645412 50.06031
61.19700 3.077820 1.645190 50.04602
61.24700 2.977618 1.644957 50.05552
61.29700 2.878795 1.644879 50.04081
61.34700 2.777634 1.644594 50.05613
61.39700 2.677390 1.644324 50.04180
61.44700 2.578018 1.643939 50.10684
61.49700 2.477470 1.643731 49.91554
61.54700 2.377735 1.643459 49.87150
61.59700 2.278344 1.643149 50.03563
61.64700 2.178212 1.642849 50.10398
61.69700 2.077036 1.642589 50.07664
61.74700 1.978312 1.642439 50.21064
61.79700 1.878364 1.642339 50.14470
61.84700 1.777307 1.642165 50.06930
61.89700 1.678044 1.641919 50.14800
61.94700 1.578551 1.641844 50.01990
61.99700 1.478744 1.641684 50.11804
62.04700 1.381116 1.642050 50.07206
62.09700 1.307967 1.605034 49.76304
62.14700 1.258020 1.479964 49.86116
62.19700 1.217728 1.350002 49.96524
62.24700 1.186832 1.222734 50.03856
62.29700 1.159280 1.098967 49.95303
62.34700 1.137591 0.9824751 49.89667
62.39700 1.117356 0.8803120 49.98242
62.44700 1.101457 0.7820124 50.13989
62.49700 1.087090 0.7021439 49.88223
62.54700 1.075962 0.6283871 50.05580
62.59700 1.066406 0.5649380 50.09397
62.64700 1.057028 0.5098894 50.18580
62.69700 1.050037 0.4657372 50.06468
62.74700 1.044174 0.4254478 49.99508
62.79700 1.038327 0.3910745 50.01472
62.84700 1.033613 0.3642109 49.92232
62.89700 1.029063 0.3409497 49.97906
62.94700 1.025754 0.3204171 49.95354
62.99700 1.023244 0.3019150 50.03604
63.04700 1.020973 0.2895606 49.85650
63.09700 1.017855 0.2772808 49.98616
63.14700 1.015996 0.2675936 49.84516
63.19700 1.014199 0.2588385 50.01309
63.24700 1.012830 0.2505195 49.84631
63.29700 1.011192 0.2422309 49.95656
63.34700 1.010283 0.2342496 50.07329
63.39700 1.008668 0.2267090 49.94783
63.44700 1.008339 0.2196688 50.04844
63.49700 1.006781 0.2128983 49.90801
63.54700 1.006915 0.2067670 50.17981
63.59700 1.005630 0.2012566 50.09922
63.64700 1.004879 0.1961299 50.16932
63.69700 1.004422 0.1914611 50.12862
63.74700 1.003375 0.1873468 50.11705
63.79700 1.002641 0.1836198 49.94930
63.84700 1.002402 0.1802342 50.11070
63.89700 1.001881 0.1772011 49.99346
63.94700 1.002516 0.1743263 50.06973
63.99700 1.001267 0.1718050 50.09296
64.04700 1.000766 0.1694762 49.92613
64.09700 1.001130 0.1673898 49.98387
64.14700 0.9997968 0.1654488 49.91883
64.19701 1.000179 0.1637587 50.12002
64.24700 0.9987090 0.1622743 49.81754
64.29700 0.9995551 0.1607747 49.98953
64.34700 1.000002 0.1595968 49.93346
64.39700 0.9994200 0.1583913 50.12188
64.44701 0.9989715 0.1572578 50.06996
64.49700 0.9987678 0.1563484 50.14152
64.54700 0.9987641 0.1554553 49.95660
64.59700 0.9979289 0.1547319 50.09352
64.64700 0.9982769 0.1540389 50.01450
64.69701 0.9984772 0.1534331 49.92922
64.74700 0.9974151 0.1527884 49.92267
64.79700 0.9974228 0.1521950 49.87746
-2.000000 2.000000 0.0000000 0.0000000