File: imagens/notebooks/dados experimentais/dsc/Karl_CTAB100 Ur 39%.txt
CLOSED
Version	1.0
Language	English
Run	1
RunSerial	144
Instrument	DSC Q100 V9.9 Build 303
Module	DSC Standard Cell FC
Operator	LL
File	\\Niger\ta\Data\DSC\2018\Geral\Karl_CTAB100 Ur 39%.001
ProcName	Karl
InstSerial	0100-1211
Sample	CTAB100 Ur 39%
Size	10.0900	mg
Method	Karl
Comment
Xcomment	Pan: Aluminum Hermetic
Xcomment	Gas1: Nitrogen 50.0 ml/min
Xcomment	Gas2: Nitrogen 0.0 ml/min
Text
Exotherm	UP
Kcell	1.09030
Calib	-11.7822
TempCal	1	pts	158.71	156.60
TzeroDt	-90.0515 -0.0093 2.2263
TzeroDtz	-90.0515 0.0466 2.4421
InstCalFile	Tzero: \\Niger\ta\Data\DSC\CALIBRATION\20122016\CALIBRATION\0_RCS_12_20_2016 17_23_31.TZR
InstCalFile	Baseline: \\Niger\ta\Data\DSC\CALIBRATION\20122016\L.Base 20122016
InstCalFile	Sapphire: \\Niger\ta\Data\DSC\CALIBRATION\20122016\Safira 20122017.001
InstCalDate	Tzero 2016-12-20 Time 19:23:31
TempRange	-90.04 to 395.23 °C at 19.96 °C/min Heat Only
AutoZero	Delta T Offset 0.000 uV
AutoZero	Delta T0 Offset 0.000 uV
Controls	Gas 1  Event Off  Sampling 0.2
Cell#	FC-02451
CoolingUnit	RCS
SelHeatFlow	Heat Flow T4 (mW)
AutoAnalysis	Off
MacroFile
Nsig	4
Sig1	Time (min)
Sig2	Temperature (°C)
Sig3	Heat Flow (mW)
Sig4	Sample Purge Flow (mL/min)
Date	2018-05-15
Time	14:22:07
OrgMethod	1: Equilibrate at 1.00 °C
OrgMethod	2: Ramp 2.00 °C/min to 60.00 °C
OrgMethod	3: Isothermal for 3.00 min
OrgMethod	4: Mark end of cycle 1
OrgMethod	5: Ramp 2.00 °C/min to 1.00 °C
OrgMethod	6: Isothermal for 3.00 min
OrgMethod	7: Mark end of cycle 2
OrgFile	C:\TA\Data\DSC\2018\Geral\Karl_CTAB100 Ur 39%.001
3.33324E-4 1.143292 0.8827072 50.00090
0.05033332 1.130536 0.7840710 49.98750
0.1003333 1.147264 0.6354757 50.06550
0.1503333 1.188482 0.4617016 50.08676
0.2003333 1.241004 0.2945709 49.87170
0.2503333 1.301688 0.1296463 49.99948
0.3003333 1.368545 -.02512647 50.04044
0.3503333 1.440773 -0.1570150 50.06900
0.4003334 1.517994 -0.2707260 50.01078
0.4503334 1.594975 -0.4028750 49.97954
0.5003334 1.679456 -0.4815352 50.00485
0.5503332 1.762779 -0.5616839 49.97900
0.6003332 1.853044 -0.6307530 50.03266
0.6503332 1.937759 -0.6913550 50.04810
0.7003332 2.027836 -0.7451600 49.95758
0.7503332 2.120474 -0.7888722 50.00997
0.8003332 2.211166 -0.8281888 50.11306
0.8503332 2.304770 -0.8581855 49.80746
0.9003332 2.398097 -0.8903974 49.92889
0.9503334 2.496623 -0.9063618 50.04620
1.000333 2.587514 -0.9334572 50.08374
1.050334 2.684879 -0.9486714 49.84240
1.100334 2.778659 -0.9622634 50.04089
1.150334 2.875841 -0.9761669 49.99695
1.200334 2.972212 -0.9897659 50.23131
1.250334 3.070177 -0.9996094 49.90610
1.300334 3.168005 -1.007804 50.00402
1.350333 3.263624 -1.016355 50.08841
1.400333 3.363223 -1.024600 49.82454
1.450334 3.461852 -1.031418 50.10126
1.500333 3.556555 -1.042101 49.95798
1.550334 3.655852 -1.049848 49.84998
1.600334 3.756430 -1.055682 50.04320
1.650333 3.854889 -1.061849 49.96988
1.700334 3.952389 -1.067403 49.79433
1.750334 4.050311 -1.073178 50.11664
1.800334 4.150391 -1.078457 50.08532
1.850334 4.249613 -1.083866 50.11496
1.900334 4.346220 -1.088248 50.04070
1.950334 4.447016 -1.092523 50.06720
2.000334 4.546472 -1.096840 49.87390
2.050333 4.644168 -1.100686 49.82883
2.100334 4.744119 -1.104490 49.76772
2.150334 4.842480 -1.107726 50.23208
2.200334 4.942742 -1.110792 50.18936
2.250334 5.043734 -1.113587 50.12657
2.300333 5.140560 -1.116248 49.96070
2.350334 5.239631 -1.118786 49.84551
2.400334 5.341366 -1.120995 49.72032
2.450334 5.438950 -1.123081 49.96586
2.500334 5.540676 -1.124987 50.01758
2.550333 5.637278 -1.127027 49.99127
2.600333 5.737021 -1.128647 50.06133
2.650333 5.835728 -1.130500 49.94157
2.700333 5.935578 -1.132234 49.80960
2.750333 6.034581 -1.133746 49.90836
2.800333 6.134004 -1.135226 49.85174
2.850333 6.235078 -1.136603 49.92288
2.900333 6.334120 -1.138371 49.99292
2.950333 6.432246 -1.139783 49.97402
3.000333 6.532307 -1.141248 49.93594
3.050333 6.633989 -1.143058 50.13182
3.100333 6.733149 -1.144229 49.97783
3.150333 6.831682 -1.145759 50.09538
3.200333 6.930599 -1.147144 49.94813
3.250333 7.032934 -1.148633 50.14540
3.300333 7.129971 -1.149687 50.08550
3.350333 7.229257 -1.150647 49.93624
3.400333 7.329542 -1.151847 50.06617
3.450333 7.428937 -1.152878 49.90024
3.500333 7.530286 -1.154039 49.99790
3.550333 7.628563 -1.154842 50.11944
3.600333 7.729302 -1.155426 50.20211
3.650333 7.830894 -1.156491 50.03041
3.700333 7.927978 -1.157291 49.94522
3.750333 8.029000 -1.157948 49.95115
3.800333 8.126708 -1.158524 50.08654
3.850333 8.226141 -1.159273 49.92563
3.900333 8.327480 -1.159898 50.04758
3.950333 8.425294 -1.160619 49.92508
4.000333 8.525259 -1.161522 49.88944
4.050333 8.626700 -1.162185 50.15274
4.100333 8.726126 -1.163120 49.91894
4.150333 8.825890 -1.164007 49.91260
4.200333 8.925038 -1.165104 49.94771
4.250333 9.025962 -1.166106 49.93440
4.300333 9.125249 -1.167145 49.93567
4.350333 9.226274 -1.167895 50.07734
4.400333 9.324484 -1.169032 50.04426
4.450333 9.427629 -1.170087 49.86128
4.500333 9.526337 -1.170556 50.08716
4.550333 9.626515 -1.170998 49.99933
4.600333 9.725914 -1.171638 49.87414
4.650333 9.825288 -1.172036 50.16933
4.700333 9.924931 -1.172296 49.88834
4.750333 10.02391 -1.172861 49.97183
4.800333 10.12597 -1.173490 49.94085
4.850333 10.22374 -1.174011 50.14139
4.900333 10.32434 -1.174615 50.00230
4.950333 10.42536 -1.175132 50.08713
5.000333 10.52585 -1.175659 49.97894
5.050333 10.62376 -1.176185 50.10206
5.100333 10.72396 -1.176737 50.16930
5.150333 10.82334 -1.177049 50.01611
5.200333 10.92326 -1.177657 49.96466
5.250332 11.02336 -1.177987 49.89606
5.300332 11.12220 -1.178204 49.97642
5.350332 11.22376 -1.178549 49.70649
5.400332 11.32542 -1.179054 49.92842
5.450332 11.42489 -1.179724 49.88572
5.500332 11.52352 -1.180036 49.95810
5.550332 11.62254 -1.180741 50.17984
5.600332 11.72484 -1.180820 49.99336
5.650332 11.82358 -1.181488 50.00324
5.700332 11.92564 -1.181663 50.01500
5.750332 12.02288 -1.182037 49.88334
5.800332 12.12067 -1.182350 49.94470
5.850332 12.22159 -1.182132 50.16804
5.900332 12.32072 -1.182712 49.90181
5.950332 12.42080 -1.182860 49.99887
6.000332 12.52094 -1.182904 50.03009
6.050332 12.62149 -1.183426 49.94168
6.100332 12.72164 -1.183804 49.98822
6.150332 12.82051 -1.184164 50.08322
6.200332 12.91977 -1.185066 49.86765
6.250332 13.02277 -1.185348 50.00292
6.300332 13.12212 -1.186055 49.97070
6.350332 13.21958 -1.186514 49.95650
6.400332 13.32416 -1.186953 49.90586
6.450332 13.42090 -1.187714 50.01898
6.500332 13.52060 -1.188438 49.93917
6.550332 13.61937 -1.189115 49.90708
6.600332 13.72212 -1.189540 50.03015
6.650332 13.82341 -1.190144 49.94463
6.700332 13.92032 -1.190822 50.06194
6.750332 14.02107 -1.190990 50.01538
6.800332 14.12270 -1.191584 50.11896
6.850332 14.22002 -1.192160 49.83098
6.900332 14.32044 -1.192963 50.10303
6.950332 14.42141 -1.193366 49.98633
7.000332 14.52089 -1.193776 49.87687
7.050332 14.62123 -1.194321 50.10750
7.100332 14.71989 -1.194458 49.44028
7.150332 14.81926 -1.194650 49.91324
7.200332 14.91963 -1.194778 50.21086
7.250332 15.01973 -1.194855 49.85274
7.300332 15.12158 -1.194548 50.12106
7.350332 15.21855 -1.194587 50.04598
7.400332 15.31820 -1.194562 49.91970
7.450332 15.41949 -1.194601 50.02503
7.500332 15.51920 -1.194554 49.88010
7.550332 15.61876 -1.194707 49.98984
7.600332 15.71792 -1.194993 50.01050
7.650332 15.81829 -1.195328 50.04565
7.700332 15.91908 -1.195334 50.20615
7.750332 16.01924 -1.195890 50.06998
7.800332 16.11860 -1.196287 49.90330
7.850332 16.21994 -1.196921 49.94079
7.900332 16.31772 -1.197456 49.85974
7.950332 16.41720 -1.198071 49.82808
8.000334 16.51878 -1.198360 49.93248
8.050332 16.61686 -1.198871 49.99112
8.100332 16.71977 -1.198816 49.88861
8.150332 16.81658 -1.199417 50.02792
8.200332 16.91825 -1.199463 49.95076
8.250334 17.01693 -1.200228 50.07294
8.300332 17.11564 -1.200596 50.04070
8.350332 17.21684 -1.201022 49.98560
8.400332 17.31793 -1.201720 50.00574
8.450332 17.41808 -1.202192 50.08442
8.500334 17.51741 -1.202741 49.97526
8.550332 17.61738 -1.203503 49.96085
8.600332 17.71878 -1.203606 49.95344
8.650332 17.81700 -1.204080 50.14822
8.700332 17.91921 -1.204369 50.13526
8.750334 18.01736 -1.204993 49.94336
8.800332 18.11932 -1.205218 49.93780
8.850332 18.21764 -1.205555 49.98540
8.900332 18.31926 -1.205916 49.93062
8.950332 18.41671 -1.206129 49.90532
9.000334 18.51921 -1.206534 50.03375
9.050332 18.61729 -1.206922 50.04874
9.100332 18.71769 -1.207217 49.96773
9.150332 18.81792 -1.207310 50.13137
9.200332 18.91686 -1.207990 50.02190
9.250334 19.01642 -1.207736 50.01080
9.300332 19.11546 -1.207869 49.95109
9.350332 19.21836 -1.208102 50.04730
9.400332 19.31675 -1.208417 50.03938
9.450332 19.41391 -1.208579 50.11075
9.500334 19.51637 -1.208909 50.08686
9.550332 19.61519 -1.209509 50.05125
9.600332 19.71832 -1.209546 49.87079
9.650332 19.81648 -1.209918 50.00037
9.700332 19.91831 -1.210189 49.79954
9.750334 20.01426 -1.210768 49.99646
9.800332 20.11566 -1.211286 50.04794
9.850332 20.21607 -1.211848 49.99510
9.900332 20.31357 -1.212522 50.18572
9.950332 20.41508 -1.213272 49.96412
10.00033 20.51591 -1.213902 50.04347
10.05033 20.61636 -1.214488 49.92688
10.10033 20.71650 -1.214980 49.98196
10.15033 20.81652 -1.215570 50.01299
10.20033 20.91482 -1.216530 49.90910
10.25033 21.01566 -1.216918 50.00489
10.30033 21.11666 -1.217214 49.96690
10.35033 21.21540 -1.217764 50.01422
10.40033 21.31565 -1.217956 50.06467
10.45033 21.41719 -1.218195 50.12078
10.50034 21.51439 -1.218690 49.99416
10.55033 21.61542 -1.218939 50.10967
10.60033 21.71708 -1.219098 50.02871
10.65033 21.81365 -1.219316 49.98400
10.70033 21.91475 -1.220251 49.94418
10.75034 22.01677 -1.219795 50.03290
10.80033 22.11628 -1.220046 50.02904
10.85033 22.21482 -1.220352 49.94389
10.90033 22.31520 -1.220669 50.01668
10.95033 22.41463 -1.221143 50.08628
11.00034 22.51552 -1.221419 50.04614
11.05033 22.61450 -1.221813 50.11926
11.10033 22.71360 -1.222683 50.01998
11.15033 22.81321 -1.223215 49.99631
11.20033 22.91402 -1.223715 50.12710
11.25034 23.01398 -1.224588 49.91208
11.30033 23.11486 -1.225172 49.92893
11.35033 23.21571 -1.225976 49.96992
11.40033 23.31452 -1.226621 49.94468
11.45033 23.41499 -1.226761 49.77949
11.50034 23.51445 -1.227114 50.06347
11.55033 23.61626 -1.228252 50.09270
11.60033 23.71425 -1.228504 49.86121
11.65033 23.81482 -1.228750 49.88246
11.70033 23.91427 -1.229430 50.07065
11.75034 24.01430 -1.230102 49.88646
11.80033 24.11461 -1.230374 49.84371
11.85033 24.21513 -1.230598 50.03916
11.90033 24.31471 -1.231271 50.09814
11.95033 24.41566 -1.231876 50.20482
12.00034 24.51504 -1.232040 49.88918
12.05033 24.61345 -1.232740 49.99690
12.10033 24.71562 -1.232787 49.95996
12.15033 24.81370 -1.233764 50.00060
12.20033 24.91451 -1.233822 50.05290
12.25034 25.01363 -1.234204 49.81389
12.30033 25.11271 -1.234365 49.90631
12.35033 25.21269 -1.234897 50.01626
12.40033 25.31156 -1.235662 50.16179
12.45033 25.41300 -1.236636 50.01396
12.50034 25.51189 -1.237149 49.87180
12.55033 25.61341 -1.237343 49.94786
12.60033 25.71256 -1.238216 50.03732
12.65033 25.81338 -1.238825 49.83909
12.70033 25.91416 -1.239782 49.84119
12.75034 26.01270 -1.241343 49.96564
12.80033 26.11206 -1.242401 49.93320
12.85033 26.21306 -1.244691 49.93209
12.90033 26.31128 -1.245854 49.99817
12.95034 26.41303 -1.247302 49.96356
13.00034 26.51055 -1.249446 49.96810
13.05033 26.61150 -1.251889 50.09656
13.10033 26.71115 -1.254486 49.95182
13.15033 26.81244 -1.257986 50.03514
13.20034 26.90956 -1.263285 49.94050
13.25034 27.00898 -1.272551 49.92387
13.30033 27.10703 -1.282789 49.99530
13.35033 27.20666 -1.292213 50.03970
13.40033 27.30494 -1.304942 50.01957
13.45034 27.40383 -1.327526 50.05152
13.50034 27.50085 -1.354174 50.06584
13.55033 27.59961 -1.387700 49.96765
13.60033 27.69646 -1.436635 49.94144
13.65033 27.79528 -1.472546 50.09696
13.70034 27.89188 -1.525958 50.07818
13.75034 27.98788 -1.569844 50.00874
13.80033 28.08148 -1.630466 49.86850
13.85033 28.17888 -1.680112 50.01582
13.90033 28.27632 -1.726929 49.94476
13.95034 28.37199 -1.778144 50.11187
14.00034 28.46606 -1.833219 50.09826
14.05033 28.56314 -1.880320 50.06906
14.10033 28.65710 -1.926388 49.85461
14.15033 28.75483 -1.967537 50.01223
14.20034 28.85190 -2.006915 49.84541
14.25034 28.94820 -2.040612 49.93926
14.30033 29.04422 -2.079480 50.14970
14.35033 29.14232 -2.108662 50.08570
14.40033 29.23856 -2.138123 49.87226
14.45034 29.33685 -2.163134 50.04410
14.50034 29.43670 -2.183764 50.10500
14.55033 29.53020 -2.206297 49.90643
14.60033 29.63052 -2.222310 50.05592
14.65033 29.72711 -2.247426 49.89576
14.70034 29.82339 -2.264826 49.95516
14.75034 29.92316 -2.278605 50.01503
14.80033 30.02295 -2.294838 49.84866
14.85033 30.12244 -2.306689 49.96474
14.90033 30.22055 -2.321357 49.82668
14.95034 30.31978 -2.332524 50.09732
15.00034 30.41714 -2.348721 50.22840
15.05033 30.51759 -2.360615 50.05632
15.10033 30.61667 -2.369199 50.01340
15.15033 30.71558 -2.378407 49.91306
15.20034 30.81537 -2.387483 49.89406
15.25034 30.91550 -2.395209 50.10766
15.30033 31.01372 -2.402930 50.08881
15.35033 31.11287 -2.410897 49.87455
15.40033 31.21364 -2.417294 50.04238
15.45034 31.31089 -2.424984 49.89348
15.50034 31.40939 -2.431292 50.07684
15.55033 31.50994 -2.438078 50.10852
15.60033 31.60893 -2.443896 49.79526
15.65033 31.71042 -2.449124 49.95574
15.70034 31.81001 -2.453600 49.32201
15.75034 31.90972 -2.458010 50.10309
15.80033 32.00781 -2.461784 49.96769
15.85033 32.10966 -2.465125 49.95926
15.90033 32.20769 -2.468152 49.98296
15.95034 32.30645 -2.470890 50.07602
16.00033 32.40686 -2.472667 50.09270
16.05033 32.50740 -2.474443 49.88660
16.10033 32.60938 -2.475165 50.09719
16.15033 32.70908 -2.475559 49.96998
16.20033 32.80606 -2.475506 49.90624
16.25033 32.90826 -2.474626 49.97969
16.30033 33.00662 -2.473322 50.07868
16.35033 33.10718 -2.471242 50.03952
16.40033 33.20737 -2.468087 49.81050
16.45033 33.31018 -2.463974 49.99808
16.50033 33.41213 -2.458497 50.06576
16.55033 33.50952 -2.448241 49.97074
16.60033 33.61250 -2.440664 50.13966
16.65033 33.71422 -2.428814 49.85803
16.70033 33.81584 -2.412554 50.00916
16.75033 33.91647 -2.393892 50.05662
16.80033 34.01744 -2.372170 49.99035
16.85033 34.12047 -2.349994 50.03346
16.90033 34.22372 -2.320544 49.98859
16.95033 34.32580 -2.290902 50.08270
17.00033 34.42566 -2.264875 49.95234
17.05033 34.52895 -2.221658 49.99717
17.10033 34.63233 -2.168557 49.85148
17.15033 34.73609 -2.091024 49.83012
17.20033 34.84200 -1.994526 50.01304
17.25033 34.94980 -1.904024 50.10297
17.30033 35.05756 -1.798321 49.89634
17.35033 35.16340 -1.716027 49.95286
17.40033 35.27101 -1.645257 50.08538
17.45033 35.37900 -1.577168 50.04760
17.50033 35.48022 -1.537634 50.02908
17.55033 35.58726 -1.489405 50.05038
17.60033 35.68973 -1.457478 49.92734
17.65033 35.79318 -1.430066 50.00203
17.70033 35.89652 -1.408614 49.91812
17.75033 35.99634 -1.392921 49.87078
17.80033 36.09800 -1.377797 49.91127
17.85033 36.20038 -1.365318 50.01114
17.90033 36.30188 -1.353894 49.99031
17.95033 36.40176 -1.346478 50.04578
18.00033 36.50326 -1.339666 50.01031
18.05033 36.60311 -1.333110 49.94550
18.10033 36.70386 -1.327401 49.85142
18.15033 36.80332 -1.322092 49.96678
18.20033 36.90204 -1.316957 49.95496
18.25033 37.00362 -1.312488 49.85806
18.30033 37.10354 -1.308438 49.87320
18.35033 37.20231 -1.304984 50.07591
18.40033 37.30412 -1.301886 50.04500
18.45033 37.40456 -1.299432 49.97830
18.50033 37.50336 -1.297278 50.16402
18.55033 37.60294 -1.295818 50.00250
18.60033 37.70314 -1.294380 49.99839
18.65033 37.80462 -1.293153 50.02474
18.70033 37.90238 -1.292403 49.89086
18.75033 38.00497 -1.291926 49.84395
18.80033 38.10328 -1.291512 50.09274
18.85033 38.20208 -1.291698 49.93208
18.90033 38.30192 -1.291667 50.04992
18.95033 38.40486 -1.291634 49.87616
19.00033 38.50394 -1.291719 50.01502
19.05033 38.60260 -1.292267 50.00941
19.10033 38.70276 -1.292181 50.13867
19.15033 38.80344 -1.292777 50.00022
19.20033 38.90351 -1.293235 49.97514
19.25033 39.00460 -1.293431 49.83597
19.30033 39.10156 -1.294023 50.01260
19.35033 39.20434 -1.294218 49.82256
19.40033 39.30359 -1.294612 50.05696
19.45033 39.40334 -1.295658 49.95123
19.50033 39.50188 -1.295847 50.32383
19.55033 39.60300 -1.296391 50.22636
19.60033 39.70315 -1.296409 50.00752
19.65033 39.80410 -1.296434 49.99672
19.70033 39.90204 -1.296691 50.07578
19.75033 40.00205 -1.297125 49.97020
19.80033 40.10080 -1.297311 49.93976
19.85033 40.20380 -1.297817 50.10727
19.90033 40.30224 -1.298390 50.05385
19.95033 40.40360 -1.298928 49.86230
20.00033 40.50222 -1.299416 50.02968
20.05033 40.60180 -1.299831 49.96559
20.10033 40.70084 -1.300351 50.03996
20.15033 40.80333 -1.300644 49.98972
20.20033 40.90128 -1.301421 49.99488
20.25033 41.00268 -1.301615 50.12140
20.30033 41.10161 -1.302019 49.96696
20.35033 41.20115 -1.302269 49.80754
20.40033 41.30156 -1.302941 50.07180
20.45033 41.40225 -1.303500 50.15589
20.50033 41.50130 -1.304075 49.98424
20.55033 41.60215 -1.304634 50.08932
20.60033 41.70305 -1.305331 50.00396
20.65033 41.80025 -1.306084 50.06468
20.70033 41.90140 -1.306782 49.93554
20.75033 41.99991 -1.307400 50.17299
20.80033 42.09946 -1.308249 49.90310
20.85033 42.19961 -1.308712 50.01350
20.90033 42.29888 -1.308992 50.04850
20.95033 42.40268 -1.309117 49.90437
21.00033 42.49848 -1.309681 50.00807
21.05033 42.59981 -1.310100 49.94896
21.10033 42.70160 -1.310176 49.91214
21.15033 42.79862 -1.311062 49.92488
21.20033 42.89804 -1.311832 49.94519
21.25033 43.00012 -1.312312 49.84973
21.30033 43.09838 -1.313044 49.88218
21.35033 43.19970 -1.313767 50.05650
21.40033 43.29810 -1.314889 50.16788
21.45033 43.39962 -1.315637 50.14307
21.50033 43.49986 -1.316176 50.12750
21.55033 43.59754 -1.317680 50.04782
21.60033 43.69824 -1.318294 50.08644
21.65033 43.79762 -1.319031 49.92481
21.70033 43.89848 -1.319665 50.05606
21.75033 43.99873 -1.320343 50.06736
21.80033 44.09887 -1.320929 49.92036
21.85033 44.19840 -1.321346 49.95372
21.90033 44.30000 -1.321682 49.99430
21.95033 44.39812 -1.322029 50.02278
22.00033 44.49720 -1.322756 49.96266
22.05033 44.59701 -1.323431 50.07204
22.10033 44.69669 -1.323874 50.00347
22.15033 44.79740 -1.324746 49.91350
22.20033 44.89887 -1.325419 49.93000
22.25033 44.99679 -1.326408 50.04238
22.30033 45.09687 -1.327696 50.03500
22.35033 45.19659 -1.328194 50.06700
22.40033 45.29770 -1.329069 50.05884
22.45033 45.39794 -1.329572 49.90564
22.50033 45.49697 -1.330549 50.12961
22.55033 45.59875 -1.331206 49.88353
22.60033 45.69692 -1.331702 49.95328
22.65033 45.79672 -1.332678 50.17410
22.70033 45.89600 -1.333757 50.00962
22.75033 45.99602 -1.334459 49.90952
22.80033 46.09621 -1.335036 50.09998
22.85033 46.19964 -1.335676 50.04770
22.90033 46.29468 -1.337192 49.87337
22.95033 46.39530 -1.337806 50.04210
23.00033 46.49716 -1.338489 49.83828
23.05033 46.59539 -1.339382 50.02506
23.10033 46.69531 -1.340177 49.92688
23.15033 46.79520 -1.340649 50.00998
23.20033 46.89761 -1.341148 49.97284
23.25033 46.99422 -1.341342 50.16741
23.30033 47.09433 -1.341736 49.89938
23.35033 47.19432 -1.342415 50.00967
23.40033 47.29534 -1.342790 50.09366
23.45033 47.39441 -1.343242 49.98118
23.50033 47.49478 -1.343962 49.92462
23.55033 47.59668 -1.344556 49.77158
23.60033 47.69473 -1.346130 49.72603
23.65033 47.79574 -1.347153 49.93671
23.70033 47.89628 -1.348092 50.04666
23.75033 47.99313 -1.349023 50.00130
23.80033 48.09470 -1.349884 49.91366
23.85033 48.19422 -1.350953 50.09447
23.90033 48.29459 -1.351982 49.97200
23.95033 48.39650 -1.352962 50.03312
24.00033 48.49370 -1.353655 49.76490
24.05033 48.59533 -1.354352 49.94678
24.10033 48.69284 -1.355441 50.13935
24.15033 48.79422 -1.356155 49.93152
24.20033 48.89562 -1.356911 50.00381
24.25033 48.99407 -1.357962 50.06866
24.30033 49.09402 -1.358695 50.02080
24.35033 49.19284 -1.359539 49.89570
24.40033 49.29429 -1.360208 49.97133
24.45033 49.39374 -1.360927 49.81312
24.50033 49.49476 -1.361869 49.37954
24.55033 49.59476 -1.362726 49.88428
24.60033 49.69366 -1.363339 49.90269
24.65033 49.79358 -1.363661 50.00839
24.70033 49.89352 -1.364686 50.18853
24.75033 49.99058 -1.365056 50.12238
24.80033 50.09388 -1.365776 50.07575
24.85033 50.19286 -1.366516 49.97717
24.90033 50.29358 -1.367202 50.19436
24.95033 50.39233 -1.368102 50.10122
25.00033 50.49102 -1.369242 50.00174
25.05033 50.59426 -1.369835 50.15301
25.10033 50.69067 -1.371241 49.93844
25.15033 50.79111 -1.372086 49.96342
25.20033 50.89156 -1.372656 49.93750
25.25033 50.99018 -1.373438 49.98413
25.30033 51.09066 -1.374287 49.94898
25.35033 51.19144 -1.375053 49.84926
25.40033 51.29101 -1.376069 49.92793
25.45033 51.39062 -1.377210 49.85305
25.50033 51.49102 -1.378209 49.95725
25.55033 51.59117 -1.379247 50.00537
25.60033 51.69054 -1.381073 50.08267
25.65033 51.79066 -1.382210 50.09990
25.70033 51.89133 -1.383151 49.77760
25.75033 51.99066 -1.384566 50.09298
25.80033 52.08946 -1.385684 49.81713
25.85033 52.18875 -1.386654 50.01380
25.90033 52.28979 -1.387880 50.05993
25.95033 52.38998 -1.388909 50.00406
26.00033 52.49024 -1.389935 50.03873
26.05033 52.59052 -1.390897 49.93080
26.10033 52.69028 -1.391968 50.09372
26.15033 52.78957 -1.393235 49.90916
26.20033 52.89206 -1.394026 50.11174
26.25033 52.98878 -1.395281 50.06524
26.30033 53.08829 -1.396171 49.89201
26.35033 53.19000 -1.396686 50.11460
26.40033 53.28986 -1.397773 49.85490
26.45033 53.38719 -1.398490 48.84206
26.50033 53.48818 -1.399688 50.01510
26.55033 53.58918 -1.401273 50.03978
26.60033 53.68791 -1.402942 49.91914
26.65033 53.78779 -1.404742 49.94734
26.70033 53.88836 -1.406119 49.96500
26.75033 53.98726 -1.407376 49.96550
26.80033 54.08870 -1.408390 50.00694
26.85033 54.18894 -1.409188 50.01664
26.90033 54.28698 -1.410028 50.09207
26.95033 54.38582 -1.410597 50.05274
27.00033 54.48666 -1.411549 49.95227
27.05033 54.58814 -1.412544 50.10390
27.10033 54.68632 -1.413801 49.89822
27.15033 54.78797 -1.414986 50.09930
27.20033 54.88672 -1.416415 50.02032
27.25033 54.98678 -1.417805 49.90780
27.30033 55.08701 -1.418880 50.09169
27.35033 55.18652 -1.420238 50.04470
27.40033 55.28688 -1.421436 50.07538
27.45033 55.38900 -1.422438 49.92824
27.50033 55.48724 -1.423415 50.08748
27.55033 55.58496 -1.424576 49.95357
27.60033 55.68719 -1.425682 49.99791
27.65033 55.78512 -1.426905 50.04950
27.70033 55.88584 -1.428126 50.03372
27.75033 55.98655 -1.428943 50.01468
27.80033 56.08489 -1.430413 50.08641
27.85033 56.18699 -1.431023 50.03369
27.90033 56.28536 -1.432152 49.92642
27.95033 56.38354 -1.432770 50.00333
28.00033 56.48280 -1.433627 50.07252
28.05033 56.58450 -1.434212 49.89438
28.10033 56.68270 -1.435396 49.32712
28.15033 56.78337 -1.436706 49.89634
28.20033 56.88259 -1.438117 49.97325
28.25033 56.98455 -1.440405 50.00790
28.30033 57.08242 -1.441566 50.01219
28.35033 57.18303 -1.442521 50.04024
28.40033 57.28224 -1.443845 49.93550
28.45033 57.38311 -1.445299 50.04490
28.50033 57.48468 -1.446553 50.09473
28.55033 57.58413 -1.448410 50.02579
28.60033 57.68238 -1.449956 49.46978
28.65033 57.78335 -1.451545 50.09018
28.70033 57.88162 -1.453195 50.01260
28.75033 57.98600 -1.454038 50.07266
28.80033 58.08450 -1.455859 49.90967
28.85033 58.18453 -1.457276 49.89024
28.90033 58.28266 -1.458450 49.87376
28.95033 58.38344 -1.459695 50.16334
29.00033 58.48256 -1.461170 50.05557
29.05033 58.58081 -1.462397 49.90010
29.10033 58.68200 -1.463489 49.96039
29.15033 58.78186 -1.465028 50.03805
29.20033 58.88098 -1.466231 49.84718
29.25033 58.98002 -1.467142 49.86480
29.30033 59.07880 -1.467892 49.90422
29.35033 59.18071 -1.468652 49.56478
29.40033 59.27910 -1.469788 49.85366
29.45033 59.37997 -1.470919 50.01877
29.50033 59.48003 -1.471936 49.79578
29.55033 59.57610 -1.474446 50.06542
29.60033 59.64538 -1.452119 49.94774
29.65033 59.69762 -1.316352 50.03009
29.70033 59.73367 -1.202926 50.04428
29.75033 59.76626 -1.075942 49.87274
29.80033 59.79204 -0.9612352 49.87414
29.85033 59.81335 -0.8556903 49.34466
29.90033 59.83212 -0.7661404 49.93967
29.95033 59.84448 -0.6835121 50.09590
30.00033 59.86030 -0.5988610 50.17175
30.05033 59.86835 -0.5450321 49.98328
30.10033 59.87708 -0.4886894 50.01836
30.15033 59.88627 -0.4460262 50.11124
30.20033 59.89210 -0.4044082 49.98548
30.25033 59.89702 -0.3741237 50.01410
30.30033 59.90110 -0.3505952 50.06791
30.35033 59.90575 -0.3228197 50.03414
30.40033 59.90793 -0.3055586 50.06226
30.45033 59.91143 -0.2941664 50.01117
30.50033 59.91328 -0.2840428 49.97408
30.55033 59.91513 -0.2729554 50.00634
30.60033 59.91858 -0.2625881 49.87650
30.65033 59.92005 -0.2556286 50.07160
30.70033 59.92212 -0.2491898 50.03228
30.75033 59.92490 -0.2428831 49.80430
30.80033 59.92521 -0.2361955 50.07820
30.85033 59.92829 -0.2303646 50.04714
30.90033 59.92810 -0.2248537 49.91860
30.95033 59.92990 -0.2190037 49.95778
31.00033 59.93072 -0.2144338 50.04178
31.05033 59.93176 -0.2101048 49.99659
31.10033 59.93106 -0.2063686 49.82540
31.15033 59.93144 -0.2027138 49.94998
31.20033 59.93350 -0.1994869 49.95836
31.25033 59.93425 -0.1964689 50.05424
31.30033 59.93382 -0.1941254 49.97978
31.35033 59.93404 -0.1916105 49.92509
31.40033 59.93586 -0.1892704 50.08530
31.45033 59.93594 -0.1868902 50.02732
31.50033 59.93540 -0.1846301 50.02320
31.55033 59.93594 -0.1823504 49.91114
31.60033 59.93461 -0.1805162 50.08537
31.65033 59.93524 -0.1785274 50.13990
31.70033 59.93316 -0.1766361 49.86280
31.75033 59.93574 -0.1749376 50.06955
31.80033 59.93572 -0.1735591 49.87634
31.85034 59.93428 -0.1725322 50.14838
31.90033 59.93543 -0.1714760 50.11862
31.95033 59.93440 -0.1709919 49.91067
32.00033 59.93619 -0.1704723 50.04134
32.05033 59.93744 -0.1701772 50.14465
32.10034 59.93672 -0.1701124 49.94922
32.15033 59.93624 -0.1697942 50.05377
32.20033 59.93686 -0.1693558 49.94434
32.25033 59.93782 -0.1692274 49.96011
32.30033 59.93724 -0.1689723 50.08803
32.35034 59.93899 -0.1684826 50.08164
32.40033 59.93828 -0.1682132 49.93119
32.45033 59.93801 -0.1674229 50.07180
-2.000000 1.000000 0.0000000 0.0000000
32.54700 59.93462 -0.1675553 50.15570
32.59700 59.90860 -0.1371945 50.13342
32.64700 59.85842 -3.0466E-3 49.82382
32.69700 59.79480 0.1166171 50.11094
32.74700 59.72701 0.2439821 50.01130
32.79700 59.65282 0.3624074 49.88003
32.84700 59.57321 0.4826197 49.85484
32.89700 59.49234 0.5768182 49.88616
32.94700 59.40538 0.6557949 50.03205
32.99700 59.32016 0.7357632 49.90288
33.04700 59.22810 0.7943438 50.13002
33.09700 59.13874 0.8467831 49.76367
33.14700 59.04410 0.8913504 49.99416
33.19700 58.95269 0.9313492 49.98020
33.24700 58.85864 0.9647464 49.99184
33.29700 58.76082 0.9914399 50.14508
33.34700 58.66509 1.011028 50.05570
33.39700 58.57080 1.034042 50.05670
33.44700 58.47356 1.052274 49.87128
33.49700 58.37446 1.064236 49.88628
33.54700 58.27879 1.078995 49.89086
33.59700 58.17928 1.089187 50.15410
33.64700 58.08186 1.098855 49.93478
33.69700 57.98192 1.107426 50.04067
33.74700 57.88432 1.115189 50.03641
33.79700 57.78441 1.122713 49.84824
33.84700 57.68709 1.128762 50.12312
33.89700 57.58620 1.134574 49.99528
33.94700 57.48878 1.141266 50.05606
33.99700 57.39004 1.146285 49.82369
34.04700 57.29059 1.150938 49.90644
34.09700 57.19336 1.156559 50.02871
34.14700 57.09198 1.160733 49.85414
34.19700 56.99514 1.164703 50.04468
34.24700 56.89410 1.169026 50.05090
34.29700 56.79748 1.172504 50.08588
34.34700 56.69790 1.175696 50.04478
34.39700 56.59564 1.178640 49.97309
34.44700 56.49852 1.182661 49.99598
34.49700 56.39631 1.185080 49.98853
34.54700 56.30126 1.188362 50.10160
34.59700 56.19930 1.190723 49.91816
34.64700 56.09756 1.193382 49.86106
34.69700 55.99913 1.196276 49.85517
34.74700 55.89981 1.198852 49.97712
34.79700 55.79985 1.201249 49.85727
34.84700 55.70208 1.203766 49.97806
34.89700 55.60130 1.206180 50.06207
34.94700 55.50100 1.208332 49.87836
34.99700 55.40260 1.210863 50.02488
35.04700 55.30193 1.212889 49.89604
35.09700 55.20094 1.215079 49.78222
35.14700 55.10186 1.216854 49.88215
35.19700 55.00340 1.218636 49.91571
35.24700 54.90460 1.220447 49.95022
35.29700 54.80278 1.221916 50.14018
35.34700 54.70518 1.223525 50.05486
35.39700 54.60674 1.225662 49.92578
35.44700 54.50350 1.226548 49.87981
35.49700 54.40530 1.228061 49.87886
35.54700 54.30712 1.229614 50.06085
35.59700 54.20440 1.231170 49.96091
35.64700 54.10594 1.232979 49.99850
35.69700 54.00626 1.234391 50.05003
35.74700 53.90588 1.235841 50.15896
35.79700 53.80453 1.236889 50.01884
35.84700 53.71021 1.239693 50.04686
35.89700 53.60400 1.241401 49.92452
35.94700 53.50410 1.242735 50.05134
35.99700 53.40586 1.244257 49.87701
36.04700 53.30531 1.245754 50.01169
36.09700 53.20668 1.247014 49.97038
36.14700 53.10642 1.248269 49.97064
36.19700 53.00680 1.249252 50.11030
36.24700 52.90762 1.249905 50.01004
36.29700 52.81075 1.251025 49.98356
36.34700 52.70791 1.251470 49.97336
36.39700 52.61091 1.252377 49.96660
36.44700 52.50867 1.253018 50.11688
36.49700 52.41060 1.254099 49.88422
36.54700 52.31028 1.255198 50.07019
36.59700 52.20948 1.256220 50.05604
36.64700 52.10950 1.257079 50.02916
36.69700 52.01172 1.258476 49.92116
36.74700 51.91047 1.259500 49.96267
36.79700 51.81054 1.260628 50.13441
36.84700 51.71360 1.262443 49.94809
36.89700 51.61436 1.263781 49.99072
36.94700 51.51090 1.264686 49.99756
36.99700 51.41063 1.265565 49.91750
37.04700 51.31402 1.267073 49.91306
37.09700 51.21283 1.268355 49.79926
37.14700 51.11184 1.269501 50.04843
37.19700 51.01146 1.270643 49.90759
37.24700 50.91244 1.271929 50.20904
37.29700 50.81314 1.273623 49.81812
37.34700 50.71234 1.275282 50.03476
37.39700 50.61200 1.276704 49.91977
37.44700 50.51228 1.278190 49.93340
37.49700 50.41398 1.279573 49.99814
37.54700 50.31394 1.280397 49.95683
37.59700 50.21493 1.281690 50.21744
37.64700 50.11156 1.282372 50.08740
37.69700 50.01238 1.282989 50.04410
37.74700 49.91550 1.283636 49.95348
37.79700 49.81598 1.284515 49.90715
37.84700 49.71417 1.285150 50.01330
37.89700 49.61676 1.286100 50.01376
37.94700 49.51534 1.286921 50.12540
37.99700 49.41566 1.287856 50.13111
38.04700 49.31528 1.288151 49.91920
38.09700 49.21616 1.288989 49.93126
38.14700 49.11768 1.290096 50.13343
38.19700 49.01439 1.290819 49.92832
38.24700 48.91750 1.291932 50.01696
38.29700 48.81502 1.292777 49.86082
38.34700 48.71702 1.293912 49.88900
38.39700 48.61641 1.294495 49.88421
38.44700 48.51617 1.295299 50.06372
38.49700 48.41842 1.296198 50.01123
38.54700 48.31775 1.297082 49.76926
38.59700 48.21758 1.298354 49.91031
38.64700 48.11600 1.299349 49.84966
38.69700 48.01779 1.300534 49.98289
38.74700 47.91669 1.301295 49.96050
38.79700 47.81820 1.302336 50.20010
38.84700 47.71858 1.302840 49.95347
38.89700 47.61782 1.303544 49.88676
38.94700 47.51783 1.304520 49.95806
38.99700 47.41600 1.304671 49.99837
39.04700 47.31832 1.305768 50.07448
39.09700 47.22034 1.307866 50.12690
39.14700 47.11688 1.307150 49.93258
39.19700 47.02089 1.307905 50.01558
39.24700 46.91985 1.308538 49.88932
39.29700 46.81832 1.309376 49.94698
39.34700 46.71919 1.309918 49.88724
39.39700 46.61937 1.310461 50.04570
39.44700 46.51856 1.311783 50.12392
39.49700 46.42309 1.313043 49.99580
39.54700 46.31889 1.313623 49.96028
39.59700 46.21944 1.315196 49.97294
39.64700 46.11824 1.316301 49.86900
39.69700 46.01742 1.317568 49.80741
39.74700 45.91771 1.318934 49.87817
39.79700 45.81800 1.320645 49.90976
39.84700 45.71988 1.321482 49.87491
39.89700 45.61959 1.322003 49.96472
39.94700 45.52234 1.322513 49.74994
39.99700 45.41950 1.322936 49.83229
40.04700 45.31959 1.323137 49.44459
40.09700 45.22194 1.323492 50.05190
40.14700 45.11893 1.323919 50.10980
40.19700 45.02286 1.324412 49.84712
40.24700 44.92054 1.324535 49.98046
40.29700 44.82118 1.324668 49.81386
40.34700 44.72263 1.325275 50.08329
40.39700 44.62419 1.325754 49.85824
40.44700 44.52296 1.326744 49.94312
40.49700 44.42312 1.327066 50.11470
40.54700 44.32246 1.327470 49.86294
40.59700 44.22358 1.328394 50.12784
40.64700 44.12182 1.329177 50.06839
40.69700 44.02332 1.330194 49.94884
40.74700 43.92285 1.331444 49.84486
40.79700 43.82525 1.332136 49.92003
40.84700 43.72384 1.332821 50.07804
40.89700 43.62326 1.333966 49.97375
40.94700 43.52522 1.334625 49.92114
40.99700 43.42444 1.335411 50.08975
41.04700 43.32484 1.336049 50.13134
41.09700 43.22364 1.336814 49.86660
41.14700 43.12503 1.337482 50.02172
41.19700 43.02300 1.337925 49.97430
41.24700 42.92450 1.338626 49.90377
41.29700 42.82534 1.339016 49.98781
41.34700 42.72506 1.339659 49.86850
41.39700 42.62668 1.340721 49.84634
41.44700 42.52484 1.340814 49.94882
41.49700 42.42485 1.341478 50.04864
41.54700 42.32668 1.342264 49.94218
41.59700 42.22452 1.342475 49.94788
41.64700 42.12516 1.343091 50.00867
41.69700 42.02646 1.343008 50.03270
41.74700 41.92569 1.343335 49.97626
41.79700 41.82582 1.344110 50.11217
41.84700 41.72519 1.344569 50.00550
41.89700 41.62594 1.345230 50.05910
41.94700 41.52668 1.345673 50.10272
41.99700 41.42547 1.346974 49.94195
42.04700 41.32521 1.346974 49.90420
42.09700 41.22551 1.347190 49.86994
42.14700 41.12556 1.347716 49.80214
42.19700 41.02633 1.348384 50.11196
42.24700 40.92965 1.348766 50.07457
42.29700 40.82652 1.349454 49.75250
42.34700 40.72725 1.349736 49.94205
42.39700 40.62611 1.350192 50.16248
42.44700 40.52671 1.350724 50.02268
42.49700 40.42765 1.351298 50.08933
42.54700 40.32856 1.351935 50.10124
42.59700 40.22726 1.352258 50.00161
42.64700 40.12770 1.353139 50.16281
42.69700 40.02674 1.354075 50.10767
42.74700 39.92700 1.354684 50.14816
42.79700 39.82816 1.355241 50.00662
42.84700 39.73065 1.356149 49.86967
42.89700 39.62636 1.356537 49.97898
42.94700 39.52854 1.357115 49.86178
42.99700 39.42865 1.357281 50.00344
43.04700 39.32710 1.357354 49.85756
43.09700 39.22821 1.357590 49.93290
43.14700 39.13031 1.357877 50.02522
43.19700 39.02949 1.358383 49.99284
43.24700 38.92810 1.358624 50.03442
43.29700 38.83128 1.359270 49.89220
43.34700 38.72811 1.359491 49.96172
43.39700 38.62836 1.359921 49.95048
43.44700 38.52950 1.360012 50.10380
43.49700 38.43157 1.360326 49.87654
43.54700 38.33020 1.360829 50.14920
43.59700 38.22937 1.361637 49.97560
43.64700 38.12926 1.362319 50.04309
43.69700 38.03111 1.363190 49.95636
43.74700 37.92984 1.363697 50.13518
43.79700 37.82922 1.364182 49.90375
43.84700 37.73224 1.364794 50.19840
43.89700 37.63074 1.365044 50.02122
43.94700 37.53102 1.365048 49.98894
43.99700 37.43047 1.365408 50.09192
44.04700 37.33150 1.365668 49.93906
44.09700 37.23006 1.365863 50.11653
44.14700 37.12906 1.366049 49.97090
44.19700 37.03000 1.366391 49.87452
44.24700 36.93198 1.366675 49.83657
44.29700 36.83045 1.366931 50.00667
44.34700 36.73012 1.367446 49.82818
44.39700 36.62970 1.367426 49.95971
44.44700 36.53174 1.368047 50.02292
44.49700 36.43145 1.368250 49.94016
44.54700 36.33210 1.368641 49.96961
44.59700 36.23004 1.369005 50.03818
44.64700 36.13006 1.369394 50.03912
44.69700 36.03366 1.370052 49.89570
44.74700 35.93160 1.370709 50.05575
44.79700 35.83128 1.371155 49.85346
44.84700 35.73496 1.371991 50.11718
44.89700 35.63088 1.372454 49.91048
44.94700 35.53090 1.372766 50.09219
44.99700 35.43035 1.372947 50.12690
45.04700 35.33250 1.373281 49.95956
45.09700 35.23084 1.373444 49.84870
45.14700 35.13310 1.373730 49.98788
45.19700 35.03347 1.373916 49.84398
45.24700 34.93265 1.373955 50.13150
45.29700 34.83507 1.373797 50.00656
45.34700 34.73366 1.374110 49.91613
45.39700 34.63787 1.374378 49.73253
45.44700 34.53485 1.374600 49.99932
45.49700 34.43510 1.374902 50.15984
45.54700 34.33266 1.375272 50.10818
45.59700 34.23295 1.375505 49.85698
45.64700 34.13464 1.375910 49.71550
45.69700 34.03573 1.376421 49.88854
45.74700 33.93286 1.376984 49.87195
45.79700 33.83463 1.377265 49.90437
45.84700 33.73424 1.377722 49.97003
45.89700 33.63413 1.378672 50.03272
45.94700 33.53510 1.378818 50.08890
45.99700 33.43340 1.379378 50.02430
46.04700 33.33418 1.379884 49.86629
46.09700 33.23545 1.380381 49.83896
46.14700 33.13235 1.380173 49.95282
46.19700 33.03398 1.381087 49.85675
46.24700 32.93972 1.382003 49.86924
46.29700 32.83452 1.381739 49.87650
46.34700 32.73715 1.382142 50.01642
46.39700 32.63574 1.382138 49.89351
46.44700 32.53564 1.382141 50.10947
46.49700 32.43620 1.382526 49.91366
46.54700 32.33534 1.382395 50.07727
46.59700 32.23680 1.382651 50.00350
46.64700 32.13697 1.382568 49.92425
46.69700 32.03652 1.382908 50.28686
46.74700 31.93972 1.383252 49.90306
46.79700 31.83556 1.383384 50.21028
46.84700 31.73577 1.383850 49.88494
46.89700 31.63620 1.383756 50.19457
46.94700 31.53433 1.384132 50.04402
46.99700 31.43386 1.385194 49.77644
47.04700 31.33503 1.385754 49.89522
47.09700 31.23556 1.386220 50.01370
47.14700 31.13353 1.386260 49.88080
47.19700 31.03422 1.386972 49.84653
47.24700 30.93470 1.387161 49.71652
47.29700 30.83602 1.387351 49.84051
47.34700 30.73345 1.386838 50.14162
47.39700 30.63575 1.386626 49.99817
47.44700 30.53583 1.386817 50.05147
47.49700 30.43884 1.387236 49.91639
47.54700 30.33716 1.387073 49.89684
47.59700 30.23590 1.387155 50.07094
47.64700 30.13859 1.387978 49.95810
47.69700 30.03574 1.387684 50.15067
47.74700 29.93813 1.387603 50.11723
47.79700 29.83650 1.387468 50.08272
47.84700 29.73759 1.387518 49.99734
47.89700 29.63935 1.387712 49.88734
47.94700 29.53954 1.388232 50.15612
47.99700 29.43729 1.387715 49.88098
48.04700 29.33700 1.388032 49.95150
48.09700 29.23609 1.388467 49.94885
48.14700 29.13736 1.388838 50.05596
48.19700 29.03746 1.388898 49.96690
48.24700 28.93702 1.389317 50.15835
48.29700 28.83908 1.389744 49.98096
48.34700 28.73877 1.389853 49.96512
48.39700 28.63729 1.390478 50.03740
48.44700 28.53974 1.390910 49.87778
48.49700 28.43890 1.390853 49.89862
48.54700 28.33790 1.390921 49.88101
48.59700 28.23969 1.391384 50.08867
48.64700 28.14032 1.392534 50.12703
48.69700 28.03880 1.393142 50.04883
48.74700 27.93800 1.393976 49.78482
48.79700 27.84005 1.395403 50.02225
48.84700 27.73810 1.397368 49.90604
48.89700 27.64004 1.400053 50.00230
48.94700 27.53940 1.403581 50.01700
48.99700 27.44160 1.415217 49.98489
49.04700 27.34416 1.431934 50.02309
49.09700 27.24611 1.458513 49.41104
49.14700 27.14584 1.500008 49.86248
49.19700 27.05002 1.558865 49.98266
49.24700 26.95588 1.631435 49.89511
49.29700 26.86182 1.710048 50.12182
49.34700 26.76761 1.812273 49.81197
49.39700 26.67695 1.936447 50.17631
49.44700 26.58711 2.066100 49.97855
49.49700 26.49763 2.213670 50.03918
49.54700 26.41115 2.377892 49.79633
49.59700 26.32286 2.550154 49.77972
49.64700 26.23793 2.743743 49.98285
49.69700 26.15397 2.942509 49.91364
49.74700 26.07086 3.166302 50.17532
49.79700 25.98938 3.379970 50.18180
49.84700 25.90542 3.588487 50.21592
49.89700 25.82168 3.786726 50.15346
49.94700 25.73864 3.963389 49.98234
49.99700 25.65169 4.116310 49.87526
50.04700 25.56268 4.249410 50.13509
50.09700 25.47296 4.329153 49.96662
50.14700 25.38411 4.391826 49.91914
50.19700 25.28695 4.412324 50.09481
50.24700 25.18695 4.417040 49.86246
50.29700 25.09294 4.406389 50.08770
50.34700 24.98535 4.344572 50.18116
50.39700 24.88068 4.249200 49.85456
50.44700 24.77365 4.148690 49.99362
50.49700 24.66779 4.030068 49.99014
50.54700 24.55674 3.905674 50.01968
50.59700 24.44727 3.766266 49.96596
50.64700 24.33630 3.622472 49.94824
50.69700 24.22503 3.458950 49.99269
50.74700 24.11336 3.320496 49.93428
50.79700 24.00210 3.168586 49.95626
50.84700 23.88914 3.001818 50.12718
50.89700 23.77416 2.858915 49.97252
50.94700 23.66289 2.697238 49.99562
50.99700 23.54912 2.548403 49.92456
51.04700 23.43988 2.413115 49.96124
51.09700 23.32793 2.275922 49.95442
51.14700 23.21311 2.151925 49.89386
51.19700 23.10536 2.047312 49.90722
51.24700 22.99849 1.949125 50.03815
51.29700 22.88654 1.863766 49.95191
51.34700 22.78105 1.787238 50.02273
51.39700 22.67346 1.729766 50.06871
51.44700 22.57047 1.682648 49.95459
51.49700 22.46475 1.642974 49.97608
51.54700 22.35943 1.601321 49.88017
51.59700 22.25730 1.572858 49.89900
51.64700 22.15496 1.547761 50.05683
51.69700 22.05373 1.531129 50.16806
51.74700 21.95316 1.510167 49.93881
51.79700 21.85048 1.498394 49.87624
51.84700 21.75170 1.487684 49.85444
51.89700 21.65127 1.478813 50.00210
51.94700 21.54736 1.470313 49.89145
51.99700 21.44786 1.463470 50.02530
52.04700 21.34598 1.453112 50.10459
52.09700 21.24654 1.447017 49.89596
52.14700 21.14427 1.441706 49.88945
52.19700 21.04782 1.435286 49.93980
52.24700 20.94905 1.430903 50.02974
52.29700 20.84401 1.426370 49.48606
52.34700 20.74680 1.423302 50.10160
52.39700 20.64588 1.420449 49.92809
52.44700 20.54680 1.416466 49.79521
52.49700 20.44525 1.413870 50.02940
52.54700 20.34327 1.411496 50.03292
52.59700 20.24252 1.409470 50.17458
52.64700 20.14399 1.407886 49.90357
52.69700 20.04441 1.406477 49.90912
52.74700 19.94889 1.405919 49.93339
52.79700 19.84443 1.404608 49.89910
52.84700 19.74378 1.403206 49.95902
52.89700 19.64523 1.402635 50.01512
52.94700 19.54555 1.401869 50.04912
52.99700 19.44500 1.401073 50.06746
53.04700 19.34377 1.400429 50.02696
53.09700 19.24394 1.399642 50.15034
53.14700 19.14497 1.398383 50.04212
53.19700 19.04366 1.397528 50.09408
53.24700 18.94310 1.398369 49.80359
53.29700 18.84318 1.398173 49.98856
53.34700 18.74691 1.398748 50.15056
53.39700 18.64530 1.398116 50.08057
53.44700 18.54456 1.397752 49.99362
53.49700 18.44418 1.397815 49.94667
53.54700 18.34381 1.397662 49.99986
53.59700 18.24531 1.396892 50.02376
53.64700 18.14417 1.397097 49.95239
53.69700 18.04357 1.396657 49.89644
53.74700 17.94234 1.395172 49.98176
53.79700 17.84514 1.395212 50.22449
53.84700 17.74730 1.395588 49.86111
53.89700 17.64224 1.394590 50.04400
53.94700 17.54566 1.393397 49.86421
53.99700 17.44448 1.393670 49.96444
54.04700 17.34229 1.393014 49.98520
54.09700 17.24310 1.393142 49.99758
54.14700 17.14912 1.393462 50.04168
54.19700 17.04479 1.394324 49.92598
54.24700 16.94163 1.392692 50.11742
54.29700 16.84836 1.394054 50.23352
54.34700 16.74258 1.393168 50.14783
54.39700 16.64523 1.393150 50.07906
54.44700 16.54335 1.392750 50.02271
54.49700 16.44366 1.391329 49.84840
54.54700 16.34439 1.392495 49.85950
54.59700 16.24681 1.392719 49.99890
54.64700 16.14457 1.391385 49.81772
54.69700 16.04720 1.393759 49.97556
54.74700 15.94358 1.393178 49.97053
54.79700 15.84266 1.392791 50.06276
54.84700 15.74402 1.391803 49.96938
54.89700 15.64529 1.391742 50.02631
54.94700 15.54621 1.391616 50.11955
54.99700 15.44583 1.389728 49.91803
55.04700 15.34690 1.389804 49.92182
55.09700 15.24739 1.389965 49.87222
55.14700 15.14758 1.389589 49.87006
55.19700 15.04718 1.389942 49.90484
55.24700 14.94797 1.390683 50.01315
55.29700 14.84572 1.389801 50.00662
55.34700 14.74428 1.389951 50.08644
55.39700 14.64860 1.389204 49.86330
55.44700 14.54456 1.387713 49.96707
55.49700 14.44815 1.388094 49.83818
55.54700 14.34650 1.389110 49.88544
55.59700 14.24654 1.388974 50.21053
55.64700 14.14580 1.388280 50.04569
55.69700 14.05076 1.390572 50.17559
55.74700 13.94829 1.390430 49.89703
55.79700 13.84880 1.390663 50.04449
55.84700 13.75006 1.390220 50.04976
55.89700 13.64690 1.390144 49.90250
55.94700 13.54683 1.389663 49.88942
55.99700 13.44678 1.389306 49.98637
56.04700 13.34768 1.389763 49.95996
56.09700 13.24518 1.389554 49.92742
56.14700 13.14559 1.387313 49.41312
56.19700 13.04553 1.388479 49.85799
56.24700 12.94792 1.388040 50.01721
56.29700 12.84824 1.388574 50.10803
56.34700 12.74702 1.387250 50.14988
56.39700 12.64972 1.387496 49.96984
56.44700 12.55092 1.387674 49.98821
56.49700 12.45051 1.387969 49.90282
56.54700 12.35000 1.387876 49.97797
56.59700 12.24692 1.388060 50.06326
56.64700 12.15110 1.388130 50.05918
56.69700 12.04876 1.387416 50.00134
56.74700 11.94698 1.387320 50.00094
56.79700 11.85000 1.384227 49.96730
56.84700 11.75208 1.384891 49.90530
56.89700 11.65051 1.385418 50.06737
56.94700 11.54658 1.386247 49.67390
56.99700 11.44912 1.386666 49.84644
57.04700 11.34799 1.385280 49.96202
57.09700 11.25068 1.385758 50.08494
57.14700 11.14612 1.386355 50.02178
57.19700 11.04836 1.387061 50.21824
57.24700 10.95124 1.387399 49.83336
57.29700 10.84767 1.387786 50.00627
57.34700 10.74807 1.387913 49.94710
57.39700 10.64781 1.387988 50.00784
57.44700 10.55022 1.388460 50.26988
57.49700 10.45017 1.388728 50.06168
57.54700 10.34989 1.386821 50.07322
57.59700 10.24690 1.386296 50.03388
57.64700 10.14827 1.385892 50.04240
57.69700 10.05156 1.385586 49.93075
57.74700 9.946774 1.385192 50.08920
57.79700 9.848405 1.384584 50.11074
57.84700 9.749092 1.385385 49.97522
57.89700 9.652719 1.384678 49.88010
57.94700 9.547508 1.383332 50.17430
57.99700 9.447293 1.383222 49.96926
58.04700 9.351696 1.383574 49.92358
58.09700 9.247382 1.382548 49.96600
58.14700 9.146386 1.382737 50.08154
58.19700 9.050205 1.383230 49.90596
58.24700 8.951043 1.383424 49.98784
58.29700 8.849262 1.383185 50.17190
58.34700 8.747570 1.383514 49.93088
58.39700 8.651964 1.383319 50.05738
58.44700 8.551866 1.382206 50.07766
58.49700 8.450072 1.381886 50.01896
58.54700 8.348712 1.381973 50.07406
58.59700 8.251587 1.384196 49.85953
58.64700 8.152928 1.382939 50.06339
58.69700 8.050974 1.381733 49.93536
58.74700 7.946866 1.381226 49.92114
58.79700 7.850488 1.381584 50.15600
58.84700 7.749589 1.381434 49.98056
58.89700 7.647737 1.381382 49.92252
58.94700 7.549825 1.381142 49.95456
58.99700 7.448787 1.381459 49.96817
59.04700 7.350799 1.381397 50.02408
59.09700 7.248084 1.380874 49.96943
59.14700 7.150244 1.381984 50.25586
59.19700 7.050654 1.381998 49.89182
59.24700 6.951099 1.382262 49.95169
59.29700 6.849878 1.382202 49.94829
59.34700 6.750562 1.382926 49.99002
59.39700 6.650109 1.381708 50.06122
59.44700 6.549052 1.381435 50.05161
59.49700 6.453003 1.381832 50.05754
59.54700 6.349568 1.381624 50.03940
59.59700 6.248076 1.380686 50.13336
59.64700 6.148568 1.379896 49.79412
59.69700 6.054021 1.379958 49.87527
59.74700 5.952068 1.380666 49.81156
59.79700 5.851591 1.379635 50.10141
59.84700 5.751622 1.380218 50.01856
59.89700 5.651582 1.380608 50.02129
59.94700 5.548398 1.380094 50.05124
59.99700 5.448772 1.379918 49.91932
60.04700 5.348538 1.380573 49.94812
60.09700 5.247162 1.379152 50.02511
60.14700 5.147938 1.382138 50.04492
60.19700 5.050041 1.382454 49.46284
60.24700 4.950613 1.381261 49.97780
60.29700 4.848356 1.380554 50.10187
60.34700 4.749678 1.381592 49.96894
60.39700 4.651486 1.381505 50.01575
60.44700 4.551104 1.379721 49.99643
60.49700 4.449287 1.379348 50.21660
60.54700 4.351430 1.378320 50.01470
60.59700 4.251426 1.378419 50.02019
60.64700 4.151303 1.378062 49.93242
60.69700 4.049469 1.377500 50.09466
60.74700 3.950126 1.377131 50.00761
60.79700 3.849852 1.375923 50.09418
60.84700 3.749822 1.375331 49.86414
60.89700 3.651596 1.373580 50.08039
60.94700 3.552520 1.374083 49.87604
60.99700 3.452394 1.374617 50.09387
61.04700 3.349906 1.375524 49.95639
61.09700 3.250315 1.376038 49.93094
61.14700 3.150616 1.376018 49.89176
61.19700 3.049948 1.376372 50.01010
61.24700 2.951724 1.377268 49.97474
61.29700 2.848549 1.377616 49.93601
61.34700 2.749380 1.377669 49.86993
61.39700 2.651390 1.377165 50.12789
61.44700 2.550772 1.377082 50.00748
61.49700 2.449496 1.376988 50.01881
61.54700 2.350241 1.376797 50.03496
61.59700 2.250384 1.377088 50.07624
61.64700 2.150872 1.376900 50.02246
61.69700 2.054030 1.376698 49.89239
61.74700 1.952469 1.376388 49.84989
61.79700 1.851528 1.375481 50.05662
61.84700 1.750494 1.374442 50.12170
61.89700 1.654430 1.374753 49.86094
61.94700 1.551140 1.374005 50.09760
61.99700 1.454669 1.375332 49.98284
62.04700 1.357476 1.376462 49.98324
62.09700 1.284096 1.344558 50.00794
62.14700 1.234964 1.231845 49.99747
62.19700 1.195453 1.119730 50.04900
62.24700 1.165580 0.9964019 50.08087
62.29700 1.141428 0.8971470 50.16382
62.34700 1.122481 0.7993003 50.09804
62.39700 1.103801 0.7169366 49.98863
62.44700 1.088066 0.6272994 50.00236
62.49700 1.075926 0.5707178 49.88206
62.54700 1.062489 0.5004213 49.82618
62.59700 1.053224 0.4475046 49.96996
62.64700 1.044929 0.4035936 50.09078
62.69700 1.040362 0.3609572 49.89637
62.74700 1.038602 0.3403357 49.94938
62.79700 1.028175 0.3129419 50.00703
62.84700 1.026785 0.2892617 50.01704
62.89700 1.023409 0.2762690 49.91797
62.94700 1.018996 0.2482964 50.08883
62.99700 1.015370 0.2351440 49.95660
63.04700 1.014960 0.2256584 50.07238
63.09700 1.012725 0.2167139 49.93722
63.14700 1.012459 0.2071527 49.98758
63.19700 1.012350 0.1993912 50.02609
63.24700 1.007578 0.1891538 50.13774
63.29700 1.007342 0.1845356 50.00608
63.34700 1.003216 0.1800391 50.15926
63.39700 1.005458 0.1743520 50.09896
63.44700 1.004092 0.1696507 49.93124
63.49700 1.004977 0.1659188 49.92388
63.54700 1.000109 0.1596515 49.98540
63.59700 1.001363 0.1575289 49.93733
63.64700 0.9977619 0.1542210 49.99326
63.69700 1.001348 0.1517099 49.85744
63.74700 1.003618 0.1485641 50.19235
63.79700 0.9992225 0.1461884 50.17394
63.84700 1.001816 0.1434804 49.99446
63.89700 1.000970 0.1414289 49.89392
63.94700 0.9997204 0.1393576 50.09341
63.99700 1.000771 0.1383436 50.11120
64.04700 1.002250 0.1372095 49.87940
64.09700 0.9993465 0.1354268 50.01266
64.14700 0.9974137 0.1338238 49.95381
64.19701 0.9977820 0.1330599 49.91538
64.24700 0.9958478 0.1316554 50.06786
64.29700 0.9983476 0.1312675 49.94030
64.34700 0.9986212 0.1305707 49.98471
64.39700 0.9973035 0.1304723 49.87566
64.44701 0.9952389 0.1307749 50.02414
64.49700 0.9988970 0.1302155 49.93027
64.54700 0.9942559 0.1267601 49.85684
64.59700 0.9974931 0.1277033 50.15180
64.64700 0.9970570 0.1270954 49.83020
64.69701 0.9939075 0.1260314 50.01519
64.74700 0.9958554 0.1252770 50.14716
64.79700 0.9922539 0.1260652 49.98722
-2.000000 2.000000 0.0000000 0.0000000