File: imagens/notebooks/dados experimentais/dsc/Karl_CTAB100 Ur 41%.txt
CLOSED
Version	1.0
Language	English
Run	1
RunSerial	146
Instrument	DSC Q100 V9.9 Build 303
Module	DSC Standard Cell FC
Operator	LL
File	\\Niger\ta\Data\DSC\2018\Geral\Karl_CTAB100 Ur 41%.002
ProcName	Karl
InstSerial	0100-1211
Sample	CTAB100 Ur 41%
Size	9.64000	mg
Method	Karl
Comment
Xcomment	Pan: Aluminum Hermetic
Xcomment	Gas1: Nitrogen 50.0 ml/min
Xcomment	Gas2: Nitrogen 0.0 ml/min
Text
Exotherm	UP
Kcell	1.09030
Calib	-11.7822
TempCal	1	pts	158.71	156.60
TzeroDt	-90.0515 -0.0093 2.2263
TzeroDtz	-90.0515 0.0466 2.4421
InstCalFile	Tzero: \\Niger\ta\Data\DSC\CALIBRATION\20122016\CALIBRATION\0_RCS_12_20_2016 17_23_31.TZR
InstCalFile	Baseline: \\Niger\ta\Data\DSC\CALIBRATION\20122016\L.Base 20122016
InstCalFile	Sapphire: \\Niger\ta\Data\DSC\CALIBRATION\20122016\Safira 20122017.001
InstCalDate	Tzero 2016-12-20 Time 19:23:31
TempRange	-90.04 to 395.23 °C at 19.96 °C/min Heat Only
AutoZero	Delta T Offset 0.000 uV
AutoZero	Delta T0 Offset 0.000 uV
Controls	Gas 1  Event Off  Sampling 0.2
Cell#	FC-02451
CoolingUnit	RCS
SelHeatFlow	Heat Flow T4 (mW)
AutoAnalysis	Off
MacroFile
Nsig	4
Sig1	Time (min)
Sig2	Temperature (°C)
Sig3	Heat Flow (mW)
Sig4	Sample Purge Flow (mL/min)
Date	2018-05-16
Time	09:39:49
OrgMethod	1: Equilibrate at 1.00 °C
OrgMethod	2: Ramp 2.00 °C/min to 60.00 °C
OrgMethod	3: Isothermal for 3.00 min
OrgMethod	4: Mark end of cycle 1
OrgMethod	5: Ramp 2.00 °C/min to 1.00 °C
OrgMethod	6: Isothermal for 3.00 min
OrgMethod	7: Mark end of cycle 2
OrgFile	C:\TA\Data\DSC\2018\Geral\Karl_CTAB100 Ur 41%.002
3.33324E-4 1.154343 0.8984082 49.95326
0.05033332 1.141832 0.8064290 49.88656
0.1003333 1.158705 0.6905078 49.83786
0.1503333 1.200766 0.5458946 50.16742
0.2003333 1.253922 0.3919094 50.18454
0.2503333 1.316542 0.2448079 50.15363
0.3003333 1.384858 0.1085327 50.09150
0.3503333 1.456582 -.01966744 49.87770
0.4003334 1.531608 -0.1386881 50.06515
0.4503334 1.611167 -0.2420559 49.88452
0.5003334 1.693931 -0.3333231 50.05444
0.5503332 1.778609 -0.4096738 50.07170
0.6003332 1.865075 -0.4778861 49.94119
0.6503332 1.952628 -0.5341944 50.12684
0.7003332 2.043545 -0.5868213 50.03461
0.7503332 2.132963 -0.6269949 50.06942
0.8003332 2.224735 -0.6671362 49.96191
0.8503332 2.317853 -0.6984402 49.79050
0.9003332 2.410966 -0.7263046 49.96735
0.9503334 2.505641 -0.7486595 49.95740
1.000333 2.600613 -0.7676424 50.05026
1.050334 2.697060 -0.7840882 49.91100
1.100334 2.791978 -0.7986035 49.89002
1.150334 2.888620 -0.8100981 49.98076
1.200334 2.984225 -0.8206398 49.92434
1.250334 3.081150 -0.8299714 50.00172
1.300334 3.178034 -0.8387452 50.02318
1.350333 3.275239 -0.8475553 49.96129
1.400333 3.373150 -0.8561382 49.90866
1.450334 3.470542 -0.8646881 49.96795
1.500333 3.569000 -0.8727197 50.00446
1.550334 3.666156 -0.8803735 49.92113
1.600334 3.764488 -0.8876492 50.13933
1.650333 3.862422 -0.8945026 49.96814
1.700334 3.961557 -0.9010968 50.05254
1.750334 4.059120 -0.9073382 49.92812
1.800334 4.158516 -0.9130788 50.01868
1.850334 4.258059 -0.9184179 49.98621
1.900334 4.356579 -0.9233969 50.17379
1.950334 4.455761 -0.9281669 49.85116
2.000334 4.554798 -0.9325668 49.99878
2.050333 4.653817 -0.9365341 49.82324
2.100334 4.753571 -0.9402192 49.83752
2.150334 4.852219 -0.9436606 49.82236
2.200334 4.951368 -0.9469100 50.00803
2.250334 5.050611 -0.9497809 49.97616
2.300333 5.149446 -0.9524766 49.97621
2.350334 5.247714 -0.9548594 50.12740
2.400334 5.348554 -0.9571128 50.04217
2.450334 5.447451 -0.9591864 50.13682
2.500334 5.545762 -0.9610235 50.08552
2.550333 5.645132 -0.9629298 50.07727
2.600333 5.744656 -0.9647218 49.88522
2.650333 5.844187 -0.9664811 49.88865
2.700333 5.943756 -0.9680181 49.97272
2.750333 6.043115 -0.9697274 50.04319
2.800333 6.142074 -0.9713316 50.04252
2.850333 6.241640 -0.9727276 49.90006
2.900333 6.342166 -0.9741303 49.96934
2.950333 6.440238 -0.9754601 49.99648
3.000333 6.540450 -0.9765125 49.98324
3.050333 6.640476 -0.9776056 50.23528
3.100333 6.738616 -0.9787058 50.02906
3.150333 6.838484 -0.9795681 49.95000
3.200333 6.938211 -0.9805816 50.05668
3.250333 7.038050 -0.9814672 50.08119
3.300333 7.137597 -0.9823531 49.76907
3.350333 7.238303 -0.9832569 49.91747
3.400333 7.336462 -0.9842489 49.78742
3.450333 7.437042 -0.9852611 49.99072
3.500333 7.536768 -0.9863254 50.02628
3.550333 7.636368 -0.9873722 50.11474
3.600333 7.736140 -0.9882578 49.91850
3.650333 7.835489 -0.9891988 50.16778
3.700333 7.935206 -0.9901141 50.03332
3.750333 8.035202 -0.9909295 49.75590
3.800333 8.135071 -0.9918710 50.04864
3.850333 8.234863 -0.9927674 50.05258
3.900333 8.334840 -0.9938965 49.99532
3.950333 8.434766 -0.9947274 50.08518
4.000333 8.533695 -0.9955901 49.82672
4.050333 8.633481 -0.9962061 49.95235
4.100333 8.732831 -0.9969816 49.89182
4.150333 8.832684 -0.9976388 50.11922
4.200333 8.932812 -0.9983066 49.91985
4.250333 9.031674 -0.9987569 50.22303
4.300333 9.131746 -0.9991320 49.93272
4.350333 9.231995 -0.9994918 50.07096
4.400333 9.331182 -0.9998866 50.01709
4.450333 9.431249 -1.000333 50.00446
4.500333 9.531001 -1.000579 50.06144
4.550333 9.630011 -1.001058 50.10843
4.600333 9.730004 -1.001664 49.91782
4.650333 9.830285 -1.002147 50.06714
4.700333 9.930006 -1.002789 49.99276
4.750333 10.03037 -1.003279 49.89978
4.800333 10.13026 -1.003934 49.85852
4.850333 10.23035 -1.004403 50.02366
4.900333 10.32983 -1.004918 49.90470
4.950333 10.42919 -1.005329 49.97696
5.000333 10.52895 -1.005934 50.08951
5.050333 10.62955 -1.006508 49.93490
5.100333 10.72863 -1.007183 50.02456
5.150333 10.82801 -1.007729 49.89804
5.200333 10.92829 -1.008285 50.06390
5.250332 11.02855 -1.008866 50.00982
5.300332 11.12825 -1.009245 50.00944
5.350332 11.22896 -1.009726 50.02834
5.400332 11.32986 -1.010188 50.04616
5.450332 11.42965 -1.010654 50.09436
5.500332 11.52870 -1.011231 50.17938
5.550332 11.62859 -1.011698 49.84050
5.600332 11.73032 -1.012158 50.01669
5.650332 11.82868 -1.012684 50.11379
5.700332 11.92902 -1.013139 49.98156
5.750332 12.02875 -1.013641 50.01552
5.800332 12.12932 -1.014142 50.02312
5.850332 12.22892 -1.014371 49.92537
5.900332 12.32886 -1.014724 49.93752
5.950332 12.42876 -1.014944 49.88108
6.000332 12.52878 -1.015198 49.92889
6.050332 12.62828 -1.015495 49.96340
6.100332 12.72839 -1.015730 50.05816
6.150332 12.82848 -1.016089 50.16016
6.200332 12.92908 -1.016399 49.89100
6.250332 13.02862 -1.016813 49.99800
6.300332 13.12826 -1.017132 50.04820
6.350332 13.22806 -1.017389 50.07530
6.400332 13.32874 -1.017478 50.18611
6.450332 13.42793 -1.017863 50.01363
6.500332 13.52839 -1.018053 50.22120
6.550332 13.62842 -1.018568 49.91292
6.600332 13.72710 -1.018793 49.89183
6.650332 13.82694 -1.019060 50.06464
6.700332 13.92815 -1.019442 50.21371
6.750332 14.02762 -1.019772 49.89081
6.800332 14.12746 -1.019879 50.21593
6.850332 14.22602 -1.020130 50.02451
6.900332 14.32725 -1.020287 49.97466
6.950332 14.42609 -1.020656 49.98928
7.000332 14.52654 -1.021019 49.92690
7.050332 14.62706 -1.021330 49.85750
7.100332 14.72609 -1.021656 50.07570
7.150332 14.82628 -1.022186 49.93954
7.200332 14.92703 -1.022574 50.01124
7.250332 15.02709 -1.023185 49.97152
7.300332 15.12655 -1.023685 49.90388
7.350332 15.22652 -1.024108 50.02738
7.400332 15.32690 -1.024541 49.95611
7.450332 15.42666 -1.024978 49.95850
7.500332 15.52748 -1.025409 50.02537
7.550332 15.62645 -1.025789 50.14066
7.600332 15.72684 -1.026299 49.88860
7.650332 15.82745 -1.026612 50.02904
7.700332 15.92734 -1.027027 49.92410
7.750332 16.02698 -1.027382 49.96890
7.800332 16.12676 -1.027581 49.84838
7.850332 16.22642 -1.027988 49.90457
7.900332 16.32676 -1.028113 50.18728
7.950332 16.42659 -1.028310 49.97493
8.000334 16.52682 -1.028530 50.01271
8.050332 16.62633 -1.028722 50.05487
8.100332 16.72626 -1.028672 50.00372
8.150332 16.82631 -1.028806 49.65400
8.200332 16.92625 -1.029018 49.87066
8.250334 17.02664 -1.029242 50.13347
8.300332 17.12455 -1.029552 50.13022
8.350332 17.22611 -1.029620 50.09253
8.400332 17.32532 -1.029778 50.03055
8.450332 17.42466 -1.029896 50.00043
8.500334 17.52559 -1.029832 50.11754
8.550332 17.62426 -1.029862 49.90191
8.600332 17.72563 -1.029932 49.92648
8.650332 17.82459 -1.030038 50.04906
8.700332 17.92526 -1.030300 49.92326
8.750334 18.02534 -1.030612 49.90258
8.800332 18.12561 -1.030864 50.02278
8.850332 18.22483 -1.031382 49.89181
8.900332 18.32566 -1.031662 49.94343
8.950332 18.42548 -1.031994 50.11620
9.000334 18.52542 -1.032361 49.87180
9.050332 18.62522 -1.032579 50.07807
9.100332 18.72519 -1.032831 50.06748
9.150332 18.82416 -1.032947 49.87026
9.200332 18.92422 -1.033142 49.87739
9.250334 19.02472 -1.033226 49.95478
9.300332 19.12403 -1.033132 50.01452
9.350332 19.22385 -1.033216 49.91930
9.400332 19.32265 -1.033358 50.03824
9.450332 19.42421 -1.033463 49.94128
9.500334 19.52355 -1.033681 50.05700
9.550332 19.62325 -1.033940 50.02613
9.600332 19.72306 -1.034160 50.09627
9.650332 19.82316 -1.034600 49.91684
9.700332 19.92273 -1.034918 49.94363
9.750334 20.02301 -1.035169 49.79562
9.800332 20.12288 -1.035617 50.01228
9.850332 20.22349 -1.036008 50.05316
9.900332 20.32306 -1.036554 49.91300
9.950332 20.42344 -1.037085 50.00602
10.00033 20.52293 -1.037471 49.98224
10.05033 20.62374 -1.038038 49.93387
10.10033 20.72373 -1.038557 49.96372
10.15033 20.82301 -1.039061 49.96608
10.20033 20.92366 -1.039469 50.00432
10.25033 21.02333 -1.039758 50.02572
10.30033 21.12270 -1.040288 50.09596
10.35033 21.22344 -1.040629 49.92670
10.40033 21.32344 -1.041222 49.78672
10.45033 21.42374 -1.041488 49.77084
10.50034 21.52350 -1.041890 50.12626
10.55033 21.62326 -1.042132 50.07060
10.60033 21.72370 -1.042494 49.96540
10.65033 21.82346 -1.042656 49.96118
10.70033 21.92333 -1.042995 49.96972
10.75034 22.02362 -1.042894 49.90780
10.80033 22.12310 -1.043185 49.99454
10.85033 22.22277 -1.043333 50.07031
10.90033 22.32322 -1.043512 50.11799
10.95033 22.42178 -1.043607 49.82466
11.00034 22.52212 -1.043743 49.95587
11.05033 22.62186 -1.043635 49.99438
11.10033 22.72130 -1.043763 49.96253
11.15033 22.82240 -1.044022 50.02030
11.20033 22.92079 -1.044156 50.10406
11.25034 23.02161 -1.044387 50.06563
11.30033 23.12116 -1.044576 49.87914
11.35033 23.22127 -1.044864 50.08594
11.40033 23.32099 -1.045199 50.11166
11.45033 23.42098 -1.045720 49.90104
11.50034 23.52070 -1.046343 50.01786
11.55033 23.61984 -1.046980 49.84410
11.60033 23.72148 -1.047583 50.04418
11.65033 23.82176 -1.048068 50.09828
11.70033 23.92114 -1.048622 50.14615
11.75034 24.02164 -1.049243 50.03174
11.80033 24.12104 -1.049820 50.11600
11.85033 24.22110 -1.050298 49.91357
11.90033 24.32138 -1.050596 50.14233
11.95033 24.42159 -1.050923 50.10524
12.00034 24.52118 -1.051233 49.90578
12.05033 24.62092 -1.051697 50.01549
12.10033 24.72114 -1.052012 49.98654
12.15033 24.82139 -1.052419 49.98098
12.20033 24.92151 -1.052794 49.94207
12.25034 25.02098 -1.053057 49.95342
12.30033 25.12096 -1.053390 50.05006
12.35033 25.22090 -1.053705 49.93035
12.40033 25.32016 -1.054083 50.08359
12.45033 25.42094 -1.054372 49.90982
12.50034 25.52150 -1.054771 49.99203
12.55033 25.62055 -1.055123 49.89776
12.60033 25.72142 -1.055505 49.99780
12.65033 25.81973 -1.055844 50.06064
12.70033 25.92114 -1.056407 49.72534
12.75034 26.02008 -1.056979 50.09422
12.80033 26.12091 -1.057506 50.31611
12.85033 26.22113 -1.058151 49.87400
12.90033 26.32115 -1.059005 50.05696
12.95034 26.42190 -1.059612 50.07444
13.00034 26.52004 -1.060145 49.89854
13.05033 26.62032 -1.060842 50.01844
13.10033 26.72070 -1.061454 50.06740
13.15033 26.82084 -1.061936 50.01230
13.20034 26.92108 -1.062427 50.07518
13.25034 27.02018 -1.062723 49.98270
13.30033 27.11958 -1.063147 50.10640
13.35033 27.22028 -1.063455 49.98560
13.40033 27.31986 -1.063678 50.07656
13.45034 27.41942 -1.064072 50.13261
13.50034 27.51970 -1.064365 49.88404
13.55033 27.61994 -1.064894 49.96244
13.60033 27.71932 -1.065234 49.97670
13.65033 27.81925 -1.065856 50.00937
13.70034 27.91945 -1.066443 49.97469
13.75034 28.01995 -1.067275 49.95214
13.80033 28.11911 -1.068023 50.05524
13.85033 28.21981 -1.068813 49.94340
13.90033 28.31980 -1.069727 50.03650
13.95034 28.41868 -1.070645 49.84872
14.00034 28.51987 -1.071805 49.96852
14.05033 28.61936 -1.072826 49.91450
14.10033 28.71820 -1.073896 50.01444
14.15033 28.81862 -1.075064 49.97139
14.20034 28.91855 -1.076414 49.96960
14.25034 29.01830 -1.077787 50.04090
14.30033 29.11803 -1.079343 50.14734
14.35033 29.21680 -1.081201 49.83657
14.40033 29.31626 -1.083630 49.80972
14.45034 29.41582 -1.086633 49.86869
14.50034 29.51567 -1.090366 49.92389
14.55033 29.61524 -1.094764 49.94150
14.60033 29.71486 -1.100580 50.00836
14.65033 29.81372 -1.107918 50.09678
14.70034 29.91254 -1.117586 50.12638
14.75034 30.01055 -1.135211 50.07000
14.80033 30.10974 -1.160381 50.07814
14.85033 30.20833 -1.198135 49.96882
14.90033 30.30556 -1.240396 50.06326
14.95034 30.40316 -1.287276 50.00642
15.00034 30.49942 -1.339151 49.93554
15.05033 30.59596 -1.394133 49.98904
15.10033 30.69146 -1.453564 49.94706
15.15033 30.78652 -1.512859 50.13204
15.20034 30.88155 -1.571538 49.89317
15.25034 30.97676 -1.631445 49.97144
15.30033 31.07281 -1.687277 49.98386
15.35033 31.16811 -1.737100 50.02472
15.40033 31.26308 -1.788276 49.93254
15.45034 31.36031 -1.831072 50.10954
15.50034 31.45455 -1.871299 49.95788
15.55033 31.55170 -1.907652 49.97228
15.60033 31.64807 -1.940632 49.80546
15.65033 31.74478 -1.972486 49.94809
15.70034 31.84231 -2.000677 49.92578
15.75034 31.94028 -2.024381 49.95276
15.80033 32.03846 -2.046045 50.08259
15.85033 32.13542 -2.063978 49.96860
15.90033 32.23506 -2.080923 50.06196
15.95034 32.33372 -2.095869 49.85824
16.00033 32.43152 -2.107838 50.10754
16.05033 32.52980 -2.120832 49.95294
16.10033 32.62946 -2.132242 50.02960
16.15033 32.72751 -2.142295 50.13891
16.20033 32.82740 -2.152226 50.01843
16.25033 32.92730 -2.161697 49.97000
16.30033 33.02643 -2.170596 50.03425
16.35033 33.12569 -2.179537 50.07960
16.40033 33.22516 -2.187961 50.02935
16.45033 33.32407 -2.195600 50.01596
16.50033 33.42441 -2.202866 50.02094
16.55033 33.52434 -2.209059 50.08230
16.60033 33.62394 -2.214587 50.21740
16.65033 33.72390 -2.219167 49.95113
16.70033 33.82352 -2.223050 50.10758
16.75033 33.92268 -2.225951 49.92900
16.80033 34.02217 -2.227744 49.97798
16.85033 34.12274 -2.228536 49.92006
16.90033 34.22204 -2.228270 49.93652
16.95033 34.32317 -2.226985 50.21184
17.00033 34.42292 -2.224211 50.09122
17.05033 34.52397 -2.220199 50.06828
17.10033 34.62422 -2.214299 50.01690
17.15033 34.72556 -2.206141 50.01414
17.20033 34.82742 -2.195214 50.06992
17.25033 34.92869 -2.177320 50.03119
17.30033 35.03044 -2.155243 49.99396
17.35033 35.13176 -2.126100 50.03491
17.40033 35.23471 -2.097955 50.05286
17.45033 35.33622 -2.067613 49.88772
17.50033 35.43864 -2.037672 50.05330
17.55033 35.54146 -2.012611 50.07532
17.60033 35.64285 -1.987540 49.96316
17.65033 35.74586 -1.961649 49.96085
17.70033 35.84760 -1.929194 50.20300
17.75033 35.94998 -1.887121 50.02993
17.80033 36.05355 -1.824283 50.03384
17.85033 36.15806 -1.738586 49.94897
17.90033 36.26568 -1.639979 50.08314
17.95033 36.37150 -1.550654 49.95809
18.00033 36.47828 -1.475635 49.82480
18.05033 36.58444 -1.412314 50.01762
18.10033 36.68974 -1.364806 50.02128
18.15033 36.79361 -1.323343 50.19838
18.20033 36.89750 -1.288446 50.20586
18.25033 36.99996 -1.260956 50.02281
18.30033 37.10312 -1.239147 49.89912
18.35033 37.20445 -1.220919 49.99313
18.40033 37.30588 -1.208254 50.24414
18.45033 37.40802 -1.198864 49.91317
18.50033 37.51005 -1.190110 50.14289
18.55033 37.60928 -1.182476 49.80150
18.60033 37.71051 -1.174542 49.94624
18.65033 37.81134 -1.167018 49.85413
18.70033 37.91192 -1.159940 49.93624
18.75033 38.01175 -1.153289 49.99506
18.80033 38.11272 -1.147267 49.88359
18.85033 38.21192 -1.142002 50.08465
18.90033 38.31188 -1.137261 50.01288
18.95033 38.41295 -1.133205 50.06780
19.00033 38.51211 -1.129691 49.96759
19.05033 38.61254 -1.126670 50.05471
19.10033 38.71228 -1.124197 50.13276
19.15033 38.81262 -1.122142 49.96933
19.20033 38.91280 -1.120447 50.00622
19.25033 39.01271 -1.118849 50.00461
19.30033 39.11325 -1.117478 50.03325
19.35033 39.21196 -1.116470 49.95282
19.40033 39.31325 -1.115775 50.01410
19.45033 39.41308 -1.115213 50.00820
19.50033 39.51282 -1.114902 50.02702
19.55033 39.61298 -1.114579 49.86980
19.60033 39.71198 -1.114372 50.14914
19.65033 39.81254 -1.114078 49.97124
19.70033 39.91102 -1.113945 49.84850
19.75033 40.01232 -1.113899 49.91294
19.80033 40.11234 -1.114054 50.04648
19.85033 40.21095 -1.114444 49.78739
19.90033 40.31094 -1.114753 49.97033
19.95033 40.41142 -1.115343 50.02836
20.00033 40.51107 -1.115835 50.00720
20.05033 40.61205 -1.116332 49.99724
20.10033 40.71176 -1.116991 50.08740
20.15033 40.81090 -1.117506 49.98667
20.20033 40.91196 -1.118160 49.81455
20.25033 41.01119 -1.118706 50.12479
20.30033 41.11153 -1.119246 50.04926
20.35033 41.21104 -1.119811 49.97769
20.40033 41.31154 -1.120449 50.14704
20.45033 41.41028 -1.121097 49.96168
20.50033 41.51120 -1.121688 49.95740
20.55033 41.61111 -1.122563 49.92934
20.60033 41.71122 -1.123196 50.00730
20.65033 41.81088 -1.123848 49.91832
20.70033 41.91056 -1.124278 50.03836
20.75033 42.01022 -1.124728 49.99429
20.80033 42.11052 -1.124943 49.92798
20.85033 42.20926 -1.125092 49.94756
20.90033 42.30947 -1.125479 50.02330
20.95033 42.40946 -1.125830 50.07639
21.00033 42.50925 -1.126492 50.08063
21.05033 42.60972 -1.127031 49.92738
21.10033 42.70868 -1.127688 50.10818
21.15033 42.80950 -1.128290 50.02460
21.20033 42.90938 -1.129118 50.07136
21.25033 43.00956 -1.129862 50.09291
21.30033 43.10950 -1.130826 49.97710
21.35033 43.20922 -1.131710 49.30262
21.40033 43.31015 -1.132544 50.19060
21.45033 43.40968 -1.133720 49.91126
21.50033 43.50890 -1.134604 49.87940
21.55033 43.60976 -1.135402 49.94162
21.60033 43.70969 -1.136156 50.00033
21.65033 43.80910 -1.136876 49.89925
21.70033 43.90987 -1.137276 50.09634
21.75033 44.00880 -1.137688 50.01389
21.80033 44.10843 -1.138144 49.92720
21.85033 44.20902 -1.138631 50.05000
21.90033 44.30860 -1.139191 50.30320
21.95033 44.40754 -1.139927 49.86074
22.00033 44.50840 -1.140705 50.03085
22.05033 44.60792 -1.141336 50.06153
22.10033 44.70777 -1.142166 49.90626
22.15033 44.80862 -1.143220 50.12990
22.20033 44.90806 -1.144219 49.81711
22.25033 45.00952 -1.145220 50.02826
22.30033 45.10891 -1.146054 50.07215
22.35033 45.20784 -1.146946 50.04942
22.40033 45.30795 -1.147724 50.00041
22.45033 45.40754 -1.148380 49.83944
22.50033 45.50765 -1.149036 49.99552
22.55033 45.60776 -1.149626 49.87418
22.60033 45.70680 -1.150151 49.99830
22.65033 45.80710 -1.150709 49.93568
22.70033 45.90762 -1.151523 49.89754
22.75033 46.00779 -1.152352 49.92688
22.80033 46.10800 -1.153163 50.01032
22.85033 46.20752 -1.153928 50.02895
22.90033 46.30806 -1.154691 49.95306
22.95033 46.40789 -1.155543 50.11226
23.00033 46.50782 -1.156377 50.09590
23.05033 46.60701 -1.157109 49.99063
23.10033 46.70754 -1.157958 49.85008
23.15033 46.80689 -1.158820 49.97831
23.20033 46.90743 -1.159441 49.83046
23.25033 47.00718 -1.160316 50.05735
23.30033 47.10760 -1.161080 50.02014
23.35033 47.20690 -1.162241 50.04778
23.40033 47.30604 -1.163144 49.80334
23.45033 47.40660 -1.163983 49.95053
23.50033 47.50778 -1.164833 49.92922
23.55033 47.60628 -1.165502 50.12532
23.60033 47.70589 -1.166154 49.94696
23.65033 47.80619 -1.166985 49.94052
23.70033 47.90613 -1.167975 49.95299
23.75033 48.00644 -1.169158 49.89498
23.80033 48.10562 -1.170186 49.99508
23.85033 48.20616 -1.171244 49.79023
23.90033 48.30692 -1.172176 50.05106
23.95033 48.40637 -1.173075 49.93123
24.00033 48.50492 -1.173625 49.93168
24.05033 48.60481 -1.174193 49.41758
24.10033 48.70465 -1.174545 50.04526
24.15033 48.80488 -1.174943 50.00156
24.20033 48.90461 -1.175564 49.95484
24.25033 49.00473 -1.176234 50.01324
24.30033 49.10412 -1.177290 49.99300
24.35033 49.20460 -1.178302 49.77710
24.40033 49.30356 -1.179350 50.11791
24.45033 49.40461 -1.180578 50.02898
24.50033 49.50440 -1.181677 49.97230
24.55033 49.60470 -1.183050 49.89564
24.60033 49.70530 -1.184095 49.97822
24.65033 49.80457 -1.185151 49.94713
24.70033 49.90454 -1.185947 49.94428
24.75033 50.00447 -1.187236 50.02404
24.80033 50.10453 -1.188152 49.83340
24.85033 50.20451 -1.189029 50.17746
24.90033 50.30397 -1.189996 49.98276
24.95033 50.40408 -1.190846 49.87274
25.00033 50.50442 -1.191627 50.20978
25.05033 50.60328 -1.192493 49.96383
25.10033 50.70324 -1.193541 50.05466
25.15033 50.80284 -1.194446 50.09549
25.20033 50.90364 -1.195447 49.86604
25.25033 51.00292 -1.196465 49.97254
25.30033 51.10288 -1.197234 49.88993
25.35033 51.20295 -1.198157 50.07511
25.40033 51.30348 -1.199118 49.97781
25.45033 51.40298 -1.200057 49.95868
25.50033 51.50391 -1.201002 50.02283
25.55033 51.60278 -1.202271 50.23013
25.60033 51.70212 -1.203486 50.12997
25.65033 51.80316 -1.204581 49.99222
25.70033 51.90305 -1.205678 49.86802
25.75033 52.00271 -1.206696 49.83606
25.80033 52.10180 -1.207694 50.00216
25.85033 52.20160 -1.208700 50.06700
25.90033 52.30218 -1.209762 49.86804
25.95033 52.40147 -1.210859 49.92234
26.00033 52.50160 -1.211908 50.25598
26.05033 52.60056 -1.212933 49.96348
26.10033 52.70121 -1.213888 49.89120
26.15033 52.80057 -1.214812 50.05670
26.20033 52.90034 -1.215474 49.97412
26.25033 53.00000 -1.216240 50.09233
26.30033 53.09986 -1.217140 49.92883
26.35033 53.20020 -1.218188 49.81086
26.40033 53.29959 -1.219466 50.13692
26.45033 53.39990 -1.220973 50.15409
26.50033 53.50010 -1.222587 49.89032
26.55033 53.59958 -1.224234 50.08477
26.60033 53.69991 -1.226093 49.89975
26.65033 53.80048 -1.227644 49.94906
26.70033 53.90012 -1.229237 50.08944
26.75033 54.00035 -1.230817 49.80261
26.80033 54.10020 -1.232391 49.86270
26.85033 54.19941 -1.233934 49.86904
26.90033 54.30053 -1.235352 50.02108
26.95033 54.40034 -1.236692 49.99685
27.00033 54.49945 -1.237895 50.01704
27.05033 54.60000 -1.238837 49.55373
27.10033 54.70059 -1.239980 50.02612
27.15033 54.79986 -1.241138 50.04352
27.20033 54.89955 -1.242261 49.90794
27.25033 54.99974 -1.243456 49.57057
27.30033 55.09970 -1.244436 50.20536
27.35033 55.19986 -1.245508 50.03692
27.40033 55.29961 -1.246398 50.06184
27.45033 55.39934 -1.246977 50.17016
27.50033 55.49829 -1.247771 49.97642
27.55033 55.59849 -1.248758 50.04795
27.60033 55.69854 -1.249851 50.09784
27.65033 55.79799 -1.251121 50.07344
27.70033 55.89855 -1.252325 50.04458
27.75033 55.99744 -1.253290 49.83650
27.80033 56.09726 -1.254464 50.03210
27.85033 56.19634 -1.255466 49.99034
27.90033 56.29701 -1.256863 50.08109
27.95033 56.39652 -1.258135 50.11356
28.00033 56.49686 -1.259472 50.01403
28.05033 56.59644 -1.260783 49.98072
28.10033 56.69633 -1.262015 49.98911
28.15033 56.79570 -1.263427 50.03381
28.20033 56.89551 -1.264576 49.96796
28.25033 56.99543 -1.265880 50.05492
28.30033 57.09488 -1.266963 50.08784
28.35033 57.19504 -1.268004 49.91885
28.40033 57.29468 -1.269216 50.07313
28.45033 57.39395 -1.270356 49.78366
28.50033 57.49492 -1.271606 49.82566
28.55033 57.59430 -1.272927 50.00720
28.60033 57.69360 -1.274288 49.95129
28.65033 57.79352 -1.275664 49.85154
28.70033 57.89415 -1.277285 49.89730
28.75033 57.99421 -1.279014 50.07539
28.80033 58.09370 -1.280759 50.03568
28.85033 58.19387 -1.282715 50.08068
28.90033 58.29491 -1.284703 50.07097
28.95033 58.39391 -1.286570 50.11902
29.00033 58.49366 -1.288184 50.05660
29.05033 58.59382 -1.289710 50.11810
29.10033 58.69372 -1.291212 49.90748
29.15033 58.79386 -1.292886 49.81910
29.20033 58.89304 -1.294553 50.10010
29.25033 58.99299 -1.296024 50.18015
29.30033 59.09312 -1.297474 50.15056
29.35033 59.19226 -1.298624 49.41911
29.40033 59.29184 -1.299744 50.16572
29.45033 59.39156 -1.300814 49.96447
29.50033 59.49168 -1.301962 49.98806
29.55033 59.58855 -1.303718 49.97050
29.60033 59.65982 -1.302398 50.08990
29.65033 59.70618 -1.222277 50.10026
29.70033 59.74343 -1.113545 49.97937
29.75033 59.77418 -1.006386 49.98948
29.80033 59.79980 -0.9005539 50.12902
29.85033 59.82021 -0.8034201 50.01490
29.90033 59.83700 -0.7157397 50.16750
29.95033 59.85093 -0.6384599 49.96740
30.00033 59.86411 -0.5699419 50.03364
30.05033 59.87406 -0.5136940 50.05034
30.10033 59.88322 -0.4635266 50.08774
30.15033 59.89022 -0.4177456 49.86866
30.20033 59.89643 -0.3846972 49.82198
30.25033 59.90246 -0.3549916 50.01572
30.30033 59.90785 -0.3322844 49.86310
30.35033 59.91138 -0.3131444 49.82242
30.40033 59.91516 -0.2968700 49.96602
30.45033 59.91844 -0.2829580 50.03367
30.50033 59.92188 -0.2727072 50.01807
30.55033 59.92426 -0.2631029 49.87378
30.60033 59.92543 -0.2541975 50.02340
30.65033 59.92842 -0.2458057 49.94415
30.70033 59.92976 -0.2376717 49.90470
30.75033 59.93128 -0.2297444 49.92910
30.80033 59.93199 -0.2223371 50.11313
30.85033 59.93402 -0.2153305 49.39960
30.90033 59.93462 -0.2089475 49.96756
30.95033 59.93598 -0.2028892 50.02765
31.00033 59.93806 -0.1977446 49.94710
31.05033 59.93703 -0.1928675 49.96838
31.10033 59.93863 -0.1881574 49.89060
31.15033 59.93847 -0.1838280 50.01903
31.20033 59.93882 -0.1797754 49.83713
31.25033 59.93840 -0.1759848 50.13530
31.30033 59.93899 -0.1724531 50.01386
31.35033 59.93980 -0.1693395 49.99220
31.40033 59.93906 -0.1665643 50.15191
31.45033 59.93958 -0.1643434 50.04507
31.50033 59.94068 -0.1625697 50.15063
31.55033 59.94055 -0.1609383 50.20774
31.60033 59.94148 -0.1596306 49.81279
31.65033 59.94078 -0.1584545 50.17742
31.70033 59.94205 -0.1574438 50.22462
31.75033 59.94250 -0.1567622 49.53720
31.80033 59.94282 -0.1560196 49.85818
31.85034 59.94220 -0.1554798 50.05148
31.90033 59.94388 -0.1550146 50.01830
31.95033 59.94350 -0.1544351 49.96359
32.00033 59.94312 -0.1538186 50.11612
32.05033 59.94387 -0.1531407 49.98953
32.10034 59.94360 -0.1522134 49.96435
32.15033 59.94434 -0.1515426 49.91993
32.20033 59.94324 -0.1510261 49.92140
32.25033 59.94488 -0.1506339 50.05509
32.30033 59.94431 -0.1503260 50.08020
32.35034 59.94452 -0.1501550 50.09688
32.40033 59.94542 -0.1498286 49.98354
32.45033 59.94520 -0.1496107 49.85941
-2.000000 1.000000 0.0000000 0.0000000
32.54700 59.94126 -0.1496124 50.08874
32.59700 59.91552 -0.1463432 50.25212
32.64700 59.86264 -.05586196 50.12778
32.69700 59.79818 0.05717422 50.20962
32.74700 59.72744 0.1652606 49.90790
32.79700 59.65250 0.2713570 50.06083
32.84700 59.57288 0.3700370 49.98300
32.89700 59.48940 0.4624106 49.83317
32.94700 59.40300 0.5416199 49.96566
32.99700 59.31616 0.6142080 49.93940
33.04700 59.22568 0.6719968 49.93180
33.09700 59.13381 0.7236062 49.96682
33.14700 59.04196 0.7653594 50.08154
33.19700 58.94834 0.8025550 49.98402
33.24700 58.85329 0.8345795 50.11580
33.29700 58.75820 0.8601161 50.16162
33.34700 58.66184 0.8821488 50.06612
33.39700 58.56572 0.8997491 49.99133
33.44700 58.46863 0.9151574 50.15650
33.49700 58.37098 0.9267762 50.04370
33.54700 58.27358 0.9370285 50.02438
33.59700 58.17590 0.9467561 49.91680
33.64700 58.07711 0.9548655 50.05830
33.69700 57.97911 0.9631772 50.02933
33.74700 57.88104 0.9715458 50.04588
33.79700 57.78165 0.9796684 49.92298
33.84700 57.68230 0.9878084 50.02576
33.89700 57.58318 0.9952062 50.05120
33.94700 57.48408 1.002187 49.95413
33.99700 57.38554 1.008724 50.03552
34.04700 57.28462 1.014929 49.91791
34.09700 57.18682 1.020672 50.10532
34.14700 57.08671 1.025802 50.00128
34.19700 56.98756 1.030608 50.15216
34.24700 56.88798 1.034895 49.85111
34.29700 56.78913 1.038846 49.87266
34.34700 56.68981 1.042398 49.91480
34.39700 56.58987 1.045648 50.06219
34.44700 56.49060 1.048630 49.90878
34.49700 56.39228 1.051535 49.84242
34.54700 56.29278 1.053976 49.92276
34.59700 56.19294 1.056417 50.12934
34.64700 56.09380 1.058774 49.91534
34.69700 55.99429 1.060917 49.93860
34.74700 55.89368 1.062976 50.12027
34.79700 55.79480 1.065307 50.00143
34.84700 55.69522 1.067450 50.05912
34.89700 55.59634 1.069500 49.78183
34.94700 55.49634 1.071508 49.79804
34.99700 55.39584 1.073673 49.93010
35.04700 55.29699 1.075581 49.88368
35.09700 55.19695 1.077449 49.94522
35.14700 55.09730 1.079246 49.99394
35.19700 54.99708 1.081260 49.77594
35.24700 54.89715 1.083100 49.94548
35.29700 54.79724 1.085044 50.10928
35.34700 54.69792 1.086762 50.03666
35.39700 54.59762 1.088476 49.91804
35.44700 54.49758 1.090204 50.07233
35.49700 54.39770 1.091701 50.06233
35.54700 54.29830 1.093196 50.04016
35.59700 54.19900 1.094567 49.92712
35.64700 54.09893 1.095841 49.98176
35.69700 54.00019 1.097022 50.08082
35.74700 53.89996 1.098269 49.76002
35.79700 53.80086 1.099584 49.94906
35.84700 53.70080 1.100756 50.05398
35.89700 53.60033 1.101964 49.97936
35.94700 53.50137 1.103208 50.05770
35.99700 53.40190 1.104400 50.23758
36.04700 53.30108 1.105627 49.96104
36.09700 53.20198 1.106896 49.99756
36.14700 53.10274 1.108146 49.85802
36.19700 53.00226 1.109555 50.04346
36.24700 52.90246 1.110946 49.79328
36.29700 52.80234 1.112324 49.92266
36.34700 52.70270 1.113710 49.98990
36.39700 52.60239 1.115189 50.07514
36.44700 52.50260 1.116719 49.87002
36.49700 52.40281 1.118243 49.79790
36.54700 52.30234 1.119634 49.98350
36.59700 52.20232 1.121212 49.96612
36.64700 52.10254 1.122410 49.80603
36.69700 52.00284 1.123576 49.99740
36.74700 51.90354 1.124537 50.19668
36.79700 51.80368 1.125406 49.93127
36.84700 51.70403 1.126334 49.90984
36.89700 51.60406 1.127267 49.94399
36.94700 51.50445 1.128241 49.88320
36.99700 51.40504 1.129055 49.91754
37.04700 51.30559 1.129972 49.99420
37.09700 51.20618 1.131059 50.01631
37.14700 51.10564 1.131943 50.37683
37.19700 51.00594 1.133050 50.13204
37.24700 50.90542 1.134119 49.93028
37.29700 50.80683 1.135216 49.97293
37.34700 50.70645 1.136440 50.16336
37.39700 50.60675 1.137514 49.99528
37.44700 50.50678 1.138673 49.92550
37.49700 50.40628 1.139810 50.08609
37.54700 50.30626 1.140993 49.92148
37.59700 50.20696 1.142213 49.93830
37.64700 50.10650 1.143671 49.98078
37.69700 50.00644 1.144861 49.99024
37.74700 49.90724 1.145850 49.95019
37.79700 49.80676 1.146996 50.10628
37.84700 49.70734 1.148004 49.86336
37.89700 49.60718 1.148837 50.02676
37.94700 49.50806 1.149596 49.99561
37.99700 49.40812 1.150391 50.01418
38.04700 49.30728 1.151124 49.91284
38.09700 49.20852 1.151942 50.00180
38.14700 49.10788 1.152661 50.15450
38.19700 49.00919 1.153564 49.89814
38.24700 48.90919 1.154364 50.05307
38.29700 48.80981 1.155258 49.96117
38.34700 48.70917 1.156228 49.75422
38.39700 48.60963 1.157264 49.78542
38.44700 48.50926 1.158175 50.06953
38.49700 48.41016 1.159125 49.88568
38.54700 48.31049 1.160325 49.83783
38.59700 48.21035 1.161261 50.10313
38.64700 48.11116 1.162298 49.98550
38.69700 48.01102 1.163055 49.97784
38.74700 47.91118 1.164004 49.96822
38.79700 47.81161 1.165056 50.04795
38.84700 47.71125 1.166084 49.94711
38.89700 47.61168 1.167220 49.91854
38.94700 47.51038 1.168498 49.86202
38.99700 47.41131 1.169710 49.94039
39.04700 47.31119 1.170905 50.14695
39.09700 47.21127 1.172057 49.96543
39.14700 47.11072 1.173019 50.36969
39.19700 47.01148 1.173888 49.98758
39.24700 46.91174 1.174671 49.99472
39.29700 46.81239 1.175535 49.93411
39.34700 46.71193 1.176237 50.06541
39.39700 46.61286 1.176914 49.86688
39.44700 46.51187 1.177691 49.93406
39.49700 46.41246 1.178401 49.95559
39.54700 46.31301 1.179269 49.86188
39.59700 46.21294 1.180427 50.11204
39.64700 46.11287 1.181403 50.13970
39.69700 46.01243 1.182432 50.18482
39.74700 45.91410 1.183310 49.97182
39.79700 45.81395 1.184134 50.08152
39.84700 45.71364 1.185069 50.02778
39.89700 45.61366 1.185771 49.87084
39.94700 45.51434 1.186517 49.95618
39.99700 45.41348 1.187308 49.94559
40.04700 45.31364 1.188069 49.99588
40.09700 45.21472 1.188815 50.05411
40.14700 45.11381 1.189618 50.01859
40.19700 45.01465 1.190386 49.97733
40.24700 44.91396 1.191222 50.07831
40.29700 44.81481 1.191969 50.00379
40.34700 44.71472 1.192563 50.03913
40.39700 44.61518 1.193250 49.93298
40.44700 44.51400 1.193876 50.04836
40.49700 44.41551 1.194537 49.97862
40.54700 44.31481 1.195155 50.00366
40.59700 44.21547 1.195808 49.99719
40.64700 44.11531 1.196372 49.97384
40.69700 44.01549 1.197095 50.05744
40.74700 43.91609 1.197660 50.25398
40.79700 43.81562 1.198561 49.94478
40.84700 43.71588 1.199243 49.99653
40.89700 43.61598 1.200003 49.88424
40.94700 43.51652 1.200574 49.91000
40.99700 43.41566 1.201208 50.05967
41.04700 43.31610 1.201905 50.08898
41.09700 43.21568 1.202726 50.14904
41.14700 43.11646 1.203456 50.07812
41.19700 43.01547 1.204464 50.06042
41.24700 42.91560 1.205421 50.12450
41.29700 42.81604 1.206195 49.89609
41.34700 42.71559 1.206965 49.86828
41.39700 42.61585 1.207620 50.16334
41.44700 42.51633 1.208342 50.02112
41.49700 42.41634 1.208875 50.22180
41.54700 42.31675 1.209199 49.89135
41.59700 42.21656 1.209753 50.11165
41.64700 42.11640 1.210166 49.89307
41.69700 42.01700 1.210692 50.24068
41.74700 41.91680 1.211168 49.99531
41.79700 41.81791 1.211672 49.86518
41.84700 41.71816 1.212066 50.01308
41.89700 41.61834 1.212582 49.84946
41.94700 41.51822 1.212932 50.09879
41.99700 41.41802 1.213432 50.05344
42.04700 41.31889 1.213828 50.05008
42.09700 41.21854 1.214288 49.97574
42.14700 41.11844 1.214776 50.00094
42.19700 41.01821 1.215302 50.15457
42.24700 40.91940 1.215663 50.11144
42.29700 40.81859 1.216197 49.92078
42.34700 40.71918 1.216647 49.94969
42.39700 40.61934 1.217233 50.06754
42.44700 40.51902 1.217792 50.13320
42.49700 40.41928 1.218459 50.11291
42.54700 40.31900 1.219320 49.87678
42.59700 40.21984 1.220178 49.95118
42.64700 40.11944 1.221012 50.10137
42.69700 40.01905 1.221801 50.00094
42.74700 39.91946 1.222517 50.07196
42.79700 39.81929 1.223146 50.06524
42.84700 39.71888 1.223660 50.05492
42.89700 39.61931 1.224150 49.82187
42.94700 39.51980 1.224690 50.00516
42.99700 39.41990 1.225195 49.95843
43.04700 39.32022 1.225429 50.06462
43.09700 39.22045 1.225645 50.12070
43.14700 39.12051 1.225993 49.80801
43.19700 39.02070 1.226446 49.96680
43.24700 38.92110 1.226712 49.85370
43.29700 38.82090 1.227083 50.26434
43.34700 38.72114 1.227563 50.06934
43.39700 38.62108 1.227940 49.31391
43.44700 38.52026 1.228436 50.07180
43.49700 38.42139 1.228836 50.01740
43.54700 38.32190 1.229208 50.01352
43.59700 38.22307 1.229645 50.01811
43.64700 38.12212 1.229984 49.91148
43.69700 38.02236 1.230558 49.98440
43.74700 37.92265 1.231104 50.00184
43.79700 37.82269 1.231456 50.06222
43.84700 37.72231 1.231957 50.06866
43.89700 37.62239 1.232491 49.99824
43.94700 37.52378 1.232783 50.03735
43.99700 37.42328 1.233401 49.94804
44.04700 37.32336 1.233891 49.93097
44.09700 37.22331 1.234414 49.98878
44.14700 37.12430 1.234737 50.10664
44.19700 37.02383 1.235419 50.05918
44.24700 36.92311 1.236071 49.98795
44.29700 36.82334 1.236906 49.84488
44.34700 36.72294 1.237766 49.98111
44.39700 36.62264 1.238460 50.07254
44.44700 36.52295 1.239227 49.97604
44.49700 36.42278 1.239837 50.05781
44.54700 36.32308 1.240495 50.05865
44.59700 36.22210 1.241072 49.92545
44.64700 36.12294 1.241706 49.84739
44.69700 36.02280 1.242180 49.99478
44.74700 35.92298 1.242547 49.96700
44.79700 35.82209 1.242971 50.02389
44.84700 35.72340 1.243294 49.94502
44.89700 35.62210 1.243438 50.06314
44.94700 35.52315 1.243556 49.81789
44.99700 35.42395 1.243640 50.14058
45.04700 35.32298 1.243626 50.10175
45.09700 35.22400 1.243845 50.00200
45.14700 35.12370 1.244053 49.89372
45.19700 35.02403 1.244087 50.01716
45.24700 34.92460 1.244178 49.98416
45.29700 34.82428 1.244426 50.07363
45.34700 34.72494 1.244490 49.85842
45.39700 34.62570 1.244589 49.94770
45.44700 34.52461 1.244916 49.92858
45.49700 34.42517 1.245150 49.87418
45.54700 34.32577 1.245535 49.85812
45.59700 34.22475 1.245953 50.03840
45.64700 34.12472 1.246255 50.09272
45.69700 34.02560 1.246592 50.12356
45.74700 33.92550 1.246918 50.08361
45.79700 33.82516 1.247394 50.00109
45.84700 33.72644 1.247691 50.11721
45.89700 33.62506 1.248086 49.92484
45.94700 33.52554 1.248504 50.08224
45.99700 33.42512 1.248951 50.04561
46.04700 33.32555 1.249338 49.95266
46.09700 33.22570 1.249590 49.98981
46.14700 33.12610 1.249913 49.93838
46.19700 33.02540 1.250146 50.03812
46.24700 32.92565 1.250461 50.08374
46.29700 32.82568 1.250917 49.96645
46.34700 32.72562 1.251434 50.07254
46.39700 32.62614 1.251842 49.93962
46.44700 32.52586 1.252209 49.98657
46.49700 32.42518 1.252373 50.06119
46.54700 32.32622 1.252549 50.08764
46.59700 32.22668 1.252787 49.94668
46.64700 32.12610 1.253107 49.95868
46.69700 32.02600 1.253484 50.07462
46.74700 31.92594 1.253702 49.97566
46.79700 31.82673 1.253918 49.93516
46.84700 31.72686 1.254150 49.99140
46.89700 31.62735 1.254294 50.03891
46.94700 31.52721 1.254574 49.99574
46.99700 31.42746 1.254781 50.14446
47.04700 31.32669 1.254946 50.05383
47.09700 31.22745 1.255117 49.96576
47.14700 31.12645 1.255275 50.19502
47.19700 31.02806 1.255556 50.11865
47.24700 30.92730 1.255694 49.98471
47.29700 30.82671 1.255945 50.00189
47.34700 30.72789 1.256159 49.89091
47.39700 30.62678 1.256162 49.94716
47.44700 30.52818 1.256298 50.00900
47.49700 30.42916 1.256483 49.94036
47.54700 30.32818 1.256799 50.10746
47.59700 30.22850 1.257245 50.15586
47.64700 30.12786 1.257753 50.11000
47.69700 30.02790 1.258139 50.11410
47.74700 29.92730 1.258574 50.15316
47.79700 29.82803 1.258934 50.08104
47.84700 29.72783 1.259243 49.96083
47.89700 29.62751 1.259564 50.07214
47.94700 29.52760 1.259764 49.93585
47.99700 29.42840 1.259828 49.98035
48.04700 29.32846 1.260104 49.90386
48.09700 29.22817 1.260402 50.09346
48.14700 29.12878 1.260831 50.05124
48.19700 29.03002 1.261528 50.14800
48.24700 28.92972 1.262669 50.14652
48.29700 28.83005 1.265156 50.04875
48.34700 28.72969 1.269348 50.15806
48.39700 28.63150 1.283126 50.10141
48.44700 28.53344 1.319511 49.94011
48.49700 28.43656 1.387723 49.95311
48.54700 28.34203 1.480493 49.97334
48.59700 28.24902 1.592228 50.17022
48.64700 28.15842 1.742699 50.04414
48.69700 28.07018 1.931713 50.12100
48.74700 27.98672 2.164910 50.03422
48.79700 27.90552 2.442293 49.94660
48.84700 27.82860 2.758167 50.08637
48.89700 27.75516 3.095335 50.00281
48.94700 27.68226 3.452050 49.90726
48.99700 27.61025 3.790400 50.06220
49.04700 27.53737 4.093328 50.03455
49.09700 27.46170 4.333126 49.92287
49.14700 27.38035 4.492490 49.89164
49.19700 27.29227 4.572259 50.02361
49.24700 27.19912 4.574334 49.94863
49.29700 27.09904 4.523560 49.88468
49.34700 26.99418 4.383597 49.94294
49.39700 26.88381 4.209328 49.99718
49.44700 26.77022 4.006180 50.02428
49.49700 26.65428 3.779738 49.94916
49.54700 26.53548 3.539218 49.94690
49.59700 26.41560 3.298350 49.86800
49.64700 26.29721 3.060644 49.97375
49.69700 26.17694 2.831009 49.88317
49.74700 26.05850 2.614800 50.12288
49.79700 25.94036 2.406366 49.99300
49.84700 25.82346 2.227570 50.07054
49.89700 25.70850 2.071664 50.12122
49.94700 25.59672 1.936708 50.10470
49.99700 25.48503 1.825391 49.98872
50.04700 25.37552 1.731662 49.94378
50.09700 25.26832 1.653887 49.98616
50.14700 25.16235 1.591345 50.10540
50.19700 25.05711 1.537914 49.90272
50.24700 24.95166 1.498556 50.05644
50.29700 24.84848 1.462996 49.89644
50.34700 24.74532 1.434458 49.99996
50.39700 24.64326 1.412747 50.11918
50.44700 24.54097 1.394419 49.95172
50.49700 24.44008 1.380440 50.04787
50.54700 24.33852 1.368851 50.03644
50.59700 24.23760 1.359774 49.91530
50.64700 24.13678 1.352000 50.14718
50.69700 24.03604 1.344041 49.84202
50.74700 23.93580 1.336430 49.96828
50.79700 23.83562 1.329002 50.14294
50.84700 23.73442 1.322074 50.15394
50.89700 23.63373 1.315749 50.15832
50.94700 23.53326 1.310037 50.00306
50.99700 23.43318 1.304920 49.94116
51.04700 23.33262 1.300336 49.94641
51.09700 23.23315 1.296310 49.99477
51.14700 23.13251 1.292597 49.95728
51.19700 23.03238 1.289440 50.17426
51.24700 22.93242 1.286560 49.94143
51.29700 22.83240 1.284067 50.06430
51.34700 22.73276 1.281793 50.02268
51.39700 22.63288 1.279922 49.98209
51.44700 22.53252 1.278185 50.11138
51.49700 22.43231 1.276581 50.00324
51.54700 22.33248 1.275162 50.03132
51.59700 22.23233 1.274078 49.99446
51.64700 22.13232 1.272870 50.05203
51.69700 22.03274 1.272012 49.86752
51.74700 21.93257 1.271040 49.99856
51.79700 21.83243 1.270233 50.11421
51.84700 21.73334 1.269564 50.08700
51.89700 21.63296 1.268930 50.09844
51.94700 21.53398 1.268454 49.95851
51.99700 21.43283 1.268030 49.92285
52.04700 21.33298 1.267833 49.96748
52.09700 21.23260 1.267784 49.99917
52.14700 21.13330 1.267524 49.97375
52.19700 21.03303 1.267104 50.15418
52.24700 20.93286 1.266726 50.06312
52.29700 20.83311 1.266596 50.09538
52.34700 20.73281 1.266415 50.04044
52.39700 20.63280 1.266570 50.02696
52.44700 20.53198 1.266649 50.07636
52.49700 20.43159 1.266726 49.96918
52.54700 20.33335 1.266763 50.14218
52.59700 20.23288 1.266614 49.95733
52.64700 20.13259 1.266598 49.72648
52.69700 20.03181 1.266521 50.07547
52.74700 19.93255 1.266482 50.07980
52.79700 19.83313 1.266238 50.02221
52.84700 19.73358 1.265989 50.02598
52.89700 19.63330 1.265502 50.08569
52.94700 19.53334 1.265190 49.97772
52.99700 19.43325 1.264986 49.91789
53.04700 19.33296 1.264692 49.96548
53.09700 19.23362 1.264410 49.96259
53.14700 19.13504 1.264287 50.25806
53.19700 19.03360 1.264009 49.98006
53.24700 18.93391 1.263910 49.97793
53.29700 18.83446 1.263774 50.16068
53.34700 18.73427 1.263689 50.06137
53.39700 18.63377 1.263733 49.89547
53.44700 18.53294 1.264023 50.34882
53.49700 18.43299 1.264387 50.00365
53.54700 18.33294 1.264650 49.94492
53.59700 18.23313 1.264952 49.94071
53.64700 18.13236 1.265113 50.00559
53.69700 18.03275 1.265055 49.94711
53.74700 17.93251 1.265036 49.92884
53.79700 17.83193 1.264975 49.91363
53.84700 17.73270 1.264733 50.04974
53.89700 17.63272 1.264442 49.96300
53.94700 17.53322 1.264253 49.95746
53.99700 17.43364 1.263854 50.05680
54.04700 17.33386 1.263462 49.91824
54.09700 17.23434 1.263016 49.97890
54.14700 17.13348 1.262803 49.93308
54.19700 17.03492 1.262431 49.90344
54.24700 16.93426 1.262156 49.98219
54.29700 16.83414 1.262124 49.85844
54.34700 16.73304 1.262099 50.00163
54.39700 16.63324 1.262113 49.99692
54.44700 16.53296 1.262302 50.08530
54.49700 16.43317 1.262578 50.05765
54.54700 16.33335 1.262776 49.96942
54.59700 16.23352 1.262966 50.09800
54.64700 16.13392 1.263247 49.98754
54.69700 16.03298 1.263235 50.18801
54.74700 15.93272 1.263181 49.83144
54.79700 15.83357 1.263036 50.08653
54.84700 15.73303 1.262999 49.86871
54.89700 15.63328 1.262929 50.21172
54.94700 15.53326 1.262723 49.32942
54.99700 15.43352 1.262446 50.03817
55.04700 15.33397 1.262200 49.90104
55.09700 15.23354 1.261915 49.98648
55.14700 15.13324 1.261662 49.82236
55.19700 15.03398 1.261395 49.97998
55.24700 14.93277 1.261280 50.17960
55.29700 14.83311 1.261131 50.03260
55.34700 14.73370 1.260901 49.90982
55.39700 14.63456 1.260838 50.01238
55.44700 14.53446 1.260698 49.99680
55.49700 14.43409 1.260591 49.98388
55.54700 14.33461 1.260431 49.97510
55.59700 14.23468 1.260208 50.02924
55.64700 14.13420 1.260092 50.26429
55.69700 14.03354 1.260009 49.98724
55.74700 13.93394 1.260030 49.96752
55.79700 13.83476 1.260065 49.27628
55.84700 13.73354 1.260093 49.96798
55.89700 13.63441 1.260246 50.08575
55.94700 13.53406 1.260224 50.15541
55.99700 13.43392 1.260205 50.13148
56.04700 13.33444 1.260469 50.37509
56.09700 13.23361 1.260596 49.89107
56.14700 13.13367 1.260659 49.60304
56.19700 13.03463 1.260508 50.08159
56.24700 12.93346 1.260195 49.97204
56.29700 12.83408 1.259967 50.01294
56.34700 12.73356 1.259877 50.59781
56.39700 12.63454 1.259467 49.66960
56.44700 12.53400 1.259034 50.03004
56.49700 12.43484 1.258608 49.96531
56.54700 12.33383 1.258190 50.09859
56.59700 12.23496 1.257765 49.19340
56.64700 12.13416 1.257685 49.41450
56.69700 12.03505 1.257582 49.98326
56.74700 11.93472 1.257446 50.06400
56.79700 11.83481 1.257228 49.74387
56.84700 11.73494 1.257010 50.11159
56.89700 11.63535 1.256952 49.98516
56.94700 11.53504 1.256780 50.07220
56.99700 11.43482 1.256664 49.96680
57.04700 11.33564 1.256506 50.06506
57.09700 11.23542 1.256643 49.41418
57.14700 11.13399 1.256579 50.08290
57.19700 11.03482 1.256606 50.08002
57.24700 10.93499 1.256467 50.06234
57.29700 10.83564 1.256281 49.88019
57.34700 10.73478 1.256026 50.20613
57.39700 10.63459 1.255767 50.10714
57.44700 10.53447 1.255690 50.22358
57.49700 10.43595 1.255374 50.02550
57.54700 10.33561 1.255113 50.02660
57.59700 10.23550 1.255101 50.11626
57.64700 10.13497 1.255080 49.88298
57.69700 10.03565 1.254882 50.03015
57.74700 9.936176 1.254716 49.86152
57.79700 9.835509 1.254633 50.11865
57.84700 9.734825 1.254746 49.99538
57.89700 9.634757 1.254664 49.96168
57.94700 9.535851 1.254846 49.95470
57.99700 9.436000 1.254692 50.10184
58.04700 9.335853 1.254581 49.89639
58.09700 9.236543 1.254510 49.90566
58.14700 9.135125 1.254394 50.09746
58.19700 9.036042 1.254200 50.16150
58.24700 8.936505 1.254113 50.08322
58.29700 8.836091 1.253723 50.00785
58.34700 8.736288 1.253596 50.03692
58.39700 8.635895 1.253303 50.04782
58.44700 8.536798 1.253003 50.17800
58.49700 8.436528 1.252684 49.99686
58.54700 8.337009 1.252390 50.07861
58.59700 8.237289 1.252075 50.04731
58.64700 8.136890 1.251667 50.14966
58.69700 8.036866 1.251419 49.94297
58.74700 7.937806 1.251155 49.94913
58.79700 7.837800 1.250928 50.00004
58.84700 7.738290 1.250706 50.04031
58.89700 7.637714 1.250573 50.07746
58.94700 7.537670 1.250481 50.10930
58.99700 7.437884 1.250492 49.84116
59.04700 7.337559 1.250619 50.20474
59.09700 7.237549 1.250671 49.95941
59.14700 7.137720 1.250938 49.92002
59.19700 7.037432 1.251059 49.93146
59.24700 6.936730 1.251153 49.90638
59.29700 6.837153 1.251376 49.90956
59.34700 6.737647 1.251498 49.89540
59.39700 6.637901 1.251492 49.77272
59.44700 6.538330 1.251459 50.09442
59.49700 6.437671 1.251574 50.07124
59.54700 6.336680 1.251593 50.11742
59.59700 6.236624 1.251335 50.01590
59.64700 6.137832 1.251233 49.90191
59.69700 6.037854 1.250855 49.99760
59.74700 5.938012 1.250628 50.08458
59.79700 5.837930 1.250240 50.13115
59.84700 5.738880 1.249954 50.08265
59.89700 5.638340 1.249715 50.00961
59.94700 5.538002 1.249436 50.01294
59.99700 5.436079 1.249327 49.96148
60.04700 5.336750 1.249438 49.90666
60.09700 5.236728 1.249536 49.96582
60.14700 5.136874 1.249814 50.00684
60.19700 5.036620 1.250175 50.00281
60.24700 4.936850 1.250376 49.95290
60.29700 4.835841 1.250459 50.21902
60.34700 4.736698 1.250406 49.98336
60.39700 4.636887 1.250357 49.92748
60.44700 4.536680 1.250034 49.69710
60.49700 4.436760 1.249783 50.05496
60.54700 4.336396 1.249416 49.89754
60.59700 4.237305 1.249221 49.98644
60.64700 4.137048 1.249158 49.85398
60.69700 4.037109 1.248812 50.09516
60.74700 3.936789 1.248550 49.89180
60.79700 3.836234 1.248247 50.18717
60.84700 3.737150 1.248234 49.95402
60.89700 3.637224 1.247950 50.10520
60.94700 3.536728 1.247676 50.17446
60.99700 3.437258 1.247393 50.00598
61.04700 3.336814 1.247072 49.84360
61.09700 3.237117 1.246881 49.92086
61.14700 3.137852 1.246666 49.92233
61.19700 3.037232 1.246441 50.00928
61.24700 2.937342 1.246203 49.85282
61.29700 2.838022 1.245949 49.77543
61.34700 2.738012 1.245603 49.91858
61.39700 2.637984 1.245456 50.07166
61.44700 2.537935 1.245278 50.11746
61.49700 2.438186 1.245164 49.90907
61.54700 2.337294 1.244944 49.96267
61.59700 2.238006 1.244848 49.94194
61.64700 2.138586 1.244524 49.38281
61.69700 2.039002 1.244356 50.61140
61.74700 1.938438 1.244110 49.91426
61.79700 1.838630 1.243928 49.95947
61.84700 1.738667 1.243701 49.79689
61.89700 1.637822 1.243559 49.89963
61.94700 1.538168 1.243243 49.79878
61.99700 1.438701 1.243266 50.09707
62.04700 1.341275 1.243712 50.01166
62.09700 1.268734 1.239543 50.18774
62.14700 1.222038 1.162458 50.07910
62.19700 1.186276 1.066567 49.96320
62.24700 1.155254 0.9655951 49.99478
62.29700 1.132509 0.8700074 49.91959
62.34700 1.112552 0.7752292 50.12126
62.39700 1.095255 0.6929440 50.20412
62.44700 1.081215 0.6210190 49.91500
62.49700 1.070323 0.5533467 50.03740
62.54700 1.060061 0.4985238 49.94518
62.59700 1.051766 0.4480469 49.89876
62.64700 1.043977 0.4078588 49.79865
62.69700 1.038467 0.3696245 49.88246
62.74700 1.032224 0.3416794 49.99396
62.79700 1.027629 0.3174532 49.87693
62.84700 1.024527 0.2964556 49.85280
62.89700 1.021367 0.2789201 49.94858
62.94700 1.017959 0.2653840 50.37370
62.99700 1.015815 0.2550542 50.08867
63.04700 1.013984 0.2450797 48.93981
63.09700 1.012400 0.2357539 50.00424
63.14700 1.009950 0.2276907 49.93938
63.19700 1.009202 0.2198130 49.78843
63.24700 1.007507 0.2123735 50.09475
63.29700 1.006857 0.2051769 50.14210
63.34700 1.005139 0.1984426 50.05916
63.39700 1.003950 0.1921000 49.81855
63.44700 1.002859 0.1861919 49.93241
63.49700 1.002588 0.1807864 50.17492
63.54700 1.001911 0.1758346 50.12613
63.59700 1.001634 0.1714496 49.96377
63.64700 1.000599 0.1676417 50.09093
63.69700 1.000410 0.1642765 50.22360
63.74700 0.9987244 0.1613386 49.77565
63.79700 0.9989664 0.1587355 49.89810
63.84700 0.9979126 0.1567226 49.28506
63.89700 0.9969778 0.1546390 49.90610
63.94700 0.9962063 0.1529326 49.88318
63.99700 0.9966199 0.1513881 50.14152
64.04700 0.9956016 0.1499786 49.80384
64.09700 0.9946158 0.1488299 50.13328
64.14700 0.9947281 0.1476700 49.97180
64.19701 0.9956746 0.1465544 49.87159
64.24700 0.9940941 0.1454511 50.18446
64.29700 0.9937035 0.1444468 50.06162
64.34700 0.9943539 0.1435536 50.09342
64.39700 0.9940551 0.1424814 49.96914
64.44701 0.9934860 0.1415054 50.06011
64.49700 0.9940708 0.1406056 50.19607
64.54700 0.9929449 0.1398231 50.03728
64.59700 0.9920988 0.1389585 49.92226
64.64700 0.9924309 0.1382398 50.21664
64.69701 0.9930266 0.1375153 50.16873
64.74700 0.9927551 0.1369416 50.02908
64.79700 0.9922852 0.1364461 49.98120
-2.000000 2.000000 0.0000000 0.0000000